{"op":"mcm","clk":"1150059458","pt":1439927657293,"mc":[{"id":"1.120089104","rc":[{"atl":[[7.2,101.39]],"id":9480385}],"con":true,"img":false,"tv":84239.52}]}
{"op":"mcm","clk":"1150059485","pt":1439927657527,"mc":[{"id":"1.120089104","rc":[{"atl":[[7.2,104.39]],"id":9480385}],"con":true,"img":false,"tv":84239.52}]}
{"op":"mcm","clk":"1150059653","pt":1439927658841,"mc":[{"id":"1.120089104","rc":[{"trd":[[1.17,25153.59]],"ltp":1.17,"tv":25153.59,"id":9612932},{"atl":[[1.17,1629.5]],"id":9612932}],"con":true,"img":false,"tv":84239.52}]}
{"op":"mcm","clk":"1150059784","pt":1439927660011,"mc":[{"id":"1.120089104","rc":[{"trd":[[1.17,25193.59]],"ltp":1.17,"tv":25193.59,"id":9612932},{"atl":[[1.17,1609.5]],"id":9612932}],"con":true,"img":false,"tv":84239.52}]}
{"op":"mcm","clk":"1150059817","pt":1439927660344,"mc":[{"id":"1.120089104","rc":[{"atl":[[1.2,1451.41]],"id":9612932}],"con":true,"img":false,"tv":84239.52}]}
{"op":"mcm","clk":"1150059883","pt":1439927660922,"mc":[{"id":"1.120089104","rc":[{"atl":[[7.2,98.39]],"id":9480385}],"con":true,"img":false,"tv":84239.52}]}
{"op":"mcm","clk":"1150059960","pt":1439927661642,"mc":[{"id":"1.120089104","rc":[{"atl":[[7.2,101.39]],"id":9480385}],"con":true,"img":false,"tv":84239.52}]}
{"op":"mcm","clk":"1150059972","pt":1439927661827,"mc":[{"id":"1.120089104","rc":[{"atl":[[7.2,104.39]],"id":9480385}],"con":true,"img":false,"tv":84239.52}]}
{"op":"mcm","clk":"1150060090","pt":1439927663041,"mc":[{"id":"1.120089104","rc":[{"atl":[[1.2,1431.41]],"id":9612932}],"con":true,"img":false,"tv":84239.52}]}
{"op":"mcm","clk":"1150060097","pt":1439927663151,"mc":[{"id":"1.120089104","rc":[{"trd":[[1.16,34292.72]],"ltp":1.16,"tv":34292.72,"id":9612932},{"atb":[[1.16,3833.45]],"id":9612932}],"con":true,"img":false,"tv":84239.52}]}
{"op":"mcm","clk":"1150060158","pt":1439927663651,"mc":[{"id":"1.120089104","rc":[{"atl":[[7.2,79.39]],"id":9480385}],"con":true,"img":false,"tv":84239.52}]}
{"op":"mcm","clk":"1150060168","pt":1439927663761,"mc":[{"id":"1.120089104","rc":[{"atl":[[1.17,1842.58],[1.18,1812.26]],"id":9612932}],"con":true,"img":false,"tv":84239.52}]}
{"op":"mcm","clk":"1150060198","pt":1439927664038,"mc":[{"id":"1.120089104","rc":[{"atb":[[1.16,3359.53]],"id":9612932}],"con":true,"img":false,"tv":84239.52}]}
{"op":"mcm","clk":"1150060232","pt":1439927664360,"mc":[{"id":"1.120089104","rc":[{"atb":[[1.16,3397.08]],"id":9612932}],"con":true,"img":false,"tv":84239.52}]}
{"op":"mcm","clk":"1150060245","pt":1439927664471,"mc":[{"id":"1.120089104","rc":[{"trd":[[7.2,266.07]],"ltp":7.2,"tv":266.07,"id":9480385},{"atl":[[7.2,45.91]],"id":9480385}],"con":true,"img":false,"tv":84306.48}]}
{"op":"mcm","clk":"1150060263","pt":1439927664696,"mc":[{"id":"1.120089104","rc":[{"atb":[[7,17.08]],"id":9480385},{"atl":[[7.2,50.82]],"id":9480385}],"con":true,"img":false,"tv":84306.48}]}
{"op":"mcm","clk":"1150060344","pt":1439927665414,"mc":[{"id":"1.120089104","rc":[{"atl":[[1.17,1953.58]],"id":9612932}],"con":true,"img":false,"tv":84306.48}]}
{"op":"mcm","clk":"1150060361","pt":1439927665509,"mc":[{"id":"1.120089104","rc":[{"trd":[[1.17,25213.59]],"ltp":1.17,"tv":25213.59,"id":9612932},{"atl":[[1.17,1943.58]],"id":9612932},{"atl":[[7.6,41.18]],"id":9480385}],"con":true,"img":false,"tv":84359.83}]}
{"op":"mcm","clk":"1150060385","pt":1439927665804,"mc":[{"id":"1.120089104","rc":[{"atb":[[1.16,3416.41]],"id":9612932},{"trd":[[7.2,299.43]],"ltp":7.2,"tv":299.43,"id":9480385},{"atl":[[7.2,34.14]],"id":9480385}],"con":true,"img":false,"tv":84359.83}]}
{"op":"mcm","clk":"1150060399","pt":1439927665920,"mc":[{"id":"1.120089104","rc":[{"atb":[[7,20.29]],"id":9480385}],"con":true,"img":false,"tv":84359.83}]}
{"op":"mcm","clk":"1150060515","pt":1439927666825,"mc":[{"id":"1.120089104","rc":[{"atl":[[1.17,1945.58]],"id":9612932}],"con":true,"img":false,"tv":84359.83}]}
{"op":"mcm","clk":"1150060546","pt":1439927667011,"mc":[{"id":"1.120089104","rc":[{"atb":[[4.5,15.71]],"id":9480385}],"con":true,"img":false,"tv":84359.83}]}
{"op":"mcm","clk":"1150060715","pt":1439927668673,"mc":[{"id":"1.120089104","rc":[{"atl":[[7.6,42.59]],"id":9480385}],"con":true,"img":false,"tv":84359.83}]}
{"op":"mcm","clk":"1150060731","pt":1439927668754,"mc":[{"id":"1.120089104","rc":[{"atl":[[7.8,48.67]],"id":9480385}],"con":true,"img":false,"tv":84359.83}]}
{"op":"mcm","clk":"1150060795","pt":1439927669437,"mc":[{"id":"1.120089104","rc":[{"atb":[[1.14,21433.32]],"id":9612932}],"con":true,"img":false,"tv":84359.83}]}
{"op":"mcm","clk":"1150060829","pt":1439927669758,"mc":[{"id":"1.120089104","rc":[{"trd":[[1.17,25216.41]],"ltp":1.17,"tv":25216.41,"id":9612932},{"atl":[[1.17,1944.17]],"id":9612932}],"con":true,"img":false,"tv":84362.65}]}
{"op":"mcm","clk":"1150060870","pt":1439927670034,"mc":[{"id":"1.120089104","rc":[{"atl":[[7.6,41.18]],"id":9480385}],"con":true,"img":false,"tv":84362.65}]}
{"op":"mcm","clk":"1150060883","pt":1439927670140,"mc":[{"id":"1.120089104","rc":[{"atl":[[1.17,2532.4]],"id":9612932}],"con":true,"img":false,"tv":84362.65}]}
{"op":"mcm","clk":"1150060902","pt":1439927670361,"mc":[{"id":"1.120089104","rc":[{"atl":[[7.8,47.26]],"id":9480385}],"con":true,"img":false,"tv":84362.65}]}
{"op":"mcm","clk":"1150060910","pt":1439927670467,"mc":[{"id":"1.120089104","rc":[{"trd":[[7,430.16]],"ltp":7.0,"tv":430.16,"id":9480385},{"atb":[[7,18.29]],"id":9480385}],"con":true,"img":false,"tv":84366.65}]}
{"op":"mcm","clk":"1150060935","pt":1439927670683,"mc":[{"id":"1.120089104","rc":[{"atb":[[1.16,3516.41]],"id":9612932}],"con":true,"img":false,"tv":84366.65}]}
{"op":"mcm","clk":"1150060944","pt":1439927670791,"mc":[{"id":"1.120089104","rc":[{"atb":[[7,23.44]],"id":9480385},{"atl":[[7.2,39.14]],"id":9480385}],"con":true,"img":false,"tv":84366.65}]}
{"op":"mcm","clk":"1150060947","pt":1439927670900,"mc":[{"id":"1.120089104","rc":[{"trd":[[7,452.16]],"ltp":7.0,"tv":452.16,"id":9480385},{"atb":[[7,12.44]],"id":9480385}],"con":true,"img":false,"tv":84388.65}]}
{"op":"mcm","clk":"1150060961","pt":1439927671015,"mc":[{"id":"1.120089104","rc":[{"atl":[[8.4,3]],"id":9480385}],"con":true,"img":false,"tv":84388.65}]}
{"op":"mcm","clk":"1150060965","pt":1439927671070,"mc":[{"id":"1.120089104","rc":[{"atb":[[6.8,118.14],[7,53.61],[6.6,63.81]],"id":9480385}],"con":true,"img":false,"tv":84388.65}]}
{"op":"mcm","clk":"1150060983","pt":1439927671181,"mc":[{"id":"1.120089104","rc":[{"atb":[[1.16,3616.41]],"id":9612932},{"atl":[[8.4,6],[7.6,39.78]],"id":9480385}],"con":true,"img":false,"tv":84388.65}]}
{"op":"mcm","clk":"1150061014","pt":1439927671451,"mc":[{"id":"1.120089104","rc":[{"spl":[[1.01,44]],"id":9480385}],"con":true,"img":false,"tv":84388.65}]}
{"op":"mcm","clk":"1150061024","pt":1439927671615,"mc":[{"id":"1.120089104","rc":[{"atb":[[1.16,3716.41]],"id":9612932},{"atl":[[7.2,37.43]],"id":9480385}],"con":true,"img":false,"tv":84388.65}]}
{"op":"mcm","clk":"1150061060","pt":1439927671890,"mc":[{"id":"1.120089104","rc":[{"trd":[[7,472.16]],"ltp":7.0,"tv":472.16,"id":9480385},{"atb":[[7,43.61]],"id":9480385}],"con":true,"img":false,"tv":84408.66}]}
{"op":"mcm","clk":"1150061266","pt":1439927673726,"mc":[{"id":"1.120089104","rc":[{"atb":[[1.15,16629.03]],"id":9612932}],"con":true,"img":false,"tv":84408.66}]}
{"op":"mcm","clk":"1150061333","pt":1439927674431,"mc":[{"id":"1.120089104","rc":[{"trd":[[1.17,25219.23]],"ltp":1.17,"tv":25219.23,"id":9612932},{"atl":[[1.17,2530.99]],"id":9612932},{"atl":[[7.2,48.43]],"id":9480385}],"con":true,"img":false,"tv":84411.47}]}
{"op":"mcm","clk":"1150061371","pt":1439927674734,"mc":[{"id":"1.120089104","rc":[{"trd":[[7,476.16]],"ltp":7.0,"tv":476.16,"id":9480385},{"atb":[[7,41.61]],"id":9480385}],"con":true,"img":false,"tv":84415.47}]}
{"op":"mcm","clk":"1150061396","pt":1439927674923,"mc":[{"id":"1.120089104","rc":[{"trd":[[7,480.16]],"ltp":7.0,"tv":480.16,"id":9480385},{"atb":[[7,39.61]],"id":9480385},{"atl":[[7.6,52.73]],"id":9480385}],"con":true,"img":false,"tv":84419.47}]}
{"op":"mcm","clk":"1150061431","pt":1439927675246,"mc":[{"id":"1.120089104","rc":[{"trd":[[7,484.16]],"ltp":7.0,"tv":484.16,"id":9480385},{"atb":[[7,37.61]],"id":9480385}],"con":true,"img":false,"tv":84423.47}]}
{"op":"mcm","clk":"1150061468","pt":1439927675566,"mc":[{"id":"1.120089104","rc":[{"trd":[[1.16,34298.52]],"ltp":1.16,"tv":34298.52,"id":9612932},{"atb":[[1.16,3713.51]],"id":9612932}],"con":true,"img":false,"tv":84429.27}]}
{"op":"mcm","clk":"1150061492","pt":1439927675835,"mc":[{"id":"1.120089104","rc":[{"trd":[[7,488.16]],"ltp":7.0,"tv":488.16,"id":9480385},{"atb":[[7,35.61]],"id":9480385}],"con":true,"img":false,"tv":84433.27}]}
{"op":"mcm","clk":"1150061549","pt":1439927676379,"mc":[{"id":"1.120089104","rc":[{"trd":[[1.17,25239.23]],"ltp":1.17,"tv":25239.23,"id":9612932},{"atl":[[1.17,2520.99]],"id":9612932}],"con":true,"img":false,"tv":84453.27}]}
{"op":"mcm","clk":"1150061567","pt":1439927676584,"mc":[{"id":"1.120089104","rc":[{"atb":[[7,43.36]],"id":9480385}],"con":true,"img":false,"tv":84453.27}]}
{"op":"mcm","clk":"1150061592","pt":1439927676782,"mc":[{"id":"1.120089104","rc":[{"trd":[[1.17,25244.97]],"ltp":1.17,"tv":25244.97,"id":9612932},{"atl":[[1.17,2518.12]],"id":9612932}],"con":true,"img":false,"tv":84459.01}]}
{"op":"mcm","clk":"1150061597","pt":1439927676867,"mc":[{"id":"1.120089104","rc":[{"atl":[[1.17,2520.12]],"id":9612932}],"con":true,"img":false,"tv":84459.01}]}
{"op":"mcm","clk":"1150061658","pt":1439927677357,"mc":[{"id":"1.120089104","rc":[{"trd":[[1.17,25253.43]],"ltp":1.17,"tv":25253.43,"id":9612932},{"atl":[[1.17,2515.89]],"id":9612932}],"con":true,"img":false,"tv":84467.47}]}
{"op":"mcm","clk":"1150061693","pt":1439927677795,"mc":[{"id":"1.120089104","rc":[{"trd":[[7,574.88]],"ltp":7.0,"tv":574.88,"id":9480385},{"atb":[[7,0]],"id":9480385},{"atl":[[7,44.71]],"id":9480385}],"con":true,"img":false,"tv":84554.19}]}
{"op":"mcm","clk":"1150061729","pt":1439927678073,"mc":[{"id":"1.120089104","rc":[{"trd":[[1.17,25257.43]],"ltp":1.17,"tv":25257.43,"id":9612932},{"atl":[[1.17,2513.89],[1.35,1.4]],"id":9612932},{"trd":[[7,630]],"ltp":7.0,"tv":630.0,"id":9480385},{"atl":[[7,17.15]],"id":9480385}],"con":true,"img":false,"tv":84613.31}]}
{"op":"mcm","clk":"1150061742","pt":1439927678181,"mc":[{"id":"1.120089104","rc":[{"atl":[[1.17,2315.3]],"id":9612932},{"atb":[[6.8,102.96],[6.6,51.23]],"id":9480385},{"atl":[[7.2,78.88]],"id":9480385}],"con":true,"img":false,"tv":84613.31}]}
{"op":"mcm","clk":"1150061763","pt":1439927678396,"mc":[{"id":"1.120089104","rc":[{"atb":[[1.16,3992.01]],"id":9612932},{"atl":[[1.17,2082.22]],"id":9612932},{"atb":[[6.8,150.46]],"id":9480385},{"atl":[[7,20.15]],"id":9480385}],"con":true,"img":false,"tv":84613.31}]}
{"op":"mcm","clk":"1150061796","pt":1439927678675,"mc":[{"id":"1.120089104","rc":[{"trd":[[1.17,25300.83]],"ltp":1.17,"tv":25300.83,"id":9612932},{"atl":[[1.17,2060.52]],"id":9612932},{"atl":[[7,27.9]],"id":9480385}],"con":true,"img":false,"tv":84656.71}]}
{"op":"mcm","clk":"1150061811","pt":1439927678784,"mc":[{"id":"1.120089104","rc":[{"atl":[[1.17,2062.52]],"id":9612932}],"con":true,"img":false,"tv":84656.71}]}
{"op":"mcm","clk":"1150061825","pt":1439927678893,"mc":[{"id":"1.120089104","rc":[{"trd":[[1.17,25350.83]],"ltp":1.17,"tv":25350.83,"id":9612932},{"atl":[[1.17,2037.52]],"id":9612932}],"con":true,"img":false,"tv":84706.71}]}
{"op":"mcm","clk":"1150061838","pt":1439927679001,"mc":[{"id":"1.120089104","rc":[{"atl":[[7,115.98]],"id":9480385}],"con":true,"img":false,"tv":84706.71}]}
{"op":"mcm","clk":"1150061863","pt":1439927679183,"mc":[{"id":"1.120089104","rc":[{"trd":[[1.16,34318.52]],"ltp":1.16,"tv":34318.52,"id":9612932},{"atb":[[1.16,3982.01]],"id":9612932}],"con":true,"img":false,"tv":84726.71}]}
{"op":"mcm","clk":"1150061875","pt":1439927679295,"mc":[{"id":"1.120089104","rc":[{"trd":[[1.17,25354.83]],"ltp":1.17,"tv":25354.83,"id":9612932},{"atl":[[1.17,2035.52]],"id":9612932}],"con":true,"img":false,"tv":84730.71}]}
{"op":"mcm","clk":"1150061894","pt":1439927679514,"mc":[{"id":"1.120089104","rc":[{"atl":[[7,117.98]],"id":9480385}],"con":true,"img":false,"tv":84730.71}]}
{"op":"mcm","clk":"1150061998","pt":1439927680467,"mc":[{"id":"1.120089104","rc":[{"atl":[[7,120.78]],"id":9480385}],"con":true,"img":false,"tv":84730.71}]}
{"op":"mcm","clk":"1150062011","pt":1439927680603,"mc":[{"id":"1.120089104","rc":[{"atl":[[7,117.78]],"id":9480385}],"con":true,"img":false,"tv":84730.71}]}
{"op":"mcm","clk":"1150062023","pt":1439927680689,"mc":[{"id":"1.120089104","rc":[{"atl":[[1.17,2031.52]],"id":9612932}],"con":true,"img":false,"tv":84730.71}]}
{"op":"mcm","clk":"1150062036","pt":1439927680791,"mc":[{"id":"1.120089104","rc":[{"trd":[[1.16,34326.52]],"ltp":1.16,"tv":34326.52,"id":9612932},{"atb":[[1.16,3978.01]],"id":9612932}],"con":true,"img":false,"tv":84738.71}]}
{"op":"mcm","clk":"1150062071","pt":1439927681118,"mc":[{"id":"1.120089104","rc":[{"atl":[[7.2,111.88]],"id":9480385}],"con":true,"img":false,"tv":84738.71}]}
{"op":"mcm","clk":"1150062095","pt":1439927681306,"mc":[{"id":"1.120089104","rc":[{"trd":[[1.17,25397.1]],"ltp":1.17,"tv":25397.1,"id":9612932},{"atl":[[1.17,2010.38]],"id":9612932}],"con":true,"img":false,"tv":84780.99}]}
{"op":"mcm","clk":"1150062129","pt":1439927681624,"mc":[{"id":"1.120089104","rc":[{"atl":[[7,119.78]],"id":9480385}],"con":true,"img":false,"tv":84780.99}]}
{"op":"mcm","clk":"1150062149","pt":1439927681825,"mc":[{"id":"1.120089104","rc":[{"trd":[[1.17,25697.1]],"ltp":1.17,"tv":25697.1,"id":9612932},{"atl":[[1.17,1860.38]],"id":9612932}],"con":true,"img":false,"tv":85080.99}]}
{"op":"mcm","clk":"1150062171","pt":1439927682007,"mc":[{"id":"1.120089104","rc":[{"atb":[[4,4]],"id":9480385},{"atl":[[7,124.78]],"id":9480385}],"con":true,"img":false,"tv":85080.99}]}
{"op":"mcm","clk":"1150062203","pt":1439927682328,"mc":[{"id":"1.120089104","rc":[{"atl":[[1000,3]],"id":9612932}],"con":true,"img":false,"tv":85080.99}]}
{"op":"mcm","clk":"1150062229","pt":1439927682525,"mc":[{"id":"1.120089104","rc":[{"atl":[[1000,1.03]],"id":9612932}],"con":true,"img":false,"tv":85080.99}]}
{"op":"mcm","clk":"1150062258","pt":1439927682802,"mc":[{"id":"1.120089104","rc":[{"atl":[[1000,1]],"id":9612932}],"con":true,"img":false,"tv":85080.99}]}
{"op":"mcm","clk":"1150062272","pt":1439927682910,"mc":[{"id":"1.120089104","rc":[{"trd":[[1.16,34326.58]],"ltp":1.16,"tv":34326.58,"id":9612932},{"atb":[[1.16,3977.98]],"id":9612932},{"spn":6.8,"spf":3.47,"id":9480385}],"con":true,"img":false,"tv":85081.05}]}
{"op":"mcm","clk":"1150062297","pt":1439927683124,"mc":[{"id":"1.120089104","rc":[{"trd":[[1.16,34330.58]],"ltp":1.16,"tv":34330.58,"id":9612932},{"atb":[[1.16,3975.98]],"id":9612932}],"con":true,"img":false,"tv":85085.05}]}
{"op":"mcm","clk":"1150062311","pt":1439927683230,"mc":[{"id":"1.120089104","rc":[{"trd":[[1.17,25747.1]],"ltp":1.17,"tv":25747.1,"id":9612932},{"atl":[[1.17,1835.38]],"id":9612932}],"con":true,"img":false,"tv":85135.05}]}
{"op":"mcm","clk":"1150062329","pt":1439927683342,"mc":[{"id":"1.120089104","rc":[{"trd":[[1.17,25947.1]],"ltp":1.17,"tv":25947.1,"id":9612932},{"atl":[[1.17,1735.38]],"id":9612932}],"con":true,"img":false,"tv":85335.05}]}
{"op":"mcm","clk":"1150062380","pt":1439927683721,"mc":[{"id":"1.120089104","rc":[{"trd":[[6.8,738.53]],"ltp":6.8,"tv":738.53,"id":9480385},{"atb":[[6.8,62.38]],"id":9480385}],"con":true,"img":false,"tv":85511.2}]}
{"op":"mcm","clk":"1150062401","pt":1439927683842,"mc":[{"id":"1.120089104","rc":[{"atl":[[80,1.55]],"id":9480385}],"con":true,"img":false,"tv":85511.2}]}
{"op":"mcm","clk":"1150062481","pt":1439927684542,"mc":[{"id":"1.120089104","rc":[{"trd":[[1.17,26047.1]],"ltp":1.17,"tv":26047.1,"id":9612932},{"atl":[[1.17,1685.38]],"id":9612932}],"con":true,"img":false,"tv":85611.2}]}
{"op":"mcm","clk":"1150062544","pt":1439927685034,"mc":[{"id":"1.120089104","rc":[{"atb":[[1.16,3977.39]],"id":9612932}],"con":true,"img":false,"tv":85611.2}]}
{"op":"mcm","clk":"1150062572","pt":1439927685250,"mc":[{"id":"1.120089104","rc":[{"trd":[[7,636]],"ltp":7.0,"tv":636.0,"id":9480385},{"atl":[[7,121.78]],"id":9480385}],"con":true,"img":false,"tv":85617.2}]}
{"op":"mcm","clk":"1150062711","pt":1439927686562,"mc":[{"id":"1.120089104","rc":[{"trd":[[1.17,26056.4]],"ltp":1.17,"tv":26056.4,"id":9612932},{"atl":[[1.17,1680.73]],"id":9612932}],"con":true,"img":false,"tv":85626.5}]}
{"op":"mcm","clk":"1150062788","pt":1439927687273,"mc":[{"id":"1.120089104","rc":[{"atb":[[1.14,21431.91]],"id":9612932}],"con":true,"img":false,"tv":85626.5}]}
{"op":"mcm","clk":"1150062830","pt":1439927687651,"mc":[{"id":"1.120089104","rc":[{"atb":[[1.15,16679.03]],"id":9612932}],"con":true,"img":false,"tv":85626.5}]}
{"op":"mcm","clk":"1150062877","pt":1439927687976,"mc":[{"id":"1.120089104","rc":[{"atb":[[3.15,11]],"id":9480385}],"con":true,"img":false,"tv":85626.5}]}
{"op":"mcm","clk":"1150062879","pt":1439927688030,"mc":[{"id":"1.120089104","rc":[{"atl":[[1.17,3442.29]],"id":9612932}],"con":true,"img":false,"tv":85626.5}]}
{"op":"mcm","clk":"1150062906","pt":1439927688245,"mc":[{"id":"1.120089104","rc":[{"trd":[[6.8,744.53]],"ltp":6.8,"tv":744.53,"id":9480385},{"atb":[[6.8,59.38]],"id":9480385}],"con":true,"img":false,"tv":85632.51}]}
{"op":"mcm","clk":"1150062917","pt":1439927688352,"mc":[{"id":"1.120089104","rc":[{"trd":[[1.16,34346.08]],"ltp":1.16,"tv":34346.08,"id":9612932},{"atb":[[1.16,3969.64]],"id":9612932}],"con":true,"img":false,"tv":85648.01}]}
{"op":"mcm","clk":"1150062942","pt":1439927688568,"mc":[{"id":"1.120089104","rc":[{"trd":[[7,691.37]],"ltp":7.0,"tv":691.37,"id":9480385},{"atl":[[7,94.09]],"id":9480385}],"con":true,"img":false,"tv":85703.37}]}
{"op":"mcm","clk":"1150062984","pt":1439927688846,"mc":[{"id":"1.120089104","rc":[{"trd":[[1.17,26114.86]],"ltp":1.17,"tv":26114.86,"id":9612932},{"atl":[[1.17,3413.06]],"id":9612932}],"con":true,"img":false,"tv":85761.83}]}
{"op":"mcm","clk":"1150063078","pt":1439927689582,"mc":[{"id":"1.120089104","rc":[{"atl":[[7,92.09]],"id":9480385}],"con":true,"img":false,"tv":85761.83}]}
{"op":"mcm","clk":"1150063089","pt":1439927689664,"mc":[{"id":"1.120089104","rc":[{"trd":[[6.8,748.54]],"ltp":6.8,"tv":748.54,"id":9480385},{"atb":[[6.8,57.38]],"id":9480385}],"con":true,"img":false,"tv":85765.83}]}
{"op":"mcm","clk":"1150063163","pt":1439927690369,"mc":[{"id":"1.120089104","rc":[{"atb":[[1.13,17683.94]],"id":9612932}],"con":true,"img":false,"tv":85765.83}]}
{"op":"mcm","clk":"1150063214","pt":1439927690680,"mc":[{"id":"1.120089104","rc":[{"trd":[[1.17,26138.86]],"ltp":1.17,"tv":26138.86,"id":9612932},{"atl":[[1.17,3401.06]],"id":9612932},{"atl":[[80,1.4]],"id":9480385}],"con":true,"img":false,"tv":85789.83}]}
{"op":"mcm","clk":"1150063224","pt":1439927690776,"mc":[{"id":"1.120089104","rc":[{"atl":[[7,92.24]],"id":9480385}],"con":true,"img":false,"tv":85789.83}]}
{"op":"mcm","clk":"1150063234","pt":1439927690879,"mc":[{"id":"1.120089104","rc":[{"atb":[[6.8,90.38]],"id":9480385}],"con":true,"img":false,"tv":85789.83}]}
{"op":"mcm","clk":"1150063350","pt":1439927691889,"mc":[{"id":"1.120089104","rc":[{"trd":[[6.8,783.77]],"ltp":6.8,"tv":783.77,"id":9480385},{"atb":[[6.8,72.77]],"id":9480385}],"con":true,"img":false,"tv":85825.06}]}
{"op":"mcm","clk":"1150063416","pt":1439927692417,"mc":[{"id":"1.120089104","rc":[{"trd":[[1.17,26174.86]],"ltp":1.17,"tv":26174.86,"id":9612932},{"atl":[[1.17,3383.06]],"id":9612932}],"con":true,"img":false,"tv":85861.06}]}
{"op":"mcm","clk":"1150063450","pt":1439927692808,"mc":[{"id":"1.120089104","rc":[{"atb":[[5.7,6.41]],"id":9480385}],"con":true,"img":false,"tv":85861.06}]}
{"op":"mcm","clk":"1150063495","pt":1439927693133,"mc":[{"id":"1.120089104","rc":[{"trd":[[6.8,819]],"ltp":6.8,"tv":819.0,"id":9480385},{"atb":[[6.8,55.15]],"id":9480385}],"con":true,"img":false,"tv":85896.3}]}
{"op":"mcm","clk":"1150063497","pt":1439927693185,"mc":[{"id":"1.120089104","rc":[{"trd":[[1.17,26198.38]],"ltp":1.17,"tv":26198.38,"id":9612932},{"atl":[[1.17,3371.3]],"id":9612932}],"con":true,"img":false,"tv":85919.82}]}
{"op":"mcm","clk":"1150063590","pt":1439927693943,"mc":[{"id":"1.120089104","rc":[{"trd":[[1.16,34790.08]],"ltp":1.16,"tv":34790.08,"id":9612932},{"atb":[[1.16,3747.64]],"id":9612932}],"con":true,"img":false,"tv":86363.82}]}
{"op":"mcm","clk":"1150063678","pt":1439927694649,"mc":[{"id":"1.120089104","rc":[{"atl":[[7.6,48.73]],"id":9480385}],"con":true,"img":false,"tv":86363.82}]}
{"op":"mcm","clk":"1150063735","pt":1439927695064,"mc":[{"id":"1.120089104","rc":[{"atb":[[2.2,22]],"id":9480385}],"con":true,"img":false,"tv":86363.82}]}
{"op":"mcm","clk":"1150063796","pt":1439927695665,"mc":[{"id":"1.120089104","rc":[{"atb":[[5.9,0]],"id":9480385}],"con":true,"img":false,"tv":86363.82}]}
{"op":"mcm","clk":"1150063801","pt":1439927695771,"mc":[{"id":"1.120089104","rc":[{"trd":[[1.16,35071.92]],"ltp":1.16,"tv":35071.92,"id":9612932},{"atb":[[1.16,3606.72]],"id":9612932},{"atb":[[5.6,78.46]],"id":9480385}],"con":true,"img":false,"tv":86645.66}]}
{"op":"mcm","clk":"1150063838","pt":1439927696046,"mc":[{"id":"1.120089104","rc":[{"trd":[[6.8,854.24]],"ltp":6.8,"tv":854.24,"id":9480385},{"atb":[[6.8,37.53]],"id":9480385}],"con":true,"img":false,"tv":86680.9}]}
{"op":"mcm","clk":"1150063877","pt":1439927696372,"mc":[{"id":"1.120089104","rc":[{"atb":[[6.8,65.04]],"id":9480385}],"con":true,"img":false,"tv":86680.9}]}
{"op":"mcm","clk":"1150063925","pt":1439927696754,"mc":[{"id":"1.120089104","rc":[{"trd":[[1.17,26202.38]],"ltp":1.17,"tv":26202.38,"id":9612932},{"atl":[[1.17,3369.3]],"id":9612932}],"con":true,"img":false,"tv":86684.9}]}
{"op":"mcm","clk":"1150063962","pt":1439927697079,"mc":[{"id":"1.120089104","rc":[{"atl":[[800,2]],"id":9480385}],"con":true,"img":false,"tv":86684.9}]}
{"op":"mcm","clk":"1150063997","pt":1439927697376,"mc":[{"id":"1.120089104","rc":[{"atb":[[4,6]],"id":9480385}],"con":true,"img":false,"tv":86684.9}]}
{"op":"mcm","clk":"1150064006","pt":1439927697462,"mc":[{"id":"1.120089104","rc":[{"atl":[[1.17,3379.3]],"id":9612932}],"con":true,"img":false,"tv":86684.9}]}
{"op":"mcm","clk":"1150064032","pt":1439927697657,"mc":[{"id":"1.120089104","rc":[{"atl":[[7,94.24]],"id":9480385}],"con":true,"img":false,"tv":86684.9}]}
{"op":"mcm","clk":"1150064054","pt":1439927697869,"mc":[{"id":"1.120089104","rc":[{"atl":[[1.17,1617.74]],"id":9612932}],"con":true,"img":false,"tv":86684.9}]}
{"op":"mcm","clk":"1150064067","pt":1439927697971,"mc":[{"id":"1.120089104","rc":[{"atb":[[6.8,75.04]],"id":9480385}],"con":true,"img":false,"tv":86684.9}]}
{"op":"mcm","clk":"1150064114","pt":1439927698379,"mc":[{"id":"1.120089104","rc":[{"atb":[[6.8,47.53]],"id":9480385}],"con":true,"img":false,"tv":86684.9}]}
{"op":"mcm","clk":"1150064125","pt":1439927698487,"mc":[{"id":"1.120089104","rc":[{"atb":[[6.8,43]],"id":9480385},{"atl":[[7.4,42.51],[7,145.66]],"id":9480385}],"con":true,"img":false,"tv":86684.9}]}
{"op":"mcm","clk":"1150064277","pt":1439927699802,"mc":[{"id":"1.120089104","rc":[{"trd":[[1.17,26210.84]],"ltp":1.17,"tv":26210.84,"id":9612932},{"atl":[[1.17,1613.52]],"id":9612932}],"con":true,"img":false,"tv":86693.35}]}
{"op":"mcm","clk":"1150064287","pt":1439927699907,"mc":[{"id":"1.120089104","rc":[{"atl":[[800,3.94]],"id":9480385}],"con":true,"img":false,"tv":86693.35}]}
{"op":"mcm","clk":"1150064360","pt":1439927700515,"mc":[{"id":"1.120089104","rc":[{"atb":[[1.15,16672.03]],"id":9612932}],"con":true,"img":false,"tv":86693.35}]}
{"op":"mcm","clk":"1150064468","pt":1439927701462,"mc":[{"id":"1.120089104","rc":[{"atl":[[800,2]],"id":9480385}],"con":true,"img":false,"tv":86693.35}]}
{"op":"mcm","clk":"1150064469","pt":1439927701556,"mc":[{"id":"1.120089104","rc":[{"trd":[[6.8,858.12]],"ltp":6.8,"tv":858.12,"id":9480385},{"atb":[[6.8,41.06]],"id":9480385}],"con":true,"img":false,"tv":86697.23}]}
{"op":"mcm","clk":"1150064621","pt":1439927702795,"mc":[{"id":"1.120089104","rc":[{"trd":[[6.8,874.12]],"ltp":6.8,"tv":874.12,"id":9480385},{"atb":[[6.8,33.06]],"id":9480385}],"con":true,"img":false,"tv":86713.23}]}
{"op":"mcm","clk":"1150064637","pt":1439927702875,"mc":[{"id":"1.120089104","rc":[{"atb":[[1.12,19172.65]],"id":9612932},{"atb":[[6,79.87]],"id":9480385}],"con":true,"img":false,"tv":86713.23}]}
{"op":"mcm","clk":"1150064803","pt":1439927704248,"mc":[{"id":"1.120089104","rc":[{"atl":[[800,0]],"id":9480385}],"con":true,"img":false,"tv":86713.23}]}
{"op":"mcm","clk":"1150064833","pt":1439927704467,"mc":[{"id":"1.120089104","rc":[{"trd":[[6.8,886.12]],"ltp":6.8,"tv":886.12,"id":9480385},{"atb":[[6.8,27.06]],"id":9480385}],"con":true,"img":false,"tv":86725.23}]}
{"op":"mcm","clk":"1150064854","pt":1439927704683,"mc":[{"id":"1.120089104","rc":[{"trd":[[1.17,26223.62]],"ltp":1.17,"tv":26223.62,"id":9612932},{"atl":[[1.17,1607.12]],"id":9612932},{"atl":[[7,165.75]],"id":9480385}],"con":true,"img":false,"tv":86738.01}]}
{"op":"mcm","clk":"1150064955","pt":1439927705345,"mc":[{"id":"1.120089104","rc":[{"atb":[[1.15,16972.03]],"id":9612932}],"con":true,"img":false,"tv":86738.01}]}
{"op":"mcm","clk":"1150065034","pt":1439927706055,"mc":[{"id":"1.120089104","rc":[{"atl":[[7,163.75]],"id":9480385}],"con":true,"img":false,"tv":86738.01}]}
{"op":"mcm","clk":"1150065046","pt":1439927706179,"mc":[{"id":"1.120089104","rc":[{"trd":[[6.8,890.12]],"ltp":6.8,"tv":890.12,"id":9480385},{"atb":[[6.8,25.06]],"id":9480385}],"con":true,"img":false,"tv":86742.01}]}
{"op":"mcm","clk":"1150065075","pt":1439927706485,"mc":[{"id":"1.120089104","rc":[{"atl":[[7,165.75]],"id":9480385}],"con":true,"img":false,"tv":86742.01}]}
{"op":"mcm","clk":"1150065221","pt":1439927707801,"mc":[{"id":"1.120089104","rc":[{"atb":[[6.6,68.84]],"id":9480385}],"con":true,"img":false,"tv":86742.01}]}
{"op":"mcm","clk":"1150065333","pt":1439927708577,"mc":[{"id":"1.120089104","rc":[{"atl":[[1.17,1605.12]],"id":9612932}],"con":true,"img":false,"tv":86742.01}]}
{"op":"mcm","clk":"1150065402","pt":1439927709071,"mc":[{"id":"1.120089104","rc":[{"trd":[[1.17,26243.61]],"ltp":1.17,"tv":26243.61,"id":9612932},{"atl":[[1.17,1595.13]],"id":9612932}],"con":true,"img":false,"tv":86762.01}]}
{"op":"mcm","clk":"1150065439","pt":1439927709397,"mc":[{"id":"1.120089104","rc":[{"atl":[[7.4,44.51]],"id":9480385}],"con":true,"img":false,"tv":86762.01}]}
{"op":"mcm","clk":"1150065515","pt":1439927709916,"mc":[{"id":"1.120089104","rc":[{"trd":[[1.17,26247.62]],"ltp":1.17,"tv":26247.62,"id":9612932},{"atl":[[1.17,1593.12]],"id":9612932}],"con":true,"img":false,"tv":86766.01}]}
{"op":"mcm","clk":"1150065538","pt":1439927710118,"mc":[{"id":"1.120089104","rc":[{"trd":[[1.17,26307.62]],"ltp":1.17,"tv":26307.62,"id":9612932},{"atl":[[1.17,1563.12]],"id":9612932}],"con":true,"img":false,"tv":86826.01}]}
{"op":"mcm","clk":"1150065589","pt":1439927710590,"mc":[{"id":"1.120089104","rc":[{"atl":[[7.2,113.88]],"id":9480385}],"con":true,"img":false,"tv":86826.01}]}
{"op":"mcm","clk":"1150065787","pt":1439927712109,"mc":[{"id":"1.120089104","rc":[{"trd":[[1.16,35132.52]],"ltp":1.16,"tv":35132.52,"id":9612932},{"atb":[[1.16,3576.42]],"id":9612932}],"con":true,"img":false,"tv":86886.61}]}
{"op":"mcm","clk":"1150065907","pt":1439927713047,"mc":[{"id":"1.120089104","rc":[{"atl":[[7,163.75]],"id":9480385}],"con":true,"img":false,"tv":86886.61}]}
{"op":"mcm","clk":"1150065943","pt":1439927713413,"mc":[{"id":"1.120089104","rc":[{"trd":[[6.8,894.12]],"ltp":6.8,"tv":894.12,"id":9480385},{"atb":[[6.8,23.06]],"id":9480385}],"con":true,"img":false,"tv":86890.61}]}
{"op":"mcm","clk":"1150066014","pt":1439927713933,"mc":[{"id":"1.120089104","rc":[{"atl":[[7,165.75]],"id":9480385}],"con":true,"img":false,"tv":86890.61}]}
{"op":"mcm","clk":"1150066068","pt":1439927714383,"mc":[{"id":"1.120089104","rc":[{"trd":[[6.8,922.31]],"ltp":6.8,"tv":922.31,"id":9480385},{"atb":[[6.8,8.96]],"id":9480385}],"con":true,"img":false,"tv":86918.81}]}
{"op":"mcm","clk":"1150066135","pt":1439927714864,"mc":[{"id":"1.120089104","rc":[{"atb":[[2.1,7]],"id":9480385}],"con":true,"img":false,"tv":86918.81}]}
{"op":"mcm","clk":"1150066158","pt":1439927715059,"mc":[{"id":"1.120089104","rc":[{"trd":[[1.17,26313.62]],"ltp":1.17,"tv":26313.62,"id":9612932},{"atl":[[1.17,1560.12]],"id":9612932}],"con":true,"img":false,"tv":86924.81}]}
{"op":"mcm","clk":"1150066171","pt":1439927715168,"mc":[{"id":"1.120089104","rc":[{"atl":[[1.17,2671.12]],"id":9612932}],"con":true,"img":false,"tv":86924.81}]}
{"op":"mcm","clk":"1150066208","pt":1439927715352,"mc":[{"id":"1.120089104","rc":[{"atb":[[6.8,54.27]],"id":9480385}],"con":true,"img":false,"tv":86924.81}]}
{"op":"mcm","clk":"1150066229","pt":1439927715554,"mc":[{"id":"1.120089104","rc":[{"atl":[[7,198.75]],"id":9480385}],"con":true,"img":false,"tv":86924.81}]}
{"op":"mcm","clk":"1150066246","pt":1439927715665,"mc":[{"id":"1.120089104","rc":[{"trd":[[6.8,926.31]],"ltp":6.8,"tv":926.31,"id":9480385},{"atb":[[6.8,52.27],[6.6,86.46]],"id":9480385}],"con":true,"img":false,"tv":86928.81}]}
{"op":"mcm","clk":"1150066503","pt":1439927717867,"mc":[{"id":"1.120089104","rc":[{"atl":[[1.18,2312.26]],"id":9612932}],"con":true,"img":false,"tv":86928.81}]}
{"op":"mcm","clk":"1150066608","pt":1439927718816,"mc":[{"id":"1.120089104","rc":[{"trd":[[6.8,933.77]],"ltp":6.8,"tv":933.77,"id":9480385},{"atb":[[6.8,48.54]],"id":9480385}],"con":true,"img":false,"tv":86936.27}]}
{"op":"mcm","clk":"1150066660","pt":1439927719237,"mc":[{"id":"1.120089104","rc":[{"trd":[[6.8,936.59]],"ltp":6.8,"tv":936.59,"id":9480385},{"atb":[[6.8,47.13]],"id":9480385}],"con":true,"img":false,"tv":86939.09}]}
{"op":"mcm","clk":"1150066675","pt":1439927719421,"mc":[{"id":"1.120089104","rc":[{"atb":[[1.16,5337.97]],"id":9612932}],"con":true,"img":false,"tv":86939.09}]}
{"op":"mcm","clk":"1150066812","pt":1439927720445,"mc":[{"id":"1.120089104","rc":[{"atb":[[1.16,7559.97]],"id":9612932}],"con":true,"img":false,"tv":86939.09}]}
{"op":"mcm","clk":"1150066817","pt":1439927720477,"mc":[{"id":"1.120089104","rc":[{"trd":[[1.17,26373.62]],"ltp":1.17,"tv":26373.62,"id":9612932},{"atl":[[1.17,2641.12]],"id":9612932}],"con":true,"img":false,"tv":86999.09}]}
{"op":"mcm","clk":"1150066846","pt":1439927720694,"mc":[{"id":"1.120089104","rc":[{"trd":[[1.17,26393.8]],"ltp":1.17,"tv":26393.8,"id":9612932},{"atl":[[1.17,2631.03]],"id":9612932}],"con":true,"img":false,"tv":87019.27}]}
{"op":"mcm","clk":"1150066861","pt":1439927720845,"mc":[{"id":"1.120089104","rc":[{"trd":[[1.17,26417.8]],"ltp":1.17,"tv":26417.8,"id":9612932},{"atl":[[1.17,2619.03]],"id":9612932}],"con":true,"img":false,"tv":87043.27}]}
{"op":"mcm","clk":"1150066877","pt":1439927721024,"mc":[{"id":"1.120089104","rc":[{"atl":[[8.4,12]],"id":9480385}],"con":true,"img":false,"tv":87043.27}]}
{"op":"mcm","clk":"1150066899","pt":1439927721296,"mc":[{"id":"1.120089104","rc":[{"trd":[[1.17,26458.15]],"ltp":1.17,"tv":26458.15,"id":9612932},{"atl":[[1.17,2598.85]],"id":9612932}],"con":true,"img":false,"tv":87083.61}]}
{"op":"mcm","clk":"1150066940","pt":1439927721530,"mc":[{"id":"1.120089104","rc":[{"atb":[[1.12,19177.65]],"id":9612932}],"con":true,"img":false,"tv":87083.61}]}
{"op":"mcm","clk":"1150067093","pt":1439927722681,"mc":[{"id":"1.120089104","rc":[{"trd":[[1.17,26462.15]],"ltp":1.17,"tv":26462.15,"id":9612932},{"atl":[[1.17,2596.85]],"id":9612932}],"con":true,"img":false,"tv":87087.61}]}
{"op":"mcm","clk":"1150067216","pt":1439927723926,"mc":[{"id":"1.120089104","rc":[{"trd":[[1.16,35432.52]],"ltp":1.16,"tv":35432.52,"id":9612932},{"atb":[[1.16,7409.97],[1.02,10279.89]],"id":9612932}],"con":true,"img":false,"tv":87387.61}]}
{"op":"mcm","clk":"1150067253","pt":1439927724310,"mc":[{"id":"1.120089104","rc":[{"trd":[[6.8,940.59]],"ltp":6.8,"tv":940.59,"id":9480385},{"atb":[[6.8,45.13]],"id":9480385}],"con":true,"img":false,"tv":87391.62}]}
{"op":"mcm","clk":"1150067325","pt":1439927724888,"mc":[{"id":"1.120089104","rc":[{"atb":[[6.8,156.13]],"id":9480385}],"con":true,"img":false,"tv":87391.62}]}
{"op":"mcm","clk":"1150067330","pt":1439927724974,"mc":[{"id":"1.120089104","rc":[{"atl":[[1.18,2318.33]],"id":9612932}],"con":true,"img":false,"tv":87391.62}]}
{"op":"mcm","clk":"1150067361","pt":1439927725142,"mc":[{"id":"1.120089104","rc":[{"trd":[[1.16,35464.52]],"ltp":1.16,"tv":35464.52,"id":9612932},{"atb":[[1.16,7393.97]],"id":9612932},{"atl":[[1.18,3022.95]],"id":9612932}],"con":true,"img":false,"tv":87423.62}]}
{"op":"mcm","clk":"1150067377","pt":1439927725253,"mc":[{"id":"1.120089104","rc":[{"trd":[[6.8,1050.59],[7,816.59]],"ltp":6.8,"tv":1867.17,"id":9480385},{"atb":[[6.8,101.13]],"id":9480385},{"atl":[[7,136.14]],"id":9480385}],"con":true,"img":false,"tv":87658.84}]}
{"op":"mcm","clk":"1150067420","pt":1439927725552,"mc":[{"id":"1.120089104","rc":[{"atl":[[80,0]],"id":9612932},{"atl":[[80,0],[7,133.34]],"id":9480385}],"con":true,"img":false,"tv":87658.84}]}
{"op":"mcm","clk":"1150067425","pt":1439927725640,"mc":[{"id":"1.120089104","rc":[{"trd":[[6.8,1056.19]],"ltp":6.8,"tv":1056.19,"id":9480385},{"atb":[[6.8,98.33]],"id":9480385}],"con":true,"img":false,"tv":87664.44}]}
{"op":"mcm","clk":"1150067579","pt":1439927726791,"mc":[{"id":"1.120089104","rc":[{"trd":[[6.8,1066.19]],"ltp":6.8,"tv":1066.19,"id":9480385},{"atb":[[6.8,93.33]],"id":9480385}],"con":true,"img":false,"tv":87674.44}]}
{"op":"mcm","clk":"1150067595","pt":1439927726848,"mc":[{"id":"1.120089104","rc":[{"trd":[[1.17,26506.15]],"ltp":1.17,"tv":26506.15,"id":9612932},{"atl":[[1.17,2574.85]],"id":9612932}],"con":true,"img":false,"tv":87718.44}]}
{"op":"mcm","clk":"1150067617","pt":1439927727068,"mc":[{"id":"1.120089104","rc":[{"trd":[[1.17,26626.14]],"ltp":1.17,"tv":26626.14,"id":9612932},{"atl":[[1.17,2514.86]],"id":9612932}],"con":true,"img":false,"tv":87838.44}]}
{"op":"mcm","clk":"1150067640","pt":1439927727311,"mc":[{"id":"1.120089104","rc":[{"trd":[[6.8,1072.19]],"ltp":6.8,"tv":1072.19,"id":9480385},{"atb":[[6.8,90.33]],"id":9480385}],"con":true,"img":false,"tv":87844.44}]}
{"op":"mcm","clk":"1150067736","pt":1439927728076,"mc":[{"id":"1.120089104","rc":[{"trd":[[1.16,35662.52]],"ltp":1.16,"tv":35662.52,"id":9612932},{"atb":[[1.16,7294.97]],"id":9612932}],"con":true,"img":false,"tv":88042.44}]}
{"op":"mcm","clk":"1150067805","pt":1439927728718,"mc":[{"id":"1.120089104","rc":[{"atl":[[7,131.34]],"id":9480385}],"con":true,"img":false,"tv":88042.44}]}
{"op":"mcm","clk":"1150067935","pt":1439927729778,"mc":[{"id":"1.120089104","rc":[{"atb":[[6.6,197.46]],"id":9480385}],"con":true,"img":false,"tv":88042.44}]}
{"op":"mcm","clk":"1150068282","pt":1439927732744,"mc":[{"id":"1.120089104","rc":[{"trd":[[1.17,26628.96]],"ltp":1.17,"tv":26628.96,"id":9612932},{"atl":[[1.17,2513.45]],"id":9612932}],"con":true,"img":false,"tv":88045.26}]}
{"op":"mcm","clk":"1150068343","pt":1439927733236,"mc":[{"id":"1.120089104","rc":[{"trd":[[6.8,1112.19]],"ltp":6.8,"tv":1112.19,"id":9480385},{"atb":[[6.8,70.33]],"id":9480385}],"con":true,"img":false,"tv":88085.26}]}
{"op":"mcm","clk":"1150068377","pt":1439927733511,"mc":[{"id":"1.120089104","rc":[{"atl":[[7,126.34]],"id":9480385}],"con":true,"img":false,"tv":88085.26}]}
{"op":"mcm","clk":"1150068388","pt":1439927733649,"mc":[{"id":"1.120089104","rc":[{"trd":[[6.8,1122.19]],"ltp":6.8,"tv":1122.19,"id":9480385},{"atb":[[6.8,65.33]],"id":9480385}],"con":true,"img":false,"tv":88095.26}]}
{"op":"mcm","clk":"1150068404","pt":1439927733758,"mc":[{"id":"1.120089104","rc":[{"trd":[[1.17,26634.08]],"ltp":1.17,"tv":26634.08,"id":9612932},{"atl":[[1.17,2510.89]],"id":9612932}],"con":true,"img":false,"tv":88100.37}]}
{"op":"mcm","clk":"1150068412","pt":1439927733842,"mc":[{"id":"1.120089104","rc":[{"trd":[[1.17,26636.89]],"ltp":1.17,"tv":26636.89,"id":9612932},{"atl":[[1.17,2509.48]],"id":9612932}],"con":true,"img":false,"tv":88103.19}]}
{"op":"mcm","clk":"1150068590","pt":1439927735232,"mc":[{"id":"1.120089104","rc":[{"trd":[[1.17,26639.71]],"ltp":1.17,"tv":26639.71,"id":9612932},{"atl":[[1.17,2508.07]],"id":9612932}],"con":true,"img":false,"tv":88106.01}]}
{"op":"mcm","clk":"1150068663","pt":1439927735763,"mc":[{"id":"1.120089104","rc":[{"atb":[[6.6,215.07]],"id":9480385}],"con":true,"img":false,"tv":88106.01}]}
{"op":"mcm","clk":"1150068712","pt":1439927736120,"mc":[{"id":"1.120089104","rc":[{"trd":[[1.17,26642.53]],"ltp":1.17,"tv":26642.53,"id":9612932},{"atl":[[1.17,2506.66]],"id":9612932}],"con":true,"img":false,"tv":88108.83}]}
{"op":"mcm","clk":"1150068731","pt":1439927736342,"mc":[{"id":"1.120089104","rc":[{"trd":[[1.17,26742.53]],"ltp":1.17,"tv":26742.53,"id":9612932},{"atl":[[1.17,2456.66]],"id":9612932}],"con":true,"img":false,"tv":88208.83}]}
{"op":"mcm","clk":"1150068764","pt":1439927736563,"mc":[{"id":"1.120089104","rc":[{"trd":[[1.17,27253.28]],"ltp":1.17,"tv":27253.28,"id":9612932},{"atl":[[1.17,1945.91]],"id":9612932},{"trd":[[6.8,1340.73]],"ltp":6.8,"tv":1340.73,"id":9480385},{"atb":[[6.8,0]],"id":9480385}],"con":true,"img":false,"tv":88938.12}]}
{"op":"mcm","clk":"1150068806","pt":1439927736836,"mc":[{"id":"1.120089104","rc":[{"trd":[[1.17,27256.1]],"ltp":1.17,"tv":27256.1,"id":9612932},{"atl":[[1.17,1944.5]],"id":9612932}],"con":true,"img":false,"tv":88940.94}]}
{"op":"mcm","clk":"1150068844","pt":1439927737119,"mc":[{"id":"1.120089104","rc":[{"atb":[[6.6,261.85]],"id":9480385}],"con":true,"img":false,"tv":88940.94}]}
{"op":"mcm","clk":"1150068905","pt":1439927737667,"mc":[{"id":"1.120089104","rc":[{"trd":[[1.17,27267.73]],"ltp":1.17,"tv":27267.73,"id":9612932},{"atl":[[1.17,1932.87]],"id":9612932},{"trd":[[6.8,1342.73]],"ltp":6.8,"tv":1342.73,"id":9480385}],"con":true,"img":false,"tv":88954.56}]}
{"op":"mcm","clk":"1150068917","pt":1439927737728,"mc":[{"id":"1.120089104","rc":[{"trd":[[1.17,27270.55]],"ltp":1.17,"tv":27270.55,"id":9612932},{"atl":[[1.17,1931.46]],"id":9612932}],"con":true,"img":false,"tv":88957.38}]}
{"op":"mcm","clk":"1150069025","pt":1439927738786,"mc":[{"id":"1.120089104","rc":[{"trd":[[1.17,27273.37]],"ltp":1.17,"tv":27273.37,"id":9612932},{"atl":[[1.17,1930.05]],"id":9612932}],"con":true,"img":false,"tv":88960.2}]}
{"op":"mcm","clk":"1150069112","pt":1439927739637,"mc":[{"id":"1.120089104","rc":[{"trd":[[1.17,27276.18]],"ltp":1.17,"tv":27276.18,"id":9612932},{"atl":[[1.17,1928.65]],"id":9612932}],"con":true,"img":false,"tv":88963.02}]}
{"op":"mcm","clk":"1150069123","pt":1439927739747,"mc":[{"id":"1.120089104","rc":[{"trd":[[1.17,27283.23]],"ltp":1.17,"tv":27283.23,"id":9612932},{"atl":[[1.17,1925.12]],"id":9612932}],"con":true,"img":false,"tv":88970.07}]}
{"op":"mcm","clk":"1150069150","pt":1439927739996,"mc":[{"id":"1.120089104","rc":[{"trd":[[1.17,27294.86]],"ltp":1.17,"tv":27294.86,"id":9612932},{"atl":[[1.17,1913.5]],"id":9612932},{"trd":[[6.8,1344.73]],"ltp":6.8,"tv":1344.73,"id":9480385}],"con":true,"img":false,"tv":88983.69}]}
{"op":"mcm","clk":"1150069171","pt":1439927740132,"mc":[{"id":"1.120089104","rc":[{"trd":[[1.16,35915.86]],"ltp":1.16,"tv":35915.86,"id":9612932},{"atb":[[1.16,7168.3]],"id":9612932}],"con":true,"img":false,"tv":89237.03}]}
{"op":"mcm","clk":"1150069183","pt":1439927740258,"mc":[{"id":"1.120089104","rc":[{"trd":[[1.17,27297.68]],"ltp":1.17,"tv":27297.68,"id":9612932},{"atl":[[1.17,1912.09]],"id":9612932}],"con":true,"img":false,"tv":89239.85}]}
{"op":"mcm","clk":"1150069248","pt":1439927741071,"mc":[{"id":"1.120089104","rc":[{"trd":[[1.17,27300.49]],"ltp":1.17,"tv":27300.49,"id":9612932},{"atl":[[1.17,1910.68]],"id":9612932}],"con":true,"img":false,"tv":89242.67}]}
{"op":"mcm","clk":"1150069263","pt":1439927741182,"mc":[{"id":"1.120089104","rc":[{"atb":[[6.6,279.47]],"id":9480385}],"con":true,"img":false,"tv":89242.67}]}
{"op":"mcm","clk":"1150069511","pt":1439927743495,"mc":[{"id":"1.120089104","rc":[{"atb":[[5.8,8.13]],"id":9480385},{"atl":[[8.6,0]],"id":9480385},{"spn":6.6,"spf":3.47,"id":9480385}],"con":true,"img":false,"tv":89242.67}]}
{"op":"mcm","clk":"1150069515","pt":1439927743606,"mc":[{"id":"1.120089104","rc":[{"atb":[[5.7,50.41]],"id":9480385},{"atl":[[8.4,42]],"id":9480385}],"con":true,"img":false,"tv":89242.67}]}
{"op":"mcm","clk":"1150069719","pt":1439927745114,"mc":[{"id":"1.120089104","rc":[{"trd":[[1.17,27305.61]],"ltp":1.17,"tv":27305.61,"id":9612932},{"atl":[[1.17,1908.12]],"id":9612932}],"con":true,"img":false,"tv":89247.78}]}
{"op":"mcm","clk":"1150069727","pt":1439927745190,"mc":[{"id":"1.120089104","rc":[{"trd":[[1.17,27334.67]],"ltp":1.17,"tv":27334.67,"id":9612932},{"atl":[[1.17,1879.06]],"id":9612932},{"trd":[[6.8,1349.73]],"ltp":6.8,"tv":1349.73,"id":9480385}],"con":true,"img":false,"tv":89281.84}]}
{"op":"mcm","clk":"1150069743","pt":1439927745310,"mc":[{"id":"1.120089104","rc":[{"atb":[[1.03,52]],"id":9612932}],"con":true,"img":false,"tv":89281.84}]}
{"op":"mcm","clk":"1150069851","pt":1439927746427,"mc":[{"id":"1.120089104","rc":[{"trd":[[1.17,27346.29]],"ltp":1.17,"tv":27346.29,"id":9612932},{"atb":[[1.16,7872.92]],"id":9612932},{"atl":[[1.17,1867.43]],"id":9612932},{"trd":[[6.8,1351.73]],"ltp":6.8,"tv":1351.73,"id":9480385}],"con":true,"img":false,"tv":89336.34}]}
{"op":"mcm","clk":"1150069913","pt":1439927747112,"mc":[{"id":"1.120089104","rc":[{"trd":[[1.17,27381.16]],"ltp":1.17,"tv":27381.16,"id":9612932},{"atl":[[1.17,1832.56]],"id":9612932},{"trd":[[6.8,1357.73]],"ltp":6.8,"tv":1357.73,"id":9480385}],"con":true,"img":false,"tv":89336.34}]}
{"op":"mcm","clk":"1150070074","pt":1439927748511,"mc":[{"id":"1.120089104","rc":[{"trd":[[1.17,27385.16]],"ltp":1.17,"tv":27385.16,"id":9612932},{"atl":[[1.17,1830.56]],"id":9612932}],"con":true,"img":false,"tv":89340.34}]}
{"op":"mcm","clk":"1150070076","pt":1439927748669,"mc":[{"id":"1.120089104","rc":[{"trd":[[1.17,27396.79]],"ltp":1.17,"tv":27396.79,"id":9612932},{"atl":[[1.17,1818.94]],"id":9612932},{"trd":[[6.8,1359.73]],"ltp":6.8,"tv":1359.73,"id":9480385}],"con":true,"img":false,"tv":89353.97}]}
{"op":"mcm","clk":"1150070350","pt":1439927751248,"mc":[{"id":"1.120089104","rc":[{"trd":[[1.16,36758.56]],"ltp":1.16,"tv":36758.56,"id":9612932},{"atb":[[1.16,7451.58]],"id":9612932}],"con":true,"img":false,"tv":90196.66}]}
{"op":"mcm","clk":"1150070423","pt":1439927751885,"mc":[{"id":"1.120089104","rc":[{"trd":[[1.16,36762.56]],"ltp":1.16,"tv":36762.56,"id":9612932},{"atb":[[1.16,7449.58]],"id":9612932},{"atb":[[6.8,70.46]],"id":9480385}],"con":true,"img":false,"tv":90200.66}]}
{"op":"mcm","clk":"1150070535","pt":1439927753164,"mc":[{"id":"1.120089104","rc":[{"atb":[[6.8,80.46]],"id":9480385}],"con":true,"img":false,"tv":90200.66}]}
{"op":"mcm","clk":"1150070662","pt":1439927754327,"mc":[{"id":"1.120089104","rc":[{"atl":[[1.17,1900.73]],"id":9612932}],"con":true,"img":false,"tv":90200.66}]}
{"op":"mcm","clk":"1150070884","pt":1439927756312,"mc":[{"id":"1.120089104","rc":[{"atb":[[6.6,349.93]],"id":9480385}],"con":true,"img":false,"tv":90200.66}]}
{"op":"mcm","clk":"1150070907","pt":1439927756529,"mc":[{"id":"1.120089104","rc":[{"atb":[[1.15,16973.44]],"id":9612932}],"con":true,"img":false,"tv":90200.66}]}
{"op":"mcm","clk":"1150070937","pt":1439927756747,"mc":[{"id":"1.120089104","rc":[{"atb":[[6.6,420.39]],"id":9480385}],"con":true,"img":false,"tv":90200.66}]}
{"op":"mcm","clk":"1150070951","pt":1439927756854,"mc":[{"id":"1.120089104","rc":[{"atl":[[8,38.15]],"id":9480385}],"con":true,"img":false,"tv":90200.66}]}
{"op":"mcm","clk":"1150070964","pt":1439927756940,"mc":[{"id":"1.120089104","rc":[{"atl":[[1000,9]],"id":9612932},{"atb":[[6.8,86.25],[1.01,2575.93]],"id":9480385}],"con":true,"img":false,"tv":90200.66}]}
{"op":"mcm","clk":"1150070973","pt":1439927757018,"mc":[{"id":"1.120089104","rc":[{"atl":[[1000,13.46]],"id":9612932},{"atb":[[1.01,2577.48]],"id":9480385},{"atl":[[8,41.15]],"id":9480385}],"con":true,"img":false,"tv":90200.66}]}
{"op":"mcm","clk":"1150070985","pt":1439927757168,"mc":[{"id":"1.120089104","rc":[{"atl":[[1000,5.46]],"id":9612932},{"atb":[[1.01,2573.48]],"id":9480385},{"atl":[[7,141.34]],"id":9480385}],"con":true,"img":false,"tv":90200.66}]}
{"op":"mcm","clk":"1150070998","pt":1439927757235,"mc":[{"id":"1.120089104","rc":[{"atl":[[1000,1]],"id":9612932},{"atb":[[1.01,2571.93]],"id":9480385}],"con":true,"img":false,"tv":90200.66}]}
