{"op":"mcm","clk":"1147321965","pt":1439878764892,"mc":[{"id":"1.120089104","marketDefinition":{"bspMarket":true,"turnInPlayEnabled":true,"persistenceEnabled":true,"marketBaseRate":5.0,"eventId":"27514783","eventTypeId":"7","numberOfWinners":1,"bettingType":"ODDS","marketType":"WIN","marketTime":"2015-08-18T20:20:00.000Z","suspendTime":"2015-08-18T20:20:00.000Z","bspReconciled":false,"complete":true,"inPlay":false,"crossMatching":false,"runnersVoidable":false,"numberOfActiveRunners":2,"betDelay":0,"status":"OPEN","runners":[{"adjustmentFactor":79.72,"status":"ACTIVE","sortPriority":1,"id":9612932,"name":"Alinstante"},{"adjustmentFactor":20.27,"status":"ACTIVE","sortPriority":2,"id":9480385,"name":"Vallance Road"}],"regulators":["MR_INT"],"venue":"Chelmsford City","countryCode":"GB","discountAllowed":false,"timezone":"Europe/London","openDate":"2015-08-18T17:20:00.000Z","version":1060767560,"name":"1m Cond Stks","eventName":"ChelmC 18th Aug"},"rc":[{"trd":[[1.3,209.87],[1.23,19.77],[1.29,43.77],[1.22,41.99],[1.24,3.95],[1.2,14.88],[1.4,49.38],[1.19,29.49],[1.28,999.46],[1.27,15.77],[1.25,1.76],[1.26,67.27],[1.21,51.3]],"ltp":1.3,"tv":1548.66,"id":9612932},{"atb":[[1.17,628.49],[1.16,22.9],[1.04,240],[1.06,20],[1.18,46.01],[1.14,400],[1.01,1752.01],[1.13,25],[1.25,5.99],[1.15,110.73],[1.02,16071.99],[1.12,420],[1.1,400],[1.08,10],[1.24,7.76],[1.2,1.77]],"id":9612932},{"atl":[[1.29,97],[1.3,95.06],[1.69,15],[46,2],[19.5,11],[630,0.09],[1.4,500],[1000,1],[4,0.25]],"id":9612932},{"spl":[[1.01,38.95]],"id":9612932},{"spn":1.2,"spf":1.0,"id":9612932},{"trd":[[4.7,11.99],[4.9,11.99],[5.2,14.84],[5.4,0.17],[5.1,12.11],[4.8,120.21],[5.6,16.37],[5.3,1.75],[5.5,13.26],[5,16.43]],"ltp":4.7,"tv":219.12,"id":9480385},{"atb":[[4.4,60],[2.62,1.41],[2.6,1.9],[1.06,20],[1.18,30],[3.75,15],[1.81,12.35],[2.28,37],[1.01,1728.01],[1.02,10251.99],[2.16,30],[1.08,10],[2.22,12.06],[4.5,6],[2.92,175],[4.6,60.11]],"id":9480385},{"atl":[[5.9,2.59],[630,0.09],[10,5.34],[5.8,0.08],[5.2,8.97],[6,0.07],[46,2],[6.6,0.06],[55,0.01],[90,2],[11.5,0.83],[10.5,15],[7.2,0.1],[5.6,0.08]],"id":9480385},{"spn":4.9,"spf":"NaN","id":9480385}],"con":true,"img":true,"tv":1767.9}]}
{"op":"mcm","clk":"1147329704","pt":1439878966222,"mc":[{"id":"1.120089104","rc":[{"atb":[[1.25,7.4]],"id":9612932},{"spn":1.2,"spf":1.0,"id":9612932}],"con":true,"img":false,"tv":1767.9}]}
{"op":"mcm","clk":"1147330804","pt":1439879057567,"mc":[{"id":"1.120089104","rc":[{"trd":[[5.2,25.64]],"ltp":5.2,"tv":25.64,"id":9480385},{"atl":[[5.2,3.58]],"id":9480385}],"con":true,"img":false,"tv":1778.7}]}
{"op":"mcm","clk":"1147330824","pt":1439879058923,"mc":[{"id":"1.120089104","rc":[{"atb":[[1.01,1729.43]],"id":9480385}],"con":true,"img":false,"tv":1778.7}]}
{"op":"mcm","clk":"1147330834","pt":1439879059656,"mc":[{"id":"1.120089104","rc":[{"atb":[[1.01,1728.12]],"id":9480385}],"con":true,"img":false,"tv":1778.7}]}
{"op":"mcm","clk":"1147330837","pt":1439879059761,"mc":[{"id":"1.120089104","rc":[{"atb":[[1.01,1728.01]],"id":9480385}],"con":true,"img":false,"tv":1778.7}]}
{"op":"mcm","clk":"1147330839","pt":1439879059865,"mc":[{"id":"1.120089104","rc":[{"atb":[[4.7,0.1]],"id":9480385}],"con":true,"img":false,"tv":1778.7}]}
{"op":"mcm","clk":"1147330992","pt":1439879071236,"mc":[{"id":"1.120089104","rc":[{"atl":[[5.2,0.7]],"id":9480385}],"con":true,"img":false,"tv":1778.7}]}
{"op":"mcm","clk":"1147331017","pt":1439879073647,"mc":[{"id":"1.120089104","rc":[{"atl":[[5.2,0]],"id":9480385}],"con":true,"img":false,"tv":1778.7}]}
{"op":"mcm","clk":"1147331018","pt":1439879073753,"mc":[{"id":"1.120089104","rc":[{"atl":[[5.5,0.7]],"id":9480385}],"con":true,"img":false,"tv":1778.7}]}
{"op":"mcm","clk":"1147331081","pt":1439879078206,"mc":[{"id":"1.120089104","rc":[{"atl":[[5.4,2]],"id":9480385}],"con":true,"img":false,"tv":1778.7}]}
{"op":"mcm","clk":"1147331137","pt":1439879081743,"mc":[{"id":"1.120089104","rc":[{"atl":[[5.3,6.7]],"id":9480385}],"con":true,"img":false,"tv":1778.7}]}
{"op":"mcm","clk":"1147331139","pt":1439879081848,"mc":[{"id":"1.120089104","rc":[{"atl":[[5.5,0]],"id":9480385}],"con":true,"img":false,"tv":1778.7}]}
{"op":"mcm","clk":"1147331265","pt":1439879089690,"mc":[{"id":"1.120089104","rc":[{"atl":[[5.3,9.53]],"id":9480385}],"con":true,"img":false,"tv":1778.7}]}
{"op":"mcm","clk":"1147331493","pt":1439879106526,"mc":[{"id":"1.120089104","rc":[{"atl":[[5.4,0]],"id":9480385}],"con":true,"img":false,"tv":1778.7}]}
{"op":"mcm","clk":"1147331780","pt":1439879127795,"mc":[{"id":"1.120089104","rc":[{"trd":[[1.24,17.52],[1.25,16.57]],"ltp":1.24,"tv":34.09,"id":9612932},{"atb":[[1.25,0],[1.24,0.98]],"id":9612932},{"spn":1.18,"spf":1.0,"id":9612932},{"spn":5.0,"spf":"NaN","id":9480385}],"con":true,"img":false,"tv":1807.08}]}
{"op":"mcm","clk":"1147331788","pt":1439879128106,"mc":[{"id":"1.120089104","rc":[{"atb":[[1.2,4.77]],"id":9612932}],"con":true,"img":false,"tv":1807.08}]}
{"op":"mcm","clk":"1147331883","pt":1439879134319,"mc":[{"id":"1.120089104","rc":[{"trd":[[5.3,15.25]],"ltp":5.3,"tv":15.25,"id":9480385},{"atl":[[5.3,2.78]],"id":9480385}],"con":true,"img":false,"tv":1820.58}]}
{"op":"mcm","clk":"1147331893","pt":1439879134895,"mc":[{"id":"1.120089104","rc":[{"atb":[[4.7,2.08]],"id":9480385}],"con":true,"img":false,"tv":1820.58}]}
{"op":"mcm","clk":"1147331896","pt":1439879134999,"mc":[{"id":"1.120089104","rc":[{"atb":[[1.17,584.39]],"id":9612932}],"con":true,"img":false,"tv":1820.58}]}
{"op":"mcm","clk":"1147331898","pt":1439879135105,"mc":[{"id":"1.120089104","rc":[{"atb":[[1.21,44.1]],"id":9612932}],"con":true,"img":false,"tv":1820.58}]}
{"op":"mcm","clk":"1147331936","pt":1439879137140,"mc":[{"id":"1.120089104","rc":[{"atb":[[1.01,1730.58]],"id":9480385}],"con":true,"img":false,"tv":1820.58}]}
{"op":"mcm","clk":"1147331945","pt":1439879137767,"mc":[{"id":"1.120089104","rc":[{"atb":[[1.01,1729.8]],"id":9480385}],"con":true,"img":false,"tv":1820.58}]}
{"op":"mcm","clk":"1147331953","pt":1439879138183,"mc":[{"id":"1.120089104","rc":[{"atb":[[1.01,1728.01]],"id":9480385}],"con":true,"img":false,"tv":1820.58}]}
{"op":"mcm","clk":"1147331954","pt":1439879138235,"mc":[{"id":"1.120089104","rc":[{"atb":[[4.7,3.87]],"id":9480385}],"con":true,"img":false,"tv":1820.58}]}
{"op":"mcm","clk":"1147332108","pt":1439879148279,"mc":[{"id":"1.120089104","rc":[{"atb":[[1.2,1.77]],"id":9612932},{"atl":[[5.3,0]],"id":9480385}],"con":true,"img":false,"tv":1820.58}]}
{"op":"mcm","clk":"1147332300","pt":1439879161429,"mc":[{"id":"1.120089104","rc":[{"atl":[[5.5,2]],"id":9480385}],"con":true,"img":false,"tv":1820.58}]}
{"op":"mcm","clk":"1147332351","pt":1439879166652,"mc":[{"id":"1.120089104","rc":[{"atl":[[5.9,0]],"id":9480385}],"con":true,"img":false,"tv":1820.58}]}
{"op":"mcm","clk":"1147332354","pt":1439879166758,"mc":[{"id":"1.120089104","rc":[{"atl":[[5.5,4.78]],"id":9480385}],"con":true,"img":false,"tv":1820.58}]}
{"op":"mcm","clk":"1147332361","pt":1439879167276,"mc":[{"id":"1.120089104","rc":[{"atl":[[5.5,7.46]],"id":9480385}],"con":true,"img":false,"tv":1820.58}]}
{"op":"mcm","clk":"1147332608","pt":1439879186564,"mc":[{"id":"1.120089104","rc":[{"atb":[[1.21,47.1]],"id":9612932}],"con":true,"img":false,"tv":1820.58}]}
{"op":"mcm","clk":"1147332717","pt":1439879194741,"mc":[{"id":"1.120089104","rc":[{"atb":[[1.22,1.41]],"id":9612932},{"spn":1.21,"spf":1.0,"id":9612932},{"spn":5.1,"spf":"NaN","id":9480385}],"con":true,"img":false,"tv":1820.58}]}
{"op":"mcm","clk":"1147332872","pt":1439879205699,"mc":[{"id":"1.120089104","rc":[{"atb":[[1.21,44.1]],"id":9612932}],"con":true,"img":false,"tv":1820.58}]}
{"op":"mcm","clk":"1147333391","pt":1439879242599,"mc":[{"id":"1.120089104","rc":[{"atb":[[1.17,0]],"id":9612932}],"con":true,"img":false,"tv":1820.58}]}
{"op":"mcm","clk":"1147333395","pt":1439879242807,"mc":[{"id":"1.120089104","rc":[{"atb":[[1.14,1109.62]],"id":9612932}],"con":true,"img":false,"tv":1820.58}]}
{"op":"mcm","clk":"1147333673","pt":1439879257875,"mc":[{"id":"1.120089104","rc":[{"trd":[[1.29,101.83]],"ltp":1.29,"tv":101.83,"id":9612932},{"atl":[[1.29,67.97]],"id":9612932}],"con":true,"img":false,"tv":1878.64}]}
{"op":"mcm","clk":"1147336774","pt":1439879498241,"mc":[{"id":"1.120089104","rc":[{"trd":[[4.7,19.75]],"ltp":4.7,"tv":19.75,"id":9480385},{"atb":[[4.7,0]],"id":9480385},{"spn":5.05,"spf":"NaN","id":9480385}],"con":true,"img":false,"tv":1886.39}]}
{"op":"mcm","clk":"1147336793","pt":1439879500371,"mc":[{"id":"1.120089104","rc":[{"atl":[[1000,1.41]],"id":9480385}],"con":true,"img":false,"tv":1886.39}]}
{"op":"mcm","clk":"1147336803","pt":1439879501256,"mc":[{"id":"1.120089104","rc":[{"atl":[[1000,0.09]],"id":9480385}],"con":true,"img":false,"tv":1886.39}]}
{"op":"mcm","clk":"1147336805","pt":1439879501360,"mc":[{"id":"1.120089104","rc":[{"atl":[[1000,0]],"id":9480385}],"con":true,"img":false,"tv":1886.39}]}
{"op":"mcm","clk":"1147336807","pt":1439879501464,"mc":[{"id":"1.120089104","rc":[{"atl":[[5.4,0.09]],"id":9480385}],"con":true,"img":false,"tv":1886.39}]}
{"op":"mcm","clk":"1147336935","pt":1439879515326,"mc":[{"id":"1.120089104","rc":[{"atl":[[5.5,5.46]],"id":9480385}],"con":true,"img":false,"tv":1886.39}]}
{"op":"mcm","clk":"1147336936","pt":1439879515430,"mc":[{"id":"1.120089104","rc":[{"atl":[[5.3,2]],"id":9480385}],"con":true,"img":false,"tv":1886.39}]}
{"op":"mcm","clk":"1147336987","pt":1439879519186,"mc":[{"id":"1.120089104","rc":[{"atb":[[4.7,1.97]],"id":9480385}],"con":true,"img":false,"tv":1886.39}]}
{"op":"mcm","clk":"1147337099","pt":1439879527640,"mc":[{"id":"1.120089104","rc":[{"atl":[[5.5,2.68]],"id":9480385}],"con":true,"img":false,"tv":1886.39}]}
{"op":"mcm","clk":"1147337100","pt":1439879527797,"mc":[{"id":"1.120089104","rc":[{"atl":[[5.3,4.89]],"id":9480385}],"con":true,"img":false,"tv":1886.39}]}
{"op":"mcm","clk":"1147337160","pt":1439879531486,"mc":[{"id":"1.120089104","rc":[{"atl":[[5.5,0]],"id":9480385}],"con":true,"img":false,"tv":1886.39}]}
{"op":"mcm","clk":"1147337381","pt":1439879550878,"mc":[{"id":"1.120089104","rc":[{"atl":[[5.3,7.67]],"id":9480385}],"con":true,"img":false,"tv":1886.39}]}
{"op":"mcm","clk":"1147337551","pt":1439879565217,"mc":[{"id":"1.120089104","rc":[{"atl":[[5.3,5.67]],"id":9480385},{"spn":5.0,"spf":"NaN","id":9480385}],"con":true,"img":false,"tv":1886.39}]}
{"op":"mcm","clk":"1147347200","pt":1439879701926,"mc":[{"id":"1.120089104","rc":[{"atb":[[4.7,41.97]],"id":9480385}],"con":true,"img":false,"tv":1886.39}]}
{"op":"mcm","clk":"1147350114","pt":1439879897404,"mc":[{"id":"1.120089104","rc":[{"atl":[[1.27,2]],"id":9612932}],"con":true,"img":false,"tv":1886.39}]}
{"op":"mcm","clk":"1147353792","pt":1439880146049,"mc":[{"id":"1.120089104","rc":[{"trd":[[1.22,44.03],[1.24,19.49]],"ltp":1.22,"tv":63.51,"id":9612932},{"atb":[[1.22,0.39],[1.24,0]],"id":9612932},{"spn":1.21,"spf":1.0,"id":9612932}],"con":true,"img":false,"tv":1890.4}]}
{"op":"mcm","clk":"1147353815","pt":1439880147347,"mc":[{"id":"1.120089104","rc":[{"atb":[[1.01,1730.58]],"id":9480385}],"con":true,"img":false,"tv":1890.4}]}
{"op":"mcm","clk":"1147353824","pt":1439880147870,"mc":[{"id":"1.120089104","rc":[{"atb":[[1.01,1728.26]],"id":9480385}],"con":true,"img":false,"tv":1890.4}]}
{"op":"mcm","clk":"1147353826","pt":1439880148028,"mc":[{"id":"1.120089104","rc":[{"atb":[[1.01,1728.01]],"id":9480385}],"con":true,"img":false,"tv":1890.4}]}
{"op":"mcm","clk":"1147353828","pt":1439880148130,"mc":[{"id":"1.120089104","rc":[{"atb":[[4.8,0.25]],"id":9480385}],"con":true,"img":false,"tv":1890.4}]}
{"op":"mcm","clk":"1147354516","pt":1439880190719,"mc":[{"id":"1.120089104","rc":[{"atb":[[1.15,88.73]],"id":9612932},{"atb":[[3.75,0]],"id":9480385}],"con":true,"img":false,"tv":1890.4}]}
{"op":"mcm","clk":"1147354626","pt":1439880199797,"mc":[{"id":"1.120089104","rc":[{"atl":[[1.26,8.09]],"id":9612932}],"con":true,"img":false,"tv":1890.4}]}
{"op":"mcm","clk":"1147354890","pt":1439880218906,"mc":[{"id":"1.120089104","rc":[{"trd":[[1.26,83.45]],"ltp":1.26,"tv":83.45,"id":9612932},{"atl":[[1.26,0]],"id":9612932},{"spn":5.05,"spf":"NaN","id":9480385}],"con":true,"img":false,"tv":1906.58}]}
{"op":"mcm","clk":"1147354921","pt":1439880222237,"mc":[{"id":"1.120089104","rc":[{"atb":[[1.22,3.39]],"id":9612932}],"con":true,"img":false,"tv":1906.58}]}
{"op":"mcm","clk":"1147355654","pt":1439880276246,"mc":[{"id":"1.120089104","rc":[{"atl":[[1.26,8.09]],"id":9612932}],"con":true,"img":false,"tv":1906.58}]}
{"op":"mcm","clk":"1147355754","pt":1439880284927,"mc":[{"id":"1.120089104","rc":[{"atb":[[1.16,0]],"id":9612932},{"spn":1.21,"spf":1.0,"id":9612932}],"con":true,"img":false,"tv":1906.58}]}
{"op":"mcm","clk":"1147355756","pt":1439880285028,"mc":[{"id":"1.120089104","rc":[{"atb":[[1.23,21.59]],"id":9612932}],"con":true,"img":false,"tv":1906.58}]}
{"op":"mcm","clk":"1147357388","pt":1439880402144,"mc":[{"id":"1.120089104","rc":[{"atl":[[1.28,43.72]],"id":9612932},{"spn":1.22,"spf":1.0,"id":9612932}],"con":true,"img":false,"tv":1906.58}]}
{"op":"mcm","clk":"1147358157","pt":1439880459350,"mc":[{"id":"1.120089104","rc":[{"trd":[[4.7,103.71],[4.8,120.71]],"ltp":4.7,"tv":224.42,"id":9480385},{"atb":[[4.8,0],[4.7,0]],"id":9480385}],"con":true,"img":false,"tv":1991.04}]}
{"op":"mcm","clk":"1147358278","pt":1439880466654,"mc":[{"id":"1.120089104","rc":[{"atb":[[1.24,7.76]],"id":9612932},{"spn":1.22,"spf":1.0,"id":9612932},{"spn":4.95,"spf":"NaN","id":9480385}],"con":true,"img":false,"tv":1991.04}]}
{"op":"mcm","clk":"1147358917","pt":1439880496652,"mc":[{"id":"1.120089104","rc":[{"atb":[[3.85,34.85]],"id":9480385}],"con":true,"img":false,"tv":1991.04}]}
{"op":"mcm","clk":"1147370718","pt":1439880749401,"mc":[{"id":"1.120089104","rc":[{"atl":[[5.1,40]],"id":9480385},{"spn":4.85,"spf":"NaN","id":9480385}],"con":true,"img":false,"tv":1991.04}]}
{"op":"mcm","clk":"1147370846","pt":1439880758494,"mc":[{"id":"1.120089104","rc":[{"atl":[[5.3,2.89]],"id":9480385}],"con":true,"img":false,"tv":1991.04}]}
{"op":"mcm","clk":"1147370934","pt":1439880766098,"mc":[{"id":"1.120089104","rc":[{"atl":[[5.3,0]],"id":9480385}],"con":true,"img":false,"tv":1991.04}]}
{"op":"mcm","clk":"1147370936","pt":1439880766201,"mc":[{"id":"1.120089104","rc":[{"atl":[[5.5,2.78]],"id":9480385}],"con":true,"img":false,"tv":1991.04}]}
{"op":"mcm","clk":"1147371102","pt":1439880777669,"mc":[{"id":"1.120089104","rc":[{"atl":[[5.1,42.89]],"id":9480385}],"con":true,"img":false,"tv":1991.04}]}
{"op":"mcm","clk":"1147371765","pt":1439880827797,"mc":[{"id":"1.120089104","rc":[{"atl":[[1.27,0]],"id":9612932}],"con":true,"img":false,"tv":1995.04}]}
{"op":"mcm","clk":"1147371767","pt":1439880827901,"mc":[{"id":"1.120089104","rc":[{"trd":[[1.24,23.49]],"ltp":1.24,"tv":23.49,"id":9612932},{"atb":[[1.24,5.76]],"id":9612932}],"con":true,"img":false,"tv":1995.04}]}
{"op":"mcm","clk":"1147371887","pt":1439880836476,"mc":[{"id":"1.120089104","rc":[{"atb":[[1.01,1730.58]],"id":9480385}],"con":true,"img":false,"tv":1995.04}]}
{"op":"mcm","clk":"1147371896","pt":1439880837201,"mc":[{"id":"1.120089104","rc":[{"atb":[[1.01,1728.54]],"id":9480385}],"con":true,"img":false,"tv":1995.04}]}
{"op":"mcm","clk":"1147371904","pt":1439880837670,"mc":[{"id":"1.120089104","rc":[{"atb":[[1.01,1728.01]],"id":9480385}],"con":true,"img":false,"tv":1995.04}]}
{"op":"mcm","clk":"1147371906","pt":1439880837774,"mc":[{"id":"1.120089104","rc":[{"atb":[[4.7,0.53]],"id":9480385}],"con":true,"img":false,"tv":1995.04}]}
{"op":"mcm","clk":"1147372108","pt":1439880854392,"mc":[{"id":"1.120089104","rc":[{"atb":[[1.22,0.39]],"id":9612932}],"con":true,"img":false,"tv":1995.04}]}
{"op":"mcm","clk":"1147372168","pt":1439880858407,"mc":[{"id":"1.120089104","rc":[{"atl":[[5.5,0]],"id":9480385}],"con":true,"img":false,"tv":1995.04}]}
{"op":"mcm","clk":"1147372170","pt":1439880858512,"mc":[{"id":"1.120089104","rc":[{"atl":[[5.7,2.68]],"id":9480385}],"con":true,"img":false,"tv":1995.04}]}
{"op":"mcm","clk":"1147372378","pt":1439880873853,"mc":[{"id":"1.120089104","rc":[{"trd":[[5.1,16.77]],"ltp":5.1,"tv":16.77,"id":9480385},{"atl":[[5.1,40.56]],"id":9480385}],"con":true,"img":false,"tv":1999.7}]}
{"op":"mcm","clk":"1147373253","pt":1439880936726,"mc":[{"id":"1.120089104","rc":[{"spn":1.22,"spf":1.0,"id":9612932},{"trd":[[5.1,21.43]],"ltp":5.1,"tv":21.43,"id":9480385},{"atl":[[5.1,38.23]],"id":9480385},{"spn":4.9,"spf":"NaN","id":9480385}],"con":true,"img":false,"tv":2004.36}]}
{"op":"mcm","clk":"1147373261","pt":1439880937452,"mc":[{"id":"1.120089104","rc":[{"atb":[[1.01,1730.01]],"id":9480385}],"con":true,"img":false,"tv":2004.36}]}
{"op":"mcm","clk":"1147373263","pt":1439880937557,"mc":[{"id":"1.120089104","rc":[{"atb":[[1.01,1731.82]],"id":9480385}],"con":true,"img":false,"tv":2004.36}]}
{"op":"mcm","clk":"1147373265","pt":1439880937766,"mc":[{"id":"1.120089104","rc":[{"atb":[[1.01,1730.01]],"id":9480385}],"con":true,"img":false,"tv":2004.36}]}
{"op":"mcm","clk":"1147373267","pt":1439880937819,"mc":[{"id":"1.120089104","rc":[{"atb":[[4,1.81]],"id":9480385}],"con":true,"img":false,"tv":2004.36}]}
{"op":"mcm","clk":"1147373272","pt":1439880938236,"mc":[{"id":"1.120089104","rc":[{"atb":[[1.01,1728.01]],"id":9480385}],"con":true,"img":false,"tv":2004.36}]}
{"op":"mcm","clk":"1147373696","pt":1439880968129,"mc":[{"id":"1.120089104","rc":[{"trd":[[5.1,26.09]],"ltp":5.1,"tv":26.09,"id":9480385},{"atl":[[5.1,35.9]],"id":9480385}],"con":true,"img":false,"tv":2009.02}]}
{"op":"mcm","clk":"1147374019","pt":1439880988900,"mc":[{"id":"1.120089104","rc":[{"atl":[[5.2,15]],"id":9612932}],"con":true,"img":false,"tv":2009.02}]}
{"op":"mcm","clk":"1147374074","pt":1439880993479,"mc":[{"id":"1.120089104","rc":[{"trd":[[5.1,30.75]],"ltp":5.1,"tv":30.75,"id":9480385},{"atl":[[5.1,33.57]],"id":9480385}],"con":true,"img":false,"tv":2013.68}]}
{"op":"mcm","clk":"1147374645","pt":1439881030848,"mc":[{"id":"1.120089104","rc":[{"trd":[[5.1,35.41]],"ltp":5.1,"tv":35.41,"id":9480385},{"atl":[[5.1,31.24]],"id":9480385}],"con":true,"img":false,"tv":2018.34}]}
{"op":"mcm","clk":"1147374977","pt":1439881052229,"mc":[{"id":"1.120089104","rc":[{"trd":[[5.1,46.31]],"ltp":5.1,"tv":46.31,"id":9480385},{"atl":[[5.1,25.79]],"id":9480385}],"con":true,"img":false,"tv":2029.24}]}
{"op":"mcm","clk":"1147375638","pt":1439881094596,"mc":[{"id":"1.120089104","rc":[{"atb":[[4.7,20.53]],"id":9480385}],"con":true,"img":false,"tv":2029.24}]}
{"op":"mcm","clk":"1147375988","pt":1439881119496,"mc":[{"id":"1.120089104","rc":[{"trd":[[5.1,89.87]],"ltp":5.1,"tv":89.87,"id":9480385},{"atl":[[5.1,4.01]],"id":9480385}],"con":true,"img":false,"tv":2072.8}]}
{"op":"mcm","clk":"1147376036","pt":1439881122910,"mc":[{"id":"1.120089104","rc":[{"atl":[[5.1,1.12]],"id":9480385}],"con":true,"img":false,"tv":2072.8}]}
{"op":"mcm","clk":"1147376051","pt":1439881123697,"mc":[{"id":"1.120089104","rc":[{"trd":[[1.24,34.84]],"ltp":1.24,"tv":34.84,"id":9612932},{"atb":[[1.24,0.08]],"id":9612932}],"con":true,"img":false,"tv":2084.15}]}
{"op":"mcm","clk":"1147376099","pt":1439881128001,"mc":[{"id":"1.120089104","rc":[{"atb":[[1.23,0]],"id":9612932}],"con":true,"img":false,"tv":2084.15}]}
{"op":"mcm","clk":"1147376100","pt":1439881128106,"mc":[{"id":"1.120089104","rc":[{"atb":[[1.23,21.59]],"id":9612932}],"con":true,"img":false,"tv":2084.15}]}
{"op":"mcm","clk":"1147376101","pt":1439881128208,"mc":[{"id":"1.120089104","rc":[{"atb":[[1.01,1754.58]],"id":9612932}],"con":true,"img":false,"tv":2084.15}]}
{"op":"mcm","clk":"1147376104","pt":1439881128312,"mc":[{"id":"1.120089104","rc":[{"atb":[[1.01,1752.19]],"id":9612932}],"con":true,"img":false,"tv":2084.15}]}
{"op":"mcm","clk":"1147376106","pt":1439881128364,"mc":[{"id":"1.120089104","rc":[{"atb":[[1.01,1752.01]],"id":9612932}],"con":true,"img":false,"tv":2084.15}]}
{"op":"mcm","clk":"1147376108","pt":1439881128469,"mc":[{"id":"1.120089104","rc":[{"atb":[[1.22,0.57]],"id":9612932}],"con":true,"img":false,"tv":2084.15}]}
{"op":"mcm","clk":"1147376154","pt":1439881132405,"mc":[{"id":"1.120089104","rc":[{"atl":[[5.7,0]],"id":9480385}],"con":true,"img":false,"tv":2084.15}]}
{"op":"mcm","clk":"1147376157","pt":1439881132510,"mc":[{"id":"1.120089104","rc":[{"atl":[[5.3,2.89]],"id":9480385}],"con":true,"img":false,"tv":2084.15}]}
{"op":"mcm","clk":"1147376288","pt":1439881142016,"mc":[{"id":"1.120089104","rc":[{"atl":[[5.3,5.67]],"id":9480385}],"con":true,"img":false,"tv":2084.15}]}
{"op":"mcm","clk":"1147376311","pt":1439881143624,"mc":[{"id":"1.120089104","rc":[{"atl":[[1.25,141.92]],"id":9612932}],"con":true,"img":false,"tv":2084.15}]}
{"op":"mcm","clk":"1147376397","pt":1439881148722,"mc":[{"id":"1.120089104","rc":[{"atb":[[1.23,0],[1.22,0.39]],"id":9612932}],"con":true,"img":false,"tv":2084.15}]}
{"op":"mcm","clk":"1147376400","pt":1439881148826,"mc":[{"id":"1.120089104","rc":[{"atb":[[1.22,22.16]],"id":9612932}],"con":true,"img":false,"tv":2084.15}]}
{"op":"mcm","clk":"1147376702","pt":1439881172691,"mc":[{"id":"1.120089104","rc":[{"atl":[[1.26,150.01]],"id":9612932},{"spn":1.21,"spf":1.0,"id":9612932}],"con":true,"img":false,"tv":2084.15}]}
{"op":"mcm","clk":"1147376726","pt":1439881174100,"mc":[{"id":"1.120089104","rc":[{"atb":[[4.9,25]],"id":9480385}],"con":true,"img":false,"tv":2084.15}]}
{"op":"mcm","clk":"1147376781","pt":1439881177337,"mc":[{"id":"1.120089104","rc":[{"atb":[[1.01,1730.58],[4.7,20]],"id":9480385}],"con":true,"img":false,"tv":2084.15}]}
{"op":"mcm","clk":"1147376788","pt":1439881177755,"mc":[{"id":"1.120089104","rc":[{"atb":[[1.01,1729.92]],"id":9480385}],"con":true,"img":false,"tv":2084.15}]}
{"op":"mcm","clk":"1147376792","pt":1439881177966,"mc":[{"id":"1.120089104","rc":[{"atb":[[1.01,1728.01]],"id":9480385}],"con":true,"img":false,"tv":2084.15}]}
{"op":"mcm","clk":"1147376796","pt":1439881178070,"mc":[{"id":"1.120089104","rc":[{"atb":[[5,1.9]],"id":9480385}],"con":true,"img":false,"tv":2084.15}]}
{"op":"mcm","clk":"1147376826","pt":1439881179791,"mc":[{"id":"1.120089104","rc":[{"atb":[[4.9,0]],"id":9480385}],"con":true,"img":false,"tv":2084.15}]}
{"op":"mcm","clk":"1147376830","pt":1439881179999,"mc":[{"id":"1.120089104","rc":[{"trd":[[1.25,300.42]],"ltp":1.25,"tv":300.42,"id":9612932},{"atl":[[1.25,0]],"id":9612932}],"con":true,"img":false,"tv":2368.0}]}
{"op":"mcm","clk":"1147376873","pt":1439881183027,"mc":[{"id":"1.120089104","rc":[{"atb":[[1.02,16070]],"id":9612932}],"con":true,"img":false,"tv":2368.0}]}
{"op":"mcm","clk":"1147376877","pt":1439881183237,"mc":[{"id":"1.120089104","rc":[{"atb":[[1.01,1750.01]],"id":9612932}],"con":true,"img":false,"tv":2368.0}]}
{"op":"mcm","clk":"1147376884","pt":1439881183603,"mc":[{"id":"1.120089104","rc":[{"atb":[[1.02,10250]],"id":9480385}],"con":true,"img":false,"tv":2368.0}]}
{"op":"mcm","clk":"1147376886","pt":1439881183812,"mc":[{"id":"1.120089104","rc":[{"atb":[[1.01,1726.01]],"id":9480385}],"con":true,"img":false,"tv":2368.0}]}
{"op":"mcm","clk":"1147377007","pt":1439881192710,"mc":[{"id":"1.120089104","rc":[{"atb":[[5,26.9]],"id":9480385}],"con":true,"img":false,"tv":2368.0}]}
{"op":"mcm","clk":"1147377022","pt":1439881193814,"mc":[{"id":"1.120089104","rc":[{"atl":[[1.27,141.92]],"id":9612932}],"con":true,"img":false,"tv":2368.0}]}
{"op":"mcm","clk":"1147377132","pt":1439881202160,"mc":[{"id":"1.120089104","rc":[{"atb":[[5,1.9]],"id":9480385}],"con":true,"img":false,"tv":2368.0}]}
{"op":"mcm","clk":"1147377203","pt":1439881204385,"mc":[{"id":"1.120089104","rc":[{"atb":[[4.7,45]],"id":9480385}],"con":true,"img":false,"tv":2368.0}]}
{"op":"mcm","clk":"1147377238","pt":1439881206769,"mc":[{"id":"1.120089104","rc":[{"atb":[[5,26.9]],"id":9480385}],"con":true,"img":false,"tv":2368.0}]}
{"op":"mcm","clk":"1147377250","pt":1439881207548,"mc":[{"id":"1.120089104","rc":[{"atl":[[1.29,0]],"id":9612932}],"con":true,"img":false,"tv":2368.0}]}
{"op":"mcm","clk":"1147377254","pt":1439881207651,"mc":[{"id":"1.120089104","rc":[{"atl":[[1.25,67.97]],"id":9612932}],"con":true,"img":false,"tv":2368.0}]}
{"op":"mcm","clk":"1147377280","pt":1439881209260,"mc":[{"id":"1.120089104","rc":[{"atl":[[1.29,6]],"id":9612932}],"con":true,"img":false,"tv":2368.0}]}
{"op":"mcm","clk":"1147377297","pt":1439881210457,"mc":[{"id":"1.120089104","rc":[{"atb":[[5,28.9]],"id":9480385}],"con":true,"img":false,"tv":2368.0}]}
{"op":"mcm","clk":"1147377319","pt":1439881211494,"mc":[{"id":"1.120089104","rc":[{"atl":[[1.28,0],[1.26,141.92]],"id":9612932},{"atb":[[5,30.9]],"id":9480385}],"con":true,"img":false,"tv":2368.0}]}
{"op":"mcm","clk":"1147377328","pt":1439881211863,"mc":[{"id":"1.120089104","rc":[{"atb":[[5,32.9]],"id":9480385}],"con":true,"img":false,"tv":2368.0}]}
{"op":"mcm","clk":"1147377340","pt":1439881212274,"mc":[{"id":"1.120089104","rc":[{"atb":[[5,34.9]],"id":9480385}],"con":true,"img":false,"tv":2368.0}]}
{"op":"mcm","clk":"1147377359","pt":1439881213261,"mc":[{"id":"1.120089104","rc":[{"atb":[[5,36.9]],"id":9480385}],"con":true,"img":false,"tv":2368.0}]}
{"op":"mcm","clk":"1147377364","pt":1439881213468,"mc":[{"id":"1.120089104","rc":[{"atl":[[1.25,209.89]],"id":9612932}],"con":true,"img":false,"tv":2368.0}]}
{"op":"mcm","clk":"1147377366","pt":1439881213673,"mc":[{"id":"1.120089104","rc":[{"atb":[[5,38.9]],"id":9480385}],"con":true,"img":false,"tv":2368.0}]}
{"op":"mcm","clk":"1147377372","pt":1439881213984,"mc":[{"id":"1.120089104","rc":[{"atb":[[5,40.9]],"id":9480385}],"con":true,"img":false,"tv":2368.0}]}
{"op":"mcm","clk":"1147377391","pt":1439881215341,"mc":[{"id":"1.120089104","rc":[{"atb":[[5,42.9]],"id":9480385}],"con":true,"img":false,"tv":2368.0}]}
{"op":"mcm","clk":"1147377398","pt":1439881215702,"mc":[{"id":"1.120089104","rc":[{"atb":[[5,44.9]],"id":9480385}],"con":true,"img":false,"tv":2368.0}]}
{"op":"mcm","clk":"1147377404","pt":1439881216223,"mc":[{"id":"1.120089104","rc":[{"atb":[[5,46.9]],"id":9480385}],"con":true,"img":false,"tv":2368.0}]}
{"op":"mcm","clk":"1147377419","pt":1439881217574,"mc":[{"id":"1.120089104","rc":[{"atb":[[5,48.9]],"id":9480385}],"con":true,"img":false,"tv":2368.0}]}
{"op":"mcm","clk":"1147377428","pt":1439881218145,"mc":[{"id":"1.120089104","rc":[{"atb":[[5,50.9]],"id":9480385}],"con":true,"img":false,"tv":2368.0}]}
{"op":"mcm","clk":"1147377432","pt":1439881218354,"mc":[{"id":"1.120089104","rc":[{"atb":[[3.85,0]],"id":9480385}],"con":true,"img":false,"tv":2368.0}]}
{"op":"mcm","clk":"1147377436","pt":1439881218459,"mc":[{"id":"1.120089104","rc":[{"atb":[[4.1,34.85]],"id":9480385}],"con":true,"img":false,"tv":2368.0}]}
{"op":"mcm","clk":"1147377924","pt":1439881254700,"mc":[{"id":"1.120089104","rc":[{"atb":[[5,1.9]],"id":9480385},{"spn":5.05,"spf":"NaN","id":9480385}],"con":true,"img":false,"tv":2368.0}]}
{"op":"mcm","clk":"1147377992","pt":1439881258562,"mc":[{"id":"1.120089104","rc":[{"atb":[[1.16,22.42]],"id":9612932}],"con":true,"img":false,"tv":2368.0}]}
{"op":"mcm","clk":"1147378173","pt":1439881269708,"mc":[{"id":"1.120089104","rc":[{"atb":[[5,356.71]],"id":9480385}],"con":true,"img":false,"tv":2368.0}]}
{"op":"mcm","clk":"1147378244","pt":1439881274216,"mc":[{"id":"1.120089104","rc":[{"trd":[[1.22,86.23],[1.24,35.02]],"ltp":1.22,"tv":121.25,"id":9612932},{"atb":[[1.22,1.07],[1.24,0]],"id":9612932}],"con":true,"img":false,"tv":2410.38}]}
{"op":"mcm","clk":"1147379148","pt":1439881338415,"mc":[{"id":"1.120089104","rc":[{"spn":1.21,"spf":1.0,"id":9612932},{"atb":[[4.7,0]],"id":9480385}],"con":true,"img":false,"tv":2410.38}]}
{"op":"mcm","clk":"1147379189","pt":1439881340394,"mc":[{"id":"1.120089104","rc":[{"atb":[[4.7,6]],"id":9480385}],"con":true,"img":false,"tv":2410.38}]}
{"op":"mcm","clk":"1147379353","pt":1439881350607,"mc":[{"id":"1.120089104","rc":[{"atl":[[5.1,0]],"id":9480385}],"con":true,"img":false,"tv":2410.38}]}
{"op":"mcm","clk":"1147379374","pt":1439881351288,"mc":[{"id":"1.120089104","rc":[{"atb":[[1.22,3.21]],"id":9612932}],"con":true,"img":false,"tv":2410.38}]}
{"op":"mcm","clk":"1147379666","pt":1439881372103,"mc":[{"id":"1.120089104","rc":[{"atl":[[1.25,292.92]],"id":9612932}],"con":true,"img":false,"tv":2410.38}]}
{"op":"mcm","clk":"1147380379","pt":1439881420296,"mc":[{"id":"1.120089104","rc":[{"spn":1.21,"spf":1.0,"id":9612932},{"trd":[[5,332.71]],"ltp":5.0,"tv":332.71,"id":9480385},{"atb":[[5,198.58]],"id":9480385},{"spn":5.15,"spf":"NaN","id":9480385}],"con":true,"img":false,"tv":2726.65}]}
{"op":"mcm","clk":"1147388869","pt":1439881467904,"mc":[{"id":"1.120089104","rc":[{"trd":[[1.22,91.67]],"ltp":1.22,"tv":91.67,"id":9612932},{"atb":[[1.22,0.48]],"id":9612932}],"con":true,"img":false,"tv":2732.1}]}
{"op":"mcm","clk":"1147389175","pt":1439881489598,"mc":[{"id":"1.120089104","rc":[{"spn":1.21,"spf":1.0,"id":9612932},{"atb":[[4.9,72.38]],"id":9480385}],"con":true,"img":false,"tv":2732.1}]}
{"op":"mcm","clk":"1147393408","pt":1439881809516,"mc":[{"id":"1.120089104","rc":[{"atb":[[5.1,21]],"id":9480385},{"spn":5.2,"spf":"NaN","id":9480385}],"con":true,"img":false,"tv":2732.1}]}
{"op":"mcm","clk":"1147395009","pt":1439881950407,"mc":[{"id":"1.120089104","rc":[{"atl":[[1.24,27.9]],"id":9612932}],"con":true,"img":false,"tv":2732.1}]}
{"op":"mcm","clk":"1147396706","pt":1439882140843,"mc":[{"id":"1.120089104","rc":[{"trd":[[1.24,90.81]],"ltp":1.24,"tv":90.81,"id":9612932},{"atl":[[1.24,0]],"id":9612932}],"con":true,"img":false,"tv":2787.89}]}
{"op":"mcm","clk":"1147397410","pt":1439882214880,"mc":[{"id":"1.120089104","rc":[{"atl":[[1.25,294.92]],"id":9612932},{"spl":[[1.25,2]],"id":9612932}],"con":true,"img":false,"tv":2787.89}]}
{"op":"mcm","clk":"1147397869","pt":1439882256099,"mc":[{"id":"1.120089104","rc":[{"atb":[[1.01,1751.91]],"id":9612932}],"con":true,"img":false,"tv":2787.89}]}
{"op":"mcm","clk":"1147397936","pt":1439882261739,"mc":[{"id":"1.120089104","rc":[{"atb":[[1.01,1750.01]],"id":9612932}],"con":true,"img":false,"tv":2787.89}]}
{"op":"mcm","clk":"1147397938","pt":1439882261844,"mc":[{"id":"1.120089104","rc":[{"atb":[[1.19,1.9]],"id":9612932}],"con":true,"img":false,"tv":2787.89}]}
{"op":"mcm","clk":"1147407614","pt":1439882381245,"mc":[{"id":"1.120089104","rc":[{"trd":[[5.1,124.9]],"ltp":5.1,"tv":124.9,"id":9480385},{"atb":[[5.1,3.48]],"id":9480385}],"con":true,"img":false,"tv":2822.92}]}
{"op":"mcm","clk":"1147407820","pt":1439882399024,"mc":[{"id":"1.120089104","rc":[{"atb":[[1.01,1752.37]],"id":9612932},{"atl":[[1.46,2.36]],"id":9612932},{"atb":[[3.4,2.36]],"id":9480385},{"atl":[[9.2,2.36]],"id":9480385}],"con":true,"img":false,"tv":2822.92}]}
{"op":"mcm","clk":"1147407960","pt":1439882410441,"mc":[{"id":"1.120089104","rc":[{"atb":[[2.28,5]],"id":9480385}],"con":true,"img":false,"tv":2822.92}]}
{"op":"mcm","clk":"1147408003","pt":1439882415029,"mc":[{"id":"1.120089104","rc":[{"atb":[[2.28,0]],"id":9480385}],"con":true,"img":false,"tv":2822.92}]}
{"op":"mcm","clk":"1147408004","pt":1439882415133,"mc":[{"id":"1.120089104","rc":[{"atb":[[5.1,8.48]],"id":9480385}],"con":true,"img":false,"tv":2822.92}]}
{"op":"mcm","clk":"1147408366","pt":1439882455097,"mc":[{"id":"1.120089104","rc":[{"atb":[[1.16,0]],"id":9612932}],"con":true,"img":false,"tv":2822.92}]}
{"op":"mcm","clk":"1147409304","pt":1439882550476,"mc":[{"id":"1.120089104","rc":[{"trd":[[1.21,138.31],[1.22,92.65]],"ltp":1.21,"tv":230.96,"id":9612932},{"atb":[[1.22,0],[1.21,0.59]],"id":9612932},{"spn":1.18,"spf":1.0,"id":9612932}],"con":true,"img":false,"tv":2910.91}]}
{"op":"mcm","clk":"1147409322","pt":1439882552658,"mc":[{"id":"1.120089104","rc":[{"atb":[[1.16,12.56]],"id":9612932},{"atl":[[1.24,11.75]],"id":9612932}],"con":true,"img":false,"tv":2910.91}]}
{"op":"mcm","clk":"1147409449","pt":1439882560665,"mc":[{"id":"1.120089104","rc":[{"atl":[[1.24,155.75]],"id":9612932}],"con":true,"img":false,"tv":2910.91}]}
{"op":"mcm","clk":"1147409669","pt":1439882579272,"mc":[{"id":"1.120089104","rc":[{"trd":[[5.3,25.25]],"ltp":5.3,"tv":25.25,"id":9480385},{"atl":[[5.3,0.67]],"id":9480385}],"con":true,"img":false,"tv":2920.91}]}
{"op":"mcm","clk":"1147409777","pt":1439882587679,"mc":[{"id":"1.120089104","rc":[{"atl":[[1.24,11.75]],"id":9612932}],"con":true,"img":false,"tv":2920.91}]}
{"op":"mcm","clk":"1147409779","pt":1439882587784,"mc":[{"id":"1.120089104","rc":[{"atl":[[1.23,144]],"id":9612932}],"con":true,"img":false,"tv":2920.91}]}
{"op":"mcm","clk":"1147409841","pt":1439882593125,"mc":[{"id":"1.120089104","rc":[{"atb":[[5.2,2.3]],"id":9480385},{"atl":[[5.3,0]],"id":9480385}],"con":true,"img":false,"tv":2920.91}]}
{"op":"mcm","clk":"1147409905","pt":1439882598471,"mc":[{"id":"1.120089104","rc":[{"atb":[[5.2,5.3]],"id":9480385}],"con":true,"img":false,"tv":2920.91}]}
{"op":"mcm","clk":"1147410011","pt":1439882611602,"mc":[{"id":"1.120089104","rc":[{"atl":[[10,0]],"id":9480385},{"spn":5.3,"spf":"NaN","id":9480385}],"con":true,"img":false,"tv":2920.91}]}
{"op":"mcm","clk":"1147410015","pt":1439882611708,"mc":[{"id":"1.120089104","rc":[{"atl":[[9,5.93]],"id":9480385}],"con":true,"img":false,"tv":2920.91}]}
{"op":"mcm","clk":"1147410043","pt":1439882615654,"mc":[{"id":"1.120089104","rc":[{"atl":[[8.8,3.39]],"id":9480385}],"con":true,"img":false,"tv":2920.91}]}
{"op":"mcm","clk":"1147410132","pt":1439882625589,"mc":[{"id":"1.120089104","rc":[{"atl":[[7.2,0]],"id":9480385}],"con":true,"img":false,"tv":2920.91}]}
{"op":"mcm","clk":"1147410307","pt":1439882644458,"mc":[{"id":"1.120089104","rc":[{"atl":[[9,0]],"id":9480385}],"con":true,"img":false,"tv":2920.91}]}
{"op":"mcm","clk":"1147410310","pt":1439882644614,"mc":[{"id":"1.120089104","rc":[{"atl":[[8.6,6.21]],"id":9480385}],"con":true,"img":false,"tv":2920.91}]}
{"op":"mcm","clk":"1147410470","pt":1439882660421,"mc":[{"id":"1.120089104","rc":[{"atl":[[8.8,0]],"id":9480385}],"con":true,"img":false,"tv":2920.91}]}
{"op":"mcm","clk":"1147410482","pt":1439882661048,"mc":[{"id":"1.120089104","rc":[{"atb":[[1.14,400]],"id":9612932}],"con":true,"img":false,"tv":2920.91}]}
{"op":"mcm","clk":"1147410485","pt":1439882661152,"mc":[{"id":"1.120089104","rc":[{"atb":[[1.12,1247.89]],"id":9612932}],"con":true,"img":false,"tv":2920.91}]}
{"op":"mcm","clk":"1147410676","pt":1439882683122,"mc":[{"id":"1.120089104","rc":[{"atl":[[8.4,3.41]],"id":9480385}],"con":true,"img":false,"tv":2920.91}]}
{"op":"mcm","clk":"1147410996","pt":1439882717127,"mc":[{"id":"1.120089104","rc":[{"atl":[[8.6,0]],"id":9480385}],"con":true,"img":false,"tv":2920.91}]}
{"op":"mcm","clk":"1147410998","pt":1439882717231,"mc":[{"id":"1.120089104","rc":[{"atl":[[8.2,6.51]],"id":9480385}],"con":true,"img":false,"tv":2920.91}]}
{"op":"mcm","clk":"1147411086","pt":1439882727872,"mc":[{"id":"1.120089104","rc":[{"atl":[[8.4,0]],"id":9480385}],"con":true,"img":false,"tv":2920.91}]}
{"op":"mcm","clk":"1147411277","pt":1439882750504,"mc":[{"id":"1.120089104","rc":[{"atl":[[8,3.43]],"id":9480385}],"con":true,"img":false,"tv":2920.91}]}
{"op":"mcm","clk":"1147411562","pt":1439882777746,"mc":[{"id":"1.120089104","rc":[{"atl":[[8.2,0]],"id":9480385}],"con":true,"img":false,"tv":2920.91}]}
{"op":"mcm","clk":"1147411564","pt":1439882777850,"mc":[{"id":"1.120089104","rc":[{"atl":[[7.8,6.84]],"id":9480385}],"con":true,"img":false,"tv":2920.91}]}
{"op":"mcm","clk":"1147411645","pt":1439882786882,"mc":[{"id":"1.120089104","rc":[{"trd":[[5.2,35.64]],"ltp":5.2,"tv":35.64,"id":9480385},{"atb":[[5.2,0.3]],"id":9480385}],"con":true,"img":false,"tv":2930.91}]}
{"op":"mcm","clk":"1147411697","pt":1439882795407,"mc":[{"id":"1.120089104","rc":[{"atl":[[8,0]],"id":9480385}],"con":true,"img":false,"tv":2930.91}]}
{"op":"mcm","clk":"1147411902","pt":1439882817656,"mc":[{"id":"1.120089104","rc":[{"atl":[[7.8,8.84]],"id":9480385}],"con":true,"img":false,"tv":2930.91}]}
{"op":"mcm","clk":"1147412334","pt":1439882850888,"mc":[{"id":"1.120089104","rc":[{"atb":[[1.16,44.84]],"id":9612932}],"con":true,"img":false,"tv":2930.91}]}
{"op":"mcm","clk":"1147412489","pt":1439882861902,"mc":[{"id":"1.120089104","rc":[{"atl":[[1.23,150]],"id":9612932},{"atl":[[7.8,14.84]],"id":9480385}],"con":true,"img":false,"tv":2930.91}]}
{"op":"mcm","clk":"1147414635","pt":1439883062133,"mc":[{"id":"1.120089104","rc":[{"atl":[[1.23,144]],"id":9612932}],"con":true,"img":false,"tv":2930.91}]}
{"op":"mcm","clk":"1147414638","pt":1439883062445,"mc":[{"id":"1.120089104","rc":[{"atl":[[7.8,8.84]],"id":9480385}],"con":true,"img":false,"tv":2930.91}]}
{"op":"mcm","clk":"1147415027","pt":1439883101849,"mc":[{"id":"1.120089104","rc":[{"trd":[[1.23,307.76]],"ltp":1.23,"tv":307.76,"id":9612932},{"atl":[[1.23,0]],"id":9612932}],"con":true,"img":false,"tv":3218.91}]}
{"op":"mcm","clk":"1147416070","pt":1439883197395,"mc":[{"id":"1.120089104","rc":[{"atl":[[1.24,166.75]],"id":9612932}],"con":true,"img":false,"tv":3218.91}]}
{"op":"mcm","clk":"1147424590","pt":1439883265641,"mc":[{"id":"1.120089104","rc":[{"atl":[[7.8,14.84]],"id":9480385}],"con":true,"img":false,"tv":3218.91}]}
{"op":"mcm","clk":"1147426916","pt":1439883465754,"mc":[{"id":"1.120089104","rc":[{"atl":[[7.8,8.84]],"id":9480385}],"con":true,"img":false,"tv":3218.91}]}
{"op":"mcm","clk":"1147427618","pt":1439883529004,"mc":[{"id":"1.120089104","rc":[{"spl":[[1.88,20.11]],"id":9612932}],"con":true,"img":false,"tv":3218.91}]}
{"op":"mcm","clk":"1147429145","pt":1439883654892,"mc":[{"id":"1.120089104","rc":[{"atl":[[7.8,14.84]],"id":9480385}],"con":true,"img":false,"tv":3218.91}]}
{"op":"mcm","clk":"1147430975","pt":1439883804553,"mc":[{"id":"1.120089104","rc":[{"atl":[[5.5,10]],"id":9480385}],"con":true,"img":false,"tv":3218.91}]}
{"op":"mcm","clk":"1147431028","pt":1439883808282,"mc":[{"id":"1.120089104","rc":[{"atl":[[7.8,12.84]],"id":9480385}],"con":true,"img":false,"tv":3218.91}]}
{"op":"mcm","clk":"1147431054","pt":1439883810202,"mc":[{"id":"1.120089104","rc":[{"atb":[[1.15,190.63]],"id":9612932}],"con":true,"img":false,"tv":3218.91}]}
{"op":"mcm","clk":"1147431176","pt":1439883820239,"mc":[{"id":"1.120089104","rc":[{"atb":[[5.2,0]],"id":9480385}],"con":true,"img":false,"tv":3218.91}]}
{"op":"mcm","clk":"1147431179","pt":1439883820287,"mc":[{"id":"1.120089104","rc":[{"atl":[[5.4,2.69]],"id":9480385}],"con":true,"img":false,"tv":3218.91}]}
{"op":"mcm","clk":"1147431342","pt":1439883831171,"mc":[{"id":"1.120089104","rc":[{"atl":[[5.4,5.57]],"id":9480385}],"con":true,"img":false,"tv":3218.91}]}
{"op":"mcm","clk":"1147431540","pt":1439883850244,"mc":[{"id":"1.120089104","rc":[{"atb":[[1.15,188.73]],"id":9612932}],"con":true,"img":false,"tv":3218.91}]}
{"op":"mcm","clk":"1147431603","pt":1439883855055,"mc":[{"id":"1.120089104","rc":[{"atl":[[7.8,6.84]],"id":9480385}],"con":true,"img":false,"tv":3218.91}]}
{"op":"mcm","clk":"1147431748","pt":1439883866036,"mc":[{"id":"1.120089104","rc":[{"atb":[[1.15,190.63]],"id":9612932},{"spn":5.25,"spf":"NaN","id":9480385}],"con":true,"img":false,"tv":3218.91}]}
{"op":"mcm","clk":"1147432358","pt":1439883914060,"mc":[{"id":"1.120089104","rc":[{"atb":[[1.15,188.73]],"id":9612932}],"con":true,"img":false,"tv":3218.91}]}
{"op":"mcm","clk":"1147432359","pt":1439883914115,"mc":[{"id":"1.120089104","rc":[{"atb":[[1.17,1.9]],"id":9612932}],"con":true,"img":false,"tv":3218.91}]}
{"op":"mcm","clk":"1147432428","pt":1439883920689,"mc":[{"id":"1.120089104","rc":[{"atb":[[1.14,0],[1.12,847.89],[1.1,0]],"id":9612932},{"atb":[[4.4,0],[4.6,0.11]],"id":9480385}],"con":true,"img":false,"tv":3218.91}]}
{"op":"mcm","clk":"1147432464","pt":1439883922678,"mc":[{"id":"1.120089104","rc":[{"atb":[[4.7,0]],"id":9480385}],"con":true,"img":false,"tv":3218.91}]}
{"op":"mcm","clk":"1147432466","pt":1439883922887,"mc":[{"id":"1.120089104","rc":[{"atb":[[4.5,0]],"id":9480385}],"con":true,"img":false,"tv":3218.91}]}
{"op":"mcm","clk":"1147432482","pt":1439883924295,"mc":[{"id":"1.120089104","rc":[{"atb":[[4.2,22.42]],"id":9480385}],"con":true,"img":false,"tv":3218.91}]}
{"op":"mcm","clk":"1147432873","pt":1439883950772,"mc":[{"id":"1.120089104","rc":[{"atb":[[4.2,0]],"id":9480385}],"con":true,"img":false,"tv":3218.91}]}
{"op":"mcm","clk":"1147433549","pt":1439884011033,"mc":[{"id":"1.120089104","rc":[{"atb":[[1.17,0]],"id":9612932}],"con":true,"img":false,"tv":3218.91}]}
{"op":"mcm","clk":"1147433551","pt":1439884011086,"mc":[{"id":"1.120089104","rc":[{"atb":[[1.19,3.8]],"id":9612932}],"con":true,"img":false,"tv":3218.91}]}
{"op":"mcm","clk":"1147433566","pt":1439884012132,"mc":[{"id":"1.120089104","rc":[{"atb":[[4.2,22.42]],"id":9480385}],"con":true,"img":false,"tv":3218.91}]}
{"op":"mcm","clk":"1147434327","pt":1439884062582,"mc":[{"id":"1.120089104","rc":[{"trd":[[1.24,424.33]],"ltp":1.24,"tv":424.33,"id":9612932},{"atl":[[1.24,0]],"id":9612932}],"con":true,"img":false,"tv":3552.42}]}
{"op":"mcm","clk":"1147434399","pt":1439884070101,"mc":[{"id":"1.120089104","rc":[{"atb":[[1.03,11]],"id":9612932},{"atl":[[900,2]],"id":9612932},{"atb":[[1.03,11]],"id":9480385},{"atl":[[900,2]],"id":9480385}],"con":true,"img":false,"tv":3552.42}]}
{"op":"mcm","clk":"1147434515","pt":1439884080331,"mc":[{"id":"1.120089104","rc":[{"atl":[[900,2.2]],"id":9612932},{"spn":1.18,"spf":1.0,"id":9612932},{"atl":[[900,2.2]],"id":9480385}],"con":true,"img":false,"tv":3552.42}]}
{"op":"mcm","clk":"1147434583","pt":1439884087126,"mc":[{"id":"1.120089104","rc":[{"atl":[[900,0.2]],"id":9612932},{"atl":[[900,0.2]],"id":9480385}],"con":true,"img":false,"tv":3552.42}]}
{"op":"mcm","clk":"1147434626","pt":1439884091784,"mc":[{"id":"1.120089104","rc":[{"atb":[[1.19,1.9]],"id":9612932}],"con":true,"img":false,"tv":3552.42}]}
{"op":"mcm","clk":"1147434628","pt":1439884091836,"mc":[{"id":"1.120089104","rc":[{"atb":[[1.2,3.67]],"id":9612932}],"con":true,"img":false,"tv":3552.42}]}
{"op":"mcm","clk":"1147435514","pt":1439884154226,"mc":[{"id":"1.120089104","rc":[{"atb":[[1.12,827.89]],"id":9612932},{"spn":1.18,"spf":1.0,"id":9612932}],"con":true,"img":false,"tv":3552.42}]}
{"op":"mcm","clk":"1147435518","pt":1439884154332,"mc":[{"id":"1.120089104","rc":[{"atb":[[1.15,208.73]],"id":9612932}],"con":true,"img":false,"tv":3552.42}]}
{"op":"mcm","clk":"1147445646","pt":1439884364676,"mc":[{"id":"1.120089104","rc":[{"atb":[[1.15,108.73]],"id":9612932}],"con":true,"img":false,"tv":3552.42}]}
{"op":"mcm","clk":"1147445647","pt":1439884364781,"mc":[{"id":"1.120089104","rc":[{"atb":[[1.17,100]],"id":9612932}],"con":true,"img":false,"tv":3552.42}]}
{"op":"mcm","clk":"1147446393","pt":1439884456269,"mc":[{"id":"1.120089104","rc":[{"atb":[[5.2,53.32]],"id":9480385},{"spn":5.3,"spf":"NaN","id":9480385}],"con":true,"img":false,"tv":3552.42}]}
{"op":"mcm","clk":"1147446444","pt":1439884459399,"mc":[{"id":"1.120089104","rc":[{"atb":[[4.7,13.6]],"id":9480385}],"con":true,"img":false,"tv":3552.42}]}
{"op":"mcm","clk":"1147447039","pt":1439884509144,"mc":[{"id":"1.120089104","rc":[{"atb":[[5.2,0]],"id":9480385}],"con":true,"img":false,"tv":3552.42}]}
{"op":"mcm","clk":"1147448341","pt":1439884638490,"mc":[{"id":"1.120089104","rc":[{"atl":[[1.29,23.08]],"id":9612932},{"atb":[[4.8,3.88]],"id":9480385},{"atl":[[7.6,4.17]],"id":9480385},{"spn":5.25,"spf":"NaN","id":9480385}],"con":true,"img":false,"tv":3552.42}]}
{"op":"mcm","clk":"1147448343","pt":1439884638698,"mc":[{"id":"1.120089104","rc":[{"atb":[[4.2,0]],"id":9480385}],"con":true,"img":false,"tv":3552.42}]}
{"op":"mcm","clk":"1147448921","pt":1439884698429,"mc":[{"id":"1.120089104","rc":[{"atb":[[1.16,71.47]],"id":9612932}],"con":true,"img":false,"tv":3552.42}]}
{"op":"mcm","clk":"1147456367","pt":1439885064863,"mc":[{"id":"1.120089104","marketDefinition":{"bspMarket":true,"turnInPlayEnabled":true,"persistenceEnabled":true,"marketBaseRate":5.0,"eventId":"27514783","eventTypeId":"7","numberOfWinners":1,"bettingType":"ODDS","marketType":"WIN","marketTime":"2015-08-18T20:20:00.000Z","suspendTime":"2015-08-18T20:20:00.000Z","bspReconciled":false,"complete":true,"inPlay":false,"crossMatching":false,"runnersVoidable":false,"numberOfActiveRunners":2,"betDelay":0,"status":"OPEN","runners":[{"adjustmentFactor":79.72,"status":"ACTIVE","sortPriority":1,"id":9612932,"name":"Alinstante"},{"adjustmentFactor":20.27,"status":"ACTIVE","sortPriority":2,"id":9480385,"name":"Vallance Road"}],"regulators":["MR_INT"],"venue":"Chelmsford City","countryCode":"GB","discountAllowed":false,"timezone":"Europe/London","openDate":"2015-08-18T17:20:00.000Z","version":1060767560,"name":"1m Cond Stks","eventName":"ChelmC 18th Aug"},"rc":[{"trd":[[1.24,424.85],[1.23,308.16],[1.3,209.95],[1.29,101.96],[1.22,92.67],[1.2,14.89],[1.4,49.38],[1.19,29.49],[1.28,1000.74],[1.27,15.79],[1.25,301.17],[1.26,83.54],[1.21,138.42]],"ltp":1.24,"tv":2771.01,"id":9612932},{"atb":[[1.17,100],[1.16,71.53],[1.04,240],[1.18,46.01],[1.06,20],[1.01,1752.89],[1.13,25],[1.15,108.73],[1.02,16070],[1.03,11],[1.12,830.01],[1.08,10],[1.2,3.67],[1.19,1.9],[1.21,0.59]],"id":9612932},{"atl":[[1.29,23.12],[1.3,95.06],[5.2,15],[1.69,15],[46,2],[19.5,11],[630,0.09],[1.4,500],[1000,1],[1.27,142.28],[1.46,2.35],[4,0.25],[1.25,295.49],[1.26,142.28],[900,0.2]],"id":9612932},{"spl":[[1.88,20.11],[1.01,38.95],[1.25,2]],"id":9612932},{"spn":1.18,"spf":1.0,"id":9612932},{"trd":[[5.2,35.66],[4.9,12.01],[4.7,103.85],[5.4,0.17],[5.1,124.97],[4.8,120.86],[5.6,16.38],[5.3,25.26],[5.5,13.28],[5,333.54]],"ltp":5.2,"tv":785.98,"id":9480385},{"atb":[[2.62,1.41],[2.6,1.9],[4.9,72.56],[1.06,20],[1.18,30],[1.81,12.35],[1.01,1726.53],[4.8,3.89],[1.02,10250],[1.03,11],[3.4,2.35],[2.16,30],[1.08,10],[4.7,13.6],[2.22,12.09],[5.1,8.48],[2.92,175],[4,1.81],[4.1,34.94],[4.6,0.11],[5,199.08]],"id":9480385},{"atl":[[5.4,5.57],[7.8,6.84],[630,0.09],[9.2,2.35],[5.8,0.08],[6,0.07],[7.6,4.19],[46,2],[55,0.01],[6.6,0.06],[90,2],[11.5,0.83],[10.5,15],[5.6,0.08],[5.5,10],[900,0.2]],"id":9480385},{"spn":5.25,"spf":"NaN","id":9480385}],"con":true,"img":true,"tv":3557.1}]}
{"op":"mcm","clk":"1147463880","pt":1439885267677,"mc":[{"id":"1.120089104","rc":[{"trd":[[1.24,424.85],[1.23,308.16],[1.3,209.95],[1.29,101.96],[1.22,92.67],[1.2,14.89],[1.19,29.49],[1.28,1000.74],[1.27,15.79],[1.25,301.17],[1.26,83.54],[1.21,138.42]],"ltp":1.24,"tv":2721.63,"id":9612932},{"atb":[[1.16,71.53],[1.18,46.01],[1.01,1752.89],[1.12,830.01],[1.2,3.67],[1.21,0.59]],"id":9612932},{"atl":[[1.29,23.12],[1.27,142.28],[1.46,2.35],[1.25,295.49],[1.26,142.28]],"id":9612932},{"trd":[[5.4,4.17],[4.9,12.01],[5.2,35.66],[4.7,103.85],[5.1,124.97],[4.8,120.86],[5.6,16.38],[5.3,25.26],[5.5,13.28],[5,333.54]],"ltp":5.4,"tv":789.98,"id":9480385},{"atb":[[2.62,1.41],[4.9,72.56],[1.01,1726.53],[4.8,3.89],[3.4,2.35],[2.22,12.09],[4.1,34.94],[4.6,0.11],[5,199.08]],"id":9480385},{"atl":[[5.4,3.57],[7.8,6.84],[9.2,2.35],[5.8,0.08],[6,0.07],[7.6,4.19],[6.6,0.06],[11.5,0.83],[5.6,0.08]],"id":9480385}],"con":true,"img":false,"tv":3561.1}]}
{"op":"mcm","clk":"1147463922","pt":1439885271183,"mc":[{"id":"1.120089104","rc":[{"atb":[[1.01,1727.96]],"id":9480385}],"con":true,"img":false,"tv":3561.1}]}
{"op":"mcm","clk":"1147463933","pt":1439885272498,"mc":[{"id":"1.120089104","rc":[{"atb":[[1.01,1726.64]],"id":9480385}],"con":true,"img":false,"tv":3561.1}]}
{"op":"mcm","clk":"1147463934","pt":1439885272603,"mc":[{"id":"1.120089104","rc":[{"atb":[[1.01,1726.53]],"id":9480385}],"con":true,"img":false,"tv":3561.1}]}
{"op":"mcm","clk":"1147463937","pt":1439885272706,"mc":[{"id":"1.120089104","rc":[{"atb":[[4.7,13.7]],"id":9480385}],"con":true,"img":false,"tv":3561.1}]}
{"op":"mcm","clk":"1147464931","pt":1439885352274,"mc":[{"id":"1.120089104","rc":[{"spl":[[1.01,42.71]],"id":9612932},{"spn":1.18,"spf":1.0,"id":9612932}],"con":true,"img":false,"tv":3561.1}]}
{"op":"mcm","clk":"1147466904","pt":1439885492553,"mc":[{"id":"1.120089104","rc":[{"spl":[[1.01,44.71]],"id":9612932},{"spn":1.18,"spf":1.0,"id":9612932}],"con":true,"img":false,"tv":3561.1}]}
{"op":"mcm","clk":"1147468034","pt":1439885579944,"mc":[{"id":"1.120089104","rc":[{"atb":[[2.62,0],[2.22,0]],"id":9480385}],"con":true,"img":false,"tv":3561.1}]}
{"op":"mcm","clk":"1147468366","pt":1439885601193,"mc":[{"id":"1.120089104","rc":[{"spl":[[1.01,59.71]],"id":9612932}],"con":true,"img":false,"tv":3561.1}]}
{"op":"mcm","clk":"1147469410","pt":1439885686064,"mc":[{"id":"1.120089104","rc":[{"spl":[[1.01,84.71]],"id":9612932},{"spn":1.17,"spf":1.0,"id":9612932}],"con":true,"img":false,"tv":3561.1}]}
{"op":"mcm","clk":"1147471790","pt":1439885886400,"mc":[{"id":"1.120089104","rc":[{"trd":[[1.2,17.69],[1.21,139.62]],"ltp":1.2,"tv":157.31,"id":9612932},{"atb":[[1.2,2.27],[1.21,0]],"id":9612932},{"spn":1.17,"spf":1.0,"id":9612932}],"con":true,"img":false,"tv":3565.1}]}
{"op":"mcm","clk":"1147480962","pt":1439885987849,"mc":[{"id":"1.120089104","rc":[{"trd":[[1.2,21.69]],"ltp":1.2,"tv":21.69,"id":9612932},{"atb":[[1.2,0.28]],"id":9612932}],"con":true,"img":false,"tv":3569.1}]}
{"op":"mcm","clk":"1147480975","pt":1439885988842,"mc":[{"id":"1.120089104","rc":[{"atl":[[1.24,1.72]],"id":9612932}],"con":true,"img":false,"tv":3569.1}]}
{"op":"mcm","clk":"1147480995","pt":1439885990520,"mc":[{"id":"1.120089104","rc":[{"atl":[[1.24,4.72]],"id":9612932}],"con":true,"img":false,"tv":3569.1}]}
{"op":"mcm","clk":"1147481126","pt":1439886001326,"mc":[{"id":"1.120089104","rc":[{"atb":[[1.11,270.8]],"id":9612932}],"con":true,"img":false,"tv":3569.1}]}
{"op":"mcm","clk":"1147481138","pt":1439886002483,"mc":[{"id":"1.120089104","rc":[{"atb":[[4.2,9.3]],"id":9480385}],"con":true,"img":false,"tv":3569.1}]}
{"op":"mcm","clk":"1147481289","pt":1439886015203,"mc":[{"id":"1.120089104","rc":[{"atb":[[1.43,1250]],"id":9480385}],"con":true,"img":false,"tv":3569.1}]}
{"op":"mcm","clk":"1147481292","pt":1439886015412,"mc":[{"id":"1.120089104","rc":[{"atb":[[1.12,1084.09]],"id":9612932}],"con":true,"img":false,"tv":3569.1}]}
{"op":"mcm","clk":"1147481307","pt":1439886016403,"mc":[{"id":"1.120089104","rc":[{"atb":[[4.2,18.83]],"id":9480385}],"con":true,"img":false,"tv":3569.1}]}
{"op":"mcm","clk":"1147481430","pt":1439886024573,"mc":[{"id":"1.120089104","rc":[{"atb":[[1.12,1348.76]],"id":9612932}],"con":true,"img":false,"tv":3569.1}]}
{"op":"mcm","clk":"1147481440","pt":1439886025408,"mc":[{"id":"1.120089104","rc":[{"atl":[[1.29,31.49]],"id":9612932},{"spn":1.17,"spf":1.0,"id":9612932},{"atb":[[4.8,5.79]],"id":9480385}],"con":true,"img":false,"tv":3569.1}]}
{"op":"mcm","clk":"1147481444","pt":1439886025613,"mc":[{"id":"1.120089104","rc":[{"atl":[[1.29,14.36]],"id":9612932},{"atb":[[4.8,1.89],[4.2,28.76]],"id":9480385}],"con":true,"img":false,"tv":3569.1}]}
{"op":"mcm","clk":"1147481511","pt":1439886030569,"mc":[{"id":"1.120089104","rc":[{"atl":[[1.29,6]],"id":9612932},{"atb":[[4.8,0]],"id":9480385}],"con":true,"img":false,"tv":3569.1}]}
{"op":"mcm","clk":"1147481583","pt":1439886035943,"mc":[{"id":"1.120089104","rc":[{"atl":[[1.29,8.32]],"id":9612932},{"atb":[[4.3,30.31]],"id":9480385}],"con":true,"img":false,"tv":3569.1}]}
{"op":"mcm","clk":"1147481728","pt":1439886044148,"mc":[{"id":"1.120089104","rc":[{"trd":[[5.1,132.97]],"ltp":5.1,"tv":132.97,"id":9480385},{"atb":[[5.1,4.48]],"id":9480385}],"con":true,"img":false,"tv":3577.1}]}
{"op":"mcm","clk":"1147481894","pt":1439886056377,"mc":[{"id":"1.120089104","rc":[{"atb":[[1.12,1524.5]],"id":9612932}],"con":true,"img":false,"tv":3577.1}]}
{"op":"mcm","clk":"1147481914","pt":1439886057371,"mc":[{"id":"1.120089104","rc":[{"atb":[[4.2,35.34]],"id":9480385}],"con":true,"img":false,"tv":3577.1}]}
{"op":"mcm","clk":"1147483062","pt":1439886149706,"mc":[{"id":"1.120089104","rc":[{"atb":[[1.11,520.78]],"id":9612932}],"con":true,"img":false,"tv":3577.1}]}
{"op":"mcm","clk":"1147483081","pt":1439886150708,"mc":[{"id":"1.120089104","rc":[{"atb":[[4.2,43.93]],"id":9480385}],"con":true,"img":false,"tv":3577.1}]}
{"op":"mcm","clk":"1147483296","pt":1439886166742,"mc":[{"id":"1.120089104","rc":[{"atb":[[5.1,9.34]],"id":9480385}],"con":true,"img":false,"tv":3577.1}]}
{"op":"mcm","clk":"1147483978","pt":1439886223787,"mc":[{"id":"1.120089104","rc":[{"trd":[[1.24,434.29]],"ltp":1.24,"tv":434.29,"id":9612932},{"atl":[[1.24,0]],"id":9612932}],"con":true,"img":false,"tv":3586.54}]}
{"op":"mcm","clk":"1147483991","pt":1439886225207,"mc":[{"id":"1.120089104","rc":[{"atb":[[1.2,2.05]],"id":9612932}],"con":true,"img":false,"tv":3586.54}]}
{"op":"mcm","clk":"1147484114","pt":1439886237331,"mc":[{"id":"1.120089104","rc":[{"atb":[[1.2,5.15]],"id":9612932}],"con":true,"img":false,"tv":3586.54}]}
{"op":"mcm","clk":"1147484186","pt":1439886244725,"mc":[{"id":"1.120089104","rc":[{"trd":[[5.1,136.97]],"ltp":5.1,"tv":136.97,"id":9480385},{"atb":[[5.1,7.34]],"id":9480385}],"con":true,"img":false,"tv":3590.54}]}
{"op":"mcm","clk":"1147484332","pt":1439886256929,"mc":[{"id":"1.120089104","rc":[{"atl":[[1.24,177.85]],"id":9612932}],"con":true,"img":false,"tv":3590.54}]}
{"op":"mcm","clk":"1147484353","pt":1439886258801,"mc":[{"id":"1.120089104","rc":[{"trd":[[1.24,790.01]],"ltp":1.24,"tv":790.01,"id":9612932},{"atl":[[1.24,0]],"id":9612932}],"con":true,"img":false,"tv":3946.26}]}
{"op":"mcm","clk":"1147484449","pt":1439886268182,"mc":[{"id":"1.120089104","rc":[{"atb":[[4.8,3.37]],"id":9480385}],"con":true,"img":false,"tv":3946.26}]}
{"op":"mcm","clk":"1147484452","pt":1439886268392,"mc":[{"id":"1.120089104","rc":[{"atb":[[4.3,0]],"id":9480385}],"con":true,"img":false,"tv":3946.26}]}
{"op":"mcm","clk":"1147485532","pt":1439886346457,"mc":[{"id":"1.120089104","rc":[{"atb":[[1.21,72.79]],"id":9612932},{"spn":1.2,"spf":1.0,"id":9612932},{"atb":[[5.2,16.93]],"id":9480385},{"spn":5.3,"spf":"NaN","id":9480385}],"con":true,"img":false,"tv":3946.26}]}
{"op":"mcm","clk":"1147485587","pt":1439886349848,"mc":[{"id":"1.120089104","rc":[{"atb":[[1.2,2.05]],"id":9612932}],"con":true,"img":false,"tv":3946.26}]}
{"op":"mcm","clk":"1147485600","pt":1439886350576,"mc":[{"id":"1.120089104","rc":[{"atb":[[1.11,270.8]],"id":9612932}],"con":true,"img":false,"tv":3946.26}]}
{"op":"mcm","clk":"1147485620","pt":1439886351101,"mc":[{"id":"1.120089104","rc":[{"atb":[[1.13,236.51]],"id":9612932}],"con":true,"img":false,"tv":3946.26}]}
{"op":"mcm","clk":"1147485678","pt":1439886355844,"mc":[{"id":"1.120089104","rc":[{"atb":[[1.16,124.51]],"id":9612932},{"atb":[[4.8,10.7]],"id":9480385}],"con":true,"img":false,"tv":3946.26}]}
{"op":"mcm","clk":"1147485683","pt":1439886356054,"mc":[{"id":"1.120089104","rc":[{"atb":[[1.16,97.82]],"id":9612932},{"atb":[[4.8,7.32]],"id":9480385}],"con":true,"img":false,"tv":3946.26}]}
{"op":"mcm","clk":"1147485801","pt":1439886368284,"mc":[{"id":"1.120089104","rc":[{"atb":[[1.21,0]],"id":9612932},{"atb":[[5.2,0]],"id":9480385}],"con":true,"img":false,"tv":3946.26}]}
{"op":"mcm","clk":"1147485854","pt":1439886372153,"mc":[{"id":"1.120089104","rc":[{"atb":[[1.2,5.15]],"id":9612932}],"con":true,"img":false,"tv":3946.26}]}
{"op":"mcm","clk":"1147485987","pt":1439886385170,"mc":[{"id":"1.120089104","rc":[{"trd":[[1.25,311.17]],"ltp":1.25,"tv":311.17,"id":9612932},{"atl":[[1.25,290.49]],"id":9612932}],"con":true,"img":false,"tv":3956.26}]}
{"op":"mcm","clk":"1147486594","pt":1439886431568,"mc":[{"id":"1.120089104","rc":[{"atl":[[1000,3]],"id":9612932},{"spn":1.17,"spf":1.0,"id":9612932},{"spn":5.25,"spf":"NaN","id":9480385}],"con":true,"img":false,"tv":3956.26}]}
{"op":"mcm","clk":"1147486596","pt":1439886431675,"mc":[{"id":"1.120089104","rc":[{"atl":[[1000,3.25]],"id":9612932}],"con":true,"img":false,"tv":3956.26}]}
{"op":"mcm","clk":"1147486599","pt":1439886431777,"mc":[{"id":"1.120089104","rc":[{"atl":[[1000,3]],"id":9612932}],"con":true,"img":false,"tv":3956.26}]}
{"op":"mcm","clk":"1147486600","pt":1439886431881,"mc":[{"id":"1.120089104","rc":[{"trd":[[1.2,22.19]],"ltp":1.2,"tv":22.19,"id":9612932},{"atb":[[1.2,4.9]],"id":9612932}],"con":true,"img":false,"tv":3956.76}]}
{"op":"mcm","clk":"1147486602","pt":1439886431934,"mc":[{"id":"1.120089104","rc":[{"atl":[[1000,1]],"id":9612932}],"con":true,"img":false,"tv":3956.76}]}
{"op":"mcm","clk":"1147486716","pt":1439886439354,"mc":[{"id":"1.120089104","rc":[{"atb":[[1.2,1.8]],"id":9612932}],"con":true,"img":false,"tv":3956.76}]}
{"op":"mcm","clk":"1147486998","pt":1439886461814,"mc":[{"id":"1.120089104","rc":[{"atb":[[1.19,5.03]],"id":9612932}],"con":true,"img":false,"tv":3956.76}]}
{"op":"mcm","clk":"1147489119","pt":1439886640676,"mc":[{"id":"1.120089104","rc":[{"spl":[[1.01,119.71]],"id":9612932},{"spn":1.17,"spf":1.0,"id":9612932}],"con":true,"img":false,"tv":3956.76}]}
{"op":"mcm","clk":"1147490731","pt":1439886789163,"mc":[{"id":"1.120089104","rc":[{"trd":[[1.19,39.55],[1.2,25.81]],"ltp":1.19,"tv":65.36,"id":9612932},{"atb":[[1.2,0],[1.19,0]],"id":9612932},{"atl":[[1.19,3.16]],"id":9612932},{"spn":1.17,"spf":1.0,"id":9612932}],"con":true,"img":false,"tv":3970.44}]}
{"op":"mcm","clk":"1147490737","pt":1439886789585,"mc":[{"id":"1.120089104","rc":[{"trd":[[1.19,45.87]],"ltp":1.19,"tv":45.87,"id":9612932},{"atl":[[1.19,0]],"id":9612932},{"atb":[[1.01,1728.53]],"id":9480385}],"con":true,"img":false,"tv":3976.76}]}
{"op":"mcm","clk":"1147490742","pt":1439886789795,"mc":[{"id":"1.120089104","rc":[{"atb":[[1.01,1727.23]],"id":9480385}],"con":true,"img":false,"tv":3976.76}]}
{"op":"mcm","clk":"1147490745","pt":1439886789902,"mc":[{"id":"1.120089104","rc":[{"atb":[[1.01,1729.23]],"id":9480385}],"con":true,"img":false,"tv":3976.76}]}
{"op":"mcm","clk":"1147490748","pt":1439886790115,"mc":[{"id":"1.120089104","rc":[{"atb":[[1.01,1726.93]],"id":9480385}],"con":true,"img":false,"tv":3976.76}]}
{"op":"mcm","clk":"1147490750","pt":1439886790219,"mc":[{"id":"1.120089104","rc":[{"trd":[[5.4,5.57]],"ltp":5.4,"tv":5.57,"id":9480385},{"atl":[[5.4,2.87]],"id":9480385}],"con":true,"img":false,"tv":3978.16}]}
{"op":"mcm","clk":"1147490755","pt":1439886790274,"mc":[{"id":"1.120089104","rc":[{"atb":[[1.01,1726.53]],"id":9480385}],"con":true,"img":false,"tv":3978.16}]}
{"op":"mcm","clk":"1147490756","pt":1439886790379,"mc":[{"id":"1.120089104","rc":[{"atb":[[5.2,0.4]],"id":9480385}],"con":true,"img":false,"tv":3978.16}]}
{"op":"mcm","clk":"1147490759","pt":1439886790800,"mc":[{"id":"1.120089104","rc":[{"atb":[[5.2,0]],"id":9480385}],"con":true,"img":false,"tv":3978.16}]}
{"op":"mcm","clk":"1147490760","pt":1439886790905,"mc":[{"id":"1.120089104","rc":[{"atl":[[1.24,1.72]],"id":9612932}],"con":true,"img":false,"tv":3978.16}]}
{"op":"mcm","clk":"1147490825","pt":1439886795276,"mc":[{"id":"1.120089104","rc":[{"trd":[[5.4,11.31]],"ltp":5.4,"tv":11.31,"id":9480385},{"atb":[[5.4,13.95]],"id":9480385},{"atl":[[5.4,0]],"id":9480385}],"con":true,"img":false,"tv":3983.9}]}
{"op":"mcm","clk":"1147490961","pt":1439886803584,"mc":[{"id":"1.120089104","rc":[{"spl":[[1.01,123.48]],"id":9612932}],"con":true,"img":false,"tv":3983.9}]}
{"op":"mcm","clk":"1147490976","pt":1439886805046,"mc":[{"id":"1.120089104","rc":[{"atl":[[7.6,11.7]],"id":9480385}],"con":true,"img":false,"tv":3983.9}]}
{"op":"mcm","clk":"1147490978","pt":1439886805256,"mc":[{"id":"1.120089104","rc":[{"atb":[[1.16,44.84]],"id":9612932},{"atl":[[7.6,7.51]],"id":9480385}],"con":true,"img":false,"tv":3983.9}]}
{"op":"mcm","clk":"1147491056","pt":1439886810764,"mc":[{"id":"1.120089104","rc":[{"atb":[[1.14,56.91]],"id":9612932}],"con":true,"img":false,"tv":3983.9}]}
{"op":"mcm","clk":"1147491109","pt":1439886815873,"mc":[{"id":"1.120089104","rc":[{"atb":[[4.8,20.29]],"id":9480385}],"con":true,"img":false,"tv":3983.9}]}
{"op":"mcm","clk":"1147491112","pt":1439886816084,"mc":[{"id":"1.120089104","rc":[{"atb":[[4.8,12.96]],"id":9480385}],"con":true,"img":false,"tv":3983.9}]}
{"op":"mcm","clk":"1147491174","pt":1439886821395,"mc":[{"id":"1.120089104","rc":[{"atl":[[1.24,4.72]],"id":9612932}],"con":true,"img":false,"tv":3983.9}]}
{"op":"mcm","clk":"1147491240","pt":1439886829224,"mc":[{"id":"1.120089104","rc":[{"atb":[[5.1,2.48]],"id":9480385}],"con":true,"img":false,"tv":3983.9}]}
{"op":"mcm","clk":"1147491243","pt":1439886829328,"mc":[{"id":"1.120089104","rc":[{"atb":[[5.4,18.8]],"id":9480385}],"con":true,"img":false,"tv":3983.9}]}
{"op":"mcm","clk":"1147494605","pt":1439886864897,"mc":[{"id":"1.120089104","marketDefinition":{"bspMarket":true,"turnInPlayEnabled":true,"persistenceEnabled":true,"marketBaseRate":5.0,"eventId":"27514783","eventTypeId":"7","numberOfWinners":1,"bettingType":"ODDS","marketType":"WIN","marketTime":"2015-08-18T20:20:00.000Z","suspendTime":"2015-08-18T20:20:00.000Z","bspReconciled":false,"complete":true,"inPlay":false,"crossMatching":false,"runnersVoidable":false,"numberOfActiveRunners":2,"betDelay":0,"status":"OPEN","runners":[{"adjustmentFactor":79.72,"status":"ACTIVE","sortPriority":1,"id":9612932,"name":"Alinstante"},{"adjustmentFactor":20.27,"status":"ACTIVE","sortPriority":2,"id":9480385,"name":"Vallance Road"}],"regulators":["MR_INT"],"venue":"Chelmsford City","countryCode":"GB","discountAllowed":false,"timezone":"Europe/London","openDate":"2015-08-18T17:20:00.000Z","version":1060767560,"name":"1m Cond Stks","eventName":"ChelmC 18th Aug"},"rc":[{"trd":[[1.19,45.87],[1.23,308.16],[1.3,209.95],[1.29,101.96],[1.22,92.67],[1.24,790.01],[1.2,25.81],[1.4,49.38],[1.28,1000.74],[1.27,15.79],[1.25,311.17],[1.26,83.54],[1.21,139.62]],"ltp":1.19,"tv":3174.67,"id":9612932},{"atb":[[1.17,100],[1.16,44.84],[1.04,240],[1.18,46.01],[1.06,20],[1.14,56.91],[1.01,1752.89],[1.13,236.51],[1.15,108.73],[1.02,16070],[1.03,11],[1.12,1524.5],[1.08,10],[1.11,270.8]],"id":9612932},{"atl":[[1.29,8.32],[1.3,95.06],[19.5,11],[630,0.09],[1.4,500],[1000,1],[1.27,142.28],[1.25,290.49],[1.26,142.28],[5.2,15],[46,2],[1.69,15],[1.24,4.72],[4,0.25],[1.46,2.35],[900,0.2]],"id":9612932},{"spl":[[1.88,20.11],[1.01,123.48],[1.25,2]],"id":9612932},{"spn":1.17,"spf":1.0,"id":9612932},{"trd":[[5.4,11.31],[4.9,12.01],[5.2,35.66],[4.7,103.85],[5.1,136.97],[4.8,120.86],[5.6,16.38],[5.3,25.26],[5.5,13.28],[5,333.54]],"ltp":5.4,"tv":809.12,"id":9480385},{"atb":[[1.43,1250],[2.6,1.9],[4.9,72.56],[5.4,18.8],[1.06,20],[1.18,30],[1.81,12.35],[1.01,1726.53],[4.8,12.96],[1.02,10250],[1.03,11],[3.4,2.35],[2.16,30],[1.08,10],[4.7,13.7],[4.2,43.93],[5.1,2.48],[2.92,175],[4,1.81],[4.1,34.94],[4.6,0.11],[5,199.08]],"id":9480385},{"atl":[[7.8,6.84],[630,0.09],[9.2,2.35],[5.8,0.08],[6,0.07],[7.6,7.51],[46,2],[6.6,0.06],[55,0.01],[90,2],[11.5,0.83],[10.5,15],[5.6,0.08],[5.5,10],[900,0.2]],"id":9480385},{"spn":5.45,"spf":"NaN","id":9480385}],"con":true,"img":true,"tv":3983.9}]}
{"op":"mcm","clk":"1147499676","pt":1439886866762,"mc":[{"id":"1.120089104","rc":[{"atl":[[1.24,1.72]],"id":9612932},{"spn":1.17,"spf":1.0,"id":9612932},{"spn":5.45,"spf":"NaN","id":9480385}],"con":true,"img":false,"tv":3983.9}]}
{"op":"mcm","clk":"1147499870","pt":1439886879566,"mc":[{"id":"1.120089104","rc":[{"atb":[[4.1,0]],"id":9480385}],"con":true,"img":false,"tv":3983.9}]}
{"op":"mcm","clk":"1147499872","pt":1439886879774,"mc":[{"id":"1.120089104","rc":[{"atb":[[4.4,29.29]],"id":9480385}],"con":true,"img":false,"tv":3983.9}]}
{"op":"mcm","clk":"1147499994","pt":1439886890524,"mc":[{"id":"1.120089104","rc":[{"atl":[[1.24,4.72]],"id":9612932}],"con":true,"img":false,"tv":3983.9}]}
{"op":"mcm","clk":"1147500314","pt":1439886916667,"mc":[{"id":"1.120089104","rc":[{"atb":[[1.19,8.09]],"id":9612932}],"con":true,"img":false,"tv":3983.9}]}
{"op":"mcm","clk":"1147500690","pt":1439886944433,"mc":[{"id":"1.120089104","rc":[{"spn":1.17,"spf":1.0,"id":9612932},{"trd":[[5.4,25.57]],"ltp":5.4,"tv":25.57,"id":9480385},{"atb":[[5.4,11.67]],"id":9480385}],"con":true,"img":false,"tv":3998.15}]}
{"op":"mcm","clk":"1147501198","pt":1439886982118,"mc":[{"id":"1.120089104","rc":[{"atb":[[1.2,250]],"id":9612932}],"con":true,"img":false,"tv":3998.15}]}
{"op":"mcm","clk":"1147501242","pt":1439886985352,"mc":[{"id":"1.120089104","rc":[{"atb":[[5.4,4.85]],"id":9480385}],"con":true,"img":false,"tv":3998.15}]}
{"op":"mcm","clk":"1147501257","pt":1439886986712,"mc":[{"id":"1.120089104","rc":[{"atb":[[1.19,0]],"id":9612932}],"con":true,"img":false,"tv":3998.15}]}
{"op":"mcm","clk":"1147501296","pt":1439886989482,"mc":[{"id":"1.120089104","rc":[{"atb":[[1.16,71.53]],"id":9612932}],"con":true,"img":false,"tv":3998.15}]}
{"op":"mcm","clk":"1147501298","pt":1439886989699,"mc":[{"id":"1.120089104","rc":[{"atb":[[1.14,0]],"id":9612932}],"con":true,"img":false,"tv":3998.15}]}
{"op":"mcm","clk":"1147502126","pt":1439887048952,"mc":[{"id":"1.120089104","rc":[{"spn":1.2,"spf":1.0,"id":9612932},{"atb":[[4.8,23.71]],"id":9480385}],"con":true,"img":false,"tv":3998.15}]}
{"op":"mcm","clk":"1147502129","pt":1439887049110,"mc":[{"id":"1.120089104","rc":[{"atb":[[4.8,10.75]],"id":9480385}],"con":true,"img":false,"tv":3998.15}]}
{"op":"mcm","clk":"1147502215","pt":1439887054379,"mc":[{"id":"1.120089104","rc":[{"atb":[[4.8,18.85]],"id":9480385}],"con":true,"img":false,"tv":3998.15}]}
{"op":"mcm","clk":"1147502218","pt":1439887054590,"mc":[{"id":"1.120089104","rc":[{"atb":[[4.8,8.09]],"id":9480385}],"con":true,"img":false,"tv":3998.15}]}
{"op":"mcm","clk":"1147502666","pt":1439887082112,"mc":[{"id":"1.120089104","rc":[{"spl":[[1.01,133.48]],"id":9612932}],"con":true,"img":false,"tv":3998.15}]}
{"op":"mcm","clk":"1147503006","pt":1439887109028,"mc":[{"id":"1.120089104","rc":[{"atb":[[1.01,1754.89]],"id":9612932}],"con":true,"img":false,"tv":3998.15}]}
{"op":"mcm","clk":"1147503007","pt":1439887109133,"mc":[{"id":"1.120089104","rc":[{"atb":[[1.01,1752.91]],"id":9612932}],"con":true,"img":false,"tv":3998.15}]}
{"op":"mcm","clk":"1147503008","pt":1439887109243,"mc":[{"id":"1.120089104","rc":[{"atb":[[1.01,1752.89]],"id":9612932}],"con":true,"img":false,"tv":3998.15}]}
{"op":"mcm","clk":"1147503010","pt":1439887109346,"mc":[{"id":"1.120089104","rc":[{"trd":[[1.24,790.05]],"ltp":1.24,"tv":790.05,"id":9612932},{"atl":[[1.24,4.7]],"id":9612932}],"con":true,"img":false,"tv":3998.2}]}
{"op":"mcm","clk":"1147503772","pt":1439887175883,"mc":[{"id":"1.120089104","rc":[{"atb":[[1.21,2.68]],"id":9612932},{"spn":1.2,"spf":1.0,"id":9612932}],"con":true,"img":false,"tv":3998.2}]}
{"op":"mcm","clk":"1147503843","pt":1439887182055,"mc":[{"id":"1.120089104","rc":[{"atl":[[1.24,1.7]],"id":9612932}],"con":true,"img":false,"tv":3998.2}]}
{"op":"mcm","clk":"1147504486","pt":1439887232495,"mc":[{"id":"1.120089104","rc":[{"atb":[[1.11,0]],"id":9612932}],"con":true,"img":false,"tv":3998.2}]}
{"op":"mcm","clk":"1147504492","pt":1439887233018,"mc":[{"id":"1.120089104","rc":[{"atb":[[1.13,465.65]],"id":9612932}],"con":true,"img":false,"tv":3998.2}]}
{"op":"mcm","clk":"1147506449","pt":1439887396629,"mc":[{"id":"1.120089104","rc":[{"atb":[[1.01,1754.99]],"id":9612932},{"atl":[[1000,2.1]],"id":9480385}],"con":true,"img":false,"tv":3998.2}]}
{"op":"mcm","clk":"1147506455","pt":1439887396945,"mc":[{"id":"1.120089104","rc":[{"atb":[[1.01,1754.88]],"id":9612932},{"atl":[[1000,1.89]],"id":9480385}],"con":true,"img":false,"tv":3998.2}]}
{"op":"mcm","clk":"1147506459","pt":1439887397363,"mc":[{"id":"1.120089104","rc":[{"atb":[[1.01,1752.89]],"id":9612932},{"atl":[[1000,0]],"id":9480385}],"con":true,"img":false,"tv":3998.2}]}
{"op":"mcm","clk":"1147506461","pt":1439887397415,"mc":[{"id":"1.120089104","rc":[{"atb":[[1.2,251.99]],"id":9612932},{"atl":[[6,1.96]],"id":9480385}],"con":true,"img":false,"tv":3998.2}]}
{"op":"mcm","clk":"1147507080","pt":1439887446051,"mc":[{"id":"1.120089104","marketDefinition":{"bspMarket":true,"turnInPlayEnabled":true,"persistenceEnabled":true,"marketBaseRate":5.0,"eventId":"27514783","eventTypeId":"7","numberOfWinners":1,"bettingType":"ODDS","marketType":"WIN","marketTime":"2015-08-18T20:20:00.000Z","suspendTime":"2015-08-18T20:20:00.000Z","bspReconciled":false,"complete":true,"inPlay":false,"crossMatching":false,"runnersVoidable":false,"numberOfActiveRunners":2,"betDelay":0,"status":"SUSPENDED","runners":[{"adjustmentFactor":79.72,"status":"ACTIVE","sortPriority":1,"id":9612932,"name":"Alinstante"},{"adjustmentFactor":20.27,"status":"ACTIVE","sortPriority":2,"id":9480385,"name":"Vallance Road"}],"regulators":["MR_INT"],"venue":"Chelmsford City","countryCode":"GB","discountAllowed":true,"timezone":"Europe/London","openDate":"2015-08-18T17:20:00.000Z","version":1061399005,"name":"1m Cond Stks","eventName":"ChelmC 18th Aug"},"rc":[],"con":true,"img":false,"tv":3998.2}]}
{"op":"mcm","clk":"1147507797","pt":1439887526050,"mc":[{"id":"1.120089104","marketDefinition":{"bspMarket":true,"turnInPlayEnabled":true,"persistenceEnabled":true,"marketBaseRate":5.0,"eventId":"27514783","eventTypeId":"7","numberOfWinners":1,"bettingType":"ODDS","marketType":"WIN","marketTime":"2015-08-18T20:20:00.000Z","suspendTime":"2015-08-18T20:20:00.000Z","bspReconciled":false,"complete":true,"inPlay":false,"crossMatching":false,"runnersVoidable":false,"numberOfActiveRunners":2,"betDelay":0,"status":"SUSPENDED","runners":[{"adjustmentFactor":79.72,"status":"ACTIVE","sortPriority":1,"id":9612932,"name":"Alinstante"},{"adjustmentFactor":20.27,"status":"ACTIVE","sortPriority":2,"id":9480385,"name":"Vallance Road"}],"regulators":["MR_NJ","MR_INT"],"venue":"Chelmsford City","countryCode":"GB","discountAllowed":true,"timezone":"Europe/London","openDate":"2015-08-18T17:20:00.000Z","version":1061399087,"name":"1m Cond Stks","eventName":"ChelmC 18th Aug"},"rc":[],"con":true,"img":false,"tv":3998.2}]}
{"op":"mcm","clk":"1147507911","pt":1439887546324,"mc":[{"id":"1.120089104","marketDefinition":{"bspMarket":true,"turnInPlayEnabled":true,"persistenceEnabled":true,"marketBaseRate":5.0,"eventId":"27514783","eventTypeId":"7","numberOfWinners":1,"bettingType":"ODDS","marketType":"WIN","marketTime":"2015-08-18T20:20:00.000Z","suspendTime":"2015-08-18T20:20:00.000Z","bspReconciled":false,"complete":true,"inPlay":false,"crossMatching":false,"runnersVoidable":false,"numberOfActiveRunners":2,"betDelay":0,"status":"OPEN","runners":[{"adjustmentFactor":79.72,"status":"ACTIVE","sortPriority":1,"id":9612932,"name":"Alinstante"},{"adjustmentFactor":20.27,"status":"ACTIVE","sortPriority":2,"id":9480385,"name":"Vallance Road"}],"regulators":["MR_NJ","MR_INT"],"venue":"Chelmsford City","countryCode":"GB","discountAllowed":true,"timezone":"Europe/London","openDate":"2015-08-18T17:20:00.000Z","version":1061399117,"name":"1m Cond Stks","eventName":"ChelmC 18th Aug"},"rc":[],"con":true,"img":false,"tv":3998.2}]}
{"op":"mcm","clk":"1147507926","pt":1439887546937,"mc":[{"id":"1.120089104","rc":[{"atb":[[4.8,10.8]],"id":9480385}],"con":true,"img":false,"tv":3998.2}]}
{"op":"mcm","clk":"1147507933","pt":1439887547138,"mc":[{"id":"1.120089104","rc":[{"atl":[[1.29,6]],"id":9612932},{"atb":[[4.8,2.71]],"id":9480385},{"atl":[[7.6,0]],"id":9480385}],"con":true,"img":false,"tv":3998.2}]}
{"op":"mcm","clk":"1147508425","pt":1439887589916,"mc":[{"id":"1.120089104","rc":[{"atl":[[1.29,16.5]],"id":9612932},{"atl":[[7.6,7.51]],"id":9480385}],"con":true,"img":false,"tv":3998.2}]}
{"op":"mcm","clk":"1147508437","pt":1439887590699,"mc":[{"id":"1.120089104","rc":[{"spl":[[1.01,183.48]],"id":9612932}],"con":true,"img":false,"tv":3998.2}]}
{"op":"mcm","clk":"1147508664","pt":1439887611451,"mc":[{"id":"1.120089104","rc":[{"spl":[[1.01,188.48]],"id":9612932}],"con":true,"img":false,"tv":3998.2}]}
{"op":"mcm","clk":"1147508739","pt":1439887622209,"mc":[{"id":"1.120089104","rc":[{"spl":[[1.01,338.48]],"id":9612932}],"con":true,"img":false,"tv":3998.2}]}
{"op":"mcm","clk":"1147513442","pt":1439887764899,"mc":[{"id":"1.120089104","marketDefinition":{"bspMarket":true,"turnInPlayEnabled":true,"persistenceEnabled":true,"marketBaseRate":5.0,"eventId":"27514783","eventTypeId":"7","numberOfWinners":1,"bettingType":"ODDS","marketType":"WIN","marketTime":"2015-08-18T20:20:00.000Z","suspendTime":"2015-08-18T20:20:00.000Z","bspReconciled":false,"complete":true,"inPlay":false,"crossMatching":false,"runnersVoidable":false,"numberOfActiveRunners":2,"betDelay":0,"status":"OPEN","runners":[{"adjustmentFactor":79.72,"status":"ACTIVE","sortPriority":1,"id":9612932,"name":"Alinstante"},{"adjustmentFactor":20.27,"status":"ACTIVE","sortPriority":2,"id":9480385,"name":"Vallance Road"}],"regulators":["MR_NJ","MR_INT"],"venue":"Chelmsford City","countryCode":"GB","discountAllowed":true,"timezone":"Europe/London","openDate":"2015-08-18T17:20:00.000Z","version":1061399117,"name":"1m Cond Stks","eventName":"ChelmC 18th Aug"},"rc":[{"trd":[[1.24,790.05],[1.23,308.16],[1.3,209.95],[1.29,101.96],[1.22,92.67],[1.2,25.81],[1.4,49.38],[1.19,45.87],[1.28,1000.74],[1.27,15.79],[1.25,311.17],[1.26,83.54],[1.21,139.62]],"ltp":1.24,"tv":3174.71,"id":9612932},{"atb":[[1.17,100],[1.16,71.53],[1.04,240],[1.18,46.01],[1.06,20],[1.01,1752.89],[1.13,465.65],[1.15,108.73],[1.02,16070],[1.03,11],[1.12,1524.5],[1.08,10],[1.2,251.99],[1.21,2.68]],"id":9612932},{"atl":[[1.29,16.5],[1.3,95.06],[19.5,11],[630,0.09],[1.4,500],[1000,1],[1.27,142.28],[1.25,290.49],[1.26,142.28],[5.2,15],[46,2],[1.69,15],[1.24,1.7],[4,0.25],[1.46,2.35],[900,0.2]],"id":9612932},{"spl":[[1.88,20.11],[1.01,338.48],[1.25,2]],"id":9612932},{"spn":1.19,"spf":1.0,"id":9612932},{"trd":[[5.4,25.57],[4.9,12.01],[5.2,35.66],[4.7,103.85],[5.1,136.97],[4.8,120.86],[5.6,16.38],[5.3,25.26],[5.5,13.28],[5,333.54]],"ltp":5.4,"tv":823.38,"id":9480385},{"atb":[[4.4,29.29],[1.43,1250],[2.6,1.9],[4.9,72.56],[5.4,4.85],[1.06,20],[1.18,30],[1.81,12.35],[1.01,1726.53],[4.8,2.71],[1.02,10250],[1.03,11],[3.4,2.35],[2.16,30],[1.08,10],[4.7,13.7],[4.2,43.93],[5.1,2.48],[2.92,175],[4,1.81],[4.6,0.11],[5,199.08]],"id":9480385},{"atl":[[7.8,6.84],[630,0.09],[9.2,2.35],[5.8,0.08],[6,1.96],[7.6,7.51],[46,2],[6.6,0.06],[55,0.01],[90,2],[11.5,0.83],[10.5,15],[5.6,0.08],[5.5,10],[900,0.2]],"id":9480385},{"spn":5.45,"spf":"NaN","id":9480385}],"con":true,"img":true,"tv":3998.2}]}
{"op":"mcm","clk":"1147519393","pt":1439887837017,"mc":[{"id":"1.120089104","rc":[{"atb":[[1.21,38.8]],"id":9612932},{"spn":1.19,"spf":1.0,"id":9612932}],"con":true,"img":false,"tv":3998.2}]}
{"op":"mcm","clk":"1147521245","pt":1439887967842,"mc":[{"id":"1.120089104","rc":[{"atb":[[1.18,67.46]],"id":9612932}],"con":true,"img":false,"tv":3998.2}]}
{"op":"mcm","clk":"1147521251","pt":1439887968054,"mc":[{"id":"1.120089104","rc":[{"atb":[[1.16,44.84]],"id":9612932}],"con":true,"img":false,"tv":3998.2}]}
{"op":"mcm","clk":"1147521372","pt":1439887974826,"mc":[{"id":"1.120089104","rc":[{"spl":[[1.01,638.48]],"id":9612932}],"con":true,"img":false,"tv":3998.2}]}
{"op":"mcm","clk":"1147522335","pt":1439888039782,"mc":[{"id":"1.120089104","rc":[{"spn":1.17,"spf":1.0,"id":9612932},{"atl":[[6,0.07]],"id":9480385}],"con":true,"img":false,"tv":3998.2}]}
{"op":"mcm","clk":"1147522337","pt":1439888039888,"mc":[{"id":"1.120089104","rc":[{"atl":[[5.9,1.89]],"id":9480385}],"con":true,"img":false,"tv":3998.2}]}
{"op":"mcm","clk":"1147524985","pt":1439888212836,"mc":[{"id":"1.120089104","rc":[{"atl":[[1.26,542.28]],"id":9612932}],"con":true,"img":false,"tv":3998.2}]}
{"op":"mcm","clk":"1147525488","pt":1439888239269,"mc":[{"id":"1.120089104","rc":[{"atl":[[1.24,201.7]],"id":9612932}],"con":true,"img":false,"tv":3998.2}]}
{"op":"mcm","clk":"1147525936","pt":1439888268492,"mc":[{"id":"1.120089104","rc":[{"atb":[[4.8,6.82]],"id":9480385}],"con":true,"img":false,"tv":3998.2}]}
{"op":"mcm","clk":"1147525939","pt":1439888268703,"mc":[{"id":"1.120089104","rc":[{"atb":[[4.8,4.11]],"id":9480385}],"con":true,"img":false,"tv":3998.2}]}
{"op":"mcm","clk":"1147526984","pt":1439888351053,"mc":[{"id":"1.120089104","rc":[{"trd":[[5.4,29.57]],"ltp":5.4,"tv":29.57,"id":9480385},{"atb":[[5.4,2.85]],"id":9480385}],"con":true,"img":false,"tv":4002.2}]}
{"op":"mcm","clk":"1147527324","pt":1439888372786,"mc":[{"id":"1.120089104","rc":[{"atb":[[2.6,2.3]],"id":9480385}],"con":true,"img":false,"tv":4002.2}]}
{"op":"mcm","clk":"1147527396","pt":1439888378516,"mc":[{"id":"1.120089104","rc":[{"atb":[[2.6,1.9]],"id":9480385}],"con":true,"img":false,"tv":4002.2}]}
{"op":"mcm","clk":"1147527398","pt":1439888378617,"mc":[{"id":"1.120089104","rc":[{"atb":[[5.4,3.25]],"id":9480385}],"con":true,"img":false,"tv":4002.2}]}
{"op":"mcm","clk":"1147527455","pt":1439888383298,"mc":[{"id":"1.120089104","rc":[{"atl":[[1000,2.84]],"id":9480385}],"con":true,"img":false,"tv":4002.2}]}
{"op":"mcm","clk":"1147527457","pt":1439888383505,"mc":[{"id":"1.120089104","rc":[{"atl":[[1000,1.96]],"id":9480385}],"con":true,"img":false,"tv":4002.2}]}
{"op":"mcm","clk":"1147527458","pt":1439888383713,"mc":[{"id":"1.120089104","rc":[{"atl":[[1000,0]],"id":9480385}],"con":true,"img":false,"tv":4002.2}]}
{"op":"mcm","clk":"1147527459","pt":1439888383818,"mc":[{"id":"1.120089104","rc":[{"atl":[[5.5,11.96]],"id":9480385}],"con":true,"img":false,"tv":4002.2}]}
{"op":"mcm","clk":"1147527463","pt":1439888383978,"mc":[{"id":"1.120089104","rc":[{"atb":[[5.4,0.4]],"id":9480385}],"con":true,"img":false,"tv":4002.2}]}
{"op":"mcm","clk":"1147527469","pt":1439888384287,"mc":[{"id":"1.120089104","rc":[{"atb":[[5.4,4.76]],"id":9480385}],"con":true,"img":false,"tv":4002.2}]}
{"op":"mcm","clk":"1147527538","pt":1439888388044,"mc":[{"id":"1.120089104","rc":[{"atb":[[5.4,4.36]],"id":9480385}],"con":true,"img":false,"tv":4002.2}]}
{"op":"mcm","clk":"1147527689","pt":1439888396890,"mc":[{"id":"1.120089104","rc":[{"atl":[[70,2]],"id":9480385}],"con":true,"img":false,"tv":4002.2}]}
{"op":"mcm","clk":"1147527753","pt":1439888401062,"mc":[{"id":"1.120089104","rc":[{"atl":[[70,2.4]],"id":9480385}],"con":true,"img":false,"tv":4002.2}]}
{"op":"mcm","clk":"1147527827","pt":1439888405193,"mc":[{"id":"1.120089104","rc":[{"atl":[[70,2]],"id":9480385}],"con":true,"img":false,"tv":4002.2}]}
{"op":"mcm","clk":"1147527831","pt":1439888405299,"mc":[{"id":"1.120089104","rc":[{"trd":[[5.4,30.36]],"ltp":5.4,"tv":30.36,"id":9480385},{"atb":[[5.4,3.96]],"id":9480385}],"con":true,"img":false,"tv":4002.99}]}
{"op":"mcm","clk":"1147529104","pt":1439888482209,"mc":[{"id":"1.120089104","rc":[{"atb":[[1.01,1754.79]],"id":9612932},{"spl":[[1.01,638.44]],"id":9612932}],"con":true,"img":false,"tv":4002.99}]}
{"op":"mcm","clk":"1147529175","pt":1439888487168,"mc":[{"id":"1.120089104","rc":[{"atb":[[1.01,1752.89]],"id":9612932}],"con":true,"img":false,"tv":4002.99}]}
{"op":"mcm","clk":"1147529176","pt":1439888487274,"mc":[{"id":"1.120089104","rc":[{"atb":[[1.22,1.9]],"id":9612932}],"con":true,"img":false,"tv":4002.99}]}
{"op":"mcm","clk":"1147529568","pt":1439888514517,"mc":[{"id":"1.120089104","rc":[{"atb":[[1.12,694.49]],"id":9612932}],"con":true,"img":false,"tv":4002.99}]}
{"op":"mcm","clk":"1147529569","pt":1439888514623,"mc":[{"id":"1.120089104","rc":[{"atb":[[1.14,711.43]],"id":9612932}],"con":true,"img":false,"tv":4002.99}]}
{"op":"mcm","clk":"1147529717","pt":1439888525526,"mc":[{"id":"1.120089104","rc":[{"atb":[[1.12,440.4]],"id":9612932}],"con":true,"img":false,"tv":4002.99}]}
{"op":"mcm","clk":"1147529722","pt":1439888525943,"mc":[{"id":"1.120089104","rc":[{"atb":[[1.14,921.72]],"id":9612932}],"con":true,"img":false,"tv":4002.99}]}
{"op":"mcm","clk":"1147530454","pt":1439888571026,"mc":[{"id":"1.120089104","rc":[{"trd":[[1.21,141.82],[1.22,96.47]],"ltp":1.21,"tv":238.29,"id":9612932},{"atb":[[1.22,0],[1.21,37.69]],"id":9612932},{"spn":1.17,"spf":1.0,"id":9612932}],"con":true,"img":false,"tv":4008.99}]}
{"op":"mcm","clk":"1147531005","pt":1439888610416,"mc":[{"id":"1.120089104","rc":[{"atl":[[1000,2.84]],"id":9480385}],"con":true,"img":false,"tv":4008.99}]}
{"op":"mcm","clk":"1147531011","pt":1439888610623,"mc":[{"id":"1.120089104","rc":[{"atl":[[1000,0.39]],"id":9480385}],"con":true,"img":false,"tv":4008.99}]}
{"op":"mcm","clk":"1147531019","pt":1439888610830,"mc":[{"id":"1.120089104","rc":[{"atl":[[1000,0]],"id":9480385}],"con":true,"img":false,"tv":4008.99}]}
{"op":"mcm","clk":"1147531021","pt":1439888610935,"mc":[{"id":"1.120089104","rc":[{"atl":[[5.5,12.35]],"id":9480385}],"con":true,"img":false,"tv":4008.99}]}
{"op":"mcm","clk":"1147531313","pt":1439888632378,"mc":[{"id":"1.120089104","rc":[{"atb":[[1.13,236.51]],"id":9612932}],"con":true,"img":false,"tv":4008.99}]}
{"op":"mcm","clk":"1147531319","pt":1439888632795,"mc":[{"id":"1.120089104","rc":[{"atb":[[1.13,1308.69]],"id":9612932}],"con":true,"img":false,"tv":4008.99}]}
{"op":"mcm","clk":"1147531327","pt":1439888633263,"mc":[{"id":"1.120089104","rc":[{"atb":[[4.2,34.62]],"id":9480385}],"con":true,"img":false,"tv":4008.99}]}
{"op":"mcm","clk":"1147531337","pt":1439888633785,"mc":[{"id":"1.120089104","rc":[{"atb":[[4.4,70.28]],"id":9480385}],"con":true,"img":false,"tv":4008.99}]}
{"op":"mcm","clk":"1147531368","pt":1439888636975,"mc":[{"id":"1.120089104","rc":[{"atb":[[4.5,6]],"id":9480385}],"con":true,"img":false,"tv":4008.99}]}
{"op":"mcm","clk":"1147531403","pt":1439888639216,"mc":[{"id":"1.120089104","rc":[{"atl":[[1.24,207.7]],"id":9612932}],"con":true,"img":false,"tv":4008.99}]}
{"op":"mcm","clk":"1147540183","pt":1439888698984,"mc":[{"id":"1.120089104","rc":[{"atl":[[1000,3]],"id":9612932}],"con":true,"img":false,"tv":4008.99}]}
{"op":"mcm","clk":"1147540186","pt":1439888699086,"mc":[{"id":"1.120089104","rc":[{"atl":[[1000,2]],"id":9612932}],"con":true,"img":false,"tv":4008.99}]}
{"op":"mcm","clk":"1147540187","pt":1439888699191,"mc":[{"id":"1.120089104","rc":[{"atl":[[1000,1]],"id":9612932}],"con":true,"img":false,"tv":4008.99}]}
{"op":"mcm","clk":"1147540188","pt":1439888699294,"mc":[{"id":"1.120089104","rc":[{"trd":[[1.21,143.82]],"ltp":1.21,"tv":143.82,"id":9612932},{"atb":[[1.21,36.69]],"id":9612932}],"con":true,"img":false,"tv":4010.99}]}
{"op":"mcm","clk":"1147541643","pt":1439888800163,"mc":[{"id":"1.120089104","rc":[{"trd":[[1.24,840.11]],"ltp":1.24,"tv":840.11,"id":9612932},{"atl":[[1.24,182.67]],"id":9612932},{"spn":1.17,"spf":1.0,"id":9612932}],"con":true,"img":false,"tv":4061.05}]}
{"op":"mcm","clk":"1147541679","pt":1439888803093,"mc":[{"id":"1.120089104","rc":[{"trd":[[1.21,193.82]],"ltp":1.21,"tv":193.82,"id":9612932},{"atb":[[1.21,11.69]],"id":9612932}],"con":true,"img":false,"tv":4111.05}]}
{"op":"mcm","clk":"1147541705","pt":1439888805294,"mc":[{"id":"1.120089104","rc":[{"atl":[[1.23,122]],"id":9612932}],"con":true,"img":false,"tv":4111.05}]}
{"op":"mcm","clk":"1147542095","pt":1439888839376,"mc":[{"id":"1.120089104","rc":[{"atl":[[1.24,176.67]],"id":9612932}],"con":true,"img":false,"tv":4111.05}]}
{"op":"mcm","clk":"1147542152","pt":1439888845307,"mc":[{"id":"1.120089104","rc":[{"trd":[[1.21,217.22]],"ltp":1.21,"tv":217.22,"id":9612932},{"atb":[[1.21,0]],"id":9612932},{"atl":[[1.21,18.3]],"id":9612932}],"con":true,"img":false,"tv":4134.45}]}
{"op":"mcm","clk":"1147542154","pt":1439888845826,"mc":[{"id":"1.120089104","rc":[{"trd":[[1.21,253.82]],"ltp":1.21,"tv":253.82,"id":9612932},{"atb":[[1.21,18.3]],"id":9612932},{"atl":[[1.21,0]],"id":9612932},{"trd":[[5.5,29.4]],"ltp":5.5,"tv":29.4,"id":9480385},{"atl":[[5.5,4.29]],"id":9480385}],"con":true,"img":false,"tv":4187.17}]}
{"op":"mcm","clk":"1147542252","pt":1439888854672,"mc":[{"id":"1.120089104","rc":[{"atl":[[7.6,13.95]],"id":9480385}],"con":true,"img":false,"tv":4187.17}]}
{"op":"mcm","clk":"1147542257","pt":1439888854884,"mc":[{"id":"1.120089104","rc":[{"atl":[[7.6,6.44]],"id":9480385}],"con":true,"img":false,"tv":4187.17}]}
{"op":"mcm","clk":"1147542424","pt":1439888867073,"mc":[{"id":"1.120089104","rc":[{"trd":[[1.23,402.09]],"ltp":1.23,"tv":402.09,"id":9612932},{"atl":[[1.23,75.04]],"id":9612932},{"spn":1.17,"spf":1.0,"id":9612932}],"con":true,"img":false,"tv":4281.1}]}
{"op":"mcm","clk":"1147543065","pt":1439888916036,"mc":[{"id":"1.120089104","rc":[{"atb":[[1.17,0]],"id":9612932}],"con":true,"img":false,"tv":4281.1}]}
{"op":"mcm","clk":"1147543069","pt":1439888916143,"mc":[{"id":"1.120089104","rc":[{"atb":[[1.21,118.3]],"id":9612932}],"con":true,"img":false,"tv":4281.1}]}
{"op":"mcm","clk":"1147548419","pt":1439889270650,"mc":[{"id":"1.120089104","rc":[{"spn":1.18,"spf":1.0,"id":9612932},{"atb":[[5.1,12.48]],"id":9480385}],"con":true,"img":false,"tv":4281.1}]}
{"op":"mcm","clk":"1147550766","pt":1439889407871,"mc":[{"id":"1.120089104","rc":[{"trd":[[1.23,400.69],[1.3,209.75],[1.29,101.62],[1.22,96.28],[1.24,836.16],[1.2,25.75],[1.19,45.78],[1.28,997.42],[1.27,15.74],[1.25,309.22],[1.26,83.08],[1.21,253.53]],"ltp":1.23,"tv":3375.02,"id":9612932},{"atb":[[1.16,44.77],[1.18,46],[1.14,915.59],[1.01,1751.52],[1.13,1301.8],[1.12,437.48]],"id":9612932},{"atl":[[1.29,16.43],[1.27,141.34],[1.25,288.99],[1.26,541.34],[1.46,2.34]],"id":9612932},{"spn":1.18,"spf":1.0,"id":9612932},{"trd":[[5.5,29.33],[4.9,11.97],[5.2,35.57],[4.7,103.47],[5.4,30.3],[5.1,136.79],[4.8,120.46],[5.6,16.34],[5.3,25.25],[5,331.36]],"ltp":5.5,"tv":840.84,"id":9480385},{"atb":[[4.4,69.87],[4.9,72.08],[5.4,3.94],[1.01,1725.18],[4.8,4.08],[3.4,2.34],[4.7,13.7],[4.2,34.41],[4.6,0.11],[5,197.76]],"id":9480385},{"atl":[[7.8,6.8],[9.2,2.34],[5.8,0.08],[6,0.07],[7.6,6.4],[6.6,0.06],[11.5,0.82],[5.6,0.08],[5.5,4.27]],"id":9480385}],"con":true,"img":false,"tv":4265.34}]}
{"op":"mcm","clk":"1147550838","pt":1439889412970,"mc":[{"id":"1.120089104","rc":[{"atb":[[1.17,11.09]],"id":9612932}],"con":true,"img":false,"tv":4265.34}]}
{"op":"mcm","clk":"1147551827","pt":1439889471802,"mc":[{"id":"1.120089104","rc":[{"atb":[[1.17,53.69]],"id":9612932},{"spn":1.18,"spf":1.0,"id":9612932}],"con":true,"img":false,"tv":4265.34}]}
{"op":"mcm","clk":"1147551831","pt":1439889472012,"mc":[{"id":"1.120089104","rc":[{"atb":[[1.17,42.6]],"id":9612932}],"con":true,"img":false,"tv":4265.34}]}
{"op":"mcm","clk":"1147553494","pt":1439889559805,"mc":[{"id":"1.120089104","rc":[{"spl":[[1.01,640.44]],"id":9612932},{"spn":1.18,"spf":1.0,"id":9612932}],"con":true,"img":false,"tv":4265.34}]}
{"op":"mcm","clk":"1147561461","pt":1439889565122,"mc":[{"id":"1.120089104","rc":[{"spl":[[7,10],[1.01,642.44]],"id":9612932},{"spl":[[7,10]],"id":9480385}],"con":true,"img":false,"tv":4265.34}]}
{"op":"mcm","clk":"1147562547","pt":1439889630786,"mc":[{"id":"1.120089104","rc":[{"atl":[[1.35,10]],"id":9612932},{"spn":1.18,"spf":1.0,"id":9612932},{"spn":5.45,"spf":1.0,"id":9480385}],"con":true,"img":false,"tv":4265.34}]}
{"op":"mcm","clk":"1147564692","pt":1439889768535,"mc":[{"id":"1.120089104","rc":[{"trd":[[1.21,257.53]],"ltp":1.21,"tv":257.53,"id":9612932},{"atb":[[1.21,116.3]],"id":9612932},{"spn":1.18,"spf":1.0,"id":9612932}],"con":true,"img":false,"tv":4269.34}]}
{"op":"mcm","clk":"1147564990","pt":1439889790997,"mc":[{"id":"1.120089104","rc":[{"atb":[[1.13,1091.42]],"id":9612932}],"con":true,"img":false,"tv":4269.34}]}
{"op":"mcm","clk":"1147565003","pt":1439889791362,"mc":[{"id":"1.120089104","rc":[{"atb":[[1.13,2645.92]],"id":9612932}],"con":true,"img":false,"tv":4269.34}]}
{"op":"mcm","clk":"1147565009","pt":1439889791779,"mc":[{"id":"1.120089104","rc":[{"atb":[[4.2,25.86]],"id":9480385}],"con":true,"img":false,"tv":4269.34}]}
{"op":"mcm","clk":"1147565017","pt":1439889792398,"mc":[{"id":"1.120089104","rc":[{"atb":[[4.4,129.31]],"id":9480385}],"con":true,"img":false,"tv":4269.34}]}
{"op":"mcm","clk":"1147566589","pt":1439889902427,"mc":[{"id":"1.120089104","rc":[{"atl":[[7.8,0]],"id":9480385}],"con":true,"img":false,"tv":4269.34}]}
{"op":"mcm","clk":"1147566592","pt":1439889902531,"mc":[{"id":"1.120089104","rc":[{"trd":[[5.4,38.19]],"ltp":5.4,"tv":38.19,"id":9480385},{"atb":[[5.4,0]],"id":9480385},{"atl":[[5.4,5.89]],"id":9480385}],"con":true,"img":false,"tv":4277.23}]}
{"op":"mcm","clk":"1147567229","pt":1439889943005,"mc":[{"id":"1.120089104","rc":[{"atl":[[1.29,53.14]],"id":9612932},{"atb":[[4.8,17.08]],"id":9480385}],"con":true,"img":false,"tv":4277.23}]}
{"op":"mcm","clk":"1147567232","pt":1439889943218,"mc":[{"id":"1.120089104","rc":[{"atl":[[1.29,42.7]],"id":9612932},{"atb":[[4.8,12.99]],"id":9480385}],"con":true,"img":false,"tv":4277.23}]}
{"op":"mcm","clk":"1147567611","pt":1439889966391,"mc":[{"id":"1.120089104","rc":[{"atl":[[5.5,3.89]],"id":9480385},{"spn":5.25,"spf":1.0,"id":9480385}],"con":true,"img":false,"tv":4277.23}]}
{"op":"mcm","clk":"1147567617","pt":1439889966496,"mc":[{"id":"1.120089104","rc":[{"atl":[[5.5,1.94]],"id":9480385}],"con":true,"img":false,"tv":4277.23}]}
{"op":"mcm","clk":"1147567873","pt":1439889980964,"mc":[{"id":"1.120089104","rc":[{"atl":[[5.4,0]],"id":9480385}],"con":true,"img":false,"tv":4277.23}]}
{"op":"mcm","clk":"1147567875","pt":1439889981069,"mc":[{"id":"1.120089104","rc":[{"atl":[[5.8,5.57]],"id":9480385}],"con":true,"img":false,"tv":4277.23}]}
{"op":"mcm","clk":"1147567975","pt":1439889988875,"mc":[{"id":"1.120089104","rc":[{"atb":[[5.2,3]],"id":9480385}],"con":true,"img":false,"tv":4277.23}]}
{"op":"mcm","clk":"1147568191","pt":1439890001064,"mc":[{"id":"1.120089104","rc":[{"atl":[[7.6,11.37]],"id":9480385}],"con":true,"img":false,"tv":4277.23}]}
{"op":"mcm","clk":"1147568193","pt":1439890001274,"mc":[{"id":"1.120089104","rc":[{"atl":[[7.6,4.97]],"id":9480385}],"con":true,"img":false,"tv":4277.23}]}
{"op":"mcm","clk":"1147568746","pt":1439890033565,"mc":[{"id":"1.120089104","rc":[{"atb":[[5,201.64]],"id":9480385},{"atl":[[5.8,8.91]],"id":9480385},{"spn":5.35,"spf":1.0,"id":9480385}],"con":true,"img":false,"tv":4277.23}]}
{"op":"mcm","clk":"1147569243","pt":1439890069641,"mc":[{"id":"1.120089104","rc":[{"atl":[[5.8,0.08]],"id":9480385}],"con":true,"img":false,"tv":4277.23}]}
{"op":"mcm","clk":"1147569244","pt":1439890069744,"mc":[{"id":"1.120089104","rc":[{"atl":[[7.4,6.91]],"id":9480385}],"con":true,"img":false,"tv":4277.23}]}
{"op":"mcm","clk":"1147569251","pt":1439890070160,"mc":[{"id":"1.120089104","rc":[{"atl":[[7.2,2.48]],"id":9480385}],"con":true,"img":false,"tv":4277.23}]}
{"op":"mcm","clk":"1147569255","pt":1439890070375,"mc":[{"id":"1.120089104","rc":[{"atl":[[7.6,0]],"id":9480385}],"con":true,"img":false,"tv":4277.23}]}
{"op":"mcm","clk":"1147570092","pt":1439890123677,"mc":[{"id":"1.120089104","rc":[{"atl":[[7.4,0]],"id":9480385}],"con":true,"img":false,"tv":4277.23}]}
{"op":"mcm","clk":"1147570094","pt":1439890123783,"mc":[{"id":"1.120089104","rc":[{"atl":[[5.8,8.91]],"id":9480385}],"con":true,"img":false,"tv":4277.23}]}
{"op":"mcm","clk":"1147570671","pt":1439890161232,"mc":[{"id":"1.120089104","rc":[{"atl":[[5.8,0.08]],"id":9480385}],"con":true,"img":false,"tv":4277.23}]}
{"op":"mcm","clk":"1147570674","pt":1439890161337,"mc":[{"id":"1.120089104","rc":[{"atl":[[7,7.31]],"id":9480385}],"con":true,"img":false,"tv":4277.23}]}
{"op":"mcm","clk":"1147570720","pt":1439890164494,"mc":[{"id":"1.120089104","rc":[{"atl":[[6.8,1.63]],"id":9480385}],"con":true,"img":false,"tv":4277.23}]}
{"op":"mcm","clk":"1147570722","pt":1439890164650,"mc":[{"id":"1.120089104","rc":[{"atl":[[7.2,0]],"id":9480385}],"con":true,"img":false,"tv":4277.23}]}
{"op":"mcm","clk":"1147571436","pt":1439890202154,"mc":[{"id":"1.120089104","rc":[{"trd":[[1.21,435.53]],"ltp":1.21,"tv":435.53,"id":9612932},{"atb":[[1.21,27.3]],"id":9612932},{"spn":1.17,"spf":1.0,"id":9612932}],"con":true,"img":false,"tv":4455.23}]}
{"op":"mcm","clk":"1147572334","pt":1439890240637,"mc":[{"id":"1.120089104","rc":[{"atb":[[1.21,327.3]],"id":9612932}],"con":true,"img":false,"tv":4455.23}]}
{"op":"mcm","clk":"1147572337","pt":1439890240951,"mc":[{"id":"1.120089104","rc":[{"atl":[[6.8,0]],"id":9480385}],"con":true,"img":false,"tv":4455.23}]}
{"op":"mcm","clk":"1147572450","pt":1439890246495,"mc":[{"id":"1.120089104","rc":[{"atl":[[7,8.93]],"id":9480385}],"con":true,"img":false,"tv":4455.23}]}
{"op":"mcm","clk":"1147572896","pt":1439890267428,"mc":[{"id":"1.120089104","rc":[{"atb":[[1.16,32.28]],"id":9612932},{"spn":1.2,"spf":1.0,"id":9612932}],"con":true,"img":false,"tv":4455.23}]}
{"op":"mcm","clk":"1147572897","pt":1439890267530,"mc":[{"id":"1.120089104","rc":[{"atb":[[1.22,11.88]],"id":9612932}],"con":true,"img":false,"tv":4455.23}]}
{"op":"mcm","clk":"1147573698","pt":1439890307782,"mc":[{"id":"1.120089104","rc":[{"atb":[[1.19,20.88]],"id":9612932}],"con":true,"img":false,"tv":4455.23}]}
{"op":"mcm","clk":"1147573703","pt":1439890307992,"mc":[{"id":"1.120089104","rc":[{"atb":[[1.17,0]],"id":9612932}],"con":true,"img":false,"tv":4455.23}]}
{"op":"mcm","clk":"1147573920","pt":1439890318474,"mc":[{"id":"1.120089104","rc":[{"atb":[[1.12,174.57]],"id":9612932}],"con":true,"img":false,"tv":4455.23}]}
{"op":"mcm","clk":"1147573931","pt":1439890319101,"mc":[{"id":"1.120089104","rc":[{"atb":[[1.14,1125.92]],"id":9612932}],"con":true,"img":false,"tv":4455.23}]}
{"op":"mcm","clk":"1147574325","pt":1439890335955,"mc":[{"id":"1.120089104","rc":[{"spl":[[1.01,648.44]],"id":9612932},{"spn":1.2,"spf":1.0,"id":9612932}],"con":true,"img":false,"tv":4455.23}]}
{"op":"mcm","clk":"1147574628","pt":1439890347464,"mc":[{"id":"1.120089104","rc":[{"atb":[[1.12,0]],"id":9612932}],"con":true,"img":false,"tv":4455.23}]}
{"op":"mcm","clk":"1147574645","pt":1439890348093,"mc":[{"id":"1.120089104","rc":[{"atb":[[1.14,1265.59]],"id":9612932}],"con":true,"img":false,"tv":4455.23}]}
{"op":"mcm","clk":"1147585209","pt":1439890482988,"mc":[{"id":"1.120089104","rc":[{"trd":[[1.23,455.29]],"ltp":1.23,"tv":455.29,"id":9612932},{"atl":[[1.23,47.74]],"id":9612932}],"con":true,"img":false,"tv":4509.83}]}
{"op":"mcm","clk":"1147585463","pt":1439890496910,"mc":[{"id":"1.120089104","rc":[{"atb":[[1.21,300]],"id":9612932}],"con":true,"img":false,"tv":4509.83}]}
{"op":"mcm","clk":"1147588226","pt":1439890620735,"mc":[{"id":"1.120089104","rc":[{"trd":[[1.22,100.28]],"ltp":1.22,"tv":100.28,"id":9612932},{"atb":[[1.22,9.88]],"id":9612932},{"spn":1.2,"spf":1.0,"id":9612932}],"con":true,"img":false,"tv":4513.83}]}
{"op":"mcm","clk":"1147588411","pt":1439890630098,"mc":[{"id":"1.120089104","rc":[{"trd":[[1.22,104.28]],"ltp":1.22,"tv":104.28,"id":9612932},{"atb":[[1.22,7.88]],"id":9612932}],"con":true,"img":false,"tv":4517.82}]}
{"op":"mcm","clk":"1147588856","pt":1439890653736,"mc":[{"id":"1.120089104","rc":[{"atl":[[1000,3]],"id":9612932}],"con":true,"img":false,"tv":4517.82}]}
{"op":"mcm","clk":"1147588860","pt":1439890653998,"mc":[{"id":"1.120089104","rc":[{"atl":[[1000,3.96]],"id":9612932}],"con":true,"img":false,"tv":4517.82}]}
{"op":"mcm","clk":"1147588863","pt":1439890654155,"mc":[{"id":"1.120089104","rc":[{"atl":[[1000,3]],"id":9612932}],"con":true,"img":false,"tv":4517.82}]}
{"op":"mcm","clk":"1147588866","pt":1439890654257,"mc":[{"id":"1.120089104","rc":[{"trd":[[1.22,106.2]],"ltp":1.22,"tv":106.2,"id":9612932},{"atb":[[1.22,6.93]],"id":9612932}],"con":true,"img":false,"tv":4519.74}]}
{"op":"mcm","clk":"1147588868","pt":1439890654468,"mc":[{"id":"1.120089104","rc":[{"atl":[[1000,1]],"id":9612932}],"con":true,"img":false,"tv":4519.74}]}
{"op":"mcm","clk":"1147589216","pt":1439890674032,"mc":[{"id":"1.120089104","rc":[{"atb":[[1.19,0]],"id":9612932}],"con":true,"img":false,"tv":4519.74}]}
{"op":"mcm","clk":"1147589351","pt":1439890679681,"mc":[{"id":"1.120089104","rc":[{"atb":[[1.18,71.2]],"id":9612932}],"con":true,"img":false,"tv":4519.74}]}
{"op":"mcm","clk":"1147589735","pt":1439890699277,"mc":[{"id":"1.120089104","rc":[{"trd":[[1.23,475.29]],"ltp":1.23,"tv":475.29,"id":9612932},{"atl":[[1.23,37.74]],"id":9612932},{"spn":1.2,"spf":1.0,"id":9612932}],"con":true,"img":false,"tv":4539.74}]}
{"op":"mcm","clk":"1147590141","pt":1439890727262,"mc":[{"id":"1.120089104","rc":[{"atb":[[1.15,70]],"id":9612932}],"con":true,"img":false,"tv":4539.74}]}
{"op":"mcm","clk":"1147590407","pt":1439890739877,"mc":[{"id":"1.120089104","rc":[{"trd":[[1.22,118.19]],"ltp":1.22,"tv":118.19,"id":9612932},{"atb":[[1.22,0.93]],"id":9612932},{"spl":[[1.01,654.44]],"id":9612932}],"con":true,"img":false,"tv":4551.74}]}
{"op":"mcm","clk":"1147590828","pt":1439890762273,"mc":[{"id":"1.120089104","rc":[{"trd":[[1.23,479.29]],"ltp":1.23,"tv":479.29,"id":9612932},{"atl":[[1.23,35.74]],"id":9612932},{"spn":1.2,"spf":1.0,"id":9612932}],"con":true,"img":false,"tv":4555.74}]}
{"op":"mcm","clk":"1147591330","pt":1439890787246,"mc":[{"id":"1.120089104","rc":[{"atb":[[1.18,90.01]],"id":9612932}],"con":true,"img":false,"tv":4555.74}]}
{"op":"mcm","clk":"1147591334","pt":1439890787456,"mc":[{"id":"1.120089104","rc":[{"atb":[[1.18,64.81]],"id":9612932}],"con":true,"img":false,"tv":4555.74}]}
{"op":"mcm","clk":"1147591413","pt":1439890792975,"mc":[{"id":"1.120089104","rc":[{"atb":[[1.18,46]],"id":9612932}],"con":true,"img":false,"tv":4555.74}]}
{"op":"mcm","clk":"1147591483","pt":1439890797927,"mc":[{"id":"1.120089104","rc":[{"atb":[[1.18,51.22]],"id":9612932}],"con":true,"img":false,"tv":4555.74}]}
{"op":"mcm","clk":"1147592432","pt":1439890850408,"mc":[{"id":"1.120089104","rc":[{"spl":[[1.01,679.44]],"id":9612932},{"spn":1.19,"spf":1.0,"id":9612932}],"con":true,"img":false,"tv":4555.74}]}
{"op":"mcm","clk":"1147595460","pt":1439891008288,"mc":[{"id":"1.120089104","rc":[{"spl":[[1.01,704.44]],"id":9612932},{"spn":1.19,"spf":1.0,"id":9612932}],"con":true,"img":false,"tv":4555.74}]}
{"op":"mcm","clk":"1147595839","pt":1439891028858,"mc":[{"id":"1.120089104","rc":[{"atb":[[4.8,22.05]],"id":9480385}],"con":true,"img":false,"tv":4555.74}]}
{"op":"mcm","clk":"1147595844","pt":1439891029017,"mc":[{"id":"1.120089104","rc":[{"atb":[[4.8,9.06]],"id":9480385}],"con":true,"img":false,"tv":4555.74}]}
{"op":"mcm","clk":"1147596010","pt":1439891036722,"mc":[{"id":"1.120089104","rc":[{"atl":[[5.2,0]],"id":9612932}],"con":true,"img":false,"tv":4555.74}]}
{"op":"mcm","clk":"1147596177","pt":1439891045549,"mc":[{"id":"1.120089104","rc":[{"atl":[[5.2,15]],"id":9612932}],"con":true,"img":false,"tv":4555.74}]}
{"op":"mcm","clk":"1147596986","pt":1439891093764,"mc":[{"id":"1.120089104","rc":[{"trd":[[1.21,733.67],[1.22,120.06]],"ltp":1.21,"tv":853.73,"id":9612932},{"atb":[[1.22,0],[1.21,150.93]],"id":9612932},{"spn":1.18,"spf":1.0,"id":9612932}],"con":true,"img":false,"tv":4855.74}]}
{"op":"mcm","clk":"1147598099","pt":1439891153687,"mc":[{"id":"1.120089104","rc":[{"atb":[[1.18,46]],"id":9612932}],"con":true,"img":false,"tv":4855.74}]}
{"op":"mcm","clk":"1147598200","pt":1439891159318,"mc":[{"id":"1.120089104","rc":[{"atb":[[1.17,27.12]],"id":9612932},{"spn":1.18,"spf":1.0,"id":9612932}],"con":true,"img":false,"tv":4855.74}]}
{"op":"mcm","clk":"1147598718","pt":1439891192095,"mc":[{"id":"1.120089104","rc":[{"trd":[[1.21,1035.53]],"ltp":1.21,"tv":1035.53,"id":9612932},{"atb":[[1.21,0]],"id":9612932},{"atl":[[1.21,369.07]],"id":9612932}],"con":true,"img":false,"tv":5157.6}]}
{"op":"mcm","clk":"1147598732","pt":1439891192785,"mc":[{"id":"1.120089104","rc":[{"trd":[[1.21,1054.23]],"ltp":1.21,"tv":1054.23,"id":9612932},{"atl":[[1.21,359.72]],"id":9612932},{"trd":[[5.6,16.51],[5.5,33.21]],"ltp":5.6,"tv":49.71,"id":9480385},{"atl":[[5.6,0],[5.5,0]],"id":9480385}],"con":true,"img":false,"tv":5180.35}]}
{"op":"mcm","clk":"1147598798","pt":1439891196335,"mc":[{"id":"1.120089104","rc":[{"atl":[[1.21,0]],"id":9612932}],"con":true,"img":false,"tv":5180.35}]}
{"op":"mcm","clk":"1147598820","pt":1439891197342,"mc":[{"id":"1.120089104","rc":[{"atl":[[5.2,0]],"id":9612932}],"con":true,"img":false,"tv":5180.35}]}
{"op":"mcm","clk":"1147598826","pt":1439891197714,"mc":[{"id":"1.120089104","rc":[{"atl":[[6.6,1.71]],"id":9480385}],"con":true,"img":false,"tv":5180.35}]}
{"op":"mcm","clk":"1147598833","pt":1439891197928,"mc":[{"id":"1.120089104","rc":[{"atl":[[7,7.31]],"id":9480385}],"con":true,"img":false,"tv":5180.35}]}
{"op":"mcm","clk":"1147599000","pt":1439891206549,"mc":[{"id":"1.120089104","rc":[{"atl":[[5.2,15]],"id":9612932}],"con":true,"img":false,"tv":5180.35}]}
{"op":"mcm","clk":"1147599008","pt":1439891207120,"mc":[{"id":"1.120089104","rc":[{"trd":[[1.2,529.73]],"ltp":1.2,"tv":529.73,"id":9612932},{"atb":[[1.2,0]],"id":9612932},{"atl":[[1.2,108.01]],"id":9612932}],"con":true,"img":false,"tv":5684.33}]}
{"op":"mcm","clk":"1147599037","pt":1439891208220,"mc":[{"id":"1.120089104","rc":[{"atl":[[6.6,0.06]],"id":9480385}],"con":true,"img":false,"tv":5684.33}]}
{"op":"mcm","clk":"1147599053","pt":1439891209468,"mc":[{"id":"1.120089104","rc":[{"atl":[[1.2,0]],"id":9612932}],"con":true,"img":false,"tv":5684.33}]}
{"op":"mcm","clk":"1147599123","pt":1439891213263,"mc":[{"id":"1.120089104","rc":[{"atl":[[7,22.19]],"id":9480385}],"con":true,"img":false,"tv":5684.33}]}
{"op":"mcm","clk":"1147599127","pt":1439891213471,"mc":[{"id":"1.120089104","rc":[{"atb":[[1.17,0]],"id":9612932}],"con":true,"img":false,"tv":5684.33}]}
{"op":"mcm","clk":"1147599147","pt":1439891214267,"mc":[{"id":"1.120089104","rc":[{"atb":[[5.2,6.01]],"id":9480385}],"con":true,"img":false,"tv":5684.33}]}
{"op":"mcm","clk":"1147599197","pt":1439891216763,"mc":[{"id":"1.120089104","rc":[{"atb":[[1.14,1056.7]],"id":9612932}],"con":true,"img":false,"tv":5684.33}]}
{"op":"mcm","clk":"1147599205","pt":1439891217179,"mc":[{"id":"1.120089104","rc":[{"atb":[[1.11,248.69]],"id":9612932}],"con":true,"img":false,"tv":5684.33}]}
{"op":"mcm","clk":"1147599239","pt":1439891219682,"mc":[{"id":"1.120089104","rc":[{"spn":1.14,"spf":1.0,"id":9612932},{"atb":[[1.01,1727.73]],"id":9480385},{"spn":5.5,"spf":1.0,"id":9480385}],"con":true,"img":false,"tv":5684.33}]}
{"op":"mcm","clk":"1147599248","pt":1439891220207,"mc":[{"id":"1.120089104","rc":[{"atb":[[1.01,1726.98]],"id":9480385}],"con":true,"img":false,"tv":5684.33}]}
{"op":"mcm","clk":"1147599252","pt":1439891220418,"mc":[{"id":"1.120089104","rc":[{"atb":[[1.01,1725.18]],"id":9480385}],"con":true,"img":false,"tv":5684.33}]}
{"op":"mcm","clk":"1147599256","pt":1439891220522,"mc":[{"id":"1.120089104","rc":[{"atb":[[5.3,1.8]],"id":9480385}],"con":true,"img":false,"tv":5684.33}]}
{"op":"mcm","clk":"1147599260","pt":1439891220573,"mc":[{"id":"1.120089104","rc":[{"trd":[[1.18,92]],"ltp":1.18,"tv":92.0,"id":9612932},{"atb":[[1.18,0]],"id":9612932},{"atl":[[1.18,162]],"id":9612932}],"con":true,"img":false,"tv":5776.33}]}
{"op":"mcm","clk":"1147599269","pt":1439891220888,"mc":[{"id":"1.120089104","rc":[{"atl":[[1.29,36.7]],"id":9612932}],"con":true,"img":false,"tv":5776.33}]}
{"op":"mcm","clk":"1147599270","pt":1439891221095,"mc":[{"id":"1.120089104","rc":[{"trd":[[1.18,133.24]],"ltp":1.18,"tv":133.24,"id":9612932},{"atb":[[1.12,6]],"id":9612932},{"atl":[[1.18,141.38]],"id":9612932},{"trd":[[6,0.15],[5.9,3.78],[5.8,0.16]],"ltp":6.0,"tv":4.09,"id":9480385},{"atb":[[1.01,1731.18]],"id":9480385},{"atl":[[5.9,0],[5.8,0],[6,0]],"id":9480385}],"con":true,"img":false,"tv":5821.67}]}
{"op":"mcm","clk":"1147599272","pt":1439891221304,"mc":[{"id":"1.120089104","rc":[{"atb":[[1.01,1727.22]],"id":9480385}],"con":true,"img":false,"tv":5821.67}]}
{"op":"mcm","clk":"1147599276","pt":1439891221511,"mc":[{"id":"1.120089104","rc":[{"atb":[[1.01,1729.22]],"id":9480385}],"con":true,"img":false,"tv":5821.67}]}
{"op":"mcm","clk":"1147599279","pt":1439891221617,"mc":[{"id":"1.120089104","rc":[{"atb":[[1.01,1727.18]],"id":9480385}],"con":true,"img":false,"tv":5821.67}]}
{"op":"mcm","clk":"1147599281","pt":1439891221722,"mc":[{"id":"1.120089104","rc":[{"atb":[[5.9,1.89],[5.8,0.08],[6,0.07],[1.01,1726.81]],"id":9480385}],"con":true,"img":false,"tv":5821.67}]}
{"op":"mcm","clk":"1147599285","pt":1439891221926,"mc":[{"id":"1.120089104","rc":[{"atb":[[1.01,1725.18]],"id":9480385}],"con":true,"img":false,"tv":5821.67}]}
{"op":"mcm","clk":"1147599288","pt":1439891222032,"mc":[{"id":"1.120089104","rc":[{"atb":[[5.9,0],[5.8,0],[6,0],[5.4,1.63]],"id":9480385}],"con":true,"img":false,"tv":5821.67}]}
{"op":"mcm","clk":"1147599302","pt":1439891223130,"mc":[{"id":"1.120089104","rc":[{"atl":[[1.18,0]],"id":9612932}],"con":true,"img":false,"tv":5821.67}]}
{"op":"mcm","clk":"1147599311","pt":1439891224177,"mc":[{"id":"1.120089104","rc":[{"atl":[[6.8,1.41]],"id":9480385}],"con":true,"img":false,"tv":5821.67}]}
{"op":"mcm","clk":"1147599313","pt":1439891224280,"mc":[{"id":"1.120089104","rc":[{"atb":[[1.12,22.51]],"id":9612932}],"con":true,"img":false,"tv":5821.67}]}
{"op":"mcm","clk":"1147599333","pt":1439891225584,"mc":[{"id":"1.120089104","rc":[{"atb":[[1.17,25.57]],"id":9612932},{"atl":[[1.22,24.52]],"id":9612932}],"con":true,"img":false,"tv":5821.67}]}
{"op":"mcm","clk":"1147599358","pt":1439891227667,"mc":[{"id":"1.120089104","rc":[{"atl":[[6.4,2]],"id":9480385}],"con":true,"img":false,"tv":5821.67}]}
{"op":"mcm","clk":"1147599382","pt":1439891228972,"mc":[{"id":"1.120089104","rc":[{"atb":[[1.14,917.04]],"id":9612932}],"con":true,"img":false,"tv":5821.67}]}
{"op":"mcm","clk":"1147599394","pt":1439891229599,"mc":[{"id":"1.120089104","rc":[{"atb":[[1.1,189.21]],"id":9612932}],"con":true,"img":false,"tv":5821.67}]}
{"op":"mcm","clk":"1147599404","pt":1439891230178,"mc":[{"id":"1.120089104","rc":[{"atb":[[4.2,19.32]],"id":9480385}],"con":true,"img":false,"tv":5821.67}]}
{"op":"mcm","clk":"1147599415","pt":1439891230800,"mc":[{"id":"1.120089104","rc":[{"atb":[[4.4,134.87]],"id":9480385}],"con":true,"img":false,"tv":5821.67}]}
{"op":"mcm","clk":"1147599486","pt":1439891234632,"mc":[{"id":"1.120089104","rc":[{"atb":[[5.2,3.01]],"id":9480385}],"con":true,"img":false,"tv":5821.67}]}
{"op":"mcm","clk":"1147599546","pt":1439891237353,"mc":[{"id":"1.120089104","rc":[{"trd":[[1.16,30.86],[1.17,51.14]],"ltp":1.16,"tv":82.0,"id":9612932},{"atb":[[1.17,0],[1.16,16.85]],"id":9612932}],"con":true,"img":false,"tv":5903.67}]}
{"op":"mcm","clk":"1147599633","pt":1439891240702,"mc":[{"id":"1.120089104","rc":[{"atb":[[5.2,0]],"id":9480385},{"atl":[[6.4,4.99]],"id":9480385}],"con":true,"img":false,"tv":5903.67}]}
{"op":"mcm","clk":"1147599672","pt":1439891244043,"mc":[{"id":"1.120089104","rc":[{"atb":[[1.14,210.33]],"id":9612932}],"con":true,"img":false,"tv":5903.67}]}
{"op":"mcm","clk":"1147599673","pt":1439891244146,"mc":[{"id":"1.120089104","rc":[{"atb":[[1.09,1099.33]],"id":9612932}],"con":true,"img":false,"tv":5903.67}]}
{"op":"mcm","clk":"1147599700","pt":1439891246448,"mc":[{"id":"1.120089104","rc":[{"atb":[[1.16,37.35]],"id":9612932},{"atb":[[5.5,1.98]],"id":9480385}],"con":true,"img":false,"tv":5903.67}]}
{"op":"mcm","clk":"1147599708","pt":1439891246760,"mc":[{"id":"1.120089104","rc":[{"atb":[[5.4,0]],"id":9480385}],"con":true,"img":false,"tv":5903.67}]}
{"op":"mcm","clk":"1147599711","pt":1439891246864,"mc":[{"id":"1.120089104","rc":[{"atb":[[5.6,1.63]],"id":9480385}],"con":true,"img":false,"tv":5903.67}]}
{"op":"mcm","clk":"1147599715","pt":1439891247178,"mc":[{"id":"1.120089104","rc":[{"atb":[[4.5,0]],"id":9480385}],"con":true,"img":false,"tv":5903.67}]}
{"op":"mcm","clk":"1147599850","pt":1439891254369,"mc":[{"id":"1.120089104","rc":[{"atl":[[6.8,0]],"id":9480385}],"con":true,"img":false,"tv":5903.67}]}
{"op":"mcm","clk":"1147599935","pt":1439891259427,"mc":[{"id":"1.120089104","rc":[{"atb":[[1.13,1579.49]],"id":9612932}],"con":true,"img":false,"tv":5903.67}]}
{"op":"mcm","clk":"1147599950","pt":1439891259796,"mc":[{"id":"1.120089104","rc":[{"atb":[[1.09,2540.34]],"id":9612932}],"con":true,"img":false,"tv":5903.67}]}
{"op":"mcm","clk":"1147600005","pt":1439891261222,"mc":[{"id":"1.120089104","rc":[{"atl":[[7,14.88]],"id":9480385}],"con":true,"img":false,"tv":5903.67}]}
{"op":"mcm","clk":"1147600009","pt":1439891261328,"mc":[{"id":"1.120089104","rc":[{"atl":[[6.4,2.99],[6.2,8.25]],"id":9480385}],"con":true,"img":false,"tv":5903.67}]}
{"op":"mcm","clk":"1147600148","pt":1439891266278,"mc":[{"id":"1.120089104","rc":[{"atl":[[1.29,60.69]],"id":9612932},{"atb":[[5.5,4.99]],"id":9480385},{"atl":[[6.4,0]],"id":9480385}],"con":true,"img":false,"tv":5903.67}]}
{"op":"mcm","clk":"1147600160","pt":1439891266592,"mc":[{"id":"1.120089104","rc":[{"atl":[[1.29,23.99]],"id":9612932},{"atl":[[7,0]],"id":9480385}],"con":true,"img":false,"tv":5903.67}]}
{"op":"mcm","clk":"1147600328","pt":1439891272101,"mc":[{"id":"1.120089104","rc":[{"atb":[[1.16,81.35]],"id":9612932}],"con":true,"img":false,"tv":5903.67}]}
{"op":"mcm","clk":"1147600397","pt":1439891274844,"mc":[{"id":"1.120089104","rc":[{"atl":[[1.22,39.2]],"id":9612932}],"con":true,"img":false,"tv":5903.67}]}
{"op":"mcm","clk":"1147600431","pt":1439891276645,"mc":[{"id":"1.120089104","rc":[{"atb":[[5.2,1.41]],"id":9480385}],"con":true,"img":false,"tv":5903.67}]}
{"op":"mcm","clk":"1147600437","pt":1439891276863,"mc":[{"id":"1.120089104","rc":[{"atb":[[4.8,0]],"id":9480385}],"con":true,"img":false,"tv":5903.67}]}
{"op":"mcm","clk":"1147600650","pt":1439891285733,"mc":[{"id":"1.120089104","rc":[{"atl":[[1000,3.1]],"id":9612932},{"spn":1.13,"spf":1.0,"id":9612932},{"atb":[[1.01,1727.28]],"id":9480385},{"spn":5.9,"spf":1.0,"id":9480385}],"con":true,"img":false,"tv":5903.67}]}
{"op":"mcm","clk":"1147600656","pt":1439891285991,"mc":[{"id":"1.120089104","rc":[{"atl":[[1000,2.89]],"id":9612932},{"atb":[[1.01,1727.17]],"id":9480385}],"con":true,"img":false,"tv":5903.67}]}
{"op":"mcm","clk":"1147600666","pt":1439891286405,"mc":[{"id":"1.120089104","rc":[{"atl":[[1000,1]],"id":9612932},{"atb":[[1.01,1725.18]],"id":9480385}],"con":true,"img":false,"tv":5903.67}]}
{"op":"mcm","clk":"1147600671","pt":1439891286512,"mc":[{"id":"1.120089104","rc":[{"atl":[[1.27,143.23]],"id":9612932},{"atb":[[5.5,6.98]],"id":9480385}],"con":true,"img":false,"tv":5903.67}]}
{"op":"mcm","clk":"1147600858","pt":1439891292184,"mc":[{"id":"1.120089104","rc":[{"atl":[[1.22,42.2]],"id":9612932}],"con":true,"img":false,"tv":5903.67}]}
{"op":"mcm","clk":"1147600884","pt":1439891293857,"mc":[{"id":"1.120089104","rc":[{"atl":[[6.2,0]],"id":9480385}],"con":true,"img":false,"tv":5903.67}]}
{"op":"mcm","clk":"1147600889","pt":1439891293960,"mc":[{"id":"1.120089104","rc":[{"atl":[[10,5.11]],"id":9480385}],"con":true,"img":false,"tv":5903.67}]}
{"op":"mcm","clk":"1147600925","pt":1439891295627,"mc":[{"id":"1.120089104","rc":[{"atl":[[11.5,0],[1000,2.55]],"id":9480385}],"con":true,"img":false,"tv":5903.67}]}
{"op":"mcm","clk":"1147600957","pt":1439891296355,"mc":[{"id":"1.120089104","rc":[{"atl":[[1000,1.06]],"id":9480385}],"con":true,"img":false,"tv":5903.67}]}
{"op":"mcm","clk":"1147600959","pt":1439891296514,"mc":[{"id":"1.120089104","rc":[{"atl":[[1000,0]],"id":9480385}],"con":true,"img":false,"tv":5903.67}]}
{"op":"mcm","clk":"1147600963","pt":1439891296616,"mc":[{"id":"1.120089104","rc":[{"atl":[[9,1.06]],"id":9480385}],"con":true,"img":false,"tv":5903.67}]}
{"op":"mcm","clk":"1147601605","pt":1439891323254,"mc":[{"id":"1.120089104","rc":[{"atl":[[8.8,1.41]],"id":9480385}],"con":true,"img":false,"tv":5903.67}]}
{"op":"mcm","clk":"1147601665","pt":1439891325628,"mc":[{"id":"1.120089104","rc":[{"atl":[[10,0]],"id":9480385}],"con":true,"img":false,"tv":5903.67}]}
{"op":"mcm","clk":"1147601667","pt":1439891325732,"mc":[{"id":"1.120089104","rc":[{"atl":[[9,6.75]],"id":9480385}],"con":true,"img":false,"tv":5903.67}]}
{"op":"mcm","clk":"1147601735","pt":1439891328406,"mc":[{"id":"1.120089104","rc":[{"atl":[[1.22,48.2]],"id":9612932}],"con":true,"img":false,"tv":5903.67}]}
{"op":"mcm","clk":"1147601749","pt":1439891329348,"mc":[{"id":"1.120089104","rc":[{"atl":[[9,12.75]],"id":9480385}],"con":true,"img":false,"tv":5903.67}]}
{"op":"mcm","clk":"1147601750","pt":1439891329401,"mc":[{"id":"1.120089104","rc":[{"atb":[[5.2,6.4]],"id":9480385},{"atl":[[8.8,10.19]],"id":9480385}],"con":true,"img":false,"tv":5903.67}]}
{"op":"mcm","clk":"1147601762","pt":1439891329611,"mc":[{"id":"1.120089104","rc":[{"atb":[[5.2,4.98]],"id":9480385}],"con":true,"img":false,"tv":5903.67}]}
{"op":"mcm","clk":"1147601786","pt":1439891330548,"mc":[{"id":"1.120089104","rc":[{"atl":[[1000,2.55],[9,11.68]],"id":9480385}],"con":true,"img":false,"tv":5903.67}]}
{"op":"mcm","clk":"1147601799","pt":1439891331227,"mc":[{"id":"1.120089104","rc":[{"atl":[[1000,1.11]],"id":9480385}],"con":true,"img":false,"tv":5903.67}]}
{"op":"mcm","clk":"1147601801","pt":1439891331437,"mc":[{"id":"1.120089104","rc":[{"atl":[[1000,0]],"id":9480385}],"con":true,"img":false,"tv":5903.67}]}
{"op":"mcm","clk":"1147601814","pt":1439891331540,"mc":[{"id":"1.120089104","rc":[{"atl":[[8.6,1.11]],"id":9480385}],"con":true,"img":false,"tv":5903.67}]}
{"op":"mcm","clk":"1147602041","pt":1439891343761,"mc":[{"id":"1.120089104","rc":[{"atl":[[8.6,4.11]],"id":9480385}],"con":true,"img":false,"tv":5903.67}]}
{"op":"mcm","clk":"1147602104","pt":1439891345880,"mc":[{"id":"1.120089104","rc":[{"atl":[[8.4,6]],"id":9480385},{"spn":6.1,"spf":1.0,"id":9480385}],"con":true,"img":false,"tv":5903.67}]}
{"op":"mcm","clk":"1147602109","pt":1439891346085,"mc":[{"id":"1.120089104","rc":[{"atl":[[8.8,1.41]],"id":9480385}],"con":true,"img":false,"tv":5903.67}]}
{"op":"mcm","clk":"1147602121","pt":1439891346773,"mc":[{"id":"1.120089104","rc":[{"atl":[[1000,2.55],[8.6,3]],"id":9480385}],"con":true,"img":false,"tv":5903.67}]}
{"op":"mcm","clk":"1147602135","pt":1439891347511,"mc":[{"id":"1.120089104","rc":[{"atl":[[1000,1.16]],"id":9480385}],"con":true,"img":false,"tv":5903.67}]}
{"op":"mcm","clk":"1147602142","pt":1439891347670,"mc":[{"id":"1.120089104","rc":[{"atl":[[1000,0]],"id":9480385}],"con":true,"img":false,"tv":5903.67}]}
{"op":"mcm","clk":"1147602143","pt":1439891347775,"mc":[{"id":"1.120089104","rc":[{"atl":[[8.2,1.16]],"id":9480385}],"con":true,"img":false,"tv":5903.67}]}
{"op":"mcm","clk":"1147602208","pt":1439891351358,"mc":[{"id":"1.120089104","rc":[{"atl":[[8.4,10.07]],"id":9480385}],"con":true,"img":false,"tv":5903.67}]}
{"op":"mcm","clk":"1147602341","pt":1439891357676,"mc":[{"id":"1.120089104","rc":[{"atl":[[9,6]],"id":9480385}],"con":true,"img":false,"tv":5903.67}]}
{"op":"mcm","clk":"1147602343","pt":1439891357781,"mc":[{"id":"1.120089104","rc":[{"atl":[[8.2,7.4]],"id":9480385}],"con":true,"img":false,"tv":5903.67}]}
{"op":"mcm","clk":"1147610348","pt":1439891367374,"mc":[{"id":"1.120089104","rc":[{"atb":[[1.17,8.18]],"id":9612932}],"con":true,"img":false,"tv":5903.67}]}
{"op":"mcm","clk":"1147610356","pt":1439891367739,"mc":[{"id":"1.120089104","rc":[{"atb":[[1.17,12.18]],"id":9612932}],"con":true,"img":false,"tv":5903.67}]}
{"op":"mcm","clk":"1147610389","pt":1439891369292,"mc":[{"id":"1.120089104","rc":[{"atl":[[8.6,0]],"id":9480385}],"con":true,"img":false,"tv":5903.67}]}
{"op":"mcm","clk":"1147610507","pt":1439891377177,"mc":[{"id":"1.120089104","rc":[{"atb":[[1.01,1727.73],[5.3,0]],"id":9480385}],"con":true,"img":false,"tv":5903.67}]}
{"op":"mcm","clk":"1147610511","pt":1439891377697,"mc":[{"id":"1.120089104","rc":[{"atb":[[1.01,1726.89]],"id":9480385}],"con":true,"img":false,"tv":5903.67}]}
{"op":"mcm","clk":"1147610516","pt":1439891377906,"mc":[{"id":"1.120089104","rc":[{"atb":[[1.01,1725.18]],"id":9480385}],"con":true,"img":false,"tv":5903.67}]}
{"op":"mcm","clk":"1147610518","pt":1439891378010,"mc":[{"id":"1.120089104","rc":[{"atb":[[5.6,3.34]],"id":9480385}],"con":true,"img":false,"tv":5903.67}]}
{"op":"mcm","clk":"1147610679","pt":1439891390488,"mc":[{"id":"1.120089104","rc":[{"atl":[[1.29,43.53]],"id":9612932}],"con":true,"img":false,"tv":5903.67}]}
{"op":"mcm","clk":"1147610681","pt":1439891390591,"mc":[{"id":"1.120089104","rc":[{"atl":[[1.29,19.54]],"id":9612932},{"atl":[[8.4,4.06]],"id":9480385}],"con":true,"img":false,"tv":5903.67}]}
{"op":"mcm","clk":"1147610767","pt":1439891395347,"mc":[{"id":"1.120089104","rc":[{"atb":[[5.5,3.97]],"id":9480385},{"atl":[[8,3]],"id":9480385}],"con":true,"img":false,"tv":5903.67}]}
{"op":"mcm","clk":"1147610774","pt":1439891395505,"mc":[{"id":"1.120089104","rc":[{"atl":[[8.8,3.27]],"id":9480385}],"con":true,"img":false,"tv":5903.67}]}
{"op":"mcm","clk":"1147610789","pt":1439891396708,"mc":[{"id":"1.120089104","rc":[{"atl":[[8.2,6.24],[1000,2.55]],"id":9480385}],"con":true,"img":false,"tv":5903.67}]}
{"op":"mcm","clk":"1147610800","pt":1439891397437,"mc":[{"id":"1.120089104","rc":[{"atl":[[1000,1.22]],"id":9480385}],"con":true,"img":false,"tv":5903.67}]}
{"op":"mcm","clk":"1147610807","pt":1439891397648,"mc":[{"id":"1.120089104","rc":[{"atl":[[1000,0]],"id":9480385}],"con":true,"img":false,"tv":5903.67}]}
{"op":"mcm","clk":"1147610811","pt":1439891397750,"mc":[{"id":"1.120089104","rc":[{"atl":[[7.8,1.22]],"id":9480385}],"con":true,"img":false,"tv":5903.67}]}
{"op":"mcm","clk":"1147610834","pt":1439891398845,"mc":[{"id":"1.120089104","rc":[{"atb":[[1.14,0]],"id":9612932}],"con":true,"img":false,"tv":5903.67}]}
{"op":"mcm","clk":"1147610843","pt":1439891399474,"mc":[{"id":"1.120089104","rc":[{"atb":[[1.1,474.18]],"id":9612932}],"con":true,"img":false,"tv":5903.67}]}
{"op":"mcm","clk":"1147610846","pt":1439891399786,"mc":[{"id":"1.120089104","rc":[{"atb":[[1.14,6]],"id":9612932}],"con":true,"img":false,"tv":5903.67}]}
{"op":"mcm","clk":"1147610854","pt":1439891400048,"mc":[{"id":"1.120089104","rc":[{"atb":[[4.2,9.46]],"id":9480385}],"con":true,"img":false,"tv":5903.67}]}
{"op":"mcm","clk":"1147610869","pt":1439891400676,"mc":[{"id":"1.120089104","rc":[{"atb":[[4.5,8.14]],"id":9480385}],"con":true,"img":false,"tv":5903.67}]}
{"op":"mcm","clk":"1147610878","pt":1439891400989,"mc":[{"id":"1.120089104","rc":[{"atb":[[1.03,18]],"id":9612932},{"atb":[[1.03,18]],"id":9480385}],"con":true,"img":false,"tv":5903.67}]}
{"op":"mcm","clk":"1147611084","pt":1439891410734,"mc":[{"id":"1.120089104","rc":[{"atb":[[1.13,25]],"id":9612932},{"spn":1.11,"spf":1.0,"id":9612932}],"con":true,"img":false,"tv":5903.67}]}
{"op":"mcm","clk":"1147611092","pt":1439891411153,"mc":[{"id":"1.120089104","rc":[{"atb":[[1.1,2311.31]],"id":9612932}],"con":true,"img":false,"tv":5903.67}]}
{"op":"mcm","clk":"1147611160","pt":1439891413741,"mc":[{"id":"1.120089104","rc":[{"atl":[[8.8,1.85]],"id":9480385}],"con":true,"img":false,"tv":5903.67}]}
{"op":"mcm","clk":"1147611163","pt":1439891413845,"mc":[{"id":"1.120089104","rc":[{"atl":[[7.6,1.41]],"id":9480385}],"con":true,"img":false,"tv":5903.67}]}
{"op":"mcm","clk":"1147611214","pt":1439891414954,"mc":[{"id":"1.120089104","rc":[{"atb":[[1.14,0]],"id":9612932}],"con":true,"img":false,"tv":5903.67}]}
{"op":"mcm","clk":"1147611371","pt":1439891420814,"mc":[{"id":"1.120089104","rc":[{"atl":[[8,0]],"id":9480385}],"con":true,"img":false,"tv":5903.67}]}
{"op":"mcm","clk":"1147611397","pt":1439891421600,"mc":[{"id":"1.120089104","rc":[{"atl":[[8.2,0]],"id":9480385}],"con":true,"img":false,"tv":5903.67}]}
{"op":"mcm","clk":"1147611404","pt":1439891421707,"mc":[{"id":"1.120089104","rc":[{"atl":[[7.6,8.15]],"id":9480385}],"con":true,"img":false,"tv":5903.67}]}
{"op":"mcm","clk":"1147611462","pt":1439891424342,"mc":[{"id":"1.120089104","rc":[{"atb":[[4.2,0]],"id":9480385}],"con":true,"img":false,"tv":5903.67}]}
{"op":"mcm","clk":"1147611472","pt":1439891424924,"mc":[{"id":"1.120089104","rc":[{"atb":[[4.5,15.48]],"id":9480385}],"con":true,"img":false,"tv":5903.67}]}
{"op":"mcm","clk":"1147611790","pt":1439891446637,"mc":[{"id":"1.120089104","rc":[{"atl":[[7.4,3]],"id":9480385}],"con":true,"img":false,"tv":5903.67}]}
{"op":"mcm","clk":"1147611886","pt":1439891452322,"mc":[{"id":"1.120089104","rc":[{"atb":[[5.2,6.63]],"id":9480385}],"con":true,"img":false,"tv":5903.67}]}
{"op":"mcm","clk":"1147611888","pt":1439891452481,"mc":[{"id":"1.120089104","rc":[{"atb":[[5.2,1.64]],"id":9480385}],"con":true,"img":false,"tv":5903.67}]}
{"op":"mcm","clk":"1147611911","pt":1439891453726,"mc":[{"id":"1.120089104","rc":[{"atl":[[7.6,1.41]],"id":9480385}],"con":true,"img":false,"tv":5903.67}]}
{"op":"mcm","clk":"1147611913","pt":1439891453830,"mc":[{"id":"1.120089104","rc":[{"atl":[[7.2,7.1]],"id":9480385}],"con":true,"img":false,"tv":5903.67}]}
{"op":"mcm","clk":"1147612237","pt":1439891473823,"mc":[{"id":"1.120089104","rc":[{"spn":1.11,"spf":1.0,"id":9612932},{"atb":[[5.6,6.35]],"id":9480385},{"atl":[[7.4,0]],"id":9480385}],"con":true,"img":false,"tv":5903.67}]}
{"op":"mcm","clk":"1147612241","pt":1439891474088,"mc":[{"id":"1.120089104","rc":[{"atl":[[7.6,0]],"id":9480385}],"con":true,"img":false,"tv":5903.67}]}
{"op":"mcm","clk":"1147612242","pt":1439891474190,"mc":[{"id":"1.120089104","rc":[{"atl":[[7,1.41]],"id":9480385}],"con":true,"img":false,"tv":5903.67}]}
{"op":"mcm","clk":"1147612473","pt":1439891486592,"mc":[{"id":"1.120089104","rc":[{"atl":[[7.2,0]],"id":9480385}],"con":true,"img":false,"tv":5903.67}]}
{"op":"mcm","clk":"1147612477","pt":1439891486696,"mc":[{"id":"1.120089104","rc":[{"atl":[[8.2,6.24]],"id":9480385}],"con":true,"img":false,"tv":5903.67}]}
{"op":"mcm","clk":"1147612804","pt":1439891504413,"mc":[{"id":"1.120089104","rc":[{"atl":[[7,0]],"id":9480385}],"con":true,"img":false,"tv":5903.67}]}
{"op":"mcm","clk":"1147612806","pt":1439891504466,"mc":[{"id":"1.120089104","rc":[{"atl":[[7.6,1.41]],"id":9480385}],"con":true,"img":false,"tv":5903.67}]}
{"op":"mcm","clk":"1147612917","pt":1439891511059,"mc":[{"id":"1.120089104","rc":[{"atb":[[5.2,6.55]],"id":9480385}],"con":true,"img":false,"tv":5903.67}]}
{"op":"mcm","clk":"1147612920","pt":1439891511271,"mc":[{"id":"1.120089104","rc":[{"atb":[[5.2,4.9]],"id":9480385}],"con":true,"img":false,"tv":5903.67}]}
{"op":"mcm","clk":"1147613095","pt":1439891523116,"mc":[{"id":"1.120089104","rc":[{"atl":[[8.2,0]],"id":9480385}],"con":true,"img":false,"tv":5903.67}]}
{"op":"mcm","clk":"1147613097","pt":1439891523218,"mc":[{"id":"1.120089104","rc":[{"atl":[[7.6,8.15]],"id":9480385}],"con":true,"img":false,"tv":5903.67}]}
{"op":"mcm","clk":"1147613150","pt":1439891526664,"mc":[{"id":"1.120089104","rc":[{"atl":[[7.4,3]],"id":9480385}],"con":true,"img":false,"tv":5903.67}]}
{"op":"mcm","clk":"1147613177","pt":1439891528535,"mc":[{"id":"1.120089104","rc":[{"atl":[[1.22,42.2]],"id":9612932}],"con":true,"img":false,"tv":5903.67}]}
{"op":"mcm","clk":"1147613182","pt":1439891529470,"mc":[{"id":"1.120089104","rc":[{"atl":[[9,0]],"id":9480385}],"con":true,"img":false,"tv":5903.67}]}
{"op":"mcm","clk":"1147613291","pt":1439891534675,"mc":[{"id":"1.120089104","rc":[{"atl":[[7.6,6.73]],"id":9480385}],"con":true,"img":false,"tv":5903.67}]}
{"op":"mcm","clk":"1147613294","pt":1439891534776,"mc":[{"id":"1.120089104","rc":[{"atl":[[7.2,1.41]],"id":9480385}],"con":true,"img":false,"tv":5903.67}]}
{"op":"mcm","clk":"1147613774","pt":1439891557128,"mc":[{"id":"1.120089104","rc":[{"atl":[[7.6,0]],"id":9480385}],"con":true,"img":false,"tv":5903.67}]}
{"op":"mcm","clk":"1147613778","pt":1439891557232,"mc":[{"id":"1.120089104","rc":[{"atl":[[7.2,8.52]],"id":9480385}],"con":true,"img":false,"tv":5903.67}]}
{"op":"mcm","clk":"1147614068","pt":1439891568614,"mc":[{"id":"1.120089104","rc":[{"atl":[[8.4,5.6]],"id":9480385}],"con":true,"img":false,"tv":5903.67}]}
{"op":"mcm","clk":"1147614071","pt":1439891568821,"mc":[{"id":"1.120089104","rc":[{"atl":[[8.8,0]],"id":9480385}],"con":true,"img":false,"tv":5903.67}]}
{"op":"mcm","clk":"1147614269","pt":1439891579817,"mc":[{"id":"1.120089104","rc":[{"atl":[[7.4,0]],"id":9480385}],"con":true,"img":false,"tv":5903.67}]}
{"op":"mcm","clk":"1147614382","pt":1439891585929,"mc":[{"id":"1.120089104","rc":[{"atl":[[8.4,1.54]],"id":9480385}],"con":true,"img":false,"tv":5903.67}]}
{"op":"mcm","clk":"1147614386","pt":1439891586138,"mc":[{"id":"1.120089104","rc":[{"atl":[[7.2,13.26]],"id":9480385}],"con":true,"img":false,"tv":5903.67}]}
{"op":"mcm","clk":"1147614787","pt":1439891606403,"mc":[{"id":"1.120089104","rc":[{"atl":[[7,2.99]],"id":9480385}],"con":true,"img":false,"tv":5903.67}]}
{"op":"mcm","clk":"1147615077","pt":1439891622325,"mc":[{"id":"1.120089104","rc":[{"atl":[[7.2,6.15]],"id":9480385}],"con":true,"img":false,"tv":5903.67}]}
{"op":"mcm","clk":"1147615082","pt":1439891622434,"mc":[{"id":"1.120089104","rc":[{"atl":[[6.8,7.53]],"id":9480385}],"con":true,"img":false,"tv":5903.67}]}
{"op":"mcm","clk":"1147615132","pt":1439891625160,"mc":[{"id":"1.120089104","rc":[{"atl":[[7.2,4.74]],"id":9480385}],"con":true,"img":false,"tv":5903.67}]}
{"op":"mcm","clk":"1147615134","pt":1439891625264,"mc":[{"id":"1.120089104","rc":[{"atl":[[6.6,1.47]],"id":9480385}],"con":true,"img":false,"tv":5903.67}]}
{"op":"mcm","clk":"1147615309","pt":1439891632931,"mc":[{"id":"1.120089104","rc":[{"atl":[[7,0]],"id":9480385}],"con":true,"img":false,"tv":5903.67}]}
{"op":"mcm","clk":"1147615674","pt":1439891654525,"mc":[{"id":"1.120089104","rc":[{"atl":[[6.8,0]],"id":9480385}],"con":true,"img":false,"tv":5903.67}]}
{"op":"mcm","clk":"1147615676","pt":1439891654578,"mc":[{"id":"1.120089104","rc":[{"atl":[[7,7.31]],"id":9480385}],"con":true,"img":false,"tv":5903.67}]}
{"op":"mcm","clk":"1147615701","pt":1439891655528,"mc":[{"id":"1.120089104","rc":[{"atl":[[6.6,0.06]],"id":9480385}],"con":true,"img":false,"tv":5903.67}]}
{"op":"mcm","clk":"1147615705","pt":1439891655634,"mc":[{"id":"1.120089104","rc":[{"atl":[[6.8,1.41]],"id":9480385}],"con":true,"img":false,"tv":5903.67}]}
{"op":"mcm","clk":"1147615783","pt":1439891659642,"mc":[{"id":"1.120089104","rc":[{"atl":[[6.8,4.4]],"id":9480385}],"con":true,"img":false,"tv":5903.67}]}
{"op":"mcm","clk":"1147615803","pt":1439891660703,"mc":[{"id":"1.120089104","rc":[{"trd":[[1.22,204.46]],"ltp":1.22,"tv":204.46,"id":9612932},{"atb":[[1.22,311.65]],"id":9612932},{"atl":[[1.22,0]],"id":9612932}],"con":true,"img":false,"tv":5988.08}]}
{"op":"mcm","clk":"1147615809","pt":1439891661182,"mc":[{"id":"1.120089104","rc":[{"atb":[[1.17,8.18]],"id":9612932}],"con":true,"img":false,"tv":5988.08}]}
{"op":"mcm","clk":"1147615917","pt":1439891665888,"mc":[{"id":"1.120089104","rc":[{"trd":[[1.22,368.4]],"ltp":1.22,"tv":368.4,"id":9612932},{"atb":[[1.22,229.67]],"id":9612932},{"trd":[[5.6,29.21]],"ltp":5.6,"tv":29.21,"id":9480385},{"atb":[[5.6,0]],"id":9480385},{"atl":[[5.6,11.51]],"id":9480385}],"con":true,"img":false,"tv":6164.72}]}
{"op":"mcm","clk":"1147615955","pt":1439891667120,"mc":[{"id":"1.120089104","rc":[{"trd":[[1.23,494.69]],"ltp":1.23,"tv":494.69,"id":9612932},{"atb":[[1.17,0]],"id":9612932},{"atl":[[1.23,28.04]],"id":9612932},{"spn":1.15,"spf":1.0,"id":9612932},{"spn":5.55,"spf":1.0,"id":9480385}],"con":true,"img":false,"tv":6180.12}]}
{"op":"mcm","clk":"1147616321","pt":1439891680819,"mc":[{"id":"1.120089104","rc":[{"atb":[[1.09,1099.33]],"id":9612932}],"con":true,"img":false,"tv":6180.12}]}
{"op":"mcm","clk":"1147616347","pt":1439891681289,"mc":[{"id":"1.120089104","rc":[{"atb":[[1.14,870.22]],"id":9612932}],"con":true,"img":false,"tv":6180.12}]}
{"op":"mcm","clk":"1147616360","pt":1439891681700,"mc":[{"id":"1.120089104","rc":[{"atb":[[4.4,94.1]],"id":9480385}],"con":true,"img":false,"tv":6180.12}]}
{"op":"mcm","clk":"1147616383","pt":1439891682216,"mc":[{"id":"1.120089104","rc":[{"atb":[[4.5,50.29]],"id":9480385}],"con":true,"img":false,"tv":6180.12}]}
{"op":"mcm","clk":"1147616395","pt":1439891682479,"mc":[{"id":"1.120089104","rc":[{"atb":[[1.17,6]],"id":9612932}],"con":true,"img":false,"tv":6180.12}]}
{"op":"mcm","clk":"1147616455","pt":1439891684305,"mc":[{"id":"1.120089104","rc":[{"atb":[[1.12,79.05]],"id":9612932}],"con":true,"img":false,"tv":6180.12}]}
{"op":"mcm","clk":"1147616465","pt":1439891684518,"mc":[{"id":"1.120089104","rc":[{"atb":[[1.12,62.53]],"id":9612932}],"con":true,"img":false,"tv":6180.12}]}
{"op":"mcm","clk":"1147616502","pt":1439891685819,"mc":[{"id":"1.120089104","rc":[{"atl":[[6.8,2.99]],"id":9480385}],"con":true,"img":false,"tv":6180.12}]}
{"op":"mcm","clk":"1147616508","pt":1439891686132,"mc":[{"id":"1.120089104","rc":[{"atb":[[1.22,232.67]],"id":9612932},{"atl":[[6.8,0]],"id":9480385}],"con":true,"img":false,"tv":6180.12}]}
{"op":"mcm","clk":"1147616549","pt":1439891687232,"mc":[{"id":"1.120089104","rc":[{"atb":[[5,197.76]],"id":9480385}],"con":true,"img":false,"tv":6180.12}]}
{"op":"mcm","clk":"1147616556","pt":1439891687337,"mc":[{"id":"1.120089104","rc":[{"atl":[[7,4.54]],"id":9480385}],"con":true,"img":false,"tv":6180.12}]}
{"op":"mcm","clk":"1147616633","pt":1439891689368,"mc":[{"id":"1.120089104","rc":[{"atl":[[1.29,37.02]],"id":9612932},{"atb":[[5.2,6.31]],"id":9480385},{"atl":[[6.8,20.3]],"id":9480385}],"con":true,"img":false,"tv":6180.12}]}
{"op":"mcm","clk":"1147616640","pt":1439891689526,"mc":[{"id":"1.120089104","rc":[{"atl":[[1.29,17.48]],"id":9612932},{"atb":[[5.2,1.41]],"id":9480385},{"atl":[[8.4,0]],"id":9480385}],"con":true,"img":false,"tv":6180.12}]}
{"op":"mcm","clk":"1147616707","pt":1439891691354,"mc":[{"id":"1.120089104","rc":[{"atb":[[1.1,2122.1]],"id":9612932}],"con":true,"img":false,"tv":6180.12}]}
{"op":"mcm","clk":"1147616733","pt":1439891691977,"mc":[{"id":"1.120089104","rc":[{"atb":[[1.14,997.18]],"id":9612932}],"con":true,"img":false,"tv":6180.12}]}
{"op":"mcm","clk":"1147616872","pt":1439891695476,"mc":[{"id":"1.120089104","rc":[{"atb":[[5.2,0]],"id":9480385}],"con":true,"img":false,"tv":6180.12}]}
{"op":"mcm","clk":"1147617010","pt":1439891701076,"mc":[{"id":"1.120089104","rc":[{"atb":[[4.8,4.98]],"id":9480385}],"con":true,"img":false,"tv":6180.12}]}
{"op":"mcm","clk":"1147617254","pt":1439891712785,"mc":[{"id":"1.120089104","rc":[{"atl":[[5.7,2.94]],"id":9480385}],"con":true,"img":false,"tv":6180.12}]}
{"op":"mcm","clk":"1147618797","pt":1439891784998,"mc":[{"id":"1.120089104","rc":[{"atb":[[1.09,0]],"id":9612932},{"spn":1.16,"spf":1.0,"id":9612932}],"con":true,"img":false,"tv":6180.12}]}
{"op":"mcm","clk":"1147618803","pt":1439891785157,"mc":[{"id":"1.120089104","rc":[{"atb":[[1.14,1703.89]],"id":9612932}],"con":true,"img":false,"tv":6180.12}]}
{"op":"mcm","clk":"1147618936","pt":1439891790801,"mc":[{"id":"1.120089104","rc":[{"spb":[[1000,10]],"id":9612932}],"con":true,"img":false,"tv":6180.12}]}
{"op":"mcm","clk":"1147619330","pt":1439891805276,"mc":[{"id":"1.120089104","rc":[{"atb":[[1.11,0]],"id":9612932}],"con":true,"img":false,"tv":6180.12}]}
{"op":"mcm","clk":"1147619336","pt":1439891805487,"mc":[{"id":"1.120089104","rc":[{"atb":[[1.14,1887.46]],"id":9612932}],"con":true,"img":false,"tv":6180.12}]}
{"op":"mcm","clk":"1147619465","pt":1439891810469,"mc":[{"id":"1.120089104","rc":[{"atb":[[1.12,56.53]],"id":9612932}],"con":true,"img":false,"tv":6180.12}]}
{"op":"mcm","clk":"1147619517","pt":1439891812725,"mc":[{"id":"1.120089104","rc":[{"atb":[[1.1,284.96]],"id":9612932}],"con":true,"img":false,"tv":6180.12}]}
{"op":"mcm","clk":"1147619528","pt":1439891813144,"mc":[{"id":"1.120089104","rc":[{"atb":[[1.14,3199.7]],"id":9612932}],"con":true,"img":false,"tv":6180.12}]}
{"op":"mcm","clk":"1147620023","pt":1439891834097,"mc":[{"id":"1.120089104","rc":[{"atl":[[7.2,0]],"id":9480385}],"con":true,"img":false,"tv":6180.12}]}
{"op":"mcm","clk":"1147620030","pt":1439891834417,"mc":[{"id":"1.120089104","rc":[{"atl":[[5.6,17.6]],"id":9480385}],"con":true,"img":false,"tv":6180.12}]}
{"op":"mcm","clk":"1147620640","pt":1439891865095,"mc":[{"id":"1.120089104","rc":[{"atb":[[1.1,0]],"id":9612932},{"spn":1.17,"spf":1.01,"id":9612932}],"con":true,"img":false,"tv":6180.12}]}
{"op":"mcm","clk":"1147620652","pt":1439891866199,"mc":[{"id":"1.120089104","rc":[{"atb":[[1.14,3390.9]],"id":9612932}],"con":true,"img":false,"tv":6180.12}]}
{"op":"mcm","clk":"1147622575","pt":1439891977782,"mc":[{"id":"1.120089104","rc":[{"trd":[[1.22,568.4]],"ltp":1.22,"tv":568.4,"id":9612932},{"atb":[[1.22,132.67]],"id":9612932},{"spn":1.16,"spf":1.01,"id":9612932}],"con":true,"img":false,"tv":6380.12}]}
{"op":"mcm","clk":"1147622768","pt":1439891991725,"mc":[{"id":"1.120089104","rc":[{"atl":[[1000,2.41]],"id":9612932},{"atl":[[1000,1.41]],"id":9480385}],"con":true,"img":false,"tv":6380.12}]}
{"op":"mcm","clk":"1147622775","pt":1439891991937,"mc":[{"id":"1.120089104","rc":[{"atl":[[1000,1.07]],"id":9612932},{"atl":[[1000,0.07]],"id":9480385}],"con":true,"img":false,"tv":6380.12}]}
{"op":"mcm","clk":"1147622778","pt":1439891992145,"mc":[{"id":"1.120089104","rc":[{"atl":[[1000,1]],"id":9612932},{"atl":[[1000,0]],"id":9480385}],"con":true,"img":false,"tv":6380.12}]}
{"op":"mcm","clk":"1147622781","pt":1439891992250,"mc":[{"id":"1.120089104","rc":[{"atl":[[540,0.07]],"id":9612932},{"atl":[[540,0.07]],"id":9480385}],"con":true,"img":false,"tv":6380.12}]}
{"op":"mcm","clk":"1147623705","pt":1439892031840,"mc":[{"id":"1.120089104","rc":[{"atl":[[5.7,0]],"id":9480385}],"con":true,"img":false,"tv":6380.12}]}
{"op":"mcm","clk":"1147624194","pt":1439892057874,"mc":[{"id":"1.120089104","rc":[{"atl":[[5.6,20.6]],"id":9480385}],"con":true,"img":false,"tv":6380.12}]}
{"op":"mcm","clk":"1147625994","pt":1439892140786,"mc":[{"id":"1.120089104","rc":[{"trd":[[1.22,833.77]],"ltp":1.22,"tv":833.77,"id":9612932},{"atb":[[1.22,0]],"id":9612932},{"atl":[[1.22,44]],"id":9612932},{"spn":1.14,"spf":1.01,"id":9612932}],"con":true,"img":false,"tv":6645.48}]}
{"op":"mcm","clk":"1147626002","pt":1439892141151,"mc":[{"id":"1.120089104","rc":[{"atb":[[1.17,10]],"id":9612932}],"con":true,"img":false,"tv":6645.48}]}
{"op":"mcm","clk":"1147626121","pt":1439892145574,"mc":[{"id":"1.120089104","rc":[{"atb":[[1.14,2684.19]],"id":9612932}],"con":true,"img":false,"tv":6645.48}]}
{"op":"mcm","clk":"1147626127","pt":1439892145787,"mc":[{"id":"1.120089104","rc":[{"atb":[[1.1,989.39]],"id":9612932}],"con":true,"img":false,"tv":6645.48}]}
{"op":"mcm","clk":"1147626455","pt":1439892157218,"mc":[{"id":"1.120089104","rc":[{"atb":[[1.11,6]],"id":9612932}],"con":true,"img":false,"tv":6645.48}]}
{"op":"mcm","clk":"1147626730","pt":1439892168416,"mc":[{"id":"1.120089104","rc":[{"atb":[[1.16,104.18]],"id":9612932},{"atl":[[1.21,21.88]],"id":9612932}],"con":true,"img":false,"tv":6645.48}]}
{"op":"mcm","clk":"1147626738","pt":1439892168626,"mc":[{"id":"1.120089104","rc":[{"trd":[[1.21,1097.99]],"ltp":1.21,"tv":1097.99,"id":9612932},{"atl":[[1.21,0]],"id":9612932},{"trd":[[5.6,38.67]],"ltp":5.6,"tv":38.67,"id":9480385},{"atl":[[5.6,15.87]],"id":9480385}],"con":true,"img":false,"tv":6698.7}]}
{"op":"mcm","clk":"1147626875","pt":1439892173745,"mc":[{"id":"1.120089104","rc":[{"atb":[[4.8,14.17]],"id":9480385}],"con":true,"img":false,"tv":6698.7}]}
{"op":"mcm","clk":"1147626884","pt":1439892173955,"mc":[{"id":"1.120089104","rc":[{"atb":[[4.8,9.18]],"id":9480385},{"atl":[[6.8,0]],"id":9480385}],"con":true,"img":false,"tv":6698.7}]}
{"op":"mcm","clk":"1147627055","pt":1439892181387,"mc":[{"id":"1.120089104","rc":[{"atb":[[1.01,1727.18]],"id":9480385}],"con":true,"img":false,"tv":6698.7}]}
{"op":"mcm","clk":"1147627062","pt":1439892181599,"mc":[{"id":"1.120089104","rc":[{"atb":[[1.01,1725.69]],"id":9480385}],"con":true,"img":false,"tv":6698.7}]}
{"op":"mcm","clk":"1147627066","pt":1439892181806,"mc":[{"id":"1.120089104","rc":[{"atb":[[1.01,1725.18]],"id":9480385}],"con":true,"img":false,"tv":6699.72}]}
{"op":"mcm","clk":"1147627069","pt":1439892181913,"mc":[{"id":"1.120089104","rc":[{"trd":[[5.6,39.69]],"ltp":5.6,"tv":39.69,"id":9480385},{"atl":[[5.6,15.36]],"id":9480385}],"con":true,"img":false,"tv":6699.72}]}
{"op":"mcm","clk":"1147627228","pt":1439892188661,"mc":[{"id":"1.120089104","rc":[{"atb":[[1.14,2500.63]],"id":9612932}],"con":true,"img":false,"tv":6699.72}]}
{"op":"mcm","clk":"1147627233","pt":1439892188871,"mc":[{"id":"1.120089104","rc":[{"atb":[[1.1,1246.38]],"id":9612932}],"con":true,"img":false,"tv":6699.72}]}
{"op":"mcm","clk":"1147627887","pt":1439892227215,"mc":[{"id":"1.120089104","rc":[{"atb":[[1.14,1188.39]],"id":9612932},{"spn":1.14,"spf":1.01,"id":9612932}],"con":true,"img":false,"tv":6699.72}]}
{"op":"mcm","clk":"1147627898","pt":1439892227641,"mc":[{"id":"1.120089104","rc":[{"atb":[[1.1,3083.52]],"id":9612932}],"con":true,"img":false,"tv":6699.72}]}
{"op":"mcm","clk":"1147636489","pt":1439892267879,"mc":[{"id":"1.120089104","rc":[{"atl":[[1.22,344]],"id":9612932}],"con":true,"img":false,"tv":6699.72}]}
{"op":"mcm","clk":"1147636806","pt":1439892288024,"mc":[{"id":"1.120089104","rc":[{"trd":[[1.22,878.63],[1.21,1098.01]],"ltp":1.22,"tv":1976.63,"id":9612932},{"atl":[[1.22,321.56],[1.21,0]],"id":9612932}],"con":true,"img":false,"tv":6744.6}]}
{"op":"mcm","clk":"1147636839","pt":1439892291556,"mc":[{"id":"1.120089104","rc":[{"atl":[[1.29,68.36]],"id":9612932},{"atb":[[5.2,24.69]],"id":9480385}],"con":true,"img":false,"tv":6744.6}]}
{"op":"mcm","clk":"1147636842","pt":1439892291770,"mc":[{"id":"1.120089104","rc":[{"atl":[[1.29,50.87]],"id":9612932},{"atb":[[4.8,0]],"id":9480385}],"con":true,"img":false,"tv":6744.6}]}
{"op":"mcm","clk":"1147636989","pt":1439892300552,"mc":[{"id":"1.120089104","rc":[{"atb":[[1.14,997.18]],"id":9612932}],"con":true,"img":false,"tv":6744.6}]}
{"op":"mcm","clk":"1147637000","pt":1439892301140,"mc":[{"id":"1.120089104","rc":[{"atb":[[1.1,3351.21]],"id":9612932}],"con":true,"img":false,"tv":6744.6}]}
{"op":"mcm","clk":"1147637034","pt":1439892302461,"mc":[{"id":"1.120089104","rc":[{"trd":[[5.6,70.43]],"ltp":5.6,"tv":70.43,"id":9480385},{"atb":[[5.6,4.9]],"id":9480385},{"atl":[[5.6,0]],"id":9480385}],"con":true,"img":false,"tv":6775.34}]}
{"op":"mcm","clk":"1147637061","pt":1439892303890,"mc":[{"id":"1.120089104","rc":[{"atb":[[1.14,126.96]],"id":9612932}],"con":true,"img":false,"tv":6775.34}]}
{"op":"mcm","clk":"1147637074","pt":1439892304365,"mc":[{"id":"1.120089104","rc":[{"atb":[[1.1,4569.52]],"id":9612932}],"con":true,"img":false,"tv":6775.34}]}
{"op":"mcm","clk":"1147637130","pt":1439892307321,"mc":[{"id":"1.120089104","rc":[{"atb":[[1.18,8.11]],"id":9612932}],"con":true,"img":false,"tv":6775.34}]}
{"op":"mcm","clk":"1147637169","pt":1439892309111,"mc":[{"id":"1.120089104","rc":[{"atl":[[1.28,6]],"id":9612932}],"con":true,"img":false,"tv":6775.34}]}
{"op":"mcm","clk":"1147637351","pt":1439892323517,"mc":[{"id":"1.120089104","rc":[{"atl":[[7,7.54]],"id":9480385}],"con":true,"img":false,"tv":6775.34}]}
{"op":"mcm","clk":"1147637468","pt":1439892331294,"mc":[{"id":"1.120089104","rc":[{"atl":[[6.8,1.41]],"id":9480385}],"con":true,"img":false,"tv":6775.34}]}
{"op":"mcm","clk":"1147637557","pt":1439892336154,"mc":[{"id":"1.120089104","rc":[{"atl":[[9,11.46]],"id":9480385}],"con":true,"img":false,"tv":6775.34}]}
{"op":"mcm","clk":"1147637773","pt":1439892348985,"mc":[{"id":"1.120089104","rc":[{"atb":[[1.17,6]],"id":9612932},{"spn":1.12,"spf":1.01,"id":9612932},{"spn":6.1,"spf":1.0,"id":9480385}],"con":true,"img":false,"tv":6775.34}]}
{"op":"mcm","clk":"1147637785","pt":1439892349453,"mc":[{"id":"1.120089104","rc":[{"atb":[[1.14,0]],"id":9612932}],"con":true,"img":false,"tv":6775.34}]}
{"op":"mcm","clk":"1147637797","pt":1439892350080,"mc":[{"id":"1.120089104","rc":[{"atb":[[1.11,167.59]],"id":9612932}],"con":true,"img":false,"tv":6775.34}]}
{"op":"mcm","clk":"1147637812","pt":1439892350808,"mc":[{"id":"1.120089104","rc":[{"atb":[[5.2,27.69]],"id":9480385}],"con":true,"img":false,"tv":6775.34}]}
{"op":"mcm","clk":"1147637858","pt":1439892352802,"mc":[{"id":"1.120089104","rc":[{"atb":[[1.12,77.68]],"id":9612932},{"atl":[[1.29,84.5]],"id":9612932},{"atb":[[5.2,40.91]],"id":9480385},{"atl":[[9,20.41]],"id":9480385}],"con":true,"img":false,"tv":6775.34}]}
{"op":"mcm","clk":"1147637863","pt":1439892353008,"mc":[{"id":"1.120089104","rc":[{"atb":[[1.12,21.14]],"id":9612932},{"atl":[[1.29,33.63]],"id":9612932},{"atb":[[5.2,16.21]],"id":9480385},{"atl":[[9,8.95]],"id":9480385}],"con":true,"img":false,"tv":6775.34}]}
{"op":"mcm","clk":"1147637892","pt":1439892354417,"mc":[{"id":"1.120089104","rc":[{"atl":[[1.28,0]],"id":9612932}],"con":true,"img":false,"tv":6775.34}]}
{"op":"mcm","clk":"1147638003","pt":1439892358349,"mc":[{"id":"1.120089104","rc":[{"atb":[[5.2,3]],"id":9480385},{"atl":[[9,0]],"id":9480385}],"con":true,"img":false,"tv":6775.34}]}
{"op":"mcm","clk":"1147638112","pt":1439892363564,"mc":[{"id":"1.120089104","rc":[{"atb":[[5.2,6.67]],"id":9480385},{"atl":[[9,2.48]],"id":9480385}],"con":true,"img":false,"tv":6775.34}]}
{"op":"mcm","clk":"1147638370","pt":1439892376746,"mc":[{"id":"1.120089104","rc":[{"atl":[[7,4.54]],"id":9480385}],"con":true,"img":false,"tv":6775.34}]}
{"op":"mcm","clk":"1147640424","pt":1439892487465,"mc":[{"id":"1.120089104","rc":[{"spn":1.12,"spf":1.01,"id":9612932},{"atl":[[7,10.54]],"id":9480385}],"con":true,"img":false,"tv":6775.34}]}
{"op":"mcm","clk":"1147640881","pt":1439892510160,"mc":[{"id":"1.120089104","rc":[{"atl":[[6.8,4.41]],"id":9480385}],"con":true,"img":false,"tv":6775.34}]}
{"op":"mcm","clk":"1147641176","pt":1439892522835,"mc":[{"id":"1.120089104","rc":[{"atl":[[7,6]],"id":9480385}],"con":true,"img":false,"tv":6775.34}]}
{"op":"mcm","clk":"1147641179","pt":1439892522938,"mc":[{"id":"1.120089104","rc":[{"atl":[[6.6,4.88]],"id":9480385}],"con":true,"img":false,"tv":6775.34}]}
{"op":"mcm","clk":"1147641350","pt":1439892529880,"mc":[{"id":"1.120089104","rc":[{"trd":[[1.18,138.24]],"ltp":1.18,"tv":138.24,"id":9612932},{"atb":[[1.18,5.6]],"id":9612932}],"con":true,"img":false,"tv":6780.34}]}
{"op":"mcm","clk":"1147641435","pt":1439892532683,"mc":[{"id":"1.120089104","rc":[{"atb":[[1.12,0]],"id":9612932}],"con":true,"img":false,"tv":6780.34}]}
{"op":"mcm","clk":"1147641522","pt":1439892537122,"mc":[{"id":"1.120089104","rc":[{"atb":[[1.01,1727.73]],"id":9480385}],"con":true,"img":false,"tv":6780.34}]}
{"op":"mcm","clk":"1147641536","pt":1439892537547,"mc":[{"id":"1.120089104","rc":[{"atb":[[1.14,27.18]],"id":9612932}],"con":true,"img":false,"tv":6780.34}]}
{"op":"mcm","clk":"1147641540","pt":1439892537653,"mc":[{"id":"1.120089104","rc":[{"atb":[[1.01,1725.69]],"id":9480385}],"con":true,"img":false,"tv":6780.34}]}
{"op":"mcm","clk":"1147641545","pt":1439892537868,"mc":[{"id":"1.120089104","rc":[{"atb":[[1.01,1725.18]],"id":9480385}],"con":true,"img":false,"tv":6780.34}]}
{"op":"mcm","clk":"1147641548","pt":1439892537971,"mc":[{"id":"1.120089104","rc":[{"atb":[[5.7,0.51]],"id":9480385}],"con":true,"img":false,"tv":6780.34}]}
{"op":"mcm","clk":"1147641593","pt":1439892539981,"mc":[{"id":"1.120089104","rc":[{"atl":[[6.8,1.41]],"id":9480385}],"con":true,"img":false,"tv":6780.34}]}
{"op":"mcm","clk":"1147641944","pt":1439892554672,"mc":[{"id":"1.120089104","rc":[{"spn":1.12,"spf":1.01,"id":9612932},{"atl":[[6.6,0.06]],"id":9480385},{"spn":6.15,"spf":1.0,"id":9480385}],"con":true,"img":false,"tv":6780.34}]}
{"op":"mcm","clk":"1147641946","pt":1439892554776,"mc":[{"id":"1.120089104","rc":[{"atl":[[6.8,6.09]],"id":9480385}],"con":true,"img":false,"tv":6780.34}]}
{"op":"mcm","clk":"1147642225","pt":1439892566036,"mc":[{"id":"1.120089104","rc":[{"trd":[[5.6,77.39],[5.7,1.03]],"ltp":5.6,"tv":78.42,"id":9480385},{"atb":[[5.7,0],[5.6,1.42]],"id":9480385}],"con":true,"img":false,"tv":6788.34}]}
{"op":"mcm","clk":"1147642251","pt":1439892566972,"mc":[{"id":"1.120089104","rc":[{"atl":[[6.6,3.06]],"id":9480385}],"con":true,"img":false,"tv":6788.34}]}
{"op":"mcm","clk":"1147642395","pt":1439892572280,"mc":[{"id":"1.120089104","rc":[{"atl":[[6.8,4.67]],"id":9480385}],"con":true,"img":false,"tv":6788.34}]}
{"op":"mcm","clk":"1147642792","pt":1439892587015,"mc":[{"id":"1.120089104","rc":[{"atl":[[6.8,0]],"id":9480385}],"con":true,"img":false,"tv":6788.34}]}
{"op":"mcm","clk":"1147642797","pt":1439892587121,"mc":[{"id":"1.120089104","rc":[{"atl":[[6.4,4.97]],"id":9480385}],"con":true,"img":false,"tv":6788.34}]}
{"op":"mcm","clk":"1147642802","pt":1439892587225,"mc":[{"id":"1.120089104","rc":[{"atb":[[5.3,3.01]],"id":9480385},{"atl":[[6.4,7.76]],"id":9480385}],"con":true,"img":false,"tv":6788.34}]}
{"op":"mcm","clk":"1147643026","pt":1439892594509,"mc":[{"id":"1.120089104","rc":[{"atl":[[6.6,0.06]],"id":9480385}],"con":true,"img":false,"tv":6788.34}]}
{"op":"mcm","clk":"1147643094","pt":1439892596626,"mc":[{"id":"1.120089104","rc":[{"atb":[[1.14,77.06]],"id":9612932},{"atl":[[1.29,93.31]],"id":9612932}],"con":true,"img":false,"tv":6788.34}]}
{"op":"mcm","clk":"1147643098","pt":1439892596836,"mc":[{"id":"1.120089104","rc":[{"atb":[[1.14,49.87]],"id":9612932},{"atl":[[1.29,59.68]],"id":9612932}],"con":true,"img":false,"tv":6788.34}]}
{"op":"mcm","clk":"1147643214","pt":1439892600796,"mc":[{"id":"1.120089104","rc":[{"atl":[[1.28,6]],"id":9612932}],"con":true,"img":false,"tv":6788.34}]}
{"op":"mcm","clk":"1147643886","pt":1439892621147,"mc":[{"id":"1.120089104","rc":[{"spn":1.12,"spf":1.01,"id":9612932},{"atl":[[6.4,0]],"id":9480385},{"spn":6.1,"spf":1.0,"id":9480385}],"con":true,"img":false,"tv":6788.34}]}
{"op":"mcm","clk":"1147643890","pt":1439892621252,"mc":[{"id":"1.120089104","rc":[{"atl":[[6.8,7.02]],"id":9480385}],"con":true,"img":false,"tv":6788.34}]}
{"op":"mcm","clk":"1147643903","pt":1439892621734,"mc":[{"id":"1.120089104","rc":[{"atl":[[6.6,3.06]],"id":9480385}],"con":true,"img":false,"tv":6788.34}]}
{"op":"mcm","clk":"1147644224","pt":1439892634395,"mc":[{"id":"1.120089104","rc":[{"atb":[[4.4,34.66]],"id":9480385}],"con":true,"img":false,"tv":6788.34}]}
{"op":"mcm","clk":"1147644235","pt":1439892634814,"mc":[{"id":"1.120089104","rc":[{"atb":[[4.5,101.24]],"id":9480385}],"con":true,"img":false,"tv":6788.34}]}
{"op":"mcm","clk":"1147645381","pt":1439892676561,"mc":[{"id":"1.120089104","rc":[{"atl":[[6.6,0.06]],"id":9480385}],"con":true,"img":false,"tv":6788.34}]}
{"op":"mcm","clk":"1147645605","pt":1439892687681,"mc":[{"id":"1.120089104","rc":[{"atl":[[7,0]],"id":9480385}],"con":true,"img":false,"tv":6788.34}]}
{"op":"mcm","clk":"1147645909","pt":1439892704754,"mc":[{"id":"1.120089104","rc":[{"atl":[[6.6,3.06]],"id":9480385}],"con":true,"img":false,"tv":6788.34}]}
{"op":"mcm","clk":"1147645916","pt":1439892704913,"mc":[{"id":"1.120089104","rc":[{"trd":[[1.24,1152.2],[1.23,550.77],[1.22,1521.77]],"ltp":1.24,"tv":3224.74,"id":9612932},{"atl":[[1.23,0],[1.22,0],[1.24,18.64]],"id":9612932}],"con":true,"img":false,"tv":7803.6}]}
{"op":"mcm","clk":"1147645921","pt":1439892705225,"mc":[{"id":"1.120089104","rc":[{"atl":[[1.24,32.64]],"id":9612932}],"con":true,"img":false,"tv":7803.6}]}
{"op":"mcm","clk":"1147646114","pt":1439892716469,"mc":[{"id":"1.120089104","rc":[{"atl":[[1.24,111.64]],"id":9612932}],"con":true,"img":false,"tv":7803.6}]}
{"op":"mcm","clk":"1147646116","pt":1439892716524,"mc":[{"id":"1.120089104","rc":[{"atb":[[5.2,9.1]],"id":9480385}],"con":true,"img":false,"tv":7803.6}]}
{"op":"mcm","clk":"1147646117","pt":1439892716732,"mc":[{"id":"1.120089104","rc":[{"atl":[[1.29,0]],"id":9612932},{"atb":[[5.2,5.43]],"id":9480385}],"con":true,"img":false,"tv":7803.6}]}
{"op":"mcm","clk":"1147646118","pt":1439892716838,"mc":[{"id":"1.120089104","rc":[{"atl":[[1.24,97.64]],"id":9612932}],"con":true,"img":false,"tv":7803.6}]}
{"op":"mcm","clk":"1147646151","pt":1439892719076,"mc":[{"id":"1.120089104","rc":[{"atl":[[1.28,0]],"id":9612932}],"con":true,"img":false,"tv":7803.6}]}
{"op":"mcm","clk":"1147646153","pt":1439892719284,"mc":[{"id":"1.120089104","rc":[{"atl":[[1.29,6]],"id":9612932}],"con":true,"img":false,"tv":7803.6}]}
{"op":"mcm","clk":"1147646203","pt":1439892722259,"mc":[{"id":"1.120089104","rc":[{"atb":[[5.2,3]],"id":9480385}],"con":true,"img":false,"tv":7803.6}]}
{"op":"mcm","clk":"1147647272","pt":1439892775204,"mc":[{"id":"1.120089104","rc":[{"atl":[[1.29,17.86]],"id":9612932}],"con":true,"img":false,"tv":7803.6}]}
{"op":"mcm","clk":"1147647589","pt":1439892793045,"mc":[{"id":"1.120089104","rc":[{"atl":[[1.24,597.65]],"id":9612932}],"con":true,"img":false,"tv":7803.6}]}
{"op":"mcm","clk":"1147648874","pt":1439892861958,"mc":[{"id":"1.120089104","rc":[{"trd":[[1.24,1191.1]],"ltp":1.24,"tv":1191.1,"id":9612932},{"atl":[[1.24,578.2]],"id":9612932}],"con":true,"img":false,"tv":7842.5}]}
{"op":"mcm","clk":"1147649012","pt":1439892870745,"mc":[{"id":"1.120089104","rc":[{"atl":[[6.6,9.06]],"id":9480385}],"con":true,"img":false,"tv":7842.5}]}
{"op":"mcm","clk":"1147653830","pt":1439893070884,"mc":[{"id":"1.120089104","rc":[{"atl":[[6.6,3.06]],"id":9480385}],"con":true,"img":false,"tv":7842.5}]}
{"op":"mcm","clk":"1147665724","pt":1439893218671,"mc":[{"id":"1.120089104","rc":[{"atb":[[5.6,2.83]],"id":9480385}],"con":true,"img":false,"tv":7842.5}]}
{"op":"mcm","clk":"1147666735","pt":1439893265125,"mc":[{"id":"1.120089104","rc":[{"atl":[[6.6,9.06]],"id":9480385}],"con":true,"img":false,"tv":7842.5}]}
{"op":"mcm","clk":"1147667184","pt":1439893286700,"mc":[{"id":"1.120089104","rc":[{"atl":[[1.22,10]],"id":9612932}],"con":true,"img":false,"tv":7842.5}]}
{"op":"mcm","clk":"1147667196","pt":1439893287279,"mc":[{"id":"1.120089104","rc":[{"atl":[[1.22,127.78]],"id":9612932}],"con":true,"img":false,"tv":7842.5}]}
{"op":"mcm","clk":"1147667624","pt":1439893310229,"mc":[{"id":"1.120089104","rc":[{"atb":[[1.16,326.18]],"id":9612932},{"atb":[[5.5,28.97]],"id":9480385}],"con":true,"img":false,"tv":7842.5}]}
{"op":"mcm","clk":"1147667632","pt":1439893310440,"mc":[{"id":"1.120089104","rc":[{"atb":[[1.18,123.39]],"id":9612932}],"con":true,"img":false,"tv":7842.5}]}
{"op":"mcm","clk":"1147667864","pt":1439893319328,"mc":[{"id":"1.120089104","rc":[{"atb":[[5.2,5.09]],"id":9480385}],"con":true,"img":false,"tv":7842.5}]}
{"op":"mcm","clk":"1147670939","pt":1439893465359,"mc":[{"id":"1.120089104","rc":[{"spn":1.15,"spf":1.01,"id":9612932},{"atl":[[6.6,3.06]],"id":9480385}],"con":true,"img":false,"tv":7842.5}]}
{"op":"mcm","clk":"1147670949","pt":1439893465624,"mc":[{"id":"1.120089104","rc":[{"atl":[[6.6,4.92]],"id":9480385}],"con":true,"img":false,"tv":7842.5}]}
{"op":"mcm","clk":"1147673722","pt":1439893582218,"mc":[{"id":"1.120089104","rc":[{"atb":[[5.6,5.83]],"id":9480385}],"con":true,"img":false,"tv":7842.5}]}
{"op":"mcm","clk":"1147675428","pt":1439893646386,"mc":[{"id":"1.120089104","rc":[{"atl":[[6.6,10.92]],"id":9480385}],"con":true,"img":false,"tv":7842.5}]}
{"op":"mcm","clk":"1147676125","pt":1439893670891,"mc":[{"id":"1.120089104","rc":[{"atl":[[6.8,0]],"id":9480385}],"con":true,"img":false,"tv":7842.5}]}
{"op":"mcm","clk":"1147676127","pt":1439893670999,"mc":[{"id":"1.120089104","rc":[{"atl":[[6.4,7.46]],"id":9480385}],"con":true,"img":false,"tv":7842.5}]}
{"op":"mcm","clk":"1147676672","pt":1439893691690,"mc":[{"id":"1.120089104","rc":[{"atl":[[6.6,7.92]],"id":9480385}],"con":true,"img":false,"tv":7842.5}]}
{"op":"mcm","clk":"1147677197","pt":1439893718929,"mc":[{"id":"1.120089104","rc":[{"atl":[[6.4,10.46]],"id":9480385},{"spn":6.0,"spf":1.0,"id":9480385}],"con":true,"img":false,"tv":7842.5}]}
{"op":"mcm","clk":"1147677835","pt":1439893749692,"mc":[{"id":"1.120089104","rc":[{"atb":[[1.12,1251.03]],"id":9612932},{"atb":[[2.92,258.33]],"id":9480385}],"con":true,"img":false,"tv":7842.5}]}
{"op":"mcm","clk":"1147677957","pt":1439893756870,"mc":[{"id":"1.120089104","rc":[{"atb":[[1.01,1753.52]],"id":9612932}],"con":true,"img":false,"tv":7842.5}]}
{"op":"mcm","clk":"1147677963","pt":1439893757084,"mc":[{"id":"1.120089104","rc":[{"atb":[[1.01,1752.36]],"id":9612932}],"con":true,"img":false,"tv":7842.5}]}
{"op":"mcm","clk":"1147677965","pt":1439893757187,"mc":[{"id":"1.120089104","rc":[{"atb":[[1.01,1751.52]],"id":9612932}],"con":true,"img":false,"tv":7842.5}]}
{"op":"mcm","clk":"1147677968","pt":1439893757241,"mc":[{"id":"1.120089104","rc":[{"atb":[[1.18,124.23]],"id":9612932}],"con":true,"img":false,"tv":7842.5}]}
{"op":"mcm","clk":"1147680073","pt":1439893846634,"mc":[{"id":"1.120089104","rc":[{"spn":1.15,"spf":1.01,"id":9612932},{"atl":[[6.6,1.92]],"id":9480385}],"con":true,"img":false,"tv":7842.5}]}
{"op":"mcm","clk":"1147680580","pt":1439893866996,"mc":[{"id":"1.120089104","rc":[{"atl":[[6.4,3]],"id":9480385}],"con":true,"img":false,"tv":7842.5}]}
{"op":"mcm","clk":"1147680583","pt":1439893867100,"mc":[{"id":"1.120089104","rc":[{"atl":[[7.6,6.28]],"id":9480385}],"con":true,"img":false,"tv":7842.5}]}
{"op":"mcm","clk":"1147680597","pt":1439893867631,"mc":[{"id":"1.120089104","rc":[{"atl":[[6.4,4.9]],"id":9480385}],"con":true,"img":false,"tv":7842.5}]}
{"op":"mcm","clk":"1147680651","pt":1439893870226,"mc":[{"id":"1.120089104","rc":[{"atl":[[7.4,4.98]],"id":9480385}],"con":true,"img":false,"tv":7842.5}]}
{"op":"mcm","clk":"1147680658","pt":1439893870441,"mc":[{"id":"1.120089104","rc":[{"atl":[[9,0]],"id":9480385}],"con":true,"img":false,"tv":7842.5}]}
{"op":"mcm","clk":"1147680978","pt":1439893883384,"mc":[{"id":"1.120089104","rc":[{"atl":[[6.4,1.9]],"id":9480385}],"con":true,"img":false,"tv":7842.5}]}
{"op":"mcm","clk":"1147681325","pt":1439893898397,"mc":[{"id":"1.120089104","rc":[{"spl":[[1.01,739.78]],"id":9612932}],"con":true,"img":false,"tv":7842.5}]}
{"op":"mcm","clk":"1147681345","pt":1439893899542,"mc":[{"id":"1.120089104","rc":[{"atl":[[7.6,0]],"id":9480385}],"con":true,"img":false,"tv":7842.5}]}
{"op":"mcm","clk":"1147681348","pt":1439893899644,"mc":[{"id":"1.120089104","rc":[{"atl":[[6.4,9.37]],"id":9480385}],"con":true,"img":false,"tv":7842.5}]}
{"op":"mcm","clk":"1147681609","pt":1439893910902,"mc":[{"id":"1.120089104","rc":[{"spn":1.15,"spf":1.01,"id":9612932},{"atl":[[6.4,12.37]],"id":9480385}],"con":true,"img":false,"tv":7842.5}]}
{"op":"mcm","clk":"1147682163","pt":1439893932493,"mc":[{"id":"1.120089104","rc":[{"atl":[[6.4,4.9]],"id":9480385}],"con":true,"img":false,"tv":7842.5}]}
{"op":"mcm","clk":"1147682166","pt":1439893932603,"mc":[{"id":"1.120089104","rc":[{"atl":[[7.2,6.63]],"id":9480385}],"con":true,"img":false,"tv":7842.5}]}
{"op":"mcm","clk":"1147683122","pt":1439893965839,"mc":[{"id":"1.120089104","rc":[{"atl":[[6.4,1.9]],"id":9480385}],"con":true,"img":false,"tv":7842.5}]}
{"op":"mcm","clk":"1147683585","pt":1439893982780,"mc":[{"id":"1.120089104","rc":[{"atl":[[7.4,0]],"id":9480385}],"con":true,"img":false,"tv":7842.5}]}
{"op":"mcm","clk":"1147683743","pt":1439893988299,"mc":[{"id":"1.120089104","rc":[{"atl":[[9,15.54]],"id":9480385}],"con":true,"img":false,"tv":7842.5}]}
{"op":"mcm","clk":"1147683874","pt":1439893993040,"mc":[{"id":"1.120089104","rc":[{"atl":[[6.6,4.92]],"id":9480385}],"con":true,"img":false,"tv":7842.5}]}
{"op":"mcm","clk":"1147684993","pt":1439894033818,"mc":[{"id":"1.120089104","rc":[{"atl":[[6.6,10.92]],"id":9480385}],"con":true,"img":false,"tv":7842.5}]}
{"op":"mcm","clk":"1147685686","pt":1439894061766,"mc":[{"id":"1.120089104","rc":[{"atl":[[7.2,0]],"id":9480385}],"con":true,"img":false,"tv":7842.5}]}
{"op":"mcm","clk":"1147685688","pt":1439894061870,"mc":[{"id":"1.120089104","rc":[{"atl":[[6.4,9.37]],"id":9480385}],"con":true,"img":false,"tv":7842.5}]}
{"op":"mcm","clk":"1147693785","pt":1439894075787,"mc":[{"id":"1.120089104","rc":[{"atl":[[6.6,7.92]],"id":9480385}],"con":true,"img":false,"tv":7842.5}]}
{"op":"mcm","clk":"1147694316","pt":1439894102123,"mc":[{"id":"1.120089104","rc":[{"atl":[[9,0]],"id":9480385}],"con":true,"img":false,"tv":7842.5}]}
{"op":"mcm","clk":"1147694331","pt":1439894102704,"mc":[{"id":"1.120089104","rc":[{"atl":[[6.2,3]],"id":9480385}],"con":true,"img":false,"tv":7842.5}]}
{"op":"mcm","clk":"1147694437","pt":1439894107170,"mc":[{"id":"1.120089104","rc":[{"atl":[[9,6.99]],"id":9480385}],"con":true,"img":false,"tv":7842.5}]}
{"op":"mcm","clk":"1147695555","pt":1439894161841,"mc":[{"id":"1.120089104","rc":[{"atl":[[9,0]],"id":9480385},{"spn":5.9,"spf":1.0,"id":9480385}],"con":true,"img":false,"tv":7842.5}]}
{"op":"mcm","clk":"1147695670","pt":1439894167789,"mc":[{"id":"1.120089104","rc":[{"atl":[[9,2.48]],"id":9480385}],"con":true,"img":false,"tv":7842.5}]}
{"op":"mcm","clk":"1147696798","pt":1439894218813,"mc":[{"id":"1.120089104","rc":[{"spl":[[1.01,744.78]],"id":9612932}],"con":true,"img":false,"tv":7842.5}]}
{"op":"mcm","clk":"1147697091","pt":1439894234011,"mc":[{"id":"1.120089104","rc":[{"spn":1.15,"spf":1.01,"id":9612932},{"atl":[[6.6,1.92]],"id":9480385}],"con":true,"img":false,"tv":7842.5}]}
{"op":"mcm","clk":"1147697132","pt":1439894236116,"mc":[{"id":"1.120089104","rc":[{"trd":[[1.18,386.72]],"ltp":1.18,"tv":386.72,"id":9612932},{"atb":[[1.18,0]],"id":9612932},{"atl":[[1.18,427.76]],"id":9612932}],"con":true,"img":false,"tv":8090.97}]}
{"op":"mcm","clk":"1147697139","pt":1439894236534,"mc":[{"id":"1.120089104","rc":[{"atl":[[6.4,7.46],[6.6,0.06]],"id":9480385}],"con":true,"img":false,"tv":8090.97}]}
{"op":"mcm","clk":"1147697145","pt":1439894236639,"mc":[{"id":"1.120089104","rc":[{"trd":[[1.18,418.24]],"ltp":1.18,"tv":418.24,"id":9612932},{"atl":[[1.18,412]],"id":9612932},{"trd":[[6.2,6]],"ltp":6.2,"tv":6.0,"id":9480385},{"atl":[[6.2,0]],"id":9480385}],"con":true,"img":false,"tv":8128.49}]}
{"op":"mcm","clk":"1147697146","pt":1439894236745,"mc":[{"id":"1.120089104","rc":[{"trd":[[1.18,551.4]],"ltp":1.18,"tv":551.4,"id":9612932},{"atl":[[1.18,345.42]],"id":9612932},{"trd":[[6.4,14.93]],"ltp":6.4,"tv":14.93,"id":9480385},{"atb":[[6.2,3],[6.4,1.9]],"id":9480385},{"atl":[[6.4,0]],"id":9480385}],"con":true,"img":false,"tv":8276.59}]}
{"op":"mcm","clk":"1147697155","pt":1439894236904,"mc":[{"id":"1.120089104","rc":[{"atb":[[6.2,0],[6.4,0]],"id":9480385}],"con":true,"img":false,"tv":8276.59}]}
{"op":"mcm","clk":"1147697167","pt":1439894237328,"mc":[{"id":"1.120089104","rc":[{"atb":[[5.7,4.31]],"id":9480385}],"con":true,"img":false,"tv":8276.59}]}
{"op":"mcm","clk":"1147697197","pt":1439894238431,"mc":[{"id":"1.120089104","rc":[{"atb":[[1.01,1727.73]],"id":9480385}],"con":true,"img":false,"tv":8276.59}]}
{"op":"mcm","clk":"1147697211","pt":1439894238961,"mc":[{"id":"1.120089104","rc":[{"atb":[[1.01,1726.86]],"id":9480385}],"con":true,"img":false,"tv":8276.59}]}
{"op":"mcm","clk":"1147697217","pt":1439894239171,"mc":[{"id":"1.120089104","rc":[{"atb":[[1.01,1725.18]],"id":9480385}],"con":true,"img":false,"tv":8276.59}]}
{"op":"mcm","clk":"1147697220","pt":1439894239227,"mc":[{"id":"1.120089104","rc":[{"atb":[[5.7,5.98]],"id":9480385}],"con":true,"img":false,"tv":8276.59}]}
{"op":"mcm","clk":"1147697225","pt":1439894239436,"mc":[{"id":"1.120089104","rc":[{"atl":[[8.4,2.48]],"id":9480385}],"con":true,"img":false,"tv":8276.59}]}
{"op":"mcm","clk":"1147697230","pt":1439894239645,"mc":[{"id":"1.120089104","rc":[{"atl":[[9,0]],"id":9480385}],"con":true,"img":false,"tv":8276.59}]}
{"op":"mcm","clk":"1147697249","pt":1439894240382,"mc":[{"id":"1.120089104","rc":[{"atb":[[5.6,2.83]],"id":9480385}],"con":true,"img":false,"tv":8276.59}]}
{"op":"mcm","clk":"1147697271","pt":1439894241675,"mc":[{"id":"1.120089104","rc":[{"atl":[[1.29,11.86]],"id":9612932}],"con":true,"img":false,"tv":8276.59}]}
{"op":"mcm","clk":"1147697299","pt":1439894243120,"mc":[{"id":"1.120089104","rc":[{"atl":[[1.18,0]],"id":9612932}],"con":true,"img":false,"tv":8276.59}]}
{"op":"mcm","clk":"1147697330","pt":1439894244912,"mc":[{"id":"1.120089104","rc":[{"atb":[[1.14,77.89]],"id":9612932}],"con":true,"img":false,"tv":8276.59}]}
{"op":"mcm","clk":"1147697333","pt":1439894245125,"mc":[{"id":"1.120089104","rc":[{"atb":[[1.14,28.01]],"id":9612932}],"con":true,"img":false,"tv":8276.59}]}
{"op":"mcm","clk":"1147697368","pt":1439894247325,"mc":[{"id":"1.120089104","rc":[{"atl":[[7.6,1.41]],"id":9480385}],"con":true,"img":false,"tv":8276.59}]}
{"op":"mcm","clk":"1147697442","pt":1439894251907,"mc":[{"id":"1.120089104","rc":[{"trd":[[1.17,63.14]],"ltp":1.17,"tv":63.14,"id":9612932},{"atb":[[1.17,0]],"id":9612932},{"atl":[[1.17,339]],"id":9612932}],"con":true,"img":false,"tv":8288.59}]}
{"op":"mcm","clk":"1147697490","pt":1439894254327,"mc":[{"id":"1.120089104","rc":[{"atl":[[1.17,0]],"id":9612932}],"con":true,"img":false,"tv":8288.59}]}
{"op":"mcm","clk":"1147697514","pt":1439894255330,"mc":[{"id":"1.120089104","rc":[{"atl":[[1.21,6]],"id":9612932}],"con":true,"img":false,"tv":8288.59}]}
{"op":"mcm","clk":"1147697542","pt":1439894256336,"mc":[{"id":"1.120089104","rc":[{"atl":[[1.21,125.27]],"id":9612932}],"con":true,"img":false,"tv":8288.59}]}
{"op":"mcm","clk":"1147697681","pt":1439894262786,"mc":[{"id":"1.120089104","rc":[{"trd":[[1.16,683.22]],"ltp":1.16,"tv":683.22,"id":9612932},{"atb":[[1.16,0]],"id":9612932},{"atl":[[1.16,12.82]],"id":9612932}],"con":true,"img":false,"tv":8940.96}]}
{"op":"mcm","clk":"1147697691","pt":1439894263316,"mc":[{"id":"1.120089104","rc":[{"atl":[[1.21,119.27]],"id":9612932}],"con":true,"img":false,"tv":8940.96}]}
{"op":"mcm","clk":"1147697693","pt":1439894263367,"mc":[{"id":"1.120089104","rc":[{"atl":[[1.16,18.82]],"id":9612932}],"con":true,"img":false,"tv":8940.96}]}
{"op":"mcm","clk":"1147697702","pt":1439894263684,"mc":[{"id":"1.120089104","rc":[{"atb":[[1.05,6]],"id":9612932}],"con":true,"img":false,"tv":8940.96}]}
{"op":"mcm","clk":"1147697737","pt":1439894265015,"mc":[{"id":"1.120089104","rc":[{"atl":[[1.16,6]],"id":9612932}],"con":true,"img":false,"tv":8940.96}]}
{"op":"mcm","clk":"1147697788","pt":1439894267556,"mc":[{"id":"1.120089104","rc":[{"atb":[[5.7,9.24]],"id":9480385}],"con":true,"img":false,"tv":8940.96}]}
{"op":"mcm","clk":"1147697869","pt":1439894271278,"mc":[{"id":"1.120089104","rc":[{"atl":[[1.16,0]],"id":9612932}],"con":true,"img":false,"tv":8940.96}]}
{"op":"mcm","clk":"1147697873","pt":1439894271386,"mc":[{"id":"1.120089104","rc":[{"atb":[[1.14,47.51]],"id":9612932},{"atl":[[1.2,6]],"id":9612932}],"con":true,"img":false,"tv":8940.96}]}
{"op":"mcm","clk":"1147697878","pt":1439894271597,"mc":[{"id":"1.120089104","rc":[{"atb":[[1.14,19.49]],"id":9612932}],"con":true,"img":false,"tv":8940.96}]}
{"op":"mcm","clk":"1147697880","pt":1439894271708,"mc":[{"id":"1.120089104","rc":[{"atl":[[1.2,126.29]],"id":9612932}],"con":true,"img":false,"tv":8940.96}]}
{"op":"mcm","clk":"1147697906","pt":1439894272715,"mc":[{"id":"1.120089104","rc":[{"atl":[[1.2,185.11]],"id":9612932}],"con":true,"img":false,"tv":8940.96}]}
{"op":"mcm","clk":"1147697954","pt":1439894274300,"mc":[{"id":"1.120089104","rc":[{"trd":[[1.15,26]],"ltp":1.15,"tv":26.0,"id":9612932},{"atb":[[1.15,57]],"id":9612932},{"atl":[[1.25,226.02]],"id":9612932}],"con":true,"img":false,"tv":8966.96}]}
{"op":"mcm","clk":"1147697965","pt":1439894274722,"mc":[{"id":"1.120089104","rc":[{"atb":[[5.5,26.99]],"id":9480385}],"con":true,"img":false,"tv":8966.96}]}
{"op":"mcm","clk":"1147697966","pt":1439894274826,"mc":[{"id":"1.120089104","rc":[{"atb":[[5.8,1.98]],"id":9480385}],"con":true,"img":false,"tv":8966.96}]}
{"op":"mcm","clk":"1147697974","pt":1439894275043,"mc":[{"id":"1.120089104","rc":[{"atb":[[1.15,177.29]],"id":9612932},{"atl":[[1.24,500]],"id":9612932}],"con":true,"img":false,"tv":8966.96}]}
{"op":"mcm","clk":"1147697982","pt":1439894275408,"mc":[{"id":"1.120089104","rc":[{"atb":[[5.7,4.93]],"id":9480385}],"con":true,"img":false,"tv":8966.96}]}
{"op":"mcm","clk":"1147697984","pt":1439894275511,"mc":[{"id":"1.120089104","rc":[{"atb":[[5.9,4.31]],"id":9480385}],"con":true,"img":false,"tv":8966.96}]}
{"op":"mcm","clk":"1147697991","pt":1439894276148,"mc":[{"id":"1.120089104","rc":[{"atb":[[5.6,1.42]],"id":9480385}],"con":true,"img":false,"tv":8966.96}]}
{"op":"mcm","clk":"1147698007","pt":1439894276891,"mc":[{"id":"1.120089104","rc":[{"atb":[[5.2,10.21]],"id":9480385}],"con":true,"img":false,"tv":8966.96}]}
{"op":"mcm","clk":"1147698010","pt":1439894277047,"mc":[{"id":"1.120089104","rc":[{"atb":[[5.2,8.12]],"id":9480385}],"con":true,"img":false,"tv":8966.96}]}
{"op":"mcm","clk":"1147698138","pt":1439894282535,"mc":[{"id":"1.120089104","rc":[{"atl":[[1.29,71.54]],"id":9612932},{"atb":[[5.8,18.21]],"id":9480385}],"con":true,"img":false,"tv":8966.96}]}
{"op":"mcm","clk":"1147698141","pt":1439894282741,"mc":[{"id":"1.120089104","rc":[{"atb":[[1.14,0]],"id":9612932},{"atl":[[1.29,59.68]],"id":9612932},{"atb":[[5.2,3]],"id":9480385},{"atl":[[8.4,0]],"id":9480385}],"con":true,"img":false,"tv":8966.96}]}
{"op":"mcm","clk":"1147698290","pt":1439894288229,"mc":[{"id":"1.120089104","rc":[{"atb":[[1.14,50.57]],"id":9612932},{"atl":[[1.19,48.44]],"id":9612932}],"con":true,"img":false,"tv":8966.96}]}
{"op":"mcm","clk":"1147698293","pt":1439894288328,"mc":[{"id":"1.120089104","rc":[{"atb":[[5.3,0]],"id":9480385}],"con":true,"img":false,"tv":8966.96}]}
{"op":"mcm","clk":"1147698298","pt":1439894288430,"mc":[{"id":"1.120089104","rc":[{"atb":[[6,2.66]],"id":9480385}],"con":true,"img":false,"tv":8966.96}]}
{"op":"mcm","clk":"1147698302","pt":1439894288639,"mc":[{"id":"1.120089104","rc":[{"atb":[[1.13,49.54]],"id":9612932},{"atl":[[8.6,8.27]],"id":9480385}],"con":true,"img":false,"tv":8966.96}]}
{"op":"mcm","clk":"1147698312","pt":1439894288849,"mc":[{"id":"1.120089104","rc":[{"atb":[[5.9,0]],"id":9480385}],"con":true,"img":false,"tv":8966.96}]}
{"op":"mcm","clk":"1147698315","pt":1439894288956,"mc":[{"id":"1.120089104","rc":[{"atb":[[6.2,4.31]],"id":9480385}],"con":true,"img":false,"tv":8966.96}]}
{"op":"mcm","clk":"1147698324","pt":1439894289219,"mc":[{"id":"1.120089104","rc":[{"atb":[[6.2,0]],"id":9480385}],"con":true,"img":false,"tv":8966.96}]}
{"op":"mcm","clk":"1147698330","pt":1439894289324,"mc":[{"id":"1.120089104","rc":[{"atb":[[5.9,4.31]],"id":9480385}],"con":true,"img":false,"tv":8966.96}]}
{"op":"mcm","clk":"1147698346","pt":1439894289845,"mc":[{"id":"1.120089104","rc":[{"atb":[[5.9,0]],"id":9480385}],"con":true,"img":false,"tv":8966.96}]}
{"op":"mcm","clk":"1147698350","pt":1439894289951,"mc":[{"id":"1.120089104","rc":[{"atb":[[6.2,4.31]],"id":9480385}],"con":true,"img":false,"tv":8966.96}]}
{"op":"mcm","clk":"1147698355","pt":1439894290159,"mc":[{"id":"1.120089104","rc":[{"atb":[[6.2,0]],"id":9480385}],"con":true,"img":false,"tv":8966.96}]}
{"op":"mcm","clk":"1147698358","pt":1439894290262,"mc":[{"id":"1.120089104","rc":[{"atb":[[5.9,4.31]],"id":9480385}],"con":true,"img":false,"tv":8966.96}]}
{"op":"mcm","clk":"1147698362","pt":1439894290420,"mc":[{"id":"1.120089104","rc":[{"atb":[[5.9,0]],"id":9480385}],"con":true,"img":false,"tv":8966.96}]}
{"op":"mcm","clk":"1147698365","pt":1439894290524,"mc":[{"id":"1.120089104","rc":[{"atb":[[6.2,4.31]],"id":9480385}],"con":true,"img":false,"tv":8966.96}]}
{"op":"mcm","clk":"1147698399","pt":1439894292558,"mc":[{"id":"1.120089104","rc":[{"atb":[[4,0]],"id":9480385}],"con":true,"img":false,"tv":8966.96}]}
{"op":"mcm","clk":"1147698421","pt":1439894293341,"mc":[{"id":"1.120089104","rc":[{"atl":[[1.2,179.11]],"id":9612932}],"con":true,"img":false,"tv":8966.96}]}
{"op":"mcm","clk":"1147698426","pt":1439894293448,"mc":[{"id":"1.120089104","rc":[{"atl":[[1.18,6]],"id":9612932}],"con":true,"img":false,"tv":8966.96}]}
{"op":"mcm","clk":"1147698434","pt":1439894293760,"mc":[{"id":"1.120089104","rc":[{"atl":[[1.18,51.06],[1.22,10],[1.21,0]],"id":9612932}],"con":true,"img":false,"tv":8966.96}]}
{"op":"mcm","clk":"1147698474","pt":1439894295479,"mc":[{"id":"1.120089104","rc":[{"atl":[[1.19,92.44]],"id":9612932},{"spn":1.13,"spf":1.01,"id":9612932},{"spn":6.4,"spf":1.0,"id":9480385}],"con":true,"img":false,"tv":8966.96}]}
{"op":"mcm","clk":"1147698653","pt":1439894305836,"mc":[{"id":"1.120089104","rc":[{"atb":[[1.17,40]],"id":9612932}],"con":true,"img":false,"tv":8966.96}]}
{"op":"mcm","clk":"1147698679","pt":1439894307924,"mc":[{"id":"1.120089104","rc":[{"atb":[[1.01,1727.73],[5.7,3.26]],"id":9480385}],"con":true,"img":false,"tv":8966.96}]}
{"op":"mcm","clk":"1147698686","pt":1439894308447,"mc":[{"id":"1.120089104","rc":[{"atb":[[1.01,1726.21]],"id":9480385}],"con":true,"img":false,"tv":8966.96}]}
{"op":"mcm","clk":"1147698688","pt":1439894308654,"mc":[{"id":"1.120089104","rc":[{"atb":[[1.01,1725.18]],"id":9480385}],"con":true,"img":false,"tv":8966.96}]}
{"op":"mcm","clk":"1147698689","pt":1439894308757,"mc":[{"id":"1.120089104","rc":[{"atb":[[6.4,1.03]],"id":9480385}],"con":true,"img":false,"tv":8966.96}]}
{"op":"mcm","clk":"1147698741","pt":1439894311477,"mc":[{"id":"1.120089104","rc":[{"atb":[[1.05,0]],"id":9612932}],"con":true,"img":false,"tv":8966.96}]}
{"op":"mcm","clk":"1147698745","pt":1439894311684,"mc":[{"id":"1.120089104","rc":[{"atl":[[1.23,6]],"id":9612932}],"con":true,"img":false,"tv":8966.96}]}
{"op":"mcm","clk":"1147698826","pt":1439894316260,"mc":[{"id":"1.120089104","rc":[{"atb":[[4.4,5.56]],"id":9480385}],"con":true,"img":false,"tv":8966.96}]}
{"op":"mcm","clk":"1147698828","pt":1439894316363,"mc":[{"id":"1.120089104","rc":[{"atb":[[4.9,101.18]],"id":9480385}],"con":true,"img":false,"tv":8966.96}]}
{"op":"mcm","clk":"1147698871","pt":1439894317881,"mc":[{"id":"1.120089104","rc":[{"atb":[[4.5,93.89]],"id":9480385}],"con":true,"img":false,"tv":8966.96}]}
{"op":"mcm","clk":"1147698873","pt":1439894317987,"mc":[{"id":"1.120089104","rc":[{"atb":[[4.9,108.53]],"id":9480385}],"con":true,"img":false,"tv":8966.96}]}
{"op":"mcm","clk":"1147698892","pt":1439894318876,"mc":[{"id":"1.120089104","rc":[{"atl":[[1.2,120.29]],"id":9612932}],"con":true,"img":false,"tv":8966.96}]}
{"op":"mcm","clk":"1147698897","pt":1439894318981,"mc":[{"id":"1.120089104","rc":[{"trd":[[1.17,143.14]],"ltp":1.17,"tv":143.14,"id":9612932},{"atb":[[1.17,0]],"id":9612932},{"atl":[[1.17,18.82]],"id":9612932}],"con":true,"img":false,"tv":9046.96}]}
{"op":"mcm","clk":"1147698920","pt":1439894320080,"mc":[{"id":"1.120089104","rc":[{"atl":[[1.19,48.44]],"id":9612932}],"con":true,"img":false,"tv":9046.96}]}
{"op":"mcm","clk":"1147698922","pt":1439894320185,"mc":[{"id":"1.120089104","rc":[{"atl":[[1.17,64.55],[1.2,0]],"id":9612932}],"con":true,"img":false,"tv":9046.96}]}
{"op":"mcm","clk":"1147698937","pt":1439894321076,"mc":[{"id":"1.120089104","rc":[{"atb":[[1.14,0]],"id":9612932},{"atl":[[1.19,0]],"id":9612932}],"con":true,"img":false,"tv":9046.96}]}
{"op":"mcm","clk":"1147698946","pt":1439894321292,"mc":[{"id":"1.120089104","rc":[{"atl":[[1.17,18.82]],"id":9612932}],"con":true,"img":false,"tv":9046.96}]}
{"op":"mcm","clk":"1147698977","pt":1439894322601,"mc":[{"id":"1.120089104","rc":[{"atb":[[5.7,0]],"id":9480385}],"con":true,"img":false,"tv":9046.96}]}
{"op":"mcm","clk":"1147699014","pt":1439894325338,"mc":[{"id":"1.120089104","rc":[{"atb":[[6.2,0]],"id":9480385}],"con":true,"img":false,"tv":9046.96}]}
{"op":"mcm","clk":"1147699016","pt":1439894325653,"mc":[{"id":"1.120089104","rc":[{"atb":[[6.4,2.44]],"id":9480385}],"con":true,"img":false,"tv":9046.96}]}
{"op":"mcm","clk":"1147699017","pt":1439894325758,"mc":[{"id":"1.120089104","rc":[{"atl":[[1.18,45.06]],"id":9612932}],"con":true,"img":false,"tv":9046.96}]}
{"op":"mcm","clk":"1147699019","pt":1439894325864,"mc":[{"id":"1.120089104","rc":[{"atl":[[1.16,6]],"id":9612932}],"con":true,"img":false,"tv":9046.96}]}
{"op":"mcm","clk":"1147699020","pt":1439894326177,"mc":[{"id":"1.120089104","rc":[{"atb":[[1.05,6]],"id":9612932}],"con":true,"img":false,"tv":9046.96}]}
{"op":"mcm","clk":"1147699074","pt":1439894329653,"mc":[{"id":"1.120089104","rc":[{"atb":[[1.04,0]],"id":9612932}],"con":true,"img":false,"tv":9046.96}]}
{"op":"mcm","clk":"1147699075","pt":1439894329758,"mc":[{"id":"1.120089104","rc":[{"atb":[[1.01,1991.52]],"id":9612932}],"con":true,"img":false,"tv":9046.96}]}
{"op":"mcm","clk":"1147699080","pt":1439894329974,"mc":[{"id":"1.120089104","rc":[{"atb":[[1.02,10250]],"id":9612932}],"con":true,"img":false,"tv":9046.96}]}
{"op":"mcm","clk":"1147699099","pt":1439894331292,"mc":[{"id":"1.120089104","rc":[{"atl":[[10.5,0]],"id":9480385}],"con":true,"img":false,"tv":9046.96}]}
{"op":"mcm","clk":"1147699102","pt":1439894331400,"mc":[{"id":"1.120089104","rc":[{"atl":[[14,15]],"id":9480385}],"con":true,"img":false,"tv":9046.96}]}
{"op":"mcm","clk":"1147699131","pt":1439894333088,"mc":[{"id":"1.120089104","rc":[{"atb":[[1.05,0]],"id":9612932}],"con":true,"img":false,"tv":9046.96}]}
{"op":"mcm","clk":"1147699278","pt":1439894339976,"mc":[{"id":"1.120089104","rc":[{"atb":[[6,5.32]],"id":9480385}],"con":true,"img":false,"tv":9046.96}]}
{"op":"mcm","clk":"1147699283","pt":1439894340081,"mc":[{"id":"1.120089104","rc":[{"atl":[[1000,2.55]],"id":9480385}],"con":true,"img":false,"tv":9046.96}]}
{"op":"mcm","clk":"1147699285","pt":1439894340186,"mc":[{"id":"1.120089104","rc":[{"atl":[[1000,2.09]],"id":9480385}],"con":true,"img":false,"tv":9046.96}]}
{"op":"mcm","clk":"1147699287","pt":1439894340295,"mc":[{"id":"1.120089104","rc":[{"atl":[[1000,0]],"id":9480385}],"con":true,"img":false,"tv":9046.96}]}
{"op":"mcm","clk":"1147699288","pt":1439894340401,"mc":[{"id":"1.120089104","rc":[{"atl":[[7.6,3.51]],"id":9480385}],"con":true,"img":false,"tv":9046.96}]}
{"op":"mcm","clk":"1147699313","pt":1439894341291,"mc":[{"id":"1.120089104","rc":[{"atl":[[1.29,68.63]],"id":9612932},{"atb":[[5.8,20]],"id":9480385}],"con":true,"img":false,"tv":9046.96}]}
{"op":"mcm","clk":"1147699316","pt":1439894341495,"mc":[{"id":"1.120089104","rc":[{"atl":[[1.29,8.95]],"id":9612932},{"atb":[[5.8,3.78]],"id":9480385}],"con":true,"img":false,"tv":9046.96}]}
{"op":"mcm","clk":"1147699460","pt":1439894347458,"mc":[{"id":"1.120089104","rc":[{"atb":[[1.13,25]],"id":9612932},{"atb":[[5.8,1.98]],"id":9480385}],"con":true,"img":false,"tv":9046.96}]}
{"op":"mcm","clk":"1147699523","pt":1439894350596,"mc":[{"id":"1.120089104","rc":[{"atb":[[6,8.42]],"id":9480385}],"con":true,"img":false,"tv":9046.96}]}
{"op":"mcm","clk":"1147699567","pt":1439894352882,"mc":[{"id":"1.120089104","rc":[{"atb":[[5.6,5.17]],"id":9480385}],"con":true,"img":false,"tv":9046.96}]}
{"op":"mcm","clk":"1147699569","pt":1439894352986,"mc":[{"id":"1.120089104","rc":[{"atl":[[7.6,1.41]],"id":9480385}],"con":true,"img":false,"tv":9046.96}]}
{"op":"mcm","clk":"1147699651","pt":1439894356225,"mc":[{"id":"1.120089104","rc":[{"atl":[[1.23,85]],"id":9612932},{"spn":1.12,"spf":1.01,"id":9612932},{"spn":6.5,"spf":1.0,"id":9480385}],"con":true,"img":false,"tv":9046.96}]}
{"op":"mcm","clk":"1147699693","pt":1439894358998,"mc":[{"id":"1.120089104","rc":[{"atb":[[1.15,285.65]],"id":9612932}],"con":true,"img":false,"tv":9046.96}]}
{"op":"mcm","clk":"1147699946","pt":1439894368520,"mc":[{"id":"1.120089104","rc":[{"atb":[[1.1,3351.21]],"id":9612932}],"con":true,"img":false,"tv":9046.96}]}
{"op":"mcm","clk":"1147699968","pt":1439894368947,"mc":[{"id":"1.120089104","rc":[{"atb":[[1.08,1488.09]],"id":9612932}],"con":true,"img":false,"tv":9046.96}]}
{"op":"mcm","clk":"1147699979","pt":1439894369467,"mc":[{"id":"1.120089104","rc":[{"atb":[[1.09,6]],"id":9612932},{"atb":[[4.5,59.08]],"id":9480385}],"con":true,"img":false,"tv":9046.96}]}
{"op":"mcm","clk":"1147699981","pt":1439894369569,"mc":[{"id":"1.120089104","rc":[{"atb":[[4.8,34.81]],"id":9480385}],"con":true,"img":false,"tv":9046.96}]}
{"op":"mcm","clk":"1147700090","pt":1439894373087,"mc":[{"id":"1.120089104","rc":[{"atb":[[1.11,6]],"id":9612932}],"con":true,"img":false,"tv":9046.96}]}
{"op":"mcm","clk":"1147700107","pt":1439894373771,"mc":[{"id":"1.120089104","rc":[{"atb":[[1.08,1703.75]],"id":9612932}],"con":true,"img":false,"tv":9046.96}]}
{"op":"mcm","clk":"1147700126","pt":1439894374395,"mc":[{"id":"1.120089104","rc":[{"atb":[[4.4,0]],"id":9480385}],"con":true,"img":false,"tv":9046.96}]}
{"op":"mcm","clk":"1147700155","pt":1439894375077,"mc":[{"id":"1.120089104","rc":[{"atb":[[5.1,16.69]],"id":9480385}],"con":true,"img":false,"tv":9046.96}]}
{"op":"mcm","clk":"1147700317","pt":1439894378826,"mc":[{"id":"1.120089104","rc":[{"trd":[[1.16,687.22]],"ltp":1.16,"tv":687.22,"id":9612932},{"atl":[[1.16,4]],"id":9612932}],"con":true,"img":false,"tv":9050.96}]}
{"op":"mcm","clk":"1147700405","pt":1439894382150,"mc":[{"id":"1.120089104","rc":[{"trd":[[1.16,695.22]],"ltp":1.16,"tv":695.22,"id":9612932},{"atb":[[1.16,4.48]],"id":9612932},{"atl":[[1.16,0]],"id":9612932}],"con":true,"img":false,"tv":9058.96}]}
{"op":"mcm","clk":"1147700444","pt":1439894383564,"mc":[{"id":"1.120089104","rc":[{"atb":[[4.5,50.94]],"id":9480385}],"con":true,"img":false,"tv":9058.96}]}
{"op":"mcm","clk":"1147700460","pt":1439894384194,"mc":[{"id":"1.120089104","rc":[{"atb":[[5.1,23.03]],"id":9480385}],"con":true,"img":false,"tv":9058.96}]}
{"op":"mcm","clk":"1147700479","pt":1439894385088,"mc":[{"id":"1.120089104","rc":[{"atb":[[1.11,32.81]],"id":9612932}],"con":true,"img":false,"tv":9058.96}]}
{"op":"mcm","clk":"1147700631","pt":1439894391147,"mc":[{"id":"1.120089104","rc":[{"trd":[[1.17,180.78]],"ltp":1.17,"tv":180.78,"id":9612932},{"atl":[[1.17,0]],"id":9612932}],"con":true,"img":false,"tv":9096.6}]}
{"op":"mcm","clk":"1147700640","pt":1439894391454,"mc":[{"id":"1.120089104","rc":[{"atb":[[1.16,18.48]],"id":9612932}],"con":true,"img":false,"tv":9096.6}]}
{"op":"mcm","clk":"1147700654","pt":1439894391773,"mc":[{"id":"1.120089104","rc":[{"atl":[[1.22,128.77]],"id":9612932}],"con":true,"img":false,"tv":9096.6}]}
{"op":"mcm","clk":"1147700702","pt":1439894393263,"mc":[{"id":"1.120089104","rc":[{"trd":[[6.4,19.82]],"ltp":6.4,"tv":19.82,"id":9480385},{"atb":[[6.4,0]],"id":9480385},{"atl":[[6.4,0.32]],"id":9480385}],"con":true,"img":false,"tv":9101.48}]}
{"op":"mcm","clk":"1147701000","pt":1439894400746,"mc":[{"id":"1.120089104","rc":[{"atl":[[1.29,42.57]],"id":9612932}],"con":true,"img":false,"tv":9101.48}]}
{"op":"mcm","clk":"1147701011","pt":1439894400961,"mc":[{"id":"1.120089104","rc":[{"atl":[[1.29,33.61]],"id":9612932},{"atl":[[8.6,0]],"id":9480385}],"con":true,"img":false,"tv":9101.48}]}
{"op":"mcm","clk":"1147701292","pt":1439894408333,"mc":[{"id":"1.120089104","rc":[{"atb":[[1.13,139]],"id":9612932}],"con":true,"img":false,"tv":9101.48}]}
{"op":"mcm","clk":"1147701389","pt":1439894411150,"mc":[{"id":"1.120089104","rc":[{"atb":[[1.14,6]],"id":9612932}],"con":true,"img":false,"tv":9101.48}]}
{"op":"mcm","clk":"1147701403","pt":1439894411582,"mc":[{"id":"1.120089104","rc":[{"atb":[[1.11,74.86]],"id":9612932}],"con":true,"img":false,"tv":9101.48}]}
{"op":"mcm","clk":"1147701407","pt":1439894411736,"mc":[{"id":"1.120089104","rc":[{"atb":[[1.11,48.05]],"id":9612932}],"con":true,"img":false,"tv":9101.48}]}
{"op":"mcm","clk":"1147701415","pt":1439894412158,"mc":[{"id":"1.120089104","rc":[{"atb":[[1.13,253]],"id":9612932}],"con":true,"img":false,"tv":9101.48}]}
{"op":"mcm","clk":"1147701556","pt":1439894415008,"mc":[{"id":"1.120089104","rc":[{"atb":[[1.13,367]],"id":9612932}],"con":true,"img":false,"tv":9101.48}]}
{"op":"mcm","clk":"1147701656","pt":1439894416722,"mc":[{"id":"1.120089104","rc":[{"atb":[[1.16,14]],"id":9612932},{"spn":1.13,"spf":1.01,"id":9612932},{"spn":6.2,"spf":1.0,"id":9480385}],"con":true,"img":false,"tv":9101.48}]}
{"op":"mcm","clk":"1147701692","pt":1439894417635,"mc":[{"id":"1.120089104","rc":[{"atb":[[6,3.1]],"id":9480385}],"con":true,"img":false,"tv":9101.48}]}
{"op":"mcm","clk":"1147701710","pt":1439894417696,"mc":[{"id":"1.120089104","rc":[{"atb":[[6,8.42]],"id":9480385}],"con":true,"img":false,"tv":9101.48}]}
{"op":"mcm","clk":"1147701742","pt":1439894418726,"mc":[{"id":"1.120089104","rc":[{"atb":[[1.13,481]],"id":9612932}],"con":true,"img":false,"tv":9101.48}]}
{"op":"mcm","clk":"1147703338","pt":1439894464511,"mc":[{"id":"1.120089104","rc":[{"atb":[[4.5,0]],"id":9480385}],"con":true,"img":false,"tv":9101.48}]}
{"op":"mcm","clk":"1147703342","pt":1439894464611,"mc":[{"id":"1.120089104","rc":[{"atb":[[4.8,85.75]],"id":9480385}],"con":true,"img":false,"tv":9101.48}]}
{"op":"mcm","clk":"1147704453","pt":1439894494748,"mc":[{"id":"1.120089104","rc":[{"spl":[[1.01,769.78]],"id":9612932},{"spn":1.13,"spf":1.01,"id":9612932}],"con":true,"img":false,"tv":9101.48}]}
{"op":"mcm","clk":"1147706133","pt":1439894548400,"mc":[{"id":"1.120089104","rc":[{"trd":[[1.18,559.88]],"ltp":1.18,"tv":559.88,"id":9612932},{"atl":[[1.18,40.82]],"id":9612932}],"con":true,"img":false,"tv":9109.96}]}
{"op":"mcm","clk":"1147707521","pt":1439894598261,"mc":[{"id":"1.120089104","rc":[{"atb":[[5.1,18.82]],"id":9480385}],"con":true,"img":false,"tv":9109.96}]}
{"op":"mcm","clk":"1147707526","pt":1439894598369,"mc":[{"id":"1.120089104","rc":[{"atb":[[4.8,89.96]],"id":9480385}],"con":true,"img":false,"tv":9109.96}]}
{"op":"mcm","clk":"1147707612","pt":1439894601629,"mc":[{"id":"1.120089104","rc":[{"trd":[[1.16,719.22]],"ltp":1.16,"tv":719.22,"id":9612932},{"atb":[[1.16,2]],"id":9612932}],"con":true,"img":false,"tv":9133.96}]}
{"op":"mcm","clk":"1147707629","pt":1439894602106,"mc":[{"id":"1.120089104","rc":[{"atl":[[1.17,11.9]],"id":9612932}],"con":true,"img":false,"tv":9133.96}]}
{"op":"mcm","clk":"1147707689","pt":1439894604556,"mc":[{"id":"1.120089104","rc":[{"atb":[[5.1,12.48]],"id":9480385}],"con":true,"img":false,"tv":9133.96}]}
{"op":"mcm","clk":"1147707694","pt":1439894604659,"mc":[{"id":"1.120089104","rc":[{"atb":[[4.8,96.3]],"id":9480385}],"con":true,"img":false,"tv":9133.96}]}
{"op":"mcm","clk":"1147708580","pt":1439894646010,"mc":[{"id":"1.120089104","rc":[{"atl":[[1.29,51.37]],"id":9612932}],"con":true,"img":false,"tv":9133.96}]}
{"op":"mcm","clk":"1147708588","pt":1439894646170,"mc":[{"id":"1.120089104","rc":[{"atl":[[1.29,17.75]],"id":9612932}],"con":true,"img":false,"tv":9133.96}]}
{"op":"mcm","clk":"1147708613","pt":1439894647483,"mc":[{"id":"1.120089104","rc":[{"atb":[[1.16,335]],"id":9612932}],"con":true,"img":false,"tv":9133.96}]}
{"op":"mcm","clk":"1147708628","pt":1439894647901,"mc":[{"id":"1.120089104","rc":[{"atb":[[1.16,333]],"id":9612932}],"con":true,"img":false,"tv":9133.96}]}
{"op":"mcm","clk":"1147708639","pt":1439894648327,"mc":[{"id":"1.120089104","rc":[{"atl":[[1.18,0]],"id":9612932}],"con":true,"img":false,"tv":9133.96}]}
{"op":"mcm","clk":"1147708865","pt":1439894657381,"mc":[{"id":"1.120089104","rc":[{"atl":[[1.2,66]],"id":9612932}],"con":true,"img":false,"tv":9133.96}]}
{"op":"mcm","clk":"1147710272","pt":1439894706904,"mc":[{"id":"1.120089104","rc":[{"spn":1.15,"spf":1.01,"id":9612932},{"atl":[[8.6,13.04]],"id":9480385}],"con":true,"img":false,"tv":9133.96}]}
{"op":"mcm","clk":"1147710434","pt":1439894712503,"mc":[{"id":"1.120089104","rc":[{"atb":[[1.14,29.68]],"id":9612932}],"con":true,"img":false,"tv":9133.96}]}
{"op":"mcm","clk":"1147710439","pt":1439894712712,"mc":[{"id":"1.120089104","rc":[{"atb":[[1.11,6]],"id":9612932}],"con":true,"img":false,"tv":9133.96}]}
{"op":"mcm","clk":"1147711074","pt":1439894736552,"mc":[{"id":"1.120089104","rc":[{"trd":[[1.17,204.58]],"ltp":1.17,"tv":204.58,"id":9612932},{"atb":[[1.17,51.91]],"id":9612932},{"atl":[[1.17,0]],"id":9612932}],"con":true,"img":false,"tv":9157.77}]}
{"op":"mcm","clk":"1147711093","pt":1439894737560,"mc":[{"id":"1.120089104","rc":[{"atb":[[1.17,170.45]],"id":9612932}],"con":true,"img":false,"tv":9157.77}]}
{"op":"mcm","clk":"1147711294","pt":1439894745997,"mc":[{"id":"1.120089104","rc":[{"atb":[[1.17,118.54]],"id":9612932}],"con":true,"img":false,"tv":9157.77}]}
{"op":"mcm","clk":"1147711295","pt":1439894746108,"mc":[{"id":"1.120089104","rc":[{"trd":[[1.2,633.55]],"ltp":1.2,"tv":633.55,"id":9612932},{"atl":[[1.2,14.09]],"id":9612932}],"con":true,"img":false,"tv":9261.59}]}
{"op":"mcm","clk":"1147711301","pt":1439894746316,"mc":[{"id":"1.120089104","rc":[{"atl":[[1.2,120.28]],"id":9612932}],"con":true,"img":false,"tv":9261.59}]}
{"op":"mcm","clk":"1147711738","pt":1439894763780,"mc":[{"id":"1.120089104","rc":[{"atl":[[1.29,49.15]],"id":9612932}],"con":true,"img":false,"tv":9261.59}]}
{"op":"mcm","clk":"1147711748","pt":1439894763985,"mc":[{"id":"1.120089104","rc":[{"atl":[[1.29,31.4]],"id":9612932}],"con":true,"img":false,"tv":9261.59}]}
{"op":"mcm","clk":"1147711923","pt":1439894770504,"mc":[{"id":"1.120089104","rc":[{"trd":[[1.17,214.58]],"ltp":1.17,"tv":214.58,"id":9612932},{"atb":[[1.17,113.54]],"id":9612932},{"spn":1.15,"spf":1.01,"id":9612932}],"con":true,"img":false,"tv":9271.59}]}
{"op":"mcm","clk":"1147712105","pt":1439894776601,"mc":[{"id":"1.120089104","rc":[{"atb":[[1.08,225.65]],"id":9612932}],"con":true,"img":false,"tv":9271.59}]}
{"op":"mcm","clk":"1147712124","pt":1439894777024,"mc":[{"id":"1.120089104","rc":[{"atb":[[1.1,4533.69]],"id":9612932}],"con":true,"img":false,"tv":9271.59}]}
{"op":"mcm","clk":"1147712921","pt":1439894802248,"mc":[{"id":"1.120089104","rc":[{"atl":[[1.2,126.28]],"id":9612932},{"atl":[[7.8,7.22]],"id":9480385}],"con":true,"img":false,"tv":9271.59}]}
{"op":"mcm","clk":"1147713620","pt":1439894825521,"mc":[{"id":"1.120089104","rc":[{"atb":[[1.08,10]],"id":9612932}],"con":true,"img":false,"tv":9271.59}]}
{"op":"mcm","clk":"1147713641","pt":1439894826105,"mc":[{"id":"1.120089104","rc":[{"atb":[[1.1,4706.21]],"id":9612932}],"con":true,"img":false,"tv":9271.59}]}
{"op":"mcm","clk":"1147713792","pt":1439894830244,"mc":[{"id":"1.120089104","rc":[{"atb":[[1.09,0]],"id":9612932}],"con":true,"img":false,"tv":9271.59}]}
{"op":"mcm","clk":"1147715061","pt":1439894867443,"mc":[{"id":"1.120089104","rc":[{"atb":[[1.15,177.29]],"id":9612932},{"spn":1.15,"spf":1.01,"id":9612932}],"con":true,"img":false,"tv":9271.59}]}
{"op":"mcm","clk":"1147725894","pt":1439894970857,"mc":[{"id":"1.120089104","rc":[{"atb":[[5.8,3.98]],"id":9480385}],"con":true,"img":false,"tv":9271.59}]}
{"op":"mcm","clk":"1147726448","pt":1439895002432,"mc":[{"id":"1.120089104","rc":[{"atl":[[1.2,120.28]],"id":9612932},{"atl":[[7.8,1.22]],"id":9480385}],"con":true,"img":false,"tv":9271.59}]}
{"op":"mcm","clk":"1147727129","pt":1439895031660,"mc":[{"id":"1.120089104","rc":[{"atl":[[1000,3]],"id":9612932}],"con":true,"img":false,"tv":9271.59}]}
{"op":"mcm","clk":"1147727132","pt":1439895031765,"mc":[{"id":"1.120089104","rc":[{"atl":[[1000,2.48]],"id":9612932}],"con":true,"img":false,"tv":9271.59}]}
{"op":"mcm","clk":"1147727133","pt":1439895031871,"mc":[{"id":"1.120089104","rc":[{"atl":[[1000,1]],"id":9612932}],"con":true,"img":false,"tv":9271.59}]}
{"op":"mcm","clk":"1147727135","pt":1439895031972,"mc":[{"id":"1.120089104","rc":[{"atl":[[1.19,1.48]],"id":9612932}],"con":true,"img":false,"tv":9271.59}]}
{"op":"mcm","clk":"1147727142","pt":1439895032654,"mc":[{"id":"1.120089104","rc":[{"atl":[[1.19,70.73]],"id":9612932}],"con":true,"img":false,"tv":9271.59}]}
{"op":"mcm","clk":"1147727805","pt":1439895067610,"mc":[{"id":"1.120089104","rc":[{"atl":[[1.29,84.17]],"id":9612932}],"con":true,"img":false,"tv":9271.59}]}
{"op":"mcm","clk":"1147727810","pt":1439895067766,"mc":[{"id":"1.120089104","rc":[{"atl":[[1.29,52.77]],"id":9612932}],"con":true,"img":false,"tv":9271.59}]}
{"op":"mcm","clk":"1147728533","pt":1439895110769,"mc":[{"id":"1.120089104","rc":[{"atb":[[1.14,6]],"id":9612932},{"spn":1.15,"spf":1.01,"id":9612932}],"con":true,"img":false,"tv":9271.59}]}
{"op":"mcm","clk":"1147729438","pt":1439895154236,"mc":[{"id":"1.120089104","rc":[{"trd":[[1.17,234.58]],"ltp":1.17,"tv":234.58,"id":9612932},{"atb":[[1.17,103.54]],"id":9612932}],"con":true,"img":false,"tv":9291.59}]}
{"op":"mcm","clk":"1147729796","pt":1439895171214,"mc":[{"id":"1.120089104","rc":[{"atb":[[1.14,29.68]],"id":9612932},{"spn":1.15,"spf":1.01,"id":9612932}],"con":true,"img":false,"tv":9291.59}]}
{"op":"mcm","clk":"1147730144","pt":1439895185693,"mc":[{"id":"1.120089104","rc":[{"atl":[[1.19,76.73]],"id":9612932},{"atl":[[7.8,7.22]],"id":9480385}],"con":true,"img":false,"tv":9291.59}]}
{"op":"mcm","clk":"1147731221","pt":1439895230874,"mc":[{"id":"1.120089104","rc":[{"atl":[[1.2,133.04]],"id":9612932}],"con":true,"img":false,"tv":9291.59}]}
{"op":"mcm","clk":"1147731603","pt":1439895244554,"mc":[{"id":"1.120089104","rc":[{"atl":[[1.2,120.28]],"id":9612932}],"con":true,"img":false,"tv":9291.59}]}
{"op":"mcm","clk":"1147731607","pt":1439895244611,"mc":[{"id":"1.120089104","rc":[{"atl":[[1.21,12.76]],"id":9612932}],"con":true,"img":false,"tv":9291.59}]}
{"op":"mcm","clk":"1147731619","pt":1439895245132,"mc":[{"id":"1.120089104","rc":[{"atl":[[1.22,10]],"id":9612932}],"con":true,"img":false,"tv":9291.59}]}
{"op":"mcm","clk":"1147734594","pt":1439895328717,"mc":[{"id":"1.120089104","rc":[{"trd":[[1.19,86.48]],"ltp":1.19,"tv":86.48,"id":9612932},{"atl":[[1.19,56.38]],"id":9612932}],"con":true,"img":false,"tv":9332.29}]}
{"op":"mcm","clk":"1147736300","pt":1439895385859,"mc":[{"id":"1.120089104","rc":[{"atl":[[1.19,50.38]],"id":9612932},{"atl":[[7.8,1.22]],"id":9480385}],"con":true,"img":false,"tv":9332.29}]}
{"op":"mcm","clk":"1147740211","pt":1439895543327,"mc":[{"id":"1.120089104","rc":[{"atb":[[1.16,563]],"id":9612932},{"spn":1.16,"spf":1.01,"id":9612932}],"con":true,"img":false,"tv":9332.29}]}
{"op":"mcm","clk":"1147740678","pt":1439895566124,"mc":[{"id":"1.120089104","rc":[{"atl":[[7.8,7.22]],"id":9480385}],"con":true,"img":false,"tv":9332.29}]}
{"op":"mcm","clk":"1147741990","pt":1439895633375,"mc":[{"id":"1.120089104","rc":[{"atl":[[1.23,6]],"id":9612932}],"con":true,"img":false,"tv":9332.29}]}
{"op":"mcm","clk":"1147742024","pt":1439895634368,"mc":[{"id":"1.120089104","rc":[{"atb":[[1.13,25]],"id":9612932}],"con":true,"img":false,"tv":9332.29}]}
{"op":"mcm","clk":"1147742182","pt":1439895640145,"mc":[{"id":"1.120089104","rc":[{"atb":[[1.14,23.68]],"id":9612932}],"con":true,"img":false,"tv":9332.29}]}
{"op":"mcm","clk":"1147742219","pt":1439895642660,"mc":[{"id":"1.120089104","rc":[{"atb":[[1.14,80.22]],"id":9612932}],"con":true,"img":false,"tv":9332.29}]}
{"op":"mcm","clk":"1147742223","pt":1439895642867,"mc":[{"id":"1.120089104","rc":[{"atb":[[1.14,56.53]],"id":9612932}],"con":true,"img":false,"tv":9332.29}]}
{"op":"mcm","clk":"1147745208","pt":1439895766319,"mc":[{"id":"1.120089104","rc":[{"atl":[[7.8,1.22]],"id":9480385}],"con":true,"img":false,"tv":9332.29}]}
{"op":"mcm","clk":"1147746212","pt":1439895806861,"mc":[{"id":"1.120089104","rc":[{"spl":[[1.01,835.41]],"id":9612932}],"con":true,"img":false,"tv":9332.29}]}
