{"op":"mcm","clk":"1148374574","pt":1439911164872,"mc":[{"id":"1.120089104","marketDefinition":{"bspMarket":true,"turnInPlayEnabled":true,"persistenceEnabled":true,"marketBaseRate":5.0,"eventId":"27514783","eventTypeId":"7","numberOfWinners":1,"bettingType":"ODDS","marketType":"WIN","marketTime":"2015-08-18T20:20:00.000Z","suspendTime":"2015-08-18T20:20:00.000Z","bspReconciled":false,"complete":true,"inPlay":false,"crossMatching":false,"runnersVoidable":false,"numberOfActiveRunners":2,"betDelay":0,"status":"OPEN","runners":[{"adjustmentFactor":79.72,"status":"ACTIVE","sortPriority":1,"id":9612932,"name":"Alinstante"},{"adjustmentFactor":20.27,"status":"ACTIVE","sortPriority":2,"id":9480385,"name":"Vallance Road"}],"regulators":["MR_NJ","MR_INT"],"venue":"Chelmsford City","countryCode":"GB","discountAllowed":true,"timezone":"Europe/London","openDate":"2015-08-18T17:20:00.000Z","version":1061399117,"name":"1m Cond Stks","eventName":"ChelmC 18th Aug"},"rc":[{"trd":[[1.17,1173.68],[1.3,209.61],[1.29,101.39],[1.16,1865.09],[1.18,3409.03],[1.4,49.38],[1.28,995.14],[1.27,15.7],[1.15,178.6],[1.25,307.89],[1.26,82.87],[1.23,549.83],[1.22,1556.55],[1.24,1188.47],[1.2,689.56],[1.19,191.64],[1.21,1174.11]],"ltp":1.17,"tv":13738.54,"id":9612932},{"atb":[[1.17,15.06],[1.16,16.67],[1.04,41],[1.06,20],[1.14,12000],[1.01,2471.54],[1.13,12000],[1.15,12005.7],[1.02,10250],[1.03,18],[1.12,1474.03],[1.1,11.95],[1.08,21.95],[1.11,340.22],[1.09,5752.14]],"id":9612932},{"spb":[[1000,58]],"id":9612932},{"atl":[[1.3,95.06],[1.18,90.33],[630,0.09],[2,20],[1000,1],[1.27,1.89],[1.25,52],[1.26,400],[1.23,6],[5.2,15],[46,2],[1.24,202],[1.2,42.87],[4,0.25],[540,0.07],[1.21,300],[900,0.24]],"id":9612932},{"spl":[[7,10],[1.88,20.11],[1.01,1072.52],[1.25,2]],"id":9612932},{"spn":1.15,"spf":1.05,"id":9612932},{"trd":[[6.8,26.31],[4.9,11.94],[5.4,38.12],[5.9,3.78],[6.4,43.26],[4.8,120.18],[5.3,25.25],[5.8,16.06],[5.7,1.03],[6,5.75],[5.2,35.52],[4.7,103.21],[6.6,5.64],[7,1.92],[5.1,136.67],[5.6,91.79],[7.2,10.16],[5.5,39.05],[5,329.88],[6.2,6.28]],"ltp":6.8,"tv":1051.8,"id":9480385},{"atb":[[1.43,1250],[1.06,20],[1.18,30],[1.81,12.35],[1.01,2449.54],[5.3,7.23],[1.02,10250],[1.03,18],[5.8,8.93],[1.1,11.95],[6,1.81],[5.2,86.38],[1.08,21.95],[4.7,13.7],[1.11,11.25],[6.6,6.12],[5.1,40.11],[2.92,83.33],[5.5,24.05],[1.09,10.55],[4.6,0.11],[5,50]],"id":9480385},{"spb":[[1000,17]],"id":9480385},{"atl":[[6.8,1.4],[46,2],[13.5,3],[7.8,4.37],[55,0.01],[630,0.09],[90,2],[7.2,16.84],[8.6,27.19],[7.4,1.4],[9.6,26],[540,0.07],[900,0.24]],"id":9480385},{"spl":[[7,10],[1.01,12]],"id":9480385},{"spn":6.39,"spf":2.41,"id":9480385}],"con":true,"img":true,"tv":14790.5}]}
{"op":"mcm","clk":"1148383384","pt":1439911216274,"mc":[{"id":"1.120089104","rc":[{"spn":1.15,"spf":1.05,"id":9612932},{"atl":[[7.2,10.84]],"id":9480385}],"con":true,"img":false,"tv":14790.5}]}
{"op":"mcm","clk":"1148384373","pt":1439911231878,"mc":[{"id":"1.120089104","rc":[{"spl":[[1.01,1082.52]],"id":9612932},{"spn":1.15,"spf":1.05,"id":9612932}],"con":true,"img":false,"tv":14790.5}]}
{"op":"mcm","clk":"1148392564","pt":1439911382546,"mc":[{"id":"1.120089104","rc":[{"atl":[[1.19,100]],"id":9612932}],"con":true,"img":false,"tv":14790.5}]}
{"op":"mcm","clk":"1148393400","pt":1439911394798,"mc":[{"id":"1.120089104","rc":[{"atl":[[1.24,0]],"id":9612932}],"con":true,"img":false,"tv":14790.5}]}
{"op":"mcm","clk":"1148393410","pt":1439911394909,"mc":[{"id":"1.120089104","rc":[{"atl":[[1.23,209]],"id":9612932}],"con":true,"img":false,"tv":14790.5}]}
{"op":"mcm","clk":"1148393752","pt":1439911400378,"mc":[{"id":"1.120089104","rc":[{"atl":[[7.2,16.84]],"id":9480385}],"con":true,"img":false,"tv":14790.5}]}
{"op":"mcm","clk":"1148393872","pt":1439911401785,"mc":[{"id":"1.120089104","rc":[{"atl":[[1.23,203]],"id":9612932}],"con":true,"img":false,"tv":14790.5}]}
{"op":"mcm","clk":"1148402208","pt":1439911541710,"mc":[{"id":"1.120089104","rc":[{"atb":[[1.16,2238.67]],"id":9612932},{"spn":1.16,"spf":1.05,"id":9612932}],"con":true,"img":false,"tv":14790.5}]}
{"op":"mcm","clk":"1148404835","pt":1439911582893,"mc":[{"id":"1.120089104","rc":[{"atb":[[5.8,0]],"id":9480385},{"atl":[[8.6,0]],"id":9480385}],"con":true,"img":false,"tv":14790.5}]}
{"op":"mcm","clk":"1148405458","pt":1439911594105,"mc":[{"id":"1.120089104","rc":[{"atb":[[5.6,5.91]],"id":9480385},{"atl":[[9.4,28.09]],"id":9480385}],"con":true,"img":false,"tv":14790.5}]}
{"op":"mcm","clk":"1148405895","pt":1439911600597,"mc":[{"id":"1.120089104","rc":[{"atl":[[7.2,10.84]],"id":9480385}],"con":true,"img":false,"tv":14790.5}]}
{"op":"mcm","clk":"1148408320","pt":1439911635758,"mc":[{"id":"1.120089104","rc":[{"atl":[[9.6,0]],"id":9480385},{"spn":6.37,"spf":2.41,"id":9480385}],"con":true,"img":false,"tv":14790.5}]}
{"op":"mcm","clk":"1148408327","pt":1439911635862,"mc":[{"id":"1.120089104","rc":[{"atl":[[11,23]],"id":9480385}],"con":true,"img":false,"tv":14790.5}]}
{"op":"mcm","clk":"1148414684","pt":1439911742046,"mc":[{"id":"1.120089104","rc":[{"atl":[[1.19,300]],"id":9612932}],"con":true,"img":false,"tv":14790.5}]}
{"op":"mcm","clk":"1148417055","pt":1439911783999,"mc":[{"id":"1.120089104","rc":[{"atl":[[7.2,16.84]],"id":9480385}],"con":true,"img":false,"tv":14790.5}]}
{"op":"mcm","clk":"1148417120","pt":1439911785166,"mc":[{"id":"1.120089104","rc":[{"atb":[[5.2,36.93]],"id":9480385}],"con":true,"img":false,"tv":14790.5}]}
{"op":"mcm","clk":"1148417150","pt":1439911785600,"mc":[{"id":"1.120089104","rc":[{"atb":[[5.3,65.92]],"id":9480385}],"con":true,"img":false,"tv":14790.5}]}
{"op":"mcm","clk":"1148417510","pt":1439911792181,"mc":[{"id":"1.120089104","rc":[{"atb":[[5.4,6]],"id":9480385}],"con":true,"img":false,"tv":14790.5}]}
{"op":"mcm","clk":"1148417592","pt":1439911793994,"mc":[{"id":"1.120089104","rc":[{"trd":[[1.18,3460.27]],"ltp":1.18,"tv":3460.27,"id":9612932},{"atl":[[1.18,64.71]],"id":9612932}],"con":true,"img":false,"tv":14841.74}]}
{"op":"mcm","clk":"1148422047","pt":1439911875302,"mc":[{"id":"1.120089104","rc":[{"trd":[[1.18,3500.27]],"ltp":1.18,"tv":3500.27,"id":9612932},{"atl":[[1.18,44.71]],"id":9612932}],"con":true,"img":false,"tv":14881.74}]}
{"op":"mcm","clk":"1148422140","pt":1439911876629,"mc":[{"id":"1.120089104","rc":[{"atb":[[1.17,115.06]],"id":9612932}],"con":true,"img":false,"tv":14881.74}]}
{"op":"mcm","clk":"1148422557","pt":1439911883961,"mc":[{"id":"1.120089104","rc":[{"atb":[[5.2,3]],"id":9480385}],"con":true,"img":false,"tv":14881.74}]}
{"op":"mcm","clk":"1148422592","pt":1439911884652,"mc":[{"id":"1.120089104","rc":[{"atb":[[5.3,104.85]],"id":9480385}],"con":true,"img":false,"tv":14881.74}]}
{"op":"mcm","clk":"1148423247","pt":1439911896861,"mc":[{"id":"1.120089104","rc":[{"atb":[[5.1,35.3]],"id":9480385}],"con":true,"img":false,"tv":14881.74}]}
{"op":"mcm","clk":"1148423275","pt":1439911897465,"mc":[{"id":"1.120089104","rc":[{"atb":[[5.3,110.51]],"id":9480385}],"con":true,"img":false,"tv":14881.74}]}
{"op":"mcm","clk":"1148428161","pt":1439911984212,"mc":[{"id":"1.120089104","rc":[{"spn":1.16,"spf":1.05,"id":9612932},{"atl":[[7.2,10.84]],"id":9480385}],"con":true,"img":false,"tv":14881.74}]}
{"op":"mcm","clk":"1148428211","pt":1439911985119,"mc":[{"id":"1.120089104","rc":[{"atb":[[5.3,103.28]],"id":9480385}],"con":true,"img":false,"tv":14881.74}]}
{"op":"mcm","clk":"1148428253","pt":1439911985708,"mc":[{"id":"1.120089104","rc":[{"atb":[[5.3,111.8]],"id":9480385}],"con":true,"img":false,"tv":14881.74}]}
{"op":"mcm","clk":"1148429093","pt":1439911998982,"mc":[{"id":"1.120089104","rc":[{"atb":[[5.1,7.16]],"id":9480385}],"con":true,"img":false,"tv":14881.74}]}
{"op":"mcm","clk":"1148429100","pt":1439911999191,"mc":[{"id":"1.120089104","rc":[{"atb":[[5.3,145.2]],"id":9480385}],"con":true,"img":false,"tv":14881.74}]}
{"op":"mcm","clk":"1148429576","pt":1439912007425,"mc":[{"id":"1.120089104","rc":[{"trd":[[1.18,3540.27]],"ltp":1.18,"tv":3540.27,"id":9612932},{"atl":[[1.18,24.71]],"id":9612932}],"con":true,"img":false,"tv":14921.74}]}
{"op":"mcm","clk":"1148430529","pt":1439912021970,"mc":[{"id":"1.120089104","rc":[{"atb":[[5.6,14.8]],"id":9480385}],"con":true,"img":false,"tv":14921.74}]}
{"op":"mcm","clk":"1148430548","pt":1439912022246,"mc":[{"id":"1.120089104","rc":[{"atb":[[5.6,8.88]],"id":9480385}],"con":true,"img":false,"tv":14921.74}]}
{"op":"mcm","clk":"1148446515","pt":1439912126998,"mc":[{"id":"1.120089104","rc":[{"atb":[[5.6,30.96]],"id":9480385}],"con":true,"img":false,"tv":14921.74}]}
{"op":"mcm","clk":"1148446534","pt":1439912127172,"mc":[{"id":"1.120089104","rc":[{"atb":[[5.6,22.08]],"id":9480385}],"con":true,"img":false,"tv":14921.74}]}
{"op":"mcm","clk":"1148446704","pt":1439912129492,"mc":[{"id":"1.120089104","rc":[{"atl":[[1.19,506.59]],"id":9612932}],"con":true,"img":false,"tv":14921.74}]}
{"op":"mcm","clk":"1148447634","pt":1439912140599,"mc":[{"id":"1.120089104","rc":[{"atb":[[1.03,3018]],"id":9612932}],"con":true,"img":false,"tv":14921.74}]}
{"op":"mcm","clk":"1148448303","pt":1439912149729,"mc":[{"id":"1.120089104","rc":[{"atb":[[1.03,18]],"id":9612932}],"con":true,"img":false,"tv":14921.74}]}
{"op":"mcm","clk":"1148448311","pt":1439912149833,"mc":[{"id":"1.120089104","rc":[{"atb":[[1.16,5238.67]],"id":9612932}],"con":true,"img":false,"tv":14921.74}]}
{"op":"mcm","clk":"1148449580","pt":1439912166303,"mc":[{"id":"1.120089104","rc":[{"atb":[[1.16,5330.83]],"id":9612932}],"con":true,"img":false,"tv":14921.74}]}
{"op":"mcm","clk":"1148449628","pt":1439912166847,"mc":[{"id":"1.120089104","rc":[{"atl":[[7.2,16.84]],"id":9480385}],"con":true,"img":false,"tv":14921.74}]}
{"op":"mcm","clk":"1148450285","pt":1439912175243,"mc":[{"id":"1.120089104","rc":[{"trd":[[1.18,3589.71]],"ltp":1.18,"tv":3589.71,"id":9612932},{"atb":[[1.18,0.28]],"id":9612932},{"atl":[[1.18,0]],"id":9612932}],"con":true,"img":false,"tv":14971.18}]}
{"op":"mcm","clk":"1148450459","pt":1439912177690,"mc":[{"id":"1.120089104","rc":[{"atl":[[1.24,27.6]],"id":9612932}],"con":true,"img":false,"tv":14971.18}]}
{"op":"mcm","clk":"1148454671","pt":1439912237550,"mc":[{"id":"1.120089104","rc":[{"atl":[[1.23,0]],"id":9612932}],"con":true,"img":false,"tv":14971.18}]}
{"op":"mcm","clk":"1148454674","pt":1439912237652,"mc":[{"id":"1.120089104","rc":[{"atl":[[1.24,229.6]],"id":9612932}],"con":true,"img":false,"tv":14971.18}]}
{"op":"mcm","clk":"1148454930","pt":1439912241301,"mc":[{"id":"1.120089104","rc":[{"atl":[[1.24,237.7]],"id":9612932}],"con":true,"img":false,"tv":14971.18}]}
{"op":"mcm","clk":"1148454943","pt":1439912241527,"mc":[{"id":"1.120089104","rc":[{"atl":[[1.24,210.1]],"id":9612932}],"con":true,"img":false,"tv":14971.18}]}
{"op":"mcm","clk":"1148455377","pt":1439912247872,"mc":[{"id":"1.120089104","rc":[{"atl":[[1.24,202]],"id":9612932}],"con":true,"img":false,"tv":14971.18}]}
{"op":"mcm","clk":"1148455650","pt":1439912252600,"mc":[{"id":"1.120089104","rc":[{"atl":[[1.23,2.19]],"id":9612932}],"con":true,"img":false,"tv":14971.18}]}
{"op":"mcm","clk":"1148463053","pt":1439912367046,"mc":[{"id":"1.120089104","rc":[{"atl":[[7.2,10.84]],"id":9480385}],"con":true,"img":false,"tv":14971.18}]}
{"op":"mcm","clk":"1148463123","pt":1439912368325,"mc":[{"id":"1.120089104","rc":[{"atb":[[1.16,5349.82]],"id":9612932}],"con":true,"img":false,"tv":14971.18}]}
{"op":"mcm","clk":"1148466141","pt":1439912413592,"mc":[{"id":"1.120089104","rc":[{"atl":[[1000,9]],"id":9612932},{"trd":[[7.2,17.4],[6.8,29.13]],"ltp":7.2,"tv":46.53,"id":9480385},{"atb":[[1.01,2453.54]],"id":9480385},{"atl":[[6.8,0],[7.2,7.22]],"id":9480385}],"con":true,"img":false,"tv":14981.24}]}
{"op":"mcm","clk":"1148466148","pt":1439912413693,"mc":[{"id":"1.120089104","rc":[{"atl":[[1000,11.25]],"id":9612932},{"atb":[[1.01,2455.05]],"id":9480385}],"con":true,"img":false,"tv":14981.24}]}
{"op":"mcm","clk":"1148466156","pt":1439912413798,"mc":[{"id":"1.120089104","rc":[{"atl":[[1000,3.25]],"id":9612932},{"atb":[[1.01,2451.05]],"id":9480385}],"con":true,"img":false,"tv":14981.24}]}
{"op":"mcm","clk":"1148466177","pt":1439912414011,"mc":[{"id":"1.120089104","rc":[{"atl":[[1000,1]],"id":9612932},{"atb":[[1.01,2449.54]],"id":9480385}],"con":true,"img":false,"tv":14981.24}]}
{"op":"mcm","clk":"1148466187","pt":1439912414071,"mc":[{"id":"1.120089104","rc":[{"trd":[[1.17,1176.57],[1.18,3590.27]],"ltp":1.17,"tv":4766.84,"id":9612932},{"atb":[[1.17,113.61],[1.18,0]],"id":9612932},{"atl":[[1.19,507.11]],"id":9612932},{"atb":[[6.6,7.63]],"id":9480385}],"con":true,"img":false,"tv":14984.69}]}
{"op":"mcm","clk":"1148469966","pt":1439912468380,"mc":[{"id":"1.120089104","rc":[{"atl":[[7,2]],"id":9480385},{"spn":6.51,"spf":2.41,"id":9480385}],"con":true,"img":false,"tv":14984.69}]}
{"op":"mcm","clk":"1148469986","pt":1439912468700,"mc":[{"id":"1.120089104","rc":[{"atl":[[7,3.75]],"id":9480385}],"con":true,"img":false,"tv":14984.69}]}
{"op":"mcm","clk":"1148470984","pt":1439912483548,"mc":[{"id":"1.120089104","rc":[{"atl":[[7,1.75]],"id":9480385}],"con":true,"img":false,"tv":14984.69}]}
{"op":"mcm","clk":"1148471441","pt":1439912489822,"mc":[{"id":"1.120089104","rc":[{"trd":[[6.6,9.64]],"ltp":6.6,"tv":9.64,"id":9480385},{"atb":[[6.6,5.63]],"id":9480385}],"con":true,"img":false,"tv":14988.69}]}
{"op":"mcm","clk":"1148472525","pt":1439912508887,"mc":[{"id":"1.120089104","rc":[{"atl":[[1.23,139.38]],"id":9612932},{"atb":[[5.6,32.96]],"id":9480385}],"con":true,"img":false,"tv":14988.69}]}
{"op":"mcm","clk":"1148472535","pt":1439912509108,"mc":[{"id":"1.120089104","rc":[{"atl":[[1.23,137.19]],"id":9612932},{"atb":[[5.6,10.88]],"id":9480385}],"con":true,"img":false,"tv":14988.69}]}
{"op":"mcm","clk":"1148475053","pt":1439912549123,"mc":[{"id":"1.120089104","rc":[{"atl":[[1.19,513.11]],"id":9612932},{"atl":[[7.2,13.22]],"id":9480385},{"spn":6.32,"spf":2.41,"id":9480385}],"con":true,"img":false,"tv":14988.69}]}
{"op":"mcm","clk":"1148475917","pt":1439912563647,"mc":[{"id":"1.120089104","rc":[{"atl":[[1.18,3.66]],"id":9612932}],"con":true,"img":false,"tv":14988.69}]}
{"op":"mcm","clk":"1148476203","pt":1439912567537,"mc":[{"id":"1.120089104","rc":[{"atl":[[1.23,141.58]],"id":9612932}],"con":true,"img":false,"tv":14988.69}]}
{"op":"mcm","clk":"1148476222","pt":1439912567805,"mc":[{"id":"1.120089104","rc":[{"atl":[[1.23,4.38]],"id":9612932}],"con":true,"img":false,"tv":14988.69}]}
{"op":"mcm","clk":"1148478232","pt":1439912598861,"mc":[{"id":"1.120089104","rc":[{"atl":[[1.24,0]],"id":9612932}],"con":true,"img":false,"tv":14988.69}]}
{"op":"mcm","clk":"1148478237","pt":1439912598966,"mc":[{"id":"1.120089104","rc":[{"atl":[[1.23,207.38]],"id":9612932}],"con":true,"img":false,"tv":14988.69}]}
{"op":"mcm","clk":"1148478963","pt":1439912610140,"mc":[{"id":"1.120089104","rc":[{"trd":[[1.18,3597.59]],"ltp":1.18,"tv":3597.59,"id":9612932},{"atb":[[1.18,296.34]],"id":9612932},{"atl":[[1.18,0]],"id":9612932},{"spn":1.16,"spf":1.05,"id":9612932}],"con":true,"img":false,"tv":14996.01}]}
{"op":"mcm","clk":"1148479005","pt":1439912610732,"mc":[{"id":"1.120089104","rc":[{"trd":[[1.18,3660.57]],"ltp":1.18,"tv":3660.57,"id":9612932},{"atb":[[1.18,264.84]],"id":9612932},{"trd":[[6.6,20.9]],"ltp":6.6,"tv":20.9,"id":9480385},{"atb":[[6.6,0.01]],"id":9480385}],"con":true,"img":false,"tv":15070.25}]}
{"op":"mcm","clk":"1148479078","pt":1439912611859,"mc":[{"id":"1.120089104","rc":[{"atb":[[5.6,20.36]],"id":9480385}],"con":true,"img":false,"tv":15070.25}]}
{"op":"mcm","clk":"1148479096","pt":1439912612020,"mc":[{"id":"1.120089104","rc":[{"atb":[[5.6,9.48]],"id":9480385}],"con":true,"img":false,"tv":15070.25}]}
{"op":"mcm","clk":"1148479121","pt":1439912612446,"mc":[{"id":"1.120089104","rc":[{"atl":[[6.8,22.96]],"id":9480385}],"con":true,"img":false,"tv":15070.25}]}
{"op":"mcm","clk":"1148479632","pt":1439912620639,"mc":[{"id":"1.120089104","rc":[{"atb":[[1.09,4431.43]],"id":9612932}],"con":true,"img":false,"tv":15070.25}]}
{"op":"mcm","clk":"1148479641","pt":1439912620754,"mc":[{"id":"1.120089104","rc":[{"atb":[[1.12,2794.74]],"id":9612932}],"con":true,"img":false,"tv":15070.25}]}
{"op":"mcm","clk":"1148479653","pt":1439912620968,"mc":[{"id":"1.120089104","rc":[{"atb":[[5.3,111.8]],"id":9480385}],"con":true,"img":false,"tv":15070.25}]}
{"op":"mcm","clk":"1148479664","pt":1439912621029,"mc":[{"id":"1.120089104","rc":[{"atb":[[4.9,33.4]],"id":9480385}],"con":true,"img":false,"tv":15070.25}]}
{"op":"mcm","clk":"1148479708","pt":1439912621783,"mc":[{"id":"1.120089104","rc":[{"atb":[[5.6,61.29]],"id":9480385},{"atl":[[7.6,3.1]],"id":9480385}],"con":true,"img":false,"tv":15070.25}]}
{"op":"mcm","clk":"1148479728","pt":1439912622106,"mc":[{"id":"1.120089104","rc":[{"atb":[[5.6,51.81]],"id":9480385},{"atl":[[9.4,0]],"id":9480385}],"con":true,"img":false,"tv":15070.25}]}
{"op":"mcm","clk":"1148479794","pt":1439912622860,"mc":[{"id":"1.120089104","rc":[{"atb":[[5.7,6]],"id":9480385},{"atl":[[7.8,1.22]],"id":9480385}],"con":true,"img":false,"tv":15070.25}]}
{"op":"mcm","clk":"1148479828","pt":1439912623462,"mc":[{"id":"1.120089104","rc":[{"atb":[[5.1,0]],"id":9480385}],"con":true,"img":false,"tv":15070.25}]}
{"op":"mcm","clk":"1148479891","pt":1439912624313,"mc":[{"id":"1.120089104","rc":[{"atb":[[4.9,42.81]],"id":9480385}],"con":true,"img":false,"tv":15070.25}]}
{"op":"mcm","clk":"1148479940","pt":1439912625289,"mc":[{"id":"1.120089104","rc":[{"atb":[[5.8,3]],"id":9480385}],"con":true,"img":false,"tv":15070.25}]}
{"op":"mcm","clk":"1148479944","pt":1439912625394,"mc":[{"id":"1.120089104","rc":[{"trd":[[6.6,20.92]],"ltp":6.6,"tv":20.92,"id":9480385},{"atb":[[6.6,0]],"id":9480385},{"atl":[[6.6,2.99]],"id":9480385}],"con":true,"img":false,"tv":15070.27}]}
{"op":"mcm","clk":"1148479979","pt":1439912625989,"mc":[{"id":"1.120089104","rc":[{"atl":[[6.8,0]],"id":9480385}],"con":true,"img":false,"tv":15070.27}]}
{"op":"mcm","clk":"1148479984","pt":1439912626089,"mc":[{"id":"1.120089104","rc":[{"atb":[[1.18,0]],"id":9612932}],"con":true,"img":false,"tv":15070.27}]}
{"op":"mcm","clk":"1148479987","pt":1439912626200,"mc":[{"id":"1.120089104","rc":[{"trd":[[1.19,721.34]],"ltp":1.19,"tv":721.34,"id":9612932},{"atl":[[1.19,248.26]],"id":9612932},{"atb":[[6,3.89]],"id":9480385},{"atl":[[6.6,5.07],[7.4,0]],"id":9480385}],"con":true,"img":false,"tv":15599.97}]}
{"op":"mcm","clk":"1148480039","pt":1439912626895,"mc":[{"id":"1.120089104","rc":[{"atl":[[7.6,13.33]],"id":9480385}],"con":true,"img":false,"tv":15599.97}]}
{"op":"mcm","clk":"1148480052","pt":1439912627104,"mc":[{"id":"1.120089104","rc":[{"atl":[[7.6,10.22]],"id":9480385}],"con":true,"img":false,"tv":15599.97}]}
{"op":"mcm","clk":"1148480435","pt":1439912632625,"mc":[{"id":"1.120089104","rc":[{"atl":[[7.6,17.88]],"id":9480385}],"con":true,"img":false,"tv":15599.97}]}
{"op":"mcm","clk":"1148480460","pt":1439912632834,"mc":[{"id":"1.120089104","rc":[{"atl":[[7.6,7.65]],"id":9480385}],"con":true,"img":false,"tv":15599.97}]}
{"op":"mcm","clk":"1148480674","pt":1439912636251,"mc":[{"id":"1.120089104","rc":[{"atb":[[1.18,17.88]],"id":9612932},{"atb":[[6.2,3.4]],"id":9480385}],"con":true,"img":false,"tv":15599.97}]}
{"op":"mcm","clk":"1148480801","pt":1439912638280,"mc":[{"id":"1.120089104","rc":[{"atb":[[5.8,32.32]],"id":9480385}],"con":true,"img":false,"tv":15599.97}]}
{"op":"mcm","clk":"1148480817","pt":1439912638478,"mc":[{"id":"1.120089104","rc":[{"atb":[[5.6,0]],"id":9480385}],"con":true,"img":false,"tv":15599.97}]}
{"op":"mcm","clk":"1148481658","pt":1439912651797,"mc":[{"id":"1.120089104","rc":[{"atb":[[5.7,0]],"id":9480385}],"con":true,"img":false,"tv":15599.97}]}
{"op":"mcm","clk":"1148482114","pt":1439912659514,"mc":[{"id":"1.120089104","rc":[{"atb":[[1.12,2571.74]],"id":9612932},{"atl":[[1.23,4.38]],"id":9612932},{"atb":[[5,0]],"id":9480385},{"atl":[[11,0]],"id":9480385}],"con":true,"img":false,"tv":15599.97}]}
{"op":"mcm","clk":"1148482118","pt":1439912659620,"mc":[{"id":"1.120089104","rc":[{"atb":[[1.13,12221]],"id":9612932},{"atl":[[1.24,202]],"id":9612932},{"atb":[[5.3,158.8]],"id":9480385},{"atl":[[8.6,29]],"id":9480385}],"con":true,"img":false,"tv":15599.97}]}
{"op":"mcm","clk":"1148482253","pt":1439912661804,"mc":[{"id":"1.120089104","rc":[{"atl":[[6.6,2.08]],"id":9480385}],"con":true,"img":false,"tv":15599.97}]}
{"op":"mcm","clk":"1148484465","pt":1439912698399,"mc":[{"id":"1.120089104","rc":[{"atb":[[1.09,2892.22]],"id":9612932},{"spn":1.16,"spf":1.05,"id":9612932},{"spn":6.04,"spf":2.41,"id":9480385}],"con":true,"img":false,"tv":15599.97}]}
{"op":"mcm","clk":"1148484469","pt":1439912698506,"mc":[{"id":"1.120089104","rc":[{"atb":[[1.12,4110.95]],"id":9612932}],"con":true,"img":false,"tv":15599.97}]}
{"op":"mcm","clk":"1148484492","pt":1439912698883,"mc":[{"id":"1.120089104","rc":[{"atb":[[5.3,119.87]],"id":9480385}],"con":true,"img":false,"tv":15599.97}]}
{"op":"mcm","clk":"1148484494","pt":1439912698986,"mc":[{"id":"1.120089104","rc":[{"atb":[[5,38.92]],"id":9480385}],"con":true,"img":false,"tv":15599.97}]}
{"op":"mcm","clk":"1148487483","pt":1439912747685,"mc":[{"id":"1.120089104","rc":[{"atb":[[1.09,2668.5]],"id":9612932}],"con":true,"img":false,"tv":15599.97}]}
{"op":"mcm","clk":"1148487488","pt":1439912747795,"mc":[{"id":"1.120089104","rc":[{"atb":[[1.12,4334.66]],"id":9612932}],"con":true,"img":false,"tv":15599.97}]}
{"op":"mcm","clk":"1148487521","pt":1439912748430,"mc":[{"id":"1.120089104","rc":[{"atb":[[5.3,114.21]],"id":9480385}],"con":true,"img":false,"tv":15599.97}]}
{"op":"mcm","clk":"1148487525","pt":1439912748537,"mc":[{"id":"1.120089104","rc":[{"atb":[[5,44.58]],"id":9480385}],"con":true,"img":false,"tv":15599.97}]}
{"op":"mcm","clk":"1148487564","pt":1439912749197,"mc":[{"id":"1.120089104","rc":[{"atl":[[1.19,242.26]],"id":9612932},{"atl":[[7.2,7.22]],"id":9480385}],"con":true,"img":false,"tv":15599.97}]}
{"op":"mcm","clk":"1148488696","pt":1439912767188,"mc":[{"id":"1.120089104","rc":[{"trd":[[1.19,761.34]],"ltp":1.19,"tv":761.34,"id":9612932},{"atl":[[1.19,222.26]],"id":9612932}],"con":true,"img":false,"tv":15639.97}]}
{"op":"mcm","clk":"1148490786","pt":1439912797848,"mc":[{"id":"1.120089104","rc":[{"atb":[[1.09,347.47]],"id":9612932}],"con":true,"img":false,"tv":15639.97}]}
{"op":"mcm","clk":"1148490794","pt":1439912797955,"mc":[{"id":"1.120089104","rc":[{"atb":[[1.12,6655.7]],"id":9612932}],"con":true,"img":false,"tv":15639.97}]}
{"op":"mcm","clk":"1148490820","pt":1439912798374,"mc":[{"id":"1.120089104","rc":[{"atb":[[5.3,55.51]],"id":9480385}],"con":true,"img":false,"tv":15639.97}]}
{"op":"mcm","clk":"1148490825","pt":1439912798477,"mc":[{"id":"1.120089104","rc":[{"atb":[[5,103.28]],"id":9480385}],"con":true,"img":false,"tv":15639.97}]}
{"op":"mcm","clk":"1148491548","pt":1439912811851,"mc":[{"id":"1.120089104","rc":[{"atb":[[5.1,6]],"id":9480385}],"con":true,"img":false,"tv":15639.97}]}
{"op":"mcm","clk":"1148492714","pt":1439912830288,"mc":[{"id":"1.120089104","rc":[{"atb":[[1.09,10.55]],"id":9612932}],"con":true,"img":false,"tv":15639.97}]}
{"op":"mcm","clk":"1148492719","pt":1439912830388,"mc":[{"id":"1.120089104","rc":[{"atb":[[1.12,6992.62]],"id":9612932}],"con":true,"img":false,"tv":15639.97}]}
{"op":"mcm","clk":"1148492749","pt":1439912830982,"mc":[{"id":"1.120089104","rc":[{"atb":[[5.3,47]],"id":9480385}],"con":true,"img":false,"tv":15639.97}]}
{"op":"mcm","clk":"1148492760","pt":1439912831092,"mc":[{"id":"1.120089104","rc":[{"atb":[[5,111.8]],"id":9480385}],"con":true,"img":false,"tv":15639.97}]}
{"op":"mcm","clk":"1148493243","pt":1439912838320,"mc":[{"id":"1.120089104","rc":[{"atb":[[5.4,0]],"id":9480385}],"con":true,"img":false,"tv":15639.97}]}
{"op":"mcm","clk":"1148502253","pt":1439912957294,"mc":[{"id":"1.120089104","rc":[{"trd":[[1.18,3684.62]],"ltp":1.18,"tv":3684.62,"id":9612932},{"atb":[[1.18,5.86]],"id":9612932},{"spn":1.16,"spf":1.05,"id":9612932}],"con":true,"img":false,"tv":15664.01}]}
{"op":"mcm","clk":"1148512232","pt":1439912969147,"mc":[{"id":"1.120089104","rc":[{"trd":[[1.18,3694.62]],"ltp":1.18,"tv":3694.62,"id":9612932},{"atb":[[1.18,0.85]],"id":9612932}],"con":true,"img":false,"tv":15674.02}]}
{"op":"mcm","clk":"1148512256","pt":1439912969573,"mc":[{"id":"1.120089104","rc":[{"atb":[[1.17,149.61]],"id":9612932}],"con":true,"img":false,"tv":15674.02}]}
{"op":"mcm","clk":"1148514343","pt":1439912998026,"mc":[{"id":"1.120089104","rc":[{"atl":[[1.23,28.81]],"id":9612932}],"con":true,"img":false,"tv":15674.02}]}
{"op":"mcm","clk":"1148514356","pt":1439912998241,"mc":[{"id":"1.120089104","rc":[{"atl":[[1.23,24.42]],"id":9612932}],"con":true,"img":false,"tv":15674.02}]}
{"op":"mcm","clk":"1148515986","pt":1439913020951,"mc":[{"id":"1.120089104","rc":[{"atb":[[1.13,12000]],"id":9612932},{"spn":1.16,"spf":1.05,"id":9612932}],"con":true,"img":false,"tv":15674.02}]}
{"op":"mcm","clk":"1148515995","pt":1439913021003,"mc":[{"id":"1.120089104","rc":[{"atb":[[1.12,7215.62]],"id":9612932}],"con":true,"img":false,"tv":15674.02}]}
{"op":"mcm","clk":"1148519672","pt":1439913078420,"mc":[{"id":"1.120089104","rc":[{"atb":[[1.12,4894.58]],"id":9612932},{"atb":[[5,53.1]],"id":9480385}],"con":true,"img":false,"tv":15674.02}]}
{"op":"mcm","clk":"1148521638","pt":1439913111358,"mc":[{"id":"1.120089104","rc":[{"atl":[[1.23,26]],"id":9612932}],"con":true,"img":false,"tv":15674.02}]}
{"op":"mcm","clk":"1148521644","pt":1439913111513,"mc":[{"id":"1.120089104","rc":[{"atl":[[1.23,1.58]],"id":9612932}],"con":true,"img":false,"tv":15674.02}]}
{"op":"mcm","clk":"1148522507","pt":1439913125267,"mc":[{"id":"1.120089104","rc":[{"atb":[[1.17,853.09]],"id":9612932}],"con":true,"img":false,"tv":15674.02}]}
{"op":"mcm","clk":"1148524429","pt":1439913152551,"mc":[{"id":"1.120089104","rc":[{"trd":[[1.19,771.34]],"ltp":1.19,"tv":771.34,"id":9612932},{"atl":[[1.19,217.26]],"id":9612932}],"con":true,"img":false,"tv":15684.02}]}
{"op":"mcm","clk":"1148524714","pt":1439913157030,"mc":[{"id":"1.120089104","rc":[{"trd":[[6.2,10.27]],"ltp":6.2,"tv":10.27,"id":9480385},{"atb":[[6.2,1.4]],"id":9480385}],"con":true,"img":false,"tv":15688.01}]}
{"op":"mcm","clk":"1148527620","pt":1439913201712,"mc":[{"id":"1.120089104","rc":[{"spn":1.17,"spf":1.05,"id":9612932},{"atb":[[5.3,0]],"id":9480385},{"spn":5.95,"spf":2.41,"id":9480385}],"con":true,"img":false,"tv":15688.01}]}
{"op":"mcm","clk":"1148527625","pt":1439913201786,"mc":[{"id":"1.120089104","rc":[{"atb":[[5,103.1]],"id":9480385}],"con":true,"img":false,"tv":15688.01}]}
{"op":"mcm","clk":"1148533963","pt":1439913309848,"mc":[{"id":"1.120089104","rc":[{"atb":[[5,64.17]],"id":9480385}],"con":true,"img":false,"tv":15688.01}]}
{"op":"mcm","clk":"1148533999","pt":1439913310339,"mc":[{"id":"1.120089104","rc":[{"atb":[[4.9,89.63]],"id":9480385}],"con":true,"img":false,"tv":15688.01}]}
{"op":"mcm","clk":"1148536768","pt":1439913357758,"mc":[{"id":"1.120089104","rc":[{"spl":[[1.4,20]],"id":9612932}],"con":true,"img":false,"tv":15688.01}]}
{"op":"mcm","clk":"1148537605","pt":1439913371891,"mc":[{"id":"1.120089104","rc":[{"atb":[[5.5,33.45]],"id":9480385},{"atl":[[6.8,7.6]],"id":9480385}],"con":true,"img":false,"tv":15688.01}]}
{"op":"mcm","clk":"1148537646","pt":1439913372424,"mc":[{"id":"1.120089104","rc":[{"spb":[[1.15,20]],"id":9612932}],"con":true,"img":false,"tv":15688.01}]}
{"op":"mcm","clk":"1148538524","pt":1439913385631,"mc":[{"id":"1.120089104","rc":[{"atb":[[5,58.51]],"id":9480385}],"con":true,"img":false,"tv":15688.01}]}
{"op":"mcm","clk":"1148538566","pt":1439913386224,"mc":[{"id":"1.120089104","rc":[{"atb":[[5,65.15]],"id":9480385}],"con":true,"img":false,"tv":15688.01}]}
{"op":"mcm","clk":"1148540725","pt":1439913422575,"mc":[{"id":"1.120089104","rc":[{"atl":[[1.23,0]],"id":9612932},{"atb":[[5.8,3]],"id":9480385},{"atl":[[7.6,0]],"id":9480385}],"con":true,"img":false,"tv":15688.01}]}
{"op":"mcm","clk":"1148541538","pt":1439913436856,"mc":[{"id":"1.120089104","rc":[{"atl":[[1.25,78.02]],"id":9612932},{"spn":1.17,"spf":1.07,"id":9612932},{"atb":[[5.8,32.32]],"id":9480385},{"atl":[[8.4,8.51]],"id":9480385}],"con":true,"img":false,"tv":15688.01}]}
{"op":"mcm","clk":"1148541902","pt":1439913442685,"mc":[{"id":"1.120089104","rc":[{"atl":[[8.6,0]],"id":9480385}],"con":true,"img":false,"tv":15688.01}]}
{"op":"mcm","clk":"1148541912","pt":1439913442795,"mc":[{"id":"1.120089104","rc":[{"atl":[[8.2,30]],"id":9480385}],"con":true,"img":false,"tv":15688.01}]}
{"op":"mcm","clk":"1148542158","pt":1439913447038,"mc":[{"id":"1.120089104","rc":[{"atl":[[8,5.81]],"id":9480385}],"con":true,"img":false,"tv":15688.01}]}
{"op":"mcm","clk":"1148542163","pt":1439913447241,"mc":[{"id":"1.120089104","rc":[{"atl":[[8.4,0]],"id":9480385}],"con":true,"img":false,"tv":15688.01}]}
{"op":"mcm","clk":"1148543397","pt":1439913467795,"mc":[{"id":"1.120089104","rc":[{"atb":[[5,56.63]],"id":9480385}],"con":true,"img":false,"tv":15688.01}]}
{"op":"mcm","clk":"1148543429","pt":1439913468175,"mc":[{"id":"1.120089104","rc":[{"atb":[[4.9,56.23]],"id":9480385}],"con":true,"img":false,"tv":15688.01}]}
{"op":"mcm","clk":"1148543442","pt":1439913468285,"mc":[{"id":"1.120089104","rc":[{"atb":[[5,95.8]],"id":9480385}],"con":true,"img":false,"tv":15688.01}]}
{"op":"mcm","clk":"1148543447","pt":1439913468390,"mc":[{"id":"1.120089104","rc":[{"atb":[[5,105.79]],"id":9480385}],"con":true,"img":false,"tv":15688.01}]}
{"op":"mcm","clk":"1148548017","pt":1439913541059,"mc":[{"id":"1.120089104","rc":[{"atb":[[1.18,23.85]],"id":9612932},{"spn":1.17,"spf":1.07,"id":9612932}],"con":true,"img":false,"tv":15688.01}]}
{"op":"mcm","clk":"1148548048","pt":1439913541699,"mc":[{"id":"1.120089104","rc":[{"atb":[[1.17,817.09]],"id":9612932}],"con":true,"img":false,"tv":15688.01}]}
{"op":"mcm","clk":"1148549479","pt":1439913563322,"mc":[{"id":"1.120089104","rc":[{"atb":[[1.12,4671.58]],"id":9612932}],"con":true,"img":false,"tv":15688.01}]}
{"op":"mcm","clk":"1148549483","pt":1439913563429,"mc":[{"id":"1.120089104","rc":[{"atb":[[1.13,12221]],"id":9612932}],"con":true,"img":false,"tv":15688.01}]}
{"op":"mcm","clk":"1148551974","pt":1439913600079,"mc":[{"id":"1.120089104","rc":[{"trd":[[1.19,780.22]],"ltp":1.19,"tv":780.22,"id":9612932},{"atl":[[1.19,212.82]],"id":9612932}],"con":true,"img":false,"tv":15696.89}]}
{"op":"mcm","clk":"1148552257","pt":1439913604126,"mc":[{"id":"1.120089104","rc":[{"atl":[[1.25,52]],"id":9612932},{"atb":[[5.8,3]],"id":9480385},{"atl":[[8,0]],"id":9480385},{"spn":5.94,"spf":2.41,"id":9480385}],"con":true,"img":false,"tv":15696.89}]}
{"op":"mcm","clk":"1148553403","pt":1439913618541,"mc":[{"id":"1.120089104","rc":[{"atl":[[1.23,32.02]],"id":9612932},{"atb":[[5.6,39.65]],"id":9480385},{"atl":[[8,5.81]],"id":9480385}],"con":true,"img":false,"tv":15696.89}]}
{"op":"mcm","clk":"1148558117","pt":1439913684047,"mc":[{"id":"1.120089104","rc":[{"trd":[[1.19,780.29],[1.3,209.65],[1.29,101.45],[1.17,1176.9],[1.16,1865.16],[1.18,3694.96],[1.28,995.73],[1.27,15.71],[1.25,308.24],[1.26,82.97],[1.23,550.09],[1.22,1556.86],[1.24,1189.19],[1.2,689.66],[1.21,1174.2]],"ltp":1.19,"tv":14391.06,"id":9612932},{"atb":[[1.17,817.97],[1.16,5349.98],[1.18,23.85],[1.01,2472.65],[1.12,4676.29],[1.1,11.97],[1.08,21.97],[1.11,340.6],[1.09,10.56]],"id":9612932},{"atl":[[1.23,32.06]],"id":9612932},{"spl":[[1.01,1082.85]],"id":9612932},{"trd":[[6.2,10.28],[6.8,29.14],[4.9,11.95],[5.4,38.14],[6.4,43.28],[4.8,120.25],[5.3,25.25],[5.8,16.06],[5.7,1.03],[6,5.76],[5.2,35.54],[4.7,103.28],[6.6,20.92],[5.1,136.7],[5.6,91.81],[7.2,17.4],[5.5,39.07],[5,330.27]],"ltp":6.2,"tv":1076.13,"id":9480385},{"atb":[[4.9,56.32],[1.01,2450.65],[1.1,11.97],[6,3.89],[1.08,21.97],[4.7,13.7],[1.11,11.26],[5.6,39.7],[5.5,33.47],[1.09,10.56],[4.6,0.11],[5,55.85],[6.2,1.4]],"id":9480385},{"atl":[[6.8,7.61],[7.8,1.22],[8,5.82],[6.6,2.08],[7,1.75]],"id":9480385},{"spn":5.95,"spf":2.41,"id":9480385}],"con":true,"img":false,"tv":15701.04}]}
{"op":"mcm","clk":"1148558124","pt":1439913684104,"mc":[{"id":"1.120089104","rc":[{"atb":[[5.1,55]],"id":9480385}],"con":true,"img":false,"tv":15701.04}]}
{"op":"mcm","clk":"1148558405","pt":1439913687636,"mc":[{"id":"1.120089104","rc":[{"atb":[[5.8,32.16]],"id":9480385}],"con":true,"img":false,"tv":15701.04}]}
{"op":"mcm","clk":"1148558417","pt":1439913687841,"mc":[{"id":"1.120089104","rc":[{"atb":[[5.6,0]],"id":9480385}],"con":true,"img":false,"tv":15701.04}]}
{"op":"mcm","clk":"1148561612","pt":1439913731762,"mc":[{"id":"1.120089104","rc":[{"atl":[[1.23,52.07]],"id":9612932}],"con":true,"img":false,"tv":15701.04}]}
{"op":"mcm","clk":"1148561626","pt":1439913731971,"mc":[{"id":"1.120089104","rc":[{"atl":[[1.23,20]],"id":9612932}],"con":true,"img":false,"tv":15701.04}]}
{"op":"mcm","clk":"1148562650","pt":1439913744586,"mc":[{"id":"1.120089104","rc":[{"atb":[[5.1,6]],"id":9480385},{"spn":5.95,"spf":2.41,"id":9480385}],"con":true,"img":false,"tv":15701.04}]}
{"op":"mcm","clk":"1148562663","pt":1439913744694,"mc":[{"id":"1.120089104","rc":[{"atb":[[5,105.85]],"id":9480385}],"con":true,"img":false,"tv":15701.04}]}
{"op":"mcm","clk":"1148564557","pt":1439913770631,"mc":[{"id":"1.120089104","rc":[{"trd":[[1.17,1349.18],[1.18,3742.68]],"ltp":1.17,"tv":5091.85,"id":9612932},{"atb":[[1.17,731.83],[1.18,0]],"id":9612932}],"con":true,"img":false,"tv":15921.04}]}
{"op":"mcm","clk":"1148566056","pt":1439913790487,"mc":[{"id":"1.120089104","rc":[{"atb":[[1.11,33.26]],"id":9612932}],"con":true,"img":false,"tv":15921.04}]}
{"op":"mcm","clk":"1148566071","pt":1439913790702,"mc":[{"id":"1.120089104","rc":[{"atb":[[1.11,399.15]],"id":9612932}],"con":true,"img":false,"tv":15921.04}]}
{"op":"mcm","clk":"1148566593","pt":1439913798362,"mc":[{"id":"1.120089104","rc":[{"atb":[[1.11,3025.8]],"id":9612932}],"con":true,"img":false,"tv":15921.04}]}
{"op":"mcm","clk":"1148566688","pt":1439913799512,"mc":[{"id":"1.120089104","rc":[{"atb":[[4.9,130.41]],"id":9480385}],"con":true,"img":false,"tv":15921.04}]}
{"op":"mcm","clk":"1148567005","pt":1439913803632,"mc":[{"id":"1.120089104","rc":[{"atb":[[6.2,8.97]],"id":9480385}],"con":true,"img":false,"tv":15921.04}]}
{"op":"mcm","clk":"1148567131","pt":1439913805160,"mc":[{"id":"1.120089104","rc":[{"atb":[[1.13,12000]],"id":9612932},{"spn":1.16,"spf":1.07,"id":9612932},{"spn":6.2,"spf":2.41,"id":9480385}],"con":true,"img":false,"tv":15921.04}]}
{"op":"mcm","clk":"1148567141","pt":1439913805258,"mc":[{"id":"1.120089104","rc":[{"atb":[[1.12,4899.29]],"id":9612932}],"con":true,"img":false,"tv":15921.04}]}
{"op":"mcm","clk":"1148581375","pt":1439913865663,"mc":[{"id":"1.120089104","rc":[{"atb":[[5,55.85]],"id":9480385}],"con":true,"img":false,"tv":15921.04}]}
{"op":"mcm","clk":"1148581387","pt":1439913865770,"mc":[{"id":"1.120089104","rc":[{"atb":[[5.3,47]],"id":9480385}],"con":true,"img":false,"tv":15921.04}]}
{"op":"mcm","clk":"1148600513","pt":1439914088297,"mc":[{"id":"1.120089104","rc":[{"atl":[[1000,9]],"id":9612932},{"atb":[[1.01,2454.65],[6.2,13.55]],"id":9480385}],"con":true,"img":false,"tv":15921.04}]}
{"op":"mcm","clk":"1148600534","pt":1439914088505,"mc":[{"id":"1.120089104","rc":[{"atl":[[1000,11.25]],"id":9612932},{"atb":[[1.01,2456.99]],"id":9480385}],"con":true,"img":false,"tv":15921.04}]}
{"op":"mcm","clk":"1148600543","pt":1439914088611,"mc":[{"id":"1.120089104","rc":[{"atl":[[1000,3.25]],"id":9612932},{"atb":[[1.01,2452.99]],"id":9480385}],"con":true,"img":false,"tv":15921.04}]}
{"op":"mcm","clk":"1148600556","pt":1439914088677,"mc":[{"id":"1.120089104","rc":[{"atl":[[1000,1]],"id":9612932},{"atb":[[1.01,2450.65]],"id":9480385}],"con":true,"img":false,"tv":15921.04}]}
{"op":"mcm","clk":"1148600564","pt":1439914088775,"mc":[{"id":"1.120089104","rc":[{"trd":[[1.17,1350.7]],"ltp":1.17,"tv":1350.7,"id":9612932},{"atb":[[1.17,731.07]],"id":9612932},{"atl":[[1.19,214.31]],"id":9612932},{"trd":[[6.6,25.09]],"ltp":6.6,"tv":25.09,"id":9480385},{"atb":[[6.6,0.26]],"id":9480385},{"atl":[[6.6,0]],"id":9480385}],"con":true,"img":false,"tv":15926.73}]}
{"op":"mcm","clk":"1148601040","pt":1439914094092,"mc":[{"id":"1.120089104","rc":[{"trd":[[1.19,980.29]],"ltp":1.19,"tv":980.29,"id":9612932},{"atl":[[1.19,114.31]],"id":9612932}],"con":true,"img":false,"tv":16126.73}]}
{"op":"mcm","clk":"1148601501","pt":1439914098608,"mc":[{"id":"1.120089104","rc":[{"atb":[[5.1,0]],"id":9480385}],"con":true,"img":false,"tv":16126.73}]}
{"op":"mcm","clk":"1148601839","pt":1439914102205,"mc":[{"id":"1.120089104","rc":[{"atb":[[1.18,28]],"id":9612932}],"con":true,"img":false,"tv":16126.73}]}
{"op":"mcm","clk":"1148601862","pt":1439914102484,"mc":[{"id":"1.120089104","rc":[{"atb":[[6,1.81]],"id":9480385}],"con":true,"img":false,"tv":16126.73}]}
{"op":"mcm","clk":"1148602619","pt":1439914111341,"mc":[{"id":"1.120089104","rc":[{"atb":[[5.5,24.05]],"id":9480385},{"atl":[[6.8,0]],"id":9480385}],"con":true,"img":false,"tv":16126.73}]}
{"op":"mcm","clk":"1148602723","pt":1439914112743,"mc":[{"id":"1.120089104","rc":[{"atb":[[5.8,29.16]],"id":9480385}],"con":true,"img":false,"tv":16126.73}]}
{"op":"mcm","clk":"1148602768","pt":1439914113455,"mc":[{"id":"1.120089104","rc":[{"atl":[[6.8,2.41]],"id":9480385}],"con":true,"img":false,"tv":16126.73}]}
{"op":"mcm","clk":"1148602864","pt":1439914114687,"mc":[{"id":"1.120089104","rc":[{"atb":[[5.6,28.08]],"id":9480385}],"con":true,"img":false,"tv":16126.73}]}
{"op":"mcm","clk":"1148602886","pt":1439914114907,"mc":[{"id":"1.120089104","rc":[{"atb":[[5.8,0]],"id":9480385}],"con":true,"img":false,"tv":16126.73}]}
{"op":"mcm","clk":"1148606987","pt":1439914166829,"mc":[{"id":"1.120089104","rc":[{"atb":[[1.12,4676.29]],"id":9612932},{"spn":1.17,"spf":1.07,"id":9612932},{"atb":[[5.3,0]],"id":9480385},{"atl":[[8.2,0]],"id":9480385},{"spn":6.21,"spf":2.41,"id":9480385}],"con":true,"img":false,"tv":16126.73}]}
{"op":"mcm","clk":"1148606999","pt":1439914166937,"mc":[{"id":"1.120089104","rc":[{"atb":[[1.13,12221]],"id":9612932},{"atb":[[5,105.85]],"id":9480385},{"atl":[[9,28]],"id":9480385}],"con":true,"img":false,"tv":16126.73}]}
{"op":"mcm","clk":"1148621800","pt":1439914352370,"mc":[{"id":"1.120089104","rc":[{"trd":[[1.19,1208.92]],"ltp":1.19,"tv":1208.92,"id":9612932},{"atb":[[1.19,71.03]],"id":9612932},{"atl":[[1.19,0]],"id":9612932},{"spn":1.17,"spf":1.07,"id":9612932}],"con":true,"img":false,"tv":16355.35}]}
{"op":"mcm","clk":"1148621886","pt":1439914353706,"mc":[{"id":"1.120089104","rc":[{"atl":[[1000,3]],"id":9612932},{"atl":[[6.8,8.47],[1000,2]],"id":9480385}],"con":true,"img":false,"tv":16355.35}]}
{"op":"mcm","clk":"1148621891","pt":1439914353813,"mc":[{"id":"1.120089104","rc":[{"atl":[[1000,2.44]],"id":9612932},{"atl":[[1000,0.26]],"id":9480385}],"con":true,"img":false,"tv":16355.35}]}
{"op":"mcm","clk":"1148621899","pt":1439914353873,"mc":[{"id":"1.120089104","rc":[{"atl":[[1000,1]],"id":9612932},{"atl":[[1000,0]],"id":9480385}],"con":true,"img":false,"tv":16355.35}]}
{"op":"mcm","clk":"1148621911","pt":1439914353985,"mc":[{"id":"1.120089104","rc":[{"trd":[[1.19,1211.79]],"ltp":1.19,"tv":1211.79,"id":9612932},{"atb":[[1.19,69.6]],"id":9612932},{"trd":[[6.6,25.61]],"ltp":6.6,"tv":25.61,"id":9480385},{"atb":[[6.6,0]],"id":9480385}],"con":true,"img":false,"tv":16358.75}]}
{"op":"mcm","clk":"1148621947","pt":1439914354618,"mc":[{"id":"1.120089104","rc":[{"atb":[[5.1,6]],"id":9480385}],"con":true,"img":false,"tv":16358.75}]}
{"op":"mcm","clk":"1148622663","pt":1439914364653,"mc":[{"id":"1.120089104","rc":[{"atl":[[1.23,133.36]],"id":9612932}],"con":true,"img":false,"tv":16358.75}]}
{"op":"mcm","clk":"1148622685","pt":1439914364863,"mc":[{"id":"1.120089104","rc":[{"atl":[[1.23,113.35]],"id":9612932}],"con":true,"img":false,"tv":16358.75}]}
{"op":"mcm","clk":"1148622753","pt":1439914365768,"mc":[{"id":"1.120089104","rc":[{"atl":[[6.8,10.76]],"id":9480385}],"con":true,"img":false,"tv":16358.75}]}
{"op":"mcm","clk":"1148623151","pt":1439914372323,"mc":[{"id":"1.120089104","rc":[{"atl":[[1.23,146.35]],"id":9612932}],"con":true,"img":false,"tv":16358.75}]}
{"op":"mcm","clk":"1148623172","pt":1439914372645,"mc":[{"id":"1.120089104","rc":[{"atl":[[1.23,32.99]],"id":9612932}],"con":true,"img":false,"tv":16358.75}]}
{"op":"mcm","clk":"1148623522","pt":1439914377508,"mc":[{"id":"1.120089104","rc":[{"atl":[[1.23,173.86]],"id":9612932}],"con":true,"img":false,"tv":16358.75}]}
{"op":"mcm","clk":"1148623540","pt":1439914377720,"mc":[{"id":"1.120089104","rc":[{"atl":[[1.23,140.86]],"id":9612932}],"con":true,"img":false,"tv":16358.75}]}
{"op":"mcm","clk":"1148624033","pt":1439914383602,"mc":[{"id":"1.120089104","rc":[{"atl":[[1.23,173.86]],"id":9612932}],"con":true,"img":false,"tv":16358.75}]}
{"op":"mcm","clk":"1148624263","pt":1439914386430,"mc":[{"id":"1.120089104","rc":[{"atl":[[1.23,32.99]],"id":9612932}],"con":true,"img":false,"tv":16358.75}]}
{"op":"mcm","clk":"1148624480","pt":1439914389425,"mc":[{"id":"1.120089104","rc":[{"atl":[[1.23,158.65]],"id":9612932}],"con":true,"img":false,"tv":16358.75}]}
{"op":"mcm","clk":"1148624505","pt":1439914389673,"mc":[{"id":"1.120089104","rc":[{"atl":[[1.23,125.65]],"id":9612932}],"con":true,"img":false,"tv":16358.75}]}
{"op":"mcm","clk":"1148624959","pt":1439914394694,"mc":[{"id":"1.120089104","rc":[{"atl":[[1.23,158.65]],"id":9612932}],"con":true,"img":false,"tv":16358.75}]}
{"op":"mcm","clk":"1148624971","pt":1439914394907,"mc":[{"id":"1.120089104","rc":[{"atl":[[1.23,32.99]],"id":9612932}],"con":true,"img":false,"tv":16358.75}]}
{"op":"mcm","clk":"1148625414","pt":1439914400419,"mc":[{"id":"1.120089104","rc":[{"atl":[[1.23,158.65]],"id":9612932}],"con":true,"img":false,"tv":16358.75}]}
{"op":"mcm","clk":"1148625425","pt":1439914400580,"mc":[{"id":"1.120089104","rc":[{"atl":[[1.23,125.65]],"id":9612932}],"con":true,"img":false,"tv":16358.75}]}
{"op":"mcm","clk":"1148625928","pt":1439914407911,"mc":[{"id":"1.120089104","rc":[{"atb":[[1.13,12000]],"id":9612932},{"atl":[[1.24,0]],"id":9612932}],"con":true,"img":false,"tv":16358.75}]}
{"op":"mcm","clk":"1148625930","pt":1439914408021,"mc":[{"id":"1.120089104","rc":[{"atb":[[1.14,12219]],"id":9612932},{"atl":[[1.26,598]],"id":9612932}],"con":true,"img":false,"tv":16358.75}]}
{"op":"mcm","clk":"1148625936","pt":1439914408121,"mc":[{"id":"1.120089104","rc":[{"atl":[[1.23,158.65]],"id":9612932}],"con":true,"img":false,"tv":16358.75}]}
{"op":"mcm","clk":"1148626128","pt":1439914411177,"mc":[{"id":"1.120089104","rc":[{"atl":[[1.23,32.99]],"id":9612932}],"con":true,"img":false,"tv":16358.75}]}
{"op":"mcm","clk":"1148626341","pt":1439914414074,"mc":[{"id":"1.120089104","rc":[{"atl":[[1.23,158.65]],"id":9612932},{"spn":6.2,"spf":2.41,"id":9480385}],"con":true,"img":false,"tv":16358.75}]}
{"op":"mcm","clk":"1148626363","pt":1439914414292,"mc":[{"id":"1.120089104","rc":[{"atl":[[1.23,125.65]],"id":9612932}],"con":true,"img":false,"tv":16358.75}]}
{"op":"mcm","clk":"1148626685","pt":1439914419384,"mc":[{"id":"1.120089104","rc":[{"atl":[[1.23,158.65]],"id":9612932}],"con":true,"img":false,"tv":16358.75}]}
{"op":"mcm","clk":"1148626691","pt":1439914419546,"mc":[{"id":"1.120089104","rc":[{"atl":[[1.23,32.99]],"id":9612932}],"con":true,"img":false,"tv":16358.75}]}
{"op":"mcm","clk":"1148628900","pt":1439914449354,"mc":[{"id":"1.120089104","rc":[{"atb":[[1.15,12011.15]],"id":9612932}],"con":true,"img":false,"tv":16358.75}]}
{"op":"mcm","clk":"1148629251","pt":1439914453590,"mc":[{"id":"1.120089104","rc":[{"trd":[[1.2,693.66]],"ltp":1.2,"tv":693.66,"id":9612932},{"atl":[[1.2,40.87]],"id":9612932},{"atb":[[5.8,2]],"id":9480385}],"con":true,"img":false,"tv":16362.75}]}
{"op":"mcm","clk":"1148635734","pt":1439914528653,"mc":[{"id":"1.120089104","rc":[{"atb":[[5,55.85]],"id":9480385}],"con":true,"img":false,"tv":16362.75}]}
{"op":"mcm","clk":"1148635741","pt":1439914528753,"mc":[{"id":"1.120089104","rc":[{"atb":[[5.1,55]],"id":9480385}],"con":true,"img":false,"tv":16362.75}]}
{"op":"mcm","clk":"1148636798","pt":1439914540874,"mc":[{"id":"1.120089104","rc":[{"trd":[[1.19,1351]],"ltp":1.19,"tv":1351.0,"id":9612932},{"atb":[[1.19,0]],"id":9612932},{"atl":[[1.19,0.83]],"id":9612932}],"con":true,"img":false,"tv":16501.95}]}
{"op":"mcm","clk":"1148636891","pt":1439914541963,"mc":[{"id":"1.120089104","rc":[{"atl":[[6.8,4.7]],"id":9480385}],"con":true,"img":false,"tv":16501.95}]}
{"op":"mcm","clk":"1148637148","pt":1439914545717,"mc":[{"id":"1.120089104","rc":[{"atl":[[1.23,48.14]],"id":9612932}],"con":true,"img":false,"tv":16501.95}]}
{"op":"mcm","clk":"1148637168","pt":1439914545886,"mc":[{"id":"1.120089104","rc":[{"atl":[[1.23,15.14]],"id":9612932}],"con":true,"img":false,"tv":16501.95}]}
{"op":"mcm","clk":"1148637761","pt":1439914552871,"mc":[{"id":"1.120089104","rc":[{"atl":[[1.2,745.19]],"id":9612932}],"con":true,"img":false,"tv":16501.95}]}
{"op":"mcm","clk":"1148638538","pt":1439914562237,"mc":[{"id":"1.120089104","rc":[{"atb":[[1.17,801.5]],"id":9612932}],"con":true,"img":false,"tv":16501.95}]}
{"op":"mcm","clk":"1148640825","pt":1439914589211,"mc":[{"id":"1.120089104","rc":[{"atb":[[1.14,12000]],"id":9612932},{"spn":1.17,"spf":1.07,"id":9612932}],"con":true,"img":false,"tv":16501.95}]}
{"op":"mcm","clk":"1148640842","pt":1439914589326,"mc":[{"id":"1.120089104","rc":[{"atb":[[1.13,12221]],"id":9612932}],"con":true,"img":false,"tv":16501.95}]}
{"op":"mcm","clk":"1148641352","pt":1439914595270,"mc":[{"id":"1.120089104","rc":[{"atb":[[1.15,12005.7]],"id":9612932}],"con":true,"img":false,"tv":16501.95}]}
{"op":"mcm","clk":"1148641367","pt":1439914595382,"mc":[{"id":"1.120089104","rc":[{"atb":[[1.12,4681.74]],"id":9612932}],"con":true,"img":false,"tv":16501.95}]}
{"op":"mcm","clk":"1148647903","pt":1439914676055,"mc":[{"id":"1.120089104","rc":[{"atl":[[5.2,0]],"id":9612932}],"con":true,"img":false,"tv":16501.95}]}
{"op":"mcm","clk":"1148649198","pt":1439914689114,"mc":[{"id":"1.120089104","rc":[{"atl":[[1.19,77.83]],"id":9612932}],"con":true,"img":false,"tv":16501.95}]}
{"op":"mcm","clk":"1148649419","pt":1439914691232,"mc":[{"id":"1.120089104","rc":[{"atl":[[5.2,15]],"id":9612932}],"con":true,"img":false,"tv":16501.95}]}
{"op":"mcm","clk":"1148649435","pt":1439914691435,"mc":[{"id":"1.120089104","rc":[{"atl":[[1.23,51.02]],"id":9612932}],"con":true,"img":false,"tv":16501.95}]}
{"op":"mcm","clk":"1148649456","pt":1439914691644,"mc":[{"id":"1.120089104","rc":[{"atl":[[1.23,35.87]],"id":9612932}],"con":true,"img":false,"tv":16501.95}]}
{"op":"mcm","clk":"1148665801","pt":1439914770006,"mc":[{"id":"1.120089104","rc":[{"atl":[[1.26,400]],"id":9612932}],"con":true,"img":false,"tv":16501.95}]}
{"op":"mcm","clk":"1148665812","pt":1439914770115,"mc":[{"id":"1.120089104","rc":[{"atl":[[1.24,202]],"id":9612932}],"con":true,"img":false,"tv":16501.95}]}
{"op":"mcm","clk":"1148669815","pt":1439914812945,"mc":[{"id":"1.120089104","rc":[{"atb":[[1.16,5351.39]],"id":9612932},{"atb":[[5.5,25.45]],"id":9480385}],"con":true,"img":false,"tv":16501.95}]}
{"op":"mcm","clk":"1148676886","pt":1439914889509,"mc":[{"id":"1.120089104","rc":[{"spl":[[1.01,1087.85]],"id":9612932},{"spn":1.17,"spf":1.07,"id":9612932}],"con":true,"img":false,"tv":16501.95}]}
{"op":"mcm","clk":"1148679274","pt":1439914915383,"mc":[{"id":"1.120089104","rc":[{"atl":[[3.95,4.22]],"id":9612932}],"con":true,"img":false,"tv":16501.95}]}
{"op":"mcm","clk":"1148681521","pt":1439914940610,"mc":[{"id":"1.120089104","rc":[{"trd":[[1.19,1381.8]],"ltp":1.19,"tv":1381.8,"id":9612932},{"atl":[[1.19,62.43]],"id":9612932}],"con":true,"img":false,"tv":16532.75}]}
{"op":"mcm","clk":"1148682139","pt":1439914948394,"mc":[{"id":"1.120089104","rc":[{"trd":[[1.19,1393.8]],"ltp":1.19,"tv":1393.8,"id":9612932},{"atl":[[1.19,56.43]],"id":9612932}],"con":true,"img":false,"tv":16544.75}]}
{"op":"mcm","clk":"1148683106","pt":1439914960058,"mc":[{"id":"1.120089104","rc":[{"trd":[[1.19,1424.7]],"ltp":1.19,"tv":1424.7,"id":9612932},{"atl":[[1.19,40.98]],"id":9612932}],"con":true,"img":false,"tv":16575.65}]}
{"op":"mcm","clk":"1148684944","pt":1439914983977,"mc":[{"id":"1.120089104","rc":[{"atb":[[5.6,49.55]],"id":9480385}],"con":true,"img":false,"tv":16575.65}]}
{"op":"mcm","clk":"1148684959","pt":1439914984144,"mc":[{"id":"1.120089104","rc":[{"atb":[[5.6,21.47]],"id":9480385}],"con":true,"img":false,"tv":16575.65}]}
{"op":"mcm","clk":"1148685392","pt":1439914989588,"mc":[{"id":"1.120089104","rc":[{"trd":[[1.19,1455.6]],"ltp":1.19,"tv":1455.6,"id":9612932},{"atl":[[1.19,25.53]],"id":9612932}],"con":true,"img":false,"tv":16606.55}]}
{"op":"mcm","clk":"1148686603","pt":1439915005369,"mc":[{"id":"1.120089104","rc":[{"trd":[[1.19,1475.6]],"ltp":1.19,"tv":1475.6,"id":9612932},{"atl":[[1.19,15.53]],"id":9612932}],"con":true,"img":false,"tv":16626.55}]}
{"op":"mcm","clk":"1148687039","pt":1439915011742,"mc":[{"id":"1.120089104","rc":[{"atb":[[5.6,38.61]],"id":9480385}],"con":true,"img":false,"tv":16626.55}]}
{"op":"mcm","clk":"1148687056","pt":1439915011952,"mc":[{"id":"1.120089104","rc":[{"atb":[[5.6,17.14]],"id":9480385}],"con":true,"img":false,"tv":16626.55}]}
{"op":"mcm","clk":"1148688270","pt":1439915028236,"mc":[{"id":"1.120089104","rc":[{"atb":[[5.6,30.03]],"id":9480385}],"con":true,"img":false,"tv":16626.55}]}
{"op":"mcm","clk":"1148688289","pt":1439915028444,"mc":[{"id":"1.120089104","rc":[{"atb":[[5.6,12.89]],"id":9480385}],"con":true,"img":false,"tv":16626.55}]}
{"op":"mcm","clk":"1148688708","pt":1439915033813,"mc":[{"id":"1.120089104","rc":[{"atb":[[5.6,54.18]],"id":9480385}],"con":true,"img":false,"tv":16626.55}]}
{"op":"mcm","clk":"1148688728","pt":1439915033974,"mc":[{"id":"1.120089104","rc":[{"atb":[[5.6,41.28]],"id":9480385}],"con":true,"img":false,"tv":16626.55}]}
{"op":"mcm","clk":"1148689683","pt":1439915045466,"mc":[{"id":"1.120089104","rc":[{"atb":[[1.18,105]],"id":9612932}],"con":true,"img":false,"tv":16626.55}]}
{"op":"mcm","clk":"1148689819","pt":1439915046710,"mc":[{"id":"1.120089104","rc":[{"atl":[[6.8,9.05]],"id":9480385}],"con":true,"img":false,"tv":16626.55}]}
{"op":"mcm","clk":"1148690062","pt":1439915049570,"mc":[{"id":"1.120089104","rc":[{"atl":[[1.23,59.55]],"id":9612932}],"con":true,"img":false,"tv":16626.55}]}
{"op":"mcm","clk":"1148690074","pt":1439915049730,"mc":[{"id":"1.120089104","rc":[{"atl":[[1.23,23.67]],"id":9612932}],"con":true,"img":false,"tv":16626.55}]}
{"op":"mcm","clk":"1148693311","pt":1439915093311,"mc":[{"id":"1.120089104","rc":[{"atl":[[1.23,29.41]],"id":9612932},{"spn":1.17,"spf":1.07,"id":9612932},{"atb":[[5.6,58.43]],"id":9480385}],"con":true,"img":false,"tv":16626.55}]}
{"op":"mcm","clk":"1148693331","pt":1439915093539,"mc":[{"id":"1.120089104","rc":[{"atl":[[1.23,5.73]],"id":9612932},{"atb":[[5.6,17.14]],"id":9480385}],"con":true,"img":false,"tv":16626.55}]}
{"op":"mcm","clk":"1148701316","pt":1439915193316,"mc":[{"id":"1.120089104","rc":[{"atl":[[8,7.23]],"id":9480385}],"con":true,"img":false,"tv":16626.55}]}
{"op":"mcm","clk":"1148701951","pt":1439915203727,"mc":[{"id":"1.120089104","rc":[{"atl":[[8,5.82]],"id":9480385}],"con":true,"img":false,"tv":16626.55}]}
{"op":"mcm","clk":"1148701961","pt":1439915203827,"mc":[{"id":"1.120089104","rc":[{"atl":[[12,1.4]],"id":9480385}],"con":true,"img":false,"tv":16626.55}]}
{"op":"mcm","clk":"1148707649","pt":1439915283460,"mc":[{"id":"1.120089104","rc":[{"trd":[[1.18,3952.68]],"ltp":1.18,"tv":3952.68,"id":9612932},{"atb":[[1.18,0]],"id":9612932},{"atl":[[1.18,395]],"id":9612932},{"spn":1.17,"spf":1.07,"id":9612932}],"con":true,"img":false,"tv":16836.55}]}
{"op":"mcm","clk":"1148707772","pt":1439915285004,"mc":[{"id":"1.120089104","rc":[{"atl":[[6.8,0]],"id":9480385}],"con":true,"img":false,"tv":16836.55}]}
{"op":"mcm","clk":"1148707938","pt":1439915287042,"mc":[{"id":"1.120089104","rc":[{"atl":[[1.23,32.89]],"id":9612932}],"con":true,"img":false,"tv":16836.55}]}
{"op":"mcm","clk":"1148707965","pt":1439915287321,"mc":[{"id":"1.120089104","rc":[{"atl":[[1.23,27.15]],"id":9612932}],"con":true,"img":false,"tv":16836.55}]}
{"op":"mcm","clk":"1148708210","pt":1439915290746,"mc":[{"id":"1.120089104","rc":[{"atl":[[1.18,0]],"id":9612932}],"con":true,"img":false,"tv":16836.55}]}
{"op":"mcm","clk":"1148708317","pt":1439915292088,"mc":[{"id":"1.120089104","rc":[{"atl":[[1.23,32.89]],"id":9612932}],"con":true,"img":false,"tv":16836.55}]}
{"op":"mcm","clk":"1148708329","pt":1439915292242,"mc":[{"id":"1.120089104","rc":[{"atl":[[1.23,5.73]],"id":9612932}],"con":true,"img":false,"tv":16836.55}]}
{"op":"mcm","clk":"1148709600","pt":1439915307814,"mc":[{"id":"1.120089104","rc":[{"trd":[[1.17,2140.7]],"ltp":1.17,"tv":2140.7,"id":9612932},{"atb":[[1.17,406.5]],"id":9612932}],"con":true,"img":false,"tv":17626.55}]}
{"op":"mcm","clk":"1148709901","pt":1439915311562,"mc":[{"id":"1.120089104","rc":[{"atb":[[1.13,12000]],"id":9612932},{"atl":[[1.24,0]],"id":9612932},{"atl":[[9,0]],"id":9480385}],"con":true,"img":false,"tv":17626.55}]}
{"op":"mcm","clk":"1148709912","pt":1439915311624,"mc":[{"id":"1.120089104","rc":[{"atb":[[1.12,4904.74]],"id":9612932},{"atl":[[1.23,208.73]],"id":9612932},{"atl":[[10,25]],"id":9480385}],"con":true,"img":false,"tv":17626.55}]}
{"op":"mcm","clk":"1148710296","pt":1439915316596,"mc":[{"id":"1.120089104","rc":[{"atb":[[1.12,3582.45]],"id":9612932}],"con":true,"img":false,"tv":17626.55}]}
{"op":"mcm","clk":"1148710313","pt":1439915316765,"mc":[{"id":"1.120089104","rc":[{"atb":[[1.11,4594.52]],"id":9612932}],"con":true,"img":false,"tv":17626.55}]}
{"op":"mcm","clk":"1148710866","pt":1439915323895,"mc":[{"id":"1.120089104","rc":[{"atb":[[1.12,2040.78]],"id":9612932}],"con":true,"img":false,"tv":17626.55}]}
{"op":"mcm","clk":"1148710911","pt":1439915324422,"mc":[{"id":"1.120089104","rc":[{"atb":[[1.11,6423.5]],"id":9612932}],"con":true,"img":false,"tv":17626.55}]}
{"op":"mcm","clk":"1148711164","pt":1439915327418,"mc":[{"id":"1.120089104","rc":[{"atb":[[4.9,120.98]],"id":9480385}],"con":true,"img":false,"tv":17626.55}]}
{"op":"mcm","clk":"1148711220","pt":1439915328006,"mc":[{"id":"1.120089104","rc":[{"atb":[[5,66.98]],"id":9480385}],"con":true,"img":false,"tv":17626.55}]}
{"op":"mcm","clk":"1148713325","pt":1439915354429,"mc":[{"id":"1.120089104","rc":[{"atb":[[1.11,6568.95]],"id":9612932},{"spn":1.16,"spf":1.07,"id":9612932},{"atb":[[2.86,8.6]],"id":9480385}],"con":true,"img":false,"tv":17626.55}]}
{"op":"mcm","clk":"1148713498","pt":1439915356737,"mc":[{"id":"1.120089104","rc":[{"atb":[[1.12,1703.46]],"id":9612932}],"con":true,"img":false,"tv":17626.55}]}
{"op":"mcm","clk":"1148713547","pt":1439915357320,"mc":[{"id":"1.120089104","rc":[{"atb":[[1.11,6969.14]],"id":9612932}],"con":true,"img":false,"tv":17626.55}]}
{"op":"mcm","clk":"1148714725","pt":1439915372497,"mc":[{"id":"1.120089104","rc":[{"atl":[[1.23,5.73]],"id":9612932},{"atl":[[10,0]],"id":9480385}],"con":true,"img":false,"tv":17626.55}]}
{"op":"mcm","clk":"1148714733","pt":1439915372563,"mc":[{"id":"1.120089104","rc":[{"atl":[[1.24,202]],"id":9612932},{"atl":[[12.5,20]],"id":9480385}],"con":true,"img":false,"tv":17626.55}]}
{"op":"mcm","clk":"1148718708","pt":1439915433045,"mc":[{"id":"1.120089104","rc":[{"atl":[[12.5,0]],"id":9480385}],"con":true,"img":false,"tv":17626.55}]}
{"op":"mcm","clk":"1148718710","pt":1439915433157,"mc":[{"id":"1.120089104","rc":[{"atl":[[15,17]],"id":9480385}],"con":true,"img":false,"tv":17626.55}]}
{"op":"mcm","clk":"1148719538","pt":1439915444969,"mc":[{"id":"1.120089104","rc":[{"spl":[[1.01,1094.88]],"id":9612932}],"con":true,"img":false,"tv":17626.55}]}
{"op":"mcm","clk":"1148721307","pt":1439915470511,"mc":[{"id":"1.120089104","rc":[{"atb":[[1.02,10282.35]],"id":9612932},{"atb":[[1.02,10282.35]],"id":9480385}],"con":true,"img":false,"tv":17626.55}]}
{"op":"mcm","clk":"1148723048","pt":1439915493604,"mc":[{"id":"1.120089104","rc":[{"spn":1.16,"spf":1.07,"id":9612932},{"atl":[[15,0]],"id":9480385}],"con":true,"img":false,"tv":17626.55}]}
{"op":"mcm","clk":"1148723058","pt":1439915493721,"mc":[{"id":"1.120089104","rc":[{"atl":[[16,16]],"id":9480385}],"con":true,"img":false,"tv":17626.55}]}
{"op":"mcm","clk":"1148724205","pt":1439915508425,"mc":[{"id":"1.120089104","rc":[{"atb":[[1.12,1479.48]],"id":9612932}],"con":true,"img":false,"tv":17626.55}]}
{"op":"mcm","clk":"1148724264","pt":1439915509065,"mc":[{"id":"1.120089104","rc":[{"atb":[[1.11,7248.85]],"id":9612932}],"con":true,"img":false,"tv":17626.55}]}
{"op":"mcm","clk":"1148724323","pt":1439915509659,"mc":[{"id":"1.120089104","rc":[{"atb":[[5,60.33]],"id":9480385}],"con":true,"img":false,"tv":17626.55}]}
{"op":"mcm","clk":"1148724380","pt":1439915510258,"mc":[{"id":"1.120089104","rc":[{"atb":[[5,68.03]],"id":9480385}],"con":true,"img":false,"tv":17626.55}]}
{"op":"mcm","clk":"1148725146","pt":1439915519591,"mc":[{"id":"1.120089104","rc":[{"trd":[[1.17,2162.7]],"ltp":1.17,"tv":2162.7,"id":9612932},{"atb":[[1.17,395.5]],"id":9612932}],"con":true,"img":false,"tv":17648.55}]}
{"op":"mcm","clk":"1148725893","pt":1439915529298,"mc":[{"id":"1.120089104","rc":[{"atb":[[5,28.81]],"id":9480385}],"con":true,"img":false,"tv":17648.55}]}
{"op":"mcm","clk":"1148725960","pt":1439915530204,"mc":[{"id":"1.120089104","rc":[{"atb":[[5,74.22]],"id":9480385}],"con":true,"img":false,"tv":17648.55}]}
{"op":"mcm","clk":"1148729658","pt":1439915583496,"mc":[{"id":"1.120089104","rc":[{"spn":1.16,"spf":1.07,"id":9612932},{"atb":[[5,64.22]],"id":9480385}],"con":true,"img":false,"tv":17648.55}]}
{"op":"mcm","clk":"1148729714","pt":1439915584098,"mc":[{"id":"1.120089104","rc":[{"atb":[[5,75.8]],"id":9480385}],"con":true,"img":false,"tv":17648.55}]}
{"op":"mcm","clk":"1148731330","pt":1439915606913,"mc":[{"id":"1.120089104","rc":[{"atl":[[1.19,52.53]],"id":9612932}],"con":true,"img":false,"tv":17648.55}]}
{"op":"mcm","clk":"1148731857","pt":1439915613845,"mc":[{"id":"1.120089104","rc":[{"atl":[[1.23,15.43]],"id":9612932}],"con":true,"img":false,"tv":17648.55}]}
{"op":"mcm","clk":"1148731884","pt":1439915614064,"mc":[{"id":"1.120089104","rc":[{"atl":[[1.23,9.7]],"id":9612932}],"con":true,"img":false,"tv":17648.55}]}
{"op":"mcm","clk":"1148733394","pt":1439915632624,"mc":[{"id":"1.120089104","rc":[{"atl":[[7.2,13.22]],"id":9480385}],"con":true,"img":false,"tv":17648.55}]}
{"op":"mcm","clk":"1148733467","pt":1439915633525,"mc":[{"id":"1.120089104","rc":[{"atl":[[1.19,58.53]],"id":9612932}],"con":true,"img":false,"tv":17648.55}]}
{"op":"mcm","clk":"1148753634","pt":1439915763108,"mc":[{"id":"1.120089104","rc":[{"atl":[[1000,9]],"id":9612932}],"con":true,"img":false,"tv":17648.55}]}
{"op":"mcm","clk":"1148753650","pt":1439915763318,"mc":[{"id":"1.120089104","rc":[{"atl":[[1000,11.25]],"id":9612932}],"con":true,"img":false,"tv":17648.55}]}
{"op":"mcm","clk":"1148753662","pt":1439915763429,"mc":[{"id":"1.120089104","rc":[{"atl":[[1000,3.25]],"id":9612932}],"con":true,"img":false,"tv":17648.55}]}
{"op":"mcm","clk":"1148753670","pt":1439915763538,"mc":[{"id":"1.120089104","rc":[{"atl":[[1000,1]],"id":9612932}],"con":true,"img":false,"tv":17648.55}]}
{"op":"mcm","clk":"1148753681","pt":1439915763649,"mc":[{"id":"1.120089104","rc":[{"trd":[[1.17,2165.24]],"ltp":1.17,"tv":2165.24,"id":9612932},{"atb":[[1.17,394.23]],"id":9612932},{"atl":[[1.19,59.51]],"id":9612932}],"con":true,"img":false,"tv":17651.09}]}
{"op":"mcm","clk":"1148757968","pt":1439915811454,"mc":[{"id":"1.120089104","rc":[{"atl":[[1.23,0]],"id":9612932},{"atb":[[5.6,0]],"id":9480385},{"atl":[[8,0]],"id":9480385}],"con":true,"img":false,"tv":17651.09}]}
{"op":"mcm","clk":"1148759236","pt":1439915825810,"mc":[{"id":"1.120089104","rc":[{"atl":[[1.23,9.7]],"id":9612932},{"atb":[[5.6,9.97]],"id":9480385}],"con":true,"img":false,"tv":17651.09}]}
{"op":"mcm","clk":"1148759816","pt":1439915832865,"mc":[{"id":"1.120089104","rc":[{"atl":[[7.2,7.22]],"id":9480385}],"con":true,"img":false,"tv":17651.09}]}
{"op":"mcm","clk":"1148759880","pt":1439915833680,"mc":[{"id":"1.120089104","rc":[{"atl":[[1.19,53.51]],"id":9612932}],"con":true,"img":false,"tv":17651.09}]}
{"op":"mcm","clk":"1148765792","pt":1439915899222,"mc":[{"id":"1.120089104","rc":[{"atb":[[1.18,175]],"id":9612932},{"spn":1.16,"spf":1.07,"id":9612932}],"con":true,"img":false,"tv":17651.09}]}
{"op":"mcm","clk":"1148765836","pt":1439915899736,"mc":[{"id":"1.120089104","rc":[{"atl":[[1.19,16.51]],"id":9612932}],"con":true,"img":false,"tv":17651.09}]}
{"op":"mcm","clk":"1148765927","pt":1439915900441,"mc":[{"id":"1.120089104","rc":[{"atl":[[6.8,15.13]],"id":9480385}],"con":true,"img":false,"tv":17651.09}]}
{"op":"mcm","clk":"1148771327","pt":1439915961535,"mc":[{"id":"1.120089104","rc":[{"atb":[[5.6,24.96]],"id":9480385}],"con":true,"img":false,"tv":17651.09}]}
{"op":"mcm","clk":"1148771341","pt":1439915961697,"mc":[{"id":"1.120089104","rc":[{"atb":[[5.6,14.99]],"id":9480385}],"con":true,"img":false,"tv":17651.09}]}
{"op":"mcm","clk":"1148771786","pt":1439915967852,"mc":[{"id":"1.120089104","rc":[{"atb":[[5.6,26.27]],"id":9480385}],"con":true,"img":false,"tv":17651.09}]}
{"op":"mcm","clk":"1148771806","pt":1439915968161,"mc":[{"id":"1.120089104","rc":[{"atb":[[5.6,11.28]],"id":9480385}],"con":true,"img":false,"tv":17651.09}]}
{"op":"mcm","clk":"1148772290","pt":1439915975035,"mc":[{"id":"1.120089104","rc":[{"atb":[[1.12,1256.48]],"id":9612932},{"atl":[[16,0]],"id":9480385}],"con":true,"img":false,"tv":17651.09}]}
{"op":"mcm","clk":"1148772300","pt":1439915975095,"mc":[{"id":"1.120089104","rc":[{"atb":[[1.13,12221]],"id":9612932},{"atl":[[14.5,17]],"id":9480385}],"con":true,"img":false,"tv":17651.09}]}
{"op":"mcm","clk":"1148773215","pt":1439915986617,"mc":[{"id":"1.120089104","rc":[{"atl":[[1.23,0]],"id":9612932},{"atb":[[5.6,0]],"id":9480385}],"con":true,"img":false,"tv":17651.09}]}
{"op":"mcm","clk":"1148774346","pt":1439916000759,"mc":[{"id":"1.120089104","rc":[{"atl":[[1.23,6.09]],"id":9612932},{"atb":[[5.6,35.91]],"id":9480385}],"con":true,"img":false,"tv":17651.09}]}
{"op":"mcm","clk":"1148774875","pt":1439916008235,"mc":[{"id":"1.120089104","rc":[{"atb":[[5.6,47.19]],"id":9480385}],"con":true,"img":false,"tv":17651.09}]}
{"op":"mcm","clk":"1148775142","pt":1439916011717,"mc":[{"id":"1.120089104","rc":[{"atb":[[5.6,11.28]],"id":9480385}],"con":true,"img":false,"tv":17651.09}]}
{"op":"mcm","clk":"1148784407","pt":1439916133270,"mc":[{"id":"1.120089104","rc":[{"atb":[[4.9,74.08]],"id":9480385}],"con":true,"img":false,"tv":17651.09}]}
{"op":"mcm","clk":"1148784448","pt":1439916133762,"mc":[{"id":"1.120089104","rc":[{"atb":[[5,131.69]],"id":9480385}],"con":true,"img":false,"tv":17651.09}]}
{"op":"mcm","clk":"1148786362","pt":1439916158293,"mc":[{"id":"1.120089104","rc":[{"trd":[[1.19,1495.6]],"ltp":1.19,"tv":1495.6,"id":9612932},{"atl":[[1.19,6.51]],"id":9612932}],"con":true,"img":false,"tv":17671.09}]}
{"op":"mcm","clk":"1148786809","pt":1439916163978,"mc":[{"id":"1.120089104","rc":[{"atb":[[5.6,16.08]],"id":9480385}],"con":true,"img":false,"tv":17671.09}]}
{"op":"mcm","clk":"1148786823","pt":1439916164194,"mc":[{"id":"1.120089104","rc":[{"atb":[[5.6,4.8]],"id":9480385}],"con":true,"img":false,"tv":17671.09}]}
{"op":"mcm","clk":"1148787275","pt":1439916169644,"mc":[{"id":"1.120089104","rc":[{"atl":[[1.23,10.9]],"id":9612932},{"atb":[[5.6,13.44]],"id":9480385}],"con":true,"img":false,"tv":17671.09}]}
{"op":"mcm","clk":"1148787289","pt":1439916169861,"mc":[{"id":"1.120089104","rc":[{"atl":[[1.23,4.81]],"id":9612932},{"atb":[[5.6,8.64]],"id":9480385}],"con":true,"img":false,"tv":17671.09}]}
{"op":"mcm","clk":"1148787695","pt":1439916175487,"mc":[{"id":"1.120089104","rc":[{"atb":[[5.6,13.44]],"id":9480385}],"con":true,"img":false,"tv":17671.09}]}
{"op":"mcm","clk":"1148787710","pt":1439916175699,"mc":[{"id":"1.120089104","rc":[{"atb":[[5.6,4.8]],"id":9480385}],"con":true,"img":false,"tv":17671.09}]}
{"op":"mcm","clk":"1148788069","pt":1439916181484,"mc":[{"id":"1.120089104","rc":[{"atb":[[5.6,13.44]],"id":9480385}],"con":true,"img":false,"tv":17671.09}]}
{"op":"mcm","clk":"1148788088","pt":1439916181648,"mc":[{"id":"1.120089104","rc":[{"atb":[[5.6,8.64]],"id":9480385}],"con":true,"img":false,"tv":17671.09}]}
{"op":"mcm","clk":"1148788514","pt":1439916186955,"mc":[{"id":"1.120089104","rc":[{"atb":[[5.6,13.44]],"id":9480385}],"con":true,"img":false,"tv":17671.09}]}
{"op":"mcm","clk":"1148788531","pt":1439916187115,"mc":[{"id":"1.120089104","rc":[{"atb":[[5.6,4.8]],"id":9480385}],"con":true,"img":false,"tv":17671.09}]}
{"op":"mcm","clk":"1148788947","pt":1439916192305,"mc":[{"id":"1.120089104","rc":[{"atb":[[5.6,13.44]],"id":9480385}],"con":true,"img":false,"tv":17671.09}]}
{"op":"mcm","clk":"1148788972","pt":1439916192471,"mc":[{"id":"1.120089104","rc":[{"atb":[[5.6,8.64]],"id":9480385}],"con":true,"img":false,"tv":17671.09}]}
{"op":"mcm","clk":"1148789473","pt":1439916197615,"mc":[{"id":"1.120089104","rc":[{"atb":[[5.6,13.44]],"id":9480385}],"con":true,"img":false,"tv":17671.09}]}
{"op":"mcm","clk":"1148789493","pt":1439916197821,"mc":[{"id":"1.120089104","rc":[{"atb":[[5.6,4.8]],"id":9480385}],"con":true,"img":false,"tv":17671.09}]}
{"op":"mcm","clk":"1148789756","pt":1439916201261,"mc":[{"id":"1.120089104","rc":[{"trd":[[1.19,1508.62]],"ltp":1.19,"tv":1508.62,"id":9612932},{"atb":[[1.19,19.04]],"id":9612932},{"atl":[[1.19,0]],"id":9612932}],"con":true,"img":false,"tv":17684.11}]}
{"op":"mcm","clk":"1148789932","pt":1439916203344,"mc":[{"id":"1.120089104","rc":[{"atb":[[5.6,13.44]],"id":9480385}],"con":true,"img":false,"tv":17684.11}]}
{"op":"mcm","clk":"1148789949","pt":1439916203556,"mc":[{"id":"1.120089104","rc":[{"atb":[[5.6,8.64]],"id":9480385}],"con":true,"img":false,"tv":17684.11}]}
{"op":"mcm","clk":"1148790340","pt":1439916208923,"mc":[{"id":"1.120089104","rc":[{"atl":[[1.23,145.67]],"id":9612932},{"atb":[[5.6,13.44]],"id":9480385}],"con":true,"img":false,"tv":17684.11}]}
{"op":"mcm","clk":"1148790355","pt":1439916209090,"mc":[{"id":"1.120089104","rc":[{"atl":[[1.23,140.86]],"id":9612932},{"atb":[[5.6,4.8]],"id":9480385}],"con":true,"img":false,"tv":17684.11}]}
{"op":"mcm","clk":"1148790388","pt":1439916209618,"mc":[{"id":"1.120089104","rc":[{"atl":[[6.8,17.42]],"id":9480385}],"con":true,"img":false,"tv":17684.11}]}
{"op":"mcm","clk":"1148790724","pt":1439916214049,"mc":[{"id":"1.120089104","rc":[{"atl":[[1.23,197.45]],"id":9612932},{"atb":[[5.6,13.15]],"id":9480385}],"con":true,"img":false,"tv":17684.11}]}
{"op":"mcm","clk":"1148790737","pt":1439916214216,"mc":[{"id":"1.120089104","rc":[{"atl":[[1.23,56.59]],"id":9612932},{"atb":[[5.6,8.35]],"id":9480385}],"con":true,"img":false,"tv":17684.11}]}
{"op":"mcm","clk":"1148791213","pt":1439916219873,"mc":[{"id":"1.120089104","rc":[{"atl":[[1.23,197.45]],"id":9612932},{"atb":[[5.6,13.15]],"id":9480385}],"con":true,"img":false,"tv":17684.11}]}
{"op":"mcm","clk":"1148791230","pt":1439916220090,"mc":[{"id":"1.120089104","rc":[{"atl":[[1.23,140.86]],"id":9612932},{"atb":[[5.6,4.8]],"id":9480385}],"con":true,"img":false,"tv":17684.11}]}
{"op":"mcm","clk":"1148791644","pt":1439916225110,"mc":[{"id":"1.120089104","rc":[{"trd":[[1.2,795.4]],"ltp":1.2,"tv":795.4,"id":9612932},{"atl":[[1.2,694.32]],"id":9612932}],"con":true,"img":false,"tv":17785.85}]}
{"op":"mcm","clk":"1148791807","pt":1439916227134,"mc":[{"id":"1.120089104","rc":[{"atl":[[1.23,197.45]],"id":9612932},{"atb":[[5.6,21.33]],"id":9480385}],"con":true,"img":false,"tv":17785.85}]}
{"op":"mcm","clk":"1148791827","pt":1439916227346,"mc":[{"id":"1.120089104","rc":[{"atl":[[1.23,56.59]],"id":9612932},{"atb":[[5.6,16.53]],"id":9480385}],"con":true,"img":false,"tv":17785.85}]}
{"op":"mcm","clk":"1148792274","pt":1439916232842,"mc":[{"id":"1.120089104","rc":[{"atl":[[1.23,194.52]],"id":9612932}],"con":true,"img":false,"tv":17785.85}]}
{"op":"mcm","clk":"1148792286","pt":1439916233003,"mc":[{"id":"1.120089104","rc":[{"atl":[[1.23,137.92]],"id":9612932}],"con":true,"img":false,"tv":17785.85}]}
{"op":"mcm","clk":"1148792332","pt":1439916233708,"mc":[{"id":"1.120089104","rc":[{"trd":[[1.19,1546.7]],"ltp":1.19,"tv":1546.7,"id":9612932},{"atb":[[1.19,0]],"id":9612932},{"atl":[[1.19,333.12]],"id":9612932}],"con":true,"img":false,"tv":17823.93}]}
{"op":"mcm","clk":"1148792685","pt":1439916237876,"mc":[{"id":"1.120089104","rc":[{"atl":[[1.23,241.89]],"id":9612932},{"atb":[[5.6,47.23]],"id":9480385}],"con":true,"img":false,"tv":17823.93}]}
{"op":"mcm","clk":"1148792704","pt":1439916238089,"mc":[{"id":"1.120089104","rc":[{"atl":[[1.23,103.96]],"id":9612932},{"atb":[[5.6,30.7]],"id":9480385}],"con":true,"img":false,"tv":17823.93}]}
{"op":"mcm","clk":"1148793000","pt":1439916241781,"mc":[{"id":"1.120089104","rc":[{"atb":[[1.18,527.16]],"id":9612932}],"con":true,"img":false,"tv":17823.93}]}
{"op":"mcm","clk":"1148793050","pt":1439916242426,"mc":[{"id":"1.120089104","rc":[{"atl":[[6.8,45.68]],"id":9480385}],"con":true,"img":false,"tv":17823.93}]}
{"op":"mcm","clk":"1148793119","pt":1439916243128,"mc":[{"id":"1.120089104","rc":[{"atb":[[5.6,54.42]],"id":9480385}],"con":true,"img":false,"tv":17823.93}]}
{"op":"mcm","clk":"1148793133","pt":1439916243347,"mc":[{"id":"1.120089104","rc":[{"atb":[[5.6,23.71]],"id":9480385}],"con":true,"img":false,"tv":17823.93}]}
{"op":"mcm","clk":"1148793665","pt":1439916248993,"mc":[{"id":"1.120089104","rc":[{"atl":[[1.23,160.55]],"id":9612932}],"con":true,"img":false,"tv":17823.93}]}
{"op":"mcm","clk":"1148793681","pt":1439916249206,"mc":[{"id":"1.120089104","rc":[{"atl":[[1.23,56.59]],"id":9612932}],"con":true,"img":false,"tv":17823.93}]}
{"op":"mcm","clk":"1148794180","pt":1439916254770,"mc":[{"id":"1.120089104","rc":[{"atl":[[1.23,197.45]],"id":9612932}],"con":true,"img":false,"tv":17823.93}]}
{"op":"mcm","clk":"1148794194","pt":1439916254981,"mc":[{"id":"1.120089104","rc":[{"atl":[[1.23,140.86]],"id":9612932}],"con":true,"img":false,"tv":17823.93}]}
{"op":"mcm","clk":"1148797813","pt":1439916297523,"mc":[{"id":"1.120089104","rc":[{"trd":[[1.18,3960.56]],"ltp":1.18,"tv":3960.56,"id":9612932},{"atb":[[1.18,523.22]],"id":9612932},{"spn":1.17,"spf":1.07,"id":9612932}],"con":true,"img":false,"tv":17831.81}]}
{"op":"mcm","clk":"1148800317","pt":1439916328369,"mc":[{"id":"1.120089104","rc":[{"atb":[[1.18,533.78]],"id":9612932}],"con":true,"img":false,"tv":17831.81}]}
{"op":"mcm","clk":"1148801156","pt":1439916339187,"mc":[{"id":"1.120089104","rc":[{"trd":[[1.19,1946.7]],"ltp":1.19,"tv":1946.7,"id":9612932},{"atl":[[1.19,133.12]],"id":9612932}],"con":true,"img":false,"tv":18231.81}]}
{"op":"mcm","clk":"1148806094","pt":1439916408229,"mc":[{"id":"1.120089104","rc":[{"atl":[[1.23,241.75]],"id":9612932},{"spn":1.17,"spf":1.07,"id":9612932}],"con":true,"img":false,"tv":18231.81}]}
{"op":"mcm","clk":"1148806106","pt":1439916408442,"mc":[{"id":"1.120089104","rc":[{"atl":[[1.23,100.89]],"id":9612932}],"con":true,"img":false,"tv":18231.81}]}
{"op":"mcm","clk":"1148826769","pt":1439916574002,"mc":[{"id":"1.120089104","rc":[{"atl":[[6.8,0]],"id":9480385}],"con":true,"img":false,"tv":18231.81}]}
{"op":"mcm","clk":"1148827083","pt":1439916578488,"mc":[{"id":"1.120089104","rc":[{"trd":[[1.18,3980.56]],"ltp":1.18,"tv":3980.56,"id":9612932},{"atb":[[1.18,523.78]],"id":9612932}],"con":true,"img":false,"tv":18251.81}]}
{"op":"mcm","clk":"1148827741","pt":1439916588270,"mc":[{"id":"1.120089104","rc":[{"atl":[[1.23,150.06]],"id":9612932}],"con":true,"img":false,"tv":18251.81}]}
{"op":"mcm","clk":"1148827757","pt":1439916588432,"mc":[{"id":"1.120089104","rc":[{"atl":[[1.23,49.16]],"id":9612932}],"con":true,"img":false,"tv":18251.81}]}
{"op":"mcm","clk":"1148829936","pt":1439916619678,"mc":[{"id":"1.120089104","rc":[{"trd":[[1.18,3984.56]],"ltp":1.18,"tv":3984.56,"id":9612932},{"atb":[[1.18,521.78]],"id":9612932}],"con":true,"img":false,"tv":18255.81}]}
{"op":"mcm","clk":"1148830984","pt":1439916635820,"mc":[{"id":"1.120089104","rc":[{"spn":1.17,"spf":1.07,"id":9612932},{"atl":[[6.8,45.22]],"id":9480385}],"con":true,"img":false,"tv":18255.81}]}
{"op":"mcm","clk":"1148831062","pt":1439916637156,"mc":[{"id":"1.120089104","rc":[{"atl":[[14.5,0]],"id":9480385}],"con":true,"img":false,"tv":18255.81}]}
{"op":"mcm","clk":"1148831066","pt":1439916637212,"mc":[{"id":"1.120089104","rc":[{"atl":[[16,16]],"id":9480385}],"con":true,"img":false,"tv":18255.81}]}
{"op":"mcm","clk":"1148832710","pt":1439916664202,"mc":[{"id":"1.120089104","rc":[{"trd":[[1.19,1970.7]],"ltp":1.19,"tv":1970.7,"id":9612932},{"atl":[[1.19,121.12]],"id":9612932}],"con":true,"img":false,"tv":18279.81}]}
{"op":"mcm","clk":"1148835147","pt":1439916697623,"mc":[{"id":"1.120089104","rc":[{"atl":[[16,0]],"id":9480385}],"con":true,"img":false,"tv":18279.81}]}
{"op":"mcm","clk":"1148835155","pt":1439916697724,"mc":[{"id":"1.120089104","rc":[{"atl":[[14.5,17]],"id":9480385}],"con":true,"img":false,"tv":18279.81}]}
{"op":"mcm","clk":"1148836582","pt":1439916716719,"mc":[{"id":"1.120089104","rc":[{"trd":[[1.19,2068.7]],"ltp":1.19,"tv":2068.7,"id":9612932},{"atl":[[1.19,72.12]],"id":9612932}],"con":true,"img":false,"tv":18377.81}]}
{"op":"mcm","clk":"1148850355","pt":1439916903635,"mc":[{"id":"1.120089104","rc":[{"trd":[[1.19,2119.35]],"ltp":1.19,"tv":2119.35,"id":9612932},{"atl":[[1.19,46.79]],"id":9612932}],"con":true,"img":false,"tv":18428.47}]}
{"op":"mcm","clk":"1148851190","pt":1439916914383,"mc":[{"id":"1.120089104","rc":[{"atl":[[1.23,83.73]],"id":9612932}],"con":true,"img":false,"tv":18428.47}]}
{"op":"mcm","clk":"1148851206","pt":1439916914589,"mc":[{"id":"1.120089104","rc":[{"atl":[[1.23,34.56]],"id":9612932}],"con":true,"img":false,"tv":18428.47}]}
{"op":"mcm","clk":"1148851603","pt":1439916919512,"mc":[{"id":"1.120089104","rc":[{"atb":[[5.6,40.86]],"id":9480385}],"con":true,"img":false,"tv":18428.47}]}
{"op":"mcm","clk":"1148851617","pt":1439916919728,"mc":[{"id":"1.120089104","rc":[{"atb":[[5.6,17.15]],"id":9480385}],"con":true,"img":false,"tv":18428.47}]}
{"op":"mcm","clk":"1148863001","pt":1439917078082,"mc":[{"id":"1.120089104","rc":[{"trd":[[1.19,2140.41]],"ltp":1.19,"tv":2140.41,"id":9612932},{"atl":[[1.19,36.26]],"id":9612932}],"con":true,"img":false,"tv":18449.53}]}
{"op":"mcm","clk":"1148863837","pt":1439917089711,"mc":[{"id":"1.120089104","rc":[{"atl":[[1.23,61.36]],"id":9612932}],"con":true,"img":false,"tv":18449.53}]}
{"op":"mcm","clk":"1148863848","pt":1439917089920,"mc":[{"id":"1.120089104","rc":[{"atl":[[1.23,26.79]],"id":9612932}],"con":true,"img":false,"tv":18449.53}]}
{"op":"mcm","clk":"1148864910","pt":1439917105704,"mc":[{"id":"1.120089104","rc":[{"atb":[[5.6,31.51]],"id":9480385}],"con":true,"img":false,"tv":18449.53}]}
{"op":"mcm","clk":"1148864945","pt":1439917106185,"mc":[{"id":"1.120089104","rc":[{"atb":[[5.6,14.36]],"id":9480385}],"con":true,"img":false,"tv":18449.53}]}
{"op":"mcm","clk":"1148871721","pt":1439917210114,"mc":[{"id":"1.120089104","rc":[{"atb":[[4.9,0]],"id":9480385}],"con":true,"img":false,"tv":18449.53}]}
{"op":"mcm","clk":"1148871777","pt":1439917210855,"mc":[{"id":"1.120089104","rc":[{"atb":[[5,220.92]],"id":9480385}],"con":true,"img":false,"tv":18449.53}]}
{"op":"mcm","clk":"1148874737","pt":1439917250026,"mc":[{"id":"1.120089104","rc":[{"trd":[[1.19,2140.68],[1.3,209.66],[1.29,101.47],[1.17,2165.5],[1.16,1865.17],[1.18,3984.68],[1.28,995.94],[1.27,15.71],[1.25,308.36],[1.26,83],[1.23,550.18],[1.22,1556.96],[1.24,1189.44],[1.2,795.43],[1.21,1174.22]],"ltp":1.19,"tv":17136.4,"id":9612932},{"atb":[[1.17,394.4],[1.16,5351.44],[1.18,521.94],[1.01,2473.04],[1.15,12000],[1.1,11.97],[1.08,21.97],[1.11,7251.38],[1.09,10.56]],"id":9612932},{"atl":[[1.23,26.8],[1.2,694.61],[1.19,36.28],[3.95,4.22]],"id":9612932},{"spl":[[1.01,1094.96]],"id":9612932},{"trd":[[6.6,25.61],[6.8,29.14],[4.9,11.95],[5.4,38.15],[6.4,43.28],[4.8,120.28],[5.3,25.25],[5.8,16.06],[5.7,1.03],[6,5.76],[5.2,35.55],[4.7,103.3],[5.1,136.71],[5.6,91.82],[7.2,17.4],[5.5,39.07],[5,330.41],[6.2,10.28]],"ltp":6.6,"tv":1081.05,"id":9480385},{"atb":[[1.01,2451.04],[1.1,11.97],[1.08,21.97],[1.11,11.27],[5.6,14.37],[5.5,25.45],[1.09,10.56],[5,221],[6.2,13.55]],"id":9480385},{"atl":[[7,1.75],[7.8,1.22],[12,1.4]],"id":9480385}],"con":true,"img":false,"tv":18451.31}]}
{"op":"mcm","clk":"1148874761","pt":1439917250398,"mc":[{"id":"1.120089104","rc":[{"atl":[[1.2,713.11]],"id":9612932}],"con":true,"img":false,"tv":18451.31}]}
{"op":"mcm","clk":"1148875044","pt":1439917254052,"mc":[{"id":"1.120089104","rc":[{"atl":[[1.2,694.61]],"id":9612932}],"con":true,"img":false,"tv":18451.31}]}
{"op":"mcm","clk":"1148875660","pt":1439917262284,"mc":[{"id":"1.120089104","rc":[{"atl":[[1000,9]],"id":9612932},{"trd":[[6.8,37.36]],"ltp":6.8,"tv":37.36,"id":9480385},{"atb":[[1.01,2455.04]],"id":9480385},{"atl":[[6.8,41.11]],"id":9480385}],"con":true,"img":false,"tv":18459.53}]}
{"op":"mcm","clk":"1148875670","pt":1439917262501,"mc":[{"id":"1.120089104","rc":[{"atl":[[1000,11.25]],"id":9612932},{"atb":[[1.01,2457.89]],"id":9480385}],"con":true,"img":false,"tv":18459.53}]}
{"op":"mcm","clk":"1148875676","pt":1439917262611,"mc":[{"id":"1.120089104","rc":[{"atl":[[1000,3.25]],"id":9612932},{"atb":[[1.01,2453.89]],"id":9480385}],"con":true,"img":false,"tv":18459.53}]}
{"op":"mcm","clk":"1148875693","pt":1439917262784,"mc":[{"id":"1.120089104","rc":[{"atl":[[1000,1]],"id":9612932},{"atb":[[1.01,2451.04]],"id":9480385}],"con":true,"img":false,"tv":18459.53}]}
{"op":"mcm","clk":"1148875703","pt":1439917262886,"mc":[{"id":"1.120089104","rc":[{"trd":[[1.18,4034.7]],"ltp":1.18,"tv":4034.7,"id":9612932},{"atb":[[1.18,496.93]],"id":9612932},{"atl":[[1.19,37.2]],"id":9612932},{"atb":[[6.2,16.4]],"id":9480385},{"atl":[[6.8,43.22]],"id":9480385}],"con":true,"img":false,"tv":18509.55}]}
{"op":"mcm","clk":"1148880637","pt":1439917334329,"mc":[{"id":"1.120089104","rc":[{"trd":[[1.19,2215.08]],"ltp":1.19,"tv":2215.08,"id":9612932},{"atb":[[1.19,13.46]],"id":9612932},{"atl":[[1.19,0]],"id":9612932}],"con":true,"img":false,"tv":18583.95}]}
{"op":"mcm","clk":"1148880998","pt":1439917340383,"mc":[{"id":"1.120089104","rc":[{"atl":[[1.23,167.72]],"id":9612932}],"con":true,"img":false,"tv":18583.95}]}
{"op":"mcm","clk":"1148881086","pt":1439917341889,"mc":[{"id":"1.120089104","rc":[{"atl":[[1.23,140.92]],"id":9612932}],"con":true,"img":false,"tv":18583.95}]}
{"op":"mcm","clk":"1148881296","pt":1439917345553,"mc":[{"id":"1.120089104","rc":[{"atl":[[1.23,241.17]],"id":9612932}],"con":true,"img":false,"tv":18583.95}]}
{"op":"mcm","clk":"1148881308","pt":1439917345724,"mc":[{"id":"1.120089104","rc":[{"atl":[[1.23,100.24]],"id":9612932}],"con":true,"img":false,"tv":18583.95}]}
{"op":"mcm","clk":"1148881651","pt":1439917350882,"mc":[{"id":"1.120089104","rc":[{"atb":[[5.6,40.65]],"id":9480385}],"con":true,"img":false,"tv":18583.95}]}
{"op":"mcm","clk":"1148881664","pt":1439917351094,"mc":[{"id":"1.120089104","rc":[{"atb":[[5.6,26.28]],"id":9480385}],"con":true,"img":false,"tv":18583.95}]}
{"op":"mcm","clk":"1148882298","pt":1439917362791,"mc":[{"id":"1.120089104","rc":[{"atb":[[1.13,12000]],"id":9612932},{"atl":[[1.24,0]],"id":9612932}],"con":true,"img":false,"tv":18583.95}]}
{"op":"mcm","clk":"1148882304","pt":1439917362855,"mc":[{"id":"1.120089104","rc":[{"atb":[[1.14,12219]],"id":9612932},{"atl":[[1.26,598]],"id":9612932}],"con":true,"img":false,"tv":18583.95}]}
{"op":"mcm","clk":"1148883304","pt":1439917379120,"mc":[{"id":"1.120089104","rc":[{"atl":[[1.23,156.86]],"id":9612932}],"con":true,"img":false,"tv":18583.95}]}
{"op":"mcm","clk":"1148883314","pt":1439917379325,"mc":[{"id":"1.120089104","rc":[{"atl":[[1.23,56.61]],"id":9612932}],"con":true,"img":false,"tv":18583.95}]}
{"op":"mcm","clk":"1148884082","pt":1439917390447,"mc":[{"id":"1.120089104","rc":[{"trd":[[6.2,17.32]],"ltp":6.2,"tv":17.32,"id":9480385},{"atb":[[6.2,12.88]],"id":9480385}],"con":true,"img":false,"tv":18591.0}]}
{"op":"mcm","clk":"1148885339","pt":1439917409000,"mc":[{"id":"1.120089104","rc":[{"atb":[[5.6,48.83]],"id":9480385}],"con":true,"img":false,"tv":18591.0}]}
{"op":"mcm","clk":"1148885354","pt":1439917409174,"mc":[{"id":"1.120089104","rc":[{"atb":[[5.6,22.55]],"id":9480385}],"con":true,"img":false,"tv":18591.0}]}
{"op":"mcm","clk":"1148904939","pt":1439917526775,"mc":[{"id":"1.120089104","rc":[{"trd":[[1.19,2242]],"ltp":1.19,"tv":2242.0,"id":9612932},{"atb":[[1.19,0]],"id":9612932},{"atl":[[1.19,38.54]],"id":9612932},{"spn":1.17,"spf":1.07,"id":9612932}],"con":true,"img":false,"tv":18617.92}]}
{"op":"mcm","clk":"1148906364","pt":1439917543689,"mc":[{"id":"1.120089104","rc":[{"atb":[[1.14,12000]],"id":9612932},{"atl":[[1.26,400]],"id":9612932}],"con":true,"img":false,"tv":18617.92}]}
{"op":"mcm","clk":"1148906371","pt":1439917543786,"mc":[{"id":"1.120089104","rc":[{"atb":[[1.13,12221]],"id":9612932},{"atl":[[1.24,202]],"id":9612932}],"con":true,"img":false,"tv":18617.92}]}
{"op":"mcm","clk":"1148907550","pt":1439917558236,"mc":[{"id":"1.120089104","rc":[{"atb":[[5.6,36.76]],"id":9480385}],"con":true,"img":false,"tv":18617.92}]}
{"op":"mcm","clk":"1148907599","pt":1439917558721,"mc":[{"id":"1.120089104","rc":[{"atb":[[5.6,14.2]],"id":9480385}],"con":true,"img":false,"tv":18617.92}]}
{"op":"mcm","clk":"1148908289","pt":1439917566192,"mc":[{"id":"1.120089104","rc":[{"atl":[[6.8,49.22]],"id":9480385}],"con":true,"img":false,"tv":18617.92}]}
{"op":"mcm","clk":"1148908529","pt":1439917569143,"mc":[{"id":"1.120089104","rc":[{"atl":[[7.2,13.94]],"id":9480385}],"con":true,"img":false,"tv":18617.92}]}
{"op":"mcm","clk":"1148913621","pt":1439917625963,"mc":[{"id":"1.120089104","rc":[{"atb":[[1.11,6885.34]],"id":9612932}],"con":true,"img":false,"tv":18617.92}]}
{"op":"mcm","clk":"1148913664","pt":1439917626443,"mc":[{"id":"1.120089104","rc":[{"atb":[[1.12,1696.86]],"id":9612932}],"con":true,"img":false,"tv":18617.92}]}
{"op":"mcm","clk":"1148913677","pt":1439917626672,"mc":[{"id":"1.120089104","rc":[{"atb":[[5,209.87]],"id":9480385}],"con":true,"img":false,"tv":18617.92}]}
{"op":"mcm","clk":"1148913747","pt":1439917627464,"mc":[{"id":"1.120089104","rc":[{"atb":[[5,223.08]],"id":9480385}],"con":true,"img":false,"tv":18617.92}]}
{"op":"mcm","clk":"1148914572","pt":1439917635643,"mc":[{"id":"1.120089104","rc":[{"trd":[[1.18,4040.7]],"ltp":1.18,"tv":4040.7,"id":9612932},{"atb":[[1.18,493.93]],"id":9612932}],"con":true,"img":false,"tv":18623.92}]}
{"op":"mcm","clk":"1148916126","pt":1439917652513,"mc":[{"id":"1.120089104","rc":[{"trd":[[6.8,45.36]],"ltp":6.8,"tv":45.36,"id":9480385},{"atl":[[6.8,45.22]],"id":9480385}],"con":true,"img":false,"tv":18631.92}]}
{"op":"mcm","clk":"1148916185","pt":1439917653315,"mc":[{"id":"1.120089104","rc":[{"trd":[[1.18,4086.8]],"ltp":1.18,"tv":4086.8,"id":9612932},{"atb":[[1.18,470.88]],"id":9612932}],"con":true,"img":false,"tv":18678.02}]}
{"op":"mcm","clk":"1148918548","pt":1439917678467,"mc":[{"id":"1.120089104","rc":[{"atl":[[1.2,1075.11]],"id":9612932}],"con":true,"img":false,"tv":18678.02}]}
{"op":"mcm","clk":"1148923183","pt":1439917726088,"mc":[{"id":"1.120089104","rc":[{"trd":[[1.2,1418.35],[1.19,2319.08]],"ltp":1.2,"tv":3737.43,"id":9612932},{"atl":[[1.2,763.65],[1.19,0]],"id":9612932},{"spn":1.17,"spf":1.07,"id":9612932}],"con":true,"img":false,"tv":19378.02}]}
{"op":"mcm","clk":"1148923692","pt":1439917731511,"mc":[{"id":"1.120089104","rc":[{"atl":[[1.23,197.54]],"id":9612932}],"con":true,"img":false,"tv":19378.02}]}
{"op":"mcm","clk":"1148923712","pt":1439917731724,"mc":[{"id":"1.120089104","rc":[{"atl":[[1.23,140.92]],"id":9612932}],"con":true,"img":false,"tv":19378.02}]}
{"op":"mcm","clk":"1148926806","pt":1439917763459,"mc":[{"id":"1.120089104","rc":[{"atb":[[1.18,787.96]],"id":9612932}],"con":true,"img":false,"tv":19378.02}]}
{"op":"mcm","clk":"1148927096","pt":1439917766378,"mc":[{"id":"1.120089104","rc":[{"atl":[[6.8,39.22]],"id":9480385}],"con":true,"img":false,"tv":19378.02}]}
{"op":"mcm","clk":"1148927136","pt":1439917766859,"mc":[{"id":"1.120089104","rc":[{"atl":[[6.8,68.36]],"id":9480385}],"con":true,"img":false,"tv":19378.02}]}
{"op":"mcm","clk":"1148927304","pt":1439917768888,"mc":[{"id":"1.120089104","rc":[{"atl":[[7.2,7.22]],"id":9480385}],"con":true,"img":false,"tv":19378.02}]}
{"op":"mcm","clk":"1148927960","pt":1439917775663,"mc":[{"id":"1.120089104","rc":[{"atb":[[5,215.39]],"id":9480385}],"con":true,"img":false,"tv":19378.02}]}
{"op":"mcm","clk":"1148928015","pt":1439917776285,"mc":[{"id":"1.120089104","rc":[{"atb":[[5,224.53]],"id":9480385}],"con":true,"img":false,"tv":19378.02}]}
{"op":"mcm","clk":"1148928825","pt":1439917784688,"mc":[{"id":"1.120089104","rc":[{"atl":[[1.24,0]],"id":9612932}],"con":true,"img":false,"tv":19378.02}]}
{"op":"mcm","clk":"1148928837","pt":1439917784787,"mc":[{"id":"1.120089104","rc":[{"atl":[[1.26,598]],"id":9612932}],"con":true,"img":false,"tv":19378.02}]}
{"op":"mcm","clk":"1148932521","pt":1439917821893,"mc":[{"id":"1.120089104","rc":[{"atb":[[1.11,4257.85]],"id":9612932},{"spn":1.18,"spf":1.07,"id":9612932}],"con":true,"img":false,"tv":19378.02}]}
{"op":"mcm","clk":"1148932565","pt":1439917822292,"mc":[{"id":"1.120089104","rc":[{"atb":[[1.12,4858.07]],"id":9612932}],"con":true,"img":false,"tv":19378.02}]}
{"op":"mcm","clk":"1148934536","pt":1439917843120,"mc":[{"id":"1.120089104","rc":[{"atl":[[1.19,266]],"id":9612932}],"con":true,"img":false,"tv":19378.02}]}
{"op":"mcm","clk":"1148934730","pt":1439917845252,"mc":[{"id":"1.120089104","rc":[{"atb":[[1.11,3857.5]],"id":9612932}],"con":true,"img":false,"tv":19378.02}]}
{"op":"mcm","clk":"1148934780","pt":1439917845845,"mc":[{"id":"1.120089104","rc":[{"atb":[[1.12,5316.81]],"id":9612932}],"con":true,"img":false,"tv":19378.02}]}
{"op":"mcm","clk":"1148934831","pt":1439917846446,"mc":[{"id":"1.120089104","rc":[{"atb":[[5,212.94]],"id":9480385}],"con":true,"img":false,"tv":19378.02}]}
{"op":"mcm","clk":"1148934890","pt":1439917847079,"mc":[{"id":"1.120089104","rc":[{"atb":[[5,226.7]],"id":9480385}],"con":true,"img":false,"tv":19378.02}]}
{"op":"mcm","clk":"1148934939","pt":1439917847667,"mc":[{"id":"1.120089104","rc":[{"atl":[[1.23,204.71]],"id":9612932},{"atb":[[5.6,41.07]],"id":9480385}],"con":true,"img":false,"tv":19378.02}]}
{"op":"mcm","clk":"1148934955","pt":1439917847878,"mc":[{"id":"1.120089104","rc":[{"atl":[[1.23,63.78]],"id":9612932},{"atb":[[5.6,26.87]],"id":9480385}],"con":true,"img":false,"tv":19378.02}]}
{"op":"mcm","clk":"1148935446","pt":1439917853041,"mc":[{"id":"1.120089104","rc":[{"atl":[[1.21,645]],"id":9612932}],"con":true,"img":false,"tv":19378.02}]}
{"op":"mcm","clk":"1148935497","pt":1439917853539,"mc":[{"id":"1.120089104","rc":[{"atb":[[5.6,49.42]],"id":9480385}],"con":true,"img":false,"tv":19378.02}]}
{"op":"mcm","clk":"1148935523","pt":1439917853748,"mc":[{"id":"1.120089104","rc":[{"atb":[[5.6,22.55]],"id":9480385}],"con":true,"img":false,"tv":19378.02}]}
{"op":"mcm","clk":"1148937935","pt":1439917878194,"mc":[{"id":"1.120089104","rc":[{"trd":[[6.8,182.08]],"ltp":6.8,"tv":182.08,"id":9480385},{"atb":[[6.8,2.09]],"id":9480385},{"atl":[[6.8,0]],"id":9480385}],"con":true,"img":false,"tv":19514.74}]}
{"op":"mcm","clk":"1148937950","pt":1439917878355,"mc":[{"id":"1.120089104","rc":[{"trd":[[1.18,4110.88]],"ltp":1.18,"tv":4110.88,"id":9612932},{"atb":[[1.18,775.92]],"id":9612932},{"trd":[[6.8,186.27]],"ltp":6.8,"tv":186.27,"id":9480385},{"atb":[[6.8,0]],"id":9480385}],"con":true,"img":false,"tv":19543.0}]}
{"op":"mcm","clk":"1148937966","pt":1439917878482,"mc":[{"id":"1.120089104","rc":[{"trd":[[1.18,4134.96]],"ltp":1.18,"tv":4134.96,"id":9612932},{"atb":[[1.18,763.88]],"id":9612932},{"trd":[[6.8,186.28]],"ltp":6.8,"tv":186.28,"id":9480385},{"atb":[[6.8,0]],"id":9480385},{"atl":[[6.8,2.08]],"id":9480385}],"con":true,"img":false,"tv":19567.1}]}
{"op":"mcm","clk":"1148937969","pt":1439917878577,"mc":[{"id":"1.120089104","rc":[{"trd":[[1.18,4922.84]],"ltp":1.18,"tv":4922.84,"id":9612932},{"atb":[[1.18,369.94]],"id":9612932},{"atl":[[6.8,35.17]],"id":9480385}],"con":true,"img":false,"tv":20354.98}]}
{"op":"mcm","clk":"1148938597","pt":1439917884781,"mc":[{"id":"1.120089104","rc":[{"spn":1.17,"spf":1.07,"id":9612932},{"atl":[[7.2,12.08]],"id":9480385}],"con":true,"img":false,"tv":20354.98}]}
{"op":"mcm","clk":"1148939773","pt":1439917896824,"mc":[{"id":"1.120089104","rc":[{"trd":[[1.18,4972.84]],"ltp":1.18,"tv":4972.84,"id":9612932},{"atb":[[1.18,344.94]],"id":9612932}],"con":true,"img":false,"tv":20404.98}]}
{"op":"mcm","clk":"1148940568","pt":1439917905425,"mc":[{"id":"1.120089104","rc":[{"atl":[[1.26,400]],"id":9612932}],"con":true,"img":false,"tv":20404.98}]}
{"op":"mcm","clk":"1148940575","pt":1439917905527,"mc":[{"id":"1.120089104","rc":[{"atl":[[1.24,202]],"id":9612932}],"con":true,"img":false,"tv":20404.98}]}
{"op":"mcm","clk":"1148942170","pt":1439917922354,"mc":[{"id":"1.120089104","rc":[{"atb":[[1.11,2027.93]],"id":9612932}],"con":true,"img":false,"tv":20404.98}]}
{"op":"mcm","clk":"1148942221","pt":1439917922836,"mc":[{"id":"1.120089104","rc":[{"atb":[[1.12,7413.18]],"id":9612932}],"con":true,"img":false,"tv":20404.98}]}
{"op":"mcm","clk":"1148946006","pt":1439917962504,"mc":[{"id":"1.120089104","rc":[{"trd":[[1.18,4980.84]],"ltp":1.18,"tv":4980.84,"id":9612932},{"atb":[[1.18,340.93]],"id":9612932},{"spn":1.17,"spf":1.07,"id":9612932}],"con":true,"img":false,"tv":20412.98}]}
{"op":"mcm","clk":"1148947339","pt":1439917975075,"mc":[{"id":"1.120089104","rc":[{"atb":[[1.11,458.55]],"id":9612932}],"con":true,"img":false,"tv":20412.98}]}
{"op":"mcm","clk":"1148947357","pt":1439917975191,"mc":[{"id":"1.120089104","rc":[{"atb":[[1.12,9211.44]],"id":9612932}],"con":true,"img":false,"tv":20412.98}]}
{"op":"mcm","clk":"1148947360","pt":1439917975291,"mc":[{"id":"1.120089104","rc":[{"atb":[[5,181.27]],"id":9480385}],"con":true,"img":false,"tv":20412.98}]}
{"op":"mcm","clk":"1148947382","pt":1439917975502,"mc":[{"id":"1.120089104","rc":[{"atb":[[5,235.22]],"id":9480385}],"con":true,"img":false,"tv":20412.98}]}
{"op":"mcm","clk":"1148950601","pt":1439918006498,"mc":[{"id":"1.120089104","rc":[{"atb":[[1.17,419.4]],"id":9612932}],"con":true,"img":false,"tv":20412.98}]}
{"op":"mcm","clk":"1148963327","pt":1439918139720,"mc":[{"id":"1.120089104","rc":[{"spn":1.17,"spf":1.07,"id":9612932},{"atl":[[6.6,19.02]],"id":9480385}],"con":true,"img":false,"tv":20412.98}]}
{"op":"mcm","clk":"1148963357","pt":1439918139989,"mc":[{"id":"1.120089104","rc":[{"atl":[[6.8,2.08]],"id":9480385}],"con":true,"img":false,"tv":20412.98}]}
{"op":"mcm","clk":"1148969013","pt":1439918198876,"mc":[{"id":"1.120089104","rc":[{"atl":[[6.8,0]],"id":9480385}],"con":true,"img":false,"tv":20412.98}]}
{"op":"mcm","clk":"1148969261","pt":1439918201632,"mc":[{"id":"1.120089104","rc":[{"trd":[[6.2,21.62]],"ltp":6.2,"tv":21.62,"id":9480385},{"atb":[[6.2,10.73]],"id":9480385}],"con":true,"img":false,"tv":20417.28}]}
{"op":"mcm","clk":"1148969756","pt":1439918206626,"mc":[{"id":"1.120089104","rc":[{"atl":[[14.5,0]],"id":9480385}],"con":true,"img":false,"tv":20417.28}]}
{"op":"mcm","clk":"1148969766","pt":1439918206685,"mc":[{"id":"1.120089104","rc":[{"atl":[[8.2,30]],"id":9480385}],"con":true,"img":false,"tv":20417.28}]}
{"op":"mcm","clk":"1148975518","pt":1439918267155,"mc":[{"id":"1.120089104","rc":[{"atl":[[8.2,0]],"id":9480385}],"con":true,"img":false,"tv":20417.28}]}
{"op":"mcm","clk":"1148975527","pt":1439918267267,"mc":[{"id":"1.120089104","rc":[{"atl":[[9.2,27]],"id":9480385}],"con":true,"img":false,"tv":20417.28}]}
{"op":"mcm","clk":"1148980428","pt":1439918315655,"mc":[{"id":"1.120089104","rc":[{"atl":[[6.6,0]],"id":9480385}],"con":true,"img":false,"tv":20417.28}]}
{"op":"mcm","clk":"1148980582","pt":1439918317060,"mc":[{"id":"1.120089104","rc":[{"atl":[[6.8,29.55]],"id":9480385}],"con":true,"img":false,"tv":20417.28}]}
{"op":"mcm","clk":"1148981069","pt":1439918321901,"mc":[{"id":"1.120089104","rc":[{"atl":[[7.2,7.22]],"id":9480385}],"con":true,"img":false,"tv":20417.28}]}
{"op":"mcm","clk":"1148981544","pt":1439918326828,"mc":[{"id":"1.120089104","rc":[{"atl":[[9,47.66]],"id":9480385}],"con":true,"img":false,"tv":20417.28}]}
{"op":"mcm","clk":"1148981640","pt":1439918327736,"mc":[{"id":"1.120089104","rc":[{"atl":[[9.2,0]],"id":9480385}],"con":true,"img":false,"tv":20417.28}]}
{"op":"mcm","clk":"1148981650","pt":1439918327840,"mc":[{"id":"1.120089104","rc":[{"atl":[[10.5,24]],"id":9480385}],"con":true,"img":false,"tv":20417.28}]}
{"op":"mcm","clk":"1148981898","pt":1439918330294,"mc":[{"id":"1.120089104","rc":[{"trd":[[1.19,2719.08]],"ltp":1.19,"tv":2719.08,"id":9612932},{"atl":[[1.19,66]],"id":9612932}],"con":true,"img":false,"tv":20817.28}]}
{"op":"mcm","clk":"1148982273","pt":1439918333961,"mc":[{"id":"1.120089104","rc":[{"atl":[[6.8,35.55]],"id":9480385}],"con":true,"img":false,"tv":20817.28}]}
{"op":"mcm","clk":"1148982747","pt":1439918338324,"mc":[{"id":"1.120089104","rc":[{"atl":[[1.23,112.54]],"id":9612932},{"atl":[[7.2,11.84]],"id":9480385}],"con":true,"img":false,"tv":20817.28}]}
{"op":"mcm","clk":"1148982763","pt":1439918338538,"mc":[{"id":"1.120089104","rc":[{"atl":[[1.23,48.75]],"id":9612932},{"atl":[[9,0]],"id":9480385}],"con":true,"img":false,"tv":20817.28}]}
{"op":"mcm","clk":"1148996475","pt":1439918383552,"mc":[{"id":"1.120089104","rc":[{"trd":[[1.18,5020.84]],"ltp":1.18,"tv":5020.84,"id":9612932},{"atb":[[1.18,320.94]],"id":9612932}],"con":true,"img":false,"tv":20857.28}]}
{"op":"mcm","clk":"1148996811","pt":1439918387573,"mc":[{"id":"1.120089104","rc":[{"atb":[[1.11,178.72]],"id":9612932}],"con":true,"img":false,"tv":20857.28}]}
{"op":"mcm","clk":"1148996864","pt":1439918388170,"mc":[{"id":"1.120089104","rc":[{"atb":[[1.12,9536.35]],"id":9612932},{"spn":1.17,"spf":1.07,"id":9612932}],"con":true,"img":false,"tv":20857.28}]}
{"op":"mcm","clk":"1148996902","pt":1439918388609,"mc":[{"id":"1.120089104","rc":[{"atl":[[10.5,0]],"id":9480385}],"con":true,"img":false,"tv":20857.28}]}
{"op":"mcm","clk":"1148996907","pt":1439918388660,"mc":[{"id":"1.120089104","rc":[{"atl":[[13,19]],"id":9480385}],"con":true,"img":false,"tv":20857.28}]}
{"op":"mcm","clk":"1149002841","pt":1439918449118,"mc":[{"id":"1.120089104","rc":[{"atl":[[13,0]],"id":9480385}],"con":true,"img":false,"tv":20857.28}]}
{"op":"mcm","clk":"1149002850","pt":1439918449228,"mc":[{"id":"1.120089104","rc":[{"atl":[[14.5,17]],"id":9480385}],"con":true,"img":false,"tv":20857.28}]}
{"op":"mcm","clk":"1149004170","pt":1439918464058,"mc":[{"id":"1.120089104","rc":[{"trd":[[1.19,2851.08]],"ltp":1.19,"tv":2851.08,"id":9612932},{"atb":[[1.19,34]],"id":9612932},{"atl":[[1.19,0]],"id":9612932}],"con":true,"img":false,"tv":20989.28}]}
{"op":"mcm","clk":"1149005035","pt":1439918473696,"mc":[{"id":"1.120089104","rc":[{"atl":[[1.23,189.67]],"id":9612932}],"con":true,"img":false,"tv":20989.28}]}
{"op":"mcm","clk":"1149005050","pt":1439918473913,"mc":[{"id":"1.120089104","rc":[{"atl":[[1.23,140.92]],"id":9612932}],"con":true,"img":false,"tv":20989.28}]}
{"op":"mcm","clk":"1149005491","pt":1439918479002,"mc":[{"id":"1.120089104","rc":[{"atl":[[1.23,226.4]],"id":9612932}],"con":true,"img":false,"tv":20989.28}]}
{"op":"mcm","clk":"1149005507","pt":1439918479215,"mc":[{"id":"1.120089104","rc":[{"atl":[[1.23,85.47]],"id":9612932}],"con":true,"img":false,"tv":20989.28}]}
{"op":"mcm","clk":"1149005967","pt":1439918484554,"mc":[{"id":"1.120089104","rc":[{"atl":[[1.23,226.4]],"id":9612932}],"con":true,"img":false,"tv":20989.28}]}
{"op":"mcm","clk":"1149005990","pt":1439918484768,"mc":[{"id":"1.120089104","rc":[{"atl":[[1.23,140.92]],"id":9612932}],"con":true,"img":false,"tv":20989.28}]}
{"op":"mcm","clk":"1149006643","pt":1439918492521,"mc":[{"id":"1.120089104","rc":[{"atl":[[1.23,232.52]],"id":9612932},{"atb":[[5.6,42.05]],"id":9480385}],"con":true,"img":false,"tv":20989.28}]}
{"op":"mcm","clk":"1149006655","pt":1439918492721,"mc":[{"id":"1.120089104","rc":[{"atl":[[1.23,91.6]],"id":9612932},{"atb":[[5.6,19.5]],"id":9480385}],"con":true,"img":false,"tv":20989.28}]}
{"op":"mcm","clk":"1149007054","pt":1439918497657,"mc":[{"id":"1.120089104","rc":[{"atl":[[1.23,232.52]],"id":9612932}],"con":true,"img":false,"tv":20989.28}]}
{"op":"mcm","clk":"1149007070","pt":1439918497866,"mc":[{"id":"1.120089104","rc":[{"atl":[[1.23,140.92]],"id":9612932}],"con":true,"img":false,"tv":20989.28}]}
{"op":"mcm","clk":"1149007536","pt":1439918503722,"mc":[{"id":"1.120089104","rc":[{"atl":[[1.23,233.44]],"id":9612932}],"con":true,"img":false,"tv":20989.28}]}
{"op":"mcm","clk":"1149007556","pt":1439918504041,"mc":[{"id":"1.120089104","rc":[{"atl":[[1.23,92.52]],"id":9612932}],"con":true,"img":false,"tv":20989.28}]}
{"op":"mcm","clk":"1149007982","pt":1439918509405,"mc":[{"id":"1.120089104","rc":[{"atl":[[1.23,233.44]],"id":9612932},{"spn":1.17,"spf":1.07,"id":9612932}],"con":true,"img":false,"tv":20989.28}]}
{"op":"mcm","clk":"1149007995","pt":1439918509583,"mc":[{"id":"1.120089104","rc":[{"atl":[[1.23,140.92]],"id":9612932}],"con":true,"img":false,"tv":20989.28}]}
{"op":"mcm","clk":"1149008005","pt":1439918509680,"mc":[{"id":"1.120089104","rc":[{"atb":[[1.13,12000]],"id":9612932},{"atl":[[1.24,0]],"id":9612932}],"con":true,"img":false,"tv":20989.28}]}
{"op":"mcm","clk":"1149008013","pt":1439918509788,"mc":[{"id":"1.120089104","rc":[{"atb":[[1.14,12219]],"id":9612932},{"atl":[[1.26,598]],"id":9612932}],"con":true,"img":false,"tv":20989.28}]}
{"op":"mcm","clk":"1149008423","pt":1439918515069,"mc":[{"id":"1.120089104","rc":[{"atl":[[1.23,197.54]],"id":9612932}],"con":true,"img":false,"tv":20989.28}]}
{"op":"mcm","clk":"1149008441","pt":1439918515235,"mc":[{"id":"1.120089104","rc":[{"atl":[[1.23,56.61]],"id":9612932}],"con":true,"img":false,"tv":20989.28}]}
{"op":"mcm","clk":"1149009720","pt":1439918530254,"mc":[{"id":"1.120089104","rc":[{"trd":[[1.2,2418.35]],"ltp":1.2,"tv":2418.35,"id":9612932},{"atl":[[1.2,263.65]],"id":9612932}],"con":true,"img":false,"tv":21989.28}]}
{"op":"mcm","clk":"1149010058","pt":1439918534105,"mc":[{"id":"1.120089104","rc":[{"atl":[[6.8,29.55]],"id":9480385}],"con":true,"img":false,"tv":21989.28}]}
{"op":"mcm","clk":"1149010173","pt":1439918535543,"mc":[{"id":"1.120089104","rc":[{"atl":[[6.8,31.9]],"id":9480385}],"con":true,"img":false,"tv":21989.28}]}
{"op":"mcm","clk":"1149010628","pt":1439918540860,"mc":[{"id":"1.120089104","rc":[{"atl":[[7.2,7.22]],"id":9480385}],"con":true,"img":false,"tv":21989.28}]}
{"op":"mcm","clk":"1149013993","pt":1439918578071,"mc":[{"id":"1.120089104","rc":[{"atb":[[5.8,52]],"id":9480385}],"con":true,"img":false,"tv":21989.28}]}
{"op":"mcm","clk":"1149014252","pt":1439918581271,"mc":[{"id":"1.120089104","rc":[{"atb":[[5.9,1.4]],"id":9480385}],"con":true,"img":false,"tv":21989.28}]}
{"op":"mcm","clk":"1149014274","pt":1439918581490,"mc":[{"id":"1.120089104","rc":[{"atb":[[5.6,0]],"id":9480385}],"con":true,"img":false,"tv":21989.28}]}
{"op":"mcm","clk":"1149014458","pt":1439918583708,"mc":[{"id":"1.120089104","rc":[{"atb":[[5.8,2]],"id":9480385}],"con":true,"img":false,"tv":21989.28}]}
{"op":"mcm","clk":"1149014467","pt":1439918583813,"mc":[{"id":"1.120089104","rc":[{"atb":[[5.7,50]],"id":9480385}],"con":true,"img":false,"tv":21989.28}]}
{"op":"mcm","clk":"1149014677","pt":1439918586274,"mc":[{"id":"1.120089104","rc":[{"atb":[[5.8,5.57]],"id":9480385}],"con":true,"img":false,"tv":21989.28}]}
{"op":"mcm","clk":"1149014691","pt":1439918586448,"mc":[{"id":"1.120089104","rc":[{"atb":[[5.9,0]],"id":9480385}],"con":true,"img":false,"tv":21989.28}]}
{"op":"mcm","clk":"1149015137","pt":1439918591490,"mc":[{"id":"1.120089104","rc":[{"atb":[[5.8,2]],"id":9480385}],"con":true,"img":false,"tv":21989.28}]}
{"op":"mcm","clk":"1149015618","pt":1439918597096,"mc":[{"id":"1.120089104","rc":[{"atb":[[5.8,5.57]],"id":9480385}],"con":true,"img":false,"tv":21989.28}]}
{"op":"mcm","clk":"1149016093","pt":1439918602873,"mc":[{"id":"1.120089104","rc":[{"atb":[[5.8,2]],"id":9480385}],"con":true,"img":false,"tv":21989.28}]}
{"op":"mcm","clk":"1149016424","pt":1439918608156,"mc":[{"id":"1.120089104","rc":[{"atb":[[5.8,5.57]],"id":9480385}],"con":true,"img":false,"tv":21989.28}]}
{"op":"mcm","clk":"1149016440","pt":1439918608432,"mc":[{"id":"1.120089104","rc":[{"atb":[[1.19,386.31]],"id":9612932}],"con":true,"img":false,"tv":21989.28}]}
{"op":"mcm","clk":"1149016525","pt":1439918609019,"mc":[{"id":"1.120089104","rc":[{"atl":[[6.8,62.75]],"id":9480385}],"con":true,"img":false,"tv":21989.28}]}
{"op":"mcm","clk":"1149016843","pt":1439918613857,"mc":[{"id":"1.120089104","rc":[{"atb":[[5.8,2]],"id":9480385}],"con":true,"img":false,"tv":21989.28}]}
{"op":"mcm","clk":"1149017264","pt":1439918619822,"mc":[{"id":"1.120089104","rc":[{"atb":[[5.8,5.57]],"id":9480385}],"con":true,"img":false,"tv":21989.28}]}
{"op":"mcm","clk":"1149017384","pt":1439918621449,"mc":[{"id":"1.120089104","rc":[{"atl":[[6.8,66.51]],"id":9480385}],"con":true,"img":false,"tv":21989.28}]}
{"op":"mcm","clk":"1149017649","pt":1439918625246,"mc":[{"id":"1.120089104","rc":[{"atb":[[5.8,2]],"id":9480385}],"con":true,"img":false,"tv":21989.28}]}
{"op":"mcm","clk":"1149017923","pt":1439918630587,"mc":[{"id":"1.120089104","rc":[{"atb":[[5.8,5.57]],"id":9480385}],"con":true,"img":false,"tv":21989.28}]}
{"op":"mcm","clk":"1149017928","pt":1439918630793,"mc":[{"id":"1.120089104","rc":[{"atb":[[5.1,6]],"id":9480385}],"con":true,"img":false,"tv":21989.28}]}
{"op":"mcm","clk":"1149017933","pt":1439918630900,"mc":[{"id":"1.120089104","rc":[{"atb":[[5.2,51]],"id":9480385}],"con":true,"img":false,"tv":21989.28}]}
{"op":"mcm","clk":"1149018182","pt":1439918635609,"mc":[{"id":"1.120089104","rc":[{"atb":[[5.8,2]],"id":9480385}],"con":true,"img":false,"tv":21989.28}]}
{"op":"mcm","clk":"1149018537","pt":1439918641491,"mc":[{"id":"1.120089104","rc":[{"spn":1.18,"spf":1.07,"id":9612932},{"atb":[[5.8,5.57]],"id":9480385}],"con":true,"img":false,"tv":21989.28}]}
{"op":"mcm","clk":"1149018885","pt":1439918647351,"mc":[{"id":"1.120089104","rc":[{"atb":[[5.8,2]],"id":9480385}],"con":true,"img":false,"tv":21989.28}]}
{"op":"mcm","clk":"1149019224","pt":1439918652124,"mc":[{"id":"1.120089104","rc":[{"atb":[[5.8,5.57]],"id":9480385}],"con":true,"img":false,"tv":21989.28}]}
{"op":"mcm","clk":"1149019622","pt":1439918657942,"mc":[{"id":"1.120089104","rc":[{"atb":[[5.8,2]],"id":9480385}],"con":true,"img":false,"tv":21989.28}]}
{"op":"mcm","clk":"1149019909","pt":1439918662117,"mc":[{"id":"1.120089104","rc":[{"trd":[[6.2,25.63]],"ltp":6.2,"tv":25.63,"id":9480385},{"atb":[[6.2,8.73]],"id":9480385}],"con":true,"img":false,"tv":21993.28}]}
{"op":"mcm","clk":"1149019975","pt":1439918663216,"mc":[{"id":"1.120089104","rc":[{"atb":[[5.8,5.57]],"id":9480385}],"con":true,"img":false,"tv":21993.28}]}
{"op":"mcm","clk":"1149020395","pt":1439918668796,"mc":[{"id":"1.120089104","rc":[{"atb":[[5.8,2]],"id":9480385}],"con":true,"img":false,"tv":21993.28}]}
{"op":"mcm","clk":"1149020788","pt":1439918673802,"mc":[{"id":"1.120089104","rc":[{"atb":[[5.8,4.93]],"id":9480385}],"con":true,"img":false,"tv":21993.28}]}
{"op":"mcm","clk":"1149021195","pt":1439918678987,"mc":[{"id":"1.120089104","rc":[{"atb":[[5.8,2]],"id":9480385}],"con":true,"img":false,"tv":21993.28}]}
{"op":"mcm","clk":"1149021628","pt":1439918684022,"mc":[{"id":"1.120089104","rc":[{"atb":[[5.8,4.93]],"id":9480385}],"con":true,"img":false,"tv":21993.28}]}
{"op":"mcm","clk":"1149021851","pt":1439918687335,"mc":[{"id":"1.120089104","rc":[{"trd":[[1.2,2450.35]],"ltp":1.2,"tv":2450.35,"id":9612932},{"atl":[[1.2,247.65]],"id":9612932}],"con":true,"img":false,"tv":22025.28}]}
{"op":"mcm","clk":"1149022026","pt":1439918689561,"mc":[{"id":"1.120089104","rc":[{"atb":[[5.8,2]],"id":9480385}],"con":true,"img":false,"tv":22025.28}]}
{"op":"mcm","clk":"1149022416","pt":1439918694917,"mc":[{"id":"1.120089104","rc":[{"atb":[[5.8,4.93]],"id":9480385}],"con":true,"img":false,"tv":22025.28}]}
{"op":"mcm","clk":"1149022853","pt":1439918700682,"mc":[{"id":"1.120089104","rc":[{"atb":[[5.8,2]],"id":9480385}],"con":true,"img":false,"tv":22025.28}]}
{"op":"mcm","clk":"1149023292","pt":1439918706183,"mc":[{"id":"1.120089104","rc":[{"atb":[[5.8,4.93]],"id":9480385}],"con":true,"img":false,"tv":22025.28}]}
{"op":"mcm","clk":"1149023718","pt":1439918711243,"mc":[{"id":"1.120089104","rc":[{"atb":[[5.8,2]],"id":9480385}],"con":true,"img":false,"tv":22025.28}]}
{"op":"mcm","clk":"1149024170","pt":1439918716204,"mc":[{"id":"1.120089104","rc":[{"atb":[[5.8,4.93]],"id":9480385}],"con":true,"img":false,"tv":22025.28}]}
{"op":"mcm","clk":"1149024375","pt":1439918718130,"mc":[{"id":"1.120089104","rc":[{"atl":[[6.8,72.51]],"id":9480385}],"con":true,"img":false,"tv":22025.28}]}
{"op":"mcm","clk":"1149024635","pt":1439918721287,"mc":[{"id":"1.120089104","rc":[{"atb":[[5.8,2]],"id":9480385}],"con":true,"img":false,"tv":22025.28}]}
{"op":"mcm","clk":"1149025350","pt":1439918730116,"mc":[{"id":"1.120089104","rc":[{"atl":[[1.23,0]],"id":9612932}],"con":true,"img":false,"tv":22025.28}]}
{"op":"mcm","clk":"1149025361","pt":1439918730225,"mc":[{"id":"1.120089104","rc":[{"trd":[[1.19,2931.08]],"ltp":1.19,"tv":2931.08,"id":9612932},{"atb":[[1.19,346.3]],"id":9612932}],"con":true,"img":false,"tv":22105.29}]}
{"op":"mcm","clk":"1149026640","pt":1439918745863,"mc":[{"id":"1.120089104","rc":[{"atl":[[1.24,29.05]],"id":9612932},{"atl":[[7.2,14.99]],"id":9480385}],"con":true,"img":false,"tv":22105.29}]}
{"op":"mcm","clk":"1149027088","pt":1439918751491,"mc":[{"id":"1.120089104","rc":[{"atl":[[1.26,400]],"id":9612932}],"con":true,"img":false,"tv":22105.29}]}
{"op":"mcm","clk":"1149027095","pt":1439918751602,"mc":[{"id":"1.120089104","rc":[{"atl":[[1.28,195]],"id":9612932}],"con":true,"img":false,"tv":22105.29}]}
{"op":"mcm","clk":"1149028943","pt":1439918774406,"mc":[{"id":"1.120089104","rc":[{"atl":[[1000,9]],"id":9612932},{"spn":1.18,"spf":1.07,"id":9612932},{"trd":[[6.8,199.68]],"ltp":6.8,"tv":199.68,"id":9480385},{"atb":[[1.01,2455.04]],"id":9480385},{"atl":[[6.8,65.81]],"id":9480385}],"con":true,"img":false,"tv":22118.69}]}
{"op":"mcm","clk":"1149028952","pt":1439918774509,"mc":[{"id":"1.120089104","rc":[{"atl":[[1000,11.25]],"id":9612932},{"atb":[[1.01,2455.6]],"id":9480385}],"con":true,"img":false,"tv":22118.69}]}
{"op":"mcm","clk":"1149028970","pt":1439918774622,"mc":[{"id":"1.120089104","rc":[{"trd":[[1.19,3007.64]],"ltp":1.19,"tv":3007.64,"id":9612932},{"atb":[[1.19,308.02]],"id":9612932},{"atl":[[1000,3.25]],"id":9612932},{"atb":[[1.01,2451.6]],"id":9480385}],"con":true,"img":false,"tv":22195.25}]}
{"op":"mcm","clk":"1149028977","pt":1439918774824,"mc":[{"id":"1.120089104","rc":[{"atl":[[1000,1]],"id":9612932},{"atb":[[1.01,2451.04]],"id":9480385}],"con":true,"img":false,"tv":22199.41}]}
{"op":"mcm","clk":"1149028986","pt":1439918774928,"mc":[{"id":"1.120089104","rc":[{"trd":[[1.19,3011.8]],"ltp":1.19,"tv":3011.8,"id":9612932},{"atb":[[1.19,305.94]],"id":9612932},{"atl":[[1.2,247.82]],"id":9612932},{"atb":[[6.2,9.29]],"id":9480385}],"con":true,"img":false,"tv":22199.41}]}
{"op":"mcm","clk":"1149029370","pt":1439918779772,"mc":[{"id":"1.120089104","rc":[{"trd":[[1.2,2454.35]],"ltp":1.2,"tv":2454.35,"id":9612932},{"atl":[[1.2,245.82]],"id":9612932}],"con":true,"img":false,"tv":22203.41}]}
{"op":"mcm","clk":"1149031777","pt":1439918812109,"mc":[{"id":"1.120089104","rc":[{"atl":[[1.28,0]],"id":9612932}],"con":true,"img":false,"tv":22203.41}]}
{"op":"mcm","clk":"1149031785","pt":1439918812212,"mc":[{"id":"1.120089104","rc":[{"atl":[[1.27,198.89]],"id":9612932}],"con":true,"img":false,"tv":22203.41}]}
{"op":"mcm","clk":"1149040383","pt":1439918908285,"mc":[{"id":"1.120089104","rc":[{"spn":1.18,"spf":1.07,"id":9612932},{"atb":[[5.2,48]],"id":9480385}],"con":true,"img":false,"tv":22203.41}]}
{"op":"mcm","clk":"1149040392","pt":1439918908391,"mc":[{"id":"1.120089104","rc":[{"atb":[[6,4.81]],"id":9480385}],"con":true,"img":false,"tv":22203.41}]}
{"op":"mcm","clk":"1149041227","pt":1439918918294,"mc":[{"id":"1.120089104","rc":[{"atl":[[6.8,59.81]],"id":9480385}],"con":true,"img":false,"tv":22203.41}]}
{"op":"mcm","clk":"1149041523","pt":1439918921944,"mc":[{"id":"1.120089104","rc":[{"atb":[[5.8,5.03]],"id":9480385}],"con":true,"img":false,"tv":22203.41}]}
{"op":"mcm","clk":"1149041544","pt":1439918922165,"mc":[{"id":"1.120089104","rc":[{"atl":[[7.2,7.22]],"id":9480385}],"con":true,"img":false,"tv":22203.41}]}
{"op":"mcm","clk":"1149042052","pt":1439918927925,"mc":[{"id":"1.120089104","rc":[{"atl":[[1.24,72.94]],"id":9612932}],"con":true,"img":false,"tv":22203.41}]}
{"op":"mcm","clk":"1149042070","pt":1439918928094,"mc":[{"id":"1.120089104","rc":[{"atl":[[1.24,43.88]],"id":9612932},{"atb":[[5.8,2]],"id":9480385}],"con":true,"img":false,"tv":22203.41}]}
{"op":"mcm","clk":"1149042486","pt":1439918932621,"mc":[{"id":"1.120089104","rc":[{"atb":[[5.2,0]],"id":9480385}],"con":true,"img":false,"tv":22203.41}]}
{"op":"mcm","clk":"1149042497","pt":1439918932727,"mc":[{"id":"1.120089104","rc":[{"atb":[[5.3,47]],"id":9480385}],"con":true,"img":false,"tv":22203.41}]}
{"op":"mcm","clk":"1149042548","pt":1439918933257,"mc":[{"id":"1.120089104","rc":[{"atb":[[5.8,5.51]],"id":9480385}],"con":true,"img":false,"tv":22203.41}]}
{"op":"mcm","clk":"1149043120","pt":1439918939342,"mc":[{"id":"1.120089104","rc":[{"atb":[[5.8,2]],"id":9480385}],"con":true,"img":false,"tv":22203.41}]}
{"op":"mcm","clk":"1149043625","pt":1439918944936,"mc":[{"id":"1.120089104","rc":[{"atb":[[5.8,5.51]],"id":9480385}],"con":true,"img":false,"tv":22203.41}]}
{"op":"mcm","clk":"1149044309","pt":1439918953232,"mc":[{"id":"1.120089104","rc":[{"atb":[[5.8,2]],"id":9480385}],"con":true,"img":false,"tv":22203.41}]}
{"op":"mcm","clk":"1149044368","pt":1439918953925,"mc":[{"id":"1.120089104","rc":[{"trd":[[6.8,213.78]],"ltp":6.8,"tv":213.78,"id":9480385},{"atl":[[6.8,52.76]],"id":9480385}],"con":true,"img":false,"tv":22217.5}]}
{"op":"mcm","clk":"1149044409","pt":1439918954352,"mc":[{"id":"1.120089104","rc":[{"trd":[[1.19,3092.38]],"ltp":1.19,"tv":3092.38,"id":9612932},{"atb":[[1.19,265.65]],"id":9612932}],"con":true,"img":false,"tv":22298.08}]}
{"op":"mcm","clk":"1149044698","pt":1439918958248,"mc":[{"id":"1.120089104","rc":[{"atb":[[5.8,5.51]],"id":9480385}],"con":true,"img":false,"tv":22298.08}]}
{"op":"mcm","clk":"1149045120","pt":1439918963203,"mc":[{"id":"1.120089104","rc":[{"atb":[[5.8,2]],"id":9480385}],"con":true,"img":false,"tv":22298.08}]}
{"op":"mcm","clk":"1149045633","pt":1439918968641,"mc":[{"id":"1.120089104","rc":[{"spn":1.18,"spf":1.07,"id":9612932},{"atb":[[5.8,5.51]],"id":9480385}],"con":true,"img":false,"tv":22298.08}]}
{"op":"mcm","clk":"1149045898","pt":1439918971602,"mc":[{"id":"1.120089104","rc":[{"atb":[[1.19,341.42]],"id":9612932}],"con":true,"img":false,"tv":22298.08}]}
{"op":"mcm","clk":"1149045954","pt":1439918972100,"mc":[{"id":"1.120089104","rc":[{"atl":[[6.8,57.7]],"id":9480385}],"con":true,"img":false,"tv":22298.08}]}
{"op":"mcm","clk":"1149046165","pt":1439918974483,"mc":[{"id":"1.120089104","rc":[{"atb":[[5.8,2]],"id":9480385}],"con":true,"img":false,"tv":22298.08}]}
{"op":"mcm","clk":"1149046609","pt":1439918979349,"mc":[{"id":"1.120089104","rc":[{"atb":[[5.8,5.51]],"id":9480385}],"con":true,"img":false,"tv":22298.08}]}
{"op":"mcm","clk":"1149046651","pt":1439918979845,"mc":[{"id":"1.120089104","rc":[{"trd":[[1.19,3108.38]],"ltp":1.19,"tv":3108.38,"id":9612932},{"atb":[[1.19,333.42]],"id":9612932}],"con":true,"img":false,"tv":22314.08}]}
{"op":"mcm","clk":"1149047173","pt":1439918985197,"mc":[{"id":"1.120089104","rc":[{"atb":[[5.8,2]],"id":9480385}],"con":true,"img":false,"tv":22314.08}]}
{"op":"mcm","clk":"1149047629","pt":1439918990485,"mc":[{"id":"1.120089104","rc":[{"atb":[[5.8,5.51]],"id":9480385}],"con":true,"img":false,"tv":22314.08}]}
{"op":"mcm","clk":"1149047648","pt":1439918990714,"mc":[{"id":"1.120089104","rc":[{"atl":[[1.24,0]],"id":9612932}],"con":true,"img":false,"tv":22314.08}]}
{"op":"mcm","clk":"1149048126","pt":1439918996405,"mc":[{"id":"1.120089104","rc":[{"atl":[[1.24,140.92]],"id":9612932}],"con":true,"img":false,"tv":22314.08}]}
{"op":"mcm","clk":"1149048143","pt":1439918996607,"mc":[{"id":"1.120089104","rc":[{"atb":[[5.8,2]],"id":9480385}],"con":true,"img":false,"tv":22314.08}]}
{"op":"mcm","clk":"1149048657","pt":1439919002479,"mc":[{"id":"1.120089104","rc":[{"atb":[[5.8,5.51]],"id":9480385}],"con":true,"img":false,"tv":22314.08}]}
{"op":"mcm","clk":"1149049041","pt":1439919006802,"mc":[{"id":"1.120089104","rc":[{"atl":[[1.2,395.82]],"id":9612932},{"atl":[[6.6,27.27]],"id":9480385}],"con":true,"img":false,"tv":22314.08}]}
{"op":"mcm","clk":"1149049074","pt":1439919007218,"mc":[{"id":"1.120089104","rc":[{"atl":[[6.8,0]],"id":9480385}],"con":true,"img":false,"tv":22314.08}]}
{"op":"mcm","clk":"1149049172","pt":1439919008339,"mc":[{"id":"1.120089104","rc":[{"atb":[[5.8,2]],"id":9480385}],"con":true,"img":false,"tv":22314.08}]}
{"op":"mcm","clk":"1149049520","pt":1439919013392,"mc":[{"id":"1.120089104","rc":[{"atb":[[5.8,5.52]],"id":9480385},{"atl":[[7,12.41]],"id":9480385}],"con":true,"img":false,"tv":22314.08}]}
{"op":"mcm","clk":"1149050010","pt":1439919019144,"mc":[{"id":"1.120089104","rc":[{"atb":[[5.8,2]],"id":9480385}],"con":true,"img":false,"tv":22314.08}]}
{"op":"mcm","clk":"1149050405","pt":1439919024106,"mc":[{"id":"1.120089104","rc":[{"atb":[[5.8,5.52]],"id":9480385}],"con":true,"img":false,"tv":22314.08}]}
{"op":"mcm","clk":"1149050575","pt":1439919026020,"mc":[{"id":"1.120089104","rc":[{"atl":[[6.8,26.47],[6.6,0]],"id":9480385}],"con":true,"img":false,"tv":22314.08}]}
{"op":"mcm","clk":"1149050619","pt":1439919026447,"mc":[{"id":"1.120089104","rc":[{"atl":[[6.6,30.02]],"id":9480385}],"con":true,"img":false,"tv":22314.08}]}
{"op":"mcm","clk":"1149050921","pt":1439919029761,"mc":[{"id":"1.120089104","rc":[{"spn":1.18,"spf":1.07,"id":9612932},{"atb":[[5.8,2]],"id":9480385}],"con":true,"img":false,"tv":22314.08}]}
{"op":"mcm","clk":"1149051403","pt":1439919035168,"mc":[{"id":"1.120089104","rc":[{"atb":[[5.8,5.51]],"id":9480385}],"con":true,"img":false,"tv":22314.08}]}
{"op":"mcm","clk":"1149051894","pt":1439919040951,"mc":[{"id":"1.120089104","rc":[{"atb":[[5.8,2]],"id":9480385}],"con":true,"img":false,"tv":22314.08}]}
{"op":"mcm","clk":"1149052308","pt":1439919045489,"mc":[{"id":"1.120089104","rc":[{"atl":[[6.4,28.12]],"id":9480385}],"con":true,"img":false,"tv":22314.08}]}
{"op":"mcm","clk":"1149052333","pt":1439919045804,"mc":[{"id":"1.120089104","rc":[{"atb":[[5.8,5.51]],"id":9480385}],"con":true,"img":false,"tv":22314.08}]}
{"op":"mcm","clk":"1149052362","pt":1439919046077,"mc":[{"id":"1.120089104","rc":[{"atl":[[6.6,0]],"id":9480385}],"con":true,"img":false,"tv":22314.08}]}
{"op":"mcm","clk":"1149052370","pt":1439919046182,"mc":[{"id":"1.120089104","rc":[{"atl":[[7,10.66]],"id":9480385}],"con":true,"img":false,"tv":22314.08}]}
{"op":"mcm","clk":"1149052441","pt":1439919047086,"mc":[{"id":"1.120089104","rc":[{"atb":[[5,145.96]],"id":9480385}],"con":true,"img":false,"tv":22314.08}]}
{"op":"mcm","clk":"1149052485","pt":1439919047513,"mc":[{"id":"1.120089104","rc":[{"atb":[[5.2,103.22]],"id":9480385}],"con":true,"img":false,"tv":22314.08}]}
{"op":"mcm","clk":"1149052785","pt":1439919051316,"mc":[{"id":"1.120089104","rc":[{"atl":[[7,30.08]],"id":9480385}],"con":true,"img":false,"tv":22314.08}]}
{"op":"mcm","clk":"1149052926","pt":1439919053252,"mc":[{"id":"1.120089104","rc":[{"atl":[[14.5,0]],"id":9480385}],"con":true,"img":false,"tv":22314.08}]}
{"op":"mcm","clk":"1149052932","pt":1439919053352,"mc":[{"id":"1.120089104","rc":[{"atl":[[8,31]],"id":9480385}],"con":true,"img":false,"tv":22314.08}]}
{"op":"mcm","clk":"1149053046","pt":1439919054599,"mc":[{"id":"1.120089104","rc":[{"atb":[[5.8,2]],"id":9480385},{"atl":[[7,19.42]],"id":9480385}],"con":true,"img":false,"tv":22314.08}]}
{"op":"mcm","clk":"1149053301","pt":1439919057498,"mc":[{"id":"1.120089104","rc":[{"atb":[[5.8,5.53]],"id":9480385}],"con":true,"img":false,"tv":22314.08}]}
{"op":"mcm","clk":"1149053743","pt":1439919062668,"mc":[{"id":"1.120089104","rc":[{"atb":[[5.8,2]],"id":9480385}],"con":true,"img":false,"tv":22314.08}]}
{"op":"mcm","clk":"1149053951","pt":1439919064998,"mc":[{"id":"1.120089104","rc":[{"atl":[[6.4,0]],"id":9480385}],"con":true,"img":false,"tv":22314.08}]}
{"op":"mcm","clk":"1149053971","pt":1439919065204,"mc":[{"id":"1.120089104","rc":[{"atl":[[6.6,30.02]],"id":9480385}],"con":true,"img":false,"tv":22314.08}]}
{"op":"mcm","clk":"1149054171","pt":1439919067430,"mc":[{"id":"1.120089104","rc":[{"atb":[[5.8,5.53]],"id":9480385}],"con":true,"img":false,"tv":22314.08}]}
{"op":"mcm","clk":"1149054622","pt":1439919072876,"mc":[{"id":"1.120089104","rc":[{"atb":[[5.8,2]],"id":9480385}],"con":true,"img":false,"tv":22314.08}]}
{"op":"mcm","clk":"1149055264","pt":1439919081349,"mc":[{"id":"1.120089104","rc":[{"atl":[[1.24,0]],"id":9612932},{"atl":[[7,0]],"id":9480385}],"con":true,"img":false,"tv":22314.08}]}
{"op":"mcm","clk":"1149055497","pt":1439919084244,"mc":[{"id":"1.120089104","rc":[{"atl":[[6.4,28.12]],"id":9480385}],"con":true,"img":false,"tv":22314.08}]}
{"op":"mcm","clk":"1149055547","pt":1439919084838,"mc":[{"id":"1.120089104","rc":[{"atl":[[6.6,0]],"id":9480385}],"con":true,"img":false,"tv":22314.08}]}
{"op":"mcm","clk":"1149056435","pt":1439919095366,"mc":[{"id":"1.120089104","rc":[{"atl":[[1.24,140.92]],"id":9612932},{"atb":[[5.8,5.51]],"id":9480385}],"con":true,"img":false,"tv":22314.08}]}
{"op":"mcm","clk":"1149056949","pt":1439919101541,"mc":[{"id":"1.120089104","rc":[{"atb":[[5.8,2]],"id":9480385}],"con":true,"img":false,"tv":22314.08}]}
{"op":"mcm","clk":"1149057115","pt":1439919103686,"mc":[{"id":"1.120089104","rc":[{"atl":[[6.8,0],[6.4,0],[7,25.71]],"id":9480385}],"con":true,"img":false,"tv":22314.08}]}
{"op":"mcm","clk":"1149057166","pt":1439919104382,"mc":[{"id":"1.120089104","rc":[{"atl":[[6.8,56.99]],"id":9480385}],"con":true,"img":false,"tv":22314.08}]}
{"op":"mcm","clk":"1149057197","pt":1439919104659,"mc":[{"id":"1.120089104","rc":[{"atb":[[5,90.05]],"id":9480385}],"con":true,"img":false,"tv":22314.08}]}
{"op":"mcm","clk":"1149057234","pt":1439919105072,"mc":[{"id":"1.120089104","rc":[{"atb":[[5.2,171.67]],"id":9480385}],"con":true,"img":false,"tv":22314.08}]}
{"op":"mcm","clk":"1149057330","pt":1439919106369,"mc":[{"id":"1.120089104","rc":[{"atb":[[5.8,5.53]],"id":9480385},{"atl":[[7.2,18.33]],"id":9480385}],"con":true,"img":false,"tv":22314.08}]}
{"op":"mcm","clk":"1149057392","pt":1439919107159,"mc":[{"id":"1.120089104","rc":[{"trd":[[6.8,253.78]],"ltp":6.8,"tv":253.78,"id":9480385},{"atl":[[6.8,36.99]],"id":9480385}],"con":true,"img":false,"tv":22354.08}]}
{"op":"mcm","clk":"1149057469","pt":1439919108168,"mc":[{"id":"1.120089104","rc":[{"trd":[[1.19,3336.94]],"ltp":1.19,"tv":3336.94,"id":9612932},{"atb":[[1.19,219.14]],"id":9612932}],"con":true,"img":false,"tv":22582.64}]}
{"op":"mcm","clk":"1149057541","pt":1439919109182,"mc":[{"id":"1.120089104","rc":[{"atl":[[6.8,46.99]],"id":9480385}],"con":true,"img":false,"tv":22582.64}]}
{"op":"mcm","clk":"1149057754","pt":1439919112326,"mc":[{"id":"1.120089104","rc":[{"atb":[[5.8,2]],"id":9480385},{"atl":[[7.2,7.22]],"id":9480385}],"con":true,"img":false,"tv":22582.64}]}
{"op":"mcm","clk":"1149057864","pt":1439919113752,"mc":[{"id":"1.120089104","rc":[{"atl":[[8,0]],"id":9480385}],"con":true,"img":false,"tv":22582.64}]}
{"op":"mcm","clk":"1149057868","pt":1439919113858,"mc":[{"id":"1.120089104","rc":[{"atl":[[8.2,30]],"id":9480385}],"con":true,"img":false,"tv":22582.64}]}
{"op":"mcm","clk":"1149058181","pt":1439919118220,"mc":[{"id":"1.120089104","rc":[{"atb":[[5.8,5.51]],"id":9480385},{"atl":[[8,59.32]],"id":9480385}],"con":true,"img":false,"tv":22582.64}]}
{"op":"mcm","clk":"1149058574","pt":1439919123070,"mc":[{"id":"1.120089104","rc":[{"atl":[[6.6,27.27]],"id":9480385}],"con":true,"img":false,"tv":22582.64}]}
{"op":"mcm","clk":"1149058651","pt":1439919124030,"mc":[{"id":"1.120089104","rc":[{"atb":[[5.8,2]],"id":9480385}],"con":true,"img":false,"tv":22582.64}]}
{"op":"mcm","clk":"1149058710","pt":1439919124785,"mc":[{"id":"1.120089104","rc":[{"atl":[[6.8,0]],"id":9480385}],"con":true,"img":false,"tv":22582.64}]}
{"op":"mcm","clk":"1149059025","pt":1439919129248,"mc":[{"id":"1.120089104","rc":[{"atb":[[5.8,5.52]],"id":9480385},{"atl":[[7.2,37.34]],"id":9480385}],"con":true,"img":false,"tv":22582.64}]}
{"op":"mcm","clk":"1149059035","pt":1439919129461,"mc":[{"id":"1.120089104","rc":[{"atl":[[8,0]],"id":9480385}],"con":true,"img":false,"tv":22582.64}]}
{"op":"mcm","clk":"1149059477","pt":1439919135573,"mc":[{"id":"1.120089104","rc":[{"atb":[[5.8,2]],"id":9480385}],"con":true,"img":false,"tv":22582.64}]}
{"op":"mcm","clk":"1149059882","pt":1439919140631,"mc":[{"id":"1.120089104","rc":[{"atb":[[5.8,5.52]],"id":9480385}],"con":true,"img":false,"tv":22582.64}]}
{"op":"mcm","clk":"1149059953","pt":1439919141552,"mc":[{"id":"1.120089104","rc":[{"atl":[[6.6,0]],"id":9480385}],"con":true,"img":false,"tv":22582.64}]}
{"op":"mcm","clk":"1149059990","pt":1439919142038,"mc":[{"id":"1.120089104","rc":[{"atl":[[6.8,46.98]],"id":9480385}],"con":true,"img":false,"tv":22582.64}]}
{"op":"mcm","clk":"1149060237","pt":1439919145276,"mc":[{"id":"1.120089104","rc":[{"trd":[[1.19,3356.94]],"ltp":1.19,"tv":3356.94,"id":9612932},{"atb":[[1.19,209.14]],"id":9612932}],"con":true,"img":false,"tv":22602.64}]}
{"op":"mcm","clk":"1149060307","pt":1439919146369,"mc":[{"id":"1.120089104","rc":[{"atb":[[5.8,2]],"id":9480385},{"atl":[[7.2,7.22]],"id":9480385}],"con":true,"img":false,"tv":22602.64}]}
{"op":"mcm","clk":"1149060776","pt":1439919152081,"mc":[{"id":"1.120089104","rc":[{"atb":[[5.8,5.51]],"id":9480385},{"atl":[[8,48.23]],"id":9480385}],"con":true,"img":false,"tv":22602.64}]}
{"op":"mcm","clk":"1149061315","pt":1439919158631,"mc":[{"id":"1.120089104","rc":[{"spn":1.17,"spf":1.07,"id":9612932},{"atb":[[5.8,2]],"id":9480385}],"con":true,"img":false,"tv":22602.64}]}
{"op":"mcm","clk":"1149061433","pt":1439919159927,"mc":[{"id":"1.120089104","rc":[{"atl":[[6.6,27.27]],"id":9480385}],"con":true,"img":false,"tv":22602.64}]}
{"op":"mcm","clk":"1149061487","pt":1439919160460,"mc":[{"id":"1.120089104","rc":[{"atl":[[6.8,0]],"id":9480385}],"con":true,"img":false,"tv":22602.64}]}
{"op":"mcm","clk":"1149061835","pt":1439919164507,"mc":[{"id":"1.120089104","rc":[{"atb":[[5.8,5.51]],"id":9480385}],"con":true,"img":false,"tv":22602.64}]}
{"op":"mcm","clk":"1149062484","pt":1439919172486,"mc":[{"id":"1.120089104","rc":[{"atl":[[7.2,21.72]],"id":9480385}],"con":true,"img":false,"tv":22602.64}]}
{"op":"mcm","clk":"1149062500","pt":1439919172700,"mc":[{"id":"1.120089104","rc":[{"atb":[[5.8,2]],"id":9480385},{"atl":[[8,0]],"id":9480385}],"con":true,"img":false,"tv":22602.64}]}
{"op":"mcm","clk":"1149062909","pt":1439919177433,"mc":[{"id":"1.120089104","rc":[{"atb":[[5.8,5.52]],"id":9480385}],"con":true,"img":false,"tv":22602.64}]}
{"op":"mcm","clk":"1149062977","pt":1439919178232,"mc":[{"id":"1.120089104","rc":[{"atl":[[6.6,0]],"id":9480385}],"con":true,"img":false,"tv":22602.64}]}
{"op":"mcm","clk":"1149063006","pt":1439919178549,"mc":[{"id":"1.120089104","rc":[{"atl":[[6.8,46.1]],"id":9480385}],"con":true,"img":false,"tv":22602.64}]}
{"op":"mcm","clk":"1149063430","pt":1439919183148,"mc":[{"id":"1.120089104","rc":[{"atb":[[5.8,2]],"id":9480385},{"atl":[[7.2,7.22]],"id":9480385}],"con":true,"img":false,"tv":22602.64}]}
{"op":"mcm","clk":"1149063929","pt":1439919188623,"mc":[{"id":"1.120089104","rc":[{"atb":[[5.8,5.51]],"id":9480385},{"atl":[[8,51.04]],"id":9480385}],"con":true,"img":false,"tv":22602.64}]}
{"op":"mcm","clk":"1149064508","pt":1439919195109,"mc":[{"id":"1.120089104","rc":[{"atb":[[5.8,2]],"id":9480385}],"con":true,"img":false,"tv":22602.64}]}
{"op":"mcm","clk":"1149064587","pt":1439919196011,"mc":[{"id":"1.120089104","rc":[{"atl":[[6.6,27.27]],"id":9480385}],"con":true,"img":false,"tv":22602.64}]}
{"op":"mcm","clk":"1149064658","pt":1439919196883,"mc":[{"id":"1.120089104","rc":[{"atl":[[6.8,0]],"id":9480385}],"con":true,"img":false,"tv":22602.64}]}
{"op":"mcm","clk":"1149065018","pt":1439919200660,"mc":[{"id":"1.120089104","rc":[{"atb":[[5.8,5.51]],"id":9480385},{"atl":[[7.2,36.97]],"id":9480385}],"con":true,"img":false,"tv":22602.64}]}
{"op":"mcm","clk":"1149065040","pt":1439919200817,"mc":[{"id":"1.120089104","rc":[{"atl":[[8,0]],"id":9480385}],"con":true,"img":false,"tv":22602.64}]}
{"op":"mcm","clk":"1149065533","pt":1439919206403,"mc":[{"id":"1.120089104","rc":[{"atb":[[5.8,2]],"id":9480385}],"con":true,"img":false,"tv":22602.64}]}
{"op":"mcm","clk":"1149066079","pt":1439919212469,"mc":[{"id":"1.120089104","rc":[{"atb":[[5.8,5.52]],"id":9480385}],"con":true,"img":false,"tv":22602.64}]}
{"op":"mcm","clk":"1149066242","pt":1439919214192,"mc":[{"id":"1.120089104","rc":[{"atl":[[6.6,0]],"id":9480385}],"con":true,"img":false,"tv":22602.64}]}
{"op":"mcm","clk":"1149066332","pt":1439919215271,"mc":[{"id":"1.120089104","rc":[{"atl":[[6.8,46.1]],"id":9480385}],"con":true,"img":false,"tv":22602.64}]}
{"op":"mcm","clk":"1149066621","pt":1439919218612,"mc":[{"id":"1.120089104","rc":[{"atb":[[5.8,2]],"id":9480385},{"atl":[[7.2,7.22]],"id":9480385}],"con":true,"img":false,"tv":22602.64}]}
{"op":"mcm","clk":"1149067113","pt":1439919224147,"mc":[{"id":"1.120089104","rc":[{"atb":[[5.8,5.51]],"id":9480385},{"atl":[[8,48.45]],"id":9480385}],"con":true,"img":false,"tv":22602.64}]}
{"op":"mcm","clk":"1149067632","pt":1439919229831,"mc":[{"id":"1.120089104","rc":[{"atb":[[5.8,2]],"id":9480385}],"con":true,"img":false,"tv":22602.64}]}
{"op":"mcm","clk":"1149067840","pt":1439919232570,"mc":[{"id":"1.120089104","rc":[{"atl":[[6.6,27.27]],"id":9480385}],"con":true,"img":false,"tv":22602.64}]}
{"op":"mcm","clk":"1149067860","pt":1439919232785,"mc":[{"id":"1.120089104","rc":[{"atl":[[6.8,0]],"id":9480385}],"con":true,"img":false,"tv":22602.64}]}
{"op":"mcm","clk":"1149067976","pt":1439919234016,"mc":[{"id":"1.120089104","rc":[{"atb":[[1.14,219],[1.13,0]],"id":9612932}],"con":true,"img":false,"tv":22602.64}]}
{"op":"mcm","clk":"1149068092","pt":1439919235526,"mc":[{"id":"1.120089104","rc":[{"atb":[[5.8,5.51]],"id":9480385},{"atl":[[7.2,32.36]],"id":9480385}],"con":true,"img":false,"tv":22602.64}]}
{"op":"mcm","clk":"1149068109","pt":1439919235741,"mc":[{"id":"1.120089104","rc":[{"atl":[[8,0]],"id":9480385}],"con":true,"img":false,"tv":22602.64}]}
{"op":"mcm","clk":"1149068515","pt":1439919240726,"mc":[{"id":"1.120089104","rc":[{"atb":[[5.8,2]],"id":9480385}],"con":true,"img":false,"tv":22602.64}]}
{"op":"mcm","clk":"1149068896","pt":1439919245197,"mc":[{"id":"1.120089104","rc":[{"atb":[[1.13,6]],"id":9612932}],"con":true,"img":false,"tv":22602.64}]}
{"op":"mcm","clk":"1149068938","pt":1439919245569,"mc":[{"id":"1.120089104","rc":[{"atb":[[5.8,5.52]],"id":9480385}],"con":true,"img":false,"tv":22602.64}]}
{"op":"mcm","clk":"1149069444","pt":1439919251081,"mc":[{"id":"1.120089104","rc":[{"atl":[[6.6,0]],"id":9480385}],"con":true,"img":false,"tv":22602.64}]}
{"op":"mcm","clk":"1149069455","pt":1439919251138,"mc":[{"id":"1.120089104","rc":[{"atb":[[5.8,2]],"id":9480385}],"con":true,"img":false,"tv":22602.64}]}
{"op":"mcm","clk":"1149069543","pt":1439919252083,"mc":[{"id":"1.120089104","rc":[{"atl":[[6.8,46.1]],"id":9480385}],"con":true,"img":false,"tv":22602.64}]}
{"op":"mcm","clk":"1149069952","pt":1439919255972,"mc":[{"id":"1.120089104","rc":[{"atb":[[5.8,5.51]],"id":9480385}],"con":true,"img":false,"tv":22602.64}]}
{"op":"mcm","clk":"1149069971","pt":1439919256184,"mc":[{"id":"1.120089104","rc":[{"atl":[[7.2,7.22]],"id":9480385}],"con":true,"img":false,"tv":22602.64}]}
{"op":"mcm","clk":"1149070491","pt":1439919261916,"mc":[{"id":"1.120089104","rc":[{"atl":[[8,51.09]],"id":9480385}],"con":true,"img":false,"tv":22602.64}]}
{"op":"mcm","clk":"1149070543","pt":1439919262444,"mc":[{"id":"1.120089104","rc":[{"atb":[[5.8,2]],"id":9480385}],"con":true,"img":false,"tv":22602.64}]}
{"op":"mcm","clk":"1149080307","pt":1439919266798,"mc":[{"id":"1.120089104","rc":[{"atb":[[5.8,5.51]],"id":9480385}],"con":true,"img":false,"tv":22602.64}]}
{"op":"mcm","clk":"1149080558","pt":1439919269617,"mc":[{"id":"1.120089104","rc":[{"atl":[[6.6,27.27]],"id":9480385}],"con":true,"img":false,"tv":22602.64}]}
{"op":"mcm","clk":"1149080612","pt":1439919270149,"mc":[{"id":"1.120089104","rc":[{"atl":[[6.8,0]],"id":9480385}],"con":true,"img":false,"tv":22602.64}]}
{"op":"mcm","clk":"1149080776","pt":1439919271861,"mc":[{"id":"1.120089104","rc":[{"atl":[[7.2,36.97]],"id":9480385}],"con":true,"img":false,"tv":22602.64}]}
{"op":"mcm","clk":"1149080793","pt":1439919272076,"mc":[{"id":"1.120089104","rc":[{"atb":[[5.8,2]],"id":9480385},{"atl":[[8,0]],"id":9480385}],"con":true,"img":false,"tv":22602.64}]}
{"op":"mcm","clk":"1149081326","pt":1439919277590,"mc":[{"id":"1.120089104","rc":[{"atb":[[5.8,5.52]],"id":9480385}],"con":true,"img":false,"tv":22602.64}]}
{"op":"mcm","clk":"1149081921","pt":1439919283334,"mc":[{"id":"1.120089104","rc":[{"atb":[[5.8,2]],"id":9480385}],"con":true,"img":false,"tv":22602.64}]}
{"op":"mcm","clk":"1149082389","pt":1439919287953,"mc":[{"id":"1.120089104","rc":[{"atl":[[6.6,0]],"id":9480385}],"con":true,"img":false,"tv":22602.64}]}
{"op":"mcm","clk":"1149082423","pt":1439919288223,"mc":[{"id":"1.120089104","rc":[{"atb":[[5.8,5.52]],"id":9480385},{"atl":[[6.8,46.1]],"id":9480385}],"con":true,"img":false,"tv":22602.64}]}
{"op":"mcm","clk":"1149082971","pt":1439919294164,"mc":[{"id":"1.120089104","rc":[{"atb":[[5.8,2]],"id":9480385},{"atl":[[7.2,7.22]],"id":9480385}],"con":true,"img":false,"tv":22602.64}]}
{"op":"mcm","clk":"1149083164","pt":1439919296204,"mc":[{"id":"1.120089104","rc":[{"atb":[[1.01,2475.04]],"id":9612932},{"atb":[[1.01,2453.04]],"id":9480385}],"con":true,"img":false,"tv":22602.64}]}
{"op":"mcm","clk":"1149083187","pt":1439919296368,"mc":[{"id":"1.120089104","rc":[{"atb":[[1.01,2474.04]],"id":9612932},{"atb":[[1.01,2452.04]],"id":9480385}],"con":true,"img":false,"tv":22602.64}]}
{"op":"mcm","clk":"1149083205","pt":1439919296584,"mc":[{"id":"1.120089104","rc":[{"atb":[[1.01,2473.04]],"id":9612932},{"atb":[[1.01,2451.04]],"id":9480385}],"con":true,"img":false,"tv":22602.64}]}
{"op":"mcm","clk":"1149083216","pt":1439919296690,"mc":[{"id":"1.120089104","rc":[{"trd":[[1.2,2456.35]],"ltp":1.2,"tv":2456.35,"id":9612932},{"atl":[[1.2,394.82]],"id":9612932},{"atb":[[1.5,1]],"id":9480385}],"con":true,"img":false,"tv":22604.64}]}
{"op":"mcm","clk":"1149083510","pt":1439919299617,"mc":[{"id":"1.120089104","rc":[{"atb":[[5.8,5.51]],"id":9480385},{"atl":[[8,48.45]],"id":9480385}],"con":true,"img":false,"tv":22604.64}]}
{"op":"mcm","clk":"1149084093","pt":1439919305742,"mc":[{"id":"1.120089104","rc":[{"atb":[[5.8,2]],"id":9480385}],"con":true,"img":false,"tv":22604.64}]}
{"op":"mcm","clk":"1149084136","pt":1439919306323,"mc":[{"id":"1.120089104","rc":[{"atl":[[6.6,27.27]],"id":9480385}],"con":true,"img":false,"tv":22604.64}]}
{"op":"mcm","clk":"1149084178","pt":1439919306754,"mc":[{"id":"1.120089104","rc":[{"atl":[[6.8,0]],"id":9480385}],"con":true,"img":false,"tv":22604.64}]}
{"op":"mcm","clk":"1149084604","pt":1439919311024,"mc":[{"id":"1.120089104","rc":[{"atb":[[5.8,5.52]],"id":9480385},{"atl":[[7.2,36.97]],"id":9480385}],"con":true,"img":false,"tv":22604.64}]}
{"op":"mcm","clk":"1149084625","pt":1439919311252,"mc":[{"id":"1.120089104","rc":[{"atl":[[8,0]],"id":9480385}],"con":true,"img":false,"tv":22604.64}]}
{"op":"mcm","clk":"1149085229","pt":1439919317101,"mc":[{"id":"1.120089104","rc":[{"atb":[[5.8,2]],"id":9480385}],"con":true,"img":false,"tv":22604.64}]}
{"op":"mcm","clk":"1149085794","pt":1439919322178,"mc":[{"id":"1.120089104","rc":[{"atb":[[5.8,5.52]],"id":9480385}],"con":true,"img":false,"tv":22604.64}]}
{"op":"mcm","clk":"1149086078","pt":1439919325100,"mc":[{"id":"1.120089104","rc":[{"atl":[[6.6,0]],"id":9480385}],"con":true,"img":false,"tv":22604.64}]}
{"op":"mcm","clk":"1149086161","pt":1439919325861,"mc":[{"id":"1.120089104","rc":[{"atl":[[6.8,46.1]],"id":9480385}],"con":true,"img":false,"tv":22604.64}]}
{"op":"mcm","clk":"1149086540","pt":1439919329902,"mc":[{"id":"1.120089104","rc":[{"atb":[[5.8,2]],"id":9480385},{"atl":[[7.2,7.22]],"id":9480385}],"con":true,"img":false,"tv":22604.64}]}
{"op":"mcm","clk":"1149087046","pt":1439919334650,"mc":[{"id":"1.120089104","rc":[{"atb":[[5.8,5.51]],"id":9480385},{"atl":[[8,48.45]],"id":9480385}],"con":true,"img":false,"tv":22604.64}]}
{"op":"mcm","clk":"1149087501","pt":1439919339451,"mc":[{"id":"1.120089104","rc":[{"atb":[[5.8,2]],"id":9480385}],"con":true,"img":false,"tv":22604.64}]}
{"op":"mcm","clk":"1149087903","pt":1439919343355,"mc":[{"id":"1.120089104","rc":[{"atl":[[6.6,27.27]],"id":9480385}],"con":true,"img":false,"tv":22604.64}]}
{"op":"mcm","clk":"1149087977","pt":1439919344094,"mc":[{"id":"1.120089104","rc":[{"atl":[[6.8,0]],"id":9480385}],"con":true,"img":false,"tv":22604.64}]}
{"op":"mcm","clk":"1149088027","pt":1439919344684,"mc":[{"id":"1.120089104","rc":[{"atb":[[5.8,5.51]],"id":9480385},{"atl":[[7.2,15.61]],"id":9480385}],"con":true,"img":false,"tv":22604.64}]}
{"op":"mcm","clk":"1149088061","pt":1439919345007,"mc":[{"id":"1.120089104","rc":[{"atl":[[8,0]],"id":9480385}],"con":true,"img":false,"tv":22604.64}]}
{"op":"mcm","clk":"1149088805","pt":1439919353167,"mc":[{"id":"1.120089104","rc":[{"atb":[[5.8,2]],"id":9480385}],"con":true,"img":false,"tv":22604.64}]}
{"op":"mcm","clk":"1149089018","pt":1439919355420,"mc":[{"id":"1.120089104","rc":[{"atb":[[5.8,5.52]],"id":9480385}],"con":true,"img":false,"tv":22604.64}]}
{"op":"mcm","clk":"1149089604","pt":1439919361294,"mc":[{"id":"1.120089104","rc":[{"atb":[[5.8,2]],"id":9480385}],"con":true,"img":false,"tv":22604.64}]}
{"op":"mcm","clk":"1149089645","pt":1439919361684,"mc":[{"id":"1.120089104","rc":[{"atl":[[6.6,0]],"id":9480385}],"con":true,"img":false,"tv":22604.64}]}
{"op":"mcm","clk":"1149089731","pt":1439919362666,"mc":[{"id":"1.120089104","rc":[{"atl":[[6.8,46.1]],"id":9480385}],"con":true,"img":false,"tv":22604.64}]}
{"op":"mcm","clk":"1149090126","pt":1439919366512,"mc":[{"id":"1.120089104","rc":[{"atb":[[5.8,5.52]],"id":9480385}],"con":true,"img":false,"tv":22604.64}]}
{"op":"mcm","clk":"1149090157","pt":1439919366730,"mc":[{"id":"1.120089104","rc":[{"atl":[[7.2,7.22]],"id":9480385}],"con":true,"img":false,"tv":22604.64}]}
{"op":"mcm","clk":"1149090860","pt":1439919373594,"mc":[{"id":"1.120089104","rc":[{"atl":[[8,51.09]],"id":9480385}],"con":true,"img":false,"tv":22604.64}]}
{"op":"mcm","clk":"1149090882","pt":1439919373799,"mc":[{"id":"1.120089104","rc":[{"atb":[[5.8,2]],"id":9480385}],"con":true,"img":false,"tv":22604.64}]}
{"op":"mcm","clk":"1149091527","pt":1439919380153,"mc":[{"id":"1.120089104","rc":[{"atl":[[6.6,27.27]],"id":9480385}],"con":true,"img":false,"tv":22604.64}]}
{"op":"mcm","clk":"1149091542","pt":1439919380329,"mc":[{"id":"1.120089104","rc":[{"atl":[[6.8,0]],"id":9480385}],"con":true,"img":false,"tv":22604.64}]}
{"op":"mcm","clk":"1149091619","pt":1439919381089,"mc":[{"id":"1.120089104","rc":[{"atb":[[5.8,5.51]],"id":9480385}],"con":true,"img":false,"tv":22604.64}]}
{"op":"mcm","clk":"1149092299","pt":1439919387653,"mc":[{"id":"1.120089104","rc":[{"atl":[[7.2,26.23]],"id":9480385}],"con":true,"img":false,"tv":22604.64}]}
{"op":"mcm","clk":"1149092338","pt":1439919387927,"mc":[{"id":"1.120089104","rc":[{"atb":[[5.8,2]],"id":9480385},{"atl":[[8,0]],"id":9480385}],"con":true,"img":false,"tv":22604.64}]}
{"op":"mcm","clk":"1149092889","pt":1439919393062,"mc":[{"id":"1.120089104","rc":[{"atb":[[5.8,5.52]],"id":9480385}],"con":true,"img":false,"tv":22604.64}]}
{"op":"mcm","clk":"1149093434","pt":1439919398509,"mc":[{"id":"1.120089104","rc":[{"atb":[[5.8,2]],"id":9480385}],"con":true,"img":false,"tv":22604.64}]}
{"op":"mcm","clk":"1149093473","pt":1439919398787,"mc":[{"id":"1.120089104","rc":[{"atl":[[6.6,0]],"id":9480385}],"con":true,"img":false,"tv":22604.64}]}
{"op":"mcm","clk":"1149093580","pt":1439919399761,"mc":[{"id":"1.120089104","rc":[{"atl":[[6.8,46.1]],"id":9480385}],"con":true,"img":false,"tv":22604.64}]}
{"op":"mcm","clk":"1149094094","pt":1439919404597,"mc":[{"id":"1.120089104","rc":[{"atb":[[5.8,5.52]],"id":9480385}],"con":true,"img":false,"tv":22604.64}]}
{"op":"mcm","clk":"1149094117","pt":1439919404808,"mc":[{"id":"1.120089104","rc":[{"atl":[[7.2,7.22]],"id":9480385}],"con":true,"img":false,"tv":22604.64}]}
{"op":"mcm","clk":"1149094788","pt":1439919411312,"mc":[{"id":"1.120089104","rc":[{"atl":[[8,48.45]],"id":9480385}],"con":true,"img":false,"tv":22604.64}]}
{"op":"mcm","clk":"1149094811","pt":1439919411530,"mc":[{"id":"1.120089104","rc":[{"atb":[[5.8,2]],"id":9480385}],"con":true,"img":false,"tv":22604.64}]}
{"op":"mcm","clk":"1149095170","pt":1439919414848,"mc":[{"id":"1.120089104","rc":[{"atl":[[8.2,0]],"id":9480385}],"con":true,"img":false,"tv":22604.64}]}
{"op":"mcm","clk":"1149095180","pt":1439919414952,"mc":[{"id":"1.120089104","rc":[{"atl":[[9.2,27]],"id":9480385}],"con":true,"img":false,"tv":22604.64}]}
{"op":"mcm","clk":"1149095399","pt":1439919417096,"mc":[{"id":"1.120089104","rc":[{"atl":[[6.6,27.27]],"id":9480385}],"con":true,"img":false,"tv":22604.64}]}
{"op":"mcm","clk":"1149095412","pt":1439919417203,"mc":[{"id":"1.120089104","rc":[{"atb":[[5.8,5.51]],"id":9480385}],"con":true,"img":false,"tv":22604.64}]}
{"op":"mcm","clk":"1149095488","pt":1439919417905,"mc":[{"id":"1.120089104","rc":[{"atl":[[6.8,0]],"id":9480385}],"con":true,"img":false,"tv":22604.64}]}
{"op":"mcm","clk":"1149095901","pt":1439919421671,"mc":[{"id":"1.120089104","rc":[{"atb":[[1.18,673.25]],"id":9612932}],"con":true,"img":false,"tv":22604.64}]}
{"op":"mcm","clk":"1149096297","pt":1439919425070,"mc":[{"id":"1.120089104","rc":[{"atl":[[7.2,21.62]],"id":9480385}],"con":true,"img":false,"tv":22604.64}]}
{"op":"mcm","clk":"1149096330","pt":1439919425393,"mc":[{"id":"1.120089104","rc":[{"atb":[[5.8,2]],"id":9480385},{"atl":[[8,0]],"id":9480385}],"con":true,"img":false,"tv":22604.64}]}
{"op":"mcm","clk":"1149097038","pt":1439919432026,"mc":[{"id":"1.120089104","rc":[{"atb":[[5.8,5.52]],"id":9480385}],"con":true,"img":false,"tv":22604.64}]}
{"op":"mcm","clk":"1149097427","pt":1439919435549,"mc":[{"id":"1.120089104","rc":[{"atl":[[6.6,0]],"id":9480385}],"con":true,"img":false,"tv":22604.64}]}
{"op":"mcm","clk":"1149097528","pt":1439919436362,"mc":[{"id":"1.120089104","rc":[{"atl":[[6.8,76.66]],"id":9480385}],"con":true,"img":false,"tv":22604.64}]}
{"op":"mcm","clk":"1149097896","pt":1439919439821,"mc":[{"id":"1.120089104","rc":[{"atb":[[5.8,2]],"id":9480385},{"atl":[[7.2,7.22]],"id":9480385}],"con":true,"img":false,"tv":22604.64}]}
{"op":"mcm","clk":"1149098231","pt":1439919442827,"mc":[{"id":"1.120089104","rc":[{"atb":[[5.8,5.51]],"id":9480385},{"atl":[[9,72.04]],"id":9480385}],"con":true,"img":false,"tv":22604.64}]}
{"op":"mcm","clk":"1149098409","pt":1439919444742,"mc":[{"id":"1.120089104","rc":[{"atl":[[8.8,6]],"id":9480385}],"con":true,"img":false,"tv":22604.64}]}
{"op":"mcm","clk":"1149098938","pt":1439919448698,"mc":[{"id":"1.120089104","rc":[{"atl":[[8.6,72.04]],"id":9480385}],"con":true,"img":false,"tv":22604.64}]}
{"op":"mcm","clk":"1149098978","pt":1439919448912,"mc":[{"id":"1.120089104","rc":[{"atb":[[5.8,2]],"id":9480385},{"atl":[[9,0]],"id":9480385}],"con":true,"img":false,"tv":22604.64}]}
{"op":"mcm","clk":"1149099571","pt":1439919453601,"mc":[{"id":"1.120089104","rc":[{"atl":[[8.8,0]],"id":9480385}],"con":true,"img":false,"tv":22604.64}]}
{"op":"mcm","clk":"1149099587","pt":1439919453817,"mc":[{"id":"1.120089104","rc":[{"atl":[[8.4,6]],"id":9480385}],"con":true,"img":false,"tv":22604.64}]}
{"op":"mcm","clk":"1149099617","pt":1439919454094,"mc":[{"id":"1.120089104","rc":[{"atb":[[1.19,360.4]],"id":9612932},{"atl":[[6.6,27.27]],"id":9480385}],"con":true,"img":false,"tv":22604.64}]}
{"op":"mcm","clk":"1149099662","pt":1439919454529,"mc":[{"id":"1.120089104","rc":[{"atb":[[5.8,5.51]],"id":9480385},{"atl":[[6.8,0]],"id":9480385}],"con":true,"img":false,"tv":22604.64}]}
{"op":"mcm","clk":"1149100332","pt":1439919460570,"mc":[{"id":"1.120089104","rc":[{"atl":[[7.2,32.09]],"id":9480385}],"con":true,"img":false,"tv":22604.64}]}
{"op":"mcm","clk":"1149100354","pt":1439919460796,"mc":[{"id":"1.120089104","rc":[{"atb":[[5.8,2]],"id":9480385},{"atl":[[8.6,0]],"id":9480385}],"con":true,"img":false,"tv":22604.64}]}
{"op":"mcm","clk":"1149100690","pt":1439919463902,"mc":[{"id":"1.120089104","rc":[{"atl":[[8.4,0]],"id":9480385}],"con":true,"img":false,"tv":22604.64}]}
{"op":"mcm","clk":"1149100880","pt":1439919465603,"mc":[{"id":"1.120089104","rc":[{"atb":[[5.8,5.52]],"id":9480385}],"con":true,"img":false,"tv":22604.64}]}
{"op":"mcm","clk":"1149101519","pt":1439919472325,"mc":[{"id":"1.120089104","rc":[{"atb":[[1.19,209.14]],"id":9612932},{"atb":[[5.8,2]],"id":9480385},{"atl":[[6.6,0]],"id":9480385}],"con":true,"img":false,"tv":22604.64}]}
{"op":"mcm","clk":"1149101632","pt":1439919473511,"mc":[{"id":"1.120089104","rc":[{"atl":[[6.8,76.66]],"id":9480385}],"con":true,"img":false,"tv":22604.64}]}
{"op":"mcm","clk":"1149101847","pt":1439919475444,"mc":[{"id":"1.120089104","rc":[{"spn":1.18,"spf":1.07,"id":9612932},{"atl":[[9.2,0]],"id":9480385}],"con":true,"img":false,"tv":22604.64}]}
{"op":"mcm","clk":"1149101859","pt":1439919475546,"mc":[{"id":"1.120089104","rc":[{"atl":[[8.2,30]],"id":9480385}],"con":true,"img":false,"tv":22604.64}]}
{"op":"mcm","clk":"1149102106","pt":1439919477537,"mc":[{"id":"1.120089104","rc":[{"atb":[[5.8,5.51]],"id":9480385}],"con":true,"img":false,"tv":22604.64}]}
{"op":"mcm","clk":"1149102127","pt":1439919477758,"mc":[{"id":"1.120089104","rc":[{"atl":[[7.2,7.22]],"id":9480385}],"con":true,"img":false,"tv":22604.64}]}
{"op":"mcm","clk":"1149102672","pt":1439919482700,"mc":[{"id":"1.120089104","rc":[{"atl":[[8,47.02]],"id":9480385}],"con":true,"img":false,"tv":22604.64}]}
{"op":"mcm","clk":"1149102705","pt":1439919483020,"mc":[{"id":"1.120089104","rc":[{"atb":[[5.8,2]],"id":9480385}],"con":true,"img":false,"tv":22604.64}]}
{"op":"mcm","clk":"1149103318","pt":1439919488745,"mc":[{"id":"1.120089104","rc":[{"atb":[[5.8,5.51]],"id":9480385}],"con":true,"img":false,"tv":22604.64}]}
{"op":"mcm","clk":"1149103550","pt":1439919490759,"mc":[{"id":"1.120089104","rc":[{"atb":[[1.19,360.4]],"id":9612932},{"atl":[[6.6,27.27]],"id":9480385}],"con":true,"img":false,"tv":22604.64}]}
{"op":"mcm","clk":"1149103613","pt":1439919491287,"mc":[{"id":"1.120089104","rc":[{"atl":[[6.8,0]],"id":9480385}],"con":true,"img":false,"tv":22604.64}]}
{"op":"mcm","clk":"1149103944","pt":1439919494127,"mc":[{"id":"1.120089104","rc":[{"atl":[[7.2,42.83]],"id":9480385}],"con":true,"img":false,"tv":22604.64}]}
{"op":"mcm","clk":"1149103968","pt":1439919494302,"mc":[{"id":"1.120089104","rc":[{"atb":[[5.8,2]],"id":9480385},{"atl":[[8,0]],"id":9480385}],"con":true,"img":false,"tv":22604.64}]}
{"op":"mcm","clk":"1149104033","pt":1439919494930,"mc":[{"id":"1.120089104","rc":[{"atb":[[1.11,1928.72]],"id":9612932}],"con":true,"img":false,"tv":22604.64}]}
{"op":"mcm","clk":"1149104519","pt":1439919499597,"mc":[{"id":"1.120089104","rc":[{"atb":[[5.8,5.52]],"id":9480385}],"con":true,"img":false,"tv":22604.64}]}
{"op":"mcm","clk":"1149105180","pt":1439919506406,"mc":[{"id":"1.120089104","rc":[{"atb":[[5.8,2]],"id":9480385}],"con":true,"img":false,"tv":22604.64}]}
{"op":"mcm","clk":"1149105504","pt":1439919509315,"mc":[{"id":"1.120089104","rc":[{"atb":[[1.19,209.14]],"id":9612932},{"atl":[[6.6,0]],"id":9480385}],"con":true,"img":false,"tv":22604.64}]}
{"op":"mcm","clk":"1149105570","pt":1439919510014,"mc":[{"id":"1.120089104","rc":[{"atl":[[6.8,76.66]],"id":9480385}],"con":true,"img":false,"tv":22604.64}]}
{"op":"mcm","clk":"1149105723","pt":1439919511624,"mc":[{"id":"1.120089104","rc":[{"atb":[[5.8,5.52]],"id":9480385}],"con":true,"img":false,"tv":22604.64}]}
{"op":"mcm","clk":"1149105732","pt":1439919511834,"mc":[{"id":"1.120089104","rc":[{"atl":[[7.2,7.22]],"id":9480385}],"con":true,"img":false,"tv":22604.64}]}
{"op":"mcm","clk":"1149106254","pt":1439919517700,"mc":[{"id":"1.120089104","rc":[{"atl":[[8,47.02]],"id":9480385}],"con":true,"img":false,"tv":22604.64}]}
{"op":"mcm","clk":"1149106268","pt":1439919517913,"mc":[{"id":"1.120089104","rc":[{"atb":[[5.8,2]],"id":9480385}],"con":true,"img":false,"tv":22604.64}]}
{"op":"mcm","clk":"1149106751","pt":1439919523855,"mc":[{"id":"1.120089104","rc":[{"atb":[[5.8,5.51]],"id":9480385}],"con":true,"img":false,"tv":22604.64}]}
{"op":"mcm","clk":"1149107000","pt":1439919526763,"mc":[{"id":"1.120089104","rc":[{"atb":[[5,76.84]],"id":9480385}],"con":true,"img":false,"tv":22604.64}]}
{"op":"mcm","clk":"1149107058","pt":1439919527570,"mc":[{"id":"1.120089104","rc":[{"atb":[[1.19,360.4]],"id":9612932},{"atb":[[5.2,187.15]],"id":9480385},{"atl":[[6.6,27.27]],"id":9480385}],"con":true,"img":false,"tv":22604.64}]}
{"op":"mcm","clk":"1149107085","pt":1439919527939,"mc":[{"id":"1.120089104","rc":[{"atl":[[6.8,0]],"id":9480385}],"con":true,"img":false,"tv":22604.64}]}
{"op":"mcm","clk":"1149107167","pt":1439919529071,"mc":[{"id":"1.120089104","rc":[{"atb":[[5.8,2]],"id":9480385}],"con":true,"img":false,"tv":22604.64}]}
{"op":"mcm","clk":"1149107585","pt":1439919534438,"mc":[{"id":"1.120089104","rc":[{"atb":[[5.8,5.52]],"id":9480385},{"atl":[[7.2,42.83]],"id":9480385}],"con":true,"img":false,"tv":22604.64}]}
{"op":"mcm","clk":"1149107598","pt":1439919534649,"mc":[{"id":"1.120089104","rc":[{"atl":[[8,0]],"id":9480385}],"con":true,"img":false,"tv":22604.64}]}
{"op":"mcm","clk":"1149108053","pt":1439919539683,"mc":[{"id":"1.120089104","rc":[{"spn":1.18,"spf":1.07,"id":9612932},{"atb":[[5.8,2]],"id":9480385}],"con":true,"img":false,"tv":22604.64}]}
{"op":"mcm","clk":"1149108608","pt":1439919545587,"mc":[{"id":"1.120089104","rc":[{"atb":[[5.8,5.52]],"id":9480385}],"con":true,"img":false,"tv":22604.64}]}
{"op":"mcm","clk":"1149108634","pt":1439919545910,"mc":[{"id":"1.120089104","rc":[{"atb":[[1.19,209.14]],"id":9612932},{"atl":[[6.6,0]],"id":9480385}],"con":true,"img":false,"tv":22604.64}]}
{"op":"mcm","clk":"1149108757","pt":1439919547472,"mc":[{"id":"1.120089104","rc":[{"atl":[[6.8,76.66]],"id":9480385}],"con":true,"img":false,"tv":22604.64}]}
{"op":"mcm","clk":"1149109065","pt":1439919551052,"mc":[{"id":"1.120089104","rc":[{"atb":[[5.8,2]],"id":9480385},{"atl":[[7.2,7.22]],"id":9480385}],"con":true,"img":false,"tv":22604.64}]}
{"op":"mcm","clk":"1149109629","pt":1439919558335,"mc":[{"id":"1.120089104","rc":[{"atb":[[5.8,5.51]],"id":9480385},{"atl":[[8,47.02]],"id":9480385}],"con":true,"img":false,"tv":22604.64}]}
{"op":"mcm","clk":"1149110194","pt":1439919564371,"mc":[{"id":"1.120089104","rc":[{"atb":[[1.19,360.4]],"id":9612932},{"atl":[[6.6,27.27]],"id":9480385}],"con":true,"img":false,"tv":22604.64}]}
{"op":"mcm","clk":"1149110250","pt":1439919565004,"mc":[{"id":"1.120089104","rc":[{"atl":[[6.8,0]],"id":9480385}],"con":true,"img":false,"tv":22604.64}]}
{"op":"mcm","clk":"1149110299","pt":1439919565490,"mc":[{"id":"1.120089104","rc":[{"atb":[[5.8,2]],"id":9480385}],"con":true,"img":false,"tv":22604.64}]}
{"op":"mcm","clk":"1149110770","pt":1439919571366,"mc":[{"id":"1.120089104","rc":[{"atb":[[5.8,5.52]],"id":9480385},{"atl":[[7.2,42.83]],"id":9480385}],"con":true,"img":false,"tv":22604.64}]}
{"op":"mcm","clk":"1149111012","pt":1439919574428,"mc":[{"id":"1.120089104","rc":[{"atl":[[8,0]],"id":9480385}],"con":true,"img":false,"tv":22604.64}]}
{"op":"mcm","clk":"1149111208","pt":1439919576945,"mc":[{"id":"1.120089104","rc":[{"atb":[[5.8,2]],"id":9480385}],"con":true,"img":false,"tv":22604.64}]}
{"op":"mcm","clk":"1149111627","pt":1439919582656,"mc":[{"id":"1.120089104","rc":[{"atb":[[1.19,209.14]],"id":9612932},{"atl":[[6.6,0]],"id":9480385}],"con":true,"img":false,"tv":22604.64}]}
{"op":"mcm","clk":"1149111714","pt":1439919583735,"mc":[{"id":"1.120089104","rc":[{"atl":[[6.8,76.66]],"id":9480385}],"con":true,"img":false,"tv":22604.64}]}
{"op":"mcm","clk":"1149111730","pt":1439919584053,"mc":[{"id":"1.120089104","rc":[{"atb":[[5.8,5.52]],"id":9480385}],"con":true,"img":false,"tv":22604.64}]}
{"op":"mcm","clk":"1149112143","pt":1439919589417,"mc":[{"id":"1.120089104","rc":[{"atb":[[5.8,2]],"id":9480385},{"atl":[[7.2,7.22]],"id":9480385}],"con":true,"img":false,"tv":22604.64}]}
{"op":"mcm","clk":"1149112514","pt":1439919594368,"mc":[{"id":"1.120089104","rc":[{"atb":[[5.8,5.51]],"id":9480385},{"atl":[[8,47.02]],"id":9480385}],"con":true,"img":false,"tv":22604.64}]}
{"op":"mcm","clk":"1149112933","pt":1439919600325,"mc":[{"id":"1.120089104","rc":[{"spn":1.18,"spf":1.07,"id":9612932},{"atb":[[5.8,2]],"id":9480385}],"con":true,"img":false,"tv":22604.64}]}
{"op":"mcm","clk":"1149112985","pt":1439919601029,"mc":[{"id":"1.120089104","rc":[{"atb":[[1.19,360.4]],"id":9612932},{"atl":[[6.6,27.27]],"id":9480385}],"con":true,"img":false,"tv":22604.64}]}
{"op":"mcm","clk":"1149112998","pt":1439919601251,"mc":[{"id":"1.120089104","rc":[{"atl":[[6.8,0]],"id":9480385}],"con":true,"img":false,"tv":22604.64}]}
{"op":"mcm","clk":"1149113404","pt":1439919606117,"mc":[{"id":"1.120089104","rc":[{"atb":[[5.8,5.51]],"id":9480385},{"atl":[[7.2,15.61]],"id":9480385}],"con":true,"img":false,"tv":22604.64}]}
{"op":"mcm","clk":"1149113411","pt":1439919606329,"mc":[{"id":"1.120089104","rc":[{"atl":[[8,0]],"id":9480385}],"con":true,"img":false,"tv":22604.64}]}
{"op":"mcm","clk":"1149113876","pt":1439919611897,"mc":[{"id":"1.120089104","rc":[{"atb":[[5.8,2]],"id":9480385}],"con":true,"img":false,"tv":22604.64}]}
{"op":"mcm","clk":"1149114357","pt":1439919617528,"mc":[{"id":"1.120089104","rc":[{"atb":[[5.8,5.52]],"id":9480385}],"con":true,"img":false,"tv":22604.64}]}
{"op":"mcm","clk":"1149114552","pt":1439919619541,"mc":[{"id":"1.120089104","rc":[{"atb":[[1.19,209.14]],"id":9612932},{"atl":[[6.6,0]],"id":9480385}],"con":true,"img":false,"tv":22604.64}]}
{"op":"mcm","clk":"1149114580","pt":1439919619861,"mc":[{"id":"1.120089104","rc":[{"atl":[[6.8,76.66]],"id":9480385}],"con":true,"img":false,"tv":22604.64}]}
{"op":"mcm","clk":"1149115256","pt":1439919626848,"mc":[{"id":"1.120089104","rc":[{"atb":[[5.8,2]],"id":9480385},{"atl":[[7.2,7.22]],"id":9480385}],"con":true,"img":false,"tv":22604.64}]}
{"op":"mcm","clk":"1149115563","pt":1439919629790,"mc":[{"id":"1.120089104","rc":[{"atb":[[5,67.7]],"id":9480385}],"con":true,"img":false,"tv":22604.64}]}
{"op":"mcm","clk":"1149115636","pt":1439919630479,"mc":[{"id":"1.120089104","rc":[{"atb":[[5.2,197.86]],"id":9480385}],"con":true,"img":false,"tv":22604.64}]}
{"op":"mcm","clk":"1149115767","pt":1439919631783,"mc":[{"id":"1.120089104","rc":[{"atb":[[5.8,5.51]],"id":9480385},{"atl":[[8,47.02]],"id":9480385}],"con":true,"img":false,"tv":22604.64}]}
{"op":"mcm","clk":"1149116302","pt":1439919637419,"mc":[{"id":"1.120089104","rc":[{"atb":[[5.8,2]],"id":9480385}],"con":true,"img":false,"tv":22604.64}]}
{"op":"mcm","clk":"1149116372","pt":1439919638105,"mc":[{"id":"1.120089104","rc":[{"atb":[[1.19,360.4]],"id":9612932},{"atl":[[6.6,27.27]],"id":9480385}],"con":true,"img":false,"tv":22604.64}]}
{"op":"mcm","clk":"1149116482","pt":1439919639106,"mc":[{"id":"1.120089104","rc":[{"atl":[[6.8,0]],"id":9480385}],"con":true,"img":false,"tv":22604.64}]}
{"op":"mcm","clk":"1149116896","pt":1439919643116,"mc":[{"id":"1.120089104","rc":[{"atb":[[5.8,5.51]],"id":9480385}],"con":true,"img":false,"tv":22604.64}]}
{"op":"mcm","clk":"1149117354","pt":1439919648633,"mc":[{"id":"1.120089104","rc":[{"atl":[[7.2,42.83]],"id":9480385}],"con":true,"img":false,"tv":22604.64}]}
{"op":"mcm","clk":"1149117374","pt":1439919648842,"mc":[{"id":"1.120089104","rc":[{"atb":[[5.8,2]],"id":9480385},{"atl":[[8,0]],"id":9480385}],"con":true,"img":false,"tv":22604.64}]}
{"op":"mcm","clk":"1149117880","pt":1439919654812,"mc":[{"id":"1.120089104","rc":[{"atb":[[5.8,5.52]],"id":9480385}],"con":true,"img":false,"tv":22604.64}]}
{"op":"mcm","clk":"1149118031","pt":1439919656414,"mc":[{"id":"1.120089104","rc":[{"atb":[[1.19,209.14]],"id":9612932},{"atl":[[6.6,0]],"id":9480385}],"con":true,"img":false,"tv":22604.64}]}
{"op":"mcm","clk":"1149118137","pt":1439919657701,"mc":[{"id":"1.120089104","rc":[{"atl":[[6.8,76.66]],"id":9480385}],"con":true,"img":false,"tv":22604.64}]}
{"op":"mcm","clk":"1149118566","pt":1439919662156,"mc":[{"id":"1.120089104","rc":[{"atb":[[5.8,2]],"id":9480385},{"atl":[[7.2,7.22]],"id":9480385}],"con":true,"img":false,"tv":22604.64}]}
{"op":"mcm","clk":"1149119280","pt":1439919669634,"mc":[{"id":"1.120089104","rc":[{"atb":[[5.8,5.51]],"id":9480385},{"atl":[[8,47.02]],"id":9480385}],"con":true,"img":false,"tv":22604.64}]}
{"op":"mcm","clk":"1149119722","pt":1439919674499,"mc":[{"id":"1.120089104","rc":[{"atb":[[5.8,2]],"id":9480385}],"con":true,"img":false,"tv":22604.64}]}
{"op":"mcm","clk":"1149119752","pt":1439919674818,"mc":[{"id":"1.120089104","rc":[{"atb":[[1.19,360.4]],"id":9612932},{"atl":[[6.6,27.27]],"id":9480385}],"con":true,"img":false,"tv":22604.64}]}
{"op":"mcm","clk":"1149119821","pt":1439919675409,"mc":[{"id":"1.120089104","rc":[{"atl":[[6.8,0]],"id":9480385}],"con":true,"img":false,"tv":22604.64}]}
{"op":"mcm","clk":"1149120219","pt":1439919679793,"mc":[{"id":"1.120089104","rc":[{"atb":[[5.8,5.51]],"id":9480385}],"con":true,"img":false,"tv":22604.64}]}
{"op":"mcm","clk":"1149120634","pt":1439919684800,"mc":[{"id":"1.120089104","rc":[{"atl":[[7.2,42.83]],"id":9480385}],"con":true,"img":false,"tv":22604.64}]}
{"op":"mcm","clk":"1149120642","pt":1439919685015,"mc":[{"id":"1.120089104","rc":[{"atb":[[5.8,2]],"id":9480385},{"atl":[[8,0]],"id":9480385}],"con":true,"img":false,"tv":22604.64}]}
{"op":"mcm","clk":"1149121049","pt":1439919689873,"mc":[{"id":"1.120089104","rc":[{"atb":[[5.8,5.52]],"id":9480385}],"con":true,"img":false,"tv":22604.64}]}
{"op":"mcm","clk":"1149121379","pt":1439919693314,"mc":[{"id":"1.120089104","rc":[{"atb":[[1.19,209.14]],"id":9612932},{"atl":[[6.6,0]],"id":9480385}],"con":true,"img":false,"tv":22604.64}]}
{"op":"mcm","clk":"1149121432","pt":1439919693904,"mc":[{"id":"1.120089104","rc":[{"atl":[[6.8,76.66]],"id":9480385}],"con":true,"img":false,"tv":22604.64}]}
{"op":"mcm","clk":"1149121645","pt":1439919696904,"mc":[{"id":"1.120089104","rc":[{"atb":[[5.8,2]],"id":9480385},{"atl":[[7.2,7.22]],"id":9480385}],"con":true,"img":false,"tv":22604.64}]}
{"op":"mcm","clk":"1149122069","pt":1439919701763,"mc":[{"id":"1.120089104","rc":[{"atb":[[5.8,5.51]],"id":9480385},{"atl":[[8,47.02]],"id":9480385}],"con":true,"img":false,"tv":22604.64}]}
{"op":"mcm","clk":"1149122104","pt":1439919702291,"mc":[{"id":"1.120089104","rc":[{"atb":[[5,53.94]],"id":9480385}],"con":true,"img":false,"tv":22604.64}]}
{"op":"mcm","clk":"1149122145","pt":1439919702882,"mc":[{"id":"1.120089104","rc":[{"atb":[[5.2,213.99]],"id":9480385}],"con":true,"img":false,"tv":22604.64}]}
{"op":"mcm","clk":"1149122431","pt":1439919706230,"mc":[{"id":"1.120089104","rc":[{"atb":[[5,0]],"id":9480385}],"con":true,"img":false,"tv":22604.64}]}
{"op":"mcm","clk":"1149122442","pt":1439919706403,"mc":[{"id":"1.120089104","rc":[{"atb":[[5.2,277.23]],"id":9480385}],"con":true,"img":false,"tv":22604.64}]}
{"op":"mcm","clk":"1149122536","pt":1439919707644,"mc":[{"id":"1.120089104","rc":[{"atb":[[5.8,2]],"id":9480385}],"con":true,"img":false,"tv":22604.64}]}
{"op":"mcm","clk":"1149122845","pt":1439919711567,"mc":[{"id":"1.120089104","rc":[{"atb":[[1.19,360.4]],"id":9612932},{"atl":[[1.2,244.82]],"id":9612932},{"atl":[[6.6,27.27]],"id":9480385}],"con":true,"img":false,"tv":22604.64}]}
{"op":"mcm","clk":"1149122891","pt":1439919712103,"mc":[{"id":"1.120089104","rc":[{"atl":[[6.8,0]],"id":9480385}],"con":true,"img":false,"tv":22604.64}]}
{"op":"mcm","clk":"1149122920","pt":1439919712484,"mc":[{"id":"1.120089104","rc":[{"atb":[[5.8,5.04]],"id":9480385},{"atl":[[7.2,15.61]],"id":9480385}],"con":true,"img":false,"tv":22604.64}]}
{"op":"mcm","clk":"1149122955","pt":1439919713022,"mc":[{"id":"1.120089104","rc":[{"atl":[[8,0]],"id":9480385}],"con":true,"img":false,"tv":22604.64}]}
{"op":"mcm","clk":"1149123032","pt":1439919713827,"mc":[{"id":"1.120089104","rc":[{"atb":[[5.1,0]],"id":9480385}],"con":true,"img":false,"tv":22604.64}]}
{"op":"mcm","clk":"1149124465","pt":1439919729999,"mc":[{"id":"1.120089104","rc":[{"atl":[[1.2,394.82]],"id":9612932},{"spn":1.18,"spf":1.07,"id":9612932},{"atl":[[6.6,0]],"id":9480385}],"con":true,"img":false,"tv":22604.64}]}
{"op":"mcm","clk":"1149124498","pt":1439919730375,"mc":[{"id":"1.120089104","rc":[{"atl":[[6.8,89.91]],"id":9480385}],"con":true,"img":false,"tv":22604.64}]}
{"op":"mcm","clk":"1149124594","pt":1439919731497,"mc":[{"id":"1.120089104","rc":[{"atl":[[8.2,280]],"id":9480385}],"con":true,"img":false,"tv":22604.64}]}
{"op":"mcm","clk":"1149125022","pt":1439919736873,"mc":[{"id":"1.120089104","rc":[{"atl":[[7.2,7.22]],"id":9480385}],"con":true,"img":false,"tv":22604.64}]}
{"op":"mcm","clk":"1149125353","pt":1439919740784,"mc":[{"id":"1.120089104","rc":[{"atl":[[8,6]],"id":9480385}],"con":true,"img":false,"tv":22604.64}]}
{"op":"mcm","clk":"1149125500","pt":1439919742589,"mc":[{"id":"1.120089104","rc":[{"atl":[[7.8,47.47]],"id":9480385}],"con":true,"img":false,"tv":22604.64}]}
{"op":"mcm","clk":"1149126050","pt":1439919748391,"mc":[{"id":"1.120089104","rc":[{"atl":[[1.2,244.82]],"id":9612932},{"atl":[[6.6,27.27]],"id":9480385}],"con":true,"img":false,"tv":22604.64}]}
{"op":"mcm","clk":"1149126084","pt":1439919748779,"mc":[{"id":"1.120089104","rc":[{"atl":[[6.8,0]],"id":9480385}],"con":true,"img":false,"tv":22604.64}]}
{"op":"mcm","clk":"1149126475","pt":1439919753375,"mc":[{"id":"1.120089104","rc":[{"atl":[[7.2,42.83]],"id":9480385}],"con":true,"img":false,"tv":22604.64}]}
{"op":"mcm","clk":"1149126498","pt":1439919753560,"mc":[{"id":"1.120089104","rc":[{"atl":[[7.8,1.22]],"id":9480385}],"con":true,"img":false,"tv":22604.64}]}
{"op":"mcm","clk":"1149127785","pt":1439919766678,"mc":[{"id":"1.120089104","rc":[{"atl":[[6.6,0]],"id":9480385}],"con":true,"img":false,"tv":22604.64}]}
{"op":"mcm","clk":"1149127790","pt":1439919766781,"mc":[{"id":"1.120089104","rc":[{"atl":[[1.2,394.82]],"id":9612932}],"con":true,"img":false,"tv":22604.64}]}
{"op":"mcm","clk":"1149127824","pt":1439919767163,"mc":[{"id":"1.120089104","rc":[{"atl":[[6.8,89.91]],"id":9480385}],"con":true,"img":false,"tv":22604.64}]}
{"op":"mcm","clk":"1149128014","pt":1439919769097,"mc":[{"id":"1.120089104","rc":[{"atl":[[7.2,7.22]],"id":9480385}],"con":true,"img":false,"tv":22604.64}]}
{"op":"mcm","clk":"1149128480","pt":1439919773998,"mc":[{"id":"1.120089104","rc":[{"atl":[[7.8,47.47]],"id":9480385}],"con":true,"img":false,"tv":22604.64}]}
{"op":"mcm","clk":"1149129521","pt":1439919785213,"mc":[{"id":"1.120089104","rc":[{"atl":[[1.2,244.82]],"id":9612932},{"atl":[[6.6,27.27]],"id":9480385}],"con":true,"img":false,"tv":22604.64}]}
{"op":"mcm","clk":"1149129585","pt":1439919785815,"mc":[{"id":"1.120089104","rc":[{"atl":[[6.8,0]],"id":9480385}],"con":true,"img":false,"tv":22604.64}]}
{"op":"mcm","clk":"1149130196","pt":1439919791884,"mc":[{"id":"1.120089104","rc":[{"atl":[[7.2,32.09]],"id":9480385}],"con":true,"img":false,"tv":22604.64}]}
{"op":"mcm","clk":"1149130214","pt":1439919792103,"mc":[{"id":"1.120089104","rc":[{"atl":[[7.8,1.22]],"id":9480385}],"con":true,"img":false,"tv":22604.64}]}
{"op":"mcm","clk":"1149131285","pt":1439919803689,"mc":[{"id":"1.120089104","rc":[{"atl":[[1.2,394.82]],"id":9612932},{"atl":[[6.6,0]],"id":9480385}],"con":true,"img":false,"tv":22604.64}]}
{"op":"mcm","clk":"1149131377","pt":1439919804705,"mc":[{"id":"1.120089104","rc":[{"atl":[[6.8,89.91]],"id":9480385}],"con":true,"img":false,"tv":22604.64}]}
{"op":"mcm","clk":"1149131890","pt":1439919810383,"mc":[{"id":"1.120089104","rc":[{"trd":[[1.2,2516.35]],"ltp":1.2,"tv":2516.35,"id":9612932},{"atl":[[1.2,364.81]],"id":9612932}],"con":true,"img":false,"tv":22664.65}]}
{"op":"mcm","clk":"1149132005","pt":1439919811505,"mc":[{"id":"1.120089104","rc":[{"atl":[[7.2,7.22]],"id":9480385}],"con":true,"img":false,"tv":22664.65}]}
{"op":"mcm","clk":"1149132798","pt":1439919819411,"mc":[{"id":"1.120089104","rc":[{"atl":[[7.8,47.47]],"id":9480385}],"con":true,"img":false,"tv":22664.65}]}
{"op":"mcm","clk":"1149133098","pt":1439919822338,"mc":[{"id":"1.120089104","rc":[{"atl":[[1.2,214.81]],"id":9612932},{"atl":[[6.6,27.27]],"id":9480385}],"con":true,"img":false,"tv":22664.65}]}
{"op":"mcm","clk":"1149133183","pt":1439919823139,"mc":[{"id":"1.120089104","rc":[{"atl":[[6.8,0]],"id":9480385}],"con":true,"img":false,"tv":22664.65}]}
{"op":"mcm","clk":"1149133428","pt":1439919825658,"mc":[{"id":"1.120089104","rc":[{"atl":[[7.2,42.83]],"id":9480385}],"con":true,"img":false,"tv":22664.65}]}
{"op":"mcm","clk":"1149133464","pt":1439919825976,"mc":[{"id":"1.120089104","rc":[{"atl":[[7.8,1.22]],"id":9480385}],"con":true,"img":false,"tv":22664.65}]}
{"op":"mcm","clk":"1149133583","pt":1439919827100,"mc":[{"id":"1.120089104","rc":[{"trd":[[1.2,2945.99]],"ltp":1.2,"tv":2945.99,"id":9612932},{"atb":[[1.2,35.18]],"id":9612932},{"atl":[[1.2,0]],"id":9612932}],"con":true,"img":false,"tv":23094.29}]}
{"op":"mcm","clk":"1149133640","pt":1439919827581,"mc":[{"id":"1.120089104","rc":[{"trd":[[1.2,2990.23]],"ltp":1.2,"tv":2990.23,"id":9612932},{"atb":[[1.2,13.06]],"id":9612932},{"trd":[[6.2,34.19]],"ltp":6.2,"tv":34.19,"id":9480385},{"atb":[[6.2,5.01]],"id":9480385}],"con":true,"img":false,"tv":23147.09}]}
{"op":"mcm","clk":"1149133649","pt":1439919827688,"mc":[{"id":"1.120089104","rc":[{"trd":[[1.2,3016.35]],"ltp":1.2,"tv":3016.35,"id":9612932},{"atb":[[1.2,0]],"id":9612932},{"atl":[[1.2,22.12]],"id":9612932},{"trd":[[6.2,44.21]],"ltp":6.2,"tv":44.21,"id":9480385},{"atb":[[6.2,0]],"id":9480385},{"atl":[[6.2,1.8]],"id":9480385}],"con":true,"img":false,"tv":23183.23}]}
{"op":"mcm","clk":"1149133661","pt":1439919827782,"mc":[{"id":"1.120089104","rc":[{"atl":[[1.2,98.49]],"id":9612932},{"atl":[[6.2,15.41]],"id":9480385}],"con":true,"img":false,"tv":23183.23}]}
{"op":"mcm","clk":"1149133682","pt":1439919827957,"mc":[{"id":"1.120089104","rc":[{"atl":[[1.2,76.37]],"id":9612932},{"atl":[[6.2,13.61]],"id":9480385}],"con":true,"img":false,"tv":23183.23}]}
{"op":"mcm","clk":"1149133730","pt":1439919828592,"mc":[{"id":"1.120089104","rc":[{"atl":[[1.2,35.18]],"id":9612932},{"atl":[[6.2,6.81]],"id":9480385}],"con":true,"img":false,"tv":23183.23}]}
{"op":"mcm","clk":"1149133868","pt":1439919829916,"mc":[{"id":"1.120089104","rc":[{"atl":[[6.2,11.79]],"id":9480385}],"con":true,"img":false,"tv":23183.23}]}
{"op":"mcm","clk":"1149134004","pt":1439919831380,"mc":[{"id":"1.120089104","rc":[{"atl":[[6.8,7.75]],"id":9480385}],"con":true,"img":false,"tv":23183.23}]}
{"op":"mcm","clk":"1149134025","pt":1439919831586,"mc":[{"id":"1.120089104","rc":[{"atl":[[7.2,7.22]],"id":9480385}],"con":true,"img":false,"tv":23183.23}]}
{"op":"mcm","clk":"1149134359","pt":1439919834738,"mc":[{"id":"1.120089104","rc":[{"atl":[[4.9,2]],"id":9612932}],"con":true,"img":false,"tv":23183.23}]}
{"op":"mcm","clk":"1149134601","pt":1439919837099,"mc":[{"id":"1.120089104","rc":[{"atl":[[1.24,243.07]],"id":9612932},{"atb":[[5.8,6.53]],"id":9480385},{"atl":[[6.8,12.61]],"id":9480385}],"con":true,"img":false,"tv":23183.23}]}
{"op":"mcm","clk":"1149134627","pt":1439919837263,"mc":[{"id":"1.120089104","rc":[{"atl":[[1.24,102.14]],"id":9612932},{"atb":[[5.8,3.49]],"id":9480385},{"atl":[[6.8,4.85]],"id":9480385}],"con":true,"img":false,"tv":23183.23}]}
{"op":"mcm","clk":"1149135183","pt":1439919842402,"mc":[{"id":"1.120089104","rc":[{"atl":[[1.24,192.33]],"id":9612932}],"con":true,"img":false,"tv":23183.23}]}
{"op":"mcm","clk":"1149135202","pt":1439919842619,"mc":[{"id":"1.120089104","rc":[{"atl":[[1.24,90.18]],"id":9612932},{"atb":[[5.8,2]],"id":9480385}],"con":true,"img":false,"tv":23183.23}]}
{"op":"mcm","clk":"1149135646","pt":1439919846648,"mc":[{"id":"1.120089104","rc":[{"trd":[[6.2,49.17]],"ltp":6.2,"tv":49.17,"id":9480385},{"atl":[[6.2,9.31]],"id":9480385}],"con":true,"img":false,"tv":23188.19}]}
{"op":"mcm","clk":"1149135795","pt":1439919847938,"mc":[{"id":"1.120089104","rc":[{"atl":[[1.24,165.72]],"id":9612932},{"atb":[[5.6,3.02]],"id":9480385}],"con":true,"img":false,"tv":23188.19}]}
{"op":"mcm","clk":"1149135820","pt":1439919848162,"mc":[{"id":"1.120089104","rc":[{"atl":[[1.24,75.54]],"id":9612932}],"con":true,"img":false,"tv":23188.19}]}
{"op":"mcm","clk":"1149137191","pt":1439919860935,"mc":[{"id":"1.120089104","rc":[{"trd":[[6,13.76]],"ltp":6.0,"tv":13.76,"id":9480385},{"atb":[[6,0.81]],"id":9480385},{"spn":5.75,"spf":2.41,"id":9480385}],"con":true,"img":false,"tv":23196.19}]}
{"op":"mcm","clk":"1149137549","pt":1439919864185,"mc":[{"id":"1.120089104","rc":[{"atl":[[1000,2]],"id":9480385}],"con":true,"img":false,"tv":23196.19}]}
{"op":"mcm","clk":"1149137558","pt":1439919864298,"mc":[{"id":"1.120089104","rc":[{"atl":[[1.24,141.27]],"id":9612932}],"con":true,"img":false,"tv":23196.19}]}
{"op":"mcm","clk":"1149137567","pt":1439919864350,"mc":[{"id":"1.120089104","rc":[{"atl":[[1000,3.81]],"id":9480385}],"con":true,"img":false,"tv":23196.19}]}
{"op":"mcm","clk":"1149137575","pt":1439919864457,"mc":[{"id":"1.120089104","rc":[{"atl":[[1.24,65.73]],"id":9612932}],"con":true,"img":false,"tv":23196.19}]}
{"op":"mcm","clk":"1149137583","pt":1439919864559,"mc":[{"id":"1.120089104","rc":[{"atl":[[1000,2]],"id":9480385}],"con":true,"img":false,"tv":23196.19}]}
{"op":"mcm","clk":"1149137588","pt":1439919864671,"mc":[{"id":"1.120089104","rc":[{"atl":[[6.4,1.81]],"id":9480385}],"con":true,"img":false,"tv":23196.19}]}
{"op":"mcm","clk":"1149137634","pt":1439919865097,"mc":[{"id":"1.120089104","rc":[{"atl":[[1000,0]],"id":9480385}],"con":true,"img":false,"tv":23196.19}]}
{"op":"mcm","clk":"1149140680","pt":1439919894299,"mc":[{"id":"1.120089104","rc":[{"atb":[[5.2,208.77]],"id":9480385}],"con":true,"img":false,"tv":23196.19}]}
{"op":"mcm","clk":"1149140746","pt":1439919894835,"mc":[{"id":"1.120089104","rc":[{"atb":[[4.9,79.38]],"id":9480385}],"con":true,"img":false,"tv":23196.19}]}
{"op":"mcm","clk":"1149140937","pt":1439919896826,"mc":[{"id":"1.120089104","rc":[{"atb":[[5.3,0]],"id":9480385},{"atl":[[8.2,250]],"id":9480385}],"con":true,"img":false,"tv":23196.19}]}
{"op":"mcm","clk":"1149140947","pt":1439919896940,"mc":[{"id":"1.120089104","rc":[{"atb":[[5.1,49]],"id":9480385},{"atl":[[7.8,33.22]],"id":9480385}],"con":true,"img":false,"tv":23196.19}]}
{"op":"mcm","clk":"1149141168","pt":1439919899147,"mc":[{"id":"1.120089104","rc":[{"atb":[[5.3,6]],"id":9480385}],"con":true,"img":false,"tv":23196.19}]}
{"op":"mcm","clk":"1149141191","pt":1439919899366,"mc":[{"id":"1.120089104","rc":[{"atb":[[5,6]],"id":9480385}],"con":true,"img":false,"tv":23196.19}]}
{"op":"mcm","clk":"1149141269","pt":1439919900169,"mc":[{"id":"1.120089104","rc":[{"atb":[[5.2,192.65]],"id":9480385}],"con":true,"img":false,"tv":23196.19}]}
{"op":"mcm","clk":"1149141280","pt":1439919900275,"mc":[{"id":"1.120089104","rc":[{"atb":[[4.9,95.51]],"id":9480385}],"con":true,"img":false,"tv":23196.19}]}
{"op":"mcm","clk":"1149141405","pt":1439919901393,"mc":[{"id":"1.120089104","rc":[{"atb":[[5.2,177.16]],"id":9480385}],"con":true,"img":false,"tv":23196.19}]}
{"op":"mcm","clk":"1149141416","pt":1439919901512,"mc":[{"id":"1.120089104","rc":[{"atb":[[4.9,111]],"id":9480385}],"con":true,"img":false,"tv":23196.19}]}
{"op":"mcm","clk":"1149142781","pt":1439919913278,"mc":[{"id":"1.120089104","rc":[{"atb":[[5.2,113.93]],"id":9480385}],"con":true,"img":false,"tv":23196.19}]}
{"op":"mcm","clk":"1149142791","pt":1439919913436,"mc":[{"id":"1.120089104","rc":[{"atb":[[4.9,174.23]],"id":9480385}],"con":true,"img":false,"tv":23196.19}]}
{"op":"mcm","clk":"1149148992","pt":1439919977665,"mc":[{"id":"1.120089104","rc":[{"trd":[[1.2,3077.89]],"ltp":1.2,"tv":3077.89,"id":9612932},{"atl":[[1.2,4.41]],"id":9612932}],"con":true,"img":false,"tv":23257.73}]}
{"op":"mcm","clk":"1149149253","pt":1439919980396,"mc":[{"id":"1.120089104","rc":[{"trd":[[1.2,3086.71]],"ltp":1.2,"tv":3086.71,"id":9612932},{"atl":[[1.2,0]],"id":9612932}],"con":true,"img":false,"tv":23266.55}]}
{"op":"mcm","clk":"1149149275","pt":1439919980718,"mc":[{"id":"1.120089104","rc":[{"atl":[[1.21,793.76]],"id":9612932}],"con":true,"img":false,"tv":23266.55}]}
{"op":"mcm","clk":"1149149369","pt":1439919981690,"mc":[{"id":"1.120089104","rc":[{"atl":[[1.24,123.61]],"id":9612932},{"atb":[[5.3,11.62]],"id":9480385}],"con":true,"img":false,"tv":23266.55}]}
{"op":"mcm","clk":"1149149374","pt":1439919981789,"mc":[{"id":"1.120089104","rc":[{"atb":[[6,4.4]],"id":9480385}],"con":true,"img":false,"tv":23266.55}]}
{"op":"mcm","clk":"1149149389","pt":1439919981904,"mc":[{"id":"1.120089104","rc":[{"atl":[[1.24,57.88]],"id":9612932},{"atb":[[5.6,0]],"id":9480385}],"con":true,"img":false,"tv":23266.55}]}
{"op":"mcm","clk":"1149149954","pt":1439919987369,"mc":[{"id":"1.120089104","rc":[{"atb":[[5.6,6.17]],"id":9480385}],"con":true,"img":false,"tv":23266.55}]}
{"op":"mcm","clk":"1149149972","pt":1439919987576,"mc":[{"id":"1.120089104","rc":[{"atb":[[5.3,6]],"id":9480385}],"con":true,"img":false,"tv":23266.55}]}
{"op":"mcm","clk":"1149150528","pt":1439919992807,"mc":[{"id":"1.120089104","rc":[{"atb":[[5.6,9.03]],"id":9480385}],"con":true,"img":false,"tv":23266.55}]}
{"op":"mcm","clk":"1149150552","pt":1439919993126,"mc":[{"id":"1.120089104","rc":[{"atb":[[5.6,2.85]],"id":9480385}],"con":true,"img":false,"tv":23266.55}]}
{"op":"mcm","clk":"1149153533","pt":1439920024516,"mc":[{"id":"1.120089104","rc":[{"atl":[[1.27,1.89]],"id":9612932},{"atb":[[5.1,0]],"id":9480385}],"con":true,"img":false,"tv":23266.55}]}
{"op":"mcm","clk":"1149153552","pt":1439920024633,"mc":[{"id":"1.120089104","rc":[{"atl":[[1.28,195]],"id":9612932},{"atb":[[5.2,161.93]],"id":9480385}],"con":true,"img":false,"tv":23266.55}]}
{"op":"mcm","clk":"1149153816","pt":1439920027566,"mc":[{"id":"1.120089104","rc":[{"atl":[[1.21,448.76]],"id":9612932}],"con":true,"img":false,"tv":23266.55}]}
{"op":"mcm","clk":"1149153828","pt":1439920027674,"mc":[{"id":"1.120089104","rc":[{"atl":[[1.22,345]],"id":9612932}],"con":true,"img":false,"tv":23266.55}]}
{"op":"mcm","clk":"1149158418","pt":1439920082238,"mc":[{"id":"1.120089104","rc":[{"atl":[[1000,9]],"id":9612932},{"trd":[[6.2,58.77]],"ltp":6.2,"tv":58.77,"id":9480385},{"atb":[[1.01,2455.04]],"id":9480385},{"atl":[[6.2,4.51]],"id":9480385},{"spn":5.87,"spf":2.41,"id":9480385}],"con":true,"img":false,"tv":23276.15}]}
{"op":"mcm","clk":"1149158433","pt":1439920082452,"mc":[{"id":"1.120089104","rc":[{"atl":[[1000,11.25]],"id":9612932},{"atb":[[1.01,2457.78]],"id":9480385}],"con":true,"img":false,"tv":23276.15}]}
{"op":"mcm","clk":"1149158441","pt":1439920082564,"mc":[{"id":"1.120089104","rc":[{"atl":[[1000,3.25]],"id":9612932},{"atb":[[1.01,2453.78]],"id":9480385}],"con":true,"img":false,"tv":23276.15}]}
{"op":"mcm","clk":"1149158448","pt":1439920082671,"mc":[{"id":"1.120089104","rc":[{"atl":[[1000,1]],"id":9612932},{"atb":[[1.01,2451.04]],"id":9480385}],"con":true,"img":false,"tv":23276.15}]}
{"op":"mcm","clk":"1149158454","pt":1439920082777,"mc":[{"id":"1.120089104","rc":[{"trd":[[1.19,3359.8]],"ltp":1.19,"tv":3359.8,"id":9612932},{"atb":[[1.19,358.97]],"id":9612932},{"atl":[[1.21,449.58]],"id":9612932},{"atb":[[6,7.14]],"id":9480385}],"con":true,"img":false,"tv":23279.01}]}
{"op":"mcm","clk":"1149158640","pt":1439920085097,"mc":[{"id":"1.120089104","rc":[{"atl":[[1.28,0]],"id":9612932}],"con":true,"img":false,"tv":23279.01}]}
{"op":"mcm","clk":"1149158652","pt":1439920085302,"mc":[{"id":"1.120089104","rc":[{"atl":[[1.27,198.89]],"id":9612932}],"con":true,"img":false,"tv":23279.01}]}
{"op":"mcm","clk":"1149158737","pt":1439920086452,"mc":[{"id":"1.120089104","rc":[{"atl":[[6.8,0]],"id":9480385}],"con":true,"img":false,"tv":23279.01}]}
{"op":"mcm","clk":"1149159127","pt":1439920091490,"mc":[{"id":"1.120089104","rc":[{"atb":[[5.6,4.53]],"id":9480385},{"atl":[[7.2,33.62]],"id":9480385}],"con":true,"img":false,"tv":23279.01}]}
{"op":"mcm","clk":"1149159141","pt":1439920091707,"mc":[{"id":"1.120089104","rc":[{"atb":[[5.6,1.68]],"id":9480385}],"con":true,"img":false,"tv":23279.01}]}
{"op":"mcm","clk":"1149159345","pt":1439920094550,"mc":[{"id":"1.120089104","rc":[{"atb":[[1.12,9095.96]],"id":9612932}],"con":true,"img":false,"tv":23279.01}]}
{"op":"mcm","clk":"1149159395","pt":1439920095145,"mc":[{"id":"1.120089104","rc":[{"atb":[[1.13,548.01]],"id":9612932}],"con":true,"img":false,"tv":23279.01}]}
{"op":"mcm","clk":"1149159666","pt":1439920098959,"mc":[{"id":"1.120089104","rc":[{"atb":[[5.6,0]],"id":9480385}],"con":true,"img":false,"tv":23279.01}]}
{"op":"mcm","clk":"1149160073","pt":1439920103803,"mc":[{"id":"1.120089104","rc":[{"atb":[[5.6,9.42]],"id":9480385}],"con":true,"img":false,"tv":23279.01}]}
{"op":"mcm","clk":"1149160228","pt":1439920105933,"mc":[{"id":"1.120089104","rc":[{"atl":[[1.2,150]],"id":9612932}],"con":true,"img":false,"tv":23279.01}]}
{"op":"mcm","clk":"1149160258","pt":1439920106248,"mc":[{"id":"1.120089104","rc":[{"atb":[[6,3.55]],"id":9480385}],"con":true,"img":false,"tv":23279.01}]}
{"op":"mcm","clk":"1149160496","pt":1439920109508,"mc":[{"id":"1.120089104","rc":[{"atb":[[5.6,11.1]],"id":9480385}],"con":true,"img":false,"tv":23279.01}]}
{"op":"mcm","clk":"1149160510","pt":1439920109719,"mc":[{"id":"1.120089104","rc":[{"atb":[[5.6,1.68]],"id":9480385}],"con":true,"img":false,"tv":23279.01}]}
{"op":"mcm","clk":"1149160917","pt":1439920114942,"mc":[{"id":"1.120089104","rc":[{"atb":[[5.6,15.36]],"id":9480385}],"con":true,"img":false,"tv":23279.01}]}
{"op":"mcm","clk":"1149160931","pt":1439920115159,"mc":[{"id":"1.120089104","rc":[{"atb":[[5.6,13.68]],"id":9480385}],"con":true,"img":false,"tv":23279.01}]}
{"op":"mcm","clk":"1149162718","pt":1439920135967,"mc":[{"id":"1.120089104","rc":[{"atb":[[5.6,39.19]],"id":9480385}],"con":true,"img":false,"tv":23279.01}]}
{"op":"mcm","clk":"1149162733","pt":1439920136181,"mc":[{"id":"1.120089104","rc":[{"atb":[[5.6,25.5]],"id":9480385}],"con":true,"img":false,"tv":23279.01}]}
{"op":"mcm","clk":"1149163528","pt":1439920145782,"mc":[{"id":"1.120089104","rc":[{"atl":[[1.27,1.89]],"id":9612932},{"atl":[[7.8,1.22]],"id":9480385},{"spn":5.84,"spf":2.41,"id":9480385}],"con":true,"img":false,"tv":23279.01}]}
{"op":"mcm","clk":"1149163540","pt":1439920145879,"mc":[{"id":"1.120089104","rc":[{"atl":[[1.25,252]],"id":9612932},{"atl":[[8,37]],"id":9480385}],"con":true,"img":false,"tv":23279.01}]}
{"op":"mcm","clk":"1149180412","pt":1439920231216,"mc":[{"id":"1.120089104","rc":[{"atb":[[1.12,8771.05]],"id":9612932}],"con":true,"img":false,"tv":23279.01}]}
{"op":"mcm","clk":"1149180459","pt":1439920231854,"mc":[{"id":"1.120089104","rc":[{"atb":[[1.13,922.91]],"id":9612932}],"con":true,"img":false,"tv":23279.01}]}
{"op":"mcm","clk":"1149180605","pt":1439920233626,"mc":[{"id":"1.120089104","rc":[{"atb":[[1.12,5609.84]],"id":9612932}],"con":true,"img":false,"tv":23279.01}]}
{"op":"mcm","clk":"1149180634","pt":1439920234055,"mc":[{"id":"1.120089104","rc":[{"atb":[[1.13,4813.62]],"id":9612932}],"con":true,"img":false,"tv":23279.01}]}
{"op":"mcm","clk":"1149180670","pt":1439920234472,"mc":[{"id":"1.120089104","rc":[{"atb":[[5.2,58.71]],"id":9480385}],"con":true,"img":false,"tv":23279.01}]}
{"op":"mcm","clk":"1149180719","pt":1439920235056,"mc":[{"id":"1.120089104","rc":[{"atb":[[5,132.45]],"id":9480385}],"con":true,"img":false,"tv":23279.01}]}
{"op":"mcm","clk":"1149181610","pt":1439920246392,"mc":[{"id":"1.120089104","rc":[{"atb":[[5.1,6]],"id":9480385}],"con":true,"img":false,"tv":23279.01}]}
{"op":"mcm","clk":"1149182370","pt":1439920255359,"mc":[{"id":"1.120089104","rc":[{"atl":[[1.2,650]],"id":9612932}],"con":true,"img":false,"tv":23279.01}]}
{"op":"mcm","clk":"1149182411","pt":1439920255806,"mc":[{"id":"1.120089104","rc":[{"atb":[[1.19,207.71]],"id":9612932},{"atb":[[6,33.55]],"id":9480385}],"con":true,"img":false,"tv":23279.01}]}
{"op":"mcm","clk":"1149182426","pt":1439920256003,"mc":[{"id":"1.120089104","rc":[{"atb":[[6,37.08]],"id":9480385}],"con":true,"img":false,"tv":23279.01}]}
{"op":"mcm","clk":"1149182864","pt":1439920260659,"mc":[{"id":"1.120089104","rc":[{"atl":[[1.24,198.8]],"id":9612932}],"con":true,"img":false,"tv":23279.01}]}
{"op":"mcm","clk":"1149182884","pt":1439920260832,"mc":[{"id":"1.120089104","rc":[{"atl":[[1.24,140.92]],"id":9612932}],"con":true,"img":false,"tv":23279.01}]}
{"op":"mcm","clk":"1149183050","pt":1439920262985,"mc":[{"id":"1.120089104","rc":[{"atb":[[1.19,225.47]],"id":9612932}],"con":true,"img":false,"tv":23279.01}]}
{"op":"mcm","clk":"1149183057","pt":1439920263094,"mc":[{"id":"1.120089104","rc":[{"atb":[[6,40.6]],"id":9480385}],"con":true,"img":false,"tv":23279.01}]}
{"op":"mcm","clk":"1149183334","pt":1439920266103,"mc":[{"id":"1.120089104","rc":[{"atb":[[5.8,5.19]],"id":9480385}],"con":true,"img":false,"tv":23279.01}]}
{"op":"mcm","clk":"1149183351","pt":1439920266324,"mc":[{"id":"1.120089104","rc":[{"atb":[[5.6,0]],"id":9480385}],"con":true,"img":false,"tv":23279.01}]}
{"op":"mcm","clk":"1149185054","pt":1439920285244,"mc":[{"id":"1.120089104","rc":[{"atb":[[1.12,3513.46]],"id":9612932}],"con":true,"img":false,"tv":23279.01}]}
{"op":"mcm","clk":"1149185100","pt":1439920285720,"mc":[{"id":"1.120089104","rc":[{"atb":[[1.13,7393.77]],"id":9612932}],"con":true,"img":false,"tv":23279.01}]}
{"op":"mcm","clk":"1149186261","pt":1439920298399,"mc":[{"id":"1.120089104","rc":[{"atb":[[1.12,3054.73]],"id":9612932},{"spn":1.18,"spf":1.07,"id":9612932},{"spn":6.0,"spf":2.41,"id":9480385}],"con":true,"img":false,"tv":23279.01}]}
{"op":"mcm","clk":"1149186329","pt":1439920298991,"mc":[{"id":"1.120089104","rc":[{"atb":[[1.13,7958.37]],"id":9612932}],"con":true,"img":false,"tv":23279.01}]}
{"op":"mcm","clk":"1149187337","pt":1439920312052,"mc":[{"id":"1.120089104","rc":[{"atb":[[1.19,243.23]],"id":9612932},{"atb":[[6,44.12]],"id":9480385}],"con":true,"img":false,"tv":23279.01}]}
{"op":"mcm","clk":"1149187371","pt":1439920312478,"mc":[{"id":"1.120089104","rc":[{"atb":[[1.01,2475.04]],"id":9612932}],"con":true,"img":false,"tv":23279.01}]}
{"op":"mcm","clk":"1149187376","pt":1439920312586,"mc":[{"id":"1.120089104","rc":[{"atb":[[1.01,2473.34]],"id":9612932}],"con":true,"img":false,"tv":23279.01}]}
{"op":"mcm","clk":"1149187388","pt":1439920312649,"mc":[{"id":"1.120089104","rc":[{"atb":[[1.01,2473.04]],"id":9612932}],"con":true,"img":false,"tv":23279.01}]}
{"op":"mcm","clk":"1149187396","pt":1439920312752,"mc":[{"id":"1.120089104","rc":[{"trd":[[1.2,3087.31]],"ltp":1.2,"tv":3087.31,"id":9612932},{"atl":[[1.2,649.7]],"id":9612932}],"con":true,"img":false,"tv":23279.61}]}
{"op":"mcm","clk":"1149187564","pt":1439920315421,"mc":[{"id":"1.120089104","rc":[{"atb":[[1.12,1256.48]],"id":9612932}],"con":true,"img":false,"tv":23279.61}]}
{"op":"mcm","clk":"1149187583","pt":1439920315589,"mc":[{"id":"1.120089104","rc":[{"atb":[[1.13,10171.61]],"id":9612932}],"con":true,"img":false,"tv":23279.61}]}
{"op":"mcm","clk":"1149194161","pt":1439920408707,"mc":[{"id":"1.120089104","rc":[{"trd":[[1.2,3401.57]],"ltp":1.2,"tv":3401.57,"id":9612932},{"atl":[[1.2,492.57]],"id":9612932},{"spn":1.18,"spf":1.07,"id":9612932}],"con":true,"img":false,"tv":23593.87}]}
{"op":"mcm","clk":"1149198349","pt":1439920467305,"mc":[{"id":"1.120089104","rc":[{"trd":[[1.2,3486.13]],"ltp":1.2,"tv":3486.13,"id":9612932},{"atl":[[1.2,450.29]],"id":9612932}],"con":true,"img":false,"tv":23678.43}]}
{"op":"mcm","clk":"1149199297","pt":1439920479532,"mc":[{"id":"1.120089104","rc":[{"atb":[[1.19,394.49]],"id":9612932},{"spn":1.18,"spf":1.07,"id":9612932},{"atb":[[6,14.12]],"id":9480385}],"con":true,"img":false,"tv":23678.43}]}
{"op":"mcm","clk":"1149199398","pt":1439920481036,"mc":[{"id":"1.120089104","rc":[{"trd":[[1.2,4190.75]],"ltp":1.2,"tv":4190.75,"id":9612932},{"atl":[[1.2,97.98]],"id":9612932}],"con":true,"img":false,"tv":24383.05}]}
{"op":"mcm","clk":"1149199474","pt":1439920482020,"mc":[{"id":"1.120089104","rc":[{"atb":[[6,10.59]],"id":9480385}],"con":true,"img":false,"tv":24383.05}]}
{"op":"mcm","clk":"1149210166","pt":1439920627986,"mc":[{"id":"1.120089104","rc":[{"atl":[[1.2,597.98]],"id":9612932}],"con":true,"img":false,"tv":24383.05}]}
{"op":"mcm","clk":"1149212044","pt":1439920657207,"mc":[{"id":"1.120089104","rc":[{"atb":[[1.19,462.7]],"id":9612932}],"con":true,"img":false,"tv":24383.05}]}
{"op":"mcm","clk":"1149212799","pt":1439920667504,"mc":[{"id":"1.120089104","rc":[{"atb":[[4.9,158.75]],"id":9480385}],"con":true,"img":false,"tv":24383.05}]}
{"op":"mcm","clk":"1149212833","pt":1439920668086,"mc":[{"id":"1.120089104","rc":[{"atb":[[5,151.66]],"id":9480385}],"con":true,"img":false,"tv":24383.05}]}
{"op":"mcm","clk":"1149214452","pt":1439920692470,"mc":[{"id":"1.120089104","rc":[{"trd":[[1.2,4210.75]],"ltp":1.2,"tv":4210.75,"id":9612932},{"atl":[[1.2,587.98]],"id":9612932},{"spn":1.18,"spf":1.07,"id":9612932}],"con":true,"img":false,"tv":24403.05}]}
{"op":"mcm","clk":"1149214729","pt":1439920696597,"mc":[{"id":"1.120089104","rc":[{"trd":[[1.19,3966.76]],"ltp":1.19,"tv":3966.76,"id":9612932},{"atb":[[1.19,159.23]],"id":9612932}],"con":true,"img":false,"tv":25010.01}]}
{"op":"mcm","clk":"1149214801","pt":1439920697601,"mc":[{"id":"1.120089104","rc":[{"atb":[[1.19,68.21]],"id":9612932},{"atb":[[6,40.59]],"id":9480385}],"con":true,"img":false,"tv":25010.01}]}
{"op":"mcm","clk":"1149218044","pt":1439920744964,"mc":[{"id":"1.120089104","rc":[{"trd":[[1.19,3988.98]],"ltp":1.19,"tv":3988.98,"id":9612932},{"atb":[[1.19,57.1]],"id":9612932}],"con":true,"img":false,"tv":25032.23}]}
{"op":"mcm","clk":"1149218298","pt":1439920748818,"mc":[{"id":"1.120089104","rc":[{"atb":[[6,57.47]],"id":9480385}],"con":true,"img":false,"tv":25032.23}]}
{"op":"mcm","clk":"1149218613","pt":1439920753390,"mc":[{"id":"1.120089104","rc":[{"atl":[[1.2,737.98]],"id":9612932},{"spn":1.18,"spf":1.07,"id":9612932}],"con":true,"img":false,"tv":25032.23}]}
{"op":"mcm","clk":"1149219887","pt":1439920771347,"mc":[{"id":"1.120089104","rc":[{"trd":[[1.19,4010.98]],"ltp":1.19,"tv":4010.98,"id":9612932},{"atb":[[1.19,46.1]],"id":9612932}],"con":true,"img":false,"tv":25054.23}]}
{"op":"mcm","clk":"1149220267","pt":1439920776497,"mc":[{"id":"1.120089104","rc":[{"trd":[[1.19,4102.58]],"ltp":1.19,"tv":4102.58,"id":9612932},{"atb":[[1.19,0.3]],"id":9612932}],"con":true,"img":false,"tv":25145.83}]}
{"op":"mcm","clk":"1149220476","pt":1439920779662,"mc":[{"id":"1.120089104","rc":[{"trd":[[6,20.8]],"ltp":6.0,"tv":20.8,"id":9480385},{"atb":[[6,53.95]],"id":9480385}],"con":true,"img":false,"tv":25152.88}]}
{"op":"mcm","clk":"1149222446","pt":1439920807651,"mc":[{"id":"1.120089104","rc":[{"atb":[[1.14,0]],"id":9612932}],"con":true,"img":false,"tv":25152.88}]}
{"op":"mcm","clk":"1149222452","pt":1439920807763,"mc":[{"id":"1.120089104","rc":[{"atb":[[1.13,10392.61]],"id":9612932}],"con":true,"img":false,"tv":25152.88}]}
{"op":"mcm","clk":"1149222706","pt":1439920812616,"mc":[{"id":"1.120089104","rc":[{"atb":[[1.14,45.78]],"id":9612932}],"con":true,"img":false,"tv":25152.88}]}
{"op":"mcm","clk":"1149223312","pt":1439920822528,"mc":[{"id":"1.120089104","rc":[{"atb":[[1.13,6501.9]],"id":9612932},{"spn":1.17,"spf":1.07,"id":9612932}],"con":true,"img":false,"tv":25152.88}]}
{"op":"mcm","clk":"1149223348","pt":1439920823061,"mc":[{"id":"1.120089104","rc":[{"atb":[[1.12,5854.59]],"id":9612932}],"con":true,"img":false,"tv":25152.88}]}
{"op":"mcm","clk":"1149223680","pt":1439920827989,"mc":[{"id":"1.120089104","rc":[{"atb":[[1.13,6127.01]],"id":9612932}],"con":true,"img":false,"tv":25152.88}]}
{"op":"mcm","clk":"1149223721","pt":1439920828631,"mc":[{"id":"1.120089104","rc":[{"atb":[[1.12,6297.65]],"id":9612932}],"con":true,"img":false,"tv":25152.88}]}
{"op":"mcm","clk":"1149223773","pt":1439920829333,"mc":[{"id":"1.120089104","rc":[{"atb":[[5.2,48]],"id":9480385}],"con":true,"img":false,"tv":25152.88}]}
{"op":"mcm","clk":"1149223818","pt":1439920830018,"mc":[{"id":"1.120089104","rc":[{"atb":[[5,164.95]],"id":9480385}],"con":true,"img":false,"tv":25152.88}]}
{"op":"mcm","clk":"1149224235","pt":1439920835725,"mc":[{"id":"1.120089104","rc":[{"atb":[[5.3,0]],"id":9480385}],"con":true,"img":false,"tv":25152.88}]}
{"op":"mcm","clk":"1149225301","pt":1439920851255,"mc":[{"id":"1.120089104","rc":[{"atb":[[1.13,5584.99]],"id":9612932}],"con":true,"img":false,"tv":25152.88}]}
{"op":"mcm","clk":"1149225318","pt":1439920851526,"mc":[{"id":"1.120089104","rc":[{"atb":[[1.12,6938.21]],"id":9612932}],"con":true,"img":false,"tv":25152.88}]}
{"op":"mcm","clk":"1149226017","pt":1439920861677,"mc":[{"id":"1.120089104","rc":[{"atb":[[1.19,77.3]],"id":9612932}],"con":true,"img":false,"tv":25152.88}]}
{"op":"mcm","clk":"1149226370","pt":1439920865885,"mc":[{"id":"1.120089104","rc":[{"atb":[[4.9,79.36]],"id":9480385}],"con":true,"img":false,"tv":25152.88}]}
{"op":"mcm","clk":"1149226414","pt":1439920866423,"mc":[{"id":"1.120089104","rc":[{"atb":[[5,256.43]],"id":9480385}],"con":true,"img":false,"tv":25152.88}]}
{"op":"mcm","clk":"1149227088","pt":1439920875270,"mc":[{"id":"1.120089104","rc":[{"atb":[[1.19,228.56]],"id":9612932}],"con":true,"img":false,"tv":25152.88}]}
{"op":"mcm","clk":"1149227363","pt":1439920878674,"mc":[{"id":"1.120089104","rc":[{"atb":[[4.9,16.12]],"id":9480385}],"con":true,"img":false,"tv":25152.88}]}
{"op":"mcm","clk":"1149227372","pt":1439920878838,"mc":[{"id":"1.120089104","rc":[{"atb":[[5,334.89]],"id":9480385}],"con":true,"img":false,"tv":25152.88}]}
{"op":"mcm","clk":"1149227476","pt":1439920880038,"mc":[{"id":"1.120089104","rc":[{"trd":[[1.19,4107.38]],"ltp":1.19,"tv":4107.38,"id":9612932},{"atb":[[1.19,226.16]],"id":9612932}],"con":true,"img":false,"tv":25157.68}]}
{"op":"mcm","clk":"1149227856","pt":1439920884938,"mc":[{"id":"1.120089104","rc":[{"spn":1.18,"spf":1.07,"id":9612932},{"atb":[[5,328.89]],"id":9480385}],"con":true,"img":false,"tv":25157.68}]}
{"op":"mcm","clk":"1149228180","pt":1439920890159,"mc":[{"id":"1.120089104","rc":[{"atb":[[4.9,0]],"id":9480385}],"con":true,"img":false,"tv":25157.68}]}
{"op":"mcm","clk":"1149228233","pt":1439920890772,"mc":[{"id":"1.120089104","rc":[{"atb":[[5,348.91]],"id":9480385}],"con":true,"img":false,"tv":25157.68}]}
{"op":"mcm","clk":"1149228673","pt":1439920895340,"mc":[{"id":"1.120089104","rc":[{"atl":[[1.2,587.98]],"id":9612932}],"con":true,"img":false,"tv":25157.68}]}
{"op":"mcm","clk":"1149230860","pt":1439920928324,"mc":[{"id":"1.120089104","rc":[{"atb":[[1.13,5363.99]],"id":9612932}],"con":true,"img":false,"tv":25157.68}]}
{"op":"mcm","clk":"1149230874","pt":1439920928440,"mc":[{"id":"1.120089104","rc":[{"atb":[[1.14,264.78]],"id":9612932}],"con":true,"img":false,"tv":25157.68}]}
{"op":"mcm","clk":"1149234031","pt":1439920969992,"mc":[{"id":"1.120089104","rc":[{"trd":[[1.19,4167.38]],"ltp":1.19,"tv":4167.38,"id":9612932},{"atb":[[1.19,196.16]],"id":9612932},{"spn":1.18,"spf":1.07,"id":9612932}],"con":true,"img":false,"tv":25217.68}]}
{"op":"mcm","clk":"1149236340","pt":1439921002112,"mc":[{"id":"1.120089104","rc":[{"atl":[[1.45,1.4]],"id":9612932}],"con":true,"img":false,"tv":25217.68}]}
{"op":"mcm","clk":"1149237703","pt":1439921019727,"mc":[{"id":"1.120089104","rc":[{"atb":[[1.19,245.48]],"id":9612932}],"con":true,"img":false,"tv":25217.68}]}
{"op":"mcm","clk":"1149239196","pt":1439921040621,"mc":[{"id":"1.120089104","rc":[{"trd":[[1.19,4658.35]],"ltp":1.19,"tv":4658.35,"id":9612932},{"atb":[[1.19,0]],"id":9612932},{"atl":[[1.19,354.52]],"id":9612932},{"spn":1.17,"spf":1.07,"id":9612932}],"con":true,"img":false,"tv":25708.64}]}
{"op":"mcm","clk":"1149239210","pt":1439921040842,"mc":[{"id":"1.120089104","rc":[{"trd":[[1.19,4705.35]],"ltp":1.19,"tv":4705.35,"id":9612932},{"atl":[[1.19,331.02]],"id":9612932},{"trd":[[6.2,67.79]],"ltp":6.2,"tv":67.79,"id":9480385},{"atl":[[6.2,0]],"id":9480385}],"con":true,"img":false,"tv":25764.66}]}
{"op":"mcm","clk":"1149239247","pt":1439921041328,"mc":[{"id":"1.120089104","rc":[{"atb":[[1.18,825.79]],"id":9612932},{"atl":[[6.2,0]],"id":9480385}],"con":true,"img":false,"tv":25764.66}]}
{"op":"mcm","clk":"1149239426","pt":1439921043465,"mc":[{"id":"1.120089104","rc":[{"atl":[[1.19,355.02]],"id":9612932}],"con":true,"img":false,"tv":25764.66}]}
{"op":"mcm","clk":"1149239502","pt":1439921044406,"mc":[{"id":"1.120089104","rc":[{"atb":[[1.18,843.71]],"id":9612932}],"con":true,"img":false,"tv":25764.66}]}
{"op":"mcm","clk":"1149239525","pt":1439921044578,"mc":[{"id":"1.120089104","rc":[{"atb":[[6.2,3.41]],"id":9480385}],"con":true,"img":false,"tv":25764.66}]}
{"op":"mcm","clk":"1149239854","pt":1439921048839,"mc":[{"id":"1.120089104","rc":[{"atl":[[1.24,201.94]],"id":9612932}],"con":true,"img":false,"tv":25764.66}]}
{"op":"mcm","clk":"1149239869","pt":1439921049002,"mc":[{"id":"1.120089104","rc":[{"atl":[[1.24,61.02]],"id":9612932}],"con":true,"img":false,"tv":25764.66}]}
{"op":"mcm","clk":"1149239943","pt":1439921049924,"mc":[{"id":"1.120089104","rc":[{"atb":[[1.13,3150.75]],"id":9612932}],"con":true,"img":false,"tv":25764.66}]}
{"op":"mcm","clk":"1149239962","pt":1439921050145,"mc":[{"id":"1.120089104","rc":[{"atb":[[1.12,9553.86]],"id":9612932}],"con":true,"img":false,"tv":25764.66}]}
{"op":"mcm","clk":"1149240113","pt":1439921051772,"mc":[{"id":"1.120089104","rc":[{"atb":[[6.2,32.44]],"id":9480385}],"con":true,"img":false,"tv":25764.66}]}
{"op":"mcm","clk":"1149240545","pt":1439921057195,"mc":[{"id":"1.120089104","rc":[{"atb":[[1.13,570.59]],"id":9612932}],"con":true,"img":false,"tv":25764.66}]}
{"op":"mcm","clk":"1149240581","pt":1439921057623,"mc":[{"id":"1.120089104","rc":[{"atb":[[1.12,12603.14]],"id":9612932}],"con":true,"img":false,"tv":25764.66}]}
{"op":"mcm","clk":"1149240971","pt":1439921062580,"mc":[{"id":"1.120089104","rc":[{"atb":[[1.18,691.17]],"id":9612932}],"con":true,"img":false,"tv":25764.66}]}
{"op":"mcm","clk":"1149250894","pt":1439921069100,"mc":[{"id":"1.120089104","rc":[{"atb":[[6,103.95]],"id":9480385}],"con":true,"img":false,"tv":25764.66}]}
{"op":"mcm","clk":"1149251956","pt":1439921081551,"mc":[{"id":"1.120089104","rc":[{"atl":[[1.2,608.38]],"id":9612932}],"con":true,"img":false,"tv":25764.66}]}
{"op":"mcm","clk":"1149252284","pt":1439921086303,"mc":[{"id":"1.120089104","rc":[{"atb":[[1.13,6]],"id":9612932}],"con":true,"img":false,"tv":25764.66}]}
{"op":"mcm","clk":"1149252331","pt":1439921086992,"mc":[{"id":"1.120089104","rc":[{"atb":[[1.12,13270.39]],"id":9612932}],"con":true,"img":false,"tv":25764.66}]}
{"op":"mcm","clk":"1149254127","pt":1439921109112,"mc":[{"id":"1.120089104","rc":[{"atb":[[1.14,45.78]],"id":9612932},{"atl":[[1.25,52]],"id":9612932},{"spn":1.17,"spf":1.07,"id":9612932},{"atb":[[5.2,0]],"id":9480385},{"atl":[[8,6]],"id":9480385},{"spn":6.2,"spf":2.41,"id":9480385}],"con":true,"img":false,"tv":25764.66}]}
{"op":"mcm","clk":"1149254130","pt":1439921109210,"mc":[{"id":"1.120089104","rc":[{"atb":[[1.13,227]],"id":9612932},{"atl":[[1.24,263.02]],"id":9612932},{"atb":[[5.3,47]],"id":9480385},{"atl":[[8.2,280]],"id":9480385}],"con":true,"img":false,"tv":25764.66}]}
{"op":"mcm","clk":"1149257773","pt":1439921151757,"mc":[{"id":"1.120089104","rc":[{"atl":[[1.19,331.02]],"id":9612932}],"con":true,"img":false,"tv":25764.66}]}
{"op":"mcm","clk":"1149257783","pt":1439921151858,"mc":[{"id":"1.120089104","rc":[{"trd":[[1.18,5068.84]],"ltp":1.18,"tv":5068.84,"id":9612932},{"atb":[[1.18,667.17]],"id":9612932}],"con":true,"img":false,"tv":25812.66}]}
{"op":"mcm","clk":"1149263049","pt":1439921216811,"mc":[{"id":"1.120089104","rc":[{"spn":1.17,"spf":1.07,"id":9612932},{"trd":[[6.6,25.99],[6.4,46.9]],"ltp":6.6,"tv":72.89,"id":9480385},{"atl":[[6.4,0],[6.6,27.08]],"id":9480385}],"con":true,"img":false,"tv":25816.66}]}
{"op":"mcm","clk":"1149263155","pt":1439921217785,"mc":[{"id":"1.120089104","rc":[{"atl":[[6.6,0]],"id":9480385}],"con":true,"img":false,"tv":25816.66}]}
{"op":"mcm","clk":"1149263186","pt":1439921218202,"mc":[{"id":"1.120089104","rc":[{"atl":[[6.8,57.87]],"id":9480385}],"con":true,"img":false,"tv":25816.66}]}
{"op":"mcm","clk":"1149263344","pt":1439921219822,"mc":[{"id":"1.120089104","rc":[{"atb":[[6.6,2]],"id":9480385}],"con":true,"img":false,"tv":25816.66}]}
{"op":"mcm","clk":"1149263367","pt":1439921220147,"mc":[{"id":"1.120089104","rc":[{"trd":[[1.18,5091.22]],"ltp":1.18,"tv":5091.22,"id":9612932},{"atb":[[1.18,655.98]],"id":9612932},{"trd":[[6.6,29.99]],"ltp":6.6,"tv":29.99,"id":9480385},{"atb":[[6.6,0]],"id":9480385}],"con":true,"img":false,"tv":25843.04}]}
{"op":"mcm","clk":"1149263534","pt":1439921221864,"mc":[{"id":"1.120089104","rc":[{"atl":[[7.2,7.22]],"id":9480385}],"con":true,"img":false,"tv":25843.04}]}
{"op":"mcm","clk":"1149263629","pt":1439921222868,"mc":[{"id":"1.120089104","rc":[{"atb":[[6.4,2]],"id":9480385}],"con":true,"img":false,"tv":25843.04}]}
{"op":"mcm","clk":"1149263645","pt":1439921223185,"mc":[{"id":"1.120089104","rc":[{"atb":[[5,270.44]],"id":9480385}],"con":true,"img":false,"tv":25843.04}]}
{"op":"mcm","clk":"1149263664","pt":1439921223320,"mc":[{"id":"1.120089104","rc":[{"atb":[[5.3,125.46]],"id":9480385}],"con":true,"img":false,"tv":25843.04}]}
{"op":"mcm","clk":"1149263771","pt":1439921224578,"mc":[{"id":"1.120089104","rc":[{"atb":[[5.1,0]],"id":9480385}],"con":true,"img":false,"tv":25843.04}]}
{"op":"mcm","clk":"1149263778","pt":1439921224684,"mc":[{"id":"1.120089104","rc":[{"atb":[[5.4,6]],"id":9480385}],"con":true,"img":false,"tv":25843.04}]}
{"op":"mcm","clk":"1149264062","pt":1439921227680,"mc":[{"id":"1.120089104","rc":[{"atl":[[7.8,39.91]],"id":9480385}],"con":true,"img":false,"tv":25843.04}]}
{"op":"mcm","clk":"1149264150","pt":1439921228687,"mc":[{"id":"1.120089104","rc":[{"atb":[[1.18,808.52]],"id":9612932},{"atl":[[6.6,27.27]],"id":9480385}],"con":true,"img":false,"tv":25843.04}]}
{"op":"mcm","clk":"1149264203","pt":1439921229324,"mc":[{"id":"1.120089104","rc":[{"atl":[[6.8,0]],"id":9480385}],"con":true,"img":false,"tv":25843.04}]}
{"op":"mcm","clk":"1149264305","pt":1439921230444,"mc":[{"id":"1.120089104","rc":[{"atb":[[6.4,0]],"id":9480385}],"con":true,"img":false,"tv":25843.04}]}
{"op":"mcm","clk":"1149264559","pt":1439921233544,"mc":[{"id":"1.120089104","rc":[{"atb":[[5.1,6]],"id":9480385}],"con":true,"img":false,"tv":25843.04}]}
{"op":"mcm","clk":"1149264587","pt":1439921234074,"mc":[{"id":"1.120089104","rc":[{"atl":[[7.2,34.51]],"id":9480385}],"con":true,"img":false,"tv":25843.04}]}
{"op":"mcm","clk":"1149264623","pt":1439921234554,"mc":[{"id":"1.120089104","rc":[{"atl":[[7.8,1.22]],"id":9480385}],"con":true,"img":false,"tv":25843.04}]}
{"op":"mcm","clk":"1149264988","pt":1439921239723,"mc":[{"id":"1.120089104","rc":[{"atl":[[6.6,0]],"id":9480385}],"con":true,"img":false,"tv":25843.04}]}
{"op":"mcm","clk":"1149265012","pt":1439921240041,"mc":[{"id":"1.120089104","rc":[{"atl":[[6.8,70.12]],"id":9480385}],"con":true,"img":false,"tv":25843.04}]}
{"op":"mcm","clk":"1149265087","pt":1439921241114,"mc":[{"id":"1.120089104","rc":[{"atb":[[6,87.07]],"id":9480385}],"con":true,"img":false,"tv":25843.04}]}
{"op":"mcm","clk":"1149265093","pt":1439921241216,"mc":[{"id":"1.120089104","rc":[{"atb":[[6.2,49.31]],"id":9480385}],"con":true,"img":false,"tv":25843.04}]}
{"op":"mcm","clk":"1149265382","pt":1439921244796,"mc":[{"id":"1.120089104","rc":[{"atl":[[7.2,7.22]],"id":9480385}],"con":true,"img":false,"tv":25843.04}]}
{"op":"mcm","clk":"1149265797","pt":1439921249728,"mc":[{"id":"1.120089104","rc":[{"atl":[[7.8,39.91]],"id":9480385}],"con":true,"img":false,"tv":25843.04}]}
{"op":"mcm","clk":"1149265904","pt":1439921251082,"mc":[{"id":"1.120089104","rc":[{"atl":[[6.6,27.27]],"id":9480385}],"con":true,"img":false,"tv":25843.04}]}
{"op":"mcm","clk":"1149265958","pt":1439921251827,"mc":[{"id":"1.120089104","rc":[{"atl":[[6.8,0]],"id":9480385}],"con":true,"img":false,"tv":25843.04}]}
{"op":"mcm","clk":"1149266292","pt":1439921255353,"mc":[{"id":"1.120089104","rc":[{"atl":[[7.2,34.51]],"id":9480385}],"con":true,"img":false,"tv":25843.04}]}
{"op":"mcm","clk":"1149266309","pt":1439921255564,"mc":[{"id":"1.120089104","rc":[{"atl":[[7.8,1.22]],"id":9480385}],"con":true,"img":false,"tv":25843.04}]}
{"op":"mcm","clk":"1149266861","pt":1439921262872,"mc":[{"id":"1.120089104","rc":[{"atl":[[6.6,0]],"id":9480385}],"con":true,"img":false,"tv":25843.04}]}
{"op":"mcm","clk":"1149266923","pt":1439921263681,"mc":[{"id":"1.120089104","rc":[{"atl":[[6.8,70.12]],"id":9480385}],"con":true,"img":false,"tv":25843.04}]}
{"op":"mcm","clk":"1149266994","pt":1439921264762,"mc":[{"id":"1.120089104","rc":[{"atb":[[5.9,2]],"id":9480385}],"con":true,"img":false,"tv":25843.04}]}
{"op":"mcm","clk":"1149267081","pt":1439921265885,"mc":[{"id":"1.120089104","rc":[{"atb":[[5.9,0]],"id":9480385}],"con":true,"img":false,"tv":25843.04}]}
{"op":"mcm","clk":"1149267091","pt":1439921265994,"mc":[{"id":"1.120089104","rc":[{"atl":[[7.2,7.22]],"id":9480385}],"con":true,"img":false,"tv":25843.04}]}
{"op":"mcm","clk":"1149267315","pt":1439921269111,"mc":[{"id":"1.120089104","rc":[{"atl":[[6.8,72.12]],"id":9480385}],"con":true,"img":false,"tv":25843.04}]}
{"op":"mcm","clk":"1149267480","pt":1439921271471,"mc":[{"id":"1.120089104","rc":[{"atl":[[7.8,35.09]],"id":9480385}],"con":true,"img":false,"tv":25843.04}]}
{"op":"mcm","clk":"1149267542","pt":1439921272383,"mc":[{"id":"1.120089104","rc":[{"atl":[[6.8,70.12]],"id":9480385}],"con":true,"img":false,"tv":25843.04}]}
{"op":"mcm","clk":"1149267761","pt":1439921275068,"mc":[{"id":"1.120089104","rc":[{"atl":[[6.6,27.27]],"id":9480385}],"con":true,"img":false,"tv":25843.04}]}
{"op":"mcm","clk":"1149267807","pt":1439921275609,"mc":[{"id":"1.120089104","rc":[{"atl":[[6.8,0]],"id":9480385}],"con":true,"img":false,"tv":25843.04}]}
{"op":"mcm","clk":"1149268091","pt":1439921278818,"mc":[{"id":"1.120089104","rc":[{"spn":1.18,"spf":1.07,"id":9612932},{"atl":[[7.2,26.11]],"id":9480385}],"con":true,"img":false,"tv":25843.04}]}
{"op":"mcm","clk":"1149268113","pt":1439921279039,"mc":[{"id":"1.120089104","rc":[{"atl":[[7.8,1.22]],"id":9480385}],"con":true,"img":false,"tv":25843.04}]}
{"op":"mcm","clk":"1149268756","pt":1439921286238,"mc":[{"id":"1.120089104","rc":[{"atl":[[6.6,0]],"id":9480385}],"con":true,"img":false,"tv":25843.04}]}
{"op":"mcm","clk":"1149268809","pt":1439921287139,"mc":[{"id":"1.120089104","rc":[{"atl":[[6.8,70.12]],"id":9480385}],"con":true,"img":false,"tv":25843.04}]}
{"op":"mcm","clk":"1149268863","pt":1439921287840,"mc":[{"id":"1.120089104","rc":[{"atl":[[5.2,0]],"id":9612932}],"con":true,"img":false,"tv":25843.04}]}
{"op":"mcm","clk":"1149269048","pt":1439921290191,"mc":[{"id":"1.120089104","rc":[{"atl":[[7.2,7.22]],"id":9480385}],"con":true,"img":false,"tv":25843.04}]}
{"op":"mcm","clk":"1149269180","pt":1439921291783,"mc":[{"id":"1.120089104","rc":[{"atl":[[5.2,15]],"id":9612932}],"con":true,"img":false,"tv":25843.04}]}
{"op":"mcm","clk":"1149269624","pt":1439921297652,"mc":[{"id":"1.120089104","rc":[{"atl":[[7.8,39.91]],"id":9480385}],"con":true,"img":false,"tv":25843.04}]}
{"op":"mcm","clk":"1149269638","pt":1439921297868,"mc":[{"id":"1.120089104","rc":[{"atl":[[6.6,27.27]],"id":9480385}],"con":true,"img":false,"tv":25843.04}]}
{"op":"mcm","clk":"1149269669","pt":1439921298242,"mc":[{"id":"1.120089104","rc":[{"atl":[[6.8,0]],"id":9480385}],"con":true,"img":false,"tv":25843.04}]}
{"op":"mcm","clk":"1149270004","pt":1439921302970,"mc":[{"id":"1.120089104","rc":[{"atl":[[7.2,34.51]],"id":9480385}],"con":true,"img":false,"tv":25843.04}]}
{"op":"mcm","clk":"1149270027","pt":1439921303289,"mc":[{"id":"1.120089104","rc":[{"atl":[[7.8,1.22]],"id":9480385}],"con":true,"img":false,"tv":25843.04}]}
{"op":"mcm","clk":"1149270598","pt":1439921310037,"mc":[{"id":"1.120089104","rc":[{"atl":[[6.6,0]],"id":9480385}],"con":true,"img":false,"tv":25843.04}]}
{"op":"mcm","clk":"1149270659","pt":1439921310749,"mc":[{"id":"1.120089104","rc":[{"atl":[[6.8,70.12]],"id":9480385}],"con":true,"img":false,"tv":25843.04}]}
{"op":"mcm","clk":"1149270874","pt":1439921313604,"mc":[{"id":"1.120089104","rc":[{"atl":[[7.2,7.22]],"id":9480385}],"con":true,"img":false,"tv":25843.04}]}
{"op":"mcm","clk":"1149271571","pt":1439921322569,"mc":[{"id":"1.120089104","rc":[{"atl":[[7.8,39.91]],"id":9480385}],"con":true,"img":false,"tv":25843.04}]}
{"op":"mcm","clk":"1149271581","pt":1439921322675,"mc":[{"id":"1.120089104","rc":[{"atl":[[6.6,27.27]],"id":9480385}],"con":true,"img":false,"tv":25843.04}]}
{"op":"mcm","clk":"1149271616","pt":1439921323066,"mc":[{"id":"1.120089104","rc":[{"atl":[[6.8,0]],"id":9480385}],"con":true,"img":false,"tv":25843.04}]}
{"op":"mcm","clk":"1149271812","pt":1439921325251,"mc":[{"id":"1.120089104","rc":[{"atl":[[7.2,26.11]],"id":9480385}],"con":true,"img":false,"tv":25843.04}]}
{"op":"mcm","clk":"1149271825","pt":1439921325468,"mc":[{"id":"1.120089104","rc":[{"atl":[[7.8,1.22]],"id":9480385}],"con":true,"img":false,"tv":25843.04}]}
{"op":"mcm","clk":"1149272557","pt":1439921334942,"mc":[{"id":"1.120089104","rc":[{"atl":[[6.4,17.81]],"id":9480385}],"con":true,"img":false,"tv":25843.04}]}
