{"op":"mcm","clk":"1147750522","pt":1439895864835,"mc":[{"id":"1.120089104","marketDefinition":{"bspMarket":true,"turnInPlayEnabled":true,"persistenceEnabled":true,"marketBaseRate":5.0,"eventId":"27514783","eventTypeId":"7","numberOfWinners":1,"bettingType":"ODDS","marketType":"WIN","marketTime":"2015-08-18T20:20:00.000Z","suspendTime":"2015-08-18T20:20:00.000Z","bspReconciled":false,"complete":true,"inPlay":false,"crossMatching":false,"runnersVoidable":false,"numberOfActiveRunners":2,"betDelay":0,"status":"OPEN","runners":[{"adjustmentFactor":79.72,"status":"ACTIVE","sortPriority":1,"id":9612932,"name":"Alinstante"},{"adjustmentFactor":20.27,"status":"ACTIVE","sortPriority":2,"id":9480385,"name":"Vallance Road"}],"regulators":["MR_NJ","MR_INT"],"venue":"Chelmsford City","countryCode":"GB","discountAllowed":true,"timezone":"Europe/London","openDate":"2015-08-18T17:20:00.000Z","version":1061399117,"name":"1m Cond Stks","eventName":"ChelmC 18th Aug"},"rc":[{"trd":[[1.19,86.48],[1.3,209.75],[1.29,101.62],[1.17,234.58],[1.16,719.22],[1.18,559.88],[1.4,49.38],[1.28,997.42],[1.27,15.74],[1.15,26],[1.25,309.22],[1.26,83.08],[1.23,550.77],[1.22,1521.77],[1.24,1191.1],[1.2,633.55],[1.21,1098.01]],"ltp":1.19,"tv":8387.57,"id":9612932},{"atb":[[1.17,103.54],[1.16,563],[1.06,20],[1.14,56.53],[1.01,1991.52],[1.13,25],[1.15,177.29],[1.03,18],[1.02,10250],[1.12,1251.03],[1.1,4706.21],[1.08,10],[1.11,6]],"id":9612932},{"spb":[[1000,10]],"id":9612932},{"atl":[[1.29,52.77],[1.3,95.06],[19.5,11],[630,0.09],[1.4,500],[1000,1],[1.27,143.23],[1.25,226.02],[1.26,541.34],[1.23,6],[5.2,15],[1.22,10],[1.69,15],[46,2],[1.35,10],[1.24,500],[1.2,120.28],[1.19,50.38],[1.46,2.34],[4,0.25],[540,0.07],[1.21,12.76],[900,0.2]],"id":9612932},{"spl":[[7,10],[1.88,20.11],[1.01,835.41],[1.25,2]],"id":9612932},{"spn":1.15,"spf":1.01,"id":9612932},{"trd":[[6.4,19.82],[4.9,11.97],[5.4,38.19],[5.9,3.78],[4.8,120.46],[5.3,25.25],[5.8,0.16],[5.7,1.03],[6,0.15],[5.2,35.57],[4.7,103.47],[5.1,136.79],[5.6,77.39],[5.5,33.21],[5,331.36],[6.2,6]],"ltp":6.4,"tv":944.6,"id":9480385},{"atb":[[1.43,1250],[2.6,1.9],[4.9,108.53],[1.06,20],[1.18,30],[1.81,12.35],[1.01,1725.18],[4.8,96.3],[1.02,10250],[1.03,18],[5.8,3.98],[3.4,2.34],[5.2,3],[6,8.42],[2.16,30],[1.08,10],[4.7,13.7],[5.1,12.48],[2.92,258.33],[5.6,5.17],[5.5,26.99],[4.6,0.11],[5,197.76]],"id":9480385},{"atl":[[14,15],[7.8,1.22],[630,0.09],[6.4,0.32],[9.2,2.34],[70,2],[7.6,1.41],[46,2],[55,0.01],[6.6,0.06],[90,2],[8.6,13.04],[540,0.07],[900,0.2]],"id":9480385},{"spl":[[7,10]],"id":9480385},{"spn":6.2,"spf":1.0,"id":9480385}],"con":true,"img":true,"tv":9332.29}]}
{"op":"mcm","clk":"1147757027","pt":1439895948024,"mc":[{"id":"1.120089104","rc":[{"spn":1.15,"spf":1.01,"id":9612932},{"atl":[[7.8,7.22]],"id":9480385}],"con":true,"img":false,"tv":9332.29}]}
{"op":"mcm","clk":"1147757652","pt":1439895982837,"mc":[{"id":"1.120089104","rc":[{"trd":[[1.19,106.84]],"ltp":1.19,"tv":106.84,"id":9612932},{"atl":[[1.19,40.21]],"id":9612932}],"con":true,"img":false,"tv":9352.65}]}
{"op":"mcm","clk":"1147760781","pt":1439896148113,"mc":[{"id":"1.120089104","rc":[{"atl":[[7.8,1.22]],"id":9480385}],"con":true,"img":false,"tv":9352.65}]}
{"op":"mcm","clk":"1147765073","pt":1439896332328,"mc":[{"id":"1.120089104","rc":[{"atl":[[7.8,7.22]],"id":9480385}],"con":true,"img":false,"tv":9352.65}]}
{"op":"mcm","clk":"1147769360","pt":1439896532514,"mc":[{"id":"1.120089104","rc":[{"atl":[[7.8,1.22]],"id":9480385}],"con":true,"img":false,"tv":9352.65}]}
{"op":"mcm","clk":"1147774141","pt":1439896710207,"mc":[{"id":"1.120089104","rc":[{"atl":[[1.35,0]],"id":9612932}],"con":true,"img":false,"tv":9352.65}]}
{"op":"mcm","clk":"1147774144","pt":1439896710313,"mc":[{"id":"1.120089104","rc":[{"atl":[[1.19,50.21]],"id":9612932}],"con":true,"img":false,"tv":9352.65}]}
{"op":"mcm","clk":"1147774684","pt":1439896733959,"mc":[{"id":"1.120089104","rc":[{"atl":[[7.8,7.22]],"id":9480385}],"con":true,"img":false,"tv":9352.65}]}
{"op":"mcm","clk":"1147783743","pt":1439896786599,"mc":[{"id":"1.120089104","rc":[{"atb":[[1.17,203.54]],"id":9612932},{"spn":1.16,"spf":1.01,"id":9612932}],"con":true,"img":false,"tv":9352.65}]}
{"op":"mcm","clk":"1147783762","pt":1439896787501,"mc":[{"id":"1.120089104","rc":[{"atl":[[1.19,10]],"id":9612932},{"atl":[[6.4,1.73]],"id":9480385}],"con":true,"img":false,"tv":9352.65}]}
{"op":"mcm","clk":"1147783957","pt":1439896793177,"mc":[{"id":"1.120089104","rc":[{"trd":[[1.19,126.84]],"ltp":1.19,"tv":126.84,"id":9612932},{"atl":[[1.19,0]],"id":9612932}],"con":true,"img":false,"tv":9372.65}]}
{"op":"mcm","clk":"1147783991","pt":1439896794233,"mc":[{"id":"1.120089104","rc":[{"atb":[[5.5,56.99]],"id":9480385}],"con":true,"img":false,"tv":9372.65}]}
{"op":"mcm","clk":"1147784224","pt":1439896805863,"mc":[{"id":"1.120089104","rc":[{"atl":[[7.6,0]],"id":9480385}],"con":true,"img":false,"tv":9372.65}]}
{"op":"mcm","clk":"1147784506","pt":1439896815849,"mc":[{"id":"1.120089104","rc":[{"atl":[[7.8,16.73]],"id":9480385}],"con":true,"img":false,"tv":9372.65}]}
{"op":"mcm","clk":"1147784515","pt":1439896816113,"mc":[{"id":"1.120089104","rc":[{"atl":[[8.6,0]],"id":9480385}],"con":true,"img":false,"tv":9372.65}]}
{"op":"mcm","clk":"1147786414","pt":1439896905158,"mc":[{"id":"1.120089104","rc":[{"atb":[[1.14,0]],"id":9612932},{"atl":[[1.29,0]],"id":9612932},{"atb":[[5.6,1.42]],"id":9480385},{"atl":[[7.8,7.22]],"id":9480385}],"con":true,"img":false,"tv":9372.65}]}
{"op":"mcm","clk":"1147786755","pt":1439896919493,"mc":[{"id":"1.120089104","rc":[{"atb":[[1.14,56.53]],"id":9612932},{"atb":[[5.6,15.85]],"id":9480385}],"con":true,"img":false,"tv":9372.65}]}
{"op":"mcm","clk":"1147787080","pt":1439896934011,"mc":[{"id":"1.120089104","rc":[{"atl":[[7.8,1.22]],"id":9480385}],"con":true,"img":false,"tv":9372.65}]}
{"op":"mcm","clk":"1147787676","pt":1439896957713,"mc":[{"id":"1.120089104","rc":[{"atl":[[1.25,276.02]],"id":9612932}],"con":true,"img":false,"tv":9372.65}]}
{"op":"mcm","clk":"1147788194","pt":1439896981377,"mc":[{"id":"1.120089104","rc":[{"atl":[[7,5]],"id":9480385}],"con":true,"img":false,"tv":9372.65}]}
{"op":"mcm","clk":"1147788210","pt":1439896981913,"mc":[{"id":"1.120089104","rc":[{"trd":[[7,1.92],[6.4,23.28],[6.6,0.12]],"ltp":7.0,"tv":25.32,"id":9480385},{"atb":[[1.01,1729.18]],"id":9480385},{"atl":[[6.6,0],[7,4.04],[6.4,0]],"id":9480385}],"con":true,"img":false,"tv":9378.16}]}
{"op":"mcm","clk":"1147788211","pt":1439896982123,"mc":[{"id":"1.120089104","rc":[{"atb":[[1.01,1726.97]],"id":9480385}],"con":true,"img":false,"tv":9378.16}]}
{"op":"mcm","clk":"1147788217","pt":1439896982235,"mc":[{"id":"1.120089104","rc":[{"atb":[[1.01,1725.18]],"id":9480385}],"con":true,"img":false,"tv":9378.16}]}
{"op":"mcm","clk":"1147788222","pt":1439896982336,"mc":[{"id":"1.120089104","rc":[{"atb":[[6.4,1.73],[6.6,0.06]],"id":9480385}],"con":true,"img":false,"tv":9378.16}]}
{"op":"mcm","clk":"1147788233","pt":1439896982505,"mc":[{"id":"1.120089104","rc":[{"atb":[[6.4,0],[6.6,0]],"id":9480385}],"con":true,"img":false,"tv":9378.16}]}
{"op":"mcm","clk":"1147788305","pt":1439896985972,"mc":[{"id":"1.120089104","rc":[{"atl":[[9,15.07]],"id":9480385}],"con":true,"img":false,"tv":9378.16}]}
{"op":"mcm","clk":"1147788321","pt":1439896986864,"mc":[{"id":"1.120089104","rc":[{"atl":[[7,6.06]],"id":9480385}],"con":true,"img":false,"tv":9378.16}]}
{"op":"mcm","clk":"1147788715","pt":1439897002602,"mc":[{"id":"1.120089104","rc":[{"atl":[[6.8,2.55]],"id":9480385}],"con":true,"img":false,"tv":9378.16}]}
{"op":"mcm","clk":"1147788743","pt":1439897003445,"mc":[{"id":"1.120089104","rc":[{"atl":[[6.8,4.05]],"id":9480385}],"con":true,"img":false,"tv":9378.16}]}
{"op":"mcm","clk":"1147790135","pt":1439897057461,"mc":[{"id":"1.120089104","rc":[{"atl":[[9,25.96]],"id":9480385},{"spn":6.4,"spf":1.0,"id":9480385}],"con":true,"img":false,"tv":9378.16}]}
{"op":"mcm","clk":"1147790140","pt":1439897057667,"mc":[{"id":"1.120089104","rc":[{"atl":[[9,10.89]],"id":9480385}],"con":true,"img":false,"tv":9378.16}]}
{"op":"mcm","clk":"1147790282","pt":1439897062680,"mc":[{"id":"1.120089104","rc":[{"atl":[[9,0]],"id":9480385}],"con":true,"img":false,"tv":9378.16}]}
{"op":"mcm","clk":"1147790454","pt":1439897067950,"mc":[{"id":"1.120089104","rc":[{"atl":[[9,3.02]],"id":9480385}],"con":true,"img":false,"tv":9378.16}]}
{"op":"mcm","clk":"1147791374","pt":1439897101541,"mc":[{"id":"1.120089104","rc":[{"atb":[[1.01,1727.18]],"id":9480385}],"con":true,"img":false,"tv":9378.16}]}
{"op":"mcm","clk":"1147791382","pt":1439897101755,"mc":[{"id":"1.120089104","rc":[{"atb":[[1.01,1726.7]],"id":9480385}],"con":true,"img":false,"tv":9378.16}]}
{"op":"mcm","clk":"1147791388","pt":1439897101966,"mc":[{"id":"1.120089104","rc":[{"atb":[[1.01,1725.18]],"id":9480385}],"con":true,"img":false,"tv":9378.16}]}
{"op":"mcm","clk":"1147791393","pt":1439897102021,"mc":[{"id":"1.120089104","rc":[{"atb":[[6.2,1.52]],"id":9480385}],"con":true,"img":false,"tv":9378.16}]}
{"op":"mcm","clk":"1147791505","pt":1439897106428,"mc":[{"id":"1.120089104","rc":[{"atb":[[5.8,14.53]],"id":9480385}],"con":true,"img":false,"tv":9378.16}]}
{"op":"mcm","clk":"1147791514","pt":1439897106639,"mc":[{"id":"1.120089104","rc":[{"atb":[[5.6,1.42]],"id":9480385}],"con":true,"img":false,"tv":9378.16}]}
{"op":"mcm","clk":"1147793678","pt":1439897177732,"mc":[{"id":"1.120089104","rc":[{"atl":[[990,2]],"id":9480385},{"spn":6.5,"spf":1.0,"id":9480385}],"con":true,"img":false,"tv":9378.16}]}
{"op":"mcm","clk":"1147793681","pt":1439897177836,"mc":[{"id":"1.120089104","rc":[{"atl":[[990,0.14]],"id":9480385}],"con":true,"img":false,"tv":9378.16}]}
{"op":"mcm","clk":"1147793685","pt":1439897178044,"mc":[{"id":"1.120089104","rc":[{"atl":[[990,0]],"id":9480385}],"con":true,"img":false,"tv":9378.16}]}
{"op":"mcm","clk":"1147793688","pt":1439897178156,"mc":[{"id":"1.120089104","rc":[{"trd":[[6.2,6.28]],"ltp":6.2,"tv":6.28,"id":9480385},{"atb":[[6.2,1.38]],"id":9480385}],"con":true,"img":false,"tv":9378.44}]}
{"op":"mcm","clk":"1147796228","pt":1439897287140,"mc":[{"id":"1.120089104","rc":[{"atb":[[1.17,205.88]],"id":9612932}],"con":true,"img":false,"tv":9378.44}]}
{"op":"mcm","clk":"1147796277","pt":1439897291283,"mc":[{"id":"1.120089104","rc":[{"atl":[[7,2.02]],"id":9480385}],"con":true,"img":false,"tv":9378.44}]}
{"op":"mcm","clk":"1147796278","pt":1439897291386,"mc":[{"id":"1.120089104","rc":[{"atl":[[6.6,4.04]],"id":9480385}],"con":true,"img":false,"tv":9378.44}]}
{"op":"mcm","clk":"1147796800","pt":1439897321747,"mc":[{"id":"1.120089104","rc":[{"atl":[[6.8,1.5]],"id":9480385}],"con":true,"img":false,"tv":9378.44}]}
{"op":"mcm","clk":"1147796806","pt":1439897321958,"mc":[{"id":"1.120089104","rc":[{"atb":[[6,5.9]],"id":9480385}],"con":true,"img":false,"tv":9378.44}]}
{"op":"mcm","clk":"1147806937","pt":1439897664832,"mc":[{"id":"1.120089104","marketDefinition":{"bspMarket":true,"turnInPlayEnabled":true,"persistenceEnabled":true,"marketBaseRate":5.0,"eventId":"27514783","eventTypeId":"7","numberOfWinners":1,"bettingType":"ODDS","marketType":"WIN","marketTime":"2015-08-18T20:20:00.000Z","suspendTime":"2015-08-18T20:20:00.000Z","bspReconciled":false,"complete":true,"inPlay":false,"crossMatching":false,"runnersVoidable":false,"numberOfActiveRunners":2,"betDelay":0,"status":"OPEN","runners":[{"adjustmentFactor":79.72,"status":"ACTIVE","sortPriority":1,"id":9612932,"name":"Alinstante"},{"adjustmentFactor":20.27,"status":"ACTIVE","sortPriority":2,"id":9480385,"name":"Vallance Road"}],"regulators":["MR_NJ","MR_INT"],"venue":"Chelmsford City","countryCode":"GB","discountAllowed":true,"timezone":"Europe/London","openDate":"2015-08-18T17:20:00.000Z","version":1061399117,"name":"1m Cond Stks","eventName":"ChelmC 18th Aug"},"rc":[{"trd":[[1.19,126.84],[1.3,209.75],[1.29,101.62],[1.17,234.58],[1.16,719.22],[1.18,559.88],[1.4,49.38],[1.28,997.42],[1.27,15.74],[1.15,26],[1.25,309.22],[1.26,83.08],[1.23,550.77],[1.22,1521.77],[1.24,1191.1],[1.2,633.55],[1.21,1098.01]],"ltp":1.19,"tv":8427.93,"id":9612932},{"atb":[[1.17,205.88],[1.16,563],[1.06,20],[1.14,56.53],[1.01,1991.52],[1.13,25],[1.15,177.29],[1.03,18],[1.02,10250],[1.12,1251.03],[1.1,4706.21],[1.08,10],[1.11,6]],"id":9612932},{"spb":[[1000,10]],"id":9612932},{"atl":[[1.3,95.06],[19.5,11],[630,0.09],[1.4,500],[1000,1],[1.27,143.23],[1.25,276.02],[1.26,541.34],[1.23,6],[5.2,15],[1.22,10],[1.69,15],[46,2],[1.24,500],[1.2,120.28],[1.46,2.34],[4,0.25],[540,0.07],[1.21,12.76],[900,0.2]],"id":9612932},{"spl":[[7,10],[1.88,20.11],[1.01,835.41],[1.25,2]],"id":9612932},{"spn":1.16,"spf":1.01,"id":9612932},{"trd":[[6.2,6.28],[4.9,11.97],[5.4,38.19],[5.9,3.78],[6.4,23.28],[4.8,120.46],[5.3,25.25],[5.8,0.16],[5.7,1.03],[6,0.15],[5.2,35.57],[4.7,103.47],[6.6,0.12],[7,1.92],[5.1,136.79],[5.6,77.39],[5.5,33.21],[5,331.36]],"ltp":6.2,"tv":950.38,"id":9480385},{"atb":[[1.43,1250],[2.6,1.9],[4.9,108.53],[1.06,20],[1.18,30],[1.81,12.35],[1.01,1725.18],[4.8,96.3],[1.02,10250],[1.03,18],[5.8,14.53],[3.4,2.34],[5.2,3],[6,5.9],[2.16,30],[1.08,10],[4.7,13.7],[5.1,12.48],[2.92,258.33],[5.6,1.42],[5.5,56.99],[4.6,0.11],[5,197.76],[6.2,1.38]],"id":9480385},{"atl":[[6.8,1.5],[14,15],[7.8,1.22],[630,0.09],[9.2,2.34],[9,3.02],[70,2],[46,2],[55,0.01],[7,2.02],[6.6,4.04],[90,2],[540,0.07],[900,0.2]],"id":9480385},{"spl":[[7,10]],"id":9480385},{"spn":6.4,"spf":1.0,"id":9480385}],"con":true,"img":true,"tv":9378.44}]}
{"op":"mcm","clk":"1147814304","pt":1439897795575,"mc":[{"id":"1.120089104","rc":[{"atl":[[6.6,0]],"id":9480385}],"con":true,"img":false,"tv":9378.44}]}
{"op":"mcm","clk":"1147814305","pt":1439897795681,"mc":[{"id":"1.120089104","rc":[{"atl":[[6.8,5.54]],"id":9480385}],"con":true,"img":false,"tv":9378.44}]}
{"op":"mcm","clk":"1147814586","pt":1439897812423,"mc":[{"id":"1.120089104","rc":[{"atb":[[1.14,84.82]],"id":9612932}],"con":true,"img":false,"tv":9378.44}]}
{"op":"mcm","clk":"1147814593","pt":1439897812587,"mc":[{"id":"1.120089104","rc":[{"atb":[[1.14,28.28]],"id":9612932}],"con":true,"img":false,"tv":9378.44}]}
{"op":"mcm","clk":"1147814707","pt":1439897818986,"mc":[{"id":"1.120089104","rc":[{"atb":[[1.01,2698.24]],"id":9612932},{"atb":[[1.01,2431.89]],"id":9480385}],"con":true,"img":false,"tv":9378.44}]}
{"op":"mcm","clk":"1147815627","pt":1439897871684,"mc":[{"id":"1.120089104","rc":[{"atb":[[1.14,80.53]],"id":9612932}],"con":true,"img":false,"tv":9378.44}]}
{"op":"mcm","clk":"1147815633","pt":1439897871883,"mc":[{"id":"1.120089104","rc":[{"atb":[[1.14,52.24]],"id":9612932}],"con":true,"img":false,"tv":9378.44}]}
{"op":"mcm","clk":"1147818135","pt":1439898009004,"mc":[{"id":"1.120089104","rc":[{"trd":[[1.17,238.58]],"ltp":1.17,"tv":238.58,"id":9612932},{"atb":[[1.17,203.88]],"id":9612932}],"con":true,"img":false,"tv":9382.44}]}
{"op":"mcm","clk":"1147819130","pt":1439898049228,"mc":[{"id":"1.120089104","rc":[{"atl":[[1.18,555]],"id":9612932}],"con":true,"img":false,"tv":9382.44}]}
{"op":"mcm","clk":"1147819134","pt":1439898049440,"mc":[{"id":"1.120089104","rc":[{"atb":[[6.2,2.79]],"id":9480385},{"atl":[[6.8,4.04]],"id":9480385}],"con":true,"img":false,"tv":9382.44}]}
{"op":"mcm","clk":"1147819430","pt":1439898061259,"mc":[{"id":"1.120089104","rc":[{"atb":[[6,2.8]],"id":9480385}],"con":true,"img":false,"tv":9382.44}]}
{"op":"mcm","clk":"1147819810","pt":1439898075063,"mc":[{"id":"1.120089104","rc":[{"atb":[[4.8,61.48]],"id":9480385}],"con":true,"img":false,"tv":9382.44}]}
{"op":"mcm","clk":"1147819821","pt":1439898075585,"mc":[{"id":"1.120089104","rc":[{"atb":[[4.9,137.98]],"id":9480385}],"con":true,"img":false,"tv":9382.44}]}
{"op":"mcm","clk":"1147819883","pt":1439898078210,"mc":[{"id":"1.120089104","rc":[{"atl":[[1.23,47.94]],"id":9612932}],"con":true,"img":false,"tv":9382.44}]}
{"op":"mcm","clk":"1147820182","pt":1439898088774,"mc":[{"id":"1.120089104","rc":[{"atb":[[6.2,5.79]],"id":9480385}],"con":true,"img":false,"tv":9382.44}]}
{"op":"mcm","clk":"1147821268","pt":1439898131237,"mc":[{"id":"1.120089104","rc":[{"trd":[[1.18,601.64]],"ltp":1.18,"tv":601.64,"id":9612932},{"atl":[[1.18,534.12]],"id":9612932}],"con":true,"img":false,"tv":9424.2}]}
{"op":"mcm","clk":"1147822039","pt":1439898164321,"mc":[{"id":"1.120089104","rc":[{"atb":[[4.9,130.63]],"id":9480385}],"con":true,"img":false,"tv":9424.2}]}
{"op":"mcm","clk":"1147822041","pt":1439898164530,"mc":[{"id":"1.120089104","rc":[{"atb":[[4.9,136.85]],"id":9480385}],"con":true,"img":false,"tv":9424.2}]}
{"op":"mcm","clk":"1147822431","pt":1439898190224,"mc":[{"id":"1.120089104","rc":[{"trd":[[1.17,438.58]],"ltp":1.17,"tv":438.58,"id":9612932},{"atb":[[1.17,103.88]],"id":9612932}],"con":true,"img":false,"tv":9624.2}]}
{"op":"mcm","clk":"1147822452","pt":1439898191444,"mc":[{"id":"1.120089104","rc":[{"atb":[[1.17,102.34]],"id":9612932}],"con":true,"img":false,"tv":9624.2}]}
{"op":"mcm","clk":"1147822659","pt":1439898201550,"mc":[{"id":"1.120089104","rc":[{"atb":[[1.16,663]],"id":9612932}],"con":true,"img":false,"tv":9624.2}]}
{"op":"mcm","clk":"1147823301","pt":1439898234490,"mc":[{"id":"1.120089104","rc":[{"trd":[[1.18,846.28]],"ltp":1.18,"tv":846.28,"id":9612932},{"atl":[[1.18,411.8]],"id":9612932},{"spn":1.16,"spf":1.01,"id":9612932}],"con":true,"img":false,"tv":9868.83}]}
{"op":"mcm","clk":"1147828408","pt":1439898436460,"mc":[{"id":"1.120089104","rc":[{"spl":[[1.01,845.41]],"id":9612932},{"spn":1.16,"spf":1.01,"id":9612932}],"con":true,"img":false,"tv":9868.83}]}
{"op":"mcm","clk":"1147829893","pt":1439898482210,"mc":[{"id":"1.120089104","rc":[{"trd":[[1.18,950.52]],"ltp":1.18,"tv":950.52,"id":9612932},{"atl":[[1.18,359.68]],"id":9612932}],"con":true,"img":false,"tv":9973.07}]}
{"op":"mcm","clk":"1147834712","pt":1439898564890,"mc":[{"id":"1.120089104","marketDefinition":{"bspMarket":true,"turnInPlayEnabled":true,"persistenceEnabled":true,"marketBaseRate":5.0,"eventId":"27514783","eventTypeId":"7","numberOfWinners":1,"bettingType":"ODDS","marketType":"WIN","marketTime":"2015-08-18T20:20:00.000Z","suspendTime":"2015-08-18T20:20:00.000Z","bspReconciled":false,"complete":true,"inPlay":false,"crossMatching":false,"runnersVoidable":false,"numberOfActiveRunners":2,"betDelay":0,"status":"OPEN","runners":[{"adjustmentFactor":79.72,"status":"ACTIVE","sortPriority":1,"id":9612932,"name":"Alinstante"},{"adjustmentFactor":20.27,"status":"ACTIVE","sortPriority":2,"id":9480385,"name":"Vallance Road"}],"regulators":["MR_NJ","MR_INT"],"venue":"Chelmsford City","countryCode":"GB","discountAllowed":true,"timezone":"Europe/London","openDate":"2015-08-18T17:20:00.000Z","version":1061399117,"name":"1m Cond Stks","eventName":"ChelmC 18th Aug"},"rc":[{"trd":[[1.18,950.52],[1.3,209.75],[1.29,101.62],[1.17,438.58],[1.16,719.22],[1.4,49.38],[1.28,997.42],[1.27,15.74],[1.15,26],[1.25,309.22],[1.26,83.08],[1.23,550.77],[1.22,1521.77],[1.24,1191.1],[1.2,633.55],[1.19,126.84],[1.21,1098.01]],"ltp":1.18,"tv":9022.57,"id":9612932},{"atb":[[1.17,102.34],[1.16,663],[1.06,20],[1.14,52.24],[1.01,2698.24],[1.13,25],[1.15,177.29],[1.03,18],[1.02,10250],[1.12,1251.03],[1.1,4706.21],[1.08,10],[1.11,6]],"id":9612932},{"spb":[[1000,10]],"id":9612932},{"atl":[[1.3,95.06],[1.18,359.68],[19.5,11],[630,0.09],[1.4,500],[1000,1],[1.27,143.23],[1.25,276.02],[1.26,541.34],[1.23,47.94],[5.2,15],[1.22,10],[1.69,15],[46,2],[1.24,500],[1.2,120.28],[1.46,2.34],[4,0.25],[540,0.07],[1.21,12.76],[900,0.2]],"id":9612932},{"spl":[[7,10],[1.88,20.11],[1.01,845.41],[1.25,2]],"id":9612932},{"spn":1.16,"spf":1.01,"id":9612932},{"trd":[[6.2,6.28],[4.9,11.97],[5.4,38.19],[5.9,3.78],[6.4,23.28],[4.8,120.46],[5.3,25.25],[5.8,0.16],[5.7,1.03],[6,0.15],[5.2,35.57],[4.7,103.47],[6.6,0.12],[7,1.92],[5.1,136.79],[5.6,77.39],[5.5,33.21],[5,331.36]],"ltp":6.2,"tv":950.38,"id":9480385},{"atb":[[1.43,1250],[2.6,1.9],[4.9,136.85],[1.06,20],[1.18,30],[1.81,12.35],[1.01,2431.89],[4.8,61.48],[1.02,10250],[1.03,18],[5.8,14.53],[3.4,2.34],[5.2,3],[6,2.8],[2.16,30],[1.08,10],[4.7,13.7],[5.1,12.48],[2.92,258.33],[5.6,1.42],[5.5,56.99],[4.6,0.11],[5,197.76],[6.2,5.79]],"id":9480385},{"atl":[[6.8,4.04],[14,15],[46,2],[7,2.02],[7.8,1.22],[55,0.01],[630,0.09],[90,2],[9.2,2.34],[9,3.02],[70,2],[540,0.07],[900,0.2]],"id":9480385},{"spl":[[7,10]],"id":9480385},{"spn":6.5,"spf":1.0,"id":9480385}],"con":true,"img":true,"tv":9973.07}]}
{"op":"mcm","clk":"1147840033","pt":1439898579297,"mc":[{"id":"1.120089104","rc":[{"trd":[[1.18,1046.6]],"ltp":1.18,"tv":1046.6,"id":9612932},{"atl":[[1.18,311.64]],"id":9612932}],"con":true,"img":false,"tv":10069.15}]}
{"op":"mcm","clk":"1147840123","pt":1439898585178,"mc":[{"id":"1.120089104","rc":[{"trd":[[1.18,1097.92]],"ltp":1.18,"tv":1097.92,"id":9612932},{"atl":[[1.18,285.98]],"id":9612932}],"con":true,"img":false,"tv":10120.47}]}
{"op":"mcm","clk":"1147840207","pt":1439898590603,"mc":[{"id":"1.120089104","rc":[{"trd":[[1.18,1244.98]],"ltp":1.18,"tv":1244.98,"id":9612932},{"atl":[[1.18,212.45]],"id":9612932}],"con":true,"img":false,"tv":10267.53}]}
{"op":"mcm","clk":"1147840860","pt":1439898625374,"mc":[{"id":"1.120089104","rc":[{"atl":[[1.23,6]],"id":9612932}],"con":true,"img":false,"tv":10267.53}]}
{"op":"mcm","clk":"1147841076","pt":1439898635482,"mc":[{"id":"1.120089104","rc":[{"atb":[[1.11,17.3]],"id":9612932},{"atb":[[1.11,11.3]],"id":9480385}],"con":true,"img":false,"tv":10267.53}]}
{"op":"mcm","clk":"1147841323","pt":1439898647201,"mc":[{"id":"1.120089104","rc":[{"atb":[[1.1,4718.23]],"id":9612932},{"atb":[[1.1,12.01]],"id":9480385}],"con":true,"img":false,"tv":10267.53}]}
{"op":"mcm","clk":"1147841540","pt":1439898660798,"mc":[{"id":"1.120089104","rc":[{"atb":[[1.09,10.6]],"id":9612932},{"atb":[[1.09,10.6]],"id":9480385}],"con":true,"img":false,"tv":10267.53}]}
{"op":"mcm","clk":"1147841862","pt":1439898675376,"mc":[{"id":"1.120089104","rc":[{"atb":[[1.08,22.01]],"id":9612932},{"atb":[[1.08,22.01]],"id":9480385}],"con":true,"img":false,"tv":10267.53}]}
{"op":"mcm","clk":"1147845219","pt":1439898844644,"mc":[{"id":"1.120089104","rc":[{"spl":[[1.01,855.41]],"id":9612932},{"spn":1.16,"spf":1.01,"id":9612932}],"con":true,"img":false,"tv":10267.53}]}
{"op":"mcm","clk":"1147845286","pt":1439898847357,"mc":[{"id":"1.120089104","rc":[{"atl":[[6.4,5]],"id":9480385}],"con":true,"img":false,"tv":10267.53}]}
{"op":"mcm","clk":"1147845294","pt":1439898847620,"mc":[{"id":"1.120089104","rc":[{"trd":[[1.18,1299.22]],"ltp":1.18,"tv":1299.22,"id":9612932},{"atl":[[1.18,185.33]],"id":9612932},{"trd":[[6.4,33.28]],"ltp":6.4,"tv":33.28,"id":9480385},{"atl":[[6.4,0]],"id":9480385}],"con":true,"img":false,"tv":10331.77}]}
{"op":"mcm","clk":"1147845301","pt":1439898847936,"mc":[{"id":"1.120089104","rc":[{"trd":[[1.18,1353.46]],"ltp":1.18,"tv":1353.46,"id":9612932},{"atl":[[1.18,158.21]],"id":9612932},{"atb":[[6.4,5]],"id":9480385}],"con":true,"img":false,"tv":10386.01}]}
{"op":"mcm","clk":"1147845304","pt":1439898848044,"mc":[{"id":"1.120089104","rc":[{"atb":[[6.4,0]],"id":9480385}],"con":true,"img":false,"tv":10386.01}]}
{"op":"mcm","clk":"1147845344","pt":1439898850188,"mc":[{"id":"1.120089104","rc":[{"atl":[[5.2,0]],"id":9612932}],"con":true,"img":false,"tv":10386.01}]}
{"op":"mcm","clk":"1147845571","pt":1439898859718,"mc":[{"id":"1.120089104","rc":[{"atl":[[5.2,15]],"id":9612932}],"con":true,"img":false,"tv":10386.01}]}
{"op":"mcm","clk":"1147845814","pt":1439898872843,"mc":[{"id":"1.120089104","rc":[{"atb":[[6.4,5]],"id":9480385}],"con":true,"img":false,"tv":10386.01}]}
{"op":"mcm","clk":"1147845837","pt":1439898874090,"mc":[{"id":"1.120089104","rc":[{"atb":[[6,17.16]],"id":9480385}],"con":true,"img":false,"tv":10386.01}]}
{"op":"mcm","clk":"1147845841","pt":1439898874298,"mc":[{"id":"1.120089104","rc":[{"atb":[[5.8,3.98]],"id":9480385}],"con":true,"img":false,"tv":10386.01}]}
{"op":"mcm","clk":"1147845843","pt":1439898874401,"mc":[{"id":"1.120089104","rc":[{"atl":[[13.5,3]],"id":9480385}],"con":true,"img":false,"tv":10386.01}]}
{"op":"mcm","clk":"1147846328","pt":1439898893998,"mc":[{"id":"1.120089104","rc":[{"atb":[[6.2,4.41]],"id":9480385}],"con":true,"img":false,"tv":10386.01}]}
{"op":"mcm","clk":"1147847005","pt":1439898922077,"mc":[{"id":"1.120089104","rc":[{"trd":[[6.4,38.8]],"ltp":6.4,"tv":38.8,"id":9480385},{"atb":[[6.4,2.24]],"id":9480385},{"spn":6.6,"spf":1.0,"id":9480385}],"con":true,"img":false,"tv":10391.53}]}
{"op":"mcm","clk":"1147847009","pt":1439898922287,"mc":[{"id":"1.120089104","rc":[{"atb":[[6.4,3.65]],"id":9480385}],"con":true,"img":false,"tv":10391.53}]}
{"op":"mcm","clk":"1147848231","pt":1439898965301,"mc":[{"id":"1.120089104","rc":[{"atb":[[4.8,55.14]],"id":9480385}],"con":true,"img":false,"tv":10391.53}]}
{"op":"mcm","clk":"1147848234","pt":1439898965357,"mc":[{"id":"1.120089104","rc":[{"atb":[[5.1,18.82]],"id":9480385}],"con":true,"img":false,"tv":10391.53}]}
{"op":"mcm","clk":"1147848363","pt":1439898969540,"mc":[{"id":"1.120089104","rc":[{"atb":[[4.8,4.2]],"id":9480385}],"con":true,"img":false,"tv":10391.53}]}
{"op":"mcm","clk":"1147848379","pt":1439898969965,"mc":[{"id":"1.120089104","rc":[{"atb":[[5.1,61.07]],"id":9480385}],"con":true,"img":false,"tv":10391.53}]}
{"op":"mcm","clk":"1147849295","pt":1439898998864,"mc":[{"id":"1.120089104","rc":[{"atb":[[4.8,0]],"id":9480385}],"con":true,"img":false,"tv":10391.53}]}
{"op":"mcm","clk":"1147849297","pt":1439898998973,"mc":[{"id":"1.120089104","rc":[{"atb":[[5.1,65.28]],"id":9480385}],"con":true,"img":false,"tv":10391.53}]}
{"op":"mcm","clk":"1147849563","pt":1439899006485,"mc":[{"id":"1.120089104","rc":[{"atl":[[6.6,2.76]],"id":9480385}],"con":true,"img":false,"tv":10391.53}]}
{"op":"mcm","clk":"1147850650","pt":1439899037845,"mc":[{"id":"1.120089104","rc":[{"atb":[[4.9,107.74]],"id":9480385}],"con":true,"img":false,"tv":10391.53}]}
{"op":"mcm","clk":"1147850657","pt":1439899038055,"mc":[{"id":"1.120089104","rc":[{"atb":[[5.1,89.41]],"id":9480385}],"con":true,"img":false,"tv":10391.53}]}
{"op":"mcm","clk":"1147851618","pt":1439899061916,"mc":[{"id":"1.120089104","rc":[{"trd":[[6.6,5.64]],"ltp":6.6,"tv":5.64,"id":9480385},{"atl":[[6.6,0]],"id":9480385}],"con":true,"img":false,"tv":10397.05}]}
{"op":"mcm","clk":"1147852923","pt":1439899096078,"mc":[{"id":"1.120089104","rc":[{"trd":[[1.18,1405.68]],"ltp":1.18,"tv":1405.68,"id":9612932},{"atl":[[1.18,132.1]],"id":9612932}],"con":true,"img":false,"tv":10449.27}]}
{"op":"mcm","clk":"1147855995","pt":1439899202904,"mc":[{"id":"1.120089104","rc":[{"atb":[[1.01,2719.44]],"id":9612932},{"atb":[[1.01,2453.09]],"id":9480385}],"con":true,"img":false,"tv":10449.27}]}
{"op":"mcm","clk":"1147856308","pt":1439899211465,"mc":[{"id":"1.120089104","rc":[{"atl":[[1.21,0]],"id":9612932}],"con":true,"img":false,"tv":10449.27}]}
{"op":"mcm","clk":"1147859036","pt":1439899306128,"mc":[{"id":"1.120089104","rc":[{"trd":[[1.18,1404.96],[1.3,209.67],[1.29,101.48],[1.17,438.14],[1.16,719.12],[1.28,996.01],[1.27,15.71],[1.25,308.4],[1.26,82.91],[1.23,550.17],[1.22,1521.15],[1.24,1189.45],[1.2,633.45],[1.19,126.7],[1.21,1097.85]],"ltp":1.18,"tv":9395.17,"id":9612932},{"atb":[[1.17,102.33],[1.14,81.3],[1.01,2716.81],[1.15,176.95],[1.1,4708.82],[1.08,21.98],[1.11,17.27],[1.09,10.57]],"id":9612932},{"atl":[[1.27,142.83],[1.25,275.39],[1.26,540.94],[1.2,119.98],[1.46,2.33],[540,0.07]],"id":9612932},{"spl":[[1.01,855.11]],"id":9612932},{"trd":[[6.6,5.64],[4.9,11.95],[5.4,38.14],[6.4,38.78],[4.8,120.29],[5.3,25.25],[5.8,0.16],[5.7,1.03],[6,0.15],[5.2,35.54],[4.7,103.31],[5.1,136.71],[5.6,77.35],[5.5,33.18],[5,330.45]],"ltp":6.6,"tv":957.93,"id":9480385},{"atb":[[4.9,107.48],[5.8,3.98],[3.4,2.33],[6,17.12],[1.08,21.98],[5.1,89.25],[5,197.2],[6.2,4.4],[6.4,3.64],[1.01,2450.47],[1.1,11.98],[4.7,13.7],[1.11,11.27],[1.09,10.57],[4.6,0.11]],"id":9480385},{"atl":[[7.8,1.22],[9.2,2.33],[9,3.01],[7,2.02],[540,0.07]],"id":9480385}],"con":true,"img":false,"tv":10440.61}]}
{"op":"mcm","clk":"1147859042","pt":1439899306337,"mc":[{"id":"1.120089104","rc":[{"atb":[[1.14,29.21]],"id":9612932}],"con":true,"img":false,"tv":10440.61}]}
{"op":"mcm","clk":"1147859539","pt":1439899325231,"mc":[{"id":"1.120089104","rc":[{"atl":[[1.22,0]],"id":9612932}],"con":true,"img":false,"tv":10440.61}]}
{"op":"mcm","clk":"1147859814","pt":1439899334313,"mc":[{"id":"1.120089104","rc":[{"atl":[[1.69,0]],"id":9612932},{"atl":[[14,0]],"id":9480385}],"con":true,"img":false,"tv":10440.61}]}
{"op":"mcm","clk":"1147859938","pt":1439899338450,"mc":[{"id":"1.120089104","rc":[{"trd":[[1.17,478.14]],"ltp":1.17,"tv":478.14,"id":9612932},{"atb":[[1.17,82.33]],"id":9612932}],"con":true,"img":false,"tv":10480.61}]}
{"op":"mcm","clk":"1147860203","pt":1439899347011,"mc":[{"id":"1.120089104","rc":[{"atb":[[1.01,2476.81]],"id":9612932},{"atb":[[2.92,83.33]],"id":9480385}],"con":true,"img":false,"tv":10480.61}]}
{"op":"mcm","clk":"1147860207","pt":1439899347223,"mc":[{"id":"1.120089104","rc":[{"atb":[[2.16,0]],"id":9480385}],"con":true,"img":false,"tv":10480.61}]}
{"op":"mcm","clk":"1147866838","pt":1439899464914,"mc":[{"id":"1.120089104","marketDefinition":{"bspMarket":true,"turnInPlayEnabled":true,"persistenceEnabled":true,"marketBaseRate":5.0,"eventId":"27514783","eventTypeId":"7","numberOfWinners":1,"bettingType":"ODDS","marketType":"WIN","marketTime":"2015-08-18T20:20:00.000Z","suspendTime":"2015-08-18T20:20:00.000Z","bspReconciled":false,"complete":true,"inPlay":false,"crossMatching":false,"runnersVoidable":false,"numberOfActiveRunners":2,"betDelay":0,"status":"OPEN","runners":[{"adjustmentFactor":79.72,"status":"ACTIVE","sortPriority":1,"id":9612932,"name":"Alinstante"},{"adjustmentFactor":20.27,"status":"ACTIVE","sortPriority":2,"id":9480385,"name":"Vallance Road"}],"regulators":["MR_NJ","MR_INT"],"venue":"Chelmsford City","countryCode":"GB","discountAllowed":true,"timezone":"Europe/London","openDate":"2015-08-18T17:20:00.000Z","version":1061399117,"name":"1m Cond Stks","eventName":"ChelmC 18th Aug"},"rc":[{"trd":[[1.17,478.14],[1.3,209.67],[1.29,101.48],[1.16,719.12],[1.18,1404.96],[1.4,49.38],[1.28,996.01],[1.27,15.71],[1.15,26],[1.25,308.4],[1.26,82.91],[1.23,550.17],[1.22,1521.15],[1.24,1189.45],[1.2,633.45],[1.19,126.7],[1.21,1097.85]],"ltp":1.17,"tv":9510.55,"id":9612932},{"atb":[[1.17,82.33],[1.16,663],[1.06,20],[1.14,29.21],[1.01,2476.81],[1.13,25],[1.15,176.95],[1.02,10250],[1.03,18],[1.12,1251.03],[1.1,4708.82],[1.08,21.98],[1.11,17.27],[1.09,10.57]],"id":9612932},{"spb":[[1000,10]],"id":9612932},{"atl":[[1.3,95.06],[1.18,132.1],[19.5,11],[630,0.09],[1.4,500],[1000,1],[1.27,142.83],[1.25,275.39],[1.26,540.94],[1.23,6],[5.2,15],[46,2],[1.24,500],[1.2,119.98],[4,0.25],[1.46,2.33],[540,0.07],[900,0.2]],"id":9612932},{"spl":[[7,10],[1.88,20.11],[1.01,855.11],[1.25,2]],"id":9612932},{"spn":1.16,"spf":1.01,"id":9612932},{"trd":[[6.6,5.64],[4.9,11.95],[5.4,38.14],[5.9,3.78],[6.4,38.78],[4.8,120.29],[5.3,25.25],[5.8,0.16],[5.7,1.03],[6,0.15],[5.2,35.54],[4.7,103.31],[7,1.92],[5.1,136.71],[5.6,77.35],[5.5,33.18],[5,330.45],[6.2,6.28]],"ltp":6.6,"tv":969.91,"id":9480385},{"atb":[[1.43,1250],[2.6,1.9],[4.9,107.48],[1.06,20],[1.18,30],[1.81,12.35],[5.8,3.98],[3.4,2.33],[6,17.12],[5.2,3],[1.08,21.98],[5.1,89.25],[5,197.2],[6.2,4.4],[6.4,3.64],[1.01,2450.47],[1.02,10250],[1.03,18],[1.1,11.98],[4.7,13.7],[1.11,11.27],[2.92,83.33],[5.6,1.42],[5.5,56.99],[1.09,10.57],[4.6,0.11]],"id":9480385},{"atl":[[6.8,4.04],[46,2],[13.5,3],[7,2.02],[7.8,1.22],[55,0.01],[630,0.09],[90,2],[9.2,2.33],[9,3.01],[70,2],[540,0.07],[900,0.2]],"id":9480385},{"spl":[[7,10]],"id":9480385},{"spn":6.6,"spf":1.0,"id":9480385}],"con":true,"img":true,"tv":10480.61}]}
{"op":"mcm","clk":"1147874474","pt":1439899553160,"mc":[{"id":"1.120089104","rc":[{"spl":[[1.01,862.11]],"id":9612932},{"spn":1.16,"spf":1.01,"id":9612932}],"con":true,"img":false,"tv":10480.61}]}
{"op":"mcm","clk":"1147877161","pt":1439899659126,"mc":[{"id":"1.120089104","rc":[{"spl":[[1.01,872.11]],"id":9612932},{"spn":1.16,"spf":1.01,"id":9612932}],"con":true,"img":false,"tv":10480.61}]}
{"op":"mcm","clk":"1147878778","pt":1439899738298,"mc":[{"id":"1.120089104","rc":[{"spl":[[1.01,886.6]],"id":9612932},{"spn":1.16,"spf":1.01,"id":9612932}],"con":true,"img":false,"tv":10480.61}]}
{"op":"mcm","clk":"1147879935","pt":1439899779468,"mc":[{"id":"1.120089104","rc":[{"trd":[[1.18,1446.72]],"ltp":1.18,"tv":1446.72,"id":9612932},{"atl":[[1.18,111.22]],"id":9612932}],"con":true,"img":false,"tv":10522.37}]}
{"op":"mcm","clk":"1147880131","pt":1439899786510,"mc":[{"id":"1.120089104","rc":[{"trd":[[1.18,1488.14]],"ltp":1.18,"tv":1488.14,"id":9612932},{"atl":[[1.18,90.51]],"id":9612932}],"con":true,"img":false,"tv":10563.79}]}
{"op":"mcm","clk":"1147890632","pt":1439900155375,"mc":[{"id":"1.120089104","rc":[{"spl":[[1.01,986.6]],"id":9612932},{"spn":1.15,"spf":1.01,"id":9612932}],"con":true,"img":false,"tv":10563.79}]}
{"op":"mcm","clk":"1147890763","pt":1439900161137,"mc":[{"id":"1.120089104","rc":[{"atl":[[1.18,110.51]],"id":9612932}],"con":true,"img":false,"tv":10563.79}]}
{"op":"mcm","clk":"1147890964","pt":1439900168718,"mc":[{"id":"1.120089104","rc":[{"atl":[[900,2.2]],"id":9612932},{"atl":[[900,2.2]],"id":9480385}],"con":true,"img":false,"tv":10563.79}]}
{"op":"mcm","clk":"1147891121","pt":1439900175464,"mc":[{"id":"1.120089104","rc":[{"atl":[[900,2.24]],"id":9612932},{"atl":[[900,2.24]],"id":9480385}],"con":true,"img":false,"tv":10563.79}]}
{"op":"mcm","clk":"1147891290","pt":1439900182874,"mc":[{"id":"1.120089104","rc":[{"atl":[[900,0.24]],"id":9612932},{"atl":[[900,0.24]],"id":9480385}],"con":true,"img":false,"tv":10563.79}]}
{"op":"mcm","clk":"1147909612","pt":1439900573664,"mc":[{"id":"1.120089104","rc":[{"trd":[[1.18,1540.36]],"ltp":1.18,"tv":1540.36,"id":9612932},{"atl":[[1.18,84.4]],"id":9612932}],"con":true,"img":false,"tv":10616.01}]}
{"op":"mcm","clk":"1147911479","pt":1439900661811,"mc":[{"id":"1.120089104","rc":[{"atb":[[1.14,0]],"id":9612932},{"atb":[[6,2.79]],"id":9480385}],"con":true,"img":false,"tv":10616.01}]}
{"op":"mcm","clk":"1147911630","pt":1439900666742,"mc":[{"id":"1.120089104","rc":[{"atb":[[1.13,40.13]],"id":9612932},{"atb":[[5.9,9.33]],"id":9480385}],"con":true,"img":false,"tv":10616.01}]}
{"op":"mcm","clk":"1147914233","pt":1439900753408,"mc":[{"id":"1.120089104","rc":[{"trd":[[1.18,1709.16]],"ltp":1.18,"tv":1709.16,"id":9612932},{"atb":[[1.18,415.6]],"id":9612932},{"atl":[[1.18,0]],"id":9612932},{"spn":1.16,"spf":1.01,"id":9612932}],"con":true,"img":false,"tv":10784.81}]}
{"op":"mcm","clk":"1147914253","pt":1439900754144,"mc":[{"id":"1.120089104","rc":[{"atb":[[1.15,57]],"id":9612932},{"atb":[[6.2,3],[6.4,2.24]],"id":9480385}],"con":true,"img":false,"tv":10784.81}]}
{"op":"mcm","clk":"1147915336","pt":1439900783290,"mc":[{"id":"1.120089104","rc":[{"atb":[[5.9,10.73]],"id":9480385}],"con":true,"img":false,"tv":10784.81}]}
{"op":"mcm","clk":"1147915347","pt":1439900783444,"mc":[{"id":"1.120089104","rc":[{"atb":[[5.9,1.4]],"id":9480385}],"con":true,"img":false,"tv":10784.81}]}
{"op":"mcm","clk":"1147915577","pt":1439900789240,"mc":[{"id":"1.120089104","rc":[{"atb":[[5.9,0]],"id":9480385}],"con":true,"img":false,"tv":10784.81}]}
{"op":"mcm","clk":"1147915776","pt":1439900794596,"mc":[{"id":"1.120089104","rc":[{"atb":[[5.6,4.57]],"id":9480385}],"con":true,"img":false,"tv":10784.81}]}
{"op":"mcm","clk":"1147916385","pt":1439900811353,"mc":[{"id":"1.120089104","rc":[{"atb":[[1.1,2874.5]],"id":9612932}],"con":true,"img":false,"tv":10784.81}]}
{"op":"mcm","clk":"1147916406","pt":1439900811878,"mc":[{"id":"1.120089104","rc":[{"atb":[[1.11,1589.55]],"id":9612932}],"con":true,"img":false,"tv":10784.81}]}
{"op":"mcm","clk":"1147916875","pt":1439900824945,"mc":[{"id":"1.120089104","rc":[{"trd":[[1.2,639.83]],"ltp":1.2,"tv":639.83,"id":9612932},{"atl":[[1.2,116.79]],"id":9612932},{"atb":[[1.5,3.18]],"id":9480385}],"con":true,"img":false,"tv":10791.19}]}
{"op":"mcm","clk":"1147917807","pt":1439900853399,"mc":[{"id":"1.120089104","rc":[{"atb":[[1.5,0]],"id":9480385}],"con":true,"img":false,"tv":10791.19}]}
{"op":"mcm","clk":"1147917889","pt":1439900857547,"mc":[{"id":"1.120089104","rc":[{"atb":[[1.1,2618.23]],"id":9612932}],"con":true,"img":false,"tv":10791.19}]}
{"op":"mcm","clk":"1147917896","pt":1439900857758,"mc":[{"id":"1.120089104","rc":[{"atb":[[1.11,1809.2]],"id":9612932}],"con":true,"img":false,"tv":10791.19}]}
{"op":"mcm","clk":"1147917937","pt":1439900860815,"mc":[{"id":"1.120089104","rc":[{"trd":[[1.18,1714.16]],"ltp":1.18,"tv":1714.16,"id":9612932},{"atb":[[1.18,413.1]],"id":9612932}],"con":true,"img":false,"tv":10796.19}]}
{"op":"mcm","clk":"1147918198","pt":1439900873088,"mc":[{"id":"1.120089104","rc":[{"spl":[[1.01,989.1]],"id":9612932}],"con":true,"img":false,"tv":10796.19}]}
{"op":"mcm","clk":"1147918476","pt":1439900884648,"mc":[{"id":"1.120089104","rc":[{"trd":[[1.18,2260.16]],"ltp":1.18,"tv":2260.16,"id":9612932},{"atb":[[1.18,140.1]],"id":9612932}],"con":true,"img":false,"tv":11342.19}]}
{"op":"mcm","clk":"1147919279","pt":1439900917786,"mc":[{"id":"1.120089104","rc":[{"trd":[[1.18,2280.16]],"ltp":1.18,"tv":2280.16,"id":9612932},{"atb":[[1.18,130.1]],"id":9612932},{"spn":1.16,"spf":1.01,"id":9612932}],"con":true,"img":false,"tv":11362.19}]}
{"op":"mcm","clk":"1147920060","pt":1439900953068,"mc":[{"id":"1.120089104","rc":[{"atb":[[1.17,80]],"id":9612932}],"con":true,"img":false,"tv":11362.19}]}
{"op":"mcm","clk":"1147920068","pt":1439900953180,"mc":[{"id":"1.120089104","rc":[{"atb":[[1.18,132.43]],"id":9612932}],"con":true,"img":false,"tv":11362.19}]}
{"op":"mcm","clk":"1147920371","pt":1439900964635,"mc":[{"id":"1.120089104","rc":[{"atl":[[1.2,122.79]],"id":9612932}],"con":true,"img":false,"tv":11362.19}]}
{"op":"mcm","clk":"1147921069","pt":1439900983922,"mc":[{"id":"1.120089104","rc":[{"trd":[[1.2,646.2]],"ltp":1.2,"tv":646.2,"id":9612932},{"atl":[[1.2,119.6]],"id":9612932},{"atb":[[1.5,3.18]],"id":9480385}],"con":true,"img":false,"tv":11368.56}]}
{"op":"mcm","clk":"1147921674","pt":1439901004434,"mc":[{"id":"1.120089104","rc":[{"atb":[[1.5,0]],"id":9480385}],"con":true,"img":false,"tv":11368.56}]}
{"op":"mcm","clk":"1147926299","pt":1439901134050,"mc":[{"id":"1.120089104","rc":[{"atb":[[1.19,6]],"id":9612932},{"spn":1.16,"spf":1.01,"id":9612932}],"con":true,"img":false,"tv":11368.56}]}
{"op":"mcm","clk":"1147926314","pt":1439901134578,"mc":[{"id":"1.120089104","rc":[{"atb":[[1.19,0]],"id":9612932}],"con":true,"img":false,"tv":11368.56}]}
{"op":"mcm","clk":"1147927411","pt":1439901164813,"mc":[{"id":"1.120089104","rc":[{"atl":[[1.2,113.6]],"id":9612932}],"con":true,"img":false,"tv":11368.56}]}
{"op":"mcm","clk":"1147933793","pt":1439901264874,"mc":[{"id":"1.120089104","marketDefinition":{"bspMarket":true,"turnInPlayEnabled":true,"persistenceEnabled":true,"marketBaseRate":5.0,"eventId":"27514783","eventTypeId":"7","numberOfWinners":1,"bettingType":"ODDS","marketType":"WIN","marketTime":"2015-08-18T20:20:00.000Z","suspendTime":"2015-08-18T20:20:00.000Z","bspReconciled":false,"complete":true,"inPlay":false,"crossMatching":false,"runnersVoidable":false,"numberOfActiveRunners":2,"betDelay":0,"status":"OPEN","runners":[{"adjustmentFactor":79.72,"status":"ACTIVE","sortPriority":1,"id":9612932,"name":"Alinstante"},{"adjustmentFactor":20.27,"status":"ACTIVE","sortPriority":2,"id":9480385,"name":"Vallance Road"}],"regulators":["MR_NJ","MR_INT"],"venue":"Chelmsford City","countryCode":"GB","discountAllowed":true,"timezone":"Europe/London","openDate":"2015-08-18T17:20:00.000Z","version":1061399117,"name":"1m Cond Stks","eventName":"ChelmC 18th Aug"},"rc":[{"trd":[[1.2,646.2],[1.3,209.67],[1.29,101.48],[1.17,478.14],[1.16,719.12],[1.18,2280.16],[1.4,49.38],[1.28,996.01],[1.27,15.71],[1.15,26],[1.25,308.4],[1.26,82.91],[1.23,550.17],[1.22,1521.15],[1.24,1189.45],[1.19,126.7],[1.21,1097.85]],"ltp":1.2,"tv":10398.5,"id":9612932},{"atb":[[1.17,80],[1.16,663],[1.18,132.43],[1.06,20],[1.01,2476.81],[1.13,40.13],[1.15,57],[1.02,10250],[1.03,18],[1.12,1251.03],[1.1,2618.23],[1.08,21.98],[1.11,1809.2],[1.09,10.57]],"id":9612932},{"spb":[[1000,10]],"id":9612932},{"atl":[[1.3,95.06],[19.5,11],[630,0.09],[1.4,500],[1000,1],[1.27,142.83],[1.25,275.39],[1.26,540.94],[1.23,6],[5.2,15],[46,2],[1.24,500],[1.2,113.6],[4,0.25],[1.46,2.33],[540,0.07],[900,0.24]],"id":9612932},{"spl":[[7,10],[1.88,20.11],[1.01,989.1],[1.25,2]],"id":9612932},{"spn":1.16,"spf":1.01,"id":9612932},{"trd":[[6.6,5.64],[4.9,11.95],[5.4,38.14],[5.9,3.78],[6.4,38.78],[4.8,120.29],[5.3,25.25],[5.8,0.16],[5.7,1.03],[6,0.15],[5.2,35.54],[4.7,103.31],[7,1.92],[5.1,136.71],[5.6,77.35],[5.5,33.18],[5,330.45],[6.2,6.28]],"ltp":6.6,"tv":969.91,"id":9480385},{"atb":[[1.43,1250],[2.6,1.9],[4.9,107.48],[1.06,20],[1.18,30],[1.81,12.35],[5.8,3.98],[3.4,2.33],[6,2.79],[5.2,3],[1.08,21.98],[5.1,89.25],[5,197.2],[6.2,3],[6.4,2.24],[1.01,2450.47],[1.02,10250],[1.03,18],[1.1,11.98],[4.7,13.7],[1.11,11.27],[2.92,83.33],[5.6,4.57],[5.5,56.99],[1.09,10.57],[4.6,0.11]],"id":9480385},{"atl":[[6.8,4.04],[46,2],[13.5,3],[7,2.02],[7.8,1.22],[55,0.01],[630,0.09],[90,2],[9.2,2.33],[9,3.01],[70,2],[540,0.07],[900,0.24]],"id":9480385},{"spl":[[7,10]],"id":9480385},{"spn":6.6,"spf":1.0,"id":9480385}],"con":true,"img":true,"tv":11368.56}]}
{"op":"mcm","clk":"1147939594","pt":1439901265097,"mc":[{"id":"1.120089104","rc":[{"atl":[[1.19,20.45]],"id":9612932},{"spn":1.16,"spf":1.01,"id":9612932}],"con":true,"img":false,"tv":11368.56}]}
{"op":"mcm","clk":"1147941230","pt":1439901334003,"mc":[{"id":"1.120089104","rc":[{"spb":[[1000,30]],"id":9612932},{"spn":1.16,"spf":1.03,"id":9612932}],"con":true,"img":false,"tv":11368.56}]}
{"op":"mcm","clk":"1147942610","pt":1439901395793,"mc":[{"id":"1.120089104","rc":[{"trd":[[1.19,167.6]],"ltp":1.19,"tv":167.6,"id":9612932},{"atb":[[1.19,89.55]],"id":9612932},{"atl":[[1.19,0]],"id":9612932},{"spn":1.16,"spf":1.03,"id":9612932}],"con":true,"img":false,"tv":11409.46}]}
{"op":"mcm","clk":"1147942612","pt":1439901396000,"mc":[{"id":"1.120089104","rc":[{"trd":[[1.19,191.7]],"ltp":1.19,"tv":191.7,"id":9612932},{"atb":[[1.19,77.5]],"id":9612932},{"trd":[[6.4,43.26]],"ltp":6.4,"tv":43.26,"id":9480385},{"atb":[[6.4,0]],"id":9480385}],"con":true,"img":false,"tv":11438.04}]}
{"op":"mcm","clk":"1147942614","pt":1439901396104,"mc":[{"id":"1.120089104","rc":[{"atl":[[1.2,7.71]],"id":9612932}],"con":true,"img":false,"tv":11438.04}]}
{"op":"mcm","clk":"1147942630","pt":1439901396787,"mc":[{"id":"1.120089104","rc":[{"atb":[[6.2,0]],"id":9480385}],"con":true,"img":false,"tv":11438.04}]}
{"op":"mcm","clk":"1147942680","pt":1439901399214,"mc":[{"id":"1.120089104","rc":[{"atb":[[1.13,96.51]],"id":9612932}],"con":true,"img":false,"tv":11438.04}]}
{"op":"mcm","clk":"1147942683","pt":1439901399425,"mc":[{"id":"1.120089104","rc":[{"atb":[[1.13,81.37]],"id":9612932}],"con":true,"img":false,"tv":11438.04}]}
{"op":"mcm","clk":"1147942893","pt":1439901408631,"mc":[{"id":"1.120089104","rc":[{"atb":[[1.1,2446.19]],"id":9612932}],"con":true,"img":false,"tv":11438.04}]}
{"op":"mcm","clk":"1147942894","pt":1439901408684,"mc":[{"id":"1.120089104","rc":[{"atb":[[1.14,6]],"id":9612932}],"con":true,"img":false,"tv":11438.04}]}
{"op":"mcm","clk":"1147942901","pt":1439901409217,"mc":[{"id":"1.120089104","rc":[{"atb":[[1.12,1390.29]],"id":9612932}],"con":true,"img":false,"tv":11438.04}]}
{"op":"mcm","clk":"1147942914","pt":1439901409795,"mc":[{"id":"1.120089104","rc":[{"atb":[[5.1,85.05]],"id":9480385}],"con":true,"img":false,"tv":11438.04}]}
{"op":"mcm","clk":"1147942915","pt":1439901409903,"mc":[{"id":"1.120089104","rc":[{"atb":[[4.8,4.19]],"id":9480385}],"con":true,"img":false,"tv":11438.04}]}
{"op":"mcm","clk":"1147942956","pt":1439901411748,"mc":[{"id":"1.120089104","rc":[{"atb":[[1.19,0]],"id":9612932}],"con":true,"img":false,"tv":11438.04}]}
{"op":"mcm","clk":"1147942961","pt":1439901411855,"mc":[{"id":"1.120089104","rc":[{"trd":[[1.2,661.62]],"ltp":1.2,"tv":661.62,"id":9612932},{"atb":[[1.2,69.79]],"id":9612932},{"atl":[[1.2,0]],"id":9612932}],"con":true,"img":false,"tv":11453.46}]}
{"op":"mcm","clk":"1147942965","pt":1439901412169,"mc":[{"id":"1.120089104","rc":[{"atl":[[1.23,30]],"id":9612932}],"con":true,"img":false,"tv":11453.46}]}
{"op":"mcm","clk":"1147942968","pt":1439901412329,"mc":[{"id":"1.120089104","rc":[{"trd":[[1.2,689.52]],"ltp":1.2,"tv":689.52,"id":9612932},{"atb":[[1.2,55.84]],"id":9612932},{"trd":[[6,5.73]],"ltp":6.0,"tv":5.73,"id":9480385},{"atb":[[6,0]],"id":9480385}],"con":true,"img":false,"tv":11486.95}]}
{"op":"mcm","clk":"1147942971","pt":1439901412646,"mc":[{"id":"1.120089104","rc":[{"atl":[[1.23,146]],"id":9612932}],"con":true,"img":false,"tv":11486.95}]}
{"op":"mcm","clk":"1147942975","pt":1439901412966,"mc":[{"id":"1.120089104","rc":[{"atl":[[1.23,122]],"id":9612932}],"con":true,"img":false,"tv":11486.95}]}
{"op":"mcm","clk":"1147943035","pt":1439901415983,"mc":[{"id":"1.120089104","rc":[{"atb":[[5.6,1.42]],"id":9480385}],"con":true,"img":false,"tv":11486.95}]}
{"op":"mcm","clk":"1147943107","pt":1439901419690,"mc":[{"id":"1.120089104","rc":[{"atl":[[1.29,6]],"id":9612932}],"con":true,"img":false,"tv":11486.95}]}
{"op":"mcm","clk":"1147943215","pt":1439901424257,"mc":[{"id":"1.120089104","rc":[{"atb":[[5.1,42.87]],"id":9480385}],"con":true,"img":false,"tv":11486.95}]}
{"op":"mcm","clk":"1147943220","pt":1439901424364,"mc":[{"id":"1.120089104","rc":[{"atb":[[4.7,55.88]],"id":9480385}],"con":true,"img":false,"tv":11486.95}]}
{"op":"mcm","clk":"1147943231","pt":1439901425002,"mc":[{"id":"1.120089104","rc":[{"atb":[[1.2,0]],"id":9612932}],"con":true,"img":false,"tv":11486.95}]}
{"op":"mcm","clk":"1147943233","pt":1439901425057,"mc":[{"id":"1.120089104","rc":[{"atb":[[1.21,55.84]],"id":9612932}],"con":true,"img":false,"tv":11486.95}]}
{"op":"mcm","clk":"1147943238","pt":1439901425480,"mc":[{"id":"1.120089104","rc":[{"trd":[[1.21,1136.01]],"ltp":1.21,"tv":1136.01,"id":9612932},{"atb":[[1.21,36.76]],"id":9612932},{"trd":[[5.8,8.1],[6,5.75]],"ltp":5.8,"tv":13.85,"id":9480385},{"atb":[[5.8,0.01],[6,0]],"id":9480385}],"con":true,"img":false,"tv":11571.24}]}
{"op":"mcm","clk":"1147943240","pt":1439901425796,"mc":[{"id":"1.120089104","rc":[{"trd":[[1.21,1174.17]],"ltp":1.21,"tv":1174.17,"id":9612932},{"atb":[[1.21,17.68]],"id":9612932},{"trd":[[5.8,8.12]],"ltp":5.8,"tv":8.12,"id":9480385},{"atb":[[5.8,0]],"id":9480385},{"atl":[[5.8,3.97]],"id":9480385}],"con":true,"img":false,"tv":11571.24}]}
{"op":"mcm","clk":"1147943243","pt":1439901425902,"mc":[{"id":"1.120089104","rc":[{"trd":[[5.8,14.52]],"ltp":5.8,"tv":14.52,"id":9480385},{"atl":[[5.8,0.77]],"id":9480385}],"con":true,"img":false,"tv":11577.64}]}
{"op":"mcm","clk":"1147943272","pt":1439901426905,"mc":[{"id":"1.120089104","rc":[{"atb":[[5.6,4.23]],"id":9480385}],"con":true,"img":false,"tv":11577.64}]}
{"op":"mcm","clk":"1147943284","pt":1439901427172,"mc":[{"id":"1.120089104","rc":[{"atb":[[5.2,7.64]],"id":9480385}],"con":true,"img":false,"tv":11577.64}]}
{"op":"mcm","clk":"1147943375","pt":1439901430305,"mc":[{"id":"1.120089104","rc":[{"atb":[[1.11,1589.55]],"id":9612932}],"con":true,"img":false,"tv":11577.64}]}
{"op":"mcm","clk":"1147943376","pt":1439901430513,"mc":[{"id":"1.120089104","rc":[{"atb":[[1.13,267.24]],"id":9612932}],"con":true,"img":false,"tv":11577.64}]}
{"op":"mcm","clk":"1147943380","pt":1439901430725,"mc":[{"id":"1.120089104","rc":[{"atb":[[4.9,101.28]],"id":9480385}],"con":true,"img":false,"tv":11577.64}]}
{"op":"mcm","clk":"1147943383","pt":1439901430831,"mc":[{"id":"1.120089104","rc":[{"atb":[[4.5,6.19]],"id":9480385}],"con":true,"img":false,"tv":11577.64}]}
{"op":"mcm","clk":"1147943390","pt":1439901431206,"mc":[{"id":"1.120089104","rc":[{"atb":[[1.01,2452.47]],"id":9480385}],"con":true,"img":false,"tv":11577.64}]}
{"op":"mcm","clk":"1147943397","pt":1439901431421,"mc":[{"id":"1.120089104","rc":[{"atb":[[1.01,2454.28]],"id":9480385}],"con":true,"img":false,"tv":11577.64}]}
{"op":"mcm","clk":"1147943402","pt":1439901431633,"mc":[{"id":"1.120089104","rc":[{"atb":[[1.01,2452.47]],"id":9480385}],"con":true,"img":false,"tv":11577.64}]}
{"op":"mcm","clk":"1147943404","pt":1439901431739,"mc":[{"id":"1.120089104","rc":[{"atb":[[4,1.81]],"id":9480385}],"con":true,"img":false,"tv":11577.64}]}
{"op":"mcm","clk":"1147943415","pt":1439901432216,"mc":[{"id":"1.120089104","rc":[{"atb":[[1.01,2450.47],[5.5,69.38]],"id":9480385},{"atl":[[6.6,10.46]],"id":9480385}],"con":true,"img":false,"tv":11577.64}]}
{"op":"mcm","clk":"1147943417","pt":1439901432323,"mc":[{"id":"1.120089104","rc":[{"atl":[[1000,2.54]],"id":9480385}],"con":true,"img":false,"tv":11577.64}]}
{"op":"mcm","clk":"1147943422","pt":1439901432431,"mc":[{"id":"1.120089104","rc":[{"atl":[[1000,0.12]],"id":9480385}],"con":true,"img":false,"tv":11577.64}]}
{"op":"mcm","clk":"1147943425","pt":1439901432540,"mc":[{"id":"1.120089104","rc":[{"atl":[[1000,0]],"id":9480385}],"con":true,"img":false,"tv":11577.64}]}
{"op":"mcm","clk":"1147943428","pt":1439901432645,"mc":[{"id":"1.120089104","rc":[{"atl":[[6.6,10.59]],"id":9480385}],"con":true,"img":false,"tv":11577.64}]}
{"op":"mcm","clk":"1147943458","pt":1439901433546,"mc":[{"id":"1.120089104","rc":[{"atl":[[7,0]],"id":9480385}],"con":true,"img":false,"tv":11577.64}]}
{"op":"mcm","clk":"1147943470","pt":1439901433920,"mc":[{"id":"1.120089104","rc":[{"atb":[[1.21,0]],"id":9612932}],"con":true,"img":false,"tv":11577.64}]}
{"op":"mcm","clk":"1147943473","pt":1439901434028,"mc":[{"id":"1.120089104","rc":[{"atb":[[1.22,17.68]],"id":9612932}],"con":true,"img":false,"tv":11577.64}]}
{"op":"mcm","clk":"1147943478","pt":1439901434238,"mc":[{"id":"1.120089104","rc":[{"trd":[[1.22,1556.51]],"ltp":1.22,"tv":1556.51,"id":9612932},{"atb":[[1.22,0]],"id":9612932},{"trd":[[5.6,85.05]],"ltp":5.6,"tv":85.05,"id":9480385},{"atb":[[5.6,0.38]],"id":9480385}],"con":true,"img":false,"tv":11620.7}]}
{"op":"mcm","clk":"1147944101","pt":1439901466192,"mc":[{"id":"1.120089104","rc":[{"atb":[[1.16,716.1]],"id":9612932},{"atl":[[1.22,50.49]],"id":9612932},{"spn":1.16,"spf":1.03,"id":9612932},{"spn":5.7,"spf":1.0,"id":9480385}],"con":true,"img":false,"tv":11620.7}]}
{"op":"mcm","clk":"1147944107","pt":1439901466610,"mc":[{"id":"1.120089104","rc":[{"atl":[[1.22,167.95]],"id":9612932}],"con":true,"img":false,"tv":11620.7}]}
{"op":"mcm","clk":"1147944414","pt":1439901484327,"mc":[{"id":"1.120089104","rc":[{"atb":[[5.6,3.38]],"id":9480385}],"con":true,"img":false,"tv":11620.7}]}
{"op":"mcm","clk":"1147945843","pt":1439901544650,"mc":[{"id":"1.120089104","rc":[{"atb":[[4.9,71.88]],"id":9480385}],"con":true,"img":false,"tv":11620.7}]}
{"op":"mcm","clk":"1147945845","pt":1439901544754,"mc":[{"id":"1.120089104","rc":[{"atb":[[4.5,35.6]],"id":9480385}],"con":true,"img":false,"tv":11620.7}]}
{"op":"mcm","clk":"1147945980","pt":1439901551053,"mc":[{"id":"1.120089104","rc":[{"atb":[[1.01,2452.47]],"id":9480385}],"con":true,"img":false,"tv":11620.7}]}
{"op":"mcm","clk":"1147945982","pt":1439901551157,"mc":[{"id":"1.120089104","rc":[{"atb":[[1.01,2450.67]],"id":9480385}],"con":true,"img":false,"tv":11620.7}]}
{"op":"mcm","clk":"1147945985","pt":1439901551258,"mc":[{"id":"1.120089104","rc":[{"atb":[[1.01,2450.47]],"id":9480385}],"con":true,"img":false,"tv":11620.7}]}
{"op":"mcm","clk":"1147945988","pt":1439901551365,"mc":[{"id":"1.120089104","rc":[{"trd":[[5.8,14.92]],"ltp":5.8,"tv":14.92,"id":9480385},{"atl":[[5.8,0.57]],"id":9480385}],"con":true,"img":false,"tv":11621.1}]}
{"op":"mcm","clk":"1147946549","pt":1439901576176,"mc":[{"id":"1.120089104","rc":[{"atb":[[5.1,18.81]],"id":9480385}],"con":true,"img":false,"tv":11621.1}]}
{"op":"mcm","clk":"1147946557","pt":1439901576394,"mc":[{"id":"1.120089104","rc":[{"atb":[[4.5,63.78]],"id":9480385}],"con":true,"img":false,"tv":11621.1}]}
{"op":"mcm","clk":"1147946963","pt":1439901591196,"mc":[{"id":"1.120089104","rc":[{"atb":[[5.1,12.48]],"id":9480385}],"con":true,"img":false,"tv":11621.1}]}
{"op":"mcm","clk":"1147946966","pt":1439901591300,"mc":[{"id":"1.120089104","rc":[{"atb":[[4.5,70.11]],"id":9480385}],"con":true,"img":false,"tv":11621.1}]}
{"op":"mcm","clk":"1147947962","pt":1439901622016,"mc":[{"id":"1.120089104","rc":[{"atb":[[1.13,81.37]],"id":9612932}],"con":true,"img":false,"tv":11621.1}]}
{"op":"mcm","clk":"1147947978","pt":1439901622234,"mc":[{"id":"1.120089104","rc":[{"atb":[[1.11,1809.2]],"id":9612932}],"con":true,"img":false,"tv":11621.1}]}
{"op":"mcm","clk":"1147948078","pt":1439901625299,"mc":[{"id":"1.120089104","rc":[{"atb":[[4.8,0]],"id":9480385}],"con":true,"img":false,"tv":11621.1}]}
{"op":"mcm","clk":"1147948082","pt":1439901625407,"mc":[{"id":"1.120089104","rc":[{"atb":[[4.5,74.3]],"id":9480385}],"con":true,"img":false,"tv":11621.1}]}
{"op":"mcm","clk":"1147948112","pt":1439901626620,"mc":[{"id":"1.120089104","rc":[{"atb":[[4.7,13.7]],"id":9480385}],"con":true,"img":false,"tv":11621.1}]}
{"op":"mcm","clk":"1147948126","pt":1439901627049,"mc":[{"id":"1.120089104","rc":[{"atb":[[4.5,123.71]],"id":9480385}],"con":true,"img":false,"tv":11621.1}]}
{"op":"mcm","clk":"1147948900","pt":1439901654191,"mc":[{"id":"1.120089104","rc":[{"trd":[[1.18,2480.16]],"ltp":1.18,"tv":2480.16,"id":9612932},{"atb":[[1.18,32.43]],"id":9612932}],"con":true,"img":false,"tv":11821.1}]}
{"op":"mcm","clk":"1147949279","pt":1439901666934,"mc":[{"id":"1.120089104","rc":[{"atb":[[1.17,0],[1.16,616.1]],"id":9612932},{"atb":[[5.5,39.38]],"id":9480385}],"con":true,"img":false,"tv":11821.1}]}
{"op":"mcm","clk":"1147949282","pt":1439901667044,"mc":[{"id":"1.120089104","rc":[{"trd":[[1.22,1556.83]],"ltp":1.22,"tv":1556.83,"id":9612932},{"atl":[[1.22,167.79]],"id":9612932}],"con":true,"img":false,"tv":11821.42}]}
{"op":"mcm","clk":"1147949698","pt":1439901682734,"mc":[{"id":"1.120089104","rc":[{"spn":1.15,"spf":1.03,"id":9612932},{"atl":[[6.6,13.59]],"id":9480385}],"con":true,"img":false,"tv":11821.42}]}
{"op":"mcm","clk":"1147951090","pt":1439901729361,"mc":[{"id":"1.120089104","rc":[{"atb":[[4.7,15.7]],"id":9480385}],"con":true,"img":false,"tv":11821.42}]}
{"op":"mcm","clk":"1147951105","pt":1439901729839,"mc":[{"id":"1.120089104","rc":[{"atl":[[6.6,19.59]],"id":9480385}],"con":true,"img":false,"tv":11821.42}]}
{"op":"mcm","clk":"1147953621","pt":1439901814561,"mc":[{"id":"1.120089104","rc":[{"atl":[[6.8,0]],"id":9480385}],"con":true,"img":false,"tv":11821.42}]}
{"op":"mcm","clk":"1147953626","pt":1439901814666,"mc":[{"id":"1.120089104","rc":[{"trd":[[5.5,39.06],[5.6,91.81]],"ltp":5.5,"tv":130.87,"id":9480385},{"atb":[[5.6,0],[5.5,36.44]],"id":9480385}],"con":true,"img":false,"tv":11834.06}]}
{"op":"mcm","clk":"1147953940","pt":1439901827418,"mc":[{"id":"1.120089104","rc":[{"atl":[[6.4,1.4]],"id":9480385}],"con":true,"img":false,"tv":11834.06}]}
{"op":"mcm","clk":"1147954267","pt":1439901838589,"mc":[{"id":"1.120089104","rc":[{"atl":[[1.21,100]],"id":9612932}],"con":true,"img":false,"tv":11834.06}]}
{"op":"mcm","clk":"1147954832","pt":1439901862434,"mc":[{"id":"1.120089104","rc":[{"atb":[[1.16,563]],"id":9612932},{"atl":[[1.22,117.45]],"id":9612932}],"con":true,"img":false,"tv":11834.06}]}
{"op":"mcm","clk":"1147954839","pt":1439901862704,"mc":[{"id":"1.120089104","rc":[{"atl":[[1.21,217.94]],"id":9612932}],"con":true,"img":false,"tv":11834.06}]}
{"op":"mcm","clk":"1147955485","pt":1439901896734,"mc":[{"id":"1.120089104","rc":[{"atb":[[1.01,2479.36]],"id":9612932},{"spn":1.15,"spf":1.03,"id":9612932},{"spn":5.65,"spf":1.0,"id":9480385}],"con":true,"img":false,"tv":11834.06}]}
{"op":"mcm","clk":"1147955489","pt":1439901896840,"mc":[{"id":"1.120089104","rc":[{"atb":[[1.01,2476.97]],"id":9612932}],"con":true,"img":false,"tv":11834.06}]}
{"op":"mcm","clk":"1147955491","pt":1439901897054,"mc":[{"id":"1.120089104","rc":[{"atb":[[1.01,2476.81]],"id":9612932}],"con":true,"img":false,"tv":11834.06}]}
{"op":"mcm","clk":"1147955492","pt":1439901897160,"mc":[{"id":"1.120089104","rc":[{"atb":[[1.16,563.16]],"id":9612932}],"con":true,"img":false,"tv":11834.06}]}
{"op":"mcm","clk":"1147956208","pt":1439901930039,"mc":[{"id":"1.120089104","rc":[{"atl":[[6.6,13.59]],"id":9480385}],"con":true,"img":false,"tv":11834.06}]}
{"op":"mcm","clk":"1147956718","pt":1439901961107,"mc":[{"id":"1.120089104","rc":[{"atl":[[6.6,3]],"id":9480385}],"con":true,"img":false,"tv":11834.06}]}
{"op":"mcm","clk":"1147956719","pt":1439901961213,"mc":[{"id":"1.120089104","rc":[{"atl":[[8.8,7.84]],"id":9480385}],"con":true,"img":false,"tv":11834.06}]}
{"op":"mcm","clk":"1147956731","pt":1439901961686,"mc":[{"id":"1.120089104","rc":[{"atl":[[8.6,4.34]],"id":9480385}],"con":true,"img":false,"tv":11834.06}]}
{"op":"mcm","clk":"1147956736","pt":1439901961897,"mc":[{"id":"1.120089104","rc":[{"atl":[[9,0]],"id":9480385}],"con":true,"img":false,"tv":11834.06}]}
{"op":"mcm","clk":"1147956809","pt":1439901965027,"mc":[{"id":"1.120089104","rc":[{"atl":[[6.6,0]],"id":9480385}],"con":true,"img":false,"tv":11834.06}]}
{"op":"mcm","clk":"1147957092","pt":1439901978077,"mc":[{"id":"1.120089104","rc":[{"atl":[[6.4,0]],"id":9480385}],"con":true,"img":false,"tv":11834.06}]}
{"op":"mcm","clk":"1147957095","pt":1439901978131,"mc":[{"id":"1.120089104","rc":[{"atl":[[7.6,1.4]],"id":9480385}],"con":true,"img":false,"tv":11834.06}]}
{"op":"mcm","clk":"1147957385","pt":1439901993130,"mc":[{"id":"1.120089104","rc":[{"atl":[[8.8,0]],"id":9480385}],"con":true,"img":false,"tv":11834.06}]}
{"op":"mcm","clk":"1147957386","pt":1439901993232,"mc":[{"id":"1.120089104","rc":[{"atl":[[7.6,10.49]],"id":9480385}],"con":true,"img":false,"tv":11834.06}]}
{"op":"mcm","clk":"1147957390","pt":1439901993655,"mc":[{"id":"1.120089104","rc":[{"atl":[[7.6,12.71]],"id":9480385}],"con":true,"img":false,"tv":11834.06}]}
{"op":"mcm","clk":"1147958038","pt":1439902026958,"mc":[{"id":"1.120089104","rc":[{"atl":[[7.6,3.62]],"id":9480385}],"con":true,"img":false,"tv":11834.06}]}
{"op":"mcm","clk":"1147958042","pt":1439902027070,"mc":[{"id":"1.120089104","rc":[{"atl":[[8.4,8.21]],"id":9480385}],"con":true,"img":false,"tv":11834.06}]}
{"op":"mcm","clk":"1147958511","pt":1439902047564,"mc":[{"id":"1.120089104","rc":[{"atb":[[1.13,25]],"id":9612932}],"con":true,"img":false,"tv":11834.06}]}
{"op":"mcm","clk":"1147958623","pt":1439902050420,"mc":[{"id":"1.120089104","rc":[{"atl":[[7.6,1.4]],"id":9480385}],"con":true,"img":false,"tv":11834.06}]}
{"op":"mcm","clk":"1147958716","pt":1439902052761,"mc":[{"id":"1.120089104","rc":[{"atb":[[1.13,45.94]],"id":9612932}],"con":true,"img":false,"tv":11834.06}]}
{"op":"mcm","clk":"1147958884","pt":1439902058987,"mc":[{"id":"1.120089104","rc":[{"atl":[[8.4,0]],"id":9480385}],"con":true,"img":false,"tv":11834.06}]}
{"op":"mcm","clk":"1147958887","pt":1439902059093,"mc":[{"id":"1.120089104","rc":[{"atl":[[7.6,10.49]],"id":9480385}],"con":true,"img":false,"tv":11834.06}]}
{"op":"mcm","clk":"1147958907","pt":1439902060215,"mc":[{"id":"1.120089104","rc":[{"atb":[[1.14,0]],"id":9612932}],"con":true,"img":false,"tv":11834.06}]}
{"op":"mcm","clk":"1147959328","pt":1439902079718,"mc":[{"id":"1.120089104","rc":[{"atl":[[7.6,12.71]],"id":9480385}],"con":true,"img":false,"tv":11834.06}]}
{"op":"mcm","clk":"1147959689","pt":1439902090839,"mc":[{"id":"1.120089104","rc":[{"spn":1.15,"spf":1.03,"id":9612932},{"atl":[[7.6,3.62]],"id":9480385}],"con":true,"img":false,"tv":11834.06}]}
{"op":"mcm","clk":"1147959693","pt":1439902090944,"mc":[{"id":"1.120089104","rc":[{"atl":[[8.4,8.21]],"id":9480385}],"con":true,"img":false,"tv":11834.06}]}
{"op":"mcm","clk":"1147960269","pt":1439902116517,"mc":[{"id":"1.120089104","rc":[{"atl":[[7.6,9.62]],"id":9480385}],"con":true,"img":false,"tv":11834.06}]}
{"op":"mcm","clk":"1147960409","pt":1439902122986,"mc":[{"id":"1.120089104","rc":[{"atl":[[8.4,0]],"id":9480385}],"con":true,"img":false,"tv":11834.06}]}
{"op":"mcm","clk":"1147960412","pt":1439902123089,"mc":[{"id":"1.120089104","rc":[{"atl":[[7.4,9.32]],"id":9480385}],"con":true,"img":false,"tv":11834.06}]}
{"op":"mcm","clk":"1147960563","pt":1439902128817,"mc":[{"id":"1.120089104","rc":[{"atl":[[7.6,8.22]],"id":9480385}],"con":true,"img":false,"tv":11834.06}]}
{"op":"mcm","clk":"1147960568","pt":1439902128922,"mc":[{"id":"1.120089104","rc":[{"atl":[[7.2,1.4]],"id":9480385}],"con":true,"img":false,"tv":11834.06}]}
{"op":"mcm","clk":"1147960787","pt":1439902135792,"mc":[{"id":"1.120089104","rc":[{"atl":[[7.6,6]],"id":9480385}],"con":true,"img":false,"tv":11834.06}]}
{"op":"mcm","clk":"1147961613","pt":1439902163966,"mc":[{"id":"1.120089104","rc":[{"atl":[[7.4,11.6]],"id":9480385}],"con":true,"img":false,"tv":11834.06}]}
{"op":"mcm","clk":"1147972942","pt":1439902243018,"mc":[{"id":"1.120089104","rc":[{"atl":[[1.27,1.89],[1.25,52],[1.26,400]],"id":9612932},{"atb":[[4.9,0],[5,0]],"id":9480385}],"con":true,"img":false,"tv":11834.06}]}
{"op":"mcm","clk":"1147973561","pt":1439902262367,"mc":[{"id":"1.120089104","rc":[{"atb":[[5.6,3]],"id":9480385}],"con":true,"img":false,"tv":11834.06}]}
{"op":"mcm","clk":"1147975158","pt":1439902316849,"mc":[{"id":"1.120089104","rc":[{"atl":[[7.6,0]],"id":9480385},{"spn":5.7,"spf":1.0,"id":9480385}],"con":true,"img":false,"tv":11834.06}]}
{"op":"mcm","clk":"1147975374","pt":1439902324252,"mc":[{"id":"1.120089104","rc":[{"atl":[[7.4,2.28]],"id":9480385}],"con":true,"img":false,"tv":11834.06}]}
{"op":"mcm","clk":"1147975376","pt":1439902324359,"mc":[{"id":"1.120089104","rc":[{"atl":[[8.4,8.21]],"id":9480385}],"con":true,"img":false,"tv":11834.06}]}
{"op":"mcm","clk":"1147975649","pt":1439902334131,"mc":[{"id":"1.120089104","rc":[{"atl":[[7.4,0]],"id":9480385}],"con":true,"img":false,"tv":11834.06}]}
{"op":"mcm","clk":"1147975809","pt":1439902339734,"mc":[{"id":"1.120089104","rc":[{"atl":[[7.2,0]],"id":9480385}],"con":true,"img":false,"tv":11834.06}]}
{"op":"mcm","clk":"1147975810","pt":1439902339842,"mc":[{"id":"1.120089104","rc":[{"atl":[[7.6,1.4]],"id":9480385}],"con":true,"img":false,"tv":11834.06}]}
{"op":"mcm","clk":"1147976210","pt":1439902356077,"mc":[{"id":"1.120089104","rc":[{"atl":[[8.4,0]],"id":9480385}],"con":true,"img":false,"tv":11834.06}]}
{"op":"mcm","clk":"1147976212","pt":1439902356181,"mc":[{"id":"1.120089104","rc":[{"atl":[[7.6,10.49]],"id":9480385}],"con":true,"img":false,"tv":11834.06}]}
{"op":"mcm","clk":"1147976396","pt":1439902362790,"mc":[{"id":"1.120089104","rc":[{"atl":[[7.6,12.71]],"id":9480385}],"con":true,"img":false,"tv":11834.06}]}
{"op":"mcm","clk":"1147977042","pt":1439902389389,"mc":[{"id":"1.120089104","rc":[{"atl":[[7.6,3.62]],"id":9480385}],"con":true,"img":false,"tv":11834.06}]}
{"op":"mcm","clk":"1147977047","pt":1439902389498,"mc":[{"id":"1.120089104","rc":[{"atl":[[8.4,8.21]],"id":9480385}],"con":true,"img":false,"tv":11834.06}]}
{"op":"mcm","clk":"1147977850","pt":1439902419104,"mc":[{"id":"1.120089104","rc":[{"atl":[[7.6,1.4]],"id":9480385}],"con":true,"img":false,"tv":11834.06}]}
{"op":"mcm","clk":"1147977920","pt":1439902421524,"mc":[{"id":"1.120089104","rc":[{"atl":[[8.4,0]],"id":9480385}],"con":true,"img":false,"tv":11834.06}]}
{"op":"mcm","clk":"1147977923","pt":1439902421630,"mc":[{"id":"1.120089104","rc":[{"atl":[[7.6,10.49]],"id":9480385}],"con":true,"img":false,"tv":11834.06}]}
{"op":"mcm","clk":"1147978658","pt":1439902448400,"mc":[{"id":"1.120089104","rc":[{"atl":[[7.6,12.71]],"id":9480385}],"con":true,"img":false,"tv":11834.06}]}
{"op":"mcm","clk":"1147978844","pt":1439902456707,"mc":[{"id":"1.120089104","rc":[{"atl":[[7.6,3.62]],"id":9480385}],"con":true,"img":false,"tv":11834.06}]}
{"op":"mcm","clk":"1147978847","pt":1439902456923,"mc":[{"id":"1.120089104","rc":[{"atl":[[8.4,8.21]],"id":9480385}],"con":true,"img":false,"tv":11834.06}]}
{"op":"mcm","clk":"1147979601","pt":1439902489380,"mc":[{"id":"1.120089104","rc":[{"atl":[[8.4,0]],"id":9480385}],"con":true,"img":false,"tv":11834.06}]}
{"op":"mcm","clk":"1147979606","pt":1439902489482,"mc":[{"id":"1.120089104","rc":[{"atl":[[7.4,9.32]],"id":9480385}],"con":true,"img":false,"tv":11834.06}]}
{"op":"mcm","clk":"1147979639","pt":1439902490483,"mc":[{"id":"1.120089104","rc":[{"atl":[[7.6,2.22]],"id":9480385}],"con":true,"img":false,"tv":11834.06}]}
{"op":"mcm","clk":"1147979643","pt":1439902490586,"mc":[{"id":"1.120089104","rc":[{"atl":[[7.2,1.4]],"id":9480385}],"con":true,"img":false,"tv":11834.06}]}
{"op":"mcm","clk":"1147979748","pt":1439902495398,"mc":[{"id":"1.120089104","rc":[{"trd":[[1.18,2545.04]],"ltp":1.18,"tv":2545.04,"id":9612932},{"atb":[[1.18,0]],"id":9612932},{"atl":[[1.18,522.56]],"id":9612932}],"con":true,"img":false,"tv":11898.94}]}
{"op":"mcm","clk":"1147979817","pt":1439902498211,"mc":[{"id":"1.120089104","rc":[{"atb":[[1.01,2453.02]],"id":9480385}],"con":true,"img":false,"tv":11898.94}]}
{"op":"mcm","clk":"1147979824","pt":1439902498734,"mc":[{"id":"1.120089104","rc":[{"atb":[[1.01,2452.15]],"id":9480385}],"con":true,"img":false,"tv":11898.94}]}
{"op":"mcm","clk":"1147979829","pt":1439902498899,"mc":[{"id":"1.120089104","rc":[{"atb":[[1.01,2450.47]],"id":9480385}],"con":true,"img":false,"tv":11898.94}]}
{"op":"mcm","clk":"1147979831","pt":1439902499004,"mc":[{"id":"1.120089104","rc":[{"atb":[[5.7,1.67]],"id":9480385}],"con":true,"img":false,"tv":11898.94}]}
{"op":"mcm","clk":"1147979832","pt":1439902499213,"mc":[{"id":"1.120089104","rc":[{"atl":[[1.29,0]],"id":9612932}],"con":true,"img":false,"tv":11898.94}]}
{"op":"mcm","clk":"1147979961","pt":1439902504944,"mc":[{"id":"1.120089104","rc":[{"atl":[[7.6,0]],"id":9480385}],"con":true,"img":false,"tv":11898.94}]}
{"op":"mcm","clk":"1147980031","pt":1439902507363,"mc":[{"id":"1.120089104","rc":[{"atb":[[1.12,1251.03]],"id":9612932}],"con":true,"img":false,"tv":11898.94}]}
{"op":"mcm","clk":"1147980048","pt":1439902507950,"mc":[{"id":"1.120089104","rc":[{"atb":[[1.09,196.25]],"id":9612932}],"con":true,"img":false,"tv":11898.94}]}
{"op":"mcm","clk":"1147980571","pt":1439902524327,"mc":[{"id":"1.120089104","rc":[{"spn":1.15,"spf":1.03,"id":9612932},{"atl":[[7.4,0]],"id":9480385},{"spn":5.75,"spf":1.0,"id":9480385}],"con":true,"img":false,"tv":11898.94}]}
{"op":"mcm","clk":"1147980578","pt":1439902524431,"mc":[{"id":"1.120089104","rc":[{"atl":[[8.4,8.21]],"id":9480385}],"con":true,"img":false,"tv":11898.94}]}
{"op":"mcm","clk":"1147980827","pt":1439902533411,"mc":[{"id":"1.120089104","rc":[{"atl":[[7.8,3.38]],"id":9480385}],"con":true,"img":false,"tv":11898.94}]}
{"op":"mcm","clk":"1147980869","pt":1439902535222,"mc":[{"id":"1.120089104","rc":[{"atl":[[8.6,12.6]],"id":9480385}],"con":true,"img":false,"tv":11898.94}]}
{"op":"mcm","clk":"1147980877","pt":1439902535435,"mc":[{"id":"1.120089104","rc":[{"atl":[[8.6,8.25]],"id":9480385}],"con":true,"img":false,"tv":11898.94}]}
{"op":"mcm","clk":"1147981306","pt":1439902550899,"mc":[{"id":"1.120089104","rc":[{"atl":[[7.2,0]],"id":9480385}],"con":true,"img":false,"tv":11898.94}]}
{"op":"mcm","clk":"1147981309","pt":1439902551004,"mc":[{"id":"1.120089104","rc":[{"atl":[[7.6,1.4]],"id":9480385}],"con":true,"img":false,"tv":11898.94}]}
{"op":"mcm","clk":"1147981480","pt":1439902556168,"mc":[{"id":"1.120089104","rc":[{"atl":[[8.4,0]],"id":9480385}],"con":true,"img":false,"tv":11898.94}]}
{"op":"mcm","clk":"1147981483","pt":1439902556277,"mc":[{"id":"1.120089104","rc":[{"atl":[[7.6,10.49]],"id":9480385}],"con":true,"img":false,"tv":11898.94}]}
{"op":"mcm","clk":"1147981518","pt":1439902557657,"mc":[{"id":"1.120089104","rc":[{"spl":[[1.01,995.47]],"id":9612932}],"con":true,"img":false,"tv":11898.94}]}
{"op":"mcm","clk":"1147982616","pt":1439902590046,"mc":[{"id":"1.120089104","rc":[{"atb":[[1.11,1589.55]],"id":9612932},{"spn":1.15,"spf":1.03,"id":9612932}],"con":true,"img":false,"tv":11898.94}]}
{"op":"mcm","clk":"1147982624","pt":1439902590158,"mc":[{"id":"1.120089104","rc":[{"atl":[[7.8,1.22]],"id":9480385}],"con":true,"img":false,"tv":11898.94}]}
{"op":"mcm","clk":"1147982628","pt":1439902590260,"mc":[{"id":"1.120089104","rc":[{"atb":[[1.09,464.72]],"id":9612932}],"con":true,"img":false,"tv":11898.94}]}
{"op":"mcm","clk":"1147983463","pt":1439902617424,"mc":[{"id":"1.120089104","rc":[{"atb":[[1.15,82]],"id":9612932}],"con":true,"img":false,"tv":11898.94}]}
{"op":"mcm","clk":"1147983500","pt":1439902618611,"mc":[{"id":"1.120089104","rc":[{"atb":[[1.17,8.16]],"id":9612932}],"con":true,"img":false,"tv":11898.94}]}
{"op":"mcm","clk":"1147983513","pt":1439902619046,"mc":[{"id":"1.120089104","rc":[{"atl":[[7.6,12.71]],"id":9480385}],"con":true,"img":false,"tv":11898.94}]}
{"op":"mcm","clk":"1147983557","pt":1439902620557,"mc":[{"id":"1.120089104","rc":[{"atl":[[7.6,3.62]],"id":9480385}],"con":true,"img":false,"tv":11898.94}]}
{"op":"mcm","clk":"1147983562","pt":1439902620668,"mc":[{"id":"1.120089104","rc":[{"atl":[[8.4,8.21]],"id":9480385}],"con":true,"img":false,"tv":11898.94}]}
{"op":"mcm","clk":"1147983582","pt":1439902621199,"mc":[{"id":"1.120089104","rc":[{"atb":[[1.15,57]],"id":9612932}],"con":true,"img":false,"tv":11898.94}]}
{"op":"mcm","clk":"1147983767","pt":1439902627259,"mc":[{"id":"1.120089104","rc":[{"atb":[[1.15,82]],"id":9612932}],"con":true,"img":false,"tv":11898.94}]}
{"op":"mcm","clk":"1147984573","pt":1439902653340,"mc":[{"id":"1.120089104","rc":[{"spn":1.15,"spf":1.03,"id":9612932},{"atl":[[8.4,0]],"id":9480385}],"con":true,"img":false,"tv":11898.94}]}
{"op":"mcm","clk":"1147984577","pt":1439902653450,"mc":[{"id":"1.120089104","rc":[{"atl":[[7.4,9.32]],"id":9480385}],"con":true,"img":false,"tv":11898.94}]}
{"op":"mcm","clk":"1147984685","pt":1439902657564,"mc":[{"id":"1.120089104","rc":[{"atl":[[8.6,0]],"id":9480385}],"con":true,"img":false,"tv":11898.94}]}
{"op":"mcm","clk":"1147984821","pt":1439902662532,"mc":[{"id":"1.120089104","rc":[{"atl":[[9,1.5]],"id":9480385}],"con":true,"img":false,"tv":11898.94}]}
{"op":"mcm","clk":"1147985121","pt":1439902671660,"mc":[{"id":"1.120089104","rc":[{"atl":[[7.6,2.22]],"id":9480385}],"con":true,"img":false,"tv":11898.94}]}
{"op":"mcm","clk":"1147985126","pt":1439902671689,"mc":[{"id":"1.120089104","rc":[{"atl":[[7.2,1.4]],"id":9480385}],"con":true,"img":false,"tv":11898.94}]}
{"op":"mcm","clk":"1147985212","pt":1439902675406,"mc":[{"id":"1.120089104","rc":[{"atl":[[7.6,0]],"id":9480385}],"con":true,"img":false,"tv":11898.94}]}
{"op":"mcm","clk":"1147985550","pt":1439902685313,"mc":[{"id":"1.120089104","rc":[{"atl":[[7.4,0]],"id":9480385}],"con":true,"img":false,"tv":11898.94}]}
{"op":"mcm","clk":"1147985554","pt":1439902685419,"mc":[{"id":"1.120089104","rc":[{"atl":[[8.8,7.84]],"id":9480385}],"con":true,"img":false,"tv":11898.94}]}
{"op":"mcm","clk":"1147986076","pt":1439902701956,"mc":[{"id":"1.120089104","rc":[{"atl":[[7.2,0]],"id":9480385}],"con":true,"img":false,"tv":11898.94}]}
{"op":"mcm","clk":"1147986079","pt":1439902702052,"mc":[{"id":"1.120089104","rc":[{"atl":[[7.6,1.4]],"id":9480385}],"con":true,"img":false,"tv":11898.94}]}
{"op":"mcm","clk":"1147986134","pt":1439902703809,"mc":[{"id":"1.120089104","rc":[{"atl":[[7.8,3.38]],"id":9480385}],"con":true,"img":false,"tv":11898.94}]}
{"op":"mcm","clk":"1147986558","pt":1439902717683,"mc":[{"id":"1.120089104","rc":[{"atl":[[8.8,0]],"id":9480385}],"con":true,"img":false,"tv":11898.94}]}
{"op":"mcm","clk":"1147986560","pt":1439902717783,"mc":[{"id":"1.120089104","rc":[{"atl":[[7.6,10.49]],"id":9480385}],"con":true,"img":false,"tv":11898.94}]}
{"op":"mcm","clk":"1147987646","pt":1439902760348,"mc":[{"id":"1.120089104","rc":[{"atl":[[7.8,1.22]],"id":9480385}],"con":true,"img":false,"tv":11898.94}]}
{"op":"mcm","clk":"1147988615","pt":1439902789411,"mc":[{"id":"1.120089104","rc":[{"atl":[[7.6,12.71]],"id":9480385}],"con":true,"img":false,"tv":11898.94}]}
{"op":"mcm","clk":"1147988621","pt":1439902789676,"mc":[{"id":"1.120089104","rc":[{"atl":[[7.6,3.62]],"id":9480385}],"con":true,"img":false,"tv":11898.94}]}
{"op":"mcm","clk":"1147988626","pt":1439902789840,"mc":[{"id":"1.120089104","rc":[{"atl":[[8.8,7.84]],"id":9480385}],"con":true,"img":false,"tv":11898.94}]}
{"op":"mcm","clk":"1147988671","pt":1439902791740,"mc":[{"id":"1.120089104","rc":[{"atb":[[5.7,4.01]],"id":9480385}],"con":true,"img":false,"tv":11898.94}]}
{"op":"mcm","clk":"1147988681","pt":1439902792165,"mc":[{"id":"1.120089104","rc":[{"atb":[[4.5,94.31]],"id":9480385}],"con":true,"img":false,"tv":11898.94}]}
{"op":"mcm","clk":"1147988687","pt":1439902792582,"mc":[{"id":"1.120089104","rc":[{"atb":[[4.5,128.04]],"id":9480385}],"con":true,"img":false,"tv":11898.94}]}
{"op":"mcm","clk":"1147988704","pt":1439902793318,"mc":[{"id":"1.120089104","rc":[{"trd":[[5.8,16.06]],"ltp":5.8,"tv":16.06,"id":9480385},{"atb":[[5.8,19.78]],"id":9480385},{"atl":[[5.8,0]],"id":9480385}],"con":true,"img":false,"tv":11900.08}]}
{"op":"mcm","clk":"1147988713","pt":1439902793480,"mc":[{"id":"1.120089104","rc":[{"atb":[[5.2,3]],"id":9480385}],"con":true,"img":false,"tv":11900.08}]}
{"op":"mcm","clk":"1147989245","pt":1439902812402,"mc":[{"id":"1.120089104","rc":[{"atl":[[7.4,2]],"id":9480385}],"con":true,"img":false,"tv":11900.08}]}
{"op":"mcm","clk":"1147989361","pt":1439902815408,"mc":[{"id":"1.120089104","rc":[{"atb":[[5.6,0]],"id":9480385}],"con":true,"img":false,"tv":11900.08}]}
{"op":"mcm","clk":"1147989363","pt":1439902815512,"mc":[{"id":"1.120089104","rc":[{"atb":[[5.9,3]],"id":9480385}],"con":true,"img":false,"tv":11900.08}]}
{"op":"mcm","clk":"1147989381","pt":1439902815930,"mc":[{"id":"1.120089104","rc":[{"atl":[[7.4,3.4]],"id":9480385}],"con":true,"img":false,"tv":11900.08}]}
{"op":"mcm","clk":"1147989414","pt":1439902817300,"mc":[{"id":"1.120089104","rc":[{"atl":[[7.6,1.4]],"id":9480385}],"con":true,"img":false,"tv":11900.08}]}
{"op":"mcm","clk":"1147989751","pt":1439902825299,"mc":[{"id":"1.120089104","rc":[{"atl":[[8.8,0]],"id":9480385}],"con":true,"img":false,"tv":11900.08}]}
{"op":"mcm","clk":"1147989756","pt":1439902825398,"mc":[{"id":"1.120089104","rc":[{"atl":[[7.2,9.58]],"id":9480385}],"con":true,"img":false,"tv":11900.08}]}
{"op":"mcm","clk":"1147990319","pt":1439902845549,"mc":[{"id":"1.120089104","rc":[{"trd":[[1.18,2545.04],[1.17,478.17],[1.16,719.13],[1.26,82.94],[1.23,550.18],[1.22,1556.87],[1.24,1189.47],[1.2,689.57],[1.19,191.71],[1.21,1174.19]],"ltp":1.18,"tv":9177.27,"id":9612932},{"atb":[[1.17,8.17],[1.1,2447.1],[1.16,563.16],[1.11,1590.75],[1.01,2476.81]],"id":9612932},{"atl":[[1.46,2.33]],"id":9612932},{"spl":[[1.01,995.41]],"id":9612932},{"trd":[[5.8,16.06],[5.4,38.15],[6.4,43.27],[4.8,120.29],[5.7,1.03],[6,5.75],[5.2,35.54],[4.7,103.31],[5.6,91.81],[5.5,39.06],[5,330.45]],"ltp":5.8,"tv":824.72,"id":9480385},{"atb":[[5.7,4.01],[3.4,2.33],[4.5,128.1],[5.5,36.45]],"id":9480385},{"atl":[[7.8,1.22],[9.2,2.33],[7.2,11.93]],"id":9480385}],"con":true,"img":false,"tv":11900.33}]}
{"op":"mcm","clk":"1147990487","pt":1439902851531,"mc":[{"id":"1.120089104","rc":[{"atl":[[7.4,1.4]],"id":9480385},{"spn":6.45,"spf":1.0,"id":9480385}],"con":true,"img":false,"tv":11900.33}]}
{"op":"mcm","clk":"1147990494","pt":1439902851745,"mc":[{"id":"1.120089104","rc":[{"atl":[[7,2]],"id":9480385}],"con":true,"img":false,"tv":11900.33}]}
{"op":"mcm","clk":"1147990517","pt":1439902852656,"mc":[{"id":"1.120089104","rc":[{"atl":[[7.6,0]],"id":9480385}],"con":true,"img":false,"tv":11900.33}]}
{"op":"mcm","clk":"1147990689","pt":1439902858523,"mc":[{"id":"1.120089104","rc":[{"atl":[[7.2,2.34]],"id":9480385}],"con":true,"img":false,"tv":11900.33}]}
{"op":"mcm","clk":"1147990693","pt":1439902858732,"mc":[{"id":"1.120089104","rc":[{"atl":[[7.6,9.09]],"id":9480385}],"con":true,"img":false,"tv":11900.33}]}
{"op":"mcm","clk":"1147991738","pt":1439902900392,"mc":[{"id":"1.120089104","rc":[{"atl":[[7.2,0]],"id":9480385}],"con":true,"img":false,"tv":11900.33}]}
{"op":"mcm","clk":"1147991977","pt":1439902909404,"mc":[{"id":"1.120089104","rc":[{"atl":[[7,0]],"id":9480385}],"con":true,"img":false,"tv":11900.33}]}
{"op":"mcm","clk":"1147991978","pt":1439902909510,"mc":[{"id":"1.120089104","rc":[{"atl":[[7.2,2]],"id":9480385}],"con":true,"img":false,"tv":11900.33}]}
{"op":"mcm","clk":"1147992006","pt":1439902911423,"mc":[{"id":"1.120089104","rc":[{"atl":[[7,1.4]],"id":9480385}],"con":true,"img":false,"tv":11900.33}]}
{"op":"mcm","clk":"1147992359","pt":1439902928417,"mc":[{"id":"1.120089104","rc":[{"atl":[[7.2,4.34]],"id":9480385}],"con":true,"img":false,"tv":11900.33}]}
{"op":"mcm","clk":"1147992528","pt":1439902937540,"mc":[{"id":"1.120089104","rc":[{"atl":[[7.2,2.34]],"id":9480385}],"con":true,"img":false,"tv":11900.33}]}
{"op":"mcm","clk":"1147993565","pt":1439902983456,"mc":[{"id":"1.120089104","rc":[{"atl":[[7.2,0]],"id":9480385}],"con":true,"img":false,"tv":11900.33}]}
{"op":"mcm","clk":"1147993647","pt":1439902986099,"mc":[{"id":"1.120089104","rc":[{"atl":[[7.6,0]],"id":9480385}],"con":true,"img":false,"tv":11900.33}]}
{"op":"mcm","clk":"1147993649","pt":1439902986207,"mc":[{"id":"1.120089104","rc":[{"atl":[[7.2,9.59]],"id":9480385}],"con":true,"img":false,"tv":11900.33}]}
{"op":"mcm","clk":"1147994241","pt":1439903011034,"mc":[{"id":"1.120089104","rc":[{"atl":[[7.2,11.93]],"id":9480385}],"con":true,"img":false,"tv":11900.33}]}
{"op":"mcm","clk":"1147994417","pt":1439903018037,"mc":[{"id":"1.120089104","rc":[{"atl":[[7.2,2.34]],"id":9480385}],"con":true,"img":false,"tv":11900.33}]}
{"op":"mcm","clk":"1147994421","pt":1439903018142,"mc":[{"id":"1.120089104","rc":[{"atl":[[7.6,9.09]],"id":9480385}],"con":true,"img":false,"tv":11900.33}]}
{"op":"mcm","clk":"1147995308","pt":1439903054124,"mc":[{"id":"1.120089104","rc":[{"trd":[[1.18,2649.46]],"ltp":1.18,"tv":2649.46,"id":9612932},{"atl":[[1.18,470.34]],"id":9612932}],"con":true,"img":false,"tv":12004.75}]}
{"op":"mcm","clk":"1148004799","pt":1439903065976,"mc":[{"id":"1.120089104","rc":[{"atl":[[7.2,0]],"id":9480385}],"con":true,"img":false,"tv":12004.75}]}
{"op":"mcm","clk":"1148005577","pt":1439903085599,"mc":[{"id":"1.120089104","rc":[{"atb":[[1.16,563]],"id":9612932}],"con":true,"img":false,"tv":12004.75}]}
{"op":"mcm","clk":"1148005582","pt":1439903085702,"mc":[{"id":"1.120089104","rc":[{"atb":[[1.01,2479.36]],"id":9612932}],"con":true,"img":false,"tv":12004.75}]}
{"op":"mcm","clk":"1148005588","pt":1439903085808,"mc":[{"id":"1.120089104","rc":[{"atb":[[1.01,2476.97]],"id":9612932}],"con":true,"img":false,"tv":12004.75}]}
{"op":"mcm","clk":"1148005594","pt":1439903085917,"mc":[{"id":"1.120089104","rc":[{"atb":[[1.01,2476.81]],"id":9612932}],"con":true,"img":false,"tv":12004.75}]}
{"op":"mcm","clk":"1148005599","pt":1439903086022,"mc":[{"id":"1.120089104","rc":[{"trd":[[1.18,2649.8]],"ltp":1.18,"tv":2649.8,"id":9612932},{"atl":[[1.18,470.17]],"id":9612932}],"con":true,"img":false,"tv":12005.09}]}
{"op":"mcm","clk":"1148005602","pt":1439903086131,"mc":[{"id":"1.120089104","rc":[{"atl":[[7.6,0]],"id":9480385}],"con":true,"img":false,"tv":12005.09}]}
{"op":"mcm","clk":"1148005605","pt":1439903086239,"mc":[{"id":"1.120089104","rc":[{"atl":[[7.2,9.59]],"id":9480385}],"con":true,"img":false,"tv":12005.09}]}
{"op":"mcm","clk":"1148005931","pt":1439903096349,"mc":[{"id":"1.120089104","rc":[{"atl":[[7.2,11.93]],"id":9480385}],"con":true,"img":false,"tv":12005.09}]}
{"op":"mcm","clk":"1148006469","pt":1439903112791,"mc":[{"id":"1.120089104","rc":[{"atb":[[5.1,2.48]],"id":9480385}],"con":true,"img":false,"tv":12005.09}]}
{"op":"mcm","clk":"1148006788","pt":1439903121488,"mc":[{"id":"1.120089104","rc":[{"atl":[[7.2,2.34]],"id":9480385}],"con":true,"img":false,"tv":12005.09}]}
{"op":"mcm","clk":"1148006791","pt":1439903121594,"mc":[{"id":"1.120089104","rc":[{"atl":[[7.6,9.09]],"id":9480385}],"con":true,"img":false,"tv":12005.09}]}
{"op":"mcm","clk":"1148007898","pt":1439903152373,"mc":[{"id":"1.120089104","rc":[{"atl":[[7.2,0]],"id":9480385}],"con":true,"img":false,"tv":12005.09}]}
{"op":"mcm","clk":"1148007933","pt":1439903153654,"mc":[{"id":"1.120089104","rc":[{"atl":[[7.6,0]],"id":9480385}],"con":true,"img":false,"tv":12005.09}]}
{"op":"mcm","clk":"1148007938","pt":1439903153761,"mc":[{"id":"1.120089104","rc":[{"atl":[[7.2,9.59]],"id":9480385}],"con":true,"img":false,"tv":12005.09}]}
{"op":"mcm","clk":"1148007998","pt":1439903155673,"mc":[{"id":"1.120089104","rc":[{"trd":[[1.17,494.51]],"ltp":1.17,"tv":494.51,"id":9612932},{"atb":[[1.17,0]],"id":9612932},{"atl":[[1.17,31.83]],"id":9612932}],"con":true,"img":false,"tv":12021.43}]}
{"op":"mcm","clk":"1148008021","pt":1439903156201,"mc":[{"id":"1.120089104","rc":[{"atl":[[1.23,6],[1.22,0]],"id":9612932}],"con":true,"img":false,"tv":12021.43}]}
{"op":"mcm","clk":"1148008154","pt":1439903159581,"mc":[{"id":"1.120089104","rc":[{"atb":[[1.01,2453.02],[5.7,2.33]],"id":9480385}],"con":true,"img":false,"tv":12021.43}]}
{"op":"mcm","clk":"1148008170","pt":1439903160067,"mc":[{"id":"1.120089104","rc":[{"atb":[[1.01,2452.06]],"id":9480385}],"con":true,"img":false,"tv":12021.43}]}
{"op":"mcm","clk":"1148008183","pt":1439903160291,"mc":[{"id":"1.120089104","rc":[{"atb":[[1.01,2450.47]],"id":9480385}],"con":true,"img":false,"tv":12021.43}]}
{"op":"mcm","clk":"1148008188","pt":1439903160395,"mc":[{"id":"1.120089104","rc":[{"atb":[[6,1.59]],"id":9480385}],"con":true,"img":false,"tv":12021.43}]}
{"op":"mcm","clk":"1148008302","pt":1439903163391,"mc":[{"id":"1.120089104","rc":[{"atb":[[4,0]],"id":9480385}],"con":true,"img":false,"tv":12021.43}]}
{"op":"mcm","clk":"1148008349","pt":1439903164623,"mc":[{"id":"1.120089104","rc":[{"atb":[[5.7,26.04]],"id":9480385}],"con":true,"img":false,"tv":12021.43}]}
{"op":"mcm","clk":"1148008355","pt":1439903164785,"mc":[{"id":"1.120089104","rc":[{"atb":[[1.13,25]],"id":9612932},{"atb":[[5.8,0]],"id":9480385}],"con":true,"img":false,"tv":12021.43}]}
{"op":"mcm","clk":"1148008368","pt":1439903165215,"mc":[{"id":"1.120089104","rc":[{"atl":[[1.17,0]],"id":9612932}],"con":true,"img":false,"tv":12021.43}]}
{"op":"mcm","clk":"1148008371","pt":1439903165323,"mc":[{"id":"1.120089104","rc":[{"trd":[[1.16,782.79]],"ltp":1.16,"tv":782.79,"id":9612932},{"atb":[[1.16,531.17]],"id":9612932}],"con":true,"img":false,"tv":12085.09}]}
{"op":"mcm","clk":"1148008444","pt":1439903167356,"mc":[{"id":"1.120089104","rc":[{"atb":[[4.5,121.91]],"id":9480385}],"con":true,"img":false,"tv":12085.09}]}
{"op":"mcm","clk":"1148008448","pt":1439903167415,"mc":[{"id":"1.120089104","rc":[{"atb":[[4.8,6.19]],"id":9480385}],"con":true,"img":false,"tv":12085.09}]}
{"op":"mcm","clk":"1148008520","pt":1439903169564,"mc":[{"id":"1.120089104","rc":[{"atb":[[5.9,0]],"id":9480385}],"con":true,"img":false,"tv":12085.09}]}
{"op":"mcm","clk":"1148008527","pt":1439903169780,"mc":[{"id":"1.120089104","rc":[{"atb":[[5.8,3]],"id":9480385}],"con":true,"img":false,"tv":12085.09}]}
{"op":"mcm","clk":"1148008922","pt":1439903180344,"mc":[{"id":"1.120089104","rc":[{"atl":[[7.2,11.93]],"id":9480385}],"con":true,"img":false,"tv":12085.09}]}
{"op":"mcm","clk":"1148009006","pt":1439903182450,"mc":[{"id":"1.120089104","rc":[{"atl":[[7,0]],"id":9480385}],"con":true,"img":false,"tv":12085.09}]}
{"op":"mcm","clk":"1148009135","pt":1439903185791,"mc":[{"id":"1.120089104","rc":[{"atl":[[7.2,2.34]],"id":9480385}],"con":true,"img":false,"tv":12085.09}]}
{"op":"mcm","clk":"1148009139","pt":1439903185895,"mc":[{"id":"1.120089104","rc":[{"atl":[[7.6,9.09]],"id":9480385}],"con":true,"img":false,"tv":12085.09}]}
{"op":"mcm","clk":"1148009835","pt":1439903204539,"mc":[{"id":"1.120089104","rc":[{"atb":[[1.1,1460.49]],"id":9612932}],"con":true,"img":false,"tv":12085.09}]}
{"op":"mcm","clk":"1148009841","pt":1439903204752,"mc":[{"id":"1.120089104","rc":[{"atb":[[1.09,1593.19]],"id":9612932}],"con":true,"img":false,"tv":12085.09}]}
{"op":"mcm","clk":"1148009849","pt":1439903204972,"mc":[{"id":"1.120089104","rc":[{"atb":[[4.5,93.72]],"id":9480385}],"con":true,"img":false,"tv":12085.09}]}
{"op":"mcm","clk":"1148009852","pt":1439903205074,"mc":[{"id":"1.120089104","rc":[{"atb":[[4.8,34.38]],"id":9480385}],"con":true,"img":false,"tv":12085.09}]}
{"op":"mcm","clk":"1148010274","pt":1439903218039,"mc":[{"id":"1.120089104","rc":[{"spn":1.15,"spf":1.03,"id":9612932},{"atl":[[7.6,0]],"id":9480385},{"spn":6.5,"spf":1.0,"id":9480385}],"con":true,"img":false,"tv":12085.09}]}
{"op":"mcm","clk":"1148010279","pt":1439903218144,"mc":[{"id":"1.120089104","rc":[{"atl":[[7.2,11.93]],"id":9480385}],"con":true,"img":false,"tv":12085.09}]}
{"op":"mcm","clk":"1148010285","pt":1439903218251,"mc":[{"id":"1.120089104","rc":[{"atb":[[1.05,41]],"id":9612932}],"con":true,"img":false,"tv":12085.09}]}
{"op":"mcm","clk":"1148010958","pt":1439903238435,"mc":[{"id":"1.120089104","rc":[{"atb":[[1.05,0]],"id":9612932}],"con":true,"img":false,"tv":12085.09}]}
{"op":"mcm","clk":"1148010964","pt":1439903238535,"mc":[{"id":"1.120089104","rc":[{"atb":[[1.04,41]],"id":9612932}],"con":true,"img":false,"tv":12085.09}]}
{"op":"mcm","clk":"1148011456","pt":1439903249937,"mc":[{"id":"1.120089104","rc":[{"atl":[[7.2,2.34]],"id":9480385}],"con":true,"img":false,"tv":12085.09}]}
{"op":"mcm","clk":"1148011459","pt":1439903250037,"mc":[{"id":"1.120089104","rc":[{"atl":[[7.6,9.09]],"id":9480385}],"con":true,"img":false,"tv":12085.09}]}
{"op":"mcm","clk":"1148012021","pt":1439903265958,"mc":[{"id":"1.120089104","rc":[{"atl":[[7.2,0]],"id":9480385}],"con":true,"img":false,"tv":12085.09}]}
{"op":"mcm","clk":"1148012140","pt":1439903269184,"mc":[{"id":"1.120089104","rc":[{"atb":[[1.13,49.47]],"id":9612932}],"con":true,"img":false,"tv":12085.09}]}
{"op":"mcm","clk":"1148012684","pt":1439903282422,"mc":[{"id":"1.120089104","rc":[{"spn":1.15,"spf":1.03,"id":9612932},{"atl":[[7.6,0]],"id":9480385}],"con":true,"img":false,"tv":12085.09}]}
{"op":"mcm","clk":"1148012688","pt":1439903282522,"mc":[{"id":"1.120089104","rc":[{"atl":[[8.8,7.84]],"id":9480385}],"con":true,"img":false,"tv":12085.09}]}
{"op":"mcm","clk":"1148012698","pt":1439903282842,"mc":[{"id":"1.120089104","rc":[{"atl":[[7.8,2.94]],"id":9480385}],"con":true,"img":false,"tv":12085.09}]}
{"op":"mcm","clk":"1148013022","pt":1439903291795,"mc":[{"id":"1.120089104","rc":[{"atl":[[7.2,2]],"id":9480385}],"con":true,"img":false,"tv":12085.09}]}
{"op":"mcm","clk":"1148013041","pt":1439903292487,"mc":[{"id":"1.120089104","rc":[{"atl":[[7.2,4.34]],"id":9480385}],"con":true,"img":false,"tv":12085.09}]}
{"op":"mcm","clk":"1148013054","pt":1439903292814,"mc":[{"id":"1.120089104","rc":[{"trd":[[1.18,2670.34]],"ltp":1.18,"tv":2670.34,"id":9612932},{"atl":[[1.18,459.9]],"id":9612932}],"con":true,"img":false,"tv":12105.63}]}
{"op":"mcm","clk":"1148013230","pt":1439903296972,"mc":[{"id":"1.120089104","rc":[{"atb":[[1.11,17.27]],"id":9612932}],"con":true,"img":false,"tv":12105.63}]}
{"op":"mcm","clk":"1148013258","pt":1439903297504,"mc":[{"id":"1.120089104","rc":[{"atb":[[1.09,3572.9]],"id":9612932}],"con":true,"img":false,"tv":12105.63}]}
{"op":"mcm","clk":"1148013940","pt":1439903314463,"mc":[{"id":"1.120089104","rc":[{"atl":[[8.8,0]],"id":9480385}],"con":true,"img":false,"tv":12105.63}]}
{"op":"mcm","clk":"1148013944","pt":1439903314572,"mc":[{"id":"1.120089104","rc":[{"atl":[[7,9.87],[8.6,1.98]],"id":9480385}],"con":true,"img":false,"tv":12105.63}]}
{"op":"mcm","clk":"1148013952","pt":1439903314783,"mc":[{"id":"1.120089104","rc":[{"atl":[[9,0]],"id":9480385}],"con":true,"img":false,"tv":12105.63}]}
{"op":"mcm","clk":"1148014179","pt":1439903320517,"mc":[{"id":"1.120089104","rc":[{"atl":[[7.2,2]],"id":9480385}],"con":true,"img":false,"tv":12105.63}]}
{"op":"mcm","clk":"1148014651","pt":1439903336012,"mc":[{"id":"1.120089104","rc":[{"atb":[[4.5,87.4]],"id":9480385}],"con":true,"img":false,"tv":12105.63}]}
{"op":"mcm","clk":"1148014657","pt":1439903336116,"mc":[{"id":"1.120089104","rc":[{"atb":[[4.8,40.7]],"id":9480385}],"con":true,"img":false,"tv":12105.63}]}
{"op":"mcm","clk":"1148015032","pt":1439903347676,"mc":[{"id":"1.120089104","rc":[{"atl":[[7,12.28]],"id":9480385}],"con":true,"img":false,"tv":12105.63}]}
{"op":"mcm","clk":"1148015136","pt":1439903351406,"mc":[{"id":"1.120089104","rc":[{"atl":[[7,2.41]],"id":9480385}],"con":true,"img":false,"tv":12105.63}]}
{"op":"mcm","clk":"1148015142","pt":1439903351577,"mc":[{"id":"1.120089104","rc":[{"atl":[[7.2,11.59]],"id":9480385}],"con":true,"img":false,"tv":12105.63}]}
{"op":"mcm","clk":"1148015204","pt":1439903353586,"mc":[{"id":"1.120089104","rc":[{"trd":[[1.18,2781.6]],"ltp":1.18,"tv":2781.6,"id":9612932},{"atl":[[1.18,404.27]],"id":9612932}],"con":true,"img":false,"tv":12216.89}]}
{"op":"mcm","clk":"1148015546","pt":1439903365121,"mc":[{"id":"1.120089104","rc":[{"atl":[[7.2,9.59]],"id":9480385}],"con":true,"img":false,"tv":12216.89}]}
{"op":"mcm","clk":"1148015625","pt":1439903368243,"mc":[{"id":"1.120089104","rc":[{"atl":[[1.4,0]],"id":9612932}],"con":true,"img":false,"tv":12216.89}]}
{"op":"mcm","clk":"1148015789","pt":1439903374080,"mc":[{"id":"1.120089104","rc":[{"atb":[[4.5,83.21]],"id":9480385}],"con":true,"img":false,"tv":12216.89}]}
{"op":"mcm","clk":"1148015794","pt":1439903374190,"mc":[{"id":"1.120089104","rc":[{"atb":[[4.8,44.89]],"id":9480385}],"con":true,"img":false,"tv":12216.89}]}
{"op":"mcm","clk":"1148015806","pt":1439903374465,"mc":[{"id":"1.120089104","rc":[{"atl":[[8.6,0]],"id":9480385}],"con":true,"img":false,"tv":12216.89}]}
{"op":"mcm","clk":"1148015934","pt":1439903379337,"mc":[{"id":"1.120089104","rc":[{"trd":[[1.18,2781.16],[1.3,209.61],[1.29,101.39],[1.17,494.28],[1.16,782.75],[1.28,995.14],[1.27,15.7],[1.25,307.89],[1.26,82.87],[1.23,549.83],[1.22,1556.55],[1.24,1188.47],[1.2,689.56],[1.19,191.64],[1.21,1174.11]],"ltp":1.18,"tv":11120.95,"id":9612932},{"atb":[[1.1,1460],[1.08,21.95],[1.11,17.25],[1.13,49.43],[1.01,2475.17],[1.09,3570.1]],"id":9612932},{"atl":[[540,0.07],[1.21,217.74]],"id":9612932},{"spl":[[1.01,995.35]],"id":9612932},{"trd":[[5.8,16.06],[4.9,11.94],[5.4,38.12],[6.4,43.26],[4.8,120.18],[5.3,25.25],[6,5.75],[5.2,35.52],[4.7,103.21],[6.6,5.64],[5.1,136.67],[5.6,91.79],[5.5,39.05],[5,329.88]],"ltp":5.8,"tv":1002.31,"id":9480385},{"atb":[[1.01,2448.84],[4.8,44.81],[5.7,26],[1.1,11.95],[1.08,21.95],[4.7,15.7],[1.11,11.25],[1.09,10.55],[4.6,0.11]],"id":9480385},{"atl":[[7.8,2.94],[9.2,4.51],[7.4,1.4],[540,0.07]],"id":9480385}],"con":true,"img":false,"tv":12211.8}]}
{"op":"mcm","clk":"1148016096","pt":1439903385378,"mc":[{"id":"1.120089104","rc":[{"spb":[[1000,17]],"id":9480385}],"con":true,"img":false,"tv":12211.8}]}
{"op":"mcm","clk":"1148016203","pt":1439903389124,"mc":[{"id":"1.120089104","rc":[{"atl":[[7.2,0]],"id":9480385}],"con":true,"img":false,"tv":12211.8}]}
{"op":"mcm","clk":"1148016205","pt":1439903389227,"mc":[{"id":"1.120089104","rc":[{"atl":[[7.6,9.09]],"id":9480385}],"con":true,"img":false,"tv":12211.8}]}
{"op":"mcm","clk":"1148016527","pt":1439903402490,"mc":[{"id":"1.120089104","rc":[{"atl":[[7,0]],"id":9480385}],"con":true,"img":false,"tv":12211.8}]}
{"op":"mcm","clk":"1148016686","pt":1439903407712,"mc":[{"id":"1.120089104","rc":[{"trd":[[1.18,2801.16]],"ltp":1.18,"tv":2801.16,"id":9612932},{"atl":[[1.18,394.27]],"id":9612932},{"spn":7.0,"spf":7.0,"id":9480385}],"con":true,"img":false,"tv":12231.8}]}
{"op":"mcm","clk":"1148017089","pt":1439903421793,"mc":[{"id":"1.120089104","rc":[{"atl":[[7.2,2]],"id":9480385}],"con":true,"img":false,"tv":12231.8}]}
{"op":"mcm","clk":"1148017203","pt":1439903424794,"mc":[{"id":"1.120089104","rc":[{"atl":[[7.6,0]],"id":9480385}],"con":true,"img":false,"tv":12231.8}]}
{"op":"mcm","clk":"1148017207","pt":1439903424902,"mc":[{"id":"1.120089104","rc":[{"atl":[[7.2,11.59]],"id":9480385}],"con":true,"img":false,"tv":12231.8}]}
{"op":"mcm","clk":"1148017305","pt":1439903428657,"mc":[{"id":"1.120089104","rc":[{"atb":[[5.7,23.67]],"id":9480385}],"con":true,"img":false,"tv":12231.8}]}
{"op":"mcm","clk":"1148017309","pt":1439903428756,"mc":[{"id":"1.120089104","rc":[{"atb":[[5.8,5.33]],"id":9480385}],"con":true,"img":false,"tv":12231.8}]}
{"op":"mcm","clk":"1148017367","pt":1439903431076,"mc":[{"id":"1.120089104","rc":[{"atl":[[7.2,13.93]],"id":9480385}],"con":true,"img":false,"tv":12231.8}]}
{"op":"mcm","clk":"1148017427","pt":1439903433407,"mc":[{"id":"1.120089104","rc":[{"trd":[[1.18,2808.19]],"ltp":1.18,"tv":2808.19,"id":9612932},{"atl":[[1.18,390.75]],"id":9612932}],"con":true,"img":false,"tv":12238.84}]}
{"op":"mcm","clk":"1148017451","pt":1439903434199,"mc":[{"id":"1.120089104","rc":[{"atb":[[5.9,17.4]],"id":9480385}],"con":true,"img":false,"tv":12238.84}]}
{"op":"mcm","clk":"1148017458","pt":1439903434410,"mc":[{"id":"1.120089104","rc":[{"atb":[[5.7,0]],"id":9480385}],"con":true,"img":false,"tv":12238.84}]}
{"op":"mcm","clk":"1148017684","pt":1439903444041,"mc":[{"id":"1.120089104","rc":[{"atb":[[5.8,2.33]],"id":9480385}],"con":true,"img":false,"tv":12238.84}]}
{"op":"mcm","clk":"1148017717","pt":1439903445420,"mc":[{"id":"1.120089104","rc":[{"atb":[[5.6,27.49]],"id":9480385}],"con":true,"img":false,"tv":12238.84}]}
{"op":"mcm","clk":"1148017724","pt":1439903445628,"mc":[{"id":"1.120089104","rc":[{"atb":[[5.9,0]],"id":9480385}],"con":true,"img":false,"tv":12238.84}]}
{"op":"mcm","clk":"1148017989","pt":1439903455493,"mc":[{"id":"1.120089104","rc":[{"atl":[[7.2,11.93]],"id":9480385}],"con":true,"img":false,"tv":12238.84}]}
{"op":"mcm","clk":"1148018060","pt":1439903457881,"mc":[{"id":"1.120089104","rc":[{"atl":[[7.2,2.34]],"id":9480385}],"con":true,"img":false,"tv":12238.84}]}
{"op":"mcm","clk":"1148018063","pt":1439903457993,"mc":[{"id":"1.120089104","rc":[{"atl":[[7.6,9.09]],"id":9480385}],"con":true,"img":false,"tv":12238.84}]}
{"op":"mcm","clk":"1148018890","pt":1439903485644,"mc":[{"id":"1.120089104","rc":[{"atl":[[7.2,0]],"id":9480385}],"con":true,"img":false,"tv":12238.84}]}
{"op":"mcm","clk":"1148019026","pt":1439903492516,"mc":[{"id":"1.120089104","rc":[{"atl":[[7.2,1.4]],"id":9480385}],"con":true,"img":false,"tv":12238.84}]}
{"op":"mcm","clk":"1148019086","pt":1439903494363,"mc":[{"id":"1.120089104","rc":[{"atb":[[5.7,3]],"id":9480385}],"con":true,"img":false,"tv":12238.84}]}
{"op":"mcm","clk":"1148019553","pt":1439903513197,"mc":[{"id":"1.120089104","rc":[{"atl":[[7.4,3.68]],"id":9480385}],"con":true,"img":false,"tv":12238.84}]}
{"op":"mcm","clk":"1148019565","pt":1439903513679,"mc":[{"id":"1.120089104","rc":[{"atl":[[7.8,1.22]],"id":9480385}],"con":true,"img":false,"tv":12238.84}]}
{"op":"mcm","clk":"1148019756","pt":1439903522496,"mc":[{"id":"1.120089104","rc":[{"atl":[[7.6,0]],"id":9480385}],"con":true,"img":false,"tv":12238.84}]}
{"op":"mcm","clk":"1148019762","pt":1439903522603,"mc":[{"id":"1.120089104","rc":[{"atl":[[7.2,11]],"id":9480385}],"con":true,"img":false,"tv":12238.84}]}
{"op":"mcm","clk":"1148020266","pt":1439903541910,"mc":[{"id":"1.120089104","rc":[{"atb":[[1.17,54.7]],"id":9612932},{"atb":[[5.9,10.85]],"id":9480385}],"con":true,"img":false,"tv":12238.84}]}
{"op":"mcm","clk":"1148020338","pt":1439903544744,"mc":[{"id":"1.120089104","rc":[{"atb":[[5.8,22.65]],"id":9480385}],"con":true,"img":false,"tv":12238.84}]}
{"op":"mcm","clk":"1148020345","pt":1439903544954,"mc":[{"id":"1.120089104","rc":[{"atb":[[5.6,0]],"id":9480385}],"con":true,"img":false,"tv":12238.84}]}
{"op":"mcm","clk":"1148020460","pt":1439903550283,"mc":[{"id":"1.120089104","rc":[{"spn":1.15,"spf":1.03,"id":9612932},{"atb":[[5.7,0]],"id":9480385}],"con":true,"img":false,"tv":12238.84}]}
{"op":"mcm","clk":"1148020528","pt":1439903552826,"mc":[{"id":"1.120089104","rc":[{"atl":[[7.2,9.59]],"id":9480385}],"con":true,"img":false,"tv":12238.84}]}
{"op":"mcm","clk":"1148020825","pt":1439903568066,"mc":[{"id":"1.120089104","rc":[{"atl":[[7.4,1.4]],"id":9480385}],"con":true,"img":false,"tv":12238.84}]}
{"op":"mcm","clk":"1148021303","pt":1439903586285,"mc":[{"id":"1.120089104","rc":[{"atl":[[7.2,0]],"id":9480385}],"con":true,"img":false,"tv":12238.84}]}
{"op":"mcm","clk":"1148021309","pt":1439903586393,"mc":[{"id":"1.120089104","rc":[{"atl":[[7.6,9.09]],"id":9480385}],"con":true,"img":false,"tv":12238.84}]}
{"op":"mcm","clk":"1148021322","pt":1439903586657,"mc":[{"id":"1.120089104","rc":[{"atl":[[7.2,1.4]],"id":9480385}],"con":true,"img":false,"tv":12238.84}]}
{"op":"mcm","clk":"1148021544","pt":1439903596458,"mc":[{"id":"1.120089104","rc":[{"atl":[[7.4,3.68]],"id":9480385}],"con":true,"img":false,"tv":12238.84}]}
{"op":"mcm","clk":"1148022043","pt":1439903618660,"mc":[{"id":"1.120089104","rc":[{"atl":[[7.6,0]],"id":9480385}],"con":true,"img":false,"tv":12238.84}]}
{"op":"mcm","clk":"1148022046","pt":1439903618862,"mc":[{"id":"1.120089104","rc":[{"atl":[[7.2,11]],"id":9480385}],"con":true,"img":false,"tv":12238.84}]}
{"op":"mcm","clk":"1148022168","pt":1439903624011,"mc":[{"id":"1.120089104","rc":[{"atl":[[7.4,1.4]],"id":9480385}],"con":true,"img":false,"tv":12238.84}]}
{"op":"mcm","clk":"1148022632","pt":1439903646954,"mc":[{"id":"1.120089104","rc":[{"atl":[[7.2,9.59]],"id":9480385}],"con":true,"img":false,"tv":12238.84}]}
{"op":"mcm","clk":"1148022774","pt":1439903651193,"mc":[{"id":"1.120089104","rc":[{"atl":[[7.2,11.93]],"id":9480385}],"con":true,"img":false,"tv":12238.84}]}
{"op":"mcm","clk":"1148022999","pt":1439903659865,"mc":[{"id":"1.120089104","rc":[{"atl":[[7.2,2.34]],"id":9480385}],"con":true,"img":false,"tv":12238.84}]}
{"op":"mcm","clk":"1148023005","pt":1439903659970,"mc":[{"id":"1.120089104","rc":[{"atl":[[7.6,9.09]],"id":9480385}],"con":true,"img":false,"tv":12238.84}]}
{"op":"mcm","clk":"1148023449","pt":1439903676780,"mc":[{"id":"1.120089104","rc":[{"trd":[[1.17,534.62]],"ltp":1.17,"tv":534.62,"id":9612932},{"atb":[[1.17,34.53]],"id":9612932}],"con":true,"img":false,"tv":12279.18}]}
{"op":"mcm","clk":"1148023992","pt":1439903697109,"mc":[{"id":"1.120089104","rc":[{"spn":1.15,"spf":1.03,"id":9612932},{"atl":[[7.6,0]],"id":9480385}],"con":true,"img":false,"tv":12279.18}]}
{"op":"mcm","clk":"1148023996","pt":1439903697215,"mc":[{"id":"1.120089104","rc":[{"atl":[[7.2,11.93]],"id":9480385}],"con":true,"img":false,"tv":12279.18}]}
{"op":"mcm","clk":"1148024018","pt":1439903698121,"mc":[{"id":"1.120089104","rc":[{"atb":[[1.17,59.53]],"id":9612932}],"con":true,"img":false,"tv":12279.18}]}
{"op":"mcm","clk":"1148024914","pt":1439903732684,"mc":[{"id":"1.120089104","rc":[{"atl":[[7.2,2.34]],"id":9480385}],"con":true,"img":false,"tv":12279.18}]}
{"op":"mcm","clk":"1148024920","pt":1439903732782,"mc":[{"id":"1.120089104","rc":[{"atl":[[7.6,9.09]],"id":9480385}],"con":true,"img":false,"tv":12279.18}]}
{"op":"mcm","clk":"1148024970","pt":1439903734891,"mc":[{"id":"1.120089104","rc":[{"atl":[[7.2,0]],"id":9480385}],"con":true,"img":false,"tv":12279.18}]}
{"op":"mcm","clk":"1148025104","pt":1439903740529,"mc":[{"id":"1.120089104","rc":[{"atl":[[7.2,2]],"id":9480385}],"con":true,"img":false,"tv":12279.18}]}
{"op":"mcm","clk":"1148025538","pt":1439903759717,"mc":[{"id":"1.120089104","rc":[{"spn":1.15,"spf":1.03,"id":9612932},{"atl":[[7.2,4.34]],"id":9480385}],"con":true,"img":false,"tv":12279.18}]}
{"op":"mcm","clk":"1148025766","pt":1439903768506,"mc":[{"id":"1.120089104","rc":[{"atl":[[7.2,2.34]],"id":9480385}],"con":true,"img":false,"tv":12279.18}]}
{"op":"mcm","clk":"1148026567","pt":1439903797942,"mc":[{"id":"1.120089104","rc":[{"atl":[[7.6,0]],"id":9480385}],"con":true,"img":false,"tv":12279.18}]}
{"op":"mcm","clk":"1148026572","pt":1439903798044,"mc":[{"id":"1.120089104","rc":[{"atl":[[7.2,11.93]],"id":9480385}],"con":true,"img":false,"tv":12279.18}]}
{"op":"mcm","clk":"1148027367","pt":1439903829794,"mc":[{"id":"1.120089104","rc":[{"atl":[[7.2,2.34]],"id":9480385}],"con":true,"img":false,"tv":12279.18}]}
{"op":"mcm","clk":"1148027373","pt":1439903830002,"mc":[{"id":"1.120089104","rc":[{"atl":[[7.6,9.09]],"id":9480385}],"con":true,"img":false,"tv":12279.18}]}
{"op":"mcm","clk":"1148027657","pt":1439903839829,"mc":[{"id":"1.120089104","rc":[{"atl":[[7.2,0]],"id":9480385}],"con":true,"img":false,"tv":12279.18}]}
{"op":"mcm","clk":"1148027975","pt":1439903854256,"mc":[{"id":"1.120089104","rc":[{"atl":[[7.2,1.4]],"id":9480385}],"con":true,"img":false,"tv":12279.18}]}
{"op":"mcm","clk":"1148028178","pt":1439903862081,"mc":[{"id":"1.120089104","rc":[{"atl":[[7.6,0]],"id":9480385}],"con":true,"img":false,"tv":12279.18}]}
{"op":"mcm","clk":"1148028186","pt":1439903862295,"mc":[{"id":"1.120089104","rc":[{"atl":[[7.2,11]],"id":9480385}],"con":true,"img":false,"tv":12279.18}]}
{"op":"mcm","clk":"1148028364","pt":1439903866463,"mc":[{"id":"1.120089104","rc":[{"atl":[[7.2,13.34]],"id":9480385}],"con":true,"img":false,"tv":12279.18}]}
{"op":"mcm","clk":"1148028941","pt":1439903884437,"mc":[{"id":"1.120089104","rc":[{"atl":[[7.2,11.93]],"id":9480385}],"con":true,"img":false,"tv":12279.18}]}
{"op":"mcm","clk":"1148029255","pt":1439903894613,"mc":[{"id":"1.120089104","rc":[{"atl":[[7.2,2.34]],"id":9480385}],"con":true,"img":false,"tv":12279.18}]}
{"op":"mcm","clk":"1148029258","pt":1439903894718,"mc":[{"id":"1.120089104","rc":[{"atl":[[7.6,9.09]],"id":9480385}],"con":true,"img":false,"tv":12279.18}]}
{"op":"mcm","clk":"1148030043","pt":1439903919944,"mc":[{"id":"1.120089104","rc":[{"atl":[[7.2,0]],"id":9480385}],"con":true,"img":false,"tv":12279.18}]}
{"op":"mcm","clk":"1148030245","pt":1439903927182,"mc":[{"id":"1.120089104","rc":[{"atl":[[7.6,0]],"id":9480385}],"con":true,"img":false,"tv":12279.18}]}
{"op":"mcm","clk":"1148030250","pt":1439903927285,"mc":[{"id":"1.120089104","rc":[{"atl":[[9,7.67]],"id":9480385}],"con":true,"img":false,"tv":12279.18}]}
{"op":"mcm","clk":"1148030265","pt":1439903927765,"mc":[{"id":"1.120089104","rc":[{"atl":[[7.8,3.25]],"id":9480385}],"con":true,"img":false,"tv":12279.18}]}
{"op":"mcm","clk":"1148030321","pt":1439903930099,"mc":[{"id":"1.120089104","rc":[{"atl":[[8.6,4.62]],"id":9480385}],"con":true,"img":false,"tv":12279.18}]}
{"op":"mcm","clk":"1148030324","pt":1439903930308,"mc":[{"id":"1.120089104","rc":[{"atl":[[9.2,2.33]],"id":9480385}],"con":true,"img":false,"tv":12279.18}]}
{"op":"mcm","clk":"1148030729","pt":1439903943048,"mc":[{"id":"1.120089104","rc":[{"atl":[[7.2,2]],"id":9480385}],"con":true,"img":false,"tv":12279.18}]}
{"op":"mcm","clk":"1148030876","pt":1439903947194,"mc":[{"id":"1.120089104","rc":[{"atl":[[7.2,4.34]],"id":9480385}],"con":true,"img":false,"tv":12279.18}]}
{"op":"mcm","clk":"1148031398","pt":1439903962219,"mc":[{"id":"1.120089104","rc":[{"atl":[[9,0]],"id":9480385}],"con":true,"img":false,"tv":12279.18}]}
{"op":"mcm","clk":"1148031401","pt":1439903962328,"mc":[{"id":"1.120089104","rc":[{"atl":[[7,9.87]],"id":9480385}],"con":true,"img":false,"tv":12279.18}]}
{"op":"mcm","clk":"1148031428","pt":1439903963220,"mc":[{"id":"1.120089104","rc":[{"spb":[[1000,58]],"id":9612932}],"con":true,"img":false,"tv":12279.18}]}
{"op":"mcm","clk":"1148040982","pt":1439903974693,"mc":[{"id":"1.120089104","rc":[{"atl":[[7.2,2]],"id":9480385}],"con":true,"img":false,"tv":12279.18}]}
{"op":"mcm","clk":"1148041723","pt":1439904000206,"mc":[{"id":"1.120089104","rc":[{"atl":[[7,0]],"id":9480385}],"con":true,"img":false,"tv":12279.18}]}
{"op":"mcm","clk":"1148041725","pt":1439904000272,"mc":[{"id":"1.120089104","rc":[{"atl":[[7.2,11.59]],"id":9480385}],"con":true,"img":false,"tv":12279.18}]}
{"op":"mcm","clk":"1148041776","pt":1439904002010,"mc":[{"id":"1.120089104","rc":[{"atl":[[7.2,13.93]],"id":9480385}],"con":true,"img":false,"tv":12279.18}]}
{"op":"mcm","clk":"1148041971","pt":1439904008893,"mc":[{"id":"1.120089104","rc":[{"atl":[[7.2,11.93]],"id":9480385}],"con":true,"img":false,"tv":12279.18}]}
{"op":"mcm","clk":"1148042782","pt":1439904033130,"mc":[{"id":"1.120089104","rc":[{"spn":1.16,"spf":1.05,"id":9612932},{"atl":[[7.2,2.34]],"id":9480385}],"con":true,"img":false,"tv":12279.18}]}
{"op":"mcm","clk":"1148042786","pt":1439904033236,"mc":[{"id":"1.120089104","rc":[{"atl":[[7.6,9.09]],"id":9480385}],"con":true,"img":false,"tv":12279.18}]}
{"op":"mcm","clk":"1148042939","pt":1439904039151,"mc":[{"id":"1.120089104","rc":[{"trd":[[1.18,2881.29]],"ltp":1.18,"tv":2881.29,"id":9612932},{"atl":[[1.18,354.2]],"id":9612932}],"con":true,"img":false,"tv":12352.28}]}
{"op":"mcm","clk":"1148042980","pt":1439904040095,"mc":[{"id":"1.120089104","rc":[{"atl":[[7.2,4.33]],"id":9480385}],"con":true,"img":false,"tv":12352.28}]}
{"op":"mcm","clk":"1148043491","pt":1439904056897,"mc":[{"id":"1.120089104","rc":[{"atl":[[7.2,1.99]],"id":9480385}],"con":true,"img":false,"tv":12352.28}]}
{"op":"mcm","clk":"1148043669","pt":1439904065192,"mc":[{"id":"1.120089104","rc":[{"atl":[[7.6,0]],"id":9480385}],"con":true,"img":false,"tv":12352.28}]}
{"op":"mcm","clk":"1148043672","pt":1439904065275,"mc":[{"id":"1.120089104","rc":[{"atl":[[7.2,11.58]],"id":9480385}],"con":true,"img":false,"tv":12352.28}]}
{"op":"mcm","clk":"1148043942","pt":1439904076772,"mc":[{"id":"1.120089104","rc":[{"atb":[[5.8,20.32]],"id":9480385}],"con":true,"img":false,"tv":12352.28}]}
{"op":"mcm","clk":"1148043946","pt":1439904076877,"mc":[{"id":"1.120089104","rc":[{"atb":[[5.8,22.65]],"id":9480385}],"con":true,"img":false,"tv":12352.28}]}
{"op":"mcm","clk":"1148044170","pt":1439904084911,"mc":[{"id":"1.120089104","rc":[{"atl":[[7.2,13.92]],"id":9480385}],"con":true,"img":false,"tv":12352.28}]}
{"op":"mcm","clk":"1148044524","pt":1439904097334,"mc":[{"id":"1.120089104","rc":[{"atl":[[7.2,4.33]],"id":9480385}],"con":true,"img":false,"tv":12352.28}]}
{"op":"mcm","clk":"1148044526","pt":1439904097436,"mc":[{"id":"1.120089104","rc":[{"atl":[[7.6,9.09]],"id":9480385}],"con":true,"img":false,"tv":12352.28}]}
{"op":"mcm","clk":"1148045604","pt":1439904137983,"mc":[{"id":"1.120089104","rc":[{"atl":[[7.2,1.99]],"id":9480385}],"con":true,"img":false,"tv":12352.28}]}
{"op":"mcm","clk":"1148045743","pt":1439904141512,"mc":[{"id":"1.120089104","rc":[{"atb":[[1.15,12082]],"id":9612932}],"con":true,"img":false,"tv":12352.28}]}
{"op":"mcm","clk":"1148046055","pt":1439904153219,"mc":[{"id":"1.120089104","rc":[{"atb":[[1.14,12000]],"id":9612932}],"con":true,"img":false,"tv":12352.28}]}
{"op":"mcm","clk":"1148046180","pt":1439904157898,"mc":[{"id":"1.120089104","rc":[{"atb":[[1.16,541.17]],"id":9612932},{"spn":1.16,"spf":1.05,"id":9612932}],"con":true,"img":false,"tv":12352.28}]}
{"op":"mcm","clk":"1148046285","pt":1439904161845,"mc":[{"id":"1.120089104","rc":[{"atl":[[7.6,0]],"id":9480385}],"con":true,"img":false,"tv":12352.28}]}
{"op":"mcm","clk":"1148046287","pt":1439904161899,"mc":[{"id":"1.120089104","rc":[{"atl":[[7.2,11.58]],"id":9480385}],"con":true,"img":false,"tv":12352.28}]}
{"op":"mcm","clk":"1148046310","pt":1439904162645,"mc":[{"id":"1.120089104","rc":[{"atb":[[1.13,12049.43]],"id":9612932}],"con":true,"img":false,"tv":12352.28}]}
{"op":"mcm","clk":"1148046376","pt":1439904164972,"mc":[{"id":"1.120089104","rc":[{"atl":[[7.2,13.92]],"id":9480385}],"con":true,"img":false,"tv":12352.28}]}
{"op":"mcm","clk":"1148046918","pt":1439904187430,"mc":[{"id":"1.120089104","rc":[{"atb":[[1.17,87.53]],"id":9612932}],"con":true,"img":false,"tv":12352.28}]}
{"op":"mcm","clk":"1148047010","pt":1439904191235,"mc":[{"id":"1.120089104","rc":[{"atb":[[1.17,59.53]],"id":9612932}],"con":true,"img":false,"tv":12352.28}]}
{"op":"mcm","clk":"1148047082","pt":1439904194127,"mc":[{"id":"1.120089104","rc":[{"atl":[[7.2,4.33]],"id":9480385}],"con":true,"img":false,"tv":12352.28}]}
{"op":"mcm","clk":"1148047083","pt":1439904194235,"mc":[{"id":"1.120089104","rc":[{"atl":[[7.6,9.09]],"id":9480385}],"con":true,"img":false,"tv":12352.28}]}
{"op":"mcm","clk":"1148047453","pt":1439904205518,"mc":[{"id":"1.120089104","rc":[{"trd":[[1.18,2941.95]],"ltp":1.18,"tv":2941.95,"id":9612932},{"atl":[[1.18,323.87]],"id":9612932}],"con":true,"img":false,"tv":12412.94}]}
{"op":"mcm","clk":"1148047893","pt":1439904218216,"mc":[{"id":"1.120089104","rc":[{"atl":[[7.2,1.99]],"id":9480385}],"con":true,"img":false,"tv":12412.94}]}
{"op":"mcm","clk":"1148048190","pt":1439904226559,"mc":[{"id":"1.120089104","rc":[{"atl":[[7.6,0]],"id":9480385}],"con":true,"img":false,"tv":12412.94}]}
{"op":"mcm","clk":"1148048194","pt":1439904226661,"mc":[{"id":"1.120089104","rc":[{"atl":[[7.2,11.58]],"id":9480385}],"con":true,"img":false,"tv":12412.94}]}
{"op":"mcm","clk":"1148048828","pt":1439904245726,"mc":[{"id":"1.120089104","rc":[{"atl":[[7.2,13.92]],"id":9480385}],"con":true,"img":false,"tv":12412.94}]}
{"op":"mcm","clk":"1148049398","pt":1439904261635,"mc":[{"id":"1.120089104","rc":[{"atl":[[7.2,4.33]],"id":9480385}],"con":true,"img":false,"tv":12412.94}]}
{"op":"mcm","clk":"1148049402","pt":1439904261741,"mc":[{"id":"1.120089104","rc":[{"atl":[[7.6,9.09]],"id":9480385}],"con":true,"img":false,"tv":12412.94}]}
{"op":"mcm","clk":"1148050608","pt":1439904299091,"mc":[{"id":"1.120089104","rc":[{"atl":[[7.2,1.99]],"id":9480385}],"con":true,"img":false,"tv":12412.94}]}
{"op":"mcm","clk":"1148051521","pt":1439904325437,"mc":[{"id":"1.120089104","rc":[{"atl":[[7.4,3.68]],"id":9480385}],"con":true,"img":false,"tv":12412.94}]}
{"op":"mcm","clk":"1148051554","pt":1439904326348,"mc":[{"id":"1.120089104","rc":[{"atl":[[7.8,1.22]],"id":9480385}],"con":true,"img":false,"tv":12412.94}]}
{"op":"mcm","clk":"1148051783","pt":1439904332658,"mc":[{"id":"1.120089104","rc":[{"atl":[[7.6,0]],"id":9480385}],"con":true,"img":false,"tv":12412.94}]}
{"op":"mcm","clk":"1148051788","pt":1439904332767,"mc":[{"id":"1.120089104","rc":[{"atl":[[7.2,11.58]],"id":9480385}],"con":true,"img":false,"tv":12412.94}]}
{"op":"mcm","clk":"1148052610","pt":1439904356682,"mc":[{"id":"1.120089104","rc":[{"spl":[[1.01,1030.52]],"id":9612932}],"con":true,"img":false,"tv":12412.94}]}
{"op":"mcm","clk":"1148053325","pt":1439904378498,"mc":[{"id":"1.120089104","rc":[{"spn":1.15,"spf":1.05,"id":9612932},{"atl":[[7.4,1.4]],"id":9480385}],"con":true,"img":false,"tv":12412.94}]}
{"op":"mcm","clk":"1148054013","pt":1439904397868,"mc":[{"id":"1.120089104","rc":[{"atl":[[7.2,1.99]],"id":9480385}],"con":true,"img":false,"tv":12412.94}]}
{"op":"mcm","clk":"1148054018","pt":1439904397928,"mc":[{"id":"1.120089104","rc":[{"atl":[[7.6,9.09]],"id":9480385}],"con":true,"img":false,"tv":12412.94}]}
{"op":"mcm","clk":"1148054269","pt":1439904405735,"mc":[{"id":"1.120089104","rc":[{"atl":[[7.4,3.68]],"id":9480385}],"con":true,"img":false,"tv":12412.94}]}
{"op":"mcm","clk":"1148055102","pt":1439904434813,"mc":[{"id":"1.120089104","rc":[{"atl":[[7.6,0]],"id":9480385}],"con":true,"img":false,"tv":12412.94}]}
{"op":"mcm","clk":"1148055105","pt":1439904434919,"mc":[{"id":"1.120089104","rc":[{"atl":[[7.2,11.58]],"id":9480385}],"con":true,"img":false,"tv":12412.94}]}
{"op":"mcm","clk":"1148055910","pt":1439904458974,"mc":[{"id":"1.120089104","rc":[{"atl":[[7.4,1.4]],"id":9480385}],"con":true,"img":false,"tv":12412.94}]}
{"op":"mcm","clk":"1148056123","pt":1439904467222,"mc":[{"id":"1.120089104","rc":[{"atl":[[7.2,1.99]],"id":9480385}],"con":true,"img":false,"tv":12412.94}]}
{"op":"mcm","clk":"1148056132","pt":1439904467332,"mc":[{"id":"1.120089104","rc":[{"atl":[[7.6,9.09]],"id":9480385}],"con":true,"img":false,"tv":12412.94}]}
{"op":"mcm","clk":"1148056656","pt":1439904485879,"mc":[{"id":"1.120089104","rc":[{"atl":[[7.4,3.68]],"id":9480385}],"con":true,"img":false,"tv":12412.94}]}
{"op":"mcm","clk":"1148057026","pt":1439904499452,"mc":[{"id":"1.120089104","rc":[{"atl":[[7.6,0]],"id":9480385}],"con":true,"img":false,"tv":12412.94}]}
{"op":"mcm","clk":"1148057029","pt":1439904499552,"mc":[{"id":"1.120089104","rc":[{"atl":[[7.2,11.58]],"id":9480385}],"con":true,"img":false,"tv":12412.94}]}
{"op":"mcm","clk":"1148057673","pt":1439904528503,"mc":[{"id":"1.120089104","rc":[{"atl":[[5.2,0]],"id":9612932}],"con":true,"img":false,"tv":12412.94}]}
{"op":"mcm","clk":"1148057916","pt":1439904537748,"mc":[{"id":"1.120089104","rc":[{"atl":[[5.2,15]],"id":9612932}],"con":true,"img":false,"tv":12412.94}]}
{"op":"mcm","clk":"1148057953","pt":1439904539283,"mc":[{"id":"1.120089104","rc":[{"atl":[[7.4,1.4]],"id":9480385}],"con":true,"img":false,"tv":12412.94}]}
{"op":"mcm","clk":"1148058681","pt":1439904566373,"mc":[{"id":"1.120089104","rc":[{"atl":[[7.2,1.99]],"id":9480385}],"con":true,"img":false,"tv":12412.94}]}
{"op":"mcm","clk":"1148058683","pt":1439904566480,"mc":[{"id":"1.120089104","rc":[{"atl":[[7.6,9.09],[7.2,4.33]],"id":9480385}],"con":true,"img":false,"tv":12412.94}]}
{"op":"mcm","clk":"1148058918","pt":1439904577355,"mc":[{"id":"1.120089104","rc":[{"trd":[[1.18,2961.95]],"ltp":1.18,"tv":2961.95,"id":9612932},{"atl":[[1.18,313.87]],"id":9612932}],"con":true,"img":false,"tv":12432.94}]}
{"op":"mcm","clk":"1148059873","pt":1439904619561,"mc":[{"id":"1.120089104","rc":[{"atl":[[7.2,1.99]],"id":9480385}],"con":true,"img":false,"tv":12432.94}]}
{"op":"mcm","clk":"1148060433","pt":1439904637837,"mc":[{"id":"1.120089104","rc":[{"atl":[[7.6,0]],"id":9480385}],"con":true,"img":false,"tv":12432.94}]}
{"op":"mcm","clk":"1148060438","pt":1439904638048,"mc":[{"id":"1.120089104","rc":[{"atl":[[7.2,11.58]],"id":9480385}],"con":true,"img":false,"tv":12432.94}]}
{"op":"mcm","clk":"1148060496","pt":1439904639962,"mc":[{"id":"1.120089104","rc":[{"atb":[[4.8,38.5]],"id":9480385}],"con":true,"img":false,"tv":12432.94}]}
{"op":"mcm","clk":"1148060514","pt":1439904640534,"mc":[{"id":"1.120089104","rc":[{"atb":[[4.8,45.74]],"id":9480385}],"con":true,"img":false,"tv":12432.94}]}
{"op":"mcm","clk":"1148060668","pt":1439904646125,"mc":[{"id":"1.120089104","rc":[{"atl":[[7.2,13.92]],"id":9480385}],"con":true,"img":false,"tv":12432.94}]}
{"op":"mcm","clk":"1148061311","pt":1439904670700,"mc":[{"id":"1.120089104","rc":[{"atl":[[7.2,4.33]],"id":9480385}],"con":true,"img":false,"tv":12432.94}]}
{"op":"mcm","clk":"1148061313","pt":1439904670806,"mc":[{"id":"1.120089104","rc":[{"atl":[[7.6,9.09]],"id":9480385}],"con":true,"img":false,"tv":12432.94}]}
{"op":"mcm","clk":"1148061746","pt":1439904688329,"mc":[{"id":"1.120089104","rc":[{"atb":[[5.8,20.32]],"id":9480385}],"con":true,"img":false,"tv":12432.94}]}
{"op":"mcm","clk":"1148061750","pt":1439904688430,"mc":[{"id":"1.120089104","rc":[{"atb":[[5.8,22.65]],"id":9480385}],"con":true,"img":false,"tv":12432.94}]}
{"op":"mcm","clk":"1148061831","pt":1439904692207,"mc":[{"id":"1.120089104","rc":[{"atb":[[4.8,41.55]],"id":9480385}],"con":true,"img":false,"tv":12432.94}]}
{"op":"mcm","clk":"1148061842","pt":1439904692839,"mc":[{"id":"1.120089104","rc":[{"atb":[[4.8,46.35]],"id":9480385}],"con":true,"img":false,"tv":12432.94}]}
{"op":"mcm","clk":"1148061996","pt":1439904699186,"mc":[{"id":"1.120089104","rc":[{"atl":[[7.2,1.99]],"id":9480385}],"con":true,"img":false,"tv":12432.94}]}
{"op":"mcm","clk":"1148062090","pt":1439904703159,"mc":[{"id":"1.120089104","rc":[{"atl":[[7.6,0]],"id":9480385}],"con":true,"img":false,"tv":12432.94}]}
{"op":"mcm","clk":"1148062095","pt":1439904703213,"mc":[{"id":"1.120089104","rc":[{"atl":[[7.2,11.58]],"id":9480385}],"con":true,"img":false,"tv":12432.94}]}
{"op":"mcm","clk":"1148062682","pt":1439904725621,"mc":[{"id":"1.120089104","rc":[{"atl":[[7.2,13.92]],"id":9480385}],"con":true,"img":false,"tv":12432.94}]}
{"op":"mcm","clk":"1148062948","pt":1439904735445,"mc":[{"id":"1.120089104","rc":[{"atl":[[7.2,4.33]],"id":9480385}],"con":true,"img":false,"tv":12432.94}]}
{"op":"mcm","clk":"1148062952","pt":1439904735549,"mc":[{"id":"1.120089104","rc":[{"atl":[[7.6,9.09]],"id":9480385}],"con":true,"img":false,"tv":12432.94}]}
{"op":"mcm","clk":"1148063936","pt":1439904776952,"mc":[{"id":"1.120089104","rc":[{"atl":[[7.2,1.99]],"id":9480385}],"con":true,"img":false,"tv":12432.94}]}
{"op":"mcm","clk":"1148064394","pt":1439904792709,"mc":[{"id":"1.120089104","rc":[{"spl":[[1.01,1060.52]],"id":9612932}],"con":true,"img":false,"tv":12432.94}]}
{"op":"mcm","clk":"1148064614","pt":1439904799388,"mc":[{"id":"1.120089104","rc":[{"atl":[[7.6,0]],"id":9480385}],"con":true,"img":false,"tv":12432.94}]}
{"op":"mcm","clk":"1148064616","pt":1439904799500,"mc":[{"id":"1.120089104","rc":[{"atl":[[7.2,11.58]],"id":9480385}],"con":true,"img":false,"tv":12432.94}]}
{"op":"mcm","clk":"1148064719","pt":1439904802638,"mc":[{"id":"1.120089104","rc":[{"atl":[[7.2,13.92]],"id":9480385}],"con":true,"img":false,"tv":12432.94}]}
{"op":"mcm","clk":"1148065548","pt":1439904831686,"mc":[{"id":"1.120089104","rc":[{"atl":[[7.2,4.33]],"id":9480385}],"con":true,"img":false,"tv":12432.94}]}
{"op":"mcm","clk":"1148065550","pt":1439904831793,"mc":[{"id":"1.120089104","rc":[{"atl":[[7.6,9.09]],"id":9480385}],"con":true,"img":false,"tv":12432.94}]}
{"op":"mcm","clk":"1148066106","pt":1439904854230,"mc":[{"id":"1.120089104","rc":[{"spn":1.15,"spf":1.05,"id":9612932},{"atl":[[7.2,1.99]],"id":9480385}],"con":true,"img":false,"tv":12432.94}]}
{"op":"mcm","clk":"1148075608","pt":1439904867078,"mc":[{"id":"1.120089104","rc":[{"atl":[[7.6,0]],"id":9480385}],"con":true,"img":false,"tv":12432.94}]}
{"op":"mcm","clk":"1148075610","pt":1439904867183,"mc":[{"id":"1.120089104","rc":[{"atl":[[7.2,11.58]],"id":9480385}],"con":true,"img":false,"tv":12432.94}]}
{"op":"mcm","clk":"1148076005","pt":1439904880707,"mc":[{"id":"1.120089104","rc":[{"atl":[[7.2,13.92]],"id":9480385}],"con":true,"img":false,"tv":12432.94}]}
{"op":"mcm","clk":"1148076410","pt":1439904899054,"mc":[{"id":"1.120089104","rc":[{"atb":[[4.5,49.45]],"id":9480385}],"con":true,"img":false,"tv":12432.94}]}
{"op":"mcm","clk":"1148076499","pt":1439904903287,"mc":[{"id":"1.120089104","rc":[{"atb":[[1.1,278.43]],"id":9612932}],"con":true,"img":false,"tv":12432.94}]}
{"op":"mcm","clk":"1148076558","pt":1439904905052,"mc":[{"id":"1.120089104","rc":[{"atl":[[7.2,4.33]],"id":9480385}],"con":true,"img":false,"tv":12432.94}]}
{"op":"mcm","clk":"1148076560","pt":1439904905159,"mc":[{"id":"1.120089104","rc":[{"atl":[[7.6,9.09]],"id":9480385}],"con":true,"img":false,"tv":12432.94}]}
{"op":"mcm","clk":"1148077372","pt":1439904933882,"mc":[{"id":"1.120089104","rc":[{"atl":[[7.2,1.99]],"id":9480385}],"con":true,"img":false,"tv":12432.94}]}
{"op":"mcm","clk":"1148077585","pt":1439904943006,"mc":[{"id":"1.120089104","rc":[{"atl":[[7.6,0]],"id":9480385}],"con":true,"img":false,"tv":12432.94}]}
{"op":"mcm","clk":"1148077590","pt":1439904943215,"mc":[{"id":"1.120089104","rc":[{"atl":[[7.2,11.58]],"id":9480385}],"con":true,"img":false,"tv":12432.94}]}
{"op":"mcm","clk":"1148078028","pt":1439904959169,"mc":[{"id":"1.120089104","rc":[{"atl":[[7.2,13.92]],"id":9480385}],"con":true,"img":false,"tv":12432.94}]}
{"op":"mcm","clk":"1148078485","pt":1439904974696,"mc":[{"id":"1.120089104","rc":[{"atl":[[7.2,4.33]],"id":9480385}],"con":true,"img":false,"tv":12432.94}]}
{"op":"mcm","clk":"1148078488","pt":1439904974755,"mc":[{"id":"1.120089104","rc":[{"atl":[[7.6,9.09]],"id":9480385}],"con":true,"img":false,"tv":12432.94}]}
{"op":"mcm","clk":"1148079593","pt":1439905011724,"mc":[{"id":"1.120089104","rc":[{"atl":[[7.2,1.99]],"id":9480385}],"con":true,"img":false,"tv":12432.94}]}
{"op":"mcm","clk":"1148080278","pt":1439905037915,"mc":[{"id":"1.120089104","rc":[{"atl":[[7.6,0]],"id":9480385}],"con":true,"img":false,"tv":12432.94}]}
{"op":"mcm","clk":"1148080283","pt":1439905038124,"mc":[{"id":"1.120089104","rc":[{"atl":[[7.2,11.58],[7.4,3.68]],"id":9480385}],"con":true,"img":false,"tv":12432.94}]}
{"op":"mcm","clk":"1148080860","pt":1439905063664,"mc":[{"id":"1.120089104","rc":[{"atl":[[7.4,1.4]],"id":9480385}],"con":true,"img":false,"tv":12432.94}]}
{"op":"mcm","clk":"1148081002","pt":1439905070259,"mc":[{"id":"1.120089104","rc":[{"atl":[[7.2,1.99]],"id":9480385}],"con":true,"img":false,"tv":12432.94}]}
{"op":"mcm","clk":"1148081008","pt":1439905070365,"mc":[{"id":"1.120089104","rc":[{"atl":[[7.6,9.09]],"id":9480385}],"con":true,"img":false,"tv":12432.94}]}
{"op":"mcm","clk":"1148081594","pt":1439905089601,"mc":[{"id":"1.120089104","rc":[{"atl":[[7.4,3.68]],"id":9480385}],"con":true,"img":false,"tv":12432.94}]}
{"op":"mcm","clk":"1148081918","pt":1439905102914,"mc":[{"id":"1.120089104","rc":[{"atl":[[7.6,0]],"id":9480385}],"con":true,"img":false,"tv":12432.94}]}
{"op":"mcm","clk":"1148081921","pt":1439905102973,"mc":[{"id":"1.120089104","rc":[{"atl":[[7.2,11.58]],"id":9480385}],"con":true,"img":false,"tv":12432.94}]}
{"op":"mcm","clk":"1148082842","pt":1439905141118,"mc":[{"id":"1.120089104","rc":[{"atl":[[7.4,1.4]],"id":9480385}],"con":true,"img":false,"tv":12432.94}]}
{"op":"mcm","clk":"1148083537","pt":1439905167483,"mc":[{"id":"1.120089104","rc":[{"atl":[[7.2,13.92]],"id":9480385}],"con":true,"img":false,"tv":12432.94}]}
{"op":"mcm","clk":"1148083619","pt":1439905171021,"mc":[{"id":"1.120089104","rc":[{"atl":[[7.2,4.33]],"id":9480385}],"con":true,"img":false,"tv":12432.94}]}
{"op":"mcm","clk":"1148083624","pt":1439905171124,"mc":[{"id":"1.120089104","rc":[{"atl":[[7.6,9.09]],"id":9480385}],"con":true,"img":false,"tv":12432.94}]}
{"op":"mcm","clk":"1148085005","pt":1439905218949,"mc":[{"id":"1.120089104","rc":[{"atl":[[7.2,1.99]],"id":9480385}],"con":true,"img":false,"tv":12432.94}]}
{"op":"mcm","clk":"1148085776","pt":1439905241652,"mc":[{"id":"1.120089104","rc":[{"atl":[[7.6,0]],"id":9480385}],"con":true,"img":false,"tv":12432.94}]}
{"op":"mcm","clk":"1148085781","pt":1439905241759,"mc":[{"id":"1.120089104","rc":[{"atl":[[7.2,11.58]],"id":9480385}],"con":true,"img":false,"tv":12432.94}]}
{"op":"mcm","clk":"1148085858","pt":1439905244498,"mc":[{"id":"1.120089104","rc":[{"atl":[[7.2,13.92]],"id":9480385}],"con":true,"img":false,"tv":12432.94}]}
{"op":"mcm","clk":"1148086864","pt":1439905273664,"mc":[{"id":"1.120089104","rc":[{"atl":[[7.2,4.33]],"id":9480385}],"con":true,"img":false,"tv":12432.94}]}
{"op":"mcm","clk":"1148086867","pt":1439905273869,"mc":[{"id":"1.120089104","rc":[{"atl":[[7.6,9.09]],"id":9480385}],"con":true,"img":false,"tv":12432.94}]}
{"op":"mcm","clk":"1148087658","pt":1439905295913,"mc":[{"id":"1.120089104","rc":[{"atl":[[7.2,1.99]],"id":9480385}],"con":true,"img":false,"tv":12432.94}]}
{"op":"mcm","clk":"1148087894","pt":1439905301669,"mc":[{"id":"1.120089104","rc":[{"atb":[[5.8,20.32]],"id":9480385}],"con":true,"img":false,"tv":12432.94}]}
{"op":"mcm","clk":"1148087897","pt":1439905301775,"mc":[{"id":"1.120089104","rc":[{"atb":[[5.8,22.65]],"id":9480385}],"con":true,"img":false,"tv":12432.94}]}
{"op":"mcm","clk":"1148088031","pt":1439905305993,"mc":[{"id":"1.120089104","rc":[{"atl":[[7.6,0]],"id":9480385}],"con":true,"img":false,"tv":12432.94}]}
{"op":"mcm","clk":"1148088034","pt":1439905306095,"mc":[{"id":"1.120089104","rc":[{"atl":[[7.2,11.58]],"id":9480385}],"con":true,"img":false,"tv":12432.94}]}
{"op":"mcm","clk":"1148088570","pt":1439905322302,"mc":[{"id":"1.120089104","rc":[{"atl":[[7.2,13.92]],"id":9480385}],"con":true,"img":false,"tv":12432.94}]}
{"op":"mcm","clk":"1148089153","pt":1439905338126,"mc":[{"id":"1.120089104","rc":[{"atl":[[7.2,4.33]],"id":9480385}],"con":true,"img":false,"tv":12432.94}]}
{"op":"mcm","clk":"1148089157","pt":1439905338228,"mc":[{"id":"1.120089104","rc":[{"atl":[[7.6,9.09]],"id":9480385}],"con":true,"img":false,"tv":12432.94}]}
{"op":"mcm","clk":"1148090529","pt":1439905373815,"mc":[{"id":"1.120089104","rc":[{"atl":[[7.2,1.99]],"id":9480385}],"con":true,"img":false,"tv":12432.94}]}
{"op":"mcm","clk":"1148091213","pt":1439905393619,"mc":[{"id":"1.120089104","rc":[{"atb":[[1.1,1533.85]],"id":9612932}],"con":true,"img":false,"tv":12432.94}]}
{"op":"mcm","clk":"1148091251","pt":1439905394636,"mc":[{"id":"1.120089104","rc":[{"atb":[[4.7,49.63]],"id":9480385}],"con":true,"img":false,"tv":12432.94}]}
{"op":"mcm","clk":"1148091406","pt":1439905399406,"mc":[{"id":"1.120089104","rc":[{"atl":[[7.4,3.68]],"id":9480385}],"con":true,"img":false,"tv":12432.94}]}
{"op":"mcm","clk":"1148091479","pt":1439905401617,"mc":[{"id":"1.120089104","rc":[{"atl":[[7.6,0]],"id":9480385}],"con":true,"img":false,"tv":12432.94}]}
{"op":"mcm","clk":"1148091485","pt":1439905401724,"mc":[{"id":"1.120089104","rc":[{"atl":[[7.2,11.58]],"id":9480385}],"con":true,"img":false,"tv":12432.94}]}
{"op":"mcm","clk":"1148093252","pt":1439905451072,"mc":[{"id":"1.120089104","rc":[{"atl":[[7.4,1.4]],"id":9480385}],"con":true,"img":false,"tv":12432.94}]}
{"op":"mcm","clk":"1148093921","pt":1439905469135,"mc":[{"id":"1.120089104","rc":[{"atl":[[7.2,1.99]],"id":9480385}],"con":true,"img":false,"tv":12432.94}]}
{"op":"mcm","clk":"1148093927","pt":1439905469237,"mc":[{"id":"1.120089104","rc":[{"atl":[[7.6,9.09]],"id":9480385}],"con":true,"img":false,"tv":12432.94}]}
{"op":"mcm","clk":"1148094224","pt":1439905477482,"mc":[{"id":"1.120089104","rc":[{"atl":[[7.4,3.68]],"id":9480385}],"con":true,"img":false,"tv":12432.94}]}
{"op":"mcm","clk":"1148094540","pt":1439905484628,"mc":[{"id":"1.120089104","rc":[{"atb":[[4.8,40.17]],"id":9480385}],"con":true,"img":false,"tv":12432.94}]}
{"op":"mcm","clk":"1148094549","pt":1439905484845,"mc":[{"id":"1.120089104","rc":[{"atb":[[4.8,47.34]],"id":9480385}],"con":true,"img":false,"tv":12432.94}]}
{"op":"mcm","clk":"1148095247","pt":1439905503266,"mc":[{"id":"1.120089104","rc":[{"atl":[[7.6,0]],"id":9480385}],"con":true,"img":false,"tv":12432.94}]}
{"op":"mcm","clk":"1148095254","pt":1439905503327,"mc":[{"id":"1.120089104","rc":[{"atl":[[7.2,11.58]],"id":9480385}],"con":true,"img":false,"tv":12432.94}]}
{"op":"mcm","clk":"1148095891","pt":1439905519329,"mc":[{"id":"1.120089104","rc":[{"atl":[[1.21,117.74]],"id":9612932}],"con":true,"img":false,"tv":12432.94}]}
{"op":"mcm","clk":"1148096295","pt":1439905529012,"mc":[{"id":"1.120089104","rc":[{"atl":[[7.4,1.4]],"id":9480385}],"con":true,"img":false,"tv":12432.94}]}
{"op":"mcm","clk":"1148096629","pt":1439905538604,"mc":[{"id":"1.120089104","rc":[{"atl":[[7.2,1.99]],"id":9480385}],"con":true,"img":false,"tv":12432.94}]}
{"op":"mcm","clk":"1148096635","pt":1439905538709,"mc":[{"id":"1.120089104","rc":[{"atl":[[7.6,9.09]],"id":9480385}],"con":true,"img":false,"tv":12432.94}]}
{"op":"mcm","clk":"1148097256","pt":1439905554502,"mc":[{"id":"1.120089104","rc":[{"atl":[[7.4,3.68]],"id":9480385}],"con":true,"img":false,"tv":12432.94}]}
{"op":"mcm","clk":"1148097996","pt":1439905571061,"mc":[{"id":"1.120089104","rc":[{"atl":[[7.6,0]],"id":9480385}],"con":true,"img":false,"tv":12432.94}]}
{"op":"mcm","clk":"1148098001","pt":1439905571167,"mc":[{"id":"1.120089104","rc":[{"atl":[[7.2,11.58]],"id":9480385}],"con":true,"img":false,"tv":12432.94}]}
{"op":"mcm","clk":"1148099412","pt":1439905605975,"mc":[{"id":"1.120089104","rc":[{"atl":[[7.4,1.4]],"id":9480385}],"con":true,"img":false,"tv":12432.94}]}
{"op":"mcm","clk":"1148100325","pt":1439905631617,"mc":[{"id":"1.120089104","rc":[{"atl":[[7.2,13.92]],"id":9480385}],"con":true,"img":false,"tv":12432.94}]}
{"op":"mcm","clk":"1148100447","pt":1439905634751,"mc":[{"id":"1.120089104","rc":[{"atl":[[7.2,4.33]],"id":9480385}],"con":true,"img":false,"tv":12432.94}]}
{"op":"mcm","clk":"1148100450","pt":1439905634860,"mc":[{"id":"1.120089104","rc":[{"atl":[[7.6,9.09]],"id":9480385}],"con":true,"img":false,"tv":12432.94}]}
{"op":"mcm","clk":"1148102209","pt":1439905681433,"mc":[{"id":"1.120089104","rc":[{"atl":[[7.2,1.99]],"id":9480385}],"con":true,"img":false,"tv":12432.94}]}
{"op":"mcm","clk":"1148102759","pt":1439905697889,"mc":[{"id":"1.120089104","rc":[{"atl":[[7.6,0]],"id":9480385}],"con":true,"img":false,"tv":12432.94}]}
{"op":"mcm","clk":"1148102763","pt":1439905697991,"mc":[{"id":"1.120089104","rc":[{"atl":[[7.2,11.58]],"id":9480385}],"con":true,"img":false,"tv":12432.94}]}
{"op":"mcm","clk":"1148103115","pt":1439905706189,"mc":[{"id":"1.120089104","rc":[{"atl":[[7.2,13.92]],"id":9480385}],"con":true,"img":false,"tv":12432.94}]}
{"op":"mcm","clk":"1148103958","pt":1439905729946,"mc":[{"id":"1.120089104","rc":[{"atl":[[7.2,4.33]],"id":9480385}],"con":true,"img":false,"tv":12432.94}]}
{"op":"mcm","clk":"1148103960","pt":1439905730052,"mc":[{"id":"1.120089104","rc":[{"atl":[[7.6,9.09]],"id":9480385}],"con":true,"img":false,"tv":12432.94}]}
{"op":"mcm","clk":"1148104842","pt":1439905756001,"mc":[{"id":"1.120089104","rc":[{"atl":[[7.2,1.99]],"id":9480385}],"con":true,"img":false,"tv":12432.94}]}
{"op":"mcm","clk":"1148114372","pt":1439905767030,"mc":[{"id":"1.120089104","rc":[{"atl":[[7.6,0]],"id":9480385}],"con":true,"img":false,"tv":12432.94}]}
{"op":"mcm","clk":"1148114378","pt":1439905767134,"mc":[{"id":"1.120089104","rc":[{"atl":[[7.2,11.58]],"id":9480385}],"con":true,"img":false,"tv":12432.94}]}
{"op":"mcm","clk":"1148114780","pt":1439905781592,"mc":[{"id":"1.120089104","rc":[{"atl":[[7.2,13.92]],"id":9480385}],"con":true,"img":false,"tv":12432.94}]}
{"op":"mcm","clk":"1148115349","pt":1439905802470,"mc":[{"id":"1.120089104","rc":[{"atl":[[7.2,4.33]],"id":9480385}],"con":true,"img":false,"tv":12432.94}]}
{"op":"mcm","clk":"1148115351","pt":1439905802576,"mc":[{"id":"1.120089104","rc":[{"atl":[[7.6,9.09]],"id":9480385}],"con":true,"img":false,"tv":12432.94}]}
{"op":"mcm","clk":"1148116347","pt":1439905831362,"mc":[{"id":"1.120089104","rc":[{"atl":[[7.2,1.99]],"id":9480385}],"con":true,"img":false,"tv":12432.94}]}
{"op":"mcm","clk":"1148116462","pt":1439905834509,"mc":[{"id":"1.120089104","rc":[{"atl":[[7.6,0]],"id":9480385}],"con":true,"img":false,"tv":12432.94}]}
{"op":"mcm","clk":"1148116466","pt":1439905834609,"mc":[{"id":"1.120089104","rc":[{"atl":[[7.2,11.58]],"id":9480385}],"con":true,"img":false,"tv":12432.94}]}
{"op":"mcm","clk":"1148117049","pt":1439905856126,"mc":[{"id":"1.120089104","rc":[{"atl":[[7.2,13.92]],"id":9480385}],"con":true,"img":false,"tv":12432.94}]}
{"op":"mcm","clk":"1148117357","pt":1439905866246,"mc":[{"id":"1.120089104","rc":[{"atl":[[7.2,4.33]],"id":9480385}],"con":true,"img":false,"tv":12432.94}]}
{"op":"mcm","clk":"1148117362","pt":1439905866350,"mc":[{"id":"1.120089104","rc":[{"atl":[[7.6,9.09]],"id":9480385}],"con":true,"img":false,"tv":12432.94}]}
{"op":"mcm","clk":"1148118597","pt":1439905907614,"mc":[{"id":"1.120089104","rc":[{"atl":[[7.2,1.99]],"id":9480385}],"con":true,"img":false,"tv":12432.94}]}
{"op":"mcm","clk":"1148118607","pt":1439905907991,"mc":[{"id":"1.120089104","rc":[{"atb":[[5.8,20.32]],"id":9480385}],"con":true,"img":false,"tv":12432.94}]}
{"op":"mcm","clk":"1148118612","pt":1439905908093,"mc":[{"id":"1.120089104","rc":[{"atb":[[5.8,22.65]],"id":9480385}],"con":true,"img":false,"tv":12432.94}]}
{"op":"mcm","clk":"1148119198","pt":1439905929789,"mc":[{"id":"1.120089104","rc":[{"atl":[[7.6,0]],"id":9480385}],"con":true,"img":false,"tv":12432.94}]}
{"op":"mcm","clk":"1148119204","pt":1439905929891,"mc":[{"id":"1.120089104","rc":[{"atl":[[7.2,11.58]],"id":9480385}],"con":true,"img":false,"tv":12432.94}]}
{"op":"mcm","clk":"1148119305","pt":1439905933311,"mc":[{"id":"1.120089104","rc":[{"atl":[[7.2,13.92]],"id":9480385}],"con":true,"img":false,"tv":12432.94}]}
{"op":"mcm","clk":"1148120120","pt":1439905962110,"mc":[{"id":"1.120089104","rc":[{"atl":[[7.2,4.33]],"id":9480385}],"con":true,"img":false,"tv":12432.94}]}
{"op":"mcm","clk":"1148120122","pt":1439905962212,"mc":[{"id":"1.120089104","rc":[{"atl":[[7.6,9.09]],"id":9480385}],"con":true,"img":false,"tv":12432.94}]}
{"op":"mcm","clk":"1148120675","pt":1439905982884,"mc":[{"id":"1.120089104","rc":[{"atl":[[7.2,1.99]],"id":9480385}],"con":true,"img":false,"tv":12432.94}]}
{"op":"mcm","clk":"1148120958","pt":1439905994326,"mc":[{"id":"1.120089104","rc":[{"atl":[[7.6,0]],"id":9480385}],"con":true,"img":false,"tv":12432.94}]}
{"op":"mcm","clk":"1148120961","pt":1439905994430,"mc":[{"id":"1.120089104","rc":[{"atl":[[7.2,11.58]],"id":9480385}],"con":true,"img":false,"tv":12432.94}]}
{"op":"mcm","clk":"1148121239","pt":1439906006450,"mc":[{"id":"1.120089104","rc":[{"trd":[[1.18,2987.95]],"ltp":1.18,"tv":2987.95,"id":9612932},{"atl":[[1.18,300.87]],"id":9612932}],"con":true,"img":false,"tv":12458.94}]}
{"op":"mcm","clk":"1148121273","pt":1439906007735,"mc":[{"id":"1.120089104","rc":[{"atl":[[7.2,13.92]],"id":9480385}],"con":true,"img":false,"tv":12458.94}]}
{"op":"mcm","clk":"1148121706","pt":1439906022365,"mc":[{"id":"1.120089104","rc":[{"atb":[[1.13,12034.43]],"id":9612932}],"con":true,"img":false,"tv":12458.94}]}
{"op":"mcm","clk":"1148121810","pt":1439906026586,"mc":[{"id":"1.120089104","rc":[{"atl":[[7.2,4.33]],"id":9480385}],"con":true,"img":false,"tv":12458.94}]}
{"op":"mcm","clk":"1148121811","pt":1439906026686,"mc":[{"id":"1.120089104","rc":[{"atl":[[7.6,9.09]],"id":9480385}],"con":true,"img":false,"tv":12458.94}]}
{"op":"mcm","clk":"1148121874","pt":1439906028853,"mc":[{"id":"1.120089104","rc":[{"atb":[[1.13,12024.43]],"id":9612932}],"con":true,"img":false,"tv":12458.94}]}
{"op":"mcm","clk":"1148121879","pt":1439906028959,"mc":[{"id":"1.120089104","rc":[{"atb":[[1.17,69.53]],"id":9612932}],"con":true,"img":false,"tv":12458.94}]}
{"op":"mcm","clk":"1148122687","pt":1439906057793,"mc":[{"id":"1.120089104","rc":[{"spn":1.15,"spf":1.05,"id":9612932},{"atl":[[7.2,1.99]],"id":9480385}],"con":true,"img":false,"tv":12458.94}]}
{"op":"mcm","clk":"1148122830","pt":1439906062615,"mc":[{"id":"1.120089104","rc":[{"atl":[[7.6,0]],"id":9480385}],"con":true,"img":false,"tv":12458.94}]}
{"op":"mcm","clk":"1148122836","pt":1439906062724,"mc":[{"id":"1.120089104","rc":[{"atl":[[7.2,11.58]],"id":9480385}],"con":true,"img":false,"tv":12458.94}]}
{"op":"mcm","clk":"1148123367","pt":1439906083595,"mc":[{"id":"1.120089104","rc":[{"atl":[[7.2,13.92]],"id":9480385}],"con":true,"img":false,"tv":12458.94}]}
{"op":"mcm","clk":"1148123678","pt":1439906096009,"mc":[{"id":"1.120089104","rc":[{"atl":[[7.2,4.33]],"id":9480385}],"con":true,"img":false,"tv":12458.94}]}
{"op":"mcm","clk":"1148123682","pt":1439906096114,"mc":[{"id":"1.120089104","rc":[{"atl":[[7.6,9.09]],"id":9480385}],"con":true,"img":false,"tv":12458.94}]}
{"op":"mcm","clk":"1148124784","pt":1439906133193,"mc":[{"id":"1.120089104","rc":[{"atl":[[7.2,1.99]],"id":9480385}],"con":true,"img":false,"tv":12458.94}]}
{"op":"mcm","clk":"1148124798","pt":1439906133621,"mc":[{"id":"1.120089104","rc":[{"trd":[[1.18,3090.61]],"ltp":1.18,"tv":3090.61,"id":9612932},{"atl":[[1.18,249.54]],"id":9612932}],"con":true,"img":false,"tv":12561.6}]}
{"op":"mcm","clk":"1148125461","pt":1439906158455,"mc":[{"id":"1.120089104","rc":[{"atl":[[7.4,3.68]],"id":9480385}],"con":true,"img":false,"tv":12561.6}]}
{"op":"mcm","clk":"1148125565","pt":1439906161982,"mc":[{"id":"1.120089104","rc":[{"atl":[[7.6,0]],"id":9480385}],"con":true,"img":false,"tv":12561.6}]}
{"op":"mcm","clk":"1148125571","pt":1439906162089,"mc":[{"id":"1.120089104","rc":[{"atl":[[7.2,11.58]],"id":9480385}],"con":true,"img":false,"tv":12561.6}]}
{"op":"mcm","clk":"1148126817","pt":1439906207838,"mc":[{"id":"1.120089104","rc":[{"atl":[[7.4,1.4]],"id":9480385}],"con":true,"img":false,"tv":12561.6}]}
{"op":"mcm","clk":"1148127289","pt":1439906225270,"mc":[{"id":"1.120089104","rc":[{"atl":[[7.2,1.99]],"id":9480385}],"con":true,"img":false,"tv":12561.6}]}
{"op":"mcm","clk":"1148127297","pt":1439906225373,"mc":[{"id":"1.120089104","rc":[{"atl":[[7.6,9.09]],"id":9480385}],"con":true,"img":false,"tv":12561.6}]}
{"op":"mcm","clk":"1148127519","pt":1439906233702,"mc":[{"id":"1.120089104","rc":[{"atl":[[7.4,3.68]],"id":9480385}],"con":true,"img":false,"tv":12561.6}]}
{"op":"mcm","clk":"1148128182","pt":1439906257822,"mc":[{"id":"1.120089104","rc":[{"atl":[[7.6,0]],"id":9480385}],"con":true,"img":false,"tv":12561.6}]}
{"op":"mcm","clk":"1148128190","pt":1439906257933,"mc":[{"id":"1.120089104","rc":[{"atl":[[7.2,11.58]],"id":9480385}],"con":true,"img":false,"tv":12561.6}]}
{"op":"mcm","clk":"1148128916","pt":1439906283534,"mc":[{"id":"1.120089104","rc":[{"atl":[[7.4,1.4]],"id":9480385}],"con":true,"img":false,"tv":12561.6}]}
{"op":"mcm","clk":"1148129079","pt":1439906289738,"mc":[{"id":"1.120089104","rc":[{"atl":[[7.2,1.99]],"id":9480385}],"con":true,"img":false,"tv":12561.6}]}
{"op":"mcm","clk":"1148129080","pt":1439906289845,"mc":[{"id":"1.120089104","rc":[{"atl":[[7.6,9.09]],"id":9480385}],"con":true,"img":false,"tv":12561.6}]}
{"op":"mcm","clk":"1148129648","pt":1439906308086,"mc":[{"id":"1.120089104","rc":[{"atl":[[7.4,3.68]],"id":9480385}],"con":true,"img":false,"tv":12561.6}]}
{"op":"mcm","clk":"1148130084","pt":1439906321798,"mc":[{"id":"1.120089104","rc":[{"atl":[[7.6,0]],"id":9480385}],"con":true,"img":false,"tv":12561.6}]}
{"op":"mcm","clk":"1148130086","pt":1439906321906,"mc":[{"id":"1.120089104","rc":[{"atl":[[7.2,11.58]],"id":9480385}],"con":true,"img":false,"tv":12561.6}]}
{"op":"mcm","clk":"1148131083","pt":1439906357918,"mc":[{"id":"1.120089104","rc":[{"atl":[[7.4,1.4]],"id":9480385}],"con":true,"img":false,"tv":12561.6}]}
{"op":"mcm","clk":"1148131891","pt":1439906383867,"mc":[{"id":"1.120089104","rc":[{"atl":[[7.2,13.92]],"id":9480385}],"con":true,"img":false,"tv":12561.6}]}
{"op":"mcm","clk":"1148132147","pt":1439906392864,"mc":[{"id":"1.120089104","rc":[{"atl":[[7.2,4.33]],"id":9480385}],"con":true,"img":false,"tv":12561.6}]}
{"op":"mcm","clk":"1148132162","pt":1439906393038,"mc":[{"id":"1.120089104","rc":[{"atl":[[7.6,9.09]],"id":9480385}],"con":true,"img":false,"tv":12561.6}]}
{"op":"mcm","clk":"1148133520","pt":1439906433738,"mc":[{"id":"1.120089104","rc":[{"atl":[[7.2,1.99]],"id":9480385}],"con":true,"img":false,"tv":12561.6}]}
{"op":"mcm","clk":"1148134426","pt":1439906458641,"mc":[{"id":"1.120089104","rc":[{"atl":[[7.4,3.68]],"id":9480385}],"con":true,"img":false,"tv":12561.6}]}
{"op":"mcm","clk":"1148134542","pt":1439906461374,"mc":[{"id":"1.120089104","rc":[{"atl":[[7.6,0]],"id":9480385}],"con":true,"img":false,"tv":12561.6}]}
{"op":"mcm","clk":"1148134548","pt":1439906461481,"mc":[{"id":"1.120089104","rc":[{"atl":[[7.2,11.58]],"id":9480385}],"con":true,"img":false,"tv":12561.6}]}
{"op":"mcm","clk":"1148136003","pt":1439906506766,"mc":[{"id":"1.120089104","rc":[{"atl":[[7.4,1.4]],"id":9480385}],"con":true,"img":false,"tv":12561.6}]}
{"op":"mcm","clk":"1148136028","pt":1439906507397,"mc":[{"id":"1.120089104","rc":[{"atb":[[5.8,20.32]],"id":9480385}],"con":true,"img":false,"tv":12561.6}]}
{"op":"mcm","clk":"1148136030","pt":1439906507455,"mc":[{"id":"1.120089104","rc":[{"atb":[[5.8,22.65]],"id":9480385}],"con":true,"img":false,"tv":12561.6}]}
{"op":"mcm","clk":"1148136649","pt":1439906526130,"mc":[{"id":"1.120089104","rc":[{"atl":[[7.2,1.99]],"id":9480385}],"con":true,"img":false,"tv":12561.6}]}
{"op":"mcm","clk":"1148136653","pt":1439906526234,"mc":[{"id":"1.120089104","rc":[{"atl":[[7.6,9.09]],"id":9480385}],"con":true,"img":false,"tv":12561.6}]}
{"op":"mcm","clk":"1148136842","pt":1439906531567,"mc":[{"id":"1.120089104","rc":[{"atl":[[7.4,3.68]],"id":9480385}],"con":true,"img":false,"tv":12561.6}]}
{"op":"mcm","clk":"1148137792","pt":1439906558352,"mc":[{"id":"1.120089104","rc":[{"atl":[[7.6,0]],"id":9480385}],"con":true,"img":false,"tv":12561.6}]}
{"op":"mcm","clk":"1148137795","pt":1439906558456,"mc":[{"id":"1.120089104","rc":[{"atl":[[7.2,11.58]],"id":9480385}],"con":true,"img":false,"tv":12561.6}]}
{"op":"mcm","clk":"1148138659","pt":1439906579733,"mc":[{"id":"1.120089104","rc":[{"atl":[[7.4,1.4]],"id":9480385}],"con":true,"img":false,"tv":12561.6}]}
{"op":"mcm","clk":"1148139126","pt":1439906590485,"mc":[{"id":"1.120089104","rc":[{"atl":[[7.2,1.99]],"id":9480385}],"con":true,"img":false,"tv":12561.6}]}
{"op":"mcm","clk":"1148139134","pt":1439906590598,"mc":[{"id":"1.120089104","rc":[{"atl":[[7.6,9.09]],"id":9480385}],"con":true,"img":false,"tv":12561.6}]}
{"op":"mcm","clk":"1148139662","pt":1439906602602,"mc":[{"id":"1.120089104","rc":[{"trd":[[1.17,538.62]],"ltp":1.17,"tv":538.62,"id":9612932},{"atb":[[1.17,67.53]],"id":9612932}],"con":true,"img":false,"tv":12565.6}]}
{"op":"mcm","clk":"1148139692","pt":1439906603613,"mc":[{"id":"1.120089104","rc":[{"atl":[[7.4,3.68]],"id":9480385}],"con":true,"img":false,"tv":12565.6}]}
{"op":"mcm","clk":"1148140437","pt":1439906622531,"mc":[{"id":"1.120089104","rc":[{"atl":[[7.6,0]],"id":9480385}],"con":true,"img":false,"tv":12565.6}]}
{"op":"mcm","clk":"1148140442","pt":1439906622583,"mc":[{"id":"1.120089104","rc":[{"atl":[[7.2,11.58]],"id":9480385}],"con":true,"img":false,"tv":12565.6}]}
{"op":"mcm","clk":"1148141684","pt":1439906651766,"mc":[{"id":"1.120089104","rc":[{"atl":[[7.4,1.4]],"id":9480385}],"con":true,"img":false,"tv":12565.6}]}
{"op":"mcm","clk":"1148141975","pt":1439906658463,"mc":[{"id":"1.120089104","rc":[{"atl":[[7.2,1.99]],"id":9480385}],"con":true,"img":false,"tv":12565.6}]}
{"op":"mcm","clk":"1148141980","pt":1439906658673,"mc":[{"id":"1.120089104","rc":[{"atl":[[7.6,9.09]],"id":9480385}],"con":true,"img":false,"tv":12565.6}]}
{"op":"mcm","clk":"1148151568","pt":1439906668076,"mc":[{"id":"1.120089104","rc":[{"trd":[[1.18,3100.61]],"ltp":1.18,"tv":3100.61,"id":9612932},{"atl":[[1.18,244.54]],"id":9612932}],"con":true,"img":false,"tv":12575.6}]}
{"op":"mcm","clk":"1148151977","pt":1439906678681,"mc":[{"id":"1.120089104","rc":[{"atl":[[7.4,3.68]],"id":9480385}],"con":true,"img":false,"tv":12575.6}]}
{"op":"mcm","clk":"1148152609","pt":1439906695124,"mc":[{"id":"1.120089104","rc":[{"atl":[[7.6,0]],"id":9480385}],"con":true,"img":false,"tv":12575.6}]}
{"op":"mcm","clk":"1148152615","pt":1439906695233,"mc":[{"id":"1.120089104","rc":[{"atl":[[7.2,11.58]],"id":9480385}],"con":true,"img":false,"tv":12575.6}]}
{"op":"mcm","clk":"1148153016","pt":1439906704031,"mc":[{"id":"1.120089104","rc":[{"atl":[[7.4,1.4]],"id":9480385}],"con":true,"img":false,"tv":12575.6}]}
{"op":"mcm","clk":"1148154316","pt":1439906728626,"mc":[{"id":"1.120089104","rc":[{"atl":[[7.2,13.92]],"id":9480385}],"con":true,"img":false,"tv":12575.6}]}
{"op":"mcm","clk":"1148154452","pt":1439906731146,"mc":[{"id":"1.120089104","rc":[{"atl":[[7.2,4.33]],"id":9480385}],"con":true,"img":false,"tv":12575.6}]}
{"op":"mcm","clk":"1148154460","pt":1439906731251,"mc":[{"id":"1.120089104","rc":[{"atl":[[7.6,9.09]],"id":9480385}],"con":true,"img":false,"tv":12575.6}]}
{"op":"mcm","clk":"1148156554","pt":1439906778505,"mc":[{"id":"1.120089104","rc":[{"atl":[[7.2,1.99]],"id":9480385}],"con":true,"img":false,"tv":12575.6}]}
{"op":"mcm","clk":"1148157353","pt":1439906794628,"mc":[{"id":"1.120089104","rc":[{"atl":[[7.6,0]],"id":9480385}],"con":true,"img":false,"tv":12575.6}]}
{"op":"mcm","clk":"1148157368","pt":1439906794799,"mc":[{"id":"1.120089104","rc":[{"atl":[[7.2,11.58]],"id":9480385}],"con":true,"img":false,"tv":12575.6}]}
{"op":"mcm","clk":"1148157747","pt":1439906803291,"mc":[{"id":"1.120089104","rc":[{"atl":[[7.2,13.92]],"id":9480385}],"con":true,"img":false,"tv":12575.6}]}
{"op":"mcm","clk":"1148158242","pt":1439906814543,"mc":[{"id":"1.120089104","rc":[{"atb":[[1.17,57.53]],"id":9612932}],"con":true,"img":false,"tv":12575.6}]}
{"op":"mcm","clk":"1148158248","pt":1439906814648,"mc":[{"id":"1.120089104","rc":[{"trd":[[1.18,3120.61]],"ltp":1.18,"tv":3120.61,"id":9612932},{"atl":[[1.18,234.54]],"id":9612932}],"con":true,"img":false,"tv":12595.6}]}
{"op":"mcm","clk":"1148158801","pt":1439906826415,"mc":[{"id":"1.120089104","rc":[{"atl":[[7.2,4.33]],"id":9480385}],"con":true,"img":false,"tv":12595.6}]}
{"op":"mcm","clk":"1148158805","pt":1439906826517,"mc":[{"id":"1.120089104","rc":[{"atl":[[7.6,9.09]],"id":9480385}],"con":true,"img":false,"tv":12595.6}]}
{"op":"mcm","clk":"1148159842","pt":1439906851391,"mc":[{"id":"1.120089104","rc":[{"atl":[[7.2,1.99]],"id":9480385}],"con":true,"img":false,"tv":12595.6}]}
{"op":"mcm","clk":"1148160151","pt":1439906858504,"mc":[{"id":"1.120089104","rc":[{"spn":1.15,"spf":1.05,"id":9612932},{"atl":[[7.6,0]],"id":9480385}],"con":true,"img":false,"tv":12595.6}]}
{"op":"mcm","clk":"1148160155","pt":1439906858613,"mc":[{"id":"1.120089104","rc":[{"atl":[[7.2,11.58]],"id":9480385}],"con":true,"img":false,"tv":12595.6}]}
{"op":"mcm","clk":"1148160821","pt":1439906875308,"mc":[{"id":"1.120089104","rc":[{"atl":[[7.2,13.92]],"id":9480385}],"con":true,"img":false,"tv":12595.6}]}
{"op":"mcm","clk":"1148160842","pt":1439906875832,"mc":[{"id":"1.120089104","rc":[{"atb":[[1.01,2476.79]],"id":9612932}],"con":true,"img":false,"tv":12595.6}]}
{"op":"mcm","clk":"1148161241","pt":1439906885623,"mc":[{"id":"1.120089104","rc":[{"atb":[[1.01,2475.17]],"id":9612932}],"con":true,"img":false,"tv":12595.6}]}
{"op":"mcm","clk":"1148161246","pt":1439906885731,"mc":[{"id":"1.120089104","rc":[{"trd":[[1.18,3123.85]],"ltp":1.18,"tv":3123.85,"id":9612932},{"atl":[[1.18,232.92]],"id":9612932}],"con":true,"img":false,"tv":12598.84}]}
{"op":"mcm","clk":"1148161446","pt":1439906891362,"mc":[{"id":"1.120089104","rc":[{"atl":[[7.2,4.33]],"id":9480385}],"con":true,"img":false,"tv":12598.84}]}
{"op":"mcm","clk":"1148161454","pt":1439906891465,"mc":[{"id":"1.120089104","rc":[{"atl":[[7.6,9.09]],"id":9480385}],"con":true,"img":false,"tv":12598.84}]}
{"op":"mcm","clk":"1148161569","pt":1439906895048,"mc":[{"id":"1.120089104","rc":[{"atb":[[1.01,2473.17]],"id":9612932},{"atl":[[19.5,0]],"id":9612932},{"atb":[[2.6,0],[5.1,0]],"id":9480385},{"atl":[[70,0]],"id":9480385}],"con":true,"img":false,"tv":12598.84}]}
{"op":"mcm","clk":"1148162587","pt":1439906923467,"mc":[{"id":"1.120089104","rc":[{"atl":[[7.2,1.99]],"id":9480385}],"con":true,"img":false,"tv":12598.84}]}
{"op":"mcm","clk":"1148162803","pt":1439906930962,"mc":[{"id":"1.120089104","rc":[{"atl":[[7.6,0]],"id":9480385}],"con":true,"img":false,"tv":12598.84}]}
{"op":"mcm","clk":"1148162807","pt":1439906931066,"mc":[{"id":"1.120089104","rc":[{"atl":[[7.2,11.58]],"id":9480385}],"con":true,"img":false,"tv":12598.84}]}
{"op":"mcm","clk":"1148163340","pt":1439906948130,"mc":[{"id":"1.120089104","rc":[{"atl":[[7.2,13.92]],"id":9480385}],"con":true,"img":false,"tv":12598.84}]}
{"op":"mcm","clk":"1148163942","pt":1439906967983,"mc":[{"id":"1.120089104","rc":[{"atl":[[7.2,4.33]],"id":9480385}],"con":true,"img":false,"tv":12598.84}]}
{"op":"mcm","clk":"1148163950","pt":1439906968196,"mc":[{"id":"1.120089104","rc":[{"atl":[[7.6,9.09]],"id":9480385}],"con":true,"img":false,"tv":12598.84}]}
{"op":"mcm","clk":"1148164868","pt":1439906996351,"mc":[{"id":"1.120089104","rc":[{"atl":[[7.2,1.99]],"id":9480385}],"con":true,"img":false,"tv":12598.84}]}
{"op":"mcm","clk":"1148165529","pt":1439907016915,"mc":[{"id":"1.120089104","rc":[{"atl":[[7.6,0]],"id":9480385}],"con":true,"img":false,"tv":12598.84}]}
{"op":"mcm","clk":"1148165536","pt":1439907017021,"mc":[{"id":"1.120089104","rc":[{"atl":[[7.2,11.58]],"id":9480385}],"con":true,"img":false,"tv":12598.84}]}
{"op":"mcm","clk":"1148165674","pt":1439907020274,"mc":[{"id":"1.120089104","rc":[{"atl":[[7.2,13.92]],"id":9480385}],"con":true,"img":false,"tv":12598.84}]}
{"op":"mcm","clk":"1148166775","pt":1439907049392,"mc":[{"id":"1.120089104","rc":[{"atl":[[7.2,4.33]],"id":9480385}],"con":true,"img":false,"tv":12598.84}]}
{"op":"mcm","clk":"1148166780","pt":1439907049496,"mc":[{"id":"1.120089104","rc":[{"atl":[[7.6,9.09]],"id":9480385}],"con":true,"img":false,"tv":12598.84}]}
{"op":"mcm","clk":"1148167467","pt":1439907068518,"mc":[{"id":"1.120089104","rc":[{"atl":[[7.2,1.99]],"id":9480385}],"con":true,"img":false,"tv":12598.84}]}
{"op":"mcm","clk":"1148167949","pt":1439907082286,"mc":[{"id":"1.120089104","rc":[{"atl":[[7.6,0]],"id":9480385}],"con":true,"img":false,"tv":12598.84}]}
{"op":"mcm","clk":"1148167960","pt":1439907082496,"mc":[{"id":"1.120089104","rc":[{"atl":[[7.2,11.58]],"id":9480385}],"con":true,"img":false,"tv":12598.84}]}
{"op":"mcm","clk":"1148168312","pt":1439907093392,"mc":[{"id":"1.120089104","rc":[{"atl":[[7.2,13.92]],"id":9480385}],"con":true,"img":false,"tv":12598.84}]}
{"op":"mcm","clk":"1148168331","pt":1439907093871,"mc":[{"id":"1.120089104","rc":[{"atl":[[5.2,0]],"id":9612932}],"con":true,"img":false,"tv":12598.84}]}
{"op":"mcm","clk":"1148168603","pt":1439907102158,"mc":[{"id":"1.120089104","rc":[{"atl":[[5.2,15]],"id":9612932}],"con":true,"img":false,"tv":12598.84}]}
{"op":"mcm","clk":"1148168955","pt":1439907114185,"mc":[{"id":"1.120089104","rc":[{"atb":[[5.8,20.32]],"id":9480385}],"con":true,"img":false,"tv":12598.84}]}
{"op":"mcm","clk":"1148168957","pt":1439907114286,"mc":[{"id":"1.120089104","rc":[{"atb":[[5.8,22.65]],"id":9480385}],"con":true,"img":false,"tv":12598.84}]}
{"op":"mcm","clk":"1148169011","pt":1439907116814,"mc":[{"id":"1.120089104","rc":[{"atl":[[7.2,4.33]],"id":9480385}],"con":true,"img":false,"tv":12598.84}]}
{"op":"mcm","clk":"1148169015","pt":1439907116922,"mc":[{"id":"1.120089104","rc":[{"atl":[[7.6,9.09]],"id":9480385}],"con":true,"img":false,"tv":12598.84}]}
{"op":"mcm","clk":"1148169770","pt":1439907141557,"mc":[{"id":"1.120089104","rc":[{"atl":[[7.2,1.99]],"id":9480385}],"con":true,"img":false,"tv":12598.84}]}
{"op":"mcm","clk":"1148169957","pt":1439907149035,"mc":[{"id":"1.120089104","rc":[{"atl":[[7.6,0]],"id":9480385}],"con":true,"img":false,"tv":12598.84}]}
{"op":"mcm","clk":"1148169963","pt":1439907149246,"mc":[{"id":"1.120089104","rc":[{"atl":[[7.2,11.58]],"id":9480385}],"con":true,"img":false,"tv":12598.84}]}
{"op":"mcm","clk":"1148170474","pt":1439907165449,"mc":[{"id":"1.120089104","rc":[{"atl":[[7.2,13.92]],"id":9480385}],"con":true,"img":false,"tv":12598.84}]}
{"op":"mcm","clk":"1148171031","pt":1439907181816,"mc":[{"id":"1.120089104","rc":[{"atl":[[7.2,4.33]],"id":9480385}],"con":true,"img":false,"tv":12598.84}]}
{"op":"mcm","clk":"1148171033","pt":1439907181918,"mc":[{"id":"1.120089104","rc":[{"atl":[[7.6,9.09]],"id":9480385}],"con":true,"img":false,"tv":12598.84}]}
{"op":"mcm","clk":"1148172023","pt":1439907213644,"mc":[{"id":"1.120089104","rc":[{"atl":[[7.2,1.99]],"id":9480385}],"con":true,"img":false,"tv":12598.84}]}
{"op":"mcm","clk":"1148172343","pt":1439907221285,"mc":[{"id":"1.120089104","rc":[{"atl":[[7.6,0]],"id":9480385}],"con":true,"img":false,"tv":12598.84}]}
{"op":"mcm","clk":"1148172347","pt":1439907221389,"mc":[{"id":"1.120089104","rc":[{"atl":[[7.2,11.58]],"id":9480385}],"con":true,"img":false,"tv":12598.84}]}
{"op":"mcm","clk":"1148172975","pt":1439907238396,"mc":[{"id":"1.120089104","rc":[{"atl":[[7.2,13.92]],"id":9480385}],"con":true,"img":false,"tv":12598.84}]}
{"op":"mcm","clk":"1148173529","pt":1439907254534,"mc":[{"id":"1.120089104","rc":[{"atb":[[6.2,22.08]],"id":9480385}],"con":true,"img":false,"tv":12598.84}]}
{"op":"mcm","clk":"1148173590","pt":1439907256253,"mc":[{"id":"1.120089104","rc":[{"atl":[[7.2,4.33]],"id":9480385}],"con":true,"img":false,"tv":12598.84}]}
{"op":"mcm","clk":"1148173595","pt":1439907256358,"mc":[{"id":"1.120089104","rc":[{"atl":[[7.6,9.09]],"id":9480385}],"con":true,"img":false,"tv":12598.84}]}
{"op":"mcm","clk":"1148173705","pt":1439907259788,"mc":[{"id":"1.120089104","rc":[{"atb":[[1.01,2451.39],[6,0]],"id":9480385}],"con":true,"img":false,"tv":12598.84}]}
{"op":"mcm","clk":"1148173720","pt":1439907260320,"mc":[{"id":"1.120089104","rc":[{"atb":[[1.01,2450.34]],"id":9480385}],"con":true,"img":false,"tv":12598.84}]}
{"op":"mcm","clk":"1148173725","pt":1439907260536,"mc":[{"id":"1.120089104","rc":[{"atb":[[1.01,2448.84]],"id":9480385}],"con":true,"img":false,"tv":12598.84}]}
{"op":"mcm","clk":"1148173730","pt":1439907260594,"mc":[{"id":"1.120089104","rc":[{"atb":[[6.4,1.49]],"id":9480385}],"con":true,"img":false,"tv":12598.84}]}
{"op":"mcm","clk":"1148173773","pt":1439907261941,"mc":[{"id":"1.120089104","rc":[{"atb":[[4.5,0]],"id":9480385}],"con":true,"img":false,"tv":12598.84}]}
{"op":"mcm","clk":"1148173777","pt":1439907262049,"mc":[{"id":"1.120089104","rc":[{"atb":[[4.9,49.45]],"id":9480385}],"con":true,"img":false,"tv":12598.84}]}
{"op":"mcm","clk":"1148173889","pt":1439907265570,"mc":[{"id":"1.120089104","rc":[{"atb":[[6,3.98]],"id":9480385}],"con":true,"img":false,"tv":12598.84}]}
{"op":"mcm","clk":"1148173892","pt":1439907265781,"mc":[{"id":"1.120089104","rc":[{"atb":[[5.8,2.33]],"id":9480385}],"con":true,"img":false,"tv":12598.84}]}
{"op":"mcm","clk":"1148174524","pt":1439907286625,"mc":[{"id":"1.120089104","rc":[{"atl":[[7.2,1.99]],"id":9480385}],"con":true,"img":false,"tv":12598.84}]}
{"op":"mcm","clk":"1148174774","pt":1439907293891,"mc":[{"id":"1.120089104","rc":[{"atl":[[7.6,0]],"id":9480385}],"con":true,"img":false,"tv":12598.84}]}
{"op":"mcm","clk":"1148174782","pt":1439907293998,"mc":[{"id":"1.120089104","rc":[{"atl":[[7.2,11.58]],"id":9480385}],"con":true,"img":false,"tv":12598.84}]}
{"op":"mcm","clk":"1148175314","pt":1439907310494,"mc":[{"id":"1.120089104","rc":[{"atl":[[7.2,13.92]],"id":9480385}],"con":true,"img":false,"tv":12598.84}]}
{"op":"mcm","clk":"1148176000","pt":1439907331294,"mc":[{"id":"1.120089104","rc":[{"atl":[[7.2,4.33]],"id":9480385}],"con":true,"img":false,"tv":12598.84}]}
{"op":"mcm","clk":"1148176006","pt":1439907331503,"mc":[{"id":"1.120089104","rc":[{"atl":[[7.6,9.09]],"id":9480385}],"con":true,"img":false,"tv":12598.84}]}
{"op":"mcm","clk":"1148176428","pt":1439907343828,"mc":[{"id":"1.120089104","rc":[{"atb":[[4.8,42.53]],"id":9480385}],"con":true,"img":false,"tv":12598.84}]}
{"op":"mcm","clk":"1148176430","pt":1439907343937,"mc":[{"id":"1.120089104","rc":[{"atb":[[5.1,4.8]],"id":9480385}],"con":true,"img":false,"tv":12598.84}]}
{"op":"mcm","clk":"1148176859","pt":1439907357023,"mc":[{"id":"1.120089104","rc":[{"atb":[[4.8,14.4]],"id":9480385}],"con":true,"img":false,"tv":12598.84}]}
{"op":"mcm","clk":"1148176868","pt":1439907357182,"mc":[{"id":"1.120089104","rc":[{"atb":[[5.1,32.94]],"id":9480385}],"con":true,"img":false,"tv":12598.84}]}
{"op":"mcm","clk":"1148176943","pt":1439907358672,"mc":[{"id":"1.120089104","rc":[{"atl":[[7.2,1.99]],"id":9480385}],"con":true,"img":false,"tv":12598.84}]}
{"op":"mcm","clk":"1148177268","pt":1439907366965,"mc":[{"id":"1.120089104","rc":[{"atl":[[7.6,0]],"id":9480385}],"con":true,"img":false,"tv":12598.84}]}
{"op":"mcm","clk":"1148177273","pt":1439907367068,"mc":[{"id":"1.120089104","rc":[{"atl":[[7.2,11.58]],"id":9480385}],"con":true,"img":false,"tv":12598.84}]}
{"op":"mcm","clk":"1148177764","pt":1439907382535,"mc":[{"id":"1.120089104","rc":[{"atl":[[7.2,13.92]],"id":9480385}],"con":true,"img":false,"tv":12598.84}]}
{"op":"mcm","clk":"1148178398","pt":1439907400603,"mc":[{"id":"1.120089104","rc":[{"atl":[[7.2,4.33]],"id":9480385}],"con":true,"img":false,"tv":12598.84}]}
{"op":"mcm","clk":"1148178404","pt":1439907400816,"mc":[{"id":"1.120089104","rc":[{"atl":[[7.6,9.09]],"id":9480385}],"con":true,"img":false,"tv":12598.84}]}
{"op":"mcm","clk":"1148178976","pt":1439907417109,"mc":[{"id":"1.120089104","rc":[{"trd":[[1.15,178.6],[1.17,653.68],[1.16,1865.09]],"ltp":1.15,"tv":2697.37,"id":9612932},{"atb":[[1.17,0],[1.16,0],[1.15,12005.7]],"id":9612932},{"spn":1.15,"spf":1.05,"id":9612932}],"con":true,"img":false,"tv":13948.84}]}
{"op":"mcm","clk":"1148179146","pt":1439907422651,"mc":[{"id":"1.120089104","rc":[{"atb":[[1.09,3302.11]],"id":9612932}],"con":true,"img":false,"tv":13948.84}]}
{"op":"mcm","clk":"1148179152","pt":1439907422864,"mc":[{"id":"1.120089104","rc":[{"atb":[[1.08,385.82]],"id":9612932}],"con":true,"img":false,"tv":13948.84}]}
{"op":"mcm","clk":"1148179156","pt":1439907423027,"mc":[{"id":"1.120089104","rc":[{"atb":[[4.8,7.23]],"id":9480385}],"con":true,"img":false,"tv":13948.84}]}
{"op":"mcm","clk":"1148179159","pt":1439907423133,"mc":[{"id":"1.120089104","rc":[{"atb":[[5.1,40.11]],"id":9480385}],"con":true,"img":false,"tv":13948.84}]}
{"op":"mcm","clk":"1148179364","pt":1439907429240,"mc":[{"id":"1.120089104","rc":[{"atl":[[7.2,1.99]],"id":9480385}],"con":true,"img":false,"tv":13948.84}]}
{"op":"mcm","clk":"1148179432","pt":1439907431535,"mc":[{"id":"1.120089104","rc":[{"atb":[[1.16,16.67]],"id":9612932}],"con":true,"img":false,"tv":13948.84}]}
{"op":"mcm","clk":"1148179434","pt":1439907431641,"mc":[{"id":"1.120089104","rc":[{"atb":[[6.6,2.93]],"id":9480385}],"con":true,"img":false,"tv":13948.84}]}
{"op":"mcm","clk":"1148179450","pt":1439907432375,"mc":[{"id":"1.120089104","rc":[{"atb":[[6.2,0]],"id":9480385}],"con":true,"img":false,"tv":13948.84}]}
{"op":"mcm","clk":"1148179460","pt":1439907432636,"mc":[{"id":"1.120089104","rc":[{"atb":[[1.01,2450.84]],"id":9480385}],"con":true,"img":false,"tv":13948.84}]}
{"op":"mcm","clk":"1148179468","pt":1439907432844,"mc":[{"id":"1.120089104","rc":[{"atb":[[1.01,2452.65]],"id":9480385}],"con":true,"img":false,"tv":13948.84}]}
{"op":"mcm","clk":"1148179474","pt":1439907433053,"mc":[{"id":"1.120089104","rc":[{"atb":[[1.01,2450.84]],"id":9480385},{"atl":[[7.6,0]],"id":9480385}],"con":true,"img":false,"tv":13948.84}]}
{"op":"mcm","clk":"1148179476","pt":1439907433158,"mc":[{"id":"1.120089104","rc":[{"atb":[[6,5.79]],"id":9480385},{"atl":[[7.2,11.58]],"id":9480385}],"con":true,"img":false,"tv":13948.84}]}
{"op":"mcm","clk":"1148179481","pt":1439907433365,"mc":[{"id":"1.120089104","rc":[{"atb":[[1.01,2448.84]],"id":9480385}],"con":true,"img":false,"tv":13948.84}]}
{"op":"mcm","clk":"1148179607","pt":1439907438612,"mc":[{"id":"1.120089104","rc":[{"atb":[[6.4,0],[1.01,2451.39]],"id":9480385}],"con":true,"img":false,"tv":13948.84}]}
{"op":"mcm","clk":"1148179617","pt":1439907439136,"mc":[{"id":"1.120089104","rc":[{"atb":[[1.01,2450.25]],"id":9480385}],"con":true,"img":false,"tv":13948.84}]}
{"op":"mcm","clk":"1148179621","pt":1439907439351,"mc":[{"id":"1.120089104","rc":[{"atb":[[1.01,2448.84]],"id":9480385}],"con":true,"img":false,"tv":13948.84}]}
{"op":"mcm","clk":"1148179625","pt":1439907439455,"mc":[{"id":"1.120089104","rc":[{"atb":[[6.8,1.4]],"id":9480385}],"con":true,"img":false,"tv":13948.84}]}
{"op":"mcm","clk":"1148180004","pt":1439907452416,"mc":[{"id":"1.120089104","rc":[{"atl":[[7.2,13.92]],"id":9480385}],"con":true,"img":false,"tv":13948.84}]}
{"op":"mcm","clk":"1148180483","pt":1439907465383,"mc":[{"id":"1.120089104","rc":[{"atb":[[5.5,24.05]],"id":9480385}],"con":true,"img":false,"tv":13948.84}]}
{"op":"mcm","clk":"1148180495","pt":1439907465594,"mc":[{"id":"1.120089104","rc":[{"atl":[[7.2,4.44]],"id":9480385}],"con":true,"img":false,"tv":13948.84}]}
{"op":"mcm","clk":"1148180575","pt":1439907468724,"mc":[{"id":"1.120089104","rc":[{"atb":[[1.1,1267.37]],"id":9612932}],"con":true,"img":false,"tv":13948.84}]}
{"op":"mcm","clk":"1148180578","pt":1439907468930,"mc":[{"id":"1.120089104","rc":[{"atb":[[1.09,1322.4]],"id":9612932}],"con":true,"img":false,"tv":13948.84}]}
{"op":"mcm","clk":"1148180601","pt":1439907469317,"mc":[{"id":"1.120089104","rc":[{"atb":[[1.09,1659.32]],"id":9612932}],"con":true,"img":false,"tv":13948.84}]}
{"op":"mcm","clk":"1148180606","pt":1439907469419,"mc":[{"id":"1.120089104","rc":[{"atb":[[1.09,3980.36]],"id":9612932}],"con":true,"img":false,"tv":13948.84}]}
{"op":"mcm","clk":"1148180616","pt":1439907469840,"mc":[{"id":"1.120089104","rc":[{"atb":[[4.9,0]],"id":9480385}],"con":true,"img":false,"tv":13948.84}]}
{"op":"mcm","clk":"1148180620","pt":1439907469952,"mc":[{"id":"1.120089104","rc":[{"atb":[[4.8,0],[5.2,52.45]],"id":9480385}],"con":true,"img":false,"tv":13948.84}]}
{"op":"mcm","clk":"1148180622","pt":1439907469998,"mc":[{"id":"1.120089104","rc":[{"atb":[[5.3,7.23]],"id":9480385}],"con":true,"img":false,"tv":13948.84}]}
{"op":"mcm","clk":"1148180952","pt":1439907478300,"mc":[{"id":"1.120089104","rc":[{"atb":[[1.13,12000]],"id":9612932},{"spn":1.15,"spf":1.05,"id":9612932}],"con":true,"img":false,"tv":13948.84}]}
{"op":"mcm","clk":"1148182376","pt":1439907514336,"mc":[{"id":"1.120089104","rc":[{"atb":[[1.09,2853.86]],"id":9612932}],"con":true,"img":false,"tv":13948.84}]}
{"op":"mcm","clk":"1148182383","pt":1439907514492,"mc":[{"id":"1.120089104","rc":[{"atb":[[1.09,4174.57]],"id":9612932}],"con":true,"img":false,"tv":13948.84}]}
{"op":"mcm","clk":"1148183590","pt":1439907548164,"mc":[{"id":"1.120089104","rc":[{"atl":[[1.18,238.92]],"id":9612932},{"atl":[[7.2,10.44]],"id":9480385}],"con":true,"img":false,"tv":13948.84}]}
{"op":"mcm","clk":"1148183929","pt":1439907558346,"mc":[{"id":"1.120089104","rc":[{"atb":[[1.09,3989.21]],"id":9612932}],"con":true,"img":false,"tv":13948.84}]}
{"op":"mcm","clk":"1148183950","pt":1439907558978,"mc":[{"id":"1.120089104","rc":[{"atb":[[1.09,4212.93]],"id":9612932}],"con":true,"img":false,"tv":13948.84}]}
{"op":"mcm","clk":"1148194427","pt":1439907597229,"mc":[{"id":"1.120089104","rc":[{"atb":[[1.1,11.95]],"id":9612932}],"con":true,"img":false,"tv":13948.84}]}
{"op":"mcm","clk":"1148194444","pt":1439907597752,"mc":[{"id":"1.120089104","rc":[{"atb":[[1.09,5752.14]],"id":9612932}],"con":true,"img":false,"tv":13948.84}]}
{"op":"mcm","clk":"1148194457","pt":1439907598277,"mc":[{"id":"1.120089104","rc":[{"atb":[[4.7,15.7]],"id":9480385}],"con":true,"img":false,"tv":13948.84}]}
{"op":"mcm","clk":"1148194460","pt":1439907598326,"mc":[{"id":"1.120089104","rc":[{"atb":[[5.2,86.38]],"id":9480385}],"con":true,"img":false,"tv":13948.84}]}
{"op":"mcm","clk":"1148194482","pt":1439907598856,"mc":[{"id":"1.120089104","rc":[{"atb":[[1.11,11.25]],"id":9612932}],"con":true,"img":false,"tv":13948.84}]}
{"op":"mcm","clk":"1148194585","pt":1439907601183,"mc":[{"id":"1.120089104","rc":[{"atb":[[1.11,236.25]],"id":9612932},{"atl":[[1.26,598]],"id":9612932},{"atb":[[5.4,46]],"id":9480385},{"atl":[[9.6,26]],"id":9480385}],"con":true,"img":false,"tv":13948.84}]}
{"op":"mcm","clk":"1148194856","pt":1439907608663,"mc":[{"id":"1.120089104","rc":[{"atl":[[2,20]],"id":9612932}],"con":true,"img":false,"tv":13948.84}]}
{"op":"mcm","clk":"1148197946","pt":1439907686507,"mc":[{"id":"1.120089104","rc":[{"atb":[[1.16,48.67]],"id":9612932},{"spn":1.15,"spf":1.05,"id":9612932}],"con":true,"img":false,"tv":13948.84}]}
{"op":"mcm","clk":"1148197983","pt":1439907687469,"mc":[{"id":"1.120089104","rc":[{"atl":[[1.2,42.87]],"id":9612932}],"con":true,"img":false,"tv":13948.84}]}
{"op":"mcm","clk":"1148198567","pt":1439907704437,"mc":[{"id":"1.120089104","rc":[{"atb":[[5.8,0]],"id":9480385}],"con":true,"img":false,"tv":13948.84}]}
{"op":"mcm","clk":"1148198573","pt":1439907704541,"mc":[{"id":"1.120089104","rc":[{"atb":[[5.8,2.33]],"id":9480385}],"con":true,"img":false,"tv":13948.84}]}
{"op":"mcm","clk":"1148199156","pt":1439907721820,"mc":[{"id":"1.120089104","rc":[{"atl":[[1.26,400]],"id":9612932}],"con":true,"img":false,"tv":13948.84}]}
{"op":"mcm","clk":"1148199158","pt":1439907721875,"mc":[{"id":"1.120089104","rc":[{"atl":[[1.24,702]],"id":9612932}],"con":true,"img":false,"tv":13948.84}]}
{"op":"mcm","clk":"1148200137","pt":1439907748309,"mc":[{"id":"1.120089104","rc":[{"atl":[[1.18,232.92]],"id":9612932},{"atl":[[7.2,4.44]],"id":9480385}],"con":true,"img":false,"tv":13948.84}]}
{"op":"mcm","clk":"1148201121","pt":1439907775791,"mc":[{"id":"1.120089104","rc":[{"atb":[[5.9,0]],"id":9480385}],"con":true,"img":false,"tv":13948.84}]}
{"op":"mcm","clk":"1148201124","pt":1439907775897,"mc":[{"id":"1.120089104","rc":[{"atb":[[6.6,13.78]],"id":9480385}],"con":true,"img":false,"tv":13948.84}]}
{"op":"mcm","clk":"1148201133","pt":1439907776108,"mc":[{"id":"1.120089104","rc":[{"atb":[[6.6,12.63]],"id":9480385}],"con":true,"img":false,"tv":13948.84}]}
{"op":"mcm","clk":"1148201377","pt":1439907782389,"mc":[{"id":"1.120089104","rc":[{"atb":[[5.4,0]],"id":9480385}],"con":true,"img":false,"tv":13948.84}]}
{"op":"mcm","clk":"1148201382","pt":1439907782499,"mc":[{"id":"1.120089104","rc":[{"atb":[[5.3,54.23]],"id":9480385}],"con":true,"img":false,"tv":13948.84}]}
{"op":"mcm","clk":"1148201497","pt":1439907785403,"mc":[{"id":"1.120089104","rc":[{"atb":[[5.4,6]],"id":9480385}],"con":true,"img":false,"tv":13948.84}]}
{"op":"mcm","clk":"1148207520","pt":1439907934396,"mc":[{"id":"1.120089104","rc":[{"atl":[[1.18,238.92]],"id":9612932},{"atl":[[7.2,10.44]],"id":9480385}],"con":true,"img":false,"tv":13948.84}]}
{"op":"mcm","clk":"1148208602","pt":1439907960070,"mc":[{"id":"1.120089104","rc":[{"trd":[[1.18,3175.17]],"ltp":1.18,"tv":3175.17,"id":9612932},{"atl":[[1.18,213.26]],"id":9612932}],"con":true,"img":false,"tv":14000.16}]}
{"op":"mcm","clk":"1148213271","pt":1439908068452,"mc":[{"id":"1.120089104","rc":[{"atb":[[6,1.81]],"id":9480385},{"atl":[[8.6,0]],"id":9480385}],"con":true,"img":false,"tv":14000.16}]}
{"op":"mcm","clk":"1148213898","pt":1439908083430,"mc":[{"id":"1.120089104","rc":[{"atb":[[5.3,7.23]],"id":9480385},{"atl":[[9.6,0]],"id":9480385}],"con":true,"img":false,"tv":14000.16}]}
{"op":"mcm","clk":"1148213902","pt":1439908083534,"mc":[{"id":"1.120089104","rc":[{"atb":[[5,50]],"id":9480385},{"atl":[[10.5,24],[9,33.42]],"id":9480385}],"con":true,"img":false,"tv":14000.16}]}
{"op":"mcm","clk":"1148214230","pt":1439908092259,"mc":[{"id":"1.120089104","rc":[{"atb":[[5.4,0]],"id":9480385}],"con":true,"img":false,"tv":14000.16}]}
{"op":"mcm","clk":"1148215898","pt":1439908134553,"mc":[{"id":"1.120089104","rc":[{"atl":[[1.18,207.26]],"id":9612932},{"atl":[[7.2,4.44]],"id":9480385}],"con":true,"img":false,"tv":14000.16}]}
{"op":"mcm","clk":"1148216222","pt":1439908144091,"mc":[{"id":"1.120089104","rc":[{"atl":[[10.5,0]],"id":9480385}],"con":true,"img":false,"tv":14000.16}]}
{"op":"mcm","clk":"1148216225","pt":1439908144198,"mc":[{"id":"1.120089104","rc":[{"atl":[[10,25]],"id":9480385}],"con":true,"img":false,"tv":14000.16}]}
{"op":"mcm","clk":"1148218049","pt":1439908195946,"mc":[{"id":"1.120089104","rc":[{"atb":[[1.01,2470.84]],"id":9612932},{"atl":[[1.46,0]],"id":9612932},{"atb":[[3.4,0]],"id":9480385},{"atl":[[9.2,0]],"id":9480385}],"con":true,"img":false,"tv":14000.16}]}
{"op":"mcm","clk":"1148219365","pt":1439908229151,"mc":[{"id":"1.120089104","rc":[{"atb":[[5.8,0]],"id":9480385}],"con":true,"img":false,"tv":14000.16}]}
{"op":"mcm","clk":"1148219370","pt":1439908229254,"mc":[{"id":"1.120089104","rc":[{"atb":[[5.8,2.33]],"id":9480385}],"con":true,"img":false,"tv":14000.16}]}
{"op":"mcm","clk":"1148221150","pt":1439908275147,"mc":[{"id":"1.120089104","rc":[{"atb":[[4.7,13.7]],"id":9480385}],"con":true,"img":false,"tv":14000.16}]}
{"op":"mcm","clk":"1148222681","pt":1439908313740,"mc":[{"id":"1.120089104","rc":[{"atl":[[7.2,10.44]],"id":9480385}],"con":true,"img":false,"tv":14000.16}]}
{"op":"mcm","clk":"1148239403","pt":1439908513855,"mc":[{"id":"1.120089104","rc":[{"atl":[[7.2,4.44]],"id":9480385}],"con":true,"img":false,"tv":14000.16}]}
{"op":"mcm","clk":"1148246832","pt":1439908700945,"mc":[{"id":"1.120089104","rc":[{"atl":[[7.2,10.44]],"id":9480385}],"con":true,"img":false,"tv":14000.16}]}
{"op":"mcm","clk":"1148246929","pt":1439908704357,"mc":[{"id":"1.120089104","rc":[{"atb":[[5.5,30.56]],"id":9480385}],"con":true,"img":false,"tv":14000.16}]}
{"op":"mcm","clk":"1148247955","pt":1439908735007,"mc":[{"id":"1.120089104","rc":[{"atb":[[5.5,24.05]],"id":9480385}],"con":true,"img":false,"tv":14000.16}]}
{"op":"mcm","clk":"1148252247","pt":1439908835646,"mc":[{"id":"1.120089104","rc":[{"atb":[[1.16,148.67]],"id":9612932},{"spn":1.15,"spf":1.05,"id":9612932}],"con":true,"img":false,"tv":14000.16}]}
{"op":"mcm","clk":"1148252749","pt":1439908846928,"mc":[{"id":"1.120089104","rc":[{"spl":[[1.01,1072.52]],"id":9612932}],"con":true,"img":false,"tv":14000.16}]}
{"op":"mcm","clk":"1148252833","pt":1439908848446,"mc":[{"id":"1.120089104","rc":[{"trd":[[1.18,3275.17]],"ltp":1.18,"tv":3275.17,"id":9612932},{"atl":[[1.18,157.26]],"id":9612932}],"con":true,"img":false,"tv":14100.16}]}
{"op":"mcm","clk":"1148252903","pt":1439908849974,"mc":[{"id":"1.120089104","rc":[{"spl":[[1.01,12]],"id":9480385}],"con":true,"img":false,"tv":14100.16}]}
{"op":"mcm","clk":"1148253273","pt":1439908859680,"mc":[{"id":"1.120089104","rc":[{"atb":[[5.8,0]],"id":9480385}],"con":true,"img":false,"tv":14100.16}]}
{"op":"mcm","clk":"1148253276","pt":1439908859738,"mc":[{"id":"1.120089104","rc":[{"atb":[[5.8,2.33]],"id":9480385}],"con":true,"img":false,"tv":14100.16}]}
{"op":"mcm","clk":"1148255114","pt":1439908901160,"mc":[{"id":"1.120089104","rc":[{"spn":1.15,"spf":1.05,"id":9612932},{"atl":[[7.2,4.44]],"id":9480385},{"spn":6.63,"spf":2.41,"id":9480385}],"con":true,"img":false,"tv":14100.16}]}
{"op":"mcm","clk":"1148262789","pt":1439909085429,"mc":[{"id":"1.120089104","rc":[{"atl":[[7.2,10.44]],"id":9480385}],"con":true,"img":false,"tv":14100.16}]}
{"op":"mcm","clk":"1148267372","pt":1439909189032,"mc":[{"id":"1.120089104","rc":[{"atb":[[1.11,258.25]],"id":9612932}],"con":true,"img":false,"tv":14100.16}]}
{"op":"mcm","clk":"1148272257","pt":1439909285939,"mc":[{"id":"1.120089104","rc":[{"atl":[[7.2,4.44]],"id":9480385}],"con":true,"img":false,"tv":14100.16}]}
{"op":"mcm","clk":"1148289075","pt":1439909460799,"mc":[{"id":"1.120089104","rc":[{"atb":[[5.8,0]],"id":9480385}],"con":true,"img":false,"tv":14100.16}]}
{"op":"mcm","clk":"1148289080","pt":1439909460855,"mc":[{"id":"1.120089104","rc":[{"atb":[[5.8,2.33]],"id":9480385}],"con":true,"img":false,"tv":14100.16}]}
{"op":"mcm","clk":"1148289816","pt":1439909481736,"mc":[{"id":"1.120089104","rc":[{"atl":[[7.2,10.44]],"id":9480385}],"con":true,"img":false,"tv":14100.16}]}
{"op":"mcm","clk":"1148291219","pt":1439909523405,"mc":[{"id":"1.120089104","rc":[{"atl":[[1.17,150]],"id":9612932}],"con":true,"img":false,"tv":14100.16}]}
{"op":"mcm","clk":"1148291270","pt":1439909524365,"mc":[{"id":"1.120089104","rc":[{"atl":[[1.21,0]],"id":9612932}],"con":true,"img":false,"tv":14100.16}]}
{"op":"mcm","clk":"1148291680","pt":1439909535947,"mc":[{"id":"1.120089104","rc":[{"atl":[[1.23,64.38]],"id":9612932}],"con":true,"img":false,"tv":14100.16}]}
{"op":"mcm","clk":"1148293679","pt":1439909587801,"mc":[{"id":"1.120089104","rc":[{"atl":[[1.24,500]],"id":9612932}],"con":true,"img":false,"tv":14100.16}]}
{"op":"mcm","clk":"1148293683","pt":1439909587908,"mc":[{"id":"1.120089104","rc":[{"atl":[[1.23,267.38]],"id":9612932}],"con":true,"img":false,"tv":14100.16}]}
{"op":"mcm","clk":"1148295681","pt":1439909638643,"mc":[{"id":"1.120089104","rc":[{"atb":[[1.16,248.67]],"id":9612932}],"con":true,"img":false,"tv":14100.16}]}
{"op":"mcm","clk":"1148297343","pt":1439909680754,"mc":[{"id":"1.120089104","rc":[{"spn":1.15,"spf":1.05,"id":9612932},{"trd":[[7.2,10.16]],"ltp":7.2,"tv":10.16,"id":9480385},{"atl":[[7.2,5.36]],"id":9480385}],"con":true,"img":false,"tv":14110.32}]}
{"op":"mcm","clk":"1148297371","pt":1439909681870,"mc":[{"id":"1.120089104","rc":[{"atl":[[7.2,0]],"id":9480385}],"con":true,"img":false,"tv":14110.32}]}
{"op":"mcm","clk":"1148297399","pt":1439909682981,"mc":[{"id":"1.120089104","rc":[{"atl":[[7.8,4.37]],"id":9480385}],"con":true,"img":false,"tv":14110.32}]}
{"op":"mcm","clk":"1148297509","pt":1439909686283,"mc":[{"id":"1.120089104","rc":[{"atb":[[5.8,28.05]],"id":9480385}],"con":true,"img":false,"tv":14110.32}]}
{"op":"mcm","clk":"1148297560","pt":1439909688043,"mc":[{"id":"1.120089104","rc":[{"atb":[[6.6,15.31],[5.5,35.02]],"id":9480385},{"atl":[[8.8,6.86]],"id":9480385}],"con":true,"img":false,"tv":14110.32}]}
{"op":"mcm","clk":"1148297701","pt":1439909692901,"mc":[{"id":"1.120089104","rc":[{"atl":[[8.6,27.19]],"id":9480385}],"con":true,"img":false,"tv":14110.32}]}
{"op":"mcm","clk":"1148297711","pt":1439909693117,"mc":[{"id":"1.120089104","rc":[{"atl":[[9,0]],"id":9480385}],"con":true,"img":false,"tv":14110.32}]}
{"op":"mcm","clk":"1148297853","pt":1439909697880,"mc":[{"id":"1.120089104","rc":[{"atl":[[7.6,5]],"id":9480385}],"con":true,"img":false,"tv":14110.32}]}
{"op":"mcm","clk":"1148298148","pt":1439909708500,"mc":[{"id":"1.120089104","rc":[{"atl":[[10,0]],"id":9480385}],"con":true,"img":false,"tv":14110.32}]}
{"op":"mcm","clk":"1148298155","pt":1439909708567,"mc":[{"id":"1.120089104","rc":[{"atl":[[9.6,26]],"id":9480385}],"con":true,"img":false,"tv":14110.32}]}
{"op":"mcm","clk":"1148298582","pt":1439909720347,"mc":[{"id":"1.120089104","rc":[{"atl":[[8.8,0]],"id":9480385}],"con":true,"img":false,"tv":14110.32}]}
{"op":"mcm","clk":"1148298586","pt":1439909720451,"mc":[{"id":"1.120089104","rc":[{"atl":[[7.4,9.56]],"id":9480385}],"con":true,"img":false,"tv":14110.32}]}
{"op":"mcm","clk":"1148298887","pt":1439909728179,"mc":[{"id":"1.120089104","rc":[{"atl":[[1.17,250]],"id":9612932}],"con":true,"img":false,"tv":14110.32}]}
{"op":"mcm","clk":"1148299092","pt":1439909731861,"mc":[{"id":"1.120089104","rc":[{"atb":[[6.6,12.63]],"id":9480385}],"con":true,"img":false,"tv":14110.32}]}
{"op":"mcm","clk":"1148299134","pt":1439909732977,"mc":[{"id":"1.120089104","rc":[{"atb":[[1.15,12017.7]],"id":9612932},{"atb":[[6.6,14.63]],"id":9480385}],"con":true,"img":false,"tv":14110.32}]}
{"op":"mcm","clk":"1148299312","pt":1439909738920,"mc":[{"id":"1.120089104","rc":[{"atb":[[6.6,12.63]],"id":9480385}],"con":true,"img":false,"tv":14110.32}]}
{"op":"mcm","clk":"1148299313","pt":1439909739025,"mc":[{"id":"1.120089104","rc":[{"atb":[[6.8,3.4]],"id":9480385}],"con":true,"img":false,"tv":14110.32}]}
{"op":"mcm","clk":"1148299739","pt":1439909751779,"mc":[{"id":"1.120089104","rc":[{"atb":[[5.5,24.05]],"id":9480385},{"atl":[[7.4,1.4]],"id":9480385},{"spn":6.67,"spf":2.41,"id":9480385}],"con":true,"img":false,"tv":14110.32}]}
{"op":"mcm","clk":"1148299972","pt":1439909760145,"mc":[{"id":"1.120089104","rc":[{"atb":[[1.15,12005.7]],"id":9612932},{"atb":[[6.8,1.4]],"id":9480385}],"con":true,"img":false,"tv":14110.32}]}
{"op":"mcm","clk":"1148300978","pt":1439909783445,"mc":[{"id":"1.120089104","rc":[{"atb":[[5.5,35.02]],"id":9480385},{"atl":[[7.4,9.56]],"id":9480385}],"con":true,"img":false,"tv":14110.32}]}
{"op":"mcm","clk":"1148302479","pt":1439909816475,"mc":[{"id":"1.120089104","rc":[{"atl":[[1.21,200]],"id":9612932},{"spn":6.63,"spf":2.41,"id":9480385}],"con":true,"img":false,"tv":14110.32}]}
{"op":"mcm","clk":"1148302968","pt":1439909829070,"mc":[{"id":"1.120089104","rc":[{"atl":[[9.6,0]],"id":9480385}],"con":true,"img":false,"tv":14110.32}]}
{"op":"mcm","clk":"1148302974","pt":1439909829130,"mc":[{"id":"1.120089104","rc":[{"atl":[[8.8,28]],"id":9480385}],"con":true,"img":false,"tv":14110.32}]}
{"op":"mcm","clk":"1148303440","pt":1439909843075,"mc":[{"id":"1.120089104","rc":[{"atb":[[1.01,2472.24]],"id":9612932}],"con":true,"img":false,"tv":14110.32}]}
{"op":"mcm","clk":"1148303450","pt":1439909843435,"mc":[{"id":"1.120089104","rc":[{"atb":[[1.01,2471.54]],"id":9612932}],"con":true,"img":false,"tv":14110.32}]}
{"op":"mcm","clk":"1148303457","pt":1439909843818,"mc":[{"id":"1.120089104","rc":[{"atb":[[1.01,2470.84]],"id":9612932}],"con":true,"img":false,"tv":14110.32}]}
{"op":"mcm","clk":"1148303463","pt":1439909843922,"mc":[{"id":"1.120089104","rc":[{"atb":[[1.01,2471.54]],"id":9612932}],"con":true,"img":false,"tv":14110.32}]}
{"op":"mcm","clk":"1148303485","pt":1439909844722,"mc":[{"id":"1.120089104","rc":[{"atb":[[1.16,48.67]],"id":9612932},{"atl":[[1.17,150]],"id":9612932}],"con":true,"img":false,"tv":14110.32}]}
{"op":"mcm","clk":"1148303583","pt":1439909847305,"mc":[{"id":"1.120089104","rc":[{"atb":[[1.01,2450.24]],"id":9480385}],"con":true,"img":false,"tv":14110.32}]}
{"op":"mcm","clk":"1148303602","pt":1439909847630,"mc":[{"id":"1.120089104","rc":[{"atb":[[1.01,2449.54]],"id":9480385}],"con":true,"img":false,"tv":14110.32}]}
{"op":"mcm","clk":"1148303622","pt":1439909848015,"mc":[{"id":"1.120089104","rc":[{"atb":[[1.01,2448.84]],"id":9480385}],"con":true,"img":false,"tv":14110.32}]}
{"op":"mcm","clk":"1148303628","pt":1439909848114,"mc":[{"id":"1.120089104","rc":[{"atb":[[1.01,2449.54]],"id":9480385}],"con":true,"img":false,"tv":14110.32}]}
{"op":"mcm","clk":"1148305771","pt":1439909900489,"mc":[{"id":"1.120089104","rc":[{"trd":[[1.17,674.76]],"ltp":1.17,"tv":674.76,"id":9612932},{"atl":[[1.17,139.46]],"id":9612932},{"spn":1.15,"spf":1.05,"id":9612932}],"con":true,"img":false,"tv":14131.4}]}
{"op":"mcm","clk":"1148309357","pt":1439910002147,"mc":[{"id":"1.120089104","rc":[{"atb":[[5.8,25.71]],"id":9480385}],"con":true,"img":false,"tv":14131.4}]}
{"op":"mcm","clk":"1148309364","pt":1439910002258,"mc":[{"id":"1.120089104","rc":[{"atb":[[6.8,3.74]],"id":9480385}],"con":true,"img":false,"tv":14131.4}]}
{"op":"mcm","clk":"1148309963","pt":1439910015318,"mc":[{"id":"1.120089104","rc":[{"atb":[[5.5,24.05]],"id":9480385},{"atl":[[7.4,1.4]],"id":9480385}],"con":true,"img":false,"tv":14131.4}]}
{"op":"mcm","clk":"1148310239","pt":1439910022307,"mc":[{"id":"1.120089104","rc":[{"atl":[[5.2,0]],"id":9612932}],"con":true,"img":false,"tv":14131.4}]}
{"op":"mcm","clk":"1148310629","pt":1439910029682,"mc":[{"id":"1.120089104","rc":[{"atl":[[5.2,15]],"id":9612932}],"con":true,"img":false,"tv":14131.4}]}
{"op":"mcm","clk":"1148312186","pt":1439910070092,"mc":[{"id":"1.120089104","rc":[{"atb":[[5,0]],"id":9480385},{"atl":[[8.8,0]],"id":9480385},{"spn":6.68,"spf":2.41,"id":9480385}],"con":true,"img":false,"tv":14131.4}]}
{"op":"mcm","clk":"1148312188","pt":1439910070200,"mc":[{"id":"1.120089104","rc":[{"atb":[[5.3,54.23]],"id":9480385},{"atl":[[9.6,26]],"id":9480385}],"con":true,"img":false,"tv":14131.4}]}
{"op":"mcm","clk":"1148312240","pt":1439910071453,"mc":[{"id":"1.120089104","rc":[{"trd":[[1.17,680.76]],"ltp":1.17,"tv":680.76,"id":9612932},{"atl":[[1.17,136.46]],"id":9612932}],"con":true,"img":false,"tv":14137.4}]}
{"op":"mcm","clk":"1148312694","pt":1439910082407,"mc":[{"id":"1.120089104","rc":[{"atb":[[5.4,6]],"id":9480385}],"con":true,"img":false,"tv":14137.4}]}
{"op":"mcm","clk":"1148313987","pt":1439910117695,"mc":[{"id":"1.120089104","rc":[{"trd":[[1.17,880.76]],"ltp":1.17,"tv":880.76,"id":9612932},{"atl":[[1.17,36.46]],"id":9612932}],"con":true,"img":false,"tv":14337.4}]}
{"op":"mcm","clk":"1148314073","pt":1439910119919,"mc":[{"id":"1.120089104","rc":[{"atl":[[1.21,300]],"id":9612932}],"con":true,"img":false,"tv":14337.4}]}
{"op":"mcm","clk":"1148314706","pt":1439910137318,"mc":[{"id":"1.120089104","rc":[{"atb":[[5.8,39.4]],"id":9480385}],"con":true,"img":false,"tv":14337.4}]}
{"op":"mcm","clk":"1148314713","pt":1439910137537,"mc":[{"id":"1.120089104","rc":[{"atb":[[5.8,13.68]],"id":9480385}],"con":true,"img":false,"tv":14337.4}]}
{"op":"mcm","clk":"1148317040","pt":1439910201403,"mc":[{"id":"1.120089104","rc":[{"trd":[[1.17,886.76]],"ltp":1.17,"tv":886.76,"id":9612932},{"atl":[[1.17,33.46]],"id":9612932}],"con":true,"img":false,"tv":14343.4}]}
{"op":"mcm","clk":"1148318789","pt":1439910248335,"mc":[{"id":"1.120089104","rc":[{"atl":[[7.6,11]],"id":9480385}],"con":true,"img":false,"tv":14343.4}]}
{"op":"mcm","clk":"1148329435","pt":1439910283697,"mc":[{"id":"1.120089104","rc":[{"trd":[[1.17,953.68]],"ltp":1.17,"tv":953.68,"id":9612932},{"atb":[[1.17,68.27]],"id":9612932},{"atl":[[1.17,0]],"id":9612932}],"con":true,"img":false,"tv":14410.32}]}
{"op":"mcm","clk":"1148329449","pt":1439910284013,"mc":[{"id":"1.120089104","rc":[{"atb":[[1.16,16.67]],"id":9612932}],"con":true,"img":false,"tv":14410.32}]}
{"op":"mcm","clk":"1148329513","pt":1439910285185,"mc":[{"id":"1.120089104","rc":[{"atl":[[7.2,5.5]],"id":9480385}],"con":true,"img":false,"tv":14410.32}]}
{"op":"mcm","clk":"1148329536","pt":1439910285493,"mc":[{"id":"1.120089104","rc":[{"atb":[[5.8,23.42]],"id":9480385}],"con":true,"img":false,"tv":14410.32}]}
{"op":"mcm","clk":"1148329548","pt":1439910285711,"mc":[{"id":"1.120089104","rc":[{"atb":[[5.8,9.74]],"id":9480385}],"con":true,"img":false,"tv":14410.32}]}
{"op":"mcm","clk":"1148330723","pt":1439910311111,"mc":[{"id":"1.120089104","rc":[{"atb":[[1.11,33.25]],"id":9612932},{"atl":[[1.23,64.38]],"id":9612932},{"atl":[[9.6,0]],"id":9480385}],"con":true,"img":false,"tv":14410.32}]}
{"op":"mcm","clk":"1148330726","pt":1439910311215,"mc":[{"id":"1.120089104","rc":[{"atb":[[1.12,1474.03]],"id":9612932},{"atl":[[1.24,702]],"id":9612932},{"atl":[[8.8,28]],"id":9480385}],"con":true,"img":false,"tv":14410.32}]}
{"op":"mcm","clk":"1148333331","pt":1439910366454,"mc":[{"id":"1.120089104","rc":[{"spn":1.15,"spf":1.05,"id":9612932},{"atl":[[7.6,6]],"id":9480385}],"con":true,"img":false,"tv":14410.32}]}
{"op":"mcm","clk":"1148335112","pt":1439910405653,"mc":[{"id":"1.120089104","rc":[{"atl":[[1.24,202]],"id":9612932}],"con":true,"img":false,"tv":14410.32}]}
{"op":"mcm","clk":"1148335786","pt":1439910421365,"mc":[{"id":"1.120089104","rc":[{"trd":[[1.18,3297.17]],"ltp":1.18,"tv":3297.17,"id":9612932},{"atl":[[1.18,146.26]],"id":9612932}],"con":true,"img":false,"tv":14432.32}]}
{"op":"mcm","clk":"1148337021","pt":1439910448553,"mc":[{"id":"1.120089104","rc":[{"atl":[[7.6,0]],"id":9480385}],"con":true,"img":false,"tv":14432.32}]}
{"op":"mcm","clk":"1148339159","pt":1439910491877,"mc":[{"id":"1.120089104","rc":[{"atl":[[8.8,0]],"id":9480385}],"con":true,"img":false,"tv":14432.32}]}
{"op":"mcm","clk":"1148339163","pt":1439910491980,"mc":[{"id":"1.120089104","rc":[{"atl":[[9.6,26]],"id":9480385}],"con":true,"img":false,"tv":14432.32}]}
{"op":"mcm","clk":"1148341779","pt":1439910549637,"mc":[{"id":"1.120089104","rc":[{"trd":[[1.18,3357.71]],"ltp":1.18,"tv":3357.71,"id":9612932},{"atl":[[1.18,115.99]],"id":9612932}],"con":true,"img":false,"tv":14492.86}]}
{"op":"mcm","clk":"1148344021","pt":1439910610195,"mc":[{"id":"1.120089104","rc":[{"atb":[[6.6,2.93]],"id":9480385},{"spn":6.52,"spf":2.41,"id":9480385}],"con":true,"img":false,"tv":14492.86}]}
{"op":"mcm","clk":"1148344025","pt":1439910610301,"mc":[{"id":"1.120089104","rc":[{"atb":[[6.8,13.44]],"id":9480385}],"con":true,"img":false,"tv":14492.86}]}
{"op":"mcm","clk":"1148344033","pt":1439910610505,"mc":[{"id":"1.120089104","rc":[{"atb":[[6.8,13.15]],"id":9480385}],"con":true,"img":false,"tv":14492.86}]}
{"op":"mcm","clk":"1148344621","pt":1439910625674,"mc":[{"id":"1.120089104","rc":[{"atb":[[5.8,27.07]],"id":9480385}],"con":true,"img":false,"tv":14492.86}]}
{"op":"mcm","clk":"1148344635","pt":1439910625942,"mc":[{"id":"1.120089104","rc":[{"atb":[[5.8,17.33]],"id":9480385}],"con":true,"img":false,"tv":14492.86}]}
{"op":"mcm","clk":"1148354809","pt":1439910854720,"mc":[{"id":"1.120089104","rc":[{"trd":[[6.8,26.31]],"ltp":6.8,"tv":26.31,"id":9480385},{"atb":[[6.8,0]],"id":9480385},{"atl":[[6.8,0.84]],"id":9480385},{"spn":6.11,"spf":2.41,"id":9480385}],"con":true,"img":false,"tv":14519.18}]}
{"op":"mcm","clk":"1148354862","pt":1439910855829,"mc":[{"id":"1.120089104","rc":[{"atl":[[6.8,2.24]],"id":9480385}],"con":true,"img":false,"tv":14519.18}]}
{"op":"mcm","clk":"1148354913","pt":1439910856631,"mc":[{"id":"1.120089104","rc":[{"atl":[[7.2,0]],"id":9480385}],"con":true,"img":false,"tv":14519.18}]}
{"op":"mcm","clk":"1148355421","pt":1439910865653,"mc":[{"id":"1.120089104","rc":[{"atb":[[5.8,26.26]],"id":9480385}],"con":true,"img":false,"tv":14519.18}]}
{"op":"mcm","clk":"1148355432","pt":1439910865861,"mc":[{"id":"1.120089104","rc":[{"atb":[[5.8,8.93]],"id":9480385}],"con":true,"img":false,"tv":14519.18}]}
{"op":"mcm","clk":"1148355676","pt":1439910871337,"mc":[{"id":"1.120089104","rc":[{"atl":[[1.23,67.39]],"id":9612932}],"con":true,"img":false,"tv":14519.18}]}
{"op":"mcm","clk":"1148355690","pt":1439910871499,"mc":[{"id":"1.120089104","rc":[{"atl":[[1.23,9]],"id":9612932}],"con":true,"img":false,"tv":14519.18}]}
{"op":"mcm","clk":"1148355847","pt":1439910874724,"mc":[{"id":"1.120089104","rc":[{"atl":[[7,10]],"id":9480385}],"con":true,"img":false,"tv":14519.18}]}
{"op":"mcm","clk":"1148355930","pt":1439910877051,"mc":[{"id":"1.120089104","rc":[{"atl":[[1.23,6]],"id":9612932}],"con":true,"img":false,"tv":14519.18}]}
{"op":"mcm","clk":"1148356113","pt":1439910881177,"mc":[{"id":"1.120089104","rc":[{"atl":[[6.8,1.4]],"id":9480385}],"con":true,"img":false,"tv":14519.18}]}
{"op":"mcm","clk":"1148356120","pt":1439910881281,"mc":[{"id":"1.120089104","rc":[{"atl":[[7,10.84]],"id":9480385}],"con":true,"img":false,"tv":14519.18}]}
{"op":"mcm","clk":"1148356151","pt":1439910881981,"mc":[{"id":"1.120089104","rc":[{"atb":[[1.17,86.3]],"id":9612932}],"con":true,"img":false,"tv":14519.18}]}
{"op":"mcm","clk":"1148356159","pt":1439910882090,"mc":[{"id":"1.120089104","rc":[{"atb":[[6.6,6.12]],"id":9480385}],"con":true,"img":false,"tv":14519.18}]}
{"op":"mcm","clk":"1148356500","pt":1439910888601,"mc":[{"id":"1.120089104","rc":[{"atl":[[7,0]],"id":9480385}],"con":true,"img":false,"tv":14519.18}]}
{"op":"mcm","clk":"1148356507","pt":1439910888665,"mc":[{"id":"1.120089104","rc":[{"atl":[[7.2,10.84]],"id":9480385}],"con":true,"img":false,"tv":14519.18}]}
{"op":"mcm","clk":"1148356528","pt":1439910888981,"mc":[{"id":"1.120089104","rc":[{"atb":[[1.17,125.06]],"id":9612932}],"con":true,"img":false,"tv":14519.18}]}
{"op":"mcm","clk":"1148356811","pt":1439910895543,"mc":[{"id":"1.120089104","rc":[{"atb":[[1.08,21.95]],"id":9612932}],"con":true,"img":false,"tv":14519.18}]}
{"op":"mcm","clk":"1148356821","pt":1439910895752,"mc":[{"id":"1.120089104","rc":[{"atb":[[1.11,340.22]],"id":9612932}],"con":true,"img":false,"tv":14519.18}]}
{"op":"mcm","clk":"1148357638","pt":1439910913326,"mc":[{"id":"1.120089104","rc":[{"atb":[[5.3,7.23]],"id":9480385}],"con":true,"img":false,"tv":14519.18}]}
{"op":"mcm","clk":"1148357642","pt":1439910913436,"mc":[{"id":"1.120089104","rc":[{"atb":[[5,50]],"id":9480385}],"con":true,"img":false,"tv":14519.18}]}
{"op":"mcm","clk":"1148358073","pt":1439910920808,"mc":[{"id":"1.120089104","rc":[{"trd":[[1.18,3409.03]],"ltp":1.18,"tv":3409.03,"id":9612932},{"atl":[[1.18,90.33]],"id":9612932},{"spn":1.15,"spf":1.05,"id":9612932},{"spn":6.39,"spf":2.41,"id":9480385}],"con":true,"img":false,"tv":14570.5}]}
{"op":"mcm","clk":"1148358500","pt":1439910927628,"mc":[{"id":"1.120089104","rc":[{"atb":[[5.4,0]],"id":9480385}],"con":true,"img":false,"tv":14570.5}]}
{"op":"mcm","clk":"1148363156","pt":1439911016139,"mc":[{"id":"1.120089104","rc":[{"atl":[[7.2,16.84]],"id":9480385}],"con":true,"img":false,"tv":14570.5}]}
{"op":"mcm","clk":"1148365451","pt":1439911062635,"mc":[{"id":"1.120089104","rc":[{"trd":[[1.17,1173.68]],"ltp":1.17,"tv":1173.68,"id":9612932},{"atb":[[1.17,15.06]],"id":9612932}],"con":true,"img":false,"tv":14790.5}]}
