{"op":"mcm","clk":"1149272913","pt":1439921339367,"mc":[{"id":"1.120089104","rc":[{"atb":[[1.15,12021.29]],"id":9612932}],"con":true,"img":false,"tv":25843.04}]}
{"op":"mcm","clk":"1149273168","pt":1439921342617,"mc":[{"id":"1.120089104","rc":[{"atl":[[7.2,7.22]],"id":9480385}],"con":true,"img":false,"tv":25843.04}]}
{"op":"mcm","clk":"1149273809","pt":1439921349074,"mc":[{"id":"1.120089104","rc":[{"atb":[[1.15,12000]],"id":9612932}],"con":true,"img":false,"tv":25843.04}]}
{"op":"mcm","clk":"1149273946","pt":1439921350579,"mc":[{"id":"1.120089104","rc":[{"atl":[[7.2,13.97]],"id":9480385}],"con":true,"img":false,"tv":25843.04}]}
{"op":"mcm","clk":"1149275298","pt":1439921364950,"mc":[{"id":"1.120089104","rc":[{"atb":[[1.15,12021.29]],"id":9612932}],"con":true,"img":false,"tv":25843.04}]}
{"op":"mcm","clk":"1149276319","pt":1439921377408,"mc":[{"id":"1.120089104","rc":[{"atb":[[1.15,12000]],"id":9612932}],"con":true,"img":false,"tv":25843.04}]}
{"op":"mcm","clk":"1149276489","pt":1439921379606,"mc":[{"id":"1.120089104","rc":[{"atl":[[12,3.4]],"id":9480385}],"con":true,"img":false,"tv":25843.04}]}
{"op":"mcm","clk":"1149278144","pt":1439921399920,"mc":[{"id":"1.120089104","rc":[{"atb":[[1.16,5364.22]],"id":9612932}],"con":true,"img":false,"tv":25843.04}]}
{"op":"mcm","clk":"1149278909","pt":1439921409109,"mc":[{"id":"1.120089104","rc":[{"atb":[[1.15,12025.55]],"id":9612932}],"con":true,"img":false,"tv":25843.04}]}
{"op":"mcm","clk":"1149279015","pt":1439921410204,"mc":[{"id":"1.120089104","rc":[{"atl":[[8.2,250]],"id":9480385}],"con":true,"img":false,"tv":25843.04}]}
{"op":"mcm","clk":"1149279022","pt":1439921410310,"mc":[{"id":"1.120089104","rc":[{"atl":[[8,37]],"id":9480385}],"con":true,"img":false,"tv":25843.04}]}
{"op":"mcm","clk":"1149279450","pt":1439921415036,"mc":[{"id":"1.120089104","rc":[{"atl":[[1000,9]],"id":9612932},{"atb":[[6.2,54.41],[1.01,2455.04]],"id":9480385}],"con":true,"img":false,"tv":25843.04}]}
{"op":"mcm","clk":"1149279460","pt":1439921415181,"mc":[{"id":"1.120089104","rc":[{"atl":[[1000,11.25]],"id":9612932},{"atb":[[1.01,2457.03]],"id":9480385}],"con":true,"img":false,"tv":25843.04}]}
{"op":"mcm","clk":"1149279470","pt":1439921415240,"mc":[{"id":"1.120089104","rc":[{"atl":[[1000,3.25]],"id":9612932},{"atb":[[1.01,2453.03]],"id":9480385}],"con":true,"img":false,"tv":25843.04}]}
{"op":"mcm","clk":"1149279488","pt":1439921415453,"mc":[{"id":"1.120089104","rc":[{"atl":[[1000,1]],"id":9612932},{"atb":[[1.01,2451.04]],"id":9480385}],"con":true,"img":false,"tv":25843.04}]}
{"op":"mcm","clk":"1149279500","pt":1439921415561,"mc":[{"id":"1.120089104","rc":[{"trd":[[1.18,5092.47]],"ltp":1.18,"tv":5092.47,"id":9612932},{"atb":[[1.18,807.89]],"id":9612932},{"atl":[[1.19,332.64]],"id":9612932},{"trd":[[6.4,50.89]],"ltp":6.4,"tv":50.89,"id":9480385},{"atl":[[6.4,15.82]],"id":9480385}],"con":true,"img":false,"tv":25848.28}]}
{"op":"mcm","clk":"1149279786","pt":1439921418817,"mc":[{"id":"1.120089104","rc":[{"trd":[[1.19,4726.41]],"ltp":1.19,"tv":4726.41,"id":9612932},{"atl":[[1.19,322.11]],"id":9612932}],"con":true,"img":false,"tv":25869.34}]}
{"op":"mcm","clk":"1149279980","pt":1439921420841,"mc":[{"id":"1.120089104","rc":[{"atb":[[1.14,96.89]],"id":9612932}],"con":true,"img":false,"tv":25869.34}]}
{"op":"mcm","clk":"1149281626","pt":1439921437803,"mc":[{"id":"1.120089104","rc":[{"atb":[[1.13,329.22]],"id":9612932}],"con":true,"img":false,"tv":25869.34}]}
{"op":"mcm","clk":"1149285603","pt":1439921479890,"mc":[{"id":"1.120089104","rc":[{"atb":[[1.16,5370.61],[1.14,122.45],[1.13,380.33],[1.15,12038.33]],"id":9612932}],"con":true,"img":false,"tv":25869.34}]}
{"op":"mcm","clk":"1149285967","pt":1439921484207,"mc":[{"id":"1.120089104","rc":[{"atl":[[6.4,0]],"id":9480385}],"con":true,"img":false,"tv":25869.34}]}
{"op":"mcm","clk":"1149286133","pt":1439921485964,"mc":[{"id":"1.120089104","rc":[{"atl":[[6.6,0]],"id":9480385}],"con":true,"img":false,"tv":25869.34}]}
{"op":"mcm","clk":"1149286178","pt":1439921486494,"mc":[{"id":"1.120089104","rc":[{"atl":[[6.8,70.06]],"id":9480385}],"con":true,"img":false,"tv":25869.34}]}
{"op":"mcm","clk":"1149286693","pt":1439921491891,"mc":[{"id":"1.120089104","rc":[{"atl":[[7.2,7.22]],"id":9480385}],"con":true,"img":false,"tv":25869.34}]}
{"op":"mcm","clk":"1149287236","pt":1439921497666,"mc":[{"id":"1.120089104","rc":[{"atl":[[7.8,36.68]],"id":9480385}],"con":true,"img":false,"tv":25869.34}]}
{"op":"mcm","clk":"1149287473","pt":1439921500214,"mc":[{"id":"1.120089104","rc":[{"atl":[[6.6,27.27]],"id":9480385}],"con":true,"img":false,"tv":25869.34}]}
{"op":"mcm","clk":"1149287529","pt":1439921500811,"mc":[{"id":"1.120089104","rc":[{"atl":[[6.8,0]],"id":9480385}],"con":true,"img":false,"tv":25869.34}]}
{"op":"mcm","clk":"1149287662","pt":1439921502316,"mc":[{"id":"1.120089104","rc":[{"atl":[[7.2,26.11]],"id":9480385}],"con":true,"img":false,"tv":25869.34}]}
{"op":"mcm","clk":"1149287680","pt":1439921502536,"mc":[{"id":"1.120089104","rc":[{"atl":[[7.8,1.22]],"id":9480385}],"con":true,"img":false,"tv":25869.34}]}
{"op":"mcm","clk":"1149288396","pt":1439921512027,"mc":[{"id":"1.120089104","rc":[{"trd":[[6.2,71.79]],"ltp":6.2,"tv":71.79,"id":9480385},{"atb":[[6.2,52.41]],"id":9480385}],"con":true,"img":false,"tv":25873.34}]}
{"op":"mcm","clk":"1149288606","pt":1439921515039,"mc":[{"id":"1.120089104","rc":[{"atl":[[30,2]],"id":9612932}],"con":true,"img":false,"tv":25873.34}]}
{"op":"mcm","clk":"1149288627","pt":1439921515252,"mc":[{"id":"1.120089104","rc":[{"atb":[[1.1,31.97]],"id":9612932},{"atb":[[1.1,31.97]],"id":9480385}],"con":true,"img":false,"tv":25873.34}]}
{"op":"mcm","clk":"1149288761","pt":1439921516727,"mc":[{"id":"1.120089104","rc":[{"atl":[[6.6,0]],"id":9480385}],"con":true,"img":false,"tv":25873.34}]}
{"op":"mcm","clk":"1149288812","pt":1439921517361,"mc":[{"id":"1.120089104","rc":[{"atl":[[6.8,70.06]],"id":9480385}],"con":true,"img":false,"tv":25873.34}]}
{"op":"mcm","clk":"1149288895","pt":1439921518342,"mc":[{"id":"1.120089104","rc":[{"atl":[[7.2,7.22]],"id":9480385}],"con":true,"img":false,"tv":25873.34}]}
{"op":"mcm","clk":"1149289276","pt":1439921524121,"mc":[{"id":"1.120089104","rc":[{"atl":[[7.8,32.87]],"id":9480385}],"con":true,"img":false,"tv":25873.34}]}
{"op":"mcm","clk":"1149289780","pt":1439921530914,"mc":[{"id":"1.120089104","rc":[{"atl":[[8,6]],"id":9480385}],"con":true,"img":false,"tv":25873.34}]}
{"op":"mcm","clk":"1149289783","pt":1439921531010,"mc":[{"id":"1.120089104","rc":[{"atl":[[8.2,280]],"id":9480385}],"con":true,"img":false,"tv":25873.34}]}
{"op":"mcm","clk":"1149289979","pt":1439921533409,"mc":[{"id":"1.120089104","rc":[{"atl":[[6.6,27.27]],"id":9480385}],"con":true,"img":false,"tv":25873.34}]}
{"op":"mcm","clk":"1149290042","pt":1439921534319,"mc":[{"id":"1.120089104","rc":[{"atl":[[6.8,0]],"id":9480385}],"con":true,"img":false,"tv":25873.34}]}
{"op":"mcm","clk":"1149290116","pt":1439921535337,"mc":[{"id":"1.120089104","rc":[{"atl":[[7.2,26.11]],"id":9480385}],"con":true,"img":false,"tv":25873.34}]}
{"op":"mcm","clk":"1149290133","pt":1439921535551,"mc":[{"id":"1.120089104","rc":[{"atl":[[7.8,1.22]],"id":9480385}],"con":true,"img":false,"tv":25873.34}]}
{"op":"mcm","clk":"1149291297","pt":1439921550152,"mc":[{"id":"1.120089104","rc":[{"atl":[[6.6,0]],"id":9480385}],"con":true,"img":false,"tv":25873.34}]}
{"op":"mcm","clk":"1149291362","pt":1439921550805,"mc":[{"id":"1.120089104","rc":[{"atl":[[6.8,70.06]],"id":9480385}],"con":true,"img":false,"tv":25873.34}]}
{"op":"mcm","clk":"1149291456","pt":1439921551906,"mc":[{"id":"1.120089104","rc":[{"atl":[[7.2,7.22]],"id":9480385}],"con":true,"img":false,"tv":25873.34}]}
{"op":"mcm","clk":"1149291855","pt":1439921556673,"mc":[{"id":"1.120089104","rc":[{"atl":[[7.8,32.87]],"id":9480385}],"con":true,"img":false,"tv":25873.34}]}
{"op":"mcm","clk":"1149292676","pt":1439921566763,"mc":[{"id":"1.120089104","rc":[{"atl":[[6.6,27.27]],"id":9480385}],"con":true,"img":false,"tv":25873.34}]}
{"op":"mcm","clk":"1149292769","pt":1439921567986,"mc":[{"id":"1.120089104","rc":[{"atl":[[6.8,0]],"id":9480385}],"con":true,"img":false,"tv":25873.34}]}
{"op":"mcm","clk":"1149292777","pt":1439921568092,"mc":[{"id":"1.120089104","rc":[{"atl":[[1.24,202]],"id":9612932}],"con":true,"img":false,"tv":25873.34}]}
{"op":"mcm","clk":"1149293128","pt":1439921572954,"mc":[{"id":"1.120089104","rc":[{"atl":[[1.23,136.77]],"id":9612932},{"atl":[[7.2,42.83]],"id":9480385}],"con":true,"img":false,"tv":25873.34}]}
{"op":"mcm","clk":"1149293145","pt":1439921573113,"mc":[{"id":"1.120089104","rc":[{"atl":[[7.8,1.22]],"id":9480385}],"con":true,"img":false,"tv":25873.34}]}
{"op":"mcm","clk":"1149293926","pt":1439921583467,"mc":[{"id":"1.120089104","rc":[{"atb":[[1.18,655.35]],"id":9612932},{"atl":[[1.19,473.37]],"id":9612932},{"atl":[[6.6,0]],"id":9480385}],"con":true,"img":false,"tv":25873.34}]}
{"op":"mcm","clk":"1149293956","pt":1439921583758,"mc":[{"id":"1.120089104","rc":[{"atl":[[6.8,56.82]],"id":9480385}],"con":true,"img":false,"tv":25873.34}]}
{"op":"mcm","clk":"1149294012","pt":1439921584405,"mc":[{"id":"1.120089104","rc":[{"atl":[[7.2,7.22]],"id":9480385}],"con":true,"img":false,"tv":25873.34}]}
{"op":"mcm","clk":"1149294611","pt":1439921591988,"mc":[{"id":"1.120089104","rc":[{"atl":[[7.8,39.91]],"id":9480385}],"con":true,"img":false,"tv":25873.34}]}
{"op":"mcm","clk":"1149295256","pt":1439921600112,"mc":[{"id":"1.120089104","rc":[{"atl":[[6.6,27.27]],"id":9480385}],"con":true,"img":false,"tv":25873.34}]}
{"op":"mcm","clk":"1149295281","pt":1439921600425,"mc":[{"id":"1.120089104","rc":[{"atl":[[6.8,0]],"id":9480385}],"con":true,"img":false,"tv":25873.34}]}
{"op":"mcm","clk":"1149295486","pt":1439921603053,"mc":[{"id":"1.120089104","rc":[{"atl":[[7.2,26.11]],"id":9480385}],"con":true,"img":false,"tv":25873.34}]}
{"op":"mcm","clk":"1149295508","pt":1439921603272,"mc":[{"id":"1.120089104","rc":[{"atl":[[7.8,1.22]],"id":9480385}],"con":true,"img":false,"tv":25873.34}]}
{"op":"mcm","clk":"1149296786","pt":1439921616941,"mc":[{"id":"1.120089104","rc":[{"spn":1.17,"spf":1.07,"id":9612932},{"atl":[[6.6,0]],"id":9480385}],"con":true,"img":false,"tv":25873.34}]}
{"op":"mcm","clk":"1149296859","pt":1439921617906,"mc":[{"id":"1.120089104","rc":[{"atl":[[6.8,56.82]],"id":9480385}],"con":true,"img":false,"tv":25873.34}]}
{"op":"mcm","clk":"1149296970","pt":1439921619642,"mc":[{"id":"1.120089104","rc":[{"atl":[[7.2,7.22]],"id":9480385}],"con":true,"img":false,"tv":25873.34}]}
{"op":"mcm","clk":"1149297100","pt":1439921621034,"mc":[{"id":"1.120089104","rc":[{"atl":[[1.19,568.37]],"id":9612932}],"con":true,"img":false,"tv":25873.34}]}
{"op":"mcm","clk":"1149297420","pt":1439921624927,"mc":[{"id":"1.120089104","rc":[{"atl":[[7.8,32.87]],"id":9480385}],"con":true,"img":false,"tv":25873.34}]}
{"op":"mcm","clk":"1149298209","pt":1439921634201,"mc":[{"id":"1.120089104","rc":[{"atl":[[6.6,27.27]],"id":9480385}],"con":true,"img":false,"tv":25873.34}]}
{"op":"mcm","clk":"1149298276","pt":1439921634941,"mc":[{"id":"1.120089104","rc":[{"atl":[[6.8,0]],"id":9480385}],"con":true,"img":false,"tv":25873.34}]}
{"op":"mcm","clk":"1149298387","pt":1439921636432,"mc":[{"id":"1.120089104","rc":[{"atl":[[7.2,26.11]],"id":9480385}],"con":true,"img":false,"tv":25873.34}]}
{"op":"mcm","clk":"1149298422","pt":1439921636847,"mc":[{"id":"1.120089104","rc":[{"atl":[[7.8,1.22]],"id":9480385}],"con":true,"img":false,"tv":25873.34}]}
{"op":"mcm","clk":"1149298745","pt":1439921640891,"mc":[{"id":"1.120089104","rc":[{"trd":[[6.2,81.79]],"ltp":6.2,"tv":81.79,"id":9480385},{"atb":[[6.2,47.41]],"id":9480385}],"con":true,"img":false,"tv":25883.34}]}
{"op":"mcm","clk":"1149298914","pt":1439921642983,"mc":[{"id":"1.120089104","rc":[{"atl":[[6.6,0]],"id":9480385}],"con":true,"img":false,"tv":25883.34}]}
{"op":"mcm","clk":"1149298991","pt":1439921643845,"mc":[{"id":"1.120089104","rc":[{"atl":[[6.8,56.82]],"id":9480385}],"con":true,"img":false,"tv":25883.34}]}
{"op":"mcm","clk":"1149299306","pt":1439921647478,"mc":[{"id":"1.120089104","rc":[{"atl":[[7.2,7.22]],"id":9480385}],"con":true,"img":false,"tv":25883.34}]}
{"op":"mcm","clk":"1149299660","pt":1439921652345,"mc":[{"id":"1.120089104","rc":[{"atl":[[7.8,32.87]],"id":9480385}],"con":true,"img":false,"tv":25883.34}]}
{"op":"mcm","clk":"1149300191","pt":1439921659615,"mc":[{"id":"1.120089104","rc":[{"atl":[[6.6,27.27]],"id":9480385}],"con":true,"img":false,"tv":25883.34}]}
{"op":"mcm","clk":"1149300227","pt":1439921660131,"mc":[{"id":"1.120089104","rc":[{"atl":[[6.8,0]],"id":9480385}],"con":true,"img":false,"tv":25883.34}]}
{"op":"mcm","clk":"1149300582","pt":1439921664382,"mc":[{"id":"1.120089104","rc":[{"atl":[[7.2,34.51]],"id":9480385}],"con":true,"img":false,"tv":25883.34}]}
{"op":"mcm","clk":"1149300598","pt":1439921664598,"mc":[{"id":"1.120089104","rc":[{"atl":[[7.8,1.22]],"id":9480385}],"con":true,"img":false,"tv":25883.34}]}
{"op":"mcm","clk":"1149301494","pt":1439921676413,"mc":[{"id":"1.120089104","rc":[{"atl":[[6.6,0]],"id":9480385}],"con":true,"img":false,"tv":25883.34}]}
{"op":"mcm","clk":"1149301542","pt":1439921676965,"mc":[{"id":"1.120089104","rc":[{"atl":[[6.8,56.82]],"id":9480385}],"con":true,"img":false,"tv":25883.34}]}
{"op":"mcm","clk":"1149301820","pt":1439921680562,"mc":[{"id":"1.120089104","rc":[{"atl":[[7.2,7.22]],"id":9480385}],"con":true,"img":false,"tv":25883.34}]}
{"op":"mcm","clk":"1149302278","pt":1439921685809,"mc":[{"id":"1.120089104","rc":[{"atl":[[7.8,39.91]],"id":9480385}],"con":true,"img":false,"tv":25883.34}]}
{"op":"mcm","clk":"1149302376","pt":1439921687130,"mc":[{"id":"1.120089104","rc":[{"trd":[[6.8,262.9]],"ltp":6.8,"tv":262.9,"id":9480385},{"atl":[[6.8,52.26]],"id":9480385}],"con":true,"img":false,"tv":25892.46}]}
{"op":"mcm","clk":"1149302409","pt":1439921687554,"mc":[{"id":"1.120089104","rc":[{"trd":[[1.18,5144.35]],"ltp":1.18,"tv":5144.35,"id":9612932},{"atb":[[1.18,629.41]],"id":9612932},{"atl":[[6.8,54.55]],"id":9480385}],"con":true,"img":false,"tv":25944.33}]}
{"op":"mcm","clk":"1149302836","pt":1439921693017,"mc":[{"id":"1.120089104","rc":[{"atl":[[6.6,27.27]],"id":9480385}],"con":true,"img":false,"tv":25944.33}]}
{"op":"mcm","clk":"1149302852","pt":1439921693186,"mc":[{"id":"1.120089104","rc":[{"atl":[[6.8,0]],"id":9480385}],"con":true,"img":false,"tv":25944.33}]}
{"op":"mcm","clk":"1149303181","pt":1439921696865,"mc":[{"id":"1.120089104","rc":[{"atl":[[7.2,34.51]],"id":9480385}],"con":true,"img":false,"tv":25944.33}]}
{"op":"mcm","clk":"1149303201","pt":1439921697064,"mc":[{"id":"1.120089104","rc":[{"atl":[[7.8,1.22]],"id":9480385}],"con":true,"img":false,"tv":25944.33}]}
{"op":"mcm","clk":"1149303580","pt":1439921701896,"mc":[{"id":"1.120089104","rc":[{"trd":[[1.19,4746.41]],"ltp":1.19,"tv":4746.41,"id":9612932},{"atl":[[1.19,558.37]],"id":9612932}],"con":true,"img":false,"tv":25964.33}]}
{"op":"mcm","clk":"1149304208","pt":1439921709484,"mc":[{"id":"1.120089104","rc":[{"atl":[[6.6,0]],"id":9480385}],"con":true,"img":false,"tv":25964.33}]}
{"op":"mcm","clk":"1149304232","pt":1439921709753,"mc":[{"id":"1.120089104","rc":[{"atl":[[6.8,54.58]],"id":9480385}],"con":true,"img":false,"tv":25964.33}]}
{"op":"mcm","clk":"1149304774","pt":1439921715512,"mc":[{"id":"1.120089104","rc":[{"atl":[[7.2,7.22]],"id":9480385}],"con":true,"img":false,"tv":25964.33}]}
{"op":"mcm","clk":"1149305212","pt":1439921720509,"mc":[{"id":"1.120089104","rc":[{"atl":[[7.8,39.91]],"id":9480385}],"con":true,"img":false,"tv":25964.33}]}
{"op":"mcm","clk":"1149305680","pt":1439921726044,"mc":[{"id":"1.120089104","rc":[{"atl":[[6.6,27.27]],"id":9480385}],"con":true,"img":false,"tv":25964.33}]}
{"op":"mcm","clk":"1149305712","pt":1439921726462,"mc":[{"id":"1.120089104","rc":[{"atl":[[6.8,0]],"id":9480385}],"con":true,"img":false,"tv":25964.33}]}
{"op":"mcm","clk":"1149306139","pt":1439921731415,"mc":[{"id":"1.120089104","rc":[{"atl":[[7.2,34.51]],"id":9480385}],"con":true,"img":false,"tv":25964.33}]}
{"op":"mcm","clk":"1149306171","pt":1439921731690,"mc":[{"id":"1.120089104","rc":[{"atl":[[7.8,1.22]],"id":9480385}],"con":true,"img":false,"tv":25964.33}]}
{"op":"mcm","clk":"1149307079","pt":1439921742625,"mc":[{"id":"1.120089104","rc":[{"spn":1.17,"spf":1.07,"id":9612932},{"atl":[[6.6,0]],"id":9480385}],"con":true,"img":false,"tv":25964.33}]}
{"op":"mcm","clk":"1149307143","pt":1439921743215,"mc":[{"id":"1.120089104","rc":[{"atl":[[6.8,54.58]],"id":9480385}],"con":true,"img":false,"tv":25964.33}]}
{"op":"mcm","clk":"1149307258","pt":1439921744565,"mc":[{"id":"1.120089104","rc":[{"trd":[[1.18,6403.19]],"ltp":1.18,"tv":6403.19,"id":9612932},{"atb":[[1.18,0]],"id":9612932},{"atl":[[1.18,670.58]],"id":9612932}],"con":true,"img":false,"tv":27223.17}]}
{"op":"mcm","clk":"1149307299","pt":1439921745051,"mc":[{"id":"1.120089104","rc":[{"atl":[[6.8,0]],"id":9480385}],"con":true,"img":false,"tv":27223.17}]}
{"op":"mcm","clk":"1149307964","pt":1439921751938,"mc":[{"id":"1.120089104","rc":[{"atl":[[7.2,7.22]],"id":9480385}],"con":true,"img":false,"tv":27223.17}]}
{"op":"mcm","clk":"1149308151","pt":1439921754159,"mc":[{"id":"1.120089104","rc":[{"atl":[[1.23,201]],"id":9612932},{"atl":[[7.8,40.66]],"id":9480385}],"con":true,"img":false,"tv":27223.17}]}
{"op":"mcm","clk":"1149308170","pt":1439921754382,"mc":[{"id":"1.120089104","rc":[{"atl":[[1.23,64.23]],"id":9612932}],"con":true,"img":false,"tv":27223.17}]}
{"op":"mcm","clk":"1149308549","pt":1439921759040,"mc":[{"id":"1.120089104","rc":[{"atb":[[1.17,573.24]],"id":9612932}],"con":true,"img":false,"tv":27223.17}]}
{"op":"mcm","clk":"1149309667","pt":1439921771227,"mc":[{"id":"1.120089104","rc":[{"atb":[[1.14,76.66]],"id":9612932}],"con":true,"img":false,"tv":27223.17}]}
{"op":"mcm","clk":"1149309731","pt":1439921771824,"mc":[{"id":"1.120089104","rc":[{"atb":[[1.13,159.33]],"id":9612932},{"atl":[[1.24,0]],"id":9612932},{"atl":[[8.2,250]],"id":9480385}],"con":true,"img":false,"tv":27223.17}]}
{"op":"mcm","clk":"1149309742","pt":1439921771932,"mc":[{"id":"1.120089104","rc":[{"atb":[[1.12,13493.39]],"id":9612932},{"atl":[[1.23,267.23]],"id":9612932},{"atl":[[8.8,28]],"id":9480385}],"con":true,"img":false,"tv":27223.17}]}
{"op":"mcm","clk":"1149310337","pt":1439921776985,"mc":[{"id":"1.120089104","rc":[{"atb":[[1.14,98.5]],"id":9612932}],"con":true,"img":false,"tv":27223.17}]}
{"op":"mcm","clk":"1149310799","pt":1439921780827,"mc":[{"id":"1.120089104","rc":[{"trd":[[1.17,2225.5]],"ltp":1.17,"tv":2225.5,"id":9612932},{"atb":[[1.17,543.24]],"id":9612932}],"con":true,"img":false,"tv":27283.17}]}
{"op":"mcm","clk":"1149314087","pt":1439921809401,"mc":[{"id":"1.120089104","rc":[{"spn":1.16,"spf":1.07,"id":9612932},{"atb":[[6.2,57.41]],"id":9480385}],"con":true,"img":false,"tv":27283.17}]}
{"op":"mcm","clk":"1149314760","pt":1439921815344,"mc":[{"id":"1.120089104","rc":[{"trd":[[1.18,6593.43]],"ltp":1.18,"tv":6593.43,"id":9612932},{"atl":[[1.18,575.46]],"id":9612932}],"con":true,"img":false,"tv":27473.42}]}
{"op":"mcm","clk":"1149317439","pt":1439921838990,"mc":[{"id":"1.120089104","rc":[{"trd":[[1.18,6614.57]],"ltp":1.18,"tv":6614.57,"id":9612932},{"atl":[[1.18,564.89]],"id":9612932}],"con":true,"img":false,"tv":27494.56}]}
{"op":"mcm","clk":"1149317772","pt":1439921842329,"mc":[{"id":"1.120089104","rc":[{"atb":[[6.2,47.41]],"id":9480385}],"con":true,"img":false,"tv":27494.56}]}
{"op":"mcm","clk":"1149317785","pt":1439921842435,"mc":[{"id":"1.120089104","rc":[{"atb":[[5.8,15.19]],"id":9480385}],"con":true,"img":false,"tv":27494.56}]}
{"op":"mcm","clk":"1149327274","pt":1439921929200,"mc":[{"id":"1.120089104","rc":[{"atl":[[6.8,22.03]],"id":9480385}],"con":true,"img":false,"tv":27494.56}]}
{"op":"mcm","clk":"1149327623","pt":1439921932894,"mc":[{"id":"1.120089104","rc":[{"atl":[[7.8,78.31]],"id":9480385}],"con":true,"img":false,"tv":27494.56}]}
{"op":"mcm","clk":"1149327644","pt":1439921933105,"mc":[{"id":"1.120089104","rc":[{"atl":[[7.8,38.88]],"id":9480385}],"con":true,"img":false,"tv":27494.56}]}
{"op":"mcm","clk":"1149328060","pt":1439921937995,"mc":[{"id":"1.120089104","rc":[{"atb":[[5.8,5.19]],"id":9480385}],"con":true,"img":false,"tv":27494.56}]}
{"op":"mcm","clk":"1149328277","pt":1439921940006,"mc":[{"id":"1.120089104","rc":[{"atl":[[7.8,1.22]],"id":9480385}],"con":true,"img":false,"tv":27494.56}]}
{"op":"mcm","clk":"1149328967","pt":1439921945804,"mc":[{"id":"1.120089104","rc":[{"atl":[[7.8,11.69]],"id":9480385}],"con":true,"img":false,"tv":27494.56}]}
{"op":"mcm","clk":"1149329877","pt":1439921952786,"mc":[{"id":"1.120089104","rc":[{"atl":[[8.8,0]],"id":9480385}],"con":true,"img":false,"tv":27494.56}]}
{"op":"mcm","clk":"1149329887","pt":1439921952893,"mc":[{"id":"1.120089104","rc":[{"atl":[[8.2,280]],"id":9480385}],"con":true,"img":false,"tv":27494.56}]}
{"op":"mcm","clk":"1149330422","pt":1439921957552,"mc":[{"id":"1.120089104","rc":[{"trd":[[1.18,6764.57]],"ltp":1.18,"tv":6764.57,"id":9612932},{"atl":[[1.18,866.86]],"id":9612932}],"con":true,"img":false,"tv":27644.56}]}
{"op":"mcm","clk":"1149342056","pt":1439921979401,"mc":[{"id":"1.120089104","rc":[{"atb":[[1.17,518.24]],"id":9612932}],"con":true,"img":false,"tv":27644.56}]}
{"op":"mcm","clk":"1149342063","pt":1439921979500,"mc":[{"id":"1.120089104","rc":[{"trd":[[1.18,6814.57]],"ltp":1.18,"tv":6814.57,"id":9612932},{"atl":[[1.18,841.86]],"id":9612932}],"con":true,"img":false,"tv":27694.56}]}
{"op":"mcm","clk":"1149342201","pt":1439921980591,"mc":[{"id":"1.120089104","rc":[{"atl":[[3.5,20]],"id":9612932}],"con":true,"img":false,"tv":27694.56}]}
{"op":"mcm","clk":"1149342993","pt":1439921987589,"mc":[{"id":"1.120089104","rc":[{"atl":[[6.8,0]],"id":9480385}],"con":true,"img":false,"tv":27694.56}]}
{"op":"mcm","clk":"1149343607","pt":1439921994100,"mc":[{"id":"1.120089104","rc":[{"spn":1.16,"spf":1.07,"id":9612932},{"atl":[[7.8,1.22]],"id":9480385}],"con":true,"img":false,"tv":27694.56}]}
{"op":"mcm","clk":"1149343943","pt":1439921997942,"mc":[{"id":"1.120089104","rc":[{"trd":[[1.17,2230.62]],"ltp":1.17,"tv":2230.62,"id":9612932},{"atb":[[1.17,515.68]],"id":9612932}],"con":true,"img":false,"tv":27699.67}]}
{"op":"mcm","clk":"1149344065","pt":1439921999131,"mc":[{"id":"1.120089104","rc":[{"atl":[[7.8,20.56]],"id":9480385}],"con":true,"img":false,"tv":27699.67}]}
{"op":"mcm","clk":"1149345417","pt":1439922013110,"mc":[{"id":"1.120089104","rc":[{"atl":[[1.2,587.98]],"id":9612932}],"con":true,"img":false,"tv":27699.67}]}
{"op":"mcm","clk":"1149345428","pt":1439922013217,"mc":[{"id":"1.120089104","rc":[{"atl":[[8.2,250]],"id":9480385}],"con":true,"img":false,"tv":27699.67}]}
{"op":"mcm","clk":"1149345431","pt":1439922013321,"mc":[{"id":"1.120089104","rc":[{"atl":[[8.8,28]],"id":9480385}],"con":true,"img":false,"tv":27699.67}]}
{"op":"mcm","clk":"1149346023","pt":1439922019195,"mc":[{"id":"1.120089104","rc":[{"atl":[[6.8,13.78]],"id":9480385}],"con":true,"img":false,"tv":27699.67}]}
{"op":"mcm","clk":"1149346283","pt":1439922021828,"mc":[{"id":"1.120089104","rc":[{"atl":[[7.8,1.22]],"id":9480385}],"con":true,"img":false,"tv":27699.67}]}
{"op":"mcm","clk":"1149346931","pt":1439922028734,"mc":[{"id":"1.120089104","rc":[{"atl":[[7.8,7.4]],"id":9480385}],"con":true,"img":false,"tv":27699.67}]}
{"op":"mcm","clk":"1149351234","pt":1439922073664,"mc":[{"id":"1.120089104","rc":[{"atl":[[8.8,0]],"id":9480385}],"con":true,"img":false,"tv":27699.67}]}
{"op":"mcm","clk":"1149351249","pt":1439922073783,"mc":[{"id":"1.120089104","rc":[{"atl":[[8.2,280]],"id":9480385}],"con":true,"img":false,"tv":27699.67}]}
{"op":"mcm","clk":"1149352782","pt":1439922089732,"mc":[{"id":"1.120089104","rc":[{"atb":[[1.17,647.3]],"id":9612932},{"atb":[[6.4,24.06]],"id":9480385}],"con":true,"img":false,"tv":27699.67}]}
{"op":"mcm","clk":"1149352977","pt":1439922091287,"mc":[{"id":"1.120089104","rc":[{"atb":[[5.1,0]],"id":9480385}],"con":true,"img":false,"tv":27699.67}]}
{"op":"mcm","clk":"1149354060","pt":1439922103246,"mc":[{"id":"1.120089104","rc":[{"atl":[[1.21,300.82]],"id":9612932},{"atb":[[6.6,27.27]],"id":9480385}],"con":true,"img":false,"tv":27699.67}]}
{"op":"mcm","clk":"1149354137","pt":1439922104179,"mc":[{"id":"1.120089104","rc":[{"atb":[[1.01,2453.04]],"id":9480385}],"con":true,"img":false,"tv":27699.67}]}
{"op":"mcm","clk":"1149354156","pt":1439922104392,"mc":[{"id":"1.120089104","rc":[{"atb":[[1.01,2454.85]],"id":9480385}],"con":true,"img":false,"tv":27699.67}]}
{"op":"mcm","clk":"1149354158","pt":1439922104489,"mc":[{"id":"1.120089104","rc":[{"atb":[[6.4,0]],"id":9480385}],"con":true,"img":false,"tv":27699.67}]}
{"op":"mcm","clk":"1149354164","pt":1439922104597,"mc":[{"id":"1.120089104","rc":[{"atb":[[1.01,2453.04],[6.6,51.33]],"id":9480385}],"con":true,"img":false,"tv":27699.67}]}
{"op":"mcm","clk":"1149354174","pt":1439922104710,"mc":[{"id":"1.120089104","rc":[{"atb":[[6,88.88]],"id":9480385}],"con":true,"img":false,"tv":27699.67}]}
{"op":"mcm","clk":"1149354181","pt":1439922104821,"mc":[{"id":"1.120089104","rc":[{"atb":[[6.6,50.6]],"id":9480385}],"con":true,"img":false,"tv":27699.67}]}
{"op":"mcm","clk":"1149354199","pt":1439922104894,"mc":[{"id":"1.120089104","rc":[{"atb":[[1.01,2451.04]],"id":9480385}],"con":true,"img":false,"tv":27699.67}]}
{"op":"mcm","clk":"1149355115","pt":1439922115486,"mc":[{"id":"1.120089104","rc":[{"atb":[[1.01,2528.04]],"id":9612932},{"atb":[[1.01,2506.04]],"id":9480385}],"con":true,"img":false,"tv":27699.67}]}
{"op":"mcm","clk":"1149356522","pt":1439922134338,"mc":[{"id":"1.120089104","rc":[{"spn":1.16,"spf":1.07,"id":9612932},{"atb":[[5.3,78.46]],"id":9480385},{"spn":6.6,"spf":2.41,"id":9480385}],"con":true,"img":false,"tv":27699.67}]}
{"op":"mcm","clk":"1149356531","pt":1439922134450,"mc":[{"id":"1.120089104","rc":[{"atb":[[5.5,70.45]],"id":9480385}],"con":true,"img":false,"tv":27699.67}]}
{"op":"mcm","clk":"1149357101","pt":1439922141645,"mc":[{"id":"1.120089104","rc":[{"atb":[[5.6,6]],"id":9480385}],"con":true,"img":false,"tv":27699.67}]}
{"op":"mcm","clk":"1149357926","pt":1439922152623,"mc":[{"id":"1.120089104","rc":[{"atb":[[5,251.23]],"id":9480385}],"con":true,"img":false,"tv":27699.67}]}
{"op":"mcm","clk":"1149357931","pt":1439922152737,"mc":[{"id":"1.120089104","rc":[{"atb":[[5.5,89.67]],"id":9480385}],"con":true,"img":false,"tv":27699.67}]}
{"op":"mcm","clk":"1149359365","pt":1439922168568,"mc":[{"id":"1.120089104","rc":[{"atb":[[5,124.78]],"id":9480385}],"con":true,"img":false,"tv":27699.67}]}
{"op":"mcm","clk":"1149359375","pt":1439922168668,"mc":[{"id":"1.120089104","rc":[{"atb":[[5.5,216.12]],"id":9480385}],"con":true,"img":false,"tv":27699.67}]}
{"op":"mcm","clk":"1149360533","pt":1439922184098,"mc":[{"id":"1.120089104","rc":[{"atl":[[6.8,0]],"id":9480385}],"con":true,"img":false,"tv":27699.67}]}
{"op":"mcm","clk":"1149360994","pt":1439922188771,"mc":[{"id":"1.120089104","rc":[{"atl":[[7.8,1.22]],"id":9480385}],"con":true,"img":false,"tv":27699.67}]}
{"op":"mcm","clk":"1149361042","pt":1439922189198,"mc":[{"id":"1.120089104","rc":[{"atb":[[5,111.49]],"id":9480385}],"con":true,"img":false,"tv":27699.67}]}
{"op":"mcm","clk":"1149361045","pt":1439922189250,"mc":[{"id":"1.120089104","rc":[{"atb":[[5.5,229.41]],"id":9480385}],"con":true,"img":false,"tv":27699.67}]}
{"op":"mcm","clk":"1149361439","pt":1439922193750,"mc":[{"id":"1.120089104","rc":[{"atl":[[7.8,8.66]],"id":9480385}],"con":true,"img":false,"tv":27699.67}]}
{"op":"mcm","clk":"1149361478","pt":1439922194143,"mc":[{"id":"1.120089104","rc":[{"atb":[[5,20.01]],"id":9480385}],"con":true,"img":false,"tv":27699.67}]}
{"op":"mcm","clk":"1149361480","pt":1439922194234,"mc":[{"id":"1.120089104","rc":[{"atb":[[5.5,320.89]],"id":9480385}],"con":true,"img":false,"tv":27699.67}]}
{"op":"mcm","clk":"1149361529","pt":1439922194827,"mc":[{"id":"1.120089104","rc":[{"atl":[[8.2,250]],"id":9480385}],"con":true,"img":false,"tv":27699.67}]}
{"op":"mcm","clk":"1149361540","pt":1439922194943,"mc":[{"id":"1.120089104","rc":[{"atl":[[9,28]],"id":9480385}],"con":true,"img":false,"tv":27699.67}]}
{"op":"mcm","clk":"1149365613","pt":1439922246782,"mc":[{"id":"1.120089104","rc":[{"atb":[[5,0]],"id":9480385}],"con":true,"img":false,"tv":27699.67}]}
{"op":"mcm","clk":"1149365622","pt":1439922246881,"mc":[{"id":"1.120089104","rc":[{"atb":[[5.5,340.9]],"id":9480385}],"con":true,"img":false,"tv":27699.67}]}
{"op":"mcm","clk":"1149366325","pt":1439922255537,"mc":[{"id":"1.120089104","rc":[{"atl":[[9,0]],"id":9480385}],"con":true,"img":false,"tv":27699.67}]}
{"op":"mcm","clk":"1149366334","pt":1439922255639,"mc":[{"id":"1.120089104","rc":[{"atl":[[8.8,28]],"id":9480385}],"con":true,"img":false,"tv":27699.67}]}
{"op":"mcm","clk":"1149366739","pt":1439922260602,"mc":[{"id":"1.120089104","rc":[{"trd":[[1.18,6855.63]],"ltp":1.18,"tv":6855.63,"id":9612932},{"atl":[[1.18,821.33]],"id":9612932}],"con":true,"img":false,"tv":27740.73}]}
{"op":"mcm","clk":"1149368925","pt":1439922285238,"mc":[{"id":"1.120089104","rc":[{"trd":[[1.17,2235.73]],"ltp":1.17,"tv":2235.73,"id":9612932},{"atb":[[1.17,644.74]],"id":9612932}],"con":true,"img":false,"tv":27745.84}]}
{"op":"mcm","clk":"1149371531","pt":1439922316356,"mc":[{"id":"1.120089104","rc":[{"trd":[[1.18,6875.63]],"ltp":1.18,"tv":6875.63,"id":9612932},{"atl":[[1.18,811.33]],"id":9612932},{"atb":[[1.18,40]],"id":9480385}],"con":true,"img":false,"tv":27765.84}]}
{"op":"mcm","clk":"1149371694","pt":1439922317974,"mc":[{"id":"1.120089104","rc":[{"atb":[[1.14,101.12]],"id":9612932}],"con":true,"img":false,"tv":27765.84}]}
{"op":"mcm","clk":"1149372024","pt":1439922321254,"mc":[{"id":"1.120089104","rc":[{"trd":[[1.18,6879.63]],"ltp":1.18,"tv":6879.63,"id":9612932},{"atl":[[1.18,809.33]],"id":9612932}],"con":true,"img":false,"tv":27769.84}]}
{"op":"mcm","clk":"1149372355","pt":1439922324885,"mc":[{"id":"1.120089104","rc":[{"trd":[[1.17,3525.22]],"ltp":1.17,"tv":3525.22,"id":9612932},{"atb":[[1.17,0]],"id":9612932},{"atl":[[1.17,4355.26]],"id":9612932}],"con":true,"img":false,"tv":29059.33}]}
{"op":"mcm","clk":"1149372707","pt":1439922328739,"mc":[{"id":"1.120089104","rc":[{"atb":[[6.8,3.1]],"id":9480385}],"con":true,"img":false,"tv":29059.33}]}
{"op":"mcm","clk":"1149372710","pt":1439922328843,"mc":[{"id":"1.120089104","rc":[{"atb":[[1.16,5388.83]],"id":9612932}],"con":true,"img":false,"tv":29059.33}]}
{"op":"mcm","clk":"1149372786","pt":1439922329615,"mc":[{"id":"1.120089104","rc":[{"atb":[[6.8,8.21]],"id":9480385}],"con":true,"img":false,"tv":29059.33}]}
{"op":"mcm","clk":"1149372954","pt":1439922331858,"mc":[{"id":"1.120089104","rc":[{"atl":[[1.26,0],[1.21,0.82]],"id":9612932},{"atb":[[6,38.88],[5.7,0]],"id":9480385}],"con":true,"img":false,"tv":29059.33}]}
{"op":"mcm","clk":"1149373051","pt":1439922332987,"mc":[{"id":"1.120089104","rc":[{"atl":[[1.17,4369.57]],"id":9612932}],"con":true,"img":false,"tv":29059.33}]}
{"op":"mcm","clk":"1149373246","pt":1439922335396,"mc":[{"id":"1.120089104","rc":[{"atb":[[1.12,12852.83]],"id":9612932}],"con":true,"img":false,"tv":29059.33}]}
{"op":"mcm","clk":"1149373266","pt":1439922335713,"mc":[{"id":"1.120089104","rc":[{"atb":[[1.11,2697.4]],"id":9612932}],"con":true,"img":false,"tv":29059.33}]}
{"op":"mcm","clk":"1149373370","pt":1439922337114,"mc":[{"id":"1.120089104","rc":[{"atl":[[1.21,141.74]],"id":9612932},{"atb":[[6.4,6.38]],"id":9480385}],"con":true,"img":false,"tv":29059.33}]}
{"op":"mcm","clk":"1149373410","pt":1439922337593,"mc":[{"id":"1.120089104","rc":[{"atl":[[1.23,203]],"id":9612932},{"atb":[[5.8,2]],"id":9480385}],"con":true,"img":false,"tv":29059.33}]}
{"op":"mcm","clk":"1149373657","pt":1439922340696,"mc":[{"id":"1.120089104","rc":[{"atl":[[1.2,887.98]],"id":9612932}],"con":true,"img":false,"tv":29059.33}]}
{"op":"mcm","clk":"1149373669","pt":1439922340909,"mc":[{"id":"1.120089104","rc":[{"atb":[[6,8.88]],"id":9480385},{"atl":[[7,0]],"id":9480385}],"con":true,"img":false,"tv":29059.33}]}
{"op":"mcm","clk":"1149373839","pt":1439922342951,"mc":[{"id":"1.120089104","rc":[{"atb":[[6.4,29.81]],"id":9480385}],"con":true,"img":false,"tv":29059.33}]}
{"op":"mcm","clk":"1149373862","pt":1439922343165,"mc":[{"id":"1.120089104","rc":[{"atl":[[1.21,0.82]],"id":9612932},{"atb":[[6.4,23.42]],"id":9480385}],"con":true,"img":false,"tv":29059.33}]}
{"op":"mcm","clk":"1149374469","pt":1439922349439,"mc":[{"id":"1.120089104","rc":[{"atl":[[1.21,141.74]],"id":9612932},{"atb":[[6,37.71]],"id":9480385}],"con":true,"img":false,"tv":29059.33}]}
{"op":"mcm","clk":"1149374489","pt":1439922349658,"mc":[{"id":"1.120089104","rc":[{"atb":[[6.4,0]],"id":9480385},{"atl":[[7.8,1.22]],"id":9480385}],"con":true,"img":false,"tv":29059.33}]}
{"op":"mcm","clk":"1149374907","pt":1439922354174,"mc":[{"id":"1.120089104","rc":[{"atb":[[1.12,5639.07]],"id":9612932}],"con":true,"img":false,"tv":29059.33}]}
{"op":"mcm","clk":"1149374918","pt":1439922354284,"mc":[{"id":"1.120089104","rc":[{"atb":[[6.4,29.81]],"id":9480385},{"atl":[[8.6,35.02]],"id":9480385}],"con":true,"img":false,"tv":29059.33}]}
{"op":"mcm","clk":"1149374924","pt":1439922354389,"mc":[{"id":"1.120089104","rc":[{"atb":[[1.11,5836.17]],"id":9612932}],"con":true,"img":false,"tv":29059.33}]}
{"op":"mcm","clk":"1149374934","pt":1439922354497,"mc":[{"id":"1.120089104","rc":[{"atl":[[1.21,0.82]],"id":9612932},{"atb":[[6,8.88],[5.3,0]],"id":9480385}],"con":true,"img":false,"tv":29059.33}]}
{"op":"mcm","clk":"1149374942","pt":1439922354556,"mc":[{"id":"1.120089104","rc":[{"atb":[[1.11,11353.91]],"id":9612932},{"atb":[[5.6,84.46]],"id":9480385}],"con":true,"img":false,"tv":29059.33}]}
{"op":"mcm","clk":"1149375442","pt":1439922359117,"mc":[{"id":"1.120089104","rc":[{"atb":[[5.4,0]],"id":9480385}],"con":true,"img":false,"tv":29059.33}]}
{"op":"mcm","clk":"1149375465","pt":1439922359329,"mc":[{"id":"1.120089104","rc":[{"atl":[[1.21,57.23]],"id":9612932}],"con":true,"img":false,"tv":29059.33}]}
{"op":"mcm","clk":"1149376595","pt":1439922368703,"mc":[{"id":"1.120089104","rc":[{"atb":[[1.16,5404.8]],"id":9612932}],"con":true,"img":false,"tv":29059.33}]}
{"op":"mcm","clk":"1149377249","pt":1439922376228,"mc":[{"id":"1.120089104","rc":[{"atb":[[1.12,5416.07]],"id":9612932},{"atl":[[1.23,0]],"id":9612932},{"atb":[[5.5,295.9]],"id":9480385},{"atl":[[8.8,0]],"id":9480385}],"con":true,"img":false,"tv":29059.33}]}
{"op":"mcm","clk":"1149377254","pt":1439922376284,"mc":[{"id":"1.120089104","rc":[{"atb":[[1.11,11578.91]],"id":9612932},{"atl":[[1.22,550]],"id":9612932},{"atb":[[5.7,44]],"id":9480385},{"atl":[[9.2,27]],"id":9480385}],"con":true,"img":false,"tv":29059.33}]}
{"op":"mcm","clk":"1149377697","pt":1439922381533,"mc":[{"id":"1.120089104","rc":[{"atb":[[1.12,2366.79]],"id":9612932},{"spn":1.16,"spf":1.07,"id":9612932},{"spn":6.78,"spf":2.41,"id":9480385}],"con":true,"img":false,"tv":29059.33}]}
{"op":"mcm","clk":"1149377752","pt":1439922382025,"mc":[{"id":"1.120089104","rc":[{"atb":[[1.11,15238.04]],"id":9612932}],"con":true,"img":false,"tv":29059.33}]}
{"op":"mcm","clk":"1149377960","pt":1439922384037,"mc":[{"id":"1.120089104","rc":[{"atb":[[1.12,1923.73]],"id":9612932}],"con":true,"img":false,"tv":29059.33}]}
{"op":"mcm","clk":"1149378029","pt":1439922384636,"mc":[{"id":"1.120089104","rc":[{"atb":[[1.11,15769.71]],"id":9612932}],"con":true,"img":false,"tv":29059.33}]}
{"op":"mcm","clk":"1149379244","pt":1439922399621,"mc":[{"id":"1.120089104","rc":[{"atb":[[6.6,27.27]],"id":9480385}],"con":true,"img":false,"tv":29059.33}]}
{"op":"mcm","clk":"1149379252","pt":1439922399727,"mc":[{"id":"1.120089104","rc":[{"atb":[[6.8,31.54]],"id":9480385}],"con":true,"img":false,"tv":29059.33}]}
{"op":"mcm","clk":"1149379269","pt":1439922399897,"mc":[{"id":"1.120089104","rc":[{"atb":[[6.8,30.85]],"id":9480385}],"con":true,"img":false,"tv":29059.33}]}
{"op":"mcm","clk":"1149382136","pt":1439922432151,"mc":[{"id":"1.120089104","rc":[{"atl":[[1.2,800]],"id":9612932}],"con":true,"img":false,"tv":29059.33}]}
{"op":"mcm","clk":"1149382148","pt":1439922432267,"mc":[{"id":"1.120089104","rc":[{"trd":[[1.16,2041.13]],"ltp":1.16,"tv":2041.13,"id":9612932},{"atb":[[1.16,5316.83]],"id":9612932}],"con":true,"img":false,"tv":29235.29}]}
{"op":"mcm","clk":"1149382597","pt":1439922437044,"mc":[{"id":"1.120089104","rc":[{"atb":[[1.12,1256.48]],"id":9612932}],"con":true,"img":false,"tv":29235.29}]}
{"op":"mcm","clk":"1149382653","pt":1439922437681,"mc":[{"id":"1.120089104","rc":[{"atb":[[1.11,16570.42]],"id":9612932}],"con":true,"img":false,"tv":29235.29}]}
{"op":"mcm","clk":"1149384111","pt":1439922455783,"mc":[{"id":"1.120089104","rc":[{"atl":[[1.2,300]],"id":9612932},{"spn":6.8,"spf":2.41,"id":9480385}],"con":true,"img":false,"tv":29235.29}]}
{"op":"mcm","clk":"1149384122","pt":1439922455892,"mc":[{"id":"1.120089104","rc":[{"trd":[[1.16,3041.13]],"ltp":1.16,"tv":3041.13,"id":9612932},{"atb":[[1.16,4816.83]],"id":9612932}],"con":true,"img":false,"tv":30235.29}]}
{"op":"mcm","clk":"1149386732","pt":1439922487498,"mc":[{"id":"1.120089104","rc":[{"trd":[[6.8,266.9]],"ltp":6.8,"tv":266.9,"id":9480385},{"atb":[[6.8,28.85]],"id":9480385}],"con":true,"img":false,"tv":30239.29}]}
{"op":"mcm","clk":"1149387107","pt":1439922492572,"mc":[{"id":"1.120089104","rc":[{"trd":[[1.16,3623.05]],"ltp":1.16,"tv":3623.05,"id":9612932},{"atb":[[1.16,4525.87]],"id":9612932}],"con":true,"img":false,"tv":30821.21}]}
{"op":"mcm","clk":"1149388007","pt":1439922503474,"mc":[{"id":"1.120089104","rc":[{"atb":[[1.16,4509.89]],"id":9612932}],"con":true,"img":false,"tv":30821.21}]}
{"op":"mcm","clk":"1149388118","pt":1439922504977,"mc":[{"id":"1.120089104","rc":[{"atb":[[1.98,10]],"id":9480385}],"con":true,"img":false,"tv":30821.21}]}
{"op":"mcm","clk":"1149388792","pt":1439922513382,"mc":[{"id":"1.120089104","rc":[{"atl":[[6,2]],"id":9612932}],"con":true,"img":false,"tv":30821.21}]}
{"op":"mcm","clk":"1149388986","pt":1439922515096,"mc":[{"id":"1.120089104","rc":[{"atb":[[6.8,31.19]],"id":9480385}],"con":true,"img":false,"tv":30821.21}]}
{"op":"mcm","clk":"1149389149","pt":1439922517023,"mc":[{"id":"1.120089104","rc":[{"atl":[[7,21.56]],"id":9480385}],"con":true,"img":false,"tv":30821.21}]}
{"op":"mcm","clk":"1149389559","pt":1439922522071,"mc":[{"id":"1.120089104","rc":[{"atb":[[1.16,4528.11]],"id":9612932}],"con":true,"img":false,"tv":30821.21}]}
{"op":"mcm","clk":"1149389605","pt":1439922522405,"mc":[{"id":"1.120089104","rc":[{"trd":[[7,7.96]],"ltp":7.0,"tv":7.96,"id":9480385},{"atl":[[7,18.53]],"id":9480385}],"con":true,"img":false,"tv":30827.26}]}
{"op":"mcm","clk":"1149389671","pt":1439922523111,"mc":[{"id":"1.120089104","rc":[{"atl":[[8,13.72]],"id":9480385}],"con":true,"img":false,"tv":30827.26}]}
{"op":"mcm","clk":"1149389684","pt":1439922523317,"mc":[{"id":"1.120089104","rc":[{"atl":[[8.6,0]],"id":9480385}],"con":true,"img":false,"tv":30827.26}]}
{"op":"mcm","clk":"1149390029","pt":1439922526876,"mc":[{"id":"1.120089104","rc":[{"trd":[[1.17,3933.22]],"ltp":1.17,"tv":3933.22,"id":9612932},{"atl":[[1.17,4165.57]],"id":9612932}],"con":true,"img":false,"tv":31235.26}]}
{"op":"mcm","clk":"1149392568","pt":1439922557022,"mc":[{"id":"1.120089104","rc":[{"atl":[[9.2,0]],"id":9480385}],"con":true,"img":false,"tv":31235.26}]}
{"op":"mcm","clk":"1149392576","pt":1439922557108,"mc":[{"id":"1.120089104","rc":[{"atl":[[9,28]],"id":9480385}],"con":true,"img":false,"tv":31235.26}]}
{"op":"mcm","clk":"1149395055","pt":1439922584424,"mc":[{"id":"1.120089104","rc":[{"atl":[[7,0]],"id":9480385}],"con":true,"img":false,"tv":31235.26}]}
{"op":"mcm","clk":"1149395462","pt":1439922588745,"mc":[{"id":"1.120089104","rc":[{"trd":[[1.17,4050.82]],"ltp":1.17,"tv":4050.82,"id":9612932},{"atl":[[1.17,4106.77]],"id":9612932}],"con":true,"img":false,"tv":31352.86}]}
{"op":"mcm","clk":"1149396107","pt":1439922595610,"mc":[{"id":"1.120089104","rc":[{"atb":[[1.14,79.28]],"id":9612932},{"atl":[[8,6]],"id":9480385}],"con":true,"img":false,"tv":31352.86}]}
{"op":"mcm","clk":"1149396514","pt":1439922600857,"mc":[{"id":"1.120089104","rc":[{"atl":[[8.8,34.94]],"id":9480385}],"con":true,"img":false,"tv":31352.86}]}
{"op":"mcm","clk":"1149397109","pt":1439922607708,"mc":[{"id":"1.120089104","rc":[{"trd":[[1.17,4459.14]],"ltp":1.17,"tv":4459.14,"id":9612932},{"atl":[[1.17,3902.61]],"id":9612932}],"con":true,"img":false,"tv":31761.18}]}
{"op":"mcm","clk":"1149397818","pt":1439922615371,"mc":[{"id":"1.120089104","rc":[{"atl":[[7,13.39]],"id":9480385}],"con":true,"img":false,"tv":31761.18}]}
{"op":"mcm","clk":"1149397921","pt":1439922616402,"mc":[{"id":"1.120089104","rc":[{"atl":[[8,24.54]],"id":9480385}],"con":true,"img":false,"tv":31761.18}]}
{"op":"mcm","clk":"1149397932","pt":1439922616613,"mc":[{"id":"1.120089104","rc":[{"atl":[[8.8,0]],"id":9480385}],"con":true,"img":false,"tv":31761.18}]}
{"op":"mcm","clk":"1149398034","pt":1439922617545,"mc":[{"id":"1.120089104","rc":[{"atl":[[9,0]],"id":9480385}],"con":true,"img":false,"tv":31761.18}]}
{"op":"mcm","clk":"1149398038","pt":1439922617653,"mc":[{"id":"1.120089104","rc":[{"atl":[[9.2,27]],"id":9480385}],"con":true,"img":false,"tv":31761.18}]}
{"op":"mcm","clk":"1149398158","pt":1439922619200,"mc":[{"id":"1.120089104","rc":[{"trd":[[1.17,4561.14]],"ltp":1.17,"tv":4561.14,"id":9612932},{"atl":[[1.17,3851.61]],"id":9612932}],"con":true,"img":false,"tv":31863.18}]}
{"op":"mcm","clk":"1149398401","pt":1439922622133,"mc":[{"id":"1.120089104","rc":[{"atb":[[1.14,135.65]],"id":9612932}],"con":true,"img":false,"tv":31863.18}]}
{"op":"mcm","clk":"1149403469","pt":1439922678099,"mc":[{"id":"1.120089104","rc":[{"atl":[[9.2,0]],"id":9480385}],"con":true,"img":false,"tv":31863.18}]}
{"op":"mcm","clk":"1149403486","pt":1439922678167,"mc":[{"id":"1.120089104","rc":[{"atl":[[9,28]],"id":9480385}],"con":true,"img":false,"tv":31863.18}]}
{"op":"mcm","clk":"1149404560","pt":1439922691390,"mc":[{"id":"1.120089104","rc":[{"atl":[[1.18,376.97]],"id":9612932}],"con":true,"img":false,"tv":31863.18}]}
{"op":"mcm","clk":"1149404569","pt":1439922691496,"mc":[{"id":"1.120089104","rc":[{"trd":[[1.16,4487.77]],"ltp":1.16,"tv":4487.77,"id":9612932},{"atb":[[1.16,4095.75]],"id":9612932}],"con":true,"img":false,"tv":32727.9}]}
{"op":"mcm","clk":"1149406797","pt":1439922714906,"mc":[{"id":"1.120089104","rc":[{"atb":[[6.4,36.46]],"id":9480385}],"con":true,"img":false,"tv":32727.9}]}
{"op":"mcm","clk":"1149406822","pt":1439922715129,"mc":[{"id":"1.120089104","rc":[{"atb":[[6.4,6.65]],"id":9480385}],"con":true,"img":false,"tv":32727.9}]}
{"op":"mcm","clk":"1149407936","pt":1439922727874,"mc":[{"id":"1.120089104","rc":[{"atl":[[1000,9]],"id":9612932},{"atb":[[6.8,36.12],[1.01,2510.04]],"id":9480385}],"con":true,"img":false,"tv":32727.9}]}
{"op":"mcm","clk":"1149407951","pt":1439922727992,"mc":[{"id":"1.120089104","rc":[{"atl":[[1000,11.25]],"id":9612932},{"atb":[[1.01,2511.36]],"id":9480385}],"con":true,"img":false,"tv":32727.9}]}
{"op":"mcm","clk":"1149407954","pt":1439922728042,"mc":[{"id":"1.120089104","rc":[{"atl":[[1000,3.25]],"id":9612932},{"atb":[[1.01,2507.36]],"id":9480385}],"con":true,"img":false,"tv":32727.9}]}
{"op":"mcm","clk":"1149407963","pt":1439922728142,"mc":[{"id":"1.120089104","rc":[{"atl":[[1000,1]],"id":9612932},{"atb":[[1.01,2506.04]],"id":9480385}],"con":true,"img":false,"tv":32727.9}]}
{"op":"mcm","clk":"1149407973","pt":1439922728252,"mc":[{"id":"1.120089104","rc":[{"trd":[[1.16,4488.71]],"ltp":1.16,"tv":4488.71,"id":9612932},{"atb":[[1.16,4095.28]],"id":9612932},{"atl":[[1.17,3853.39]],"id":9612932},{"trd":[[7,10.6]],"ltp":7.0,"tv":10.6,"id":9480385},{"atl":[[7,12.07]],"id":9480385}],"con":true,"img":false,"tv":32731.48}]}
{"op":"mcm","clk":"1149410353","pt":1439922757123,"mc":[{"id":"1.120089104","rc":[{"trd":[[6.8,276.9]],"ltp":6.8,"tv":276.9,"id":9480385},{"atb":[[6.8,31.13]],"id":9480385}],"con":true,"img":false,"tv":32741.47}]}
{"op":"mcm","clk":"1149411138","pt":1439922767229,"mc":[{"id":"1.120089104","rc":[{"trd":[[1.17,4575.14]],"ltp":1.17,"tv":4575.14,"id":9612932},{"atl":[[1.17,3846.39]],"id":9612932}],"con":true,"img":false,"tv":32755.47}]}
{"op":"mcm","clk":"1149412164","pt":1439922778878,"mc":[{"id":"1.120089104","rc":[{"atl":[[7,0]],"id":9480385}],"con":true,"img":false,"tv":32755.47}]}
{"op":"mcm","clk":"1149412420","pt":1439922781900,"mc":[{"id":"1.120089104","rc":[{"atl":[[8,6]],"id":9480385}],"con":true,"img":false,"tv":32755.47}]}
{"op":"mcm","clk":"1149412989","pt":1439922787779,"mc":[{"id":"1.120089104","rc":[{"atl":[[8.8,39.35]],"id":9480385}],"con":true,"img":false,"tv":32755.47}]}
{"op":"mcm","clk":"1149413008","pt":1439922787991,"mc":[{"id":"1.120089104","rc":[{"atb":[[1.14,79.28]],"id":9612932}],"con":true,"img":false,"tv":32755.47}]}
{"op":"mcm","clk":"1149413089","pt":1439922788897,"mc":[{"id":"1.120089104","rc":[{"atl":[[7,21.42]],"id":9480385}],"con":true,"img":false,"tv":32755.47}]}
{"op":"mcm","clk":"1149413451","pt":1439922793230,"mc":[{"id":"1.120089104","rc":[{"atb":[[1.14,102.9]],"id":9612932},{"atl":[[8,15.82]],"id":9480385}],"con":true,"img":false,"tv":32755.47}]}
{"op":"mcm","clk":"1149413470","pt":1439922793400,"mc":[{"id":"1.120089104","rc":[{"atl":[[8.8,0]],"id":9480385}],"con":true,"img":false,"tv":32755.47}]}
{"op":"mcm","clk":"1149430458","pt":1439922872135,"mc":[{"id":"1.120089104","rc":[{"atl":[[7,0]],"id":9480385}],"con":true,"img":false,"tv":32755.47}]}
{"op":"mcm","clk":"1149431120","pt":1439922878841,"mc":[{"id":"1.120089104","rc":[{"atl":[[8,6]],"id":9480385}],"con":true,"img":false,"tv":32755.47}]}
{"op":"mcm","clk":"1149431577","pt":1439922884236,"mc":[{"id":"1.120089104","rc":[{"atl":[[8.8,44.19]],"id":9480385}],"con":true,"img":false,"tv":32755.47}]}
{"op":"mcm","clk":"1149435262","pt":1439922918939,"mc":[{"id":"1.120089104","rc":[{"atl":[[9,0]],"id":9480385}],"con":true,"img":false,"tv":32755.47}]}
{"op":"mcm","clk":"1149435280","pt":1439922919058,"mc":[{"id":"1.120089104","rc":[{"atl":[[9.2,27]],"id":9480385}],"con":true,"img":false,"tv":32755.47}]}
{"op":"mcm","clk":"1149435338","pt":1439922919656,"mc":[{"id":"1.120089104","rc":[{"atl":[[7,13.39]],"id":9480385}],"con":true,"img":false,"tv":32755.47}]}
{"op":"mcm","clk":"1149435666","pt":1439922923167,"mc":[{"id":"1.120089104","rc":[{"atl":[[8,12.08]],"id":9480385}],"con":true,"img":false,"tv":32755.47}]}
{"op":"mcm","clk":"1149435686","pt":1439922923385,"mc":[{"id":"1.120089104","rc":[{"atl":[[8.8,0]],"id":9480385}],"con":true,"img":false,"tv":32755.47}]}
{"op":"mcm","clk":"1149435728","pt":1439922923778,"mc":[{"id":"1.120089104","rc":[{"trd":[[1.17,4631.14]],"ltp":1.17,"tv":4631.14,"id":9612932},{"atl":[[1.17,3818.39]],"id":9612932}],"con":true,"img":false,"tv":32811.47}]}
{"op":"mcm","clk":"1149436600","pt":1439922931964,"mc":[{"id":"1.120089104","rc":[{"trd":[[1.16,4932.71]],"ltp":1.16,"tv":4932.71,"id":9612932},{"atb":[[1.16,3873.28]],"id":9612932}],"con":true,"img":false,"tv":33255.47}]}
{"op":"mcm","clk":"1149440673","pt":1439922968302,"mc":[{"id":"1.120089104","rc":[{"trd":[[1.17,4683.38]],"ltp":1.17,"tv":4683.38,"id":9612932},{"atl":[[1.17,3792.27]],"id":9612932}],"con":true,"img":false,"tv":33307.71}]}
{"op":"mcm","clk":"1149441169","pt":1439922973057,"mc":[{"id":"1.120089104","rc":[{"trd":[[1.17,4688.16]],"ltp":1.17,"tv":4688.16,"id":9612932},{"atl":[[1.17,3789.88]],"id":9612932}],"con":true,"img":false,"tv":33312.49}]}
{"op":"mcm","clk":"1149441808","pt":1439922979542,"mc":[{"id":"1.120089104","rc":[{"atl":[[9.2,0]],"id":9480385}],"con":true,"img":false,"tv":33312.49}]}
{"op":"mcm","clk":"1149441815","pt":1439922979654,"mc":[{"id":"1.120089104","rc":[{"atl":[[9,28]],"id":9480385}],"con":true,"img":false,"tv":33312.49}]}
{"op":"mcm","clk":"1149444396","pt":1439923005082,"mc":[{"id":"1.120089104","rc":[{"trd":[[1.16,4940.71]],"ltp":1.16,"tv":4940.71,"id":9612932},{"atb":[[1.16,3869.28]],"id":9612932}],"con":true,"img":false,"tv":33320.49}]}
{"op":"mcm","clk":"1149447646","pt":1439923033295,"mc":[{"id":"1.120089104","rc":[{"trd":[[7.2,31.84],[7,37.39]],"ltp":7.2,"tv":69.23,"id":9480385},{"atb":[[7.4,29.39]],"id":9480385},{"atl":[[7,0],[7.2,0]],"id":9480385}],"con":true,"img":false,"tv":33361.72}]}
{"op":"mcm","clk":"1149447676","pt":1439923033607,"mc":[{"id":"1.120089104","rc":[{"trd":[[7.4,58.78]],"ltp":7.4,"tv":58.78,"id":9480385},{"atb":[[7.4,0]],"id":9480385}],"con":true,"img":false,"tv":33420.5}]}
{"op":"mcm","clk":"1149447699","pt":1439923033686,"mc":[{"id":"1.120089104","rc":[{"trd":[[1.16,5018.29]],"ltp":1.16,"tv":5018.29,"id":9612932},{"atb":[[1.16,3830.49]],"id":9612932},{"atl":[[7.8,5.86],[7.4,6.08]],"id":9480385}],"con":true,"img":false,"tv":33498.08}]}
{"op":"mcm","clk":"1149447710","pt":1439923033790,"mc":[{"id":"1.120089104","rc":[{"trd":[[1.16,5393.27]],"ltp":1.16,"tv":5393.27,"id":9612932},{"atb":[[1.16,3643]],"id":9612932},{"atl":[[7.4,35.47]],"id":9480385}],"con":true,"img":false,"tv":33873.06}]}
{"op":"mcm","clk":"1149448426","pt":1439923040624,"mc":[{"id":"1.120089104","rc":[{"atl":[[8,6]],"id":9480385}],"con":true,"img":false,"tv":33873.06}]}
{"op":"mcm","clk":"1149448558","pt":1439923041958,"mc":[{"id":"1.120089104","rc":[{"atb":[[6.8,57.6],[6.2,21.97]],"id":9480385},{"atl":[[7.4,59.79]],"id":9480385}],"con":true,"img":false,"tv":33873.06}]}
{"op":"mcm","clk":"1149448960","pt":1439923045883,"mc":[{"id":"1.120089104","rc":[{"atl":[[8,40.31]],"id":9480385}],"con":true,"img":false,"tv":33873.06}]}
{"op":"mcm","clk":"1149452094","pt":1439923076153,"mc":[{"id":"1.120089104","rc":[{"atb":[[1.14,15102.9]],"id":9612932}],"con":true,"img":false,"tv":33873.06}]}
{"op":"mcm","clk":"1149452453","pt":1439923079484,"mc":[{"id":"1.120089104","rc":[{"atb":[[1.13,15159.33]],"id":9612932}],"con":true,"img":false,"tv":33873.06}]}
{"op":"mcm","clk":"1149452676","pt":1439923081229,"mc":[{"id":"1.120089104","rc":[{"trd":[[1.17,4708.16]],"ltp":1.17,"tv":4708.16,"id":9612932},{"atl":[[1.17,3779.88]],"id":9612932}],"con":true,"img":false,"tv":33893.06}]}
{"op":"mcm","clk":"1149453379","pt":1439923087280,"mc":[{"id":"1.120089104","rc":[{"spl":[[1.01,22]],"id":9480385}],"con":true,"img":false,"tv":33893.06}]}
{"op":"mcm","clk":"1149453542","pt":1439923089099,"mc":[{"id":"1.120089104","rc":[{"atb":[[1.12,16256.48]],"id":9612932}],"con":true,"img":false,"tv":33893.06}]}
{"op":"mcm","clk":"1149456063","pt":1439923115043,"mc":[{"id":"1.120089104","rc":[{"atl":[[7.2,20.62]],"id":9480385}],"con":true,"img":false,"tv":33893.06}]}
{"op":"mcm","clk":"1149456926","pt":1439923123706,"mc":[{"id":"1.120089104","rc":[{"atl":[[1.18,389.75]],"id":9612932}],"con":true,"img":false,"tv":33893.06}]}
{"op":"mcm","clk":"1149461027","pt":1439923160266,"mc":[{"id":"1.120089104","rc":[{"atl":[[9,0]],"id":9480385},{"spn":6.8,"spf":1.77,"id":9480385}],"con":true,"img":false,"tv":33893.06}]}
{"op":"mcm","clk":"1149461036","pt":1439923160328,"mc":[{"id":"1.120089104","rc":[{"atl":[[8.8,28]],"id":9480385}],"con":true,"img":false,"tv":33893.06}]}
{"op":"mcm","clk":"1149463873","pt":1439923185079,"mc":[{"id":"1.120089104","rc":[{"atl":[[7.4,53.71]],"id":9480385}],"con":true,"img":false,"tv":33893.06}]}
{"op":"mcm","clk":"1149463897","pt":1439923185294,"mc":[{"id":"1.120089104","rc":[{"trd":[[6.8,290.13]],"ltp":6.8,"tv":290.13,"id":9480385},{"atb":[[6.8,50.98]],"id":9480385}],"con":true,"img":false,"tv":33906.29}]}
{"op":"mcm","clk":"1149464530","pt":1439923191296,"mc":[{"id":"1.120089104","rc":[{"atl":[[7.2,0]],"id":9480385}],"con":true,"img":false,"tv":33906.29}]}
{"op":"mcm","clk":"1149467012","pt":1439923214796,"mc":[{"id":"1.120089104","rc":[{"trd":[[1.17,4718.16]],"ltp":1.17,"tv":4718.16,"id":9612932},{"atl":[[1.17,3774.88]],"id":9612932}],"con":true,"img":false,"tv":33916.29}]}
{"op":"mcm","clk":"1149467327","pt":1439923217388,"mc":[{"id":"1.120089104","rc":[{"atl":[[7.2,13.02]],"id":9480385}],"con":true,"img":false,"tv":33916.29}]}
{"op":"mcm","clk":"1149467732","pt":1439923220788,"mc":[{"id":"1.120089104","rc":[{"atl":[[8.8,0]],"id":9480385}],"con":true,"img":false,"tv":33916.29}]}
{"op":"mcm","clk":"1149467747","pt":1439923220896,"mc":[{"id":"1.120089104","rc":[{"atl":[[9,28]],"id":9480385}],"con":true,"img":false,"tv":33916.29}]}
{"op":"mcm","clk":"1149468979","pt":1439923232189,"mc":[{"id":"1.120089104","rc":[{"trd":[[1.16,5473.27]],"ltp":1.16,"tv":5473.27,"id":9612932},{"atb":[[1.16,3603]],"id":9612932}],"con":true,"img":false,"tv":33996.29}]}
{"op":"mcm","clk":"1149471681","pt":1439923258372,"mc":[{"id":"1.120089104","rc":[{"atb":[[1.14,15079.28]],"id":9612932},{"atl":[[1.21,0.82]],"id":9612932},{"atb":[[6.4,0]],"id":9480385},{"atl":[[8,6]],"id":9480385}],"con":true,"img":false,"tv":33996.29}]}
{"op":"mcm","clk":"1149471715","pt":1439923258696,"mc":[{"id":"1.120089104","rc":[{"atl":[[7.2,18.06]],"id":9480385}],"con":true,"img":false,"tv":33996.29}]}
{"op":"mcm","clk":"1149472102","pt":1439923262671,"mc":[{"id":"1.120089104","rc":[{"trd":[[1.17,5517.76]],"ltp":1.17,"tv":5517.76,"id":9612932},{"atl":[[1.17,3375.08]],"id":9612932}],"con":true,"img":false,"tv":34795.89}]}
{"op":"mcm","clk":"1149472181","pt":1439923263370,"mc":[{"id":"1.120089104","rc":[{"trd":[[1.17,5729.14]],"ltp":1.17,"tv":5729.14,"id":9612932},{"atl":[[1.17,3269.39]],"id":9612932}],"con":true,"img":false,"tv":35007.28}]}
{"op":"mcm","clk":"1149472541","pt":1439923266571,"mc":[{"id":"1.120089104","rc":[{"trd":[[1.17,5940.53]],"ltp":1.17,"tv":5940.53,"id":9612932},{"atl":[[1.17,3163.7]],"id":9612932}],"con":true,"img":false,"tv":35218.66}]}
{"op":"mcm","clk":"1149472932","pt":1439923269778,"mc":[{"id":"1.120089104","rc":[{"trd":[[1.17,6151.91]],"ltp":1.17,"tv":6151.91,"id":9612932},{"atl":[[1.17,3058.01]],"id":9612932}],"con":true,"img":false,"tv":35430.04}]}
{"op":"mcm","clk":"1149473110","pt":1439923271331,"mc":[{"id":"1.120089104","rc":[{"atl":[[1.21,57.23]],"id":9612932},{"atb":[[6.2,58.12]],"id":9480385},{"atl":[[7.8,26.85]],"id":9480385}],"con":true,"img":false,"tv":35430.04}]}
{"op":"mcm","clk":"1149473164","pt":1439923271817,"mc":[{"id":"1.120089104","rc":[{"atb":[[6.4,6]],"id":9480385}],"con":true,"img":false,"tv":35430.04}]}
{"op":"mcm","clk":"1149473790","pt":1439923276950,"mc":[{"id":"1.120089104","rc":[{"atl":[[7.8,33.64]],"id":9480385}],"con":true,"img":false,"tv":35430.04}]}
{"op":"mcm","clk":"1149473805","pt":1439923277165,"mc":[{"id":"1.120089104","rc":[{"atl":[[1.21,0.82]],"id":9612932},{"atl":[[7.8,12.65]],"id":9480385}],"con":true,"img":false,"tv":35430.04}]}
{"op":"mcm","clk":"1149474301","pt":1439923281242,"mc":[{"id":"1.120089104","rc":[{"atl":[[9,0]],"id":9480385}],"con":true,"img":false,"tv":35430.04}]}
{"op":"mcm","clk":"1149474311","pt":1439923281309,"mc":[{"id":"1.120089104","rc":[{"atl":[[8.8,28]],"id":9480385}],"con":true,"img":false,"tv":35430.04}]}
{"op":"mcm","clk":"1149474494","pt":1439923282923,"mc":[{"id":"1.120089104","rc":[{"atl":[[1.21,25.11]],"id":9612932}],"con":true,"img":false,"tv":35430.04}]}
{"op":"mcm","clk":"1149476116","pt":1439923296799,"mc":[{"id":"1.120089104","rc":[{"trd":[[1.16,5553.27]],"ltp":1.16,"tv":5553.27,"id":9612932},{"atb":[[1.16,3563]],"id":9612932}],"con":true,"img":false,"tv":35510.04}]}
{"op":"mcm","clk":"1149485582","pt":1439923381577,"mc":[{"id":"1.120089104","rc":[{"atl":[[7.2,5.03]],"id":9480385}],"con":true,"img":false,"tv":35510.04}]}
{"op":"mcm","clk":"1149486252","pt":1439923387153,"mc":[{"id":"1.120089104","rc":[{"atl":[[7,21.42]],"id":9480385}],"con":true,"img":false,"tv":35510.04}]}
{"op":"mcm","clk":"1149488113","pt":1439923401899,"mc":[{"id":"1.120089104","rc":[{"atl":[[8.8,0]],"id":9480385}],"con":true,"img":false,"tv":35510.04}]}
{"op":"mcm","clk":"1149488126","pt":1439923402013,"mc":[{"id":"1.120089104","rc":[{"atl":[[8.4,30]],"id":9480385}],"con":true,"img":false,"tv":35510.04}]}
{"op":"mcm","clk":"1149488625","pt":1439923406473,"mc":[{"id":"1.120089104","rc":[{"atb":[[1.16,3598.64],[1.14,15118.87],[1.12,16304.32],[1.1,88.94]],"id":9612932},{"atl":[[1.18,424.05],[1.22,577.54],[1.24,26.48],[1.2,331.39]],"id":9612932},{"atb":[[6.8,57.11],[5.8,8.13],[6,14.78],[6.4,12.07]],"id":9480385},{"atl":[[7.8,18.41],[8.2,255.65],[8.8,5.54],[7.2,10.86]],"id":9480385}],"con":true,"img":false,"tv":35510.04}]}
{"op":"mcm","clk":"1149488764","pt":1439923407609,"mc":[{"id":"1.120089104","rc":[{"atl":[[7.8,13.77]],"id":9480385}],"con":true,"img":false,"tv":35510.04}]}
{"op":"mcm","clk":"1149493013","pt":1439923447515,"mc":[{"id":"1.120089104","rc":[{"atl":[[1000,9]],"id":9612932},{"atb":[[6.8,62.04],[1.01,2510.04]],"id":9480385}],"con":true,"img":false,"tv":35510.04}]}
{"op":"mcm","clk":"1149493026","pt":1439923447625,"mc":[{"id":"1.120089104","rc":[{"atl":[[1000,11.25]],"id":9612932},{"atb":[[1.01,2511.36]],"id":9480385}],"con":true,"img":false,"tv":35510.04}]}
{"op":"mcm","clk":"1149493037","pt":1439923447736,"mc":[{"id":"1.120089104","rc":[{"atl":[[1000,3.25]],"id":9612932},{"atb":[[1.01,2507.36]],"id":9480385}],"con":true,"img":false,"tv":35510.04}]}
{"op":"mcm","clk":"1149493044","pt":1439923447839,"mc":[{"id":"1.120089104","rc":[{"atl":[[1000,1]],"id":9612932},{"atb":[[1.01,2506.04]],"id":9480385}],"con":true,"img":false,"tv":35510.04}]}
{"op":"mcm","clk":"1149493053","pt":1439923447948,"mc":[{"id":"1.120089104","rc":[{"trd":[[1.16,5554.21]],"ltp":1.16,"tv":5554.21,"id":9612932},{"atb":[[1.16,3598.17]],"id":9612932},{"atl":[[1.17,3059.79]],"id":9612932},{"trd":[[7,40.03]],"ltp":7.0,"tv":40.03,"id":9480385},{"atl":[[7,20.1]],"id":9480385}],"con":true,"img":false,"tv":35513.63}]}
{"op":"mcm","clk":"1149494660","pt":1439923462711,"mc":[{"id":"1.120089104","rc":[{"trd":[[1.16,5564.21]],"ltp":1.16,"tv":5564.21,"id":9612932},{"atb":[[1.16,3593.17]],"id":9612932}],"con":true,"img":false,"tv":35523.63}]}
{"op":"mcm","clk":"1149495177","pt":1439923467648,"mc":[{"id":"1.120089104","rc":[{"atb":[[1.16,3598.17]],"id":9612932}],"con":true,"img":false,"tv":35523.63}]}
{"op":"mcm","clk":"1149496459","pt":1439923479932,"mc":[{"id":"1.120089104","rc":[{"atl":[[7,0]],"id":9480385}],"con":true,"img":false,"tv":35523.63}]}
{"op":"mcm","clk":"1149497275","pt":1439923487806,"mc":[{"id":"1.120089104","rc":[{"atl":[[7.8,18.35]],"id":9480385}],"con":true,"img":false,"tv":35523.63}]}
{"op":"mcm","clk":"1149497297","pt":1439923488017,"mc":[{"id":"1.120089104","rc":[{"atl":[[7.8,11.56]],"id":9480385}],"con":true,"img":false,"tv":35523.63}]}
{"op":"mcm","clk":"1149498125","pt":1439923496416,"mc":[{"id":"1.120089104","rc":[{"trd":[[1.17,6162.27]],"ltp":1.17,"tv":6162.27,"id":9612932},{"atl":[[1.17,3054.61]],"id":9612932}],"con":true,"img":false,"tv":35533.99}]}
{"op":"mcm","clk":"1149498476","pt":1439923499978,"mc":[{"id":"1.120089104","rc":[{"atl":[[7.8,6.98]],"id":9480385}],"con":true,"img":false,"tv":35533.99}]}
{"op":"mcm","clk":"1149499178","pt":1439923505335,"mc":[{"id":"1.120089104","rc":[{"atl":[[8,41.89]],"id":9480385}],"con":true,"img":false,"tv":35533.99}]}
{"op":"mcm","clk":"1149499591","pt":1439923509372,"mc":[{"id":"1.120089104","rc":[{"atl":[[7,13.39]],"id":9480385}],"con":true,"img":false,"tv":35533.99}]}
{"op":"mcm","clk":"1149499681","pt":1439923510299,"mc":[{"id":"1.120089104","rc":[{"atl":[[7,18.5]],"id":9480385}],"con":true,"img":false,"tv":35533.99}]}
{"op":"mcm","clk":"1149500370","pt":1439923516533,"mc":[{"id":"1.120089104","rc":[{"atl":[[8,6]],"id":9480385}],"con":true,"img":false,"tv":35533.99}]}
{"op":"mcm","clk":"1149501147","pt":1439923522938,"mc":[{"id":"1.120089104","rc":[{"atl":[[7.8,9.91]],"id":9480385}],"con":true,"img":false,"tv":35533.99}]}
{"op":"mcm","clk":"1149519453","pt":1439923666882,"mc":[{"id":"1.120089104","rc":[{"atl":[[7,20.5]],"id":9480385}],"con":true,"img":false,"tv":35533.99}]}
{"op":"mcm","clk":"1149520023","pt":1439923670664,"mc":[{"id":"1.120089104","rc":[{"atl":[[7,25.5]],"id":9480385}],"con":true,"img":false,"tv":35533.99}]}
{"op":"mcm","clk":"1149520260","pt":1439923672042,"mc":[{"id":"1.120089104","rc":[{"atl":[[7,23.5]],"id":9480385}],"con":true,"img":false,"tv":35533.99}]}
{"op":"mcm","clk":"1149520330","pt":1439923672574,"mc":[{"id":"1.120089104","rc":[{"atl":[[7,10.1]],"id":9480385}],"con":true,"img":false,"tv":35533.99}]}
{"op":"mcm","clk":"1149520575","pt":1439923674080,"mc":[{"id":"1.120089104","rc":[{"atl":[[1.21,0.82]],"id":9612932}],"con":true,"img":false,"tv":35533.99}]}
{"op":"mcm","clk":"1149522981","pt":1439923690040,"mc":[{"id":"1.120089104","rc":[{"atl":[[7,12.1]],"id":9480385}],"con":true,"img":false,"tv":35533.99}]}
{"op":"mcm","clk":"1149524542","pt":1439923700347,"mc":[{"id":"1.120089104","rc":[{"atl":[[7,28.04]],"id":9480385}],"con":true,"img":false,"tv":35533.99}]}
{"op":"mcm","clk":"1149530964","pt":1439923742169,"mc":[{"id":"1.120089104","rc":[{"trd":[[1.17,6805.13]],"ltp":1.17,"tv":6805.13,"id":9612932},{"atl":[[1.17,2733.18]],"id":9612932}],"con":true,"img":false,"tv":36176.85}]}
{"op":"mcm","clk":"1149545861","pt":1439923779445,"mc":[{"id":"1.120089104","rc":[{"atl":[[1.18,47.07]],"id":9612932}],"con":true,"img":false,"tv":36176.85}]}
{"op":"mcm","clk":"1149546026","pt":1439923780486,"mc":[{"id":"1.120089104","rc":[{"trd":[[1.17,6908.71]],"ltp":1.17,"tv":6908.71,"id":9612932},{"atl":[[1.17,2681.39]],"id":9612932}],"con":true,"img":false,"tv":36280.43}]}
{"op":"mcm","clk":"1149547008","pt":1439923786532,"mc":[{"id":"1.120089104","rc":[{"atl":[[7,12.1]],"id":9480385}],"con":true,"img":false,"tv":36280.43}]}
{"op":"mcm","clk":"1149548842","pt":1439923797755,"mc":[{"id":"1.120089104","rc":[{"atl":[[7,7.1]],"id":9480385}],"con":true,"img":false,"tv":36280.43}]}
{"op":"mcm","clk":"1149549199","pt":1439923799981,"mc":[{"id":"1.120089104","rc":[{"trd":[[1.17,8068.71]],"ltp":1.17,"tv":8068.71,"id":9612932},{"atl":[[1.17,2101.39]],"id":9612932}],"con":true,"img":false,"tv":37440.43}]}
{"op":"mcm","clk":"1149551314","pt":1439923812765,"mc":[{"id":"1.120089104","rc":[{"atl":[[7,20.5]],"id":9480385}],"con":true,"img":false,"tv":37440.43}]}
{"op":"mcm","clk":"1149551860","pt":1439923815996,"mc":[{"id":"1.120089104","rc":[{"atl":[[7.8,14.91]],"id":9480385}],"con":true,"img":false,"tv":37440.43}]}
{"op":"mcm","clk":"1149553911","pt":1439923828099,"mc":[{"id":"1.120089104","rc":[{"trd":[[1.16,5690.69]],"ltp":1.16,"tv":5690.69,"id":9612932},{"atb":[[1.16,3534.93]],"id":9612932}],"con":true,"img":false,"tv":37566.91}]}
{"op":"mcm","clk":"1149554128","pt":1439923829396,"mc":[{"id":"1.120089104","rc":[{"trd":[[1.16,5695.09]],"ltp":1.16,"tv":5695.09,"id":9612932},{"atb":[[1.16,3532.73]],"id":9612932}],"con":true,"img":false,"tv":37571.31}]}
{"op":"mcm","clk":"1149564306","pt":1439923891443,"mc":[{"id":"1.120089104","rc":[{"trd":[[7,46.03]],"ltp":7.0,"tv":46.03,"id":9480385},{"atl":[[7,17.49]],"id":9480385}],"con":true,"img":false,"tv":37577.31}]}
{"op":"mcm","clk":"1149568366","pt":1439923919935,"mc":[{"id":"1.120089104","rc":[{"trd":[[1.17,8120.17]],"ltp":1.17,"tv":8120.17,"id":9612932},{"atl":[[1.17,2075.66]],"id":9612932}],"con":true,"img":false,"tv":37628.77}]}
{"op":"mcm","clk":"1149576154","pt":1439923976017,"mc":[{"id":"1.120089104","rc":[{"atl":[[7,4.1]],"id":9480385}],"con":true,"img":false,"tv":37628.77}]}
{"op":"mcm","clk":"1149577946","pt":1439923989255,"mc":[{"id":"1.120089104","rc":[{"atl":[[7.8,17.26]],"id":9480385}],"con":true,"img":false,"tv":37628.77}]}
{"op":"mcm","clk":"1149577992","pt":1439923989496,"mc":[{"id":"1.120089104","rc":[{"atl":[[7.8,14.32]],"id":9480385}],"con":true,"img":false,"tv":37628.77}]}
{"op":"mcm","clk":"1149578183","pt":1439923990692,"mc":[{"id":"1.120089104","rc":[{"atl":[[7,17.49]],"id":9480385}],"con":true,"img":false,"tv":37628.77}]}
{"op":"mcm","clk":"1149580677","pt":1439924008710,"mc":[{"id":"1.120089104","rc":[{"trd":[[1.17,8227.31]],"ltp":1.17,"tv":8227.31,"id":9612932},{"atl":[[1.17,2022.09]],"id":9612932}],"con":true,"img":false,"tv":37735.91}]}
{"op":"mcm","clk":"1149584461","pt":1439924036034,"mc":[{"id":"1.120089104","rc":[{"trd":[[1.17,8248.21]],"ltp":1.17,"tv":8248.21,"id":9612932},{"atl":[[1.17,2011.64]],"id":9612932}],"con":true,"img":false,"tv":37756.81}]}
{"op":"mcm","clk":"1149586497","pt":1439924049780,"mc":[{"id":"1.120089104","rc":[{"trd":[[1.17,8299.67]],"ltp":1.17,"tv":8299.67,"id":9612932},{"atl":[[1.17,1985.91]],"id":9612932}],"con":true,"img":false,"tv":37808.27}]}
{"op":"mcm","clk":"1149588820","pt":1439924066999,"mc":[{"id":"1.120089104","rc":[{"trd":[[7,50.03]],"ltp":7.0,"tv":50.03,"id":9480385},{"atl":[[7,15.49]],"id":9480385}],"con":true,"img":false,"tv":37812.27}]}
{"op":"mcm","clk":"1149589623","pt":1439924073375,"mc":[{"id":"1.120089104","rc":[{"atl":[[7,2.1]],"id":9480385}],"con":true,"img":false,"tv":37812.27}]}
{"op":"mcm","clk":"1149590376","pt":1439924079320,"mc":[{"id":"1.120089104","rc":[{"atl":[[7.8,11.98]],"id":9480385}],"con":true,"img":false,"tv":37812.27}]}
{"op":"mcm","clk":"1149591022","pt":1439924084446,"mc":[{"id":"1.120089104","rc":[{"atl":[[7.8,46]],"id":9480385}],"con":true,"img":false,"tv":37812.27}]}
{"op":"mcm","clk":"1149591905","pt":1439924091764,"mc":[{"id":"1.120089104","rc":[{"atl":[[7.8,53.48]],"id":9480385}],"con":true,"img":false,"tv":37812.27}]}
{"op":"mcm","clk":"1149591931","pt":1439924092089,"mc":[{"id":"1.120089104","rc":[{"atl":[[7.8,19.46]],"id":9480385}],"con":true,"img":false,"tv":37812.27}]}
{"op":"mcm","clk":"1149592475","pt":1439924096726,"mc":[{"id":"1.120089104","rc":[{"atl":[[7.8,11.98]],"id":9480385}],"con":true,"img":false,"tv":37812.27}]}
{"op":"mcm","clk":"1149593150","pt":1439924102632,"mc":[{"id":"1.120089104","rc":[{"atl":[[7.6,1.66]],"id":9480385}],"con":true,"img":false,"tv":37812.27}]}
{"op":"mcm","clk":"1149594834","pt":1439924116547,"mc":[{"id":"1.120089104","rc":[{"atl":[[7,12.15]],"id":9480385}],"con":true,"img":false,"tv":37812.27}]}
{"op":"mcm","clk":"1149595259","pt":1439924119843,"mc":[{"id":"1.120089104","rc":[{"atl":[[7.6,7.03]],"id":9480385}],"con":true,"img":false,"tv":37812.27}]}
{"op":"mcm","clk":"1149595288","pt":1439924120065,"mc":[{"id":"1.120089104","rc":[{"atl":[[7.6,5.36]],"id":9480385}],"con":true,"img":false,"tv":37812.27}]}
{"op":"mcm","clk":"1149597320","pt":1439924136840,"mc":[{"id":"1.120089104","rc":[{"trd":[[1.17,8915.75]],"ltp":1.17,"tv":8915.75,"id":9612932},{"atl":[[1.17,1677.87]],"id":9612932}],"con":true,"img":false,"tv":38428.35}]}
{"op":"mcm","clk":"1149600961","pt":1439924166478,"mc":[{"id":"1.120089104","rc":[{"atl":[[1.21,141.74]],"id":9612932}],"con":true,"img":false,"tv":38428.35}]}
{"op":"mcm","clk":"1149601042","pt":1439924167205,"mc":[{"id":"1.120089104","rc":[{"atl":[[1000,9]],"id":9612932},{"atb":[[6.8,66.97],[1.01,2510.04]],"id":9480385}],"con":true,"img":false,"tv":38428.35}]}
{"op":"mcm","clk":"1149601067","pt":1439924167433,"mc":[{"id":"1.120089104","rc":[{"atl":[[1000,11.25]],"id":9612932},{"atb":[[1.01,2511.36]],"id":9480385}],"con":true,"img":false,"tv":38428.35}]}
{"op":"mcm","clk":"1149601090","pt":1439924167599,"mc":[{"id":"1.120089104","rc":[{"atl":[[1000,3.25]],"id":9612932},{"atb":[[1.01,2507.36]],"id":9480385}],"con":true,"img":false,"tv":38428.35}]}
{"op":"mcm","clk":"1149601096","pt":1439924167757,"mc":[{"id":"1.120089104","rc":[{"atl":[[1000,1]],"id":9612932},{"atb":[[1.01,2506.04]],"id":9480385}],"con":true,"img":false,"tv":38428.35}]}
{"op":"mcm","clk":"1149601119","pt":1439924167834,"mc":[{"id":"1.120089104","rc":[{"trd":[[1.16,5696.03]],"ltp":1.16,"tv":5696.03,"id":9612932},{"atb":[[1.16,3532.26]],"id":9612932},{"atl":[[1.17,1679.65]],"id":9612932},{"trd":[[7,52.67]],"ltp":7.0,"tv":52.67,"id":9480385},{"atl":[[7,10.83]],"id":9480385}],"con":true,"img":false,"tv":38431.93}]}
{"op":"mcm","clk":"1149602448","pt":1439924178255,"mc":[{"id":"1.120089104","rc":[{"atl":[[1.18,1158.07]],"id":9612932}],"con":true,"img":false,"tv":38431.93}]}
{"op":"mcm","clk":"1149603321","pt":1439924184748,"mc":[{"id":"1.120089104","rc":[{"atl":[[1.22,1688.54]],"id":9612932}],"con":true,"img":false,"tv":38431.93}]}
{"op":"mcm","clk":"1149604017","pt":1439924190337,"mc":[{"id":"1.120089104","rc":[{"atb":[[1.16,5754.26]],"id":9612932}],"con":true,"img":false,"tv":38431.93}]}
{"op":"mcm","clk":"1149604897","pt":1439924196921,"mc":[{"id":"1.120089104","rc":[{"atl":[[1.19,1238.33]],"id":9612932}],"con":true,"img":false,"tv":38431.93}]}
{"op":"mcm","clk":"1149606016","pt":1439924206568,"mc":[{"id":"1.120089104","rc":[{"trd":[[1.17,8987.75]],"ltp":1.17,"tv":8987.75,"id":9612932},{"atl":[[1.17,1643.65]],"id":9612932}],"con":true,"img":false,"tv":38503.93}]}
{"op":"mcm","clk":"1149607286","pt":1439924215779,"mc":[{"id":"1.120089104","rc":[{"trd":[[1.16,6317.43]],"ltp":1.16,"tv":6317.43,"id":9612932},{"atb":[[1.16,5443.56]],"id":9612932}],"con":true,"img":false,"tv":39125.33}]}
{"op":"mcm","clk":"1149607593","pt":1439924217984,"mc":[{"id":"1.120089104","rc":[{"atb":[[6.8,177.97]],"id":9480385}],"con":true,"img":false,"tv":39125.33}]}
{"op":"mcm","clk":"1149611755","pt":1439924251526,"mc":[{"id":"1.120089104","rc":[{"trd":[[7,56.67]],"ltp":7.0,"tv":56.67,"id":9480385},{"atl":[[7,8.83]],"id":9480385}],"con":true,"img":false,"tv":39129.32}]}
{"op":"mcm","clk":"1149613257","pt":1439924262119,"mc":[{"id":"1.120089104","rc":[{"trd":[[1.17,9057.75]],"ltp":1.17,"tv":9057.75,"id":9612932},{"atl":[[1.17,1608.65]],"id":9612932}],"con":true,"img":false,"tv":39199.32}]}
{"op":"mcm","clk":"1149613603","pt":1439924264735,"mc":[{"id":"1.120089104","rc":[{"trd":[[6.8,294.13]],"ltp":6.8,"tv":294.13,"id":9480385},{"atb":[[6.8,175.97]],"id":9480385}],"con":true,"img":false,"tv":39203.32}]}
{"op":"mcm","clk":"1149613887","pt":1439924266859,"mc":[{"id":"1.120089104","rc":[{"atl":[[1.19,1358.33]],"id":9612932}],"con":true,"img":false,"tv":39203.32}]}
{"op":"mcm","clk":"1149614107","pt":1439924268496,"mc":[{"id":"1.120089104","rc":[{"atl":[[1.45,0]],"id":9612932}],"con":true,"img":false,"tv":39203.32}]}
{"op":"mcm","clk":"1149615425","pt":1439924278388,"mc":[{"id":"1.120089104","rc":[{"atl":[[7,0]],"id":9480385}],"con":true,"img":false,"tv":39203.32}]}
{"op":"mcm","clk":"1149615733","pt":1439924280150,"mc":[{"id":"1.120089104","rc":[{"trd":[[1.16,6328.63]],"ltp":1.16,"tv":6328.63,"id":9612932},{"atb":[[1.16,5437.96]],"id":9612932}],"con":true,"img":false,"tv":39214.52}]}
{"op":"mcm","clk":"1149615999","pt":1439924282025,"mc":[{"id":"1.120089104","rc":[{"atl":[[7.2,35.86]],"id":9480385}],"con":true,"img":false,"tv":39214.52}]}
{"op":"mcm","clk":"1149616082","pt":1439924282597,"mc":[{"id":"1.120089104","rc":[{"atl":[[7.6,8.7]],"id":9480385}],"con":true,"img":false,"tv":39214.52}]}
{"op":"mcm","clk":"1149616102","pt":1439924282821,"mc":[{"id":"1.120089104","rc":[{"atl":[[1.21,0.82]],"id":9612932},{"atl":[[7.6,3.33]],"id":9480385}],"con":true,"img":false,"tv":39214.52}]}
{"op":"mcm","clk":"1149616706","pt":1439924287823,"mc":[{"id":"1.120089104","rc":[{"atl":[[7.8,22.69]],"id":9480385}],"con":true,"img":false,"tv":39214.52}]}
{"op":"mcm","clk":"1149616734","pt":1439924288071,"mc":[{"id":"1.120089104","rc":[{"atl":[[7.6,0]],"id":9480385}],"con":true,"img":false,"tv":39214.52}]}
{"op":"mcm","clk":"1149617385","pt":1439924292734,"mc":[{"id":"1.120089104","rc":[{"atl":[[7.8,11.98]],"id":9480385}],"con":true,"img":false,"tv":39214.52}]}
{"op":"mcm","clk":"1149618045","pt":1439924297858,"mc":[{"id":"1.120089104","rc":[{"atl":[[7.8,22.69]],"id":9480385}],"con":true,"img":false,"tv":39214.52}]}
{"op":"mcm","clk":"1149618469","pt":1439924300810,"mc":[{"id":"1.120089104","rc":[{"trd":[[6.8,300.55]],"ltp":6.8,"tv":300.55,"id":9480385},{"atb":[[6.8,172.76]],"id":9480385}],"con":true,"img":false,"tv":39220.94}]}
{"op":"mcm","clk":"1149618737","pt":1439924302909,"mc":[{"id":"1.120089104","rc":[{"atl":[[7.8,11.98]],"id":9480385}],"con":true,"img":false,"tv":39220.94}]}
{"op":"mcm","clk":"1149619276","pt":1439924307378,"mc":[{"id":"1.120089104","rc":[{"atl":[[8.4,0]],"id":9480385}],"con":true,"img":false,"tv":39220.94}]}
{"op":"mcm","clk":"1149619298","pt":1439924307544,"mc":[{"id":"1.120089104","rc":[{"atl":[[8.8,33.54]],"id":9480385}],"con":true,"img":false,"tv":39220.94}]}
{"op":"mcm","clk":"1149619356","pt":1439924307965,"mc":[{"id":"1.120089104","rc":[{"atl":[[7,21.56]],"id":9480385}],"con":true,"img":false,"tv":39220.94}]}
{"op":"mcm","clk":"1149619458","pt":1439924308814,"mc":[{"id":"1.120089104","rc":[{"atl":[[7.8,22.69]],"id":9480385}],"con":true,"img":false,"tv":39220.94}]}
{"op":"mcm","clk":"1149625086","pt":1439924352870,"mc":[{"id":"1.120089104","rc":[{"trd":[[1.16,7536.65]],"ltp":1.16,"tv":7536.65,"id":9612932},{"atb":[[1.16,4833.95]],"id":9612932}],"con":true,"img":false,"tv":40428.96}]}
{"op":"mcm","clk":"1149626756","pt":1439924365785,"mc":[{"id":"1.120089104","rc":[{"trd":[[1.16,8536.65]],"ltp":1.16,"tv":8536.65,"id":9612932},{"atb":[[1.16,4333.95]],"id":9612932}],"con":true,"img":false,"tv":41428.96}]}
{"op":"mcm","clk":"1149627066","pt":1439924367918,"mc":[{"id":"1.120089104","rc":[{"atl":[[8.8,5.54]],"id":9480385}],"con":true,"img":false,"tv":41428.96}]}
{"op":"mcm","clk":"1149627081","pt":1439924367974,"mc":[{"id":"1.120089104","rc":[{"atl":[[8.4,30]],"id":9480385}],"con":true,"img":false,"tv":41428.96}]}
{"op":"mcm","clk":"1149629129","pt":1439924384541,"mc":[{"id":"1.120089104","rc":[{"atl":[[7,0]],"id":9480385}],"con":true,"img":false,"tv":41428.96}]}
{"op":"mcm","clk":"1149629360","pt":1439924386241,"mc":[{"id":"1.120089104","rc":[{"atl":[[1.17,1762.49]],"id":9612932}],"con":true,"img":false,"tv":41428.96}]}
{"op":"mcm","clk":"1149629726","pt":1439924389081,"mc":[{"id":"1.120089104","rc":[{"atl":[[1.17,1783.49]],"id":9612932}],"con":true,"img":false,"tv":41428.96}]}
{"op":"mcm","clk":"1149630306","pt":1439924393349,"mc":[{"id":"1.120089104","rc":[{"trd":[[1.16,9336.65]],"ltp":1.16,"tv":9336.65,"id":9612932},{"atb":[[1.16,3933.95]],"id":9612932}],"con":true,"img":false,"tv":42228.96}]}
{"op":"mcm","clk":"1149630498","pt":1439924395319,"mc":[{"id":"1.120089104","rc":[{"atl":[[7.8,11.98]],"id":9480385}],"con":true,"img":false,"tv":42228.96}]}
{"op":"mcm","clk":"1149631187","pt":1439924401335,"mc":[{"id":"1.120089104","rc":[{"atl":[[7.8,31.91]],"id":9480385}],"con":true,"img":false,"tv":42228.96}]}
{"op":"mcm","clk":"1149632164","pt":1439924409136,"mc":[{"id":"1.120089104","rc":[{"atl":[[7,13.39]],"id":9480385}],"con":true,"img":false,"tv":42228.96}]}
{"op":"mcm","clk":"1149633589","pt":1439924420123,"mc":[{"id":"1.120089104","rc":[{"atl":[[7.8,39.54]],"id":9480385}],"con":true,"img":false,"tv":42228.96}]}
{"op":"mcm","clk":"1149633906","pt":1439924422413,"mc":[{"id":"1.120089104","rc":[{"trd":[[7,66.67]],"ltp":7.0,"tv":66.67,"id":9480385},{"atl":[[7,8.39]],"id":9480385}],"con":true,"img":false,"tv":42238.96}]}
{"op":"mcm","clk":"1149634078","pt":1439924423687,"mc":[{"id":"1.120089104","rc":[{"atl":[[7.8,19.61]],"id":9480385}],"con":true,"img":false,"tv":42238.96}]}
{"op":"mcm","clk":"1149634351","pt":1439924425887,"mc":[{"id":"1.120089104","rc":[{"atl":[[7.8,11.98]],"id":9480385}],"con":true,"img":false,"tv":42238.96}]}
{"op":"mcm","clk":"1149635022","pt":1439924431388,"mc":[{"id":"1.120089104","rc":[{"atl":[[7.6,1.72]],"id":9480385}],"con":true,"img":false,"tv":42238.96}]}
{"op":"mcm","clk":"1149641660","pt":1439924483540,"mc":[{"id":"1.120089104","rc":[{"trd":[[1.16,9358.91]],"ltp":1.16,"tv":9358.91,"id":9612932},{"atb":[[1.16,3922.82]],"id":9612932}],"con":true,"img":false,"tv":42261.22}]}
{"op":"mcm","clk":"1149646464","pt":1439924523594,"mc":[{"id":"1.120089104","rc":[{"trd":[[1.16,9378.91]],"ltp":1.16,"tv":9378.91,"id":9612932},{"atb":[[1.16,3912.82]],"id":9612932}],"con":true,"img":false,"tv":42281.22}]}
{"op":"mcm","clk":"1149646715","pt":1439924525597,"mc":[{"id":"1.120089104","rc":[{"trd":[[1.17,9700.61]],"ltp":1.17,"tv":9700.61,"id":9612932},{"atl":[[1.17,1462.06]],"id":9612932}],"con":true,"img":false,"tv":42924.08}]}
{"op":"mcm","clk":"1149647913","pt":1439924535061,"mc":[{"id":"1.120089104","rc":[{"atl":[[7.6,7.43]],"id":9480385}],"con":true,"img":false,"tv":42924.08}]}
{"op":"mcm","clk":"1149647940","pt":1439924535259,"mc":[{"id":"1.120089104","rc":[{"atl":[[7.6,5.7]],"id":9480385}],"con":true,"img":false,"tv":42924.08}]}
{"op":"mcm","clk":"1149649159","pt":1439924545843,"mc":[{"id":"1.120089104","rc":[{"trd":[[1.16,10365.39]],"ltp":1.16,"tv":10365.39,"id":9612932},{"atb":[[1.16,3419.58]],"id":9612932}],"con":true,"img":false,"tv":43910.56}]}
{"op":"mcm","clk":"1149649506","pt":1439924548516,"mc":[{"id":"1.120089104","rc":[{"atb":[[1.11,36570.42]],"id":9612932}],"con":true,"img":false,"tv":43910.56}]}
{"op":"mcm","clk":"1149649612","pt":1439924549342,"mc":[{"id":"1.120089104","rc":[{"atl":[[1.19,678.37]],"id":9612932}],"con":true,"img":false,"tv":43910.56}]}
{"op":"mcm","clk":"1149649626","pt":1439924549477,"mc":[{"id":"1.120089104","rc":[{"atl":[[1.17,2142.02]],"id":9612932}],"con":true,"img":false,"tv":43910.56}]}
{"op":"mcm","clk":"1149649718","pt":1439924550275,"mc":[{"id":"1.120089104","rc":[{"atl":[[7.2,10.86]],"id":9480385}],"con":true,"img":false,"tv":43910.56}]}
{"op":"mcm","clk":"1149649979","pt":1439924552391,"mc":[{"id":"1.120089104","rc":[{"atb":[[1.1,20088.94]],"id":9612932}],"con":true,"img":false,"tv":43910.56}]}
{"op":"mcm","clk":"1149652663","pt":1439924573213,"mc":[{"id":"1.120089104","rc":[{"trd":[[1.16,11791.53]],"ltp":1.16,"tv":11791.53,"id":9612932},{"atb":[[1.16,2706.51]],"id":9612932}],"con":true,"img":false,"tv":45336.7}]}
{"op":"mcm","clk":"1149653826","pt":1439924581830,"mc":[{"id":"1.120089104","rc":[{"atl":[[7,0]],"id":9480385}],"con":true,"img":false,"tv":45336.7}]}
{"op":"mcm","clk":"1149654525","pt":1439924587389,"mc":[{"id":"1.120089104","rc":[{"atl":[[7.8,15.04]],"id":9480385}],"con":true,"img":false,"tv":45336.7}]}
{"op":"mcm","clk":"1149654590","pt":1439924588194,"mc":[{"id":"1.120089104","rc":[{"atl":[[7.6,0]],"id":9480385}],"con":true,"img":false,"tv":45336.7}]}
{"op":"mcm","clk":"1149655321","pt":1439924593525,"mc":[{"id":"1.120089104","rc":[{"atl":[[7,21.42]],"id":9480385}],"con":true,"img":false,"tv":45336.7}]}
{"op":"mcm","clk":"1149662224","pt":1439924643430,"mc":[{"id":"1.120089104","rc":[{"trd":[[1.17,9780.61]],"ltp":1.17,"tv":9780.61,"id":9612932},{"atl":[[1.17,2102.02]],"id":9612932}],"con":true,"img":false,"tv":45416.7}]}
{"op":"mcm","clk":"1149674654","pt":1439924665341,"mc":[{"id":"1.120089104","rc":[{"atl":[[1.2,31.39]],"id":9612932}],"con":true,"img":false,"tv":45416.7}]}
{"op":"mcm","clk":"1149674678","pt":1439924665430,"mc":[{"id":"1.120089104","rc":[{"atl":[[1.19,978.37]],"id":9612932}],"con":true,"img":false,"tv":45416.7}]}
{"op":"mcm","clk":"1149676263","pt":1439924675873,"mc":[{"id":"1.120089104","rc":[{"atl":[[7,0]],"id":9480385}],"con":true,"img":false,"tv":45416.7}]}
{"op":"mcm","clk":"1149677141","pt":1439924682035,"mc":[{"id":"1.120089104","rc":[{"atl":[[1.19,678.37]],"id":9612932}],"con":true,"img":false,"tv":45416.7}]}
{"op":"mcm","clk":"1149677156","pt":1439924682117,"mc":[{"id":"1.120089104","rc":[{"atl":[[1.18,1458.07]],"id":9612932}],"con":true,"img":false,"tv":45416.7}]}
{"op":"mcm","clk":"1149679566","pt":1439924697483,"mc":[{"id":"1.120089104","rc":[{"trd":[[1.17,9980.61]],"ltp":1.17,"tv":9980.61,"id":9612932},{"atl":[[1.17,2002.02]],"id":9612932}],"con":true,"img":false,"tv":45616.7}]}
{"op":"mcm","clk":"1149680406","pt":1439924702543,"mc":[{"id":"1.120089104","rc":[{"trd":[[1.17,10024.61]],"ltp":1.17,"tv":10024.61,"id":9612932},{"atl":[[1.17,1980.02]],"id":9612932}],"con":true,"img":false,"tv":45660.7}]}
{"op":"mcm","clk":"1149681202","pt":1439924708265,"mc":[{"id":"1.120089104","rc":[{"atl":[[7,13.39]],"id":9480385}],"con":true,"img":false,"tv":45660.7}]}
{"op":"mcm","clk":"1149681845","pt":1439924712507,"mc":[{"id":"1.120089104","rc":[{"atl":[[7.8,11.98]],"id":9480385}],"con":true,"img":false,"tv":45660.7}]}
{"op":"mcm","clk":"1149682142","pt":1439924714751,"mc":[{"id":"1.120089104","rc":[{"trd":[[1.17,10088.89]],"ltp":1.17,"tv":10088.89,"id":9612932},{"atl":[[1.17,1947.88]],"id":9612932}],"con":true,"img":false,"tv":45724.98}]}
{"op":"mcm","clk":"1149682587","pt":1439924717862,"mc":[{"id":"1.120089104","rc":[{"atl":[[7.8,15.85]],"id":9480385}],"con":true,"img":false,"tv":45724.98}]}
{"op":"mcm","clk":"1149684443","pt":1439924731686,"mc":[{"id":"1.120089104","rc":[{"trd":[[1.17,10129.27]],"ltp":1.17,"tv":10129.27,"id":9612932},{"atl":[[1.17,1927.69]],"id":9612932}],"con":true,"img":false,"tv":45765.36}]}
{"op":"mcm","clk":"1149688516","pt":1439924764289,"mc":[{"id":"1.120089104","rc":[{"trd":[[1.17,10151.23]],"ltp":1.17,"tv":10151.23,"id":9612932},{"atl":[[1.17,1916.71]],"id":9612932}],"con":true,"img":false,"tv":45787.32}]}
{"op":"mcm","clk":"1149694671","pt":1439924808693,"mc":[{"id":"1.120089104","rc":[{"trd":[[1.17,10361.23]],"ltp":1.17,"tv":10361.23,"id":9612932},{"atl":[[1.17,1811.71]],"id":9612932}],"con":true,"img":false,"tv":45997.32}]}
{"op":"mcm","clk":"1149697019","pt":1439924826233,"mc":[{"id":"1.120089104","rc":[{"trd":[[1.17,10424.23]],"ltp":1.17,"tv":10424.23,"id":9612932},{"atl":[[1.17,1780.21]],"id":9612932}],"con":true,"img":false,"tv":46060.32}]}
{"op":"mcm","clk":"1149697655","pt":1439924830716,"mc":[{"id":"1.120089104","rc":[{"trd":[[7,76.67]],"ltp":7.0,"tv":76.67,"id":9480385},{"atl":[[7,8.39]],"id":9480385}],"con":true,"img":false,"tv":46070.32}]}
{"op":"mcm","clk":"1149698266","pt":1439924835818,"mc":[{"id":"1.120089104","rc":[{"atb":[[1.01,2530.04]],"id":9612932}],"con":true,"img":false,"tv":46070.32}]}
{"op":"mcm","clk":"1149698281","pt":1439924835930,"mc":[{"id":"1.120089104","rc":[{"atb":[[1.01,2528.77]],"id":9612932}],"con":true,"img":false,"tv":46070.32}]}
{"op":"mcm","clk":"1149698289","pt":1439924836031,"mc":[{"id":"1.120089104","rc":[{"atb":[[1.01,2528.04]],"id":9612932}],"con":true,"img":false,"tv":46070.32}]}
{"op":"mcm","clk":"1149698309","pt":1439924836178,"mc":[{"id":"1.120089104","rc":[{"trd":[[1.17,10425.69]],"ltp":1.17,"tv":10425.69,"id":9612932},{"atl":[[1.17,1779.48]],"id":9612932}],"con":true,"img":false,"tv":46071.78}]}
{"op":"mcm","clk":"1149698316","pt":1439924836257,"mc":[{"id":"1.120089104","rc":[{"trd":[[1.17,10526.04]],"ltp":1.17,"tv":10526.04,"id":9612932},{"atl":[[1.17,1729.3]],"id":9612932}],"con":true,"img":false,"tv":46172.14}]}
{"op":"mcm","clk":"1149699926","pt":1439924848855,"mc":[{"id":"1.120089104","rc":[{"trd":[[6.8,304.55]],"ltp":6.8,"tv":304.55,"id":9480385},{"atb":[[6.8,170.76]],"id":9480385}],"con":true,"img":false,"tv":46176.14}]}
{"op":"mcm","clk":"1149704244","pt":1439924881534,"mc":[{"id":"1.120089104","rc":[{"atl":[[7,0]],"id":9480385}],"con":true,"img":false,"tv":46176.14}]}
{"op":"mcm","clk":"1149705411","pt":1439924889951,"mc":[{"id":"1.120089104","rc":[{"atl":[[7,21.56]],"id":9480385}],"con":true,"img":false,"tv":46176.14}]}
{"op":"mcm","clk":"1149705827","pt":1439924892922,"mc":[{"id":"1.120089104","rc":[{"trd":[[1.17,10546.04]],"ltp":1.17,"tv":10546.04,"id":9612932},{"atl":[[1.17,1719.3]],"id":9612932}],"con":true,"img":false,"tv":46196.14}]}
{"op":"mcm","clk":"1149706087","pt":1439924894491,"mc":[{"id":"1.120089104","rc":[{"atl":[[1000,9]],"id":9612932},{"atb":[[6.8,175.69],[1.01,2510.04]],"id":9480385}],"con":true,"img":false,"tv":46196.14}]}
{"op":"mcm","clk":"1149706114","pt":1439924894706,"mc":[{"id":"1.120089104","rc":[{"atl":[[1000,11.25]],"id":9612932},{"atb":[[1.01,2511.36]],"id":9480385}],"con":true,"img":false,"tv":46196.14}]}
{"op":"mcm","clk":"1149706143","pt":1439924894819,"mc":[{"id":"1.120089104","rc":[{"atl":[[1000,3.25]],"id":9612932},{"atb":[[1.01,2507.36]],"id":9480385}],"con":true,"img":false,"tv":46196.14}]}
{"op":"mcm","clk":"1149706149","pt":1439924894925,"mc":[{"id":"1.120089104","rc":[{"atl":[[1000,1]],"id":9612932},{"atb":[[1.01,2506.04]],"id":9480385}],"con":true,"img":false,"tv":46196.14}]}
{"op":"mcm","clk":"1149706163","pt":1439924895034,"mc":[{"id":"1.120089104","rc":[{"trd":[[1.16,11792.47]],"ltp":1.16,"tv":11792.47,"id":9612932},{"atb":[[1.16,2706.04]],"id":9612932},{"atl":[[1.17,1721.08]],"id":9612932},{"trd":[[7,79.31]],"ltp":7.0,"tv":79.31,"id":9480385},{"atl":[[7,20.24]],"id":9480385}],"con":true,"img":false,"tv":46199.72}]}
{"op":"mcm","clk":"1149707383","pt":1439924904377,"mc":[{"id":"1.120089104","rc":[{"trd":[[1.17,10647.82]],"ltp":1.17,"tv":10647.82,"id":9612932},{"atl":[[1.17,1670.19]],"id":9612932}],"con":true,"img":false,"tv":46301.5}]}
{"op":"mcm","clk":"1149708765","pt":1439924915007,"mc":[{"id":"1.120089104","rc":[{"atl":[[1.17,1947.19]],"id":9612932}],"con":true,"img":false,"tv":46301.5}]}
{"op":"mcm","clk":"1149711421","pt":1439924933876,"mc":[{"id":"1.120089104","rc":[{"spl":[[1.01,24]],"id":9480385}],"con":true,"img":false,"tv":46301.5}]}
{"op":"mcm","clk":"1149714425","pt":1439924958040,"mc":[{"id":"1.120089104","rc":[{"trd":[[6.8,309.51]],"ltp":6.8,"tv":309.51,"id":9480385},{"atb":[[6.8,173.21]],"id":9480385},{"spn":6.8,"spf":1.7,"id":9480385}],"con":true,"img":false,"tv":46306.46}]}
{"op":"mcm","clk":"1149714985","pt":1439924962492,"mc":[{"id":"1.120089104","rc":[{"trd":[[1.17,10700.06]],"ltp":1.17,"tv":10700.06,"id":9612932},{"atl":[[1.17,1921.07]],"id":9612932}],"con":true,"img":false,"tv":46358.7}]}
{"op":"mcm","clk":"1149715213","pt":1439924964321,"mc":[{"id":"1.120089104","rc":[{"trd":[[1.17,10740.18]],"ltp":1.17,"tv":10740.18,"id":9612932},{"atl":[[1.17,1901.01]],"id":9612932}],"con":true,"img":false,"tv":46398.82}]}
{"op":"mcm","clk":"1149717582","pt":1439924984159,"mc":[{"id":"1.120089104","rc":[{"atl":[[7,0]],"id":9480385}],"con":true,"img":false,"tv":46398.82}]}
{"op":"mcm","clk":"1149720988","pt":1439925009426,"mc":[{"id":"1.120089104","rc":[{"atl":[[7,13.39]],"id":9480385}],"con":true,"img":false,"tv":46398.82}]}
{"op":"mcm","clk":"1149724252","pt":1439925034362,"mc":[{"id":"1.120089104","rc":[{"trd":[[1.16,11883.17]],"ltp":1.16,"tv":11883.17,"id":9612932},{"atb":[[1.16,2660.69]],"id":9612932}],"con":true,"img":false,"tv":46489.52}]}
{"op":"mcm","clk":"1149743058","pt":1439925171200,"mc":[{"id":"1.120089104","rc":[{"atl":[[7,0]],"id":9480385}],"con":true,"img":false,"tv":46489.52}]}
{"op":"mcm","clk":"1149745362","pt":1439925186811,"mc":[{"id":"1.120089104","rc":[{"atl":[[7,13.39]],"id":9480385}],"con":true,"img":false,"tv":46489.52}]}
{"op":"mcm","clk":"1149745658","pt":1439925188741,"mc":[{"id":"1.120089104","rc":[{"trd":[[1.16,11893.17]],"ltp":1.16,"tv":11893.17,"id":9612932},{"atb":[[1.16,2655.69]],"id":9612932}],"con":true,"img":false,"tv":46499.52}]}
{"op":"mcm","clk":"1149749080","pt":1439925210432,"mc":[{"id":"1.120089104","rc":[{"trd":[[1.16,12007.57]],"ltp":1.16,"tv":12007.57,"id":9612932},{"atb":[[1.16,2598.49]],"id":9612932}],"con":true,"img":false,"tv":46613.92}]}
{"op":"mcm","clk":"1149753404","pt":1439925239584,"mc":[{"id":"1.120089104","rc":[{"atl":[[1.2,56.41]],"id":9612932}],"con":true,"img":false,"tv":46613.92}]}
{"op":"mcm","clk":"1149754684","pt":1439925248075,"mc":[{"id":"1.120089104","rc":[{"trd":[[6.8,315.51]],"ltp":6.8,"tv":315.51,"id":9480385},{"atb":[[6.8,170.21]],"id":9480385}],"con":true,"img":false,"tv":46619.92}]}
{"op":"mcm","clk":"1149755191","pt":1439925251434,"mc":[{"id":"1.120089104","rc":[{"trd":[[1.17,10752.18]],"ltp":1.17,"tv":10752.18,"id":9612932},{"atl":[[1.17,1895.01]],"id":9612932}],"con":true,"img":false,"tv":46631.92}]}
{"op":"mcm","clk":"1149759287","pt":1439925278423,"mc":[{"id":"1.120089104","rc":[{"atl":[[7,0]],"id":9480385}],"con":true,"img":false,"tv":46631.92}]}
{"op":"mcm","clk":"1149767301","pt":1439925330652,"mc":[{"id":"1.120089104","rc":[{"atl":[[8.4,0]],"id":9480385}],"con":true,"img":false,"tv":46631.92}]}
{"op":"mcm","clk":"1149767311","pt":1439925330808,"mc":[{"id":"1.120089104","rc":[{"atl":[[8.8,33.54]],"id":9480385}],"con":true,"img":false,"tv":46631.92}]}
{"op":"mcm","clk":"1149780762","pt":1439925416839,"mc":[{"id":"1.120089104","rc":[{"atl":[[1.19,367.88]],"id":9612932}],"con":true,"img":false,"tv":46631.92}]}
{"op":"mcm","clk":"1149780775","pt":1439925416922,"mc":[{"id":"1.120089104","rc":[{"trd":[[1.16,12628.54]],"ltp":1.16,"tv":12628.54,"id":9612932},{"atb":[[1.16,2288]],"id":9612932}],"con":true,"img":false,"tv":47252.89}]}
{"op":"mcm","clk":"1149783029","pt":1439925430944,"mc":[{"id":"1.120089104","rc":[{"trd":[[1.16,12848.55]],"ltp":1.16,"tv":12848.55,"id":9612932},{"atb":[[1.16,2178]],"id":9612932}],"con":true,"img":false,"tv":47472.9}]}
{"op":"mcm","clk":"1149783063","pt":1439925431173,"mc":[{"id":"1.120089104","rc":[{"atb":[[1.16,2215.54]],"id":9612932}],"con":true,"img":false,"tv":47472.9}]}
{"op":"mcm","clk":"1149783401","pt":1439925433432,"mc":[{"id":"1.120089104","rc":[{"trd":[[7.2,37.14]],"ltp":7.2,"tv":37.14,"id":9480385},{"atl":[[7.2,8.21]],"id":9480385}],"con":true,"img":false,"tv":47478.2}]}
{"op":"mcm","clk":"1149783830","pt":1439925436177,"mc":[{"id":"1.120089104","rc":[{"atb":[[1.14,15151.9]],"id":9612932}],"con":true,"img":false,"tv":47478.2}]}
{"op":"mcm","clk":"1149786636","pt":1439925455605,"mc":[{"id":"1.120089104","rc":[{"atb":[[1.14,15118.87]],"id":9612932}],"con":true,"img":false,"tv":47478.2}]}
{"op":"mcm","clk":"1149788891","pt":1439925471846,"mc":[{"id":"1.120089104","rc":[{"trd":[[1.17,10816.46]],"ltp":1.17,"tv":10816.46,"id":9612932},{"atl":[[1.17,1862.87]],"id":9612932}],"con":true,"img":false,"tv":47542.48}]}
{"op":"mcm","clk":"1149788955","pt":1439925472120,"mc":[{"id":"1.120089104","rc":[{"atl":[[7,6]],"id":9480385}],"con":true,"img":false,"tv":47542.48}]}
{"op":"mcm","clk":"1149789359","pt":1439925475006,"mc":[{"id":"1.120089104","rc":[{"atb":[[1.16,2233.77]],"id":9612932}],"con":true,"img":false,"tv":47542.48}]}
{"op":"mcm","clk":"1149789364","pt":1439925475090,"mc":[{"id":"1.120089104","rc":[{"trd":[[7,85.35]],"ltp":7.0,"tv":85.35,"id":9480385},{"atl":[[7,2.98]],"id":9480385}],"con":true,"img":false,"tv":47548.52}]}
{"op":"mcm","clk":"1149792748","pt":1439925497471,"mc":[{"id":"1.120089104","rc":[{"atl":[[7,18.91]],"id":9480385}],"con":true,"img":false,"tv":47548.52}]}
{"op":"mcm","clk":"1149793768","pt":1439925504516,"mc":[{"id":"1.120089104","rc":[{"trd":[[1.17,10936.46]],"ltp":1.17,"tv":10936.46,"id":9612932},{"atl":[[1.17,1802.87]],"id":9612932}],"con":true,"img":false,"tv":47668.52}]}
{"op":"mcm","clk":"1149794927","pt":1439925512527,"mc":[{"id":"1.120089104","rc":[{"atl":[[8.8,5.54]],"id":9480385}],"con":true,"img":false,"tv":47668.52}]}
{"op":"mcm","clk":"1149794949","pt":1439925512608,"mc":[{"id":"1.120089104","rc":[{"atl":[[8.4,30]],"id":9480385}],"con":true,"img":false,"tv":47668.52}]}
{"op":"mcm","clk":"1149795793","pt":1439925518018,"mc":[{"id":"1.120089104","rc":[{"atl":[[1.17,1806.87]],"id":9612932}],"con":true,"img":false,"tv":47668.52}]}
{"op":"mcm","clk":"1149796324","pt":1439925521613,"mc":[{"id":"1.120089104","rc":[{"trd":[[7,91.39]],"ltp":7.0,"tv":91.39,"id":9480385},{"atl":[[7,15.89]],"id":9480385}],"con":true,"img":false,"tv":47674.56}]}
{"op":"mcm","clk":"1149796358","pt":1439925521785,"mc":[{"id":"1.120089104","rc":[{"atb":[[1.16,2251.99]],"id":9612932}],"con":true,"img":false,"tv":47674.56}]}
{"op":"mcm","clk":"1149799506","pt":1439925543139,"mc":[{"id":"1.120089104","rc":[{"trd":[[1.16,16848.55]],"ltp":1.16,"tv":16848.55,"id":9612932},{"atb":[[1.16,251.99]],"id":9612932}],"con":true,"img":false,"tv":51674.56}]}
{"op":"mcm","clk":"1149799765","pt":1439925544744,"mc":[{"id":"1.120089104","rc":[{"atb":[[6.4,123.07]],"id":9480385}],"con":true,"img":false,"tv":51674.56}]}
{"op":"mcm","clk":"1149800272","pt":1439925547975,"mc":[{"id":"1.120089104","rc":[{"trd":[[1.16,16980.55]],"ltp":1.16,"tv":16980.55,"id":9612932},{"atb":[[1.16,185.99]],"id":9612932}],"con":true,"img":false,"tv":51806.56}]}
{"op":"mcm","clk":"1149801286","pt":1439925554656,"mc":[{"id":"1.120089104","rc":[{"trd":[[1.17,11136.46]],"ltp":1.17,"tv":11136.46,"id":9612932},{"atl":[[1.17,1706.87]],"id":9612932}],"con":true,"img":false,"tv":52006.56}]}
{"op":"mcm","clk":"1149801838","pt":1439925558463,"mc":[{"id":"1.120089104","rc":[{"atl":[[1.2,31.39]],"id":9612932},{"spn":1.15,"spf":1.07,"id":9612932}],"con":true,"img":false,"tv":52006.56}]}
{"op":"mcm","clk":"1149802102","pt":1439925559970,"mc":[{"id":"1.120089104","rc":[{"trd":[[1.16,17068.55]],"ltp":1.16,"tv":17068.55,"id":9612932},{"atb":[[1.16,141.99]],"id":9612932}],"con":true,"img":false,"tv":52094.56}]}
{"op":"mcm","clk":"1149802128","pt":1439925560138,"mc":[{"id":"1.120089104","rc":[{"atl":[[7.4,29.39]],"id":9480385}],"con":true,"img":false,"tv":52094.56}]}
{"op":"mcm","clk":"1149802302","pt":1439925561161,"mc":[{"id":"1.120089104","rc":[{"atl":[[7.2,2.38]],"id":9480385}],"con":true,"img":false,"tv":52094.56}]}
{"op":"mcm","clk":"1149802469","pt":1439925562182,"mc":[{"id":"1.120089104","rc":[{"atl":[[7.4,35.49]],"id":9480385}],"con":true,"img":false,"tv":52094.56}]}
{"op":"mcm","clk":"1149802695","pt":1439925563542,"mc":[{"id":"1.120089104","rc":[{"trd":[[7,121.39]],"ltp":7.0,"tv":121.39,"id":9480385},{"atl":[[7,0.89]],"id":9480385}],"con":true,"img":false,"tv":52124.56}]}
{"op":"mcm","clk":"1149812098","pt":1439925565550,"mc":[{"id":"1.120089104","rc":[{"trd":[[6.8,323.51]],"ltp":6.8,"tv":323.51,"id":9480385},{"atb":[[6.8,166.21]],"id":9480385}],"con":true,"img":false,"tv":52132.56}]}
{"op":"mcm","clk":"1149813530","pt":1439925574751,"mc":[{"id":"1.120089104","rc":[{"trd":[[1.16,17101.68]],"ltp":1.16,"tv":17101.68,"id":9612932},{"atb":[[1.16,125.42]],"id":9612932}],"con":true,"img":false,"tv":52165.7}]}
{"op":"mcm","clk":"1149814900","pt":1439925582998,"mc":[{"id":"1.120089104","rc":[{"atl":[[7,0]],"id":9480385}],"con":true,"img":false,"tv":52165.7}]}
{"op":"mcm","clk":"1149816869","pt":1439925597183,"mc":[{"id":"1.120089104","rc":[{"spb":[[1000,73]],"id":9612932},{"spb":[[1000,109]],"id":9480385}],"con":true,"img":false,"tv":52165.7}]}
{"op":"mcm","clk":"1149817049","pt":1439925598711,"mc":[{"id":"1.120089104","rc":[{"atl":[[1.26,2.11]],"id":9612932}],"con":true,"img":false,"tv":52165.7}]}
{"op":"mcm","clk":"1149817832","pt":1439925604178,"mc":[{"id":"1.120089104","rc":[{"atb":[[5.5,327.22]],"id":9480385}],"con":true,"img":false,"tv":52165.7}]}
{"op":"mcm","clk":"1149818376","pt":1439925608760,"mc":[{"id":"1.120089104","rc":[{"atl":[[1000,9]],"id":9612932},{"atb":[[1.01,2514.04]],"id":9480385}],"con":true,"img":false,"tv":52165.7}]}
{"op":"mcm","clk":"1149818392","pt":1439925608918,"mc":[{"id":"1.120089104","rc":[{"atl":[[1000,11.25]],"id":9612932},{"atb":[[1.01,2520.2]],"id":9480385}],"con":true,"img":false,"tv":52165.7}]}
{"op":"mcm","clk":"1149818399","pt":1439925609033,"mc":[{"id":"1.120089104","rc":[{"atl":[[1000,3.25]],"id":9612932},{"atb":[[1.01,2512.2]],"id":9480385}],"con":true,"img":false,"tv":52165.7}]}
{"op":"mcm","clk":"1149818430","pt":1439925609212,"mc":[{"id":"1.120089104","rc":[{"atl":[[1000,1]],"id":9612932},{"atb":[[1.01,2506.04]],"id":9480385}],"con":true,"img":false,"tv":52165.7}]}
{"op":"mcm","clk":"1149818435","pt":1439925609315,"mc":[{"id":"1.120089104","rc":[{"trd":[[1.16,17103.54]],"ltp":1.16,"tv":17103.54,"id":9612932},{"atb":[[1.16,124.49]],"id":9612932},{"atl":[[1.17,1708.19]],"id":9612932},{"trd":[[7.2,41.92]],"ltp":7.2,"tv":41.92,"id":9480385},{"atb":[[6.8,169.83],[7.2,0.15]],"id":9480385},{"atl":[[7.2,0]],"id":9480385}],"con":true,"img":false,"tv":52172.33}]}
{"op":"mcm","clk":"1149818479","pt":1439925609725,"mc":[{"id":"1.120089104","rc":[{"trd":[[1.16,17109.64]],"ltp":1.16,"tv":17109.64,"id":9612932},{"atb":[[1.16,121.44]],"id":9612932}],"con":true,"img":false,"tv":52178.43}]}
{"op":"mcm","clk":"1149818668","pt":1439925611087,"mc":[{"id":"1.120089104","rc":[{"trd":[[7.2,42.22]],"ltp":7.2,"tv":42.22,"id":9480385},{"atb":[[7.2,0]],"id":9480385},{"atl":[[7.2,12.87]],"id":9480385}],"con":true,"img":false,"tv":52178.73}]}
{"op":"mcm","clk":"1149819482","pt":1439925616149,"mc":[{"id":"1.120089104","rc":[{"atb":[[1.16,173.44]],"id":9612932}],"con":true,"img":false,"tv":52178.73}]}
{"op":"mcm","clk":"1149820334","pt":1439925622194,"mc":[{"id":"1.120089104","rc":[{"spn":1.15,"spf":1.08,"id":9612932},{"atl":[[22,7.4]],"id":9480385},{"spn":6.8,"spf":5.54,"id":9480385}],"con":true,"img":false,"tv":52178.73}]}
{"op":"mcm","clk":"1149821646","pt":1439925631082,"mc":[{"id":"1.120089104","rc":[{"trd":[[6.8,335.51]],"ltp":6.8,"tv":335.51,"id":9480385},{"atb":[[6.8,163.83]],"id":9480385}],"con":true,"img":false,"tv":52190.74}]}
{"op":"mcm","clk":"1149821946","pt":1439925633188,"mc":[{"id":"1.120089104","rc":[{"atl":[[8.4,0]],"id":9480385}],"con":true,"img":false,"tv":52190.74}]}
{"op":"mcm","clk":"1149821974","pt":1439925633310,"mc":[{"id":"1.120089104","rc":[{"atl":[[8.8,33.54]],"id":9480385}],"con":true,"img":false,"tv":52190.74}]}
{"op":"mcm","clk":"1149822878","pt":1439925639303,"mc":[{"id":"1.120089104","rc":[{"trd":[[1.16,17127.64]],"ltp":1.16,"tv":17127.64,"id":9612932},{"atb":[[1.16,164.44]],"id":9612932}],"con":true,"img":false,"tv":52208.74}]}
{"op":"mcm","clk":"1149824745","pt":1439925652479,"mc":[{"id":"1.120089104","rc":[{"atb":[[6.8,166.17]],"id":9480385}],"con":true,"img":false,"tv":52208.74}]}
{"op":"mcm","clk":"1149825717","pt":1439925660811,"mc":[{"id":"1.120089104","rc":[{"atb":[[6,21.83]],"id":9480385}],"con":true,"img":false,"tv":52208.74}]}
{"op":"mcm","clk":"1149825732","pt":1439925660901,"mc":[{"id":"1.120089104","rc":[{"atb":[[6,28.87]],"id":9480385}],"con":true,"img":false,"tv":52208.74}]}
{"op":"mcm","clk":"1149825736","pt":1439925660929,"mc":[{"id":"1.120089104","rc":[{"atb":[[6,35.92]],"id":9480385}],"con":true,"img":false,"tv":52208.74}]}
{"op":"mcm","clk":"1149826145","pt":1439925663765,"mc":[{"id":"1.120089104","rc":[{"trd":[[1.17,11147.2]],"ltp":1.17,"tv":11147.2,"id":9612932},{"atl":[[1.17,1702.82]],"id":9612932}],"con":true,"img":false,"tv":52219.48}]}
{"op":"mcm","clk":"1149826608","pt":1439925667146,"mc":[{"id":"1.120089104","rc":[{"spl":[[1.5,2]],"id":9612932}],"con":true,"img":false,"tv":52219.48}]}
{"op":"mcm","clk":"1149829080","pt":1439925684157,"mc":[{"id":"1.120089104","rc":[{"trd":[[1.17,11168.66]],"ltp":1.17,"tv":11168.66,"id":9612932},{"atl":[[1.17,1692.09]],"id":9612932},{"spn":1.15,"spf":1.08,"id":9612932}],"con":true,"img":false,"tv":52240.94}]}
{"op":"mcm","clk":"1149829972","pt":1439925690386,"mc":[{"id":"1.120089104","rc":[{"atl":[[1.17,2803.09]],"id":9612932}],"con":true,"img":false,"tv":52240.94}]}
{"op":"mcm","clk":"1149830428","pt":1439925693373,"mc":[{"id":"1.120089104","rc":[{"trd":[[1.17,11190.12]],"ltp":1.17,"tv":11190.12,"id":9612932},{"atl":[[1.17,2792.36]],"id":9612932}],"con":true,"img":false,"tv":52262.4}]}
{"op":"mcm","clk":"1149830502","pt":1439925693870,"mc":[{"id":"1.120089104","rc":[{"trd":[[1.17,11200.86]],"ltp":1.17,"tv":11200.86,"id":9612932},{"atl":[[1.17,2786.99]],"id":9612932}],"con":true,"img":false,"tv":52273.14}]}
{"op":"mcm","clk":"1149830704","pt":1439925695370,"mc":[{"id":"1.120089104","rc":[{"atb":[[1.15,14260.33]],"id":9612932}],"con":true,"img":false,"tv":52273.14}]}
{"op":"mcm","clk":"1149831185","pt":1439925698701,"mc":[{"id":"1.120089104","rc":[{"trd":[[1.17,11222.32]],"ltp":1.17,"tv":11222.32,"id":9612932},{"atl":[[1.17,2776.26]],"id":9612932}],"con":true,"img":false,"tv":52294.6}]}
{"op":"mcm","clk":"1149831549","pt":1439925701144,"mc":[{"id":"1.120089104","rc":[{"atb":[[1.14,17340.87]],"id":9612932}],"con":true,"img":false,"tv":52294.6}]}
{"op":"mcm","clk":"1149831917","pt":1439925703764,"mc":[{"id":"1.120089104","rc":[{"trd":[[1.16,17155.83]],"ltp":1.16,"tv":17155.83,"id":9612932},{"atb":[[1.16,150.35]],"id":9612932}],"con":true,"img":false,"tv":52322.78}]}
{"op":"mcm","clk":"1149832232","pt":1439925705922,"mc":[{"id":"1.120089104","rc":[{"trd":[[1.17,11243.78]],"ltp":1.17,"tv":11243.78,"id":9612932},{"atl":[[1.17,2765.53]],"id":9612932}],"con":true,"img":false,"tv":52344.24}]}
{"op":"mcm","clk":"1149832893","pt":1439925710054,"mc":[{"id":"1.120089104","rc":[{"trd":[[6.8,341.51]],"ltp":6.8,"tv":341.51,"id":9480385},{"atb":[[6.8,163.17]],"id":9480385}],"con":true,"img":false,"tv":52350.24}]}
{"op":"mcm","clk":"1149834297","pt":1439925719201,"mc":[{"id":"1.120089104","rc":[{"trd":[[1.17,11254.52]],"ltp":1.17,"tv":11254.52,"id":9612932},{"atl":[[1.17,2760.16]],"id":9612932}],"con":true,"img":false,"tv":52360.98}]}
{"op":"mcm","clk":"1149834438","pt":1439925720181,"mc":[{"id":"1.120089104","rc":[{"trd":[[1.17,11358.1]],"ltp":1.17,"tv":11358.1,"id":9612932},{"atl":[[1.17,2708.37]],"id":9612932}],"con":true,"img":false,"tv":52464.56}]}
{"op":"mcm","clk":"1149835636","pt":1439925728803,"mc":[{"id":"1.120089104","rc":[{"atl":[[1.5,10]],"id":9612932}],"con":true,"img":false,"tv":52464.56}]}
{"op":"mcm","clk":"1149836117","pt":1439925732061,"mc":[{"id":"1.120089104","rc":[{"trd":[[1.17,11379.56]],"ltp":1.17,"tv":11379.56,"id":9612932},{"atl":[[1.17,2697.64]],"id":9612932}],"con":true,"img":false,"tv":52486.02}]}
{"op":"mcm","clk":"1149836739","pt":1439925736594,"mc":[{"id":"1.120089104","rc":[{"atb":[[1.16,368.74],[1.14,17591.32],[1.13,15434.94],[1.15,14500.99]],"id":9612932},{"atl":[[1.17,2896.23],[1.18,1663.86],[1.2,206.41],[1.19,562.49]],"id":9612932},{"atb":[[6.8,199.23],[6.2,93.28],[6.4,157.26],[6.6,62.77]],"id":9480385},{"atl":[[7.8,51.13],[8.2,289.6],[7.4,69.22],[8,41.15]],"id":9480385}],"con":true,"img":false,"tv":52486.02}]}
{"op":"mcm","clk":"1149837644","pt":1439925742660,"mc":[{"id":"1.120089104","rc":[{"atb":[[1.16,2368.74]],"id":9612932}],"con":true,"img":false,"tv":52486.02}]}
{"op":"mcm","clk":"1149837748","pt":1439925743608,"mc":[{"id":"1.120089104","rc":[{"atl":[[2,50]],"id":9612932}],"con":true,"img":false,"tv":52486.02}]}
{"op":"mcm","clk":"1149839253","pt":1439925754124,"mc":[{"id":"1.120089104","rc":[{"trd":[[1.17,11401.02]],"ltp":1.17,"tv":11401.02,"id":9612932},{"atl":[[1.17,2885.5]],"id":9612932},{"spn":1.16,"spf":1.08,"id":9612932}],"con":true,"img":false,"tv":52507.48}]}
{"op":"mcm","clk":"1149840715","pt":1439925765026,"mc":[{"id":"1.120089104","rc":[{"trd":[[6.8,351.51]],"ltp":6.8,"tv":351.51,"id":9480385},{"atb":[[6.8,194.23]],"id":9480385}],"con":true,"img":false,"tv":52517.48}]}
{"op":"mcm","clk":"1149841047","pt":1439925767440,"mc":[{"id":"1.120089104","rc":[{"trd":[[1.17,11857.02]],"ltp":1.17,"tv":11857.02,"id":9612932},{"atl":[[1.17,2657.5]],"id":9612932}],"con":true,"img":false,"tv":52973.48}]}
{"op":"mcm","clk":"1149841246","pt":1439925768856,"mc":[{"id":"1.120089104","rc":[{"atb":[[1.16,368.74]],"id":9612932}],"con":true,"img":false,"tv":52973.48}]}
{"op":"mcm","clk":"1149841270","pt":1439925769022,"mc":[{"id":"1.120089104","rc":[{"trd":[[1.17,15857.03]],"ltp":1.17,"tv":15857.03,"id":9612932},{"atl":[[1.17,657.5]],"id":9612932}],"con":true,"img":false,"tv":56973.48}]}
{"op":"mcm","clk":"1149841327","pt":1439925769482,"mc":[{"id":"1.120089104","rc":[{"atb":[[1.16,523.91]],"id":9612932},{"atl":[[1.17,811.34]],"id":9612932}],"con":true,"img":false,"tv":56973.48}]}
{"op":"mcm","clk":"1149841765","pt":1439925772849,"mc":[{"id":"1.120089104","rc":[{"atl":[[7.2,0]],"id":9480385}],"con":true,"img":false,"tv":56973.48}]}
{"op":"mcm","clk":"1149841848","pt":1439925773477,"mc":[{"id":"1.120089104","rc":[{"atl":[[4.8,26.77]],"id":9612932},{"atl":[[7.4,93.54]],"id":9480385}],"con":true,"img":false,"tv":56973.48}]}
{"op":"mcm","clk":"1149842703","pt":1439925779495,"mc":[{"id":"1.120089104","rc":[{"trd":[[1.17,15867.77]],"ltp":1.17,"tv":15867.77,"id":9612932},{"atl":[[1.17,905.97]],"id":9612932}],"con":true,"img":false,"tv":56984.22}]}
{"op":"mcm","clk":"1149843383","pt":1439925784016,"mc":[{"id":"1.120089104","rc":[{"atl":[[7.2,20.83]],"id":9480385}],"con":true,"img":false,"tv":56984.22}]}
{"op":"mcm","clk":"1149845410","pt":1439925798941,"mc":[{"id":"1.120089104","rc":[{"atb":[[1.16,1228.53]],"id":9612932}],"con":true,"img":false,"tv":56984.22}]}
{"op":"mcm","clk":"1149848139","pt":1439925819793,"mc":[{"id":"1.120089104","rc":[{"trd":[[1.16,19612.89]],"ltp":1.16,"tv":19612.89,"id":9612932},{"atb":[[1.16,0]],"id":9612932},{"atl":[[1.16,771.47]],"id":9612932},{"spn":1.15,"spf":1.08,"id":9612932}],"con":true,"img":false,"tv":59441.29}]}
{"op":"mcm","clk":"1149848204","pt":1439925820180,"mc":[{"id":"1.120089104","rc":[{"trd":[[1.16,19871.47]],"ltp":1.16,"tv":19871.47,"id":9612932},{"atb":[[1.15,14690.68]],"id":9612932},{"atl":[[1.19,411.23],[1.16,642.18]],"id":9612932},{"trd":[[7.2,83.88]],"ltp":7.2,"tv":83.88,"id":9480385},{"atb":[[7,11.45]],"id":9480385},{"atl":[[7.4,69.22],[7.2,0]],"id":9480385}],"con":true,"img":false,"tv":59741.53}]}
{"op":"mcm","clk":"1149848252","pt":1439925820504,"mc":[{"id":"1.120089104","rc":[{"atb":[[7,15.45]],"id":9480385}],"con":true,"img":false,"tv":59741.53}]}
{"op":"mcm","clk":"1149848267","pt":1439925820617,"mc":[{"id":"1.120089104","rc":[{"atl":[[7.4,35.49]],"id":9480385}],"con":true,"img":false,"tv":59741.53}]}
{"op":"mcm","clk":"1149848281","pt":1439925820725,"mc":[{"id":"1.120089104","rc":[{"atb":[[1.12,16585.46]],"id":9612932},{"atb":[[7,51.32]],"id":9480385}],"con":true,"img":false,"tv":59741.53}]}
{"op":"mcm","clk":"1149848322","pt":1439925821007,"mc":[{"id":"1.120089104","rc":[{"atb":[[1.09,68.81]],"id":9612932},{"atl":[[7.4,29.39]],"id":9480385}],"con":true,"img":false,"tv":59741.53}]}
{"op":"mcm","clk":"1149848339","pt":1439925821115,"mc":[{"id":"1.120089104","rc":[{"atb":[[7,47.32]],"id":9480385}],"con":true,"img":false,"tv":59741.53}]}
{"op":"mcm","clk":"1149848428","pt":1439925821726,"mc":[{"id":"1.120089104","rc":[{"trd":[[1.16,20371.47]],"ltp":1.16,"tv":20371.47,"id":9612932},{"atl":[[1.16,392.18]],"id":9612932},{"atl":[[8.8,67.88]],"id":9480385}],"con":true,"img":false,"tv":60241.53}]}
{"op":"mcm","clk":"1149848495","pt":1439925822110,"mc":[{"id":"1.120089104","rc":[{"atl":[[9.4,5.73]],"id":9480385}],"con":true,"img":false,"tv":60241.53}]}
{"op":"mcm","clk":"1149848530","pt":1439925822437,"mc":[{"id":"1.120089104","rc":[{"trd":[[1.17,16083.41],[1.16,21155.83]],"ltp":1.17,"tv":37239.24,"id":9612932},{"atl":[[1.17,798.15],[1.16,0]],"id":9612932}],"con":true,"img":false,"tv":61241.53}]}
{"op":"mcm","clk":"1149848592","pt":1439925822866,"mc":[{"id":"1.120089104","rc":[{"atl":[[7.4,64.21]],"id":9480385}],"con":true,"img":false,"tv":61241.53}]}
{"op":"mcm","clk":"1149848614","pt":1439925823053,"mc":[{"id":"1.120089104","rc":[{"atb":[[5.6,6]],"id":9480385}],"con":true,"img":false,"tv":61241.53}]}
{"op":"mcm","clk":"1149848630","pt":1439925823170,"mc":[{"id":"1.120089104","rc":[{"atb":[[5.9,78.46]],"id":9480385},{"atl":[[7.4,96.31]],"id":9480385}],"con":true,"img":false,"tv":61241.53}]}
{"op":"mcm","clk":"1149848633","pt":1439925823223,"mc":[{"id":"1.120089104","rc":[{"atl":[[7.4,101.99]],"id":9480385}],"con":true,"img":false,"tv":61241.53}]}
{"op":"mcm","clk":"1149848650","pt":1439925823338,"mc":[{"id":"1.120089104","rc":[{"atb":[[1.15,14709.07]],"id":9612932},{"atb":[[7.2,2.93]],"id":9480385}],"con":true,"img":false,"tv":61241.53}]}
{"op":"mcm","clk":"1149848834","pt":1439925824777,"mc":[{"id":"1.120089104","rc":[{"atl":[[80,1.4]],"id":9612932},{"atl":[[80,1.4]],"id":9480385}],"con":true,"img":false,"tv":61241.53}]}
{"op":"mcm","clk":"1149848917","pt":1439925825322,"mc":[{"id":"1.120089104","rc":[{"atl":[[1.21,18.13]],"id":9612932}],"con":true,"img":false,"tv":61241.53}]}
{"op":"mcm","clk":"1149849231","pt":1439925827733,"mc":[{"id":"1.120089104","rc":[{"atl":[[1.17,1502.77]],"id":9612932}],"con":true,"img":false,"tv":61241.53}]}
{"op":"mcm","clk":"1149849538","pt":1439925830033,"mc":[{"id":"1.120089104","rc":[{"atl":[[8.6,6]],"id":9480385}],"con":true,"img":false,"tv":61241.53}]}
{"op":"mcm","clk":"1149850073","pt":1439925833903,"mc":[{"id":"1.120089104","rc":[{"trd":[[1.17,16104.87]],"ltp":1.17,"tv":16104.87,"id":9612932},{"atl":[[1.17,1492.04]],"id":9612932}],"con":true,"img":false,"tv":61262.99}]}
{"op":"mcm","clk":"1149850384","pt":1439925836153,"mc":[{"id":"1.120089104","rc":[{"atb":[[6.2,106.45]],"id":9480385}],"con":true,"img":false,"tv":61262.99}]}
{"op":"mcm","clk":"1149850410","pt":1439925836379,"mc":[{"id":"1.120089104","rc":[{"atb":[[6.2,70.29]],"id":9480385}],"con":true,"img":false,"tv":61262.99}]}
{"op":"mcm","clk":"1149852002","pt":1439925847523,"mc":[{"id":"1.120089104","rc":[{"spl":[[1.01,1121.48]],"id":9612932}],"con":true,"img":false,"tv":61262.99}]}
{"op":"mcm","clk":"1149854644","pt":1439925865432,"mc":[{"id":"1.120089104","rc":[{"atb":[[5.5,200.77]],"id":9480385}],"con":true,"img":false,"tv":61262.99}]}
{"op":"mcm","clk":"1149854657","pt":1439925865542,"mc":[{"id":"1.120089104","rc":[{"atb":[[6,162.37]],"id":9480385}],"con":true,"img":false,"tv":61262.99}]}
{"op":"mcm","clk":"1149855726","pt":1439925873187,"mc":[{"id":"1.120089104","rc":[{"atb":[[1.16,22]],"id":9612932}],"con":true,"img":false,"tv":61262.99}]}
{"op":"mcm","clk":"1149855850","pt":1439925874119,"mc":[{"id":"1.120089104","rc":[{"atb":[[1.11,36345.42]],"id":9612932},{"atb":[[5.7,0]],"id":9480385},{"atl":[[8.8,39.88]],"id":9480385}],"con":true,"img":false,"tv":61262.99}]}
{"op":"mcm","clk":"1149855861","pt":1439925874182,"mc":[{"id":"1.120089104","rc":[{"atb":[[1.16,43.18]],"id":9612932}],"con":true,"img":false,"tv":61262.99}]}
{"op":"mcm","clk":"1149855874","pt":1439925874286,"mc":[{"id":"1.120089104","rc":[{"atb":[[1.1,20315.94]],"id":9612932},{"atb":[[5.9,120.46]],"id":9480385},{"atl":[[9,28]],"id":9480385}],"con":true,"img":false,"tv":61262.99}]}
{"op":"mcm","clk":"1149856194","pt":1439925876705,"mc":[{"id":"1.120089104","rc":[{"atb":[[6.8,191.89]],"id":9480385}],"con":true,"img":false,"tv":61262.99}]}
{"op":"mcm","clk":"1149856210","pt":1439925876816,"mc":[{"id":"1.120089104","rc":[{"atb":[[7.2,5.28]],"id":9480385}],"con":true,"img":false,"tv":61262.99}]}
{"op":"mcm","clk":"1149856228","pt":1439925876926,"mc":[{"id":"1.120089104","rc":[{"atl":[[8.6,0]],"id":9480385}],"con":true,"img":false,"tv":61262.99}]}
{"op":"mcm","clk":"1149856811","pt":1439925880859,"mc":[{"id":"1.120089104","rc":[{"spn":1.15,"spf":1.08,"id":9612932},{"atl":[[13.5,8]],"id":9480385},{"spn":7.06,"spf":5.54,"id":9480385}],"con":true,"img":false,"tv":61262.99}]}
{"op":"mcm","clk":"1149857172","pt":1439925883482,"mc":[{"id":"1.120089104","rc":[{"trd":[[7.2,88.72]],"ltp":7.2,"tv":88.72,"id":9480385},{"atb":[[7.2,2.86]],"id":9480385}],"con":true,"img":false,"tv":61267.83}]}
{"op":"mcm","clk":"1149857208","pt":1439925883794,"mc":[{"id":"1.120089104","rc":[{"trd":[[1.17,16198.09]],"ltp":1.17,"tv":16198.09,"id":9612932},{"atl":[[1.17,1445.43]],"id":9612932}],"con":true,"img":false,"tv":61361.05}]}
{"op":"mcm","clk":"1149857892","pt":1439925888139,"mc":[{"id":"1.120089104","rc":[{"trd":[[1.16,21242.19]],"ltp":1.16,"tv":21242.19,"id":9612932},{"atb":[[1.16,0]],"id":9612932},{"atl":[[1.16,23.05]],"id":9612932}],"con":true,"img":false,"tv":61447.4}]}
{"op":"mcm","clk":"1149858407","pt":1439925891898,"mc":[{"id":"1.120089104","rc":[{"trd":[[1.16,21252.93]],"ltp":1.16,"tv":21252.93,"id":9612932},{"atl":[[1.16,17.68]],"id":9612932}],"con":true,"img":false,"tv":61458.14}]}
{"op":"mcm","clk":"1149858425","pt":1439925892091,"mc":[{"id":"1.120089104","rc":[{"atb":[[1.15,14727.45]],"id":9612932}],"con":true,"img":false,"tv":61458.14}]}
{"op":"mcm","clk":"1149858440","pt":1439925892205,"mc":[{"id":"1.120089104","rc":[{"atb":[[7.2,5.79]],"id":9480385}],"con":true,"img":false,"tv":61458.14}]}
{"op":"mcm","clk":"1149858810","pt":1439925894797,"mc":[{"id":"1.120089104","rc":[{"atb":[[5.5,109.29]],"id":9480385}],"con":true,"img":false,"tv":61458.14}]}
{"op":"mcm","clk":"1149858821","pt":1439925894903,"mc":[{"id":"1.120089104","rc":[{"atb":[[6,253.85]],"id":9480385}],"con":true,"img":false,"tv":61458.14}]}
{"op":"mcm","clk":"1149860393","pt":1439925906573,"mc":[{"id":"1.120089104","rc":[{"atl":[[7.4,114.66]],"id":9480385}],"con":true,"img":false,"tv":61458.14}]}
{"op":"mcm","clk":"1149861025","pt":1439925911045,"mc":[{"id":"1.120089104","rc":[{"trd":[[1.16,21265.93]],"ltp":1.16,"tv":21265.93,"id":9612932},{"atl":[[1.16,11.18]],"id":9612932}],"con":true,"img":false,"tv":61471.14}]}
{"op":"mcm","clk":"1149861681","pt":1439925915303,"mc":[{"id":"1.120089104","rc":[{"trd":[[1.16,21288.31]],"ltp":1.16,"tv":21288.31,"id":9612932},{"atb":[[1.16,6.42]],"id":9612932},{"atl":[[1.16,0]],"id":9612932}],"con":true,"img":false,"tv":61493.52}]}
{"op":"mcm","clk":"1149861853","pt":1439925916434,"mc":[{"id":"1.120089104","rc":[{"atb":[[1.16,8.59]],"id":9612932}],"con":true,"img":false,"tv":61493.52}]}
{"op":"mcm","clk":"1149862025","pt":1439925917658,"mc":[{"id":"1.120089104","rc":[{"atb":[[6.2,82.05]],"id":9480385}],"con":true,"img":false,"tv":61493.52}]}
{"op":"mcm","clk":"1149862041","pt":1439925917805,"mc":[{"id":"1.120089104","rc":[{"atl":[[1.21,0.82]],"id":9612932},{"atb":[[6.2,68.88]],"id":9480385}],"con":true,"img":false,"tv":61493.52}]}
{"op":"mcm","clk":"1149862132","pt":1439925918445,"mc":[{"id":"1.120089104","rc":[{"trd":[[7.2,92.72]],"ltp":7.2,"tv":92.72,"id":9480385},{"atb":[[7.2,3.79]],"id":9480385}],"con":true,"img":false,"tv":61497.52}]}
{"op":"mcm","clk":"1149862698","pt":1439925922971,"mc":[{"id":"1.120089104","rc":[{"atb":[[5.5,96]],"id":9480385}],"con":true,"img":false,"tv":61497.52}]}
{"op":"mcm","clk":"1149862700","pt":1439925923057,"mc":[{"id":"1.120089104","rc":[{"atb":[[6,267.13]],"id":9480385}],"con":true,"img":false,"tv":61497.52}]}
{"op":"mcm","clk":"1149864320","pt":1439925934839,"mc":[{"id":"1.120089104","rc":[{"atl":[[1.22,1483.54]],"id":9612932}],"con":true,"img":false,"tv":61497.52}]}
{"op":"mcm","clk":"1149864337","pt":1439925934976,"mc":[{"id":"1.120089104","rc":[{"atl":[[1.21,207.82]],"id":9612932}],"con":true,"img":false,"tv":61497.52}]}
{"op":"mcm","clk":"1149866659","pt":1439925951510,"mc":[{"id":"1.120089104","rc":[{"atl":[[1.17,2556.43]],"id":9612932},{"spn":1.15,"spf":1.08,"id":9612932},{"spn":7.04,"spf":5.54,"id":9480385}],"con":true,"img":false,"tv":61497.52}]}
{"op":"mcm","clk":"1149866985","pt":1439925953892,"mc":[{"id":"1.120089104","rc":[{"atb":[[1.16,23.59]],"id":9612932}],"con":true,"img":false,"tv":61497.52}]}
{"op":"mcm","clk":"1149868168","pt":1439925962948,"mc":[{"id":"1.120089104","rc":[{"atl":[[1000,9]],"id":9612932},{"trd":[[7.4,69.64]],"ltp":7.4,"tv":69.64,"id":9480385},{"atb":[[1.01,2510.04]],"id":9480385},{"atl":[[7.4,109.23]],"id":9480385}],"con":true,"img":false,"tv":61508.38}]}
{"op":"mcm","clk":"1149868184","pt":1439925963012,"mc":[{"id":"1.120089104","rc":[{"atl":[[1000,11.25]],"id":9612932},{"atb":[[1.01,2510.55]],"id":9480385}],"con":true,"img":false,"tv":61508.38}]}
{"op":"mcm","clk":"1149868201","pt":1439925963116,"mc":[{"id":"1.120089104","rc":[{"atl":[[1000,3.25]],"id":9612932},{"atb":[[1.01,2506.55]],"id":9480385}],"con":true,"img":false,"tv":61508.38}]}
{"op":"mcm","clk":"1149868218","pt":1439925963255,"mc":[{"id":"1.120089104","rc":[{"atl":[[1000,1]],"id":9612932},{"atb":[[1.01,2506.04]],"id":9480385}],"con":true,"img":false,"tv":61508.38}]}
{"op":"mcm","clk":"1149868224","pt":1439925963334,"mc":[{"id":"1.120089104","rc":[{"trd":[[1.16,21292.42]],"ltp":1.16,"tv":21292.42,"id":9612932},{"atb":[[1.16,21.53]],"id":9612932},{"atl":[[1.17,2556.62]],"id":9612932},{"atb":[[7.2,4.3]],"id":9480385}],"con":true,"img":false,"tv":61512.5}]}
{"op":"mcm","clk":"1149869051","pt":1439925969149,"mc":[{"id":"1.120089104","rc":[{"trd":[[1.16,21335.5]],"ltp":1.16,"tv":21335.5,"id":9612932},{"atb":[[1.16,0]],"id":9612932},{"atl":[[1.16,48.92]],"id":9612932}],"con":true,"img":false,"tv":61555.58}]}
{"op":"mcm","clk":"1149869136","pt":1439925969738,"mc":[{"id":"1.120089104","rc":[{"atl":[[1.17,2649.62]],"id":9612932}],"con":true,"img":false,"tv":61555.58}]}
{"op":"mcm","clk":"1149869180","pt":1439925970054,"mc":[{"id":"1.120089104","rc":[{"atl":[[7.4,77.13]],"id":9480385}],"con":true,"img":false,"tv":61555.58}]}
{"op":"mcm","clk":"1149869483","pt":1439925972284,"mc":[{"id":"1.120089104","rc":[{"atb":[[5.5,75.98]],"id":9480385}],"con":true,"img":false,"tv":61555.58}]}
{"op":"mcm","clk":"1149869498","pt":1439925972390,"mc":[{"id":"1.120089104","rc":[{"atb":[[6,287.15]],"id":9480385}],"con":true,"img":false,"tv":61555.58}]}
{"op":"mcm","clk":"1149869537","pt":1439925972662,"mc":[{"id":"1.120089104","rc":[{"atb":[[1.15,14745.83]],"id":9612932},{"atb":[[7.2,7.24]],"id":9480385}],"con":true,"img":false,"tv":61555.58}]}
{"op":"mcm","clk":"1149869736","pt":1439925973955,"mc":[{"id":"1.120089104","rc":[{"spb":[[1000,89.67]],"id":9612932}],"con":true,"img":false,"tv":61555.58}]}
{"op":"mcm","clk":"1149869752","pt":1439925974066,"mc":[{"id":"1.120089104","rc":[{"atb":[[5.5,56.77]],"id":9480385}],"con":true,"img":false,"tv":61555.58}]}
{"op":"mcm","clk":"1149869771","pt":1439925974171,"mc":[{"id":"1.120089104","rc":[{"atb":[[6,306.37]],"id":9480385}],"con":true,"img":false,"tv":61555.58}]}
{"op":"mcm","clk":"1149871134","pt":1439925983763,"mc":[{"id":"1.120089104","rc":[{"trd":[[1.16,21432.74]],"ltp":1.16,"tv":21432.74,"id":9612932},{"atl":[[1.16,0.3]],"id":9612932}],"con":true,"img":false,"tv":61652.82}]}
{"op":"mcm","clk":"1149871268","pt":1439925984709,"mc":[{"id":"1.120089104","rc":[{"atl":[[1.21,224.44]],"id":9612932}],"con":true,"img":false,"tv":61652.82}]}
{"op":"mcm","clk":"1149873834","pt":1439926004484,"mc":[{"id":"1.120089104","rc":[{"trd":[[1.17,16238.69],[1.16,21433.34]],"ltp":1.17,"tv":37672.03,"id":9612932},{"atl":[[1.17,2629.32],[1.16,0]],"id":9612932}],"con":true,"img":false,"tv":61694.02}]}
{"op":"mcm","clk":"1149874969","pt":1439926014154,"mc":[{"id":"1.120089104","rc":[{"spn":1.15,"spf":1.09,"id":9612932},{"trd":[[7.2,102.72]],"ltp":7.2,"tv":102.72,"id":9480385},{"atb":[[7.2,2.24]],"id":9480385},{"spn":7.02,"spf":5.54,"id":9480385}],"con":true,"img":false,"tv":61704.02}]}
{"op":"mcm","clk":"1149875557","pt":1439926018755,"mc":[{"id":"1.120089104","rc":[{"atb":[[6.2,75.97]],"id":9480385}],"con":true,"img":false,"tv":61704.02}]}
{"op":"mcm","clk":"1149875585","pt":1439926018975,"mc":[{"id":"1.120089104","rc":[{"atb":[[6.2,64.21]],"id":9480385}],"con":true,"img":false,"tv":61704.02}]}
{"op":"mcm","clk":"1149876070","pt":1439926022222,"mc":[{"id":"1.120089104","rc":[{"atl":[[1.2,306.41]],"id":9612932}],"con":true,"img":false,"tv":61704.02}]}
{"op":"mcm","clk":"1149877520","pt":1439926033652,"mc":[{"id":"1.120089104","rc":[{"atb":[[7.2,4.58]],"id":9480385}],"con":true,"img":false,"tv":61704.02}]}
{"op":"mcm","clk":"1149880092","pt":1439926052709,"mc":[{"id":"1.120089104","rc":[{"trd":[[7.4,143.64]],"ltp":7.4,"tv":143.64,"id":9480385},{"atl":[[7.4,40.13]],"id":9480385}],"con":true,"img":false,"tv":61778.02}]}
{"op":"mcm","clk":"1149880177","pt":1439926053306,"mc":[{"id":"1.120089104","rc":[{"atl":[[7.4,18.34]],"id":9480385}],"con":true,"img":false,"tv":61778.02}]}
{"op":"mcm","clk":"1149880227","pt":1439926053691,"mc":[{"id":"1.120089104","rc":[{"atl":[[7.4,12.67]],"id":9480385}],"con":true,"img":false,"tv":61778.02}]}
{"op":"mcm","clk":"1149880356","pt":1439926054694,"mc":[{"id":"1.120089104","rc":[{"atl":[[9,33.89]],"id":9480385}],"con":true,"img":false,"tv":61778.02}]}
{"op":"mcm","clk":"1149880571","pt":1439926056338,"mc":[{"id":"1.120089104","rc":[{"atl":[[1.21,17.44]],"id":9612932}],"con":true,"img":false,"tv":61778.02}]}
{"op":"mcm","clk":"1149880586","pt":1439926056448,"mc":[{"id":"1.120089104","rc":[{"atl":[[1.22,1688.54]],"id":9612932}],"con":true,"img":false,"tv":61778.02}]}
{"op":"mcm","clk":"1149883282","pt":1439926076974,"mc":[{"id":"1.120089104","rc":[{"atb":[[1.16,9]],"id":9612932},{"spn":1.15,"spf":1.09,"id":9612932},{"spn":7.05,"spf":5.54,"id":9480385}],"con":true,"img":false,"tv":61778.02}]}
{"op":"mcm","clk":"1149883477","pt":1439926078424,"mc":[{"id":"1.120089104","rc":[{"atl":[[7.4,0]],"id":9480385}],"con":true,"img":false,"tv":61778.02}]}
{"op":"mcm","clk":"1149883627","pt":1439926079629,"mc":[{"id":"1.120089104","rc":[{"atl":[[7.6,23.68]],"id":9480385}],"con":true,"img":false,"tv":61778.02}]}
{"op":"mcm","clk":"1149883654","pt":1439926079766,"mc":[{"id":"1.120089104","rc":[{"atl":[[7.8,57.13]],"id":9480385}],"con":true,"img":false,"tv":61778.02}]}
{"op":"mcm","clk":"1149883762","pt":1439926080518,"mc":[{"id":"1.120089104","rc":[{"atl":[[7.6,59.46]],"id":9480385}],"con":true,"img":false,"tv":61778.02}]}
{"op":"mcm","clk":"1149883904","pt":1439926081477,"mc":[{"id":"1.120089104","rc":[{"atl":[[7.4,1.4]],"id":9480385}],"con":true,"img":false,"tv":61778.02}]}
{"op":"mcm","clk":"1149883931","pt":1439926081676,"mc":[{"id":"1.120089104","rc":[{"atl":[[7.8,53.26]],"id":9480385}],"con":true,"img":false,"tv":61778.02}]}
{"op":"mcm","clk":"1149884434","pt":1439926085298,"mc":[{"id":"1.120089104","rc":[{"trd":[[7.2,106.73]],"ltp":7.2,"tv":106.73,"id":9480385},{"atb":[[7.2,2.58]],"id":9480385}],"con":true,"img":false,"tv":61782.02}]}
{"op":"mcm","clk":"1149885125","pt":1439926089809,"mc":[{"id":"1.120089104","rc":[{"atl":[[7.4,2.81]],"id":9480385}],"con":true,"img":false,"tv":61782.02}]}
{"op":"mcm","clk":"1149885159","pt":1439926090068,"mc":[{"id":"1.120089104","rc":[{"atl":[[7.4,1.4]],"id":9480385}],"con":true,"img":false,"tv":61782.02}]}
{"op":"mcm","clk":"1149886167","pt":1439926098007,"mc":[{"id":"1.120089104","rc":[{"atl":[[7.4,2.81]],"id":9480385}],"con":true,"img":false,"tv":61782.02}]}
{"op":"mcm","clk":"1149886227","pt":1439926098489,"mc":[{"id":"1.120089104","rc":[{"atl":[[7.4,1.4]],"id":9480385}],"con":true,"img":false,"tv":61782.02}]}
{"op":"mcm","clk":"1149886951","pt":1439926103749,"mc":[{"id":"1.120089104","rc":[{"atl":[[7.4,2.81]],"id":9480385}],"con":true,"img":false,"tv":61782.02}]}
{"op":"mcm","clk":"1149886972","pt":1439926103946,"mc":[{"id":"1.120089104","rc":[{"atl":[[7.4,1.4]],"id":9480385}],"con":true,"img":false,"tv":61782.02}]}
{"op":"mcm","clk":"1149887079","pt":1439926104658,"mc":[{"id":"1.120089104","rc":[{"atb":[[1.7,2]],"id":9480385}],"con":true,"img":false,"tv":61782.02}]}
{"op":"mcm","clk":"1149887479","pt":1439926107696,"mc":[{"id":"1.120089104","rc":[{"trd":[[1.17,16242.69]],"ltp":1.17,"tv":16242.69,"id":9612932},{"atl":[[1.17,2627.32]],"id":9612932}],"con":true,"img":false,"tv":61786.02}]}
{"op":"mcm","clk":"1149887655","pt":1439926109098,"mc":[{"id":"1.120089104","rc":[{"atl":[[7.4,2.81]],"id":9480385}],"con":true,"img":false,"tv":61786.02}]}
{"op":"mcm","clk":"1149887687","pt":1439926109278,"mc":[{"id":"1.120089104","rc":[{"atl":[[7.4,1.4]],"id":9480385}],"con":true,"img":false,"tv":61786.02}]}
{"op":"mcm","clk":"1149888428","pt":1439926114941,"mc":[{"id":"1.120089104","rc":[{"atl":[[7.4,2.81]],"id":9480385}],"con":true,"img":false,"tv":61786.02}]}
{"op":"mcm","clk":"1149888455","pt":1439926115142,"mc":[{"id":"1.120089104","rc":[{"atl":[[7.4,1.4]],"id":9480385}],"con":true,"img":false,"tv":61786.02}]}
{"op":"mcm","clk":"1149888674","pt":1439926116882,"mc":[{"id":"1.120089104","rc":[{"atb":[[1.1,20088.94]],"id":9612932},{"trd":[[7.2,110.72]],"ltp":7.2,"tv":110.72,"id":9480385},{"atb":[[7.2,0.58]],"id":9480385}],"con":true,"img":false,"tv":61790.02}]}
{"op":"mcm","clk":"1149888688","pt":1439926116990,"mc":[{"id":"1.120089104","rc":[{"atb":[[1.11,36570.42]],"id":9612932}],"con":true,"img":false,"tv":61790.02}]}
{"op":"mcm","clk":"1149890027","pt":1439926127669,"mc":[{"id":"1.120089104","rc":[{"atb":[[1.1,33.97]],"id":9480385}],"con":true,"img":false,"tv":61790.02}]}
{"op":"mcm","clk":"1149891287","pt":1439926137652,"mc":[{"id":"1.120089104","rc":[{"trd":[[1.17,16322.69]],"ltp":1.17,"tv":16322.69,"id":9612932},{"atl":[[1.17,2587.32]],"id":9612932},{"spn":7.0,"spf":5.54,"id":9480385}],"con":true,"img":false,"tv":61870.02}]}
{"op":"mcm","clk":"1149892793","pt":1439926150297,"mc":[{"id":"1.120089104","rc":[{"atb":[[1.16,25]],"id":9612932}],"con":true,"img":false,"tv":61870.02}]}
{"op":"mcm","clk":"1149892852","pt":1439926150820,"mc":[{"id":"1.120089104","rc":[{"atl":[[7.4,7.21]],"id":9480385}],"con":true,"img":false,"tv":61870.02}]}
{"op":"mcm","clk":"1149896360","pt":1439926178044,"mc":[{"id":"1.120089104","rc":[{"atb":[[5.9,78.46]],"id":9480385},{"atl":[[9,5.89]],"id":9480385}],"con":true,"img":false,"tv":61870.02}]}
{"op":"mcm","clk":"1149896380","pt":1439926178160,"mc":[{"id":"1.120089104","rc":[{"atb":[[5.8,51.13]],"id":9480385},{"atl":[[8.8,67.88]],"id":9480385}],"con":true,"img":false,"tv":61870.02}]}
{"op":"mcm","clk":"1149896473","pt":1439926178730,"mc":[{"id":"1.120089104","rc":[{"trd":[[1.16,21483.34]],"ltp":1.16,"tv":21483.34,"id":9612932},{"atb":[[1.16,0]],"id":9612932},{"atl":[[1.16,45.46]],"id":9612932}],"con":true,"img":false,"tv":61920.02}]}
{"op":"mcm","clk":"1149896546","pt":1439926179256,"mc":[{"id":"1.120089104","rc":[{"atl":[[7.4,1.4]],"id":9480385}],"con":true,"img":false,"tv":61920.02}]}
{"op":"mcm","clk":"1149896899","pt":1439926181758,"mc":[{"id":"1.120089104","rc":[{"trd":[[1.16,21519.8]],"ltp":1.16,"tv":21519.8,"id":9612932},{"atl":[[1.16,27.23]],"id":9612932}],"con":true,"img":false,"tv":61956.48}]}
{"op":"mcm","clk":"1149896923","pt":1439926181884,"mc":[{"id":"1.120089104","rc":[{"atb":[[7,50.34]],"id":9480385}],"con":true,"img":false,"tv":61956.48}]}
{"op":"mcm","clk":"1149897775","pt":1439926187748,"mc":[{"id":"1.120089104","rc":[{"trd":[[1.16,21574.27]],"ltp":1.16,"tv":21574.27,"id":9612932},{"atb":[[1.16,43.22]],"id":9612932},{"atl":[[1.16,0]],"id":9612932}],"con":true,"img":false,"tv":62010.95}]}
{"op":"mcm","clk":"1149897933","pt":1439926189068,"mc":[{"id":"1.120089104","rc":[{"atl":[[7.4,7.21]],"id":9480385}],"con":true,"img":false,"tv":62010.95}]}
{"op":"mcm","clk":"1149898434","pt":1439926192786,"mc":[{"id":"1.120089104","rc":[{"atb":[[1.14,17598.32]],"id":9612932}],"con":true,"img":false,"tv":62010.95}]}
{"op":"mcm","clk":"1149899071","pt":1439926197134,"mc":[{"id":"1.120089104","rc":[{"trd":[[1.16,21660.73]],"ltp":1.16,"tv":21660.73,"id":9612932},{"atb":[[1.16,0]],"id":9612932},{"atl":[[1.16,75.06]],"id":9612932}],"con":true,"img":false,"tv":62097.4}]}
{"op":"mcm","clk":"1149899147","pt":1439926197735,"mc":[{"id":"1.120089104","rc":[{"spn":1.15,"spf":1.09,"id":9612932},{"atb":[[7.2,6.35]],"id":9480385},{"atl":[[7.4,1.4]],"id":9480385},{"spn":7.07,"spf":5.54,"id":9480385}],"con":true,"img":false,"tv":62097.4}]}
{"op":"mcm","clk":"1149899686","pt":1439926201786,"mc":[{"id":"1.120089104","rc":[{"trd":[[1.16,21680.74]],"ltp":1.16,"tv":21680.74,"id":9612932},{"atl":[[1.16,65.05]],"id":9612932}],"con":true,"img":false,"tv":62117.42}]}
{"op":"mcm","clk":"1149899906","pt":1439926203408,"mc":[{"id":"1.120089104","rc":[{"atl":[[1.21,158.37]],"id":9612932},{"atb":[[6.2,77.3]],"id":9480385}],"con":true,"img":false,"tv":62117.42}]}
{"op":"mcm","clk":"1149899927","pt":1439926203608,"mc":[{"id":"1.120089104","rc":[{"atl":[[1.21,141.74]],"id":9612932},{"atb":[[6.2,70.22]],"id":9480385},{"atl":[[7.4,0]],"id":9480385}],"con":true,"img":false,"tv":62117.42}]}
{"op":"mcm","clk":"1149900052","pt":1439926204435,"mc":[{"id":"1.120089104","rc":[{"trd":[[1.16,21810.84]],"ltp":1.16,"tv":21810.84,"id":9612932},{"atb":[[1.16,9.63]],"id":9612932},{"atl":[[1.16,0]],"id":9612932}],"con":true,"img":false,"tv":62247.52}]}
{"op":"mcm","clk":"1149900213","pt":1439926205383,"mc":[{"id":"1.120089104","rc":[{"atb":[[7.2,0.58]],"id":9480385}],"con":true,"img":false,"tv":62247.52}]}
{"op":"mcm","clk":"1149900312","pt":1439926205999,"mc":[{"id":"1.120089104","rc":[{"atl":[[8.6,6]],"id":9480385}],"con":true,"img":false,"tv":62247.52}]}
{"op":"mcm","clk":"1149900339","pt":1439926206147,"mc":[{"id":"1.120089104","rc":[{"atb":[[3,2]],"id":9480385},{"atl":[[7.4,4.18]],"id":9480385}],"con":true,"img":false,"tv":62247.52}]}
{"op":"mcm","clk":"1149900367","pt":1439926206441,"mc":[{"id":"1.120089104","rc":[{"atl":[[7.4,16.85]],"id":9480385}],"con":true,"img":false,"tv":62247.52}]}
{"op":"mcm","clk":"1149900510","pt":1439926207600,"mc":[{"id":"1.120089104","rc":[{"atl":[[7.4,22.47]],"id":9480385}],"con":true,"img":false,"tv":62247.52}]}
{"op":"mcm","clk":"1149900521","pt":1439926207708,"mc":[{"id":"1.120089104","rc":[{"atb":[[1.16,20.46]],"id":9612932}],"con":true,"img":false,"tv":62247.52}]}
{"op":"mcm","clk":"1149900639","pt":1439926208398,"mc":[{"id":"1.120089104","rc":[{"atl":[[7.4,56.94]],"id":9480385}],"con":true,"img":false,"tv":62247.52}]}
{"op":"mcm","clk":"1149900678","pt":1439926208581,"mc":[{"id":"1.120089104","rc":[{"atl":[[8,43.15]],"id":9480385}],"con":true,"img":false,"tv":62247.52}]}
{"op":"mcm","clk":"1149900847","pt":1439926209885,"mc":[{"id":"1.120089104","rc":[{"trd":[[7.2,111.9]],"ltp":7.2,"tv":111.9,"id":9480385},{"atb":[[7.2,0]],"id":9480385},{"atl":[[7.2,4.41]],"id":9480385}],"con":true,"img":false,"tv":62248.7}]}
{"op":"mcm","clk":"1149901421","pt":1439926214266,"mc":[{"id":"1.120089104","rc":[{"atb":[[7,52.68]],"id":9480385}],"con":true,"img":false,"tv":62248.7}]}
{"op":"mcm","clk":"1149901720","pt":1439926216578,"mc":[{"id":"1.120089104","rc":[{"atl":[[7.4,52.75]],"id":9480385}],"con":true,"img":false,"tv":62248.7}]}
{"op":"mcm","clk":"1149901746","pt":1439926216750,"mc":[{"id":"1.120089104","rc":[{"atl":[[7.2,8.71]],"id":9480385}],"con":true,"img":false,"tv":62248.7}]}
{"op":"mcm","clk":"1149902951","pt":1439926225893,"mc":[{"id":"1.120089104","rc":[{"atb":[[1.16,38.69]],"id":9612932},{"atb":[[7,55.71]],"id":9480385}],"con":true,"img":false,"tv":62248.7}]}
{"op":"mcm","clk":"1149904520","pt":1439926238519,"mc":[{"id":"1.120089104","rc":[{"atb":[[1.16,242.69]],"id":9612932}],"con":true,"img":false,"tv":62248.7}]}
{"op":"mcm","clk":"1149904546","pt":1439926238615,"mc":[{"id":"1.120089104","rc":[{"atl":[[8.8,39.88]],"id":9480385}],"con":true,"img":false,"tv":62248.7}]}
{"op":"mcm","clk":"1149904559","pt":1439926238706,"mc":[{"id":"1.120089104","rc":[{"atl":[[8.6,35]],"id":9480385}],"con":true,"img":false,"tv":62248.7}]}
{"op":"mcm","clk":"1149904590","pt":1439926238917,"mc":[{"id":"1.120089104","rc":[{"atb":[[7,19.83]],"id":9480385}],"con":true,"img":false,"tv":62248.7}]}
{"op":"mcm","clk":"1149904656","pt":1439926239341,"mc":[{"id":"1.120089104","rc":[{"atl":[[8.6,29]],"id":9480385}],"con":true,"img":false,"tv":62248.7}]}
{"op":"mcm","clk":"1149905344","pt":1439926245327,"mc":[{"id":"1.120089104","rc":[{"atb":[[1.16,293.69]],"id":9612932}],"con":true,"img":false,"tv":62248.7}]}
{"op":"mcm","clk":"1149905670","pt":1439926247640,"mc":[{"id":"1.120089104","rc":[{"trd":[[1.17,16328.69]],"ltp":1.17,"tv":16328.69,"id":9612932},{"atl":[[1.17,2584.32]],"id":9612932}],"con":true,"img":false,"tv":62254.7}]}
{"op":"mcm","clk":"1149909867","pt":1439926279729,"mc":[{"id":"1.120089104","rc":[{"atl":[[1.21,0.82]],"id":9612932},{"spn":1.15,"spf":1.09,"id":9612932},{"spn":7.0,"spf":5.54,"id":9480385}],"con":true,"img":false,"tv":62254.7}]}
{"op":"mcm","clk":"1149909904","pt":1439926280024,"mc":[{"id":"1.120089104","rc":[{"atl":[[7.8,47.26]],"id":9480385}],"con":true,"img":false,"tv":62254.7}]}
{"op":"mcm","clk":"1149910525","pt":1439926285410,"mc":[{"id":"1.120089104","rc":[{"atl":[[1.21,141.74]],"id":9612932}],"con":true,"img":false,"tv":62254.7}]}
{"op":"mcm","clk":"1149912088","pt":1439926299144,"mc":[{"id":"1.120089104","rc":[{"atl":[[7.2,4.3]],"id":9480385}],"con":true,"img":false,"tv":62254.7}]}
{"op":"mcm","clk":"1149912100","pt":1439926299281,"mc":[{"id":"1.120089104","rc":[{"trd":[[7,130.21]],"ltp":7.0,"tv":130.21,"id":9480385},{"atb":[[7,15.42]],"id":9480385}],"con":true,"img":false,"tv":62263.52}]}
{"op":"mcm","clk":"1149912119","pt":1439926299441,"mc":[{"id":"1.120089104","rc":[{"atb":[[7,20.87]],"id":9480385},{"atl":[[7.2,9.59]],"id":9480385}],"con":true,"img":false,"tv":62263.52}]}
{"op":"mcm","clk":"1149914906","pt":1439926322884,"mc":[{"id":"1.120089104","rc":[{"atl":[[1000,9]],"id":9612932},{"atb":[[1.01,2514.04]],"id":9480385}],"con":true,"img":false,"tv":62263.52}]}
{"op":"mcm","clk":"1149914916","pt":1439926322994,"mc":[{"id":"1.120089104","rc":[{"atl":[[1000,11.25]],"id":9612932},{"atb":[[1.01,2520.14]],"id":9480385}],"con":true,"img":false,"tv":62263.52}]}
{"op":"mcm","clk":"1149914931","pt":1439926323053,"mc":[{"id":"1.120089104","rc":[{"atl":[[1000,3.25]],"id":9612932},{"atb":[[1.01,2512.14]],"id":9480385}],"con":true,"img":false,"tv":62263.52}]}
{"op":"mcm","clk":"1149914944","pt":1439926323161,"mc":[{"id":"1.120089104","rc":[{"atl":[[1000,1]],"id":9612932},{"atb":[[1.01,2506.04]],"id":9480385}],"con":true,"img":false,"tv":62263.52}]}
{"op":"mcm","clk":"1149914955","pt":1439926323269,"mc":[{"id":"1.120089104","rc":[{"trd":[[1.16,21813.38]],"ltp":1.16,"tv":21813.38,"id":9612932},{"atb":[[1.16,292.42]],"id":9612932},{"atl":[[1.17,2585.3]],"id":9612932},{"trd":[[7.2,118.8]],"ltp":7.2,"tv":118.8,"id":9480385},{"atb":[[7,23.52]],"id":9480385},{"atl":[[7.2,6.14]],"id":9480385}],"con":true,"img":false,"tv":62272.96}]}
{"op":"mcm","clk":"1149915196","pt":1439926325425,"mc":[{"id":"1.120089104","rc":[{"atb":[[1.16,310.92]],"id":9612932}],"con":true,"img":false,"tv":62272.96}]}
{"op":"mcm","clk":"1149915791","pt":1439926329948,"mc":[{"id":"1.120089104","rc":[{"atb":[[1.16,259.92]],"id":9612932}],"con":true,"img":false,"tv":62272.96}]}
{"op":"mcm","clk":"1149915816","pt":1439926330079,"mc":[{"id":"1.120089104","rc":[{"trd":[[1.17,16430.69]],"ltp":1.17,"tv":16430.69,"id":9612932},{"atl":[[1.17,2534.3]],"id":9612932}],"con":true,"img":false,"tv":62374.96}]}
{"op":"mcm","clk":"1149916237","pt":1439926333643,"mc":[{"id":"1.120089104","rc":[{"trd":[[1.16,21828.71]],"ltp":1.16,"tv":21828.71,"id":9612932},{"atb":[[1.16,252.25]],"id":9612932}],"con":true,"img":false,"tv":62390.29}]}
{"op":"mcm","clk":"1149916571","pt":1439926336270,"mc":[{"id":"1.120089104","rc":[{"atb":[[1.16,1363.25]],"id":9612932}],"con":true,"img":false,"tv":62390.29}]}
{"op":"mcm","clk":"1149918438","pt":1439926351973,"mc":[{"id":"1.120089104","rc":[{"trd":[[1.17,16470.69]],"ltp":1.17,"tv":16470.69,"id":9612932},{"atl":[[1.17,2514.3]],"id":9612932},{"spn":1.16,"spf":1.09,"id":9612932}],"con":true,"img":false,"tv":62430.29}]}
{"op":"mcm","clk":"1149918771","pt":1439926354578,"mc":[{"id":"1.120089104","rc":[{"atb":[[1.16,1159.25]],"id":9612932}],"con":true,"img":false,"tv":62430.29}]}
{"op":"mcm","clk":"1149918781","pt":1439926354683,"mc":[{"id":"1.120089104","rc":[{"trd":[[1.17,16878.68]],"ltp":1.17,"tv":16878.68,"id":9612932},{"atl":[[1.17,2310.3]],"id":9612932}],"con":true,"img":false,"tv":62838.29}]}
{"op":"mcm","clk":"1149918823","pt":1439926354964,"mc":[{"id":"1.120089104","rc":[{"atb":[[1.16,1140.75]],"id":9612932}],"con":true,"img":false,"tv":62838.29}]}
{"op":"mcm","clk":"1149918835","pt":1439926355073,"mc":[{"id":"1.120089104","rc":[{"trd":[[1.17,16915.69]],"ltp":1.17,"tv":16915.69,"id":9612932},{"atl":[[1.17,2291.8]],"id":9612932}],"con":true,"img":false,"tv":62875.29}]}
{"op":"mcm","clk":"1149918860","pt":1439926355290,"mc":[{"id":"1.120089104","rc":[{"trd":[[1.17,16936.58]],"ltp":1.17,"tv":16936.58,"id":9612932},{"atl":[[1.17,2281.35]],"id":9612932}],"con":true,"img":false,"tv":62896.19}]}
{"op":"mcm","clk":"1149920615","pt":1439926369079,"mc":[{"id":"1.120089104","rc":[{"trd":[[1.17,16976.58]],"ltp":1.17,"tv":16976.58,"id":9612932},{"atl":[[1.17,2261.35]],"id":9612932}],"con":true,"img":false,"tv":62936.19}]}
{"op":"mcm","clk":"1149921739","pt":1439926378277,"mc":[{"id":"1.120089104","rc":[{"atl":[[7.4,40.08]],"id":9480385}],"con":true,"img":false,"tv":62936.19}]}
{"op":"mcm","clk":"1149922415","pt":1439926383729,"mc":[{"id":"1.120089104","rc":[{"trd":[[7,140.49]],"ltp":7.0,"tv":140.49,"id":9480385},{"atb":[[7,18.38]],"id":9480385}],"con":true,"img":false,"tv":62946.46}]}
{"op":"mcm","clk":"1149922457","pt":1439926384101,"mc":[{"id":"1.120089104","rc":[{"atb":[[7,42.19]],"id":9480385}],"con":true,"img":false,"tv":62946.46}]}
{"op":"mcm","clk":"1149922588","pt":1439926385087,"mc":[{"id":"1.120089104","rc":[{"atl":[[9,7.89]],"id":9480385}],"con":true,"img":false,"tv":62946.46}]}
{"op":"mcm","clk":"1149924343","pt":1439926401958,"mc":[{"id":"1.120089104","rc":[{"atl":[[1.2,406.41]],"id":9612932}],"con":true,"img":false,"tv":62946.46}]}
{"op":"mcm","clk":"1149924656","pt":1439926404815,"mc":[{"id":"1.120089104","rc":[{"trd":[[1.17,17376.59]],"ltp":1.17,"tv":17376.59,"id":9612932},{"atl":[[1.17,2061.35]],"id":9612932}],"con":true,"img":false,"tv":63346.47}]}
{"op":"mcm","clk":"1149924695","pt":1439926405360,"mc":[{"id":"1.120089104","rc":[{"atb":[[1.16,1295.92]],"id":9612932}],"con":true,"img":false,"tv":63346.47}]}
{"op":"mcm","clk":"1149924749","pt":1439926405955,"mc":[{"id":"1.120089104","rc":[{"atl":[[1.17,2279.58]],"id":9612932}],"con":true,"img":false,"tv":63346.47}]}
{"op":"mcm","clk":"1149926397","pt":1439926422229,"mc":[{"id":"1.120089104","rc":[{"trd":[[1.17,17413.59]],"ltp":1.17,"tv":17413.59,"id":9612932},{"atb":[[1.11,32911.29]],"id":9612932},{"atl":[[1.17,2261.08]],"id":9612932},{"atb":[[6,214.89]],"id":9480385}],"con":true,"img":false,"tv":63383.47}]}
{"op":"mcm","clk":"1149929935","pt":1439926460665,"mc":[{"id":"1.120089104","rc":[{"atb":[[1.11,27393.55]],"id":9612932},{"atb":[[6,88.44]],"id":9480385}],"con":true,"img":false,"tv":63383.47}]}
{"op":"mcm","clk":"1149940229","pt":1439926474397,"mc":[{"id":"1.120089104","rc":[{"atb":[[1.16,1321.92]],"id":9612932}],"con":true,"img":false,"tv":63383.47}]}
{"op":"mcm","clk":"1149940274","pt":1439926474923,"mc":[{"id":"1.120089104","rc":[{"trd":[[1.17,17434.49]],"ltp":1.17,"tv":17434.49,"id":9612932},{"atl":[[1.17,2250.63]],"id":9612932}],"con":true,"img":false,"tv":63404.37}]}
{"op":"mcm","clk":"1149943528","pt":1439926511952,"mc":[{"id":"1.120089104","rc":[{"trd":[[7,167.27]],"ltp":7.0,"tv":167.27,"id":9480385},{"atb":[[7,28.8]],"id":9480385}],"con":true,"img":false,"tv":63431.15}]}
{"op":"mcm","clk":"1149943835","pt":1439926515648,"mc":[{"id":"1.120089104","rc":[{"trd":[[7.2,131.08]],"ltp":7.2,"tv":131.08,"id":9480385},{"atb":[[7.2,1.86]],"id":9480385},{"atl":[[7.2,0]],"id":9480385}],"con":true,"img":false,"tv":63443.44}]}
{"op":"mcm","clk":"1149943940","pt":1439926516770,"mc":[{"id":"1.120089104","rc":[{"atb":[[6.2,126.59]],"id":9480385}],"con":true,"img":false,"tv":63443.44}]}
{"op":"mcm","clk":"1149943958","pt":1439926516986,"mc":[{"id":"1.120089104","rc":[{"atb":[[6.2,113.49]],"id":9480385}],"con":true,"img":false,"tv":63443.44}]}
{"op":"mcm","clk":"1149944107","pt":1439926518486,"mc":[{"id":"1.120089104","rc":[{"atl":[[7.4,64.4]],"id":9480385}],"con":true,"img":false,"tv":63443.44}]}
{"op":"mcm","clk":"1149944928","pt":1439926527882,"mc":[{"id":"1.120089104","rc":[{"trd":[[7,203.55],[7.2,134.8]],"ltp":7.0,"tv":338.35,"id":9480385},{"atb":[[7,10.66],[7.2,0]],"id":9480385}],"con":true,"img":false,"tv":63483.44}]}
{"op":"mcm","clk":"1149944942","pt":1439926528096,"mc":[{"id":"1.120089104","rc":[{"atb":[[7,15.72]],"id":9480385},{"atl":[[7.2,4.91]],"id":9480385}],"con":true,"img":false,"tv":63483.44}]}
{"op":"mcm","clk":"1149944962","pt":1439926528326,"mc":[{"id":"1.120089104","rc":[{"trd":[[7.2,139.49]],"ltp":7.2,"tv":139.49,"id":9480385},{"atb":[[7,21.4]],"id":9480385},{"atl":[[7.2,8.09]],"id":9480385}],"con":true,"img":false,"tv":63488.12}]}
{"op":"mcm","clk":"1149944968","pt":1439926528374,"mc":[{"id":"1.120089104","rc":[{"atb":[[7,10.74]],"id":9480385}],"con":true,"img":false,"tv":63488.12}]}
{"op":"mcm","clk":"1149945000","pt":1439926528698,"mc":[{"id":"1.120089104","rc":[{"atb":[[1.16,1358.7]],"id":9612932}],"con":true,"img":false,"tv":63488.12}]}
{"op":"mcm","clk":"1149945059","pt":1439926529406,"mc":[{"id":"1.120089104","rc":[{"atb":[[1.16,1586.29]],"id":9612932}],"con":true,"img":false,"tv":63488.12}]}
{"op":"mcm","clk":"1149945235","pt":1439926531612,"mc":[{"id":"1.120089104","rc":[{"atb":[[1.15,14556.14]],"id":9612932},{"atl":[[7.6,35.78],[7.2,33.09]],"id":9480385}],"con":true,"img":false,"tv":63488.12}]}
{"op":"mcm","clk":"1149945477","pt":1439926534473,"mc":[{"id":"1.120089104","rc":[{"atl":[[7.6,37.18]],"id":9480385}],"con":true,"img":false,"tv":63488.12}]}
{"op":"mcm","clk":"1149945492","pt":1439926534675,"mc":[{"id":"1.120089104","rc":[{"atl":[[8,41.15]],"id":9480385}],"con":true,"img":false,"tv":63488.12}]}
{"op":"mcm","clk":"1149946729","pt":1439926549317,"mc":[{"id":"1.120089104","rc":[{"atb":[[1.16,1660.82]],"id":9612932}],"con":true,"img":false,"tv":63488.12}]}
{"op":"mcm","clk":"1149948352","pt":1439926569223,"mc":[{"id":"1.120089104","rc":[{"atl":[[7.2,37.09]],"id":9480385}],"con":true,"img":false,"tv":63488.12}]}
{"op":"mcm","clk":"1149950207","pt":1439926591543,"mc":[{"id":"1.120089104","rc":[{"trd":[[1.17,17438.57]],"ltp":1.17,"tv":17438.57,"id":9612932},{"atl":[[1.17,2248.59]],"id":9612932}],"con":true,"img":false,"tv":63492.2}]}
{"op":"mcm","clk":"1149950673","pt":1439926597793,"mc":[{"id":"1.120089104","rc":[{"atb":[[1.01,2530.6]],"id":9612932}],"con":true,"img":false,"tv":63492.2}]}
{"op":"mcm","clk":"1149951020","pt":1439926602192,"mc":[{"id":"1.120089104","rc":[{"trd":[[1.17,17450.67]],"ltp":1.17,"tv":17450.67,"id":9612932},{"atl":[[1.17,2242.54]],"id":9612932}],"con":true,"img":false,"tv":63504.3}]}
{"op":"mcm","clk":"1149951325","pt":1439926606011,"mc":[{"id":"1.120089104","rc":[{"atl":[[1.17,3354.54]],"id":9612932}],"con":true,"img":false,"tv":63504.3}]}
{"op":"mcm","clk":"1149951391","pt":1439926606848,"mc":[{"id":"1.120089104","rc":[{"atb":[[1.01,2530.92]],"id":9612932}],"con":true,"img":false,"tv":63504.3}]}
{"op":"mcm","clk":"1149951888","pt":1439926613399,"mc":[{"id":"1.120089104","rc":[{"atb":[[1.01,2528.04]],"id":9612932}],"con":true,"img":false,"tv":63504.3}]}
{"op":"mcm","clk":"1149951897","pt":1439926613505,"mc":[{"id":"1.120089104","rc":[{"trd":[[1.17,17451.31]],"ltp":1.17,"tv":17451.31,"id":9612932},{"atl":[[1.17,3354.22]],"id":9612932}],"con":true,"img":false,"tv":63504.94}]}
{"op":"mcm","clk":"1149952047","pt":1439926615317,"mc":[{"id":"1.120089104","rc":[{"trd":[[1.16,21906.24]],"ltp":1.16,"tv":21906.24,"id":9612932},{"atb":[[1.16,1622.05]],"id":9612932}],"con":true,"img":false,"tv":63582.47}]}
{"op":"mcm","clk":"1149952677","pt":1439926623597,"mc":[{"id":"1.120089104","rc":[{"atb":[[1.16,1640.28]],"id":9612932},{"atb":[[7,13.76]],"id":9480385}],"con":true,"img":false,"tv":63582.47}]}
{"op":"mcm","clk":"1149953354","pt":1439926632910,"mc":[{"id":"1.120089104","rc":[{"atl":[[1.19,1522.23]],"id":9612932}],"con":true,"img":false,"tv":63582.47}]}
{"op":"mcm","clk":"1149953760","pt":1439926637698,"mc":[{"id":"1.120089104","rc":[{"atb":[[1.01,2591.93]],"id":9612932},{"atb":[[1.01,2569.93]],"id":9480385}],"con":true,"img":false,"tv":63582.47}]}
{"op":"mcm","clk":"1149954820","pt":1439926650374,"mc":[{"id":"1.120089104","rc":[{"trd":[[1.16,21962.24]],"ltp":1.16,"tv":21962.24,"id":9612932},{"atb":[[1.16,1612.28]],"id":9612932}],"con":true,"img":false,"tv":63638.47}]}
{"op":"mcm","clk":"1149955672","pt":1439926660176,"mc":[{"id":"1.120089104","rc":[{"trd":[[7.2,151.57]],"ltp":7.2,"tv":151.57,"id":9480385},{"atl":[[7.2,31.05]],"id":9480385}],"con":true,"img":false,"tv":63650.55}]}
{"op":"mcm","clk":"1149955681","pt":1439926660238,"mc":[{"id":"1.120089104","rc":[{"trd":[[1.16,22162.24]],"ltp":1.16,"tv":22162.24,"id":9612932},{"atb":[[1.16,1512.28]],"id":9612932}],"con":true,"img":false,"tv":63850.55}]}
{"op":"mcm","clk":"1149956032","pt":1439926664727,"mc":[{"id":"1.120089104","rc":[{"trd":[[1.16,22166.24]],"ltp":1.16,"tv":22166.24,"id":9612932},{"atb":[[1.16,1510.28]],"id":9612932}],"con":true,"img":false,"tv":63854.55}]}
{"op":"mcm","clk":"1149956053","pt":1439926664894,"mc":[{"id":"1.120089104","rc":[{"trd":[[1.16,22170.24]],"ltp":1.16,"tv":22170.24,"id":9612932},{"atb":[[1.16,1508.28]],"id":9612932}],"con":true,"img":false,"tv":63858.55}]}
{"op":"mcm","clk":"1149956743","pt":1439926673730,"mc":[{"id":"1.120089104","rc":[{"trd":[[1.17,17515.19]],"ltp":1.17,"tv":17515.19,"id":9612932},{"atl":[[1.17,3322.28]],"id":9612932}],"con":true,"img":false,"tv":63922.43}]}
{"op":"mcm","clk":"1149957480","pt":1439926682919,"mc":[{"id":"1.120089104","rc":[{"atl":[[1000,9]],"id":9612932},{"atb":[[1.01,2577.93]],"id":9480385}],"con":true,"img":false,"tv":63922.43}]}
{"op":"mcm","clk":"1149957489","pt":1439926683036,"mc":[{"id":"1.120089104","rc":[{"atl":[[1000,11.25]],"id":9612932},{"atb":[[1.01,2584.03]],"id":9480385}],"con":true,"img":false,"tv":63922.43}]}
{"op":"mcm","clk":"1149957496","pt":1439926683145,"mc":[{"id":"1.120089104","rc":[{"atl":[[1000,3.25]],"id":9612932},{"atb":[[1.01,2576.03]],"id":9480385}],"con":true,"img":false,"tv":63922.43}]}
{"op":"mcm","clk":"1149957502","pt":1439926683238,"mc":[{"id":"1.120089104","rc":[{"atl":[[1000,1]],"id":9612932},{"atb":[[1.01,2569.93]],"id":9480385}],"con":true,"img":false,"tv":63922.43}]}
{"op":"mcm","clk":"1149957510","pt":1439926683354,"mc":[{"id":"1.120089104","rc":[{"trd":[[1.16,22172.78]],"ltp":1.16,"tv":22172.78,"id":9612932},{"atb":[[1.16,1507.01]],"id":9612932},{"atl":[[1.17,3323.26]],"id":9612932},{"trd":[[7.2,158.47]],"ltp":7.2,"tv":158.47,"id":9480385},{"atb":[[7,16.41]],"id":9480385},{"atl":[[7.2,27.6]],"id":9480385}],"con":true,"img":false,"tv":63931.87}]}
{"op":"mcm","clk":"1149958422","pt":1439926693491,"mc":[{"id":"1.120089104","rc":[{"atl":[[1.3,120.61]],"id":9612932}],"con":true,"img":false,"tv":63931.87}]}
{"op":"mcm","clk":"1149958903","pt":1439926698998,"mc":[{"id":"1.120089104","rc":[{"atl":[[7.4,66.83]],"id":9480385}],"con":true,"img":false,"tv":63931.87}]}
{"op":"mcm","clk":"1149959805","pt":1439926709898,"mc":[{"id":"1.120089104","rc":[{"trd":[[1.16,22178.78]],"ltp":1.16,"tv":22178.78,"id":9612932},{"atb":[[1.16,1504.01]],"id":9612932}],"con":true,"img":false,"tv":63937.87}]}
{"op":"mcm","clk":"1149959912","pt":1439926711237,"mc":[{"id":"1.120089104","rc":[{"trd":[[7,207.78]],"ltp":7.0,"tv":207.78,"id":9480385},{"atb":[[7,14.3]],"id":9480385}],"con":true,"img":false,"tv":63942.09}]}
{"op":"mcm","clk":"1149960079","pt":1439926713443,"mc":[{"id":"1.120089104","rc":[{"trd":[[7.2,190.69]],"ltp":7.2,"tv":190.69,"id":9480385},{"atl":[[7.2,11.49]],"id":9480385}],"con":true,"img":false,"tv":63974.31}]}
{"op":"mcm","clk":"1149960112","pt":1439926713918,"mc":[{"id":"1.120089104","rc":[{"atb":[[7,40.01]],"id":9480385},{"atl":[[7.2,4]],"id":9480385}],"con":true,"img":false,"tv":63974.31}]}
{"op":"mcm","clk":"1149961131","pt":1439926726344,"mc":[{"id":"1.120089104","rc":[{"atb":[[1.15,14599.44]],"id":9612932}],"con":true,"img":false,"tv":63974.31}]}
{"op":"mcm","clk":"1149962429","pt":1439926740766,"mc":[{"id":"1.120089104","rc":[{"atl":[[7.4,64.4]],"id":9480385}],"con":true,"img":false,"tv":63974.31}]}
{"op":"mcm","clk":"1149962433","pt":1439926740857,"mc":[{"id":"1.120089104","rc":[{"atl":[[9.8,2.43]],"id":9480385}],"con":true,"img":false,"tv":63974.31}]}
{"op":"mcm","clk":"1149962575","pt":1439926742408,"mc":[{"id":"1.120089104","rc":[{"trd":[[1.17,17535.19]],"ltp":1.17,"tv":17535.19,"id":9612932},{"atl":[[1.17,3313.26]],"id":9612932}],"con":true,"img":false,"tv":63994.31}]}
{"op":"mcm","clk":"1149964245","pt":1439926761263,"mc":[{"id":"1.120089104","rc":[{"atl":[[1.21,0.82]],"id":9612932}],"con":true,"img":false,"tv":63994.31}]}
{"op":"mcm","clk":"1149964574","pt":1439926765263,"mc":[{"id":"1.120089104","rc":[{"atl":[[1.21,141.74]],"id":9612932}],"con":true,"img":false,"tv":63994.31}]}
{"op":"mcm","clk":"1149965876","pt":1439926779419,"mc":[{"id":"1.120089104","rc":[{"trd":[[1.17,21135.19]],"ltp":1.17,"tv":21135.19,"id":9612932},{"atl":[[1.17,1513.25]],"id":9612932}],"con":true,"img":false,"tv":67594.32}]}
{"op":"mcm","clk":"1149966098","pt":1439926781932,"mc":[{"id":"1.120089104","rc":[{"atb":[[7,14.3]],"id":9480385}],"con":true,"img":false,"tv":67594.32}]}
{"op":"mcm","clk":"1149966133","pt":1439926782253,"mc":[{"id":"1.120089104","rc":[{"atb":[[7,19.53]],"id":9480385},{"atl":[[7.2,9.08]],"id":9480385}],"con":true,"img":false,"tv":67594.32}]}
{"op":"mcm","clk":"1149966423","pt":1439926785368,"mc":[{"id":"1.120089104","rc":[{"atb":[[1.09,152.81]],"id":9612932},{"spb":[[1000,99.67]],"id":9612932}],"con":true,"img":false,"tv":67594.32}]}
{"op":"mcm","clk":"1149967135","pt":1439926793375,"mc":[{"id":"1.120089104","rc":[{"atb":[[1.16,2208.63]],"id":9612932},{"spn":1.16,"spf":1.1,"id":9612932}],"con":true,"img":false,"tv":67594.32}]}
{"op":"mcm","clk":"1149967301","pt":1439926795375,"mc":[{"id":"1.120089104","rc":[{"atl":[[7.2,34.08]],"id":9480385}],"con":true,"img":false,"tv":67594.32}]}
{"op":"mcm","clk":"1149967378","pt":1439926796287,"mc":[{"id":"1.120089104","rc":[{"atl":[[1.19,1554.18]],"id":9612932}],"con":true,"img":false,"tv":67594.32}]}
{"op":"mcm","clk":"1149967442","pt":1439926797050,"mc":[{"id":"1.120089104","rc":[{"trd":[[1.17,21160.75]],"ltp":1.17,"tv":21160.75,"id":9612932},{"atl":[[1.17,1500.47]],"id":9612932}],"con":true,"img":false,"tv":67619.87}]}
{"op":"mcm","clk":"1149967883","pt":1439926801536,"mc":[{"id":"1.120089104","rc":[{"atl":[[7.2,51.2]],"id":9480385}],"con":true,"img":false,"tv":67619.87}]}
{"op":"mcm","clk":"1149968093","pt":1439926803410,"mc":[{"id":"1.120089104","rc":[{"trd":[[1.17,21201.83]],"ltp":1.17,"tv":21201.83,"id":9612932},{"atl":[[1.17,1479.93]],"id":9612932}],"con":true,"img":false,"tv":67660.95}]}
{"op":"mcm","clk":"1149968228","pt":1439926804938,"mc":[{"id":"1.120089104","rc":[{"atl":[[9.8,0]],"id":9480385}],"con":true,"img":false,"tv":67660.95}]}
{"op":"mcm","clk":"1149968238","pt":1439926804993,"mc":[{"id":"1.120089104","rc":[{"atl":[[7.4,66.83]],"id":9480385}],"con":true,"img":false,"tv":67660.95}]}
{"op":"mcm","clk":"1149968425","pt":1439926807008,"mc":[{"id":"1.120089104","rc":[{"trd":[[7,246.84]],"ltp":7.0,"tv":246.84,"id":9480385},{"atb":[[7,0]],"id":9480385},{"atl":[[7,0.55]],"id":9480385}],"con":true,"img":false,"tv":67700.02}]}
{"op":"mcm","clk":"1149968774","pt":1439926810878,"mc":[{"id":"1.120089104","rc":[{"trd":[[1.17,21401.83]],"ltp":1.17,"tv":21401.83,"id":9612932},{"atl":[[1.17,1379.93]],"id":9612932}],"con":true,"img":false,"tv":67900.02}]}
{"op":"mcm","clk":"1149968840","pt":1439926811571,"mc":[{"id":"1.120089104","rc":[{"atb":[[1.16,3455.29]],"id":9612932}],"con":true,"img":false,"tv":67900.02}]}
{"op":"mcm","clk":"1149970435","pt":1439926830759,"mc":[{"id":"1.120089104","rc":[{"atb":[[6,75.15]],"id":9480385}],"con":true,"img":false,"tv":67900.02}]}
{"op":"mcm","clk":"1149970446","pt":1439926830866,"mc":[{"id":"1.120089104","rc":[{"atb":[[5.6,19.28]],"id":9480385}],"con":true,"img":false,"tv":67900.02}]}
{"op":"mcm","clk":"1149970656","pt":1439926833539,"mc":[{"id":"1.120089104","rc":[{"atl":[[1.21,0.82]],"id":9612932}],"con":true,"img":false,"tv":67900.02}]}
{"op":"mcm","clk":"1149970839","pt":1439926835594,"mc":[{"id":"1.120089104","rc":[{"atl":[[1.2,906.41]],"id":9612932}],"con":true,"img":false,"tv":67900.02}]}
{"op":"mcm","clk":"1149970884","pt":1439926836180,"mc":[{"id":"1.120089104","rc":[{"atb":[[1.15,14720.48]],"id":9612932}],"con":true,"img":false,"tv":67900.02}]}
{"op":"mcm","clk":"1149970948","pt":1439926836823,"mc":[{"id":"1.120089104","rc":[{"atl":[[1.21,141.74]],"id":9612932}],"con":true,"img":false,"tv":67900.02}]}
{"op":"mcm","clk":"1149970967","pt":1439926836996,"mc":[{"id":"1.120089104","rc":[{"atl":[[7.2,47.2]],"id":9480385}],"con":true,"img":false,"tv":67900.02}]}
{"op":"mcm","clk":"1149971240","pt":1439926839813,"mc":[{"id":"1.120089104","rc":[{"atb":[[5.8,8.13]],"id":9480385}],"con":true,"img":false,"tv":67900.02}]}
{"op":"mcm","clk":"1149971253","pt":1439926839927,"mc":[{"id":"1.120089104","rc":[{"atb":[[5.7,44]],"id":9480385}],"con":true,"img":false,"tv":67900.02}]}
{"op":"mcm","clk":"1149971736","pt":1439926845247,"mc":[{"id":"1.120089104","rc":[{"atb":[[5.9,0]],"id":9480385}],"con":true,"img":false,"tv":67900.02}]}
{"op":"mcm","clk":"1149971746","pt":1439926845371,"mc":[{"id":"1.120089104","rc":[{"atb":[[5.6,97.75]],"id":9480385}],"con":true,"img":false,"tv":67900.02}]}
{"op":"mcm","clk":"1149972180","pt":1439926849860,"mc":[{"id":"1.120089104","rc":[{"spl":[[1.01,1123.48]],"id":9612932}],"con":true,"img":false,"tv":67900.02}]}
{"op":"mcm","clk":"1149972540","pt":1439926854197,"mc":[{"id":"1.120089104","rc":[{"spn":1.16,"spf":1.1,"id":9612932},{"atl":[[13.5,3]],"id":9480385},{"spn":6.8,"spf":5.54,"id":9480385}],"con":true,"img":false,"tv":67900.02}]}
{"op":"mcm","clk":"1149973140","pt":1439926860585,"mc":[{"id":"1.120089104","rc":[{"atb":[[1.16,5677.29]],"id":9612932}],"con":true,"img":false,"tv":67900.02}]}
{"op":"mcm","clk":"1149973901","pt":1439926868271,"mc":[{"id":"1.120089104","rc":[{"atb":[[1.15,14677.18]],"id":9612932}],"con":true,"img":false,"tv":67900.02}]}
{"op":"mcm","clk":"1149973956","pt":1439926868863,"mc":[{"id":"1.120089104","rc":[{"trd":[[1.17,21601.83]],"ltp":1.17,"tv":21601.83,"id":9612932},{"atl":[[1.17,1279.94]],"id":9612932}],"con":true,"img":false,"tv":68100.02}]}
{"op":"mcm","clk":"1149974624","pt":1439926875546,"mc":[{"id":"1.120089104","rc":[{"atl":[[9,17.89]],"id":9480385}],"con":true,"img":false,"tv":68100.02}]}
{"op":"mcm","clk":"1149974655","pt":1439926875972,"mc":[{"id":"1.120089104","rc":[{"atb":[[6,55.94]],"id":9480385}],"con":true,"img":false,"tv":68100.02}]}
{"op":"mcm","clk":"1149974659","pt":1439926876079,"mc":[{"id":"1.120089104","rc":[{"atb":[[5.6,116.97]],"id":9480385}],"con":true,"img":false,"tv":68100.02}]}
{"op":"mcm","clk":"1149975030","pt":1439926879992,"mc":[{"id":"1.120089104","rc":[{"atb":[[6,35.92]],"id":9480385}],"con":true,"img":false,"tv":68100.02}]}
{"op":"mcm","clk":"1149975039","pt":1439926880088,"mc":[{"id":"1.120089104","rc":[{"atb":[[5.6,136.98]],"id":9480385}],"con":true,"img":false,"tv":68100.02}]}
{"op":"mcm","clk":"1149976371","pt":1439926894120,"mc":[{"id":"1.120089104","rc":[{"trd":[[6.8,355.51]],"ltp":6.8,"tv":355.51,"id":9480385},{"atb":[[6.8,189.89]],"id":9480385}],"con":true,"img":false,"tv":68104.02}]}
{"op":"mcm","clk":"1149976884","pt":1439926899338,"mc":[{"id":"1.120089104","rc":[{"trd":[[1.17,21689.83]],"ltp":1.17,"tv":21689.83,"id":9612932},{"atl":[[1.17,1235.94]],"id":9612932}],"con":true,"img":false,"tv":68192.02}]}
{"op":"mcm","clk":"1149977085","pt":1439926901477,"mc":[{"id":"1.120089104","rc":[{"atb":[[1.16,5717.79]],"id":9612932}],"con":true,"img":false,"tv":68192.02}]}
{"op":"mcm","clk":"1149977899","pt":1439926909862,"mc":[{"id":"1.120089104","rc":[{"atl":[[1.21,0.82]],"id":9612932}],"con":true,"img":false,"tv":68192.02}]}
{"op":"mcm","clk":"1149978141","pt":1439926912696,"mc":[{"id":"1.120089104","rc":[{"atl":[[1.21,57.75]],"id":9612932}],"con":true,"img":false,"tv":68192.02}]}
{"op":"mcm","clk":"1149978203","pt":1439926913496,"mc":[{"id":"1.120089104","rc":[{"atb":[[1.02,10272]],"id":9612932},{"atb":[[1.02,10272]],"id":9480385}],"con":true,"img":false,"tv":68192.02}]}
{"op":"mcm","clk":"1149978437","pt":1439926916160,"mc":[{"id":"1.120089104","rc":[{"trd":[[1.17,21751.83]],"ltp":1.17,"tv":21751.83,"id":9612932},{"atl":[[1.17,1204.94]],"id":9612932}],"con":true,"img":false,"tv":68254.02}]}
{"op":"mcm","clk":"1149978604","pt":1439926917974,"mc":[{"id":"1.120089104","rc":[{"trd":[[1.17,21755.83]],"ltp":1.17,"tv":21755.83,"id":9612932},{"atl":[[1.17,1202.93]],"id":9612932}],"con":true,"img":false,"tv":68258.02}]}
{"op":"mcm","clk":"1149978945","pt":1439926921406,"mc":[{"id":"1.120089104","rc":[{"atl":[[11,3]],"id":9612932}],"con":true,"img":false,"tv":68258.02}]}
{"op":"mcm","clk":"1149979347","pt":1439926925581,"mc":[{"id":"1.120089104","rc":[{"trd":[[6.8,484.28]],"ltp":6.8,"tv":484.28,"id":9480385},{"atb":[[6.8,125.51]],"id":9480385}],"con":true,"img":false,"tv":68386.79}]}
{"op":"mcm","clk":"1149979380","pt":1439926925968,"mc":[{"id":"1.120089104","rc":[{"atl":[[7,12.24]],"id":9480385}],"con":true,"img":false,"tv":68386.79}]}
{"op":"mcm","clk":"1149979393","pt":1439926926167,"mc":[{"id":"1.120089104","rc":[{"atb":[[6.8,131.45]],"id":9480385}],"con":true,"img":false,"tv":68386.79}]}
{"op":"mcm","clk":"1149979454","pt":1439926926862,"mc":[{"id":"1.120089104","rc":[{"atl":[[8.8,5.54],[7.2,81.08]],"id":9480385}],"con":true,"img":false,"tv":68386.79}]}
{"op":"mcm","clk":"1149979468","pt":1439926926980,"mc":[{"id":"1.120089104","rc":[{"trd":[[6.8,489]],"ltp":6.8,"tv":489.0,"id":9480385},{"atb":[[6.8,129.09]],"id":9480385}],"con":true,"img":false,"tv":68391.51}]}
{"op":"mcm","clk":"1149979531","pt":1439926927773,"mc":[{"id":"1.120089104","rc":[{"trd":[[6.8,493.6]],"ltp":6.8,"tv":493.6,"id":9480385},{"atb":[[6.8,126.79]],"id":9480385}],"con":true,"img":false,"tv":68396.11}]}
{"op":"mcm","clk":"1149979650","pt":1439926929021,"mc":[{"id":"1.120089104","rc":[{"atb":[[1.16,5737.12]],"id":9612932}],"con":true,"img":false,"tv":68396.11}]}
{"op":"mcm","clk":"1149979670","pt":1439926929288,"mc":[{"id":"1.120089104","rc":[{"atb":[[6.8,130.09]],"id":9480385}],"con":true,"img":false,"tv":68396.11}]}
{"op":"mcm","clk":"1149981380","pt":1439926949685,"mc":[{"id":"1.120089104","rc":[{"trd":[[1.16,22378.78]],"ltp":1.16,"tv":22378.78,"id":9612932},{"atb":[[1.16,5637.12]],"id":9612932}],"con":true,"img":false,"tv":68596.11}]}
{"op":"mcm","clk":"1149982261","pt":1439926960482,"mc":[{"id":"1.120089104","rc":[{"atl":[[8.6,0]],"id":9480385}],"con":true,"img":false,"tv":68596.11}]}
{"op":"mcm","clk":"1149982269","pt":1439926960586,"mc":[{"id":"1.120089104","rc":[{"atl":[[8.4,30]],"id":9480385}],"con":true,"img":false,"tv":68596.11}]}
{"op":"mcm","clk":"1149982321","pt":1439926961312,"mc":[{"id":"1.120089104","rc":[{"atl":[[7,11.69]],"id":9480385}],"con":true,"img":false,"tv":68596.11}]}
{"op":"mcm","clk":"1149982471","pt":1439926963220,"mc":[{"id":"1.120089104","rc":[{"trd":[[1.17,21765.83]],"ltp":1.17,"tv":21765.83,"id":9612932},{"atl":[[1.17,1197.93]],"id":9612932}],"con":true,"img":false,"tv":68606.11}]}
{"op":"mcm","clk":"1149983720","pt":1439926979205,"mc":[{"id":"1.120089104","rc":[{"atb":[[2.7,2]],"id":9480385}],"con":true,"img":false,"tv":68606.11}]}
{"op":"mcm","clk":"1149984408","pt":1439926986984,"mc":[{"id":"1.120089104","rc":[{"atl":[[7,31.78]],"id":9480385}],"con":true,"img":false,"tv":68606.11}]}
{"op":"mcm","clk":"1149984455","pt":1439926987466,"mc":[{"id":"1.120089104","rc":[{"atl":[[7,58.62]],"id":9480385}],"con":true,"img":false,"tv":68606.11}]}
{"op":"mcm","clk":"1149984497","pt":1439926988002,"mc":[{"id":"1.120089104","rc":[{"atl":[[1.17,1112.98]],"id":9612932}],"con":true,"img":false,"tv":68606.11}]}
{"op":"mcm","clk":"1149984578","pt":1439926989125,"mc":[{"id":"1.120089104","rc":[{"atl":[[1.21,231.32]],"id":9612932}],"con":true,"img":false,"tv":68606.11}]}
{"op":"mcm","clk":"1149986082","pt":1439927007199,"mc":[{"id":"1.120089104","rc":[{"atl":[[1.2,911.41]],"id":9612932}],"con":true,"img":false,"tv":68606.11}]}
{"op":"mcm","clk":"1149986750","pt":1439927015860,"mc":[{"id":"1.120089104","rc":[{"atl":[[1.2,906.41]],"id":9612932}],"con":true,"img":false,"tv":68606.11}]}
{"op":"mcm","clk":"1149986752","pt":1439927015907,"mc":[{"id":"1.120089104","rc":[{"trd":[[1.16,22388.78]],"ltp":1.16,"tv":22388.78,"id":9612932},{"atb":[[1.16,5632.12]],"id":9612932}],"con":true,"img":false,"tv":68616.11}]}
{"op":"mcm","clk":"1149986766","pt":1439927016124,"mc":[{"id":"1.120089104","rc":[{"atb":[[1.15,14682.18]],"id":9612932}],"con":true,"img":false,"tv":68616.11}]}
{"op":"mcm","clk":"1149986900","pt":1439927018246,"mc":[{"id":"1.120089104","rc":[{"atb":[[1.15,14677.18]],"id":9612932}],"con":true,"img":false,"tv":68616.11}]}
{"op":"mcm","clk":"1149986910","pt":1439927018354,"mc":[{"id":"1.120089104","rc":[{"atb":[[1.16,5637.12]],"id":9612932}],"con":true,"img":false,"tv":68616.11}]}
{"op":"mcm","clk":"1149987321","pt":1439927023650,"mc":[{"id":"1.120089104","rc":[{"trd":[[6.8,499.6]],"ltp":6.8,"tv":499.6,"id":9480385},{"atb":[[6.8,127.09]],"id":9480385}],"con":true,"img":false,"tv":68622.11}]}
{"op":"mcm","clk":"1149987352","pt":1439927024136,"mc":[{"id":"1.120089104","rc":[{"trd":[[1.16,22528.78]],"ltp":1.16,"tv":22528.78,"id":9612932},{"atb":[[1.16,5567.12]],"id":9612932}],"con":true,"img":false,"tv":68762.11}]}
{"op":"mcm","clk":"1149987627","pt":1439927027521,"mc":[{"id":"1.120089104","rc":[{"trd":[[1.16,22550.78]],"ltp":1.16,"tv":22550.78,"id":9612932},{"atb":[[1.16,5556.12]],"id":9612932}],"con":true,"img":false,"tv":68784.11}]}
{"op":"mcm","clk":"1149987737","pt":1439927028800,"mc":[{"id":"1.120089104","rc":[{"trd":[[1.16,22590.78]],"ltp":1.16,"tv":22590.78,"id":9612932},{"atb":[[1.16,5536.12]],"id":9612932}],"con":true,"img":false,"tv":68824.11}]}
{"op":"mcm","clk":"1149988848","pt":1439927042906,"mc":[{"id":"1.120089104","rc":[{"atl":[[1000,9]],"id":9612932},{"atb":[[6.8,132.02],[1.01,2573.93]],"id":9480385}],"con":true,"img":false,"tv":68824.11}]}
{"op":"mcm","clk":"1149988854","pt":1439927043055,"mc":[{"id":"1.120089104","rc":[{"atl":[[1000,11.25]],"id":9612932},{"atb":[[1.01,2575.25]],"id":9480385}],"con":true,"img":false,"tv":68824.11}]}
{"op":"mcm","clk":"1149988864","pt":1439927043128,"mc":[{"id":"1.120089104","rc":[{"atl":[[1000,3.25]],"id":9612932},{"atb":[[1.01,2571.25]],"id":9480385}],"con":true,"img":false,"tv":68824.11}]}
{"op":"mcm","clk":"1149988872","pt":1439927043215,"mc":[{"id":"1.120089104","rc":[{"atl":[[1000,1]],"id":9612932},{"atb":[[1.01,2569.93]],"id":9480385}],"con":true,"img":false,"tv":68824.11}]}
{"op":"mcm","clk":"1149988878","pt":1439927043319,"mc":[{"id":"1.120089104","rc":[{"trd":[[1.16,22591.72]],"ltp":1.16,"tv":22591.72,"id":9612932},{"atb":[[1.16,5535.65]],"id":9612932},{"atl":[[1.17,1114.76]],"id":9612932},{"trd":[[7,249.48]],"ltp":7.0,"tv":249.48,"id":9480385},{"atl":[[7,57.3]],"id":9480385}],"con":true,"img":false,"tv":68827.69}]}
{"op":"mcm","clk":"1149988918","pt":1439927043905,"mc":[{"id":"1.120089104","rc":[{"atl":[[7,61.3]],"id":9480385}],"con":true,"img":false,"tv":68827.69}]}
{"op":"mcm","clk":"1149991317","pt":1439927073383,"mc":[{"id":"1.120089104","rc":[{"trd":[[1.17,21777.11]],"ltp":1.17,"tv":21777.11,"id":9612932},{"atl":[[1.17,1109.12]],"id":9612932}],"con":true,"img":false,"tv":68838.97}]}
{"op":"mcm","clk":"1149992144","pt":1439927082463,"mc":[{"id":"1.120089104","rc":[{"trd":[[6.8,511.02]],"ltp":6.8,"tv":511.02,"id":9480385},{"atb":[[6.8,126.31]],"id":9480385}],"con":true,"img":false,"tv":68850.39}]}
{"op":"mcm","clk":"1149992503","pt":1439927086620,"mc":[{"id":"1.120089104","rc":[{"trd":[[1.17,21875.75]],"ltp":1.17,"tv":21875.75,"id":9612932},{"atl":[[1.17,1059.8]],"id":9612932}],"con":true,"img":false,"tv":68949.03}]}
{"op":"mcm","clk":"1149993128","pt":1439927093908,"mc":[{"id":"1.120089104","rc":[{"trd":[[1.17,21895.75]],"ltp":1.17,"tv":21895.75,"id":9612932},{"atl":[[1.17,1049.8]],"id":9612932}],"con":true,"img":false,"tv":68969.03}]}
{"op":"mcm","clk":"1149994078","pt":1439927104110,"mc":[{"id":"1.120089104","rc":[{"trd":[[6.8,517.02]],"ltp":6.8,"tv":517.02,"id":9480385},{"atb":[[6.8,123.31]],"id":9480385}],"con":true,"img":false,"tv":68975.03}]}
{"op":"mcm","clk":"1149995674","pt":1439927122008,"mc":[{"id":"1.120089104","rc":[{"trd":[[1.17,22895.75]],"ltp":1.17,"tv":22895.75,"id":9612932},{"atl":[[1.17,549.8]],"id":9612932}],"con":true,"img":false,"tv":69975.03}]}
{"op":"mcm","clk":"1149996729","pt":1439927134169,"mc":[{"id":"1.120089104","rc":[{"atl":[[1.17,2.76]],"id":9612932}],"con":true,"img":false,"tv":69975.03}]}
{"op":"mcm","clk":"1149996749","pt":1439927134383,"mc":[{"id":"1.120089104","rc":[{"atb":[[6.8,87.25]],"id":9480385}],"con":true,"img":false,"tv":69975.03}]}
{"op":"mcm","clk":"1149996859","pt":1439927135508,"mc":[{"id":"1.120089104","rc":[{"atb":[[6,72.83]],"id":9480385}],"con":true,"img":false,"tv":69975.03}]}
{"op":"mcm","clk":"1149996923","pt":1439927136196,"mc":[{"id":"1.120089104","rc":[{"trd":[[1.17,22901.27]],"ltp":1.17,"tv":22901.27,"id":9612932},{"atl":[[1.17,0]],"id":9612932}],"con":true,"img":false,"tv":69980.54}]}
{"op":"mcm","clk":"1149996958","pt":1439927136472,"mc":[{"id":"1.120089104","rc":[{"atl":[[1.18,1816.4]],"id":9612932}],"con":true,"img":false,"tv":69980.54}]}
{"op":"mcm","clk":"1149996970","pt":1439927136578,"mc":[{"id":"1.120089104","rc":[{"trd":[[1.16,23991.72]],"ltp":1.16,"tv":23991.72,"id":9612932},{"atb":[[1.16,4835.65]],"id":9612932}],"con":true,"img":false,"tv":71380.54}]}
{"op":"mcm","clk":"1149997299","pt":1439927140097,"mc":[{"id":"1.120089104","rc":[{"atl":[[7,41.2]],"id":9480385}],"con":true,"img":false,"tv":71380.54}]}
{"op":"mcm","clk":"1149997743","pt":1439927145233,"mc":[{"id":"1.120089104","rc":[{"atb":[[1.17,25.45]],"id":9612932}],"con":true,"img":false,"tv":71380.54}]}
{"op":"mcm","clk":"1149997963","pt":1439927147700,"mc":[{"id":"1.120089104","rc":[{"trd":[[1.18,6914.83]],"ltp":1.18,"tv":6914.83,"id":9612932},{"atl":[[1.18,1798.8]],"id":9612932}],"con":true,"img":false,"tv":71415.74}]}
{"op":"mcm","clk":"1149998469","pt":1439927153358,"mc":[{"id":"1.120089104","rc":[{"trd":[[1.17,22924.47]],"ltp":1.17,"tv":22924.47,"id":9612932},{"atb":[[1.17,13.85]],"id":9612932}],"con":true,"img":false,"tv":71438.94}]}
{"op":"mcm","clk":"1149998689","pt":1439927155980,"mc":[{"id":"1.120089104","rc":[{"atb":[[1.16,4761.11]],"id":9612932}],"con":true,"img":false,"tv":71438.94}]}
{"op":"mcm","clk":"1149998698","pt":1439927156086,"mc":[{"id":"1.120089104","rc":[{"atb":[[1.17,88.38]],"id":9612932}],"con":true,"img":false,"tv":71438.94}]}
{"op":"mcm","clk":"1149998733","pt":1439927156526,"mc":[{"id":"1.120089104","rc":[{"atb":[[6.8,81.3]],"id":9480385}],"con":true,"img":false,"tv":71438.94}]}
{"op":"mcm","clk":"1149998834","pt":1439927157615,"mc":[{"id":"1.120089104","rc":[{"atb":[[5.5,62.64]],"id":9480385}],"con":true,"img":false,"tv":71438.94}]}
{"op":"mcm","clk":"1149999250","pt":1439927161837,"mc":[{"id":"1.120089104","rc":[{"atb":[[1.16,4764.64]],"id":9612932}],"con":true,"img":false,"tv":71438.94}]}
{"op":"mcm","clk":"1149999627","pt":1439927165892,"mc":[{"id":"1.120089104","rc":[{"spn":1.16,"spf":1.1,"id":9612932},{"trd":[[6.8,558.38]],"ltp":6.8,"tv":558.38,"id":9480385},{"atb":[[6.8,60.62]],"id":9480385}],"con":true,"img":false,"tv":71480.3}]}
{"op":"mcm","clk":"1150000341","pt":1439927174328,"mc":[{"id":"1.120089104","rc":[{"trd":[[1.17,23101.23]],"ltp":1.17,"tv":23101.23,"id":9612932},{"atb":[[1.17,0]],"id":9612932},{"atl":[[1.17,182.62]],"id":9612932}],"con":true,"img":false,"tv":71657.07}]}
{"op":"mcm","clk":"1150000755","pt":1439927179169,"mc":[{"id":"1.120089104","rc":[{"atl":[[1.18,1964.8]],"id":9612932}],"con":true,"img":false,"tv":71657.07}]}
{"op":"mcm","clk":"1150000798","pt":1439927179709,"mc":[{"id":"1.120089104","rc":[{"trd":[[1.17,23123.23]],"ltp":1.17,"tv":23123.23,"id":9612932},{"atl":[[1.17,171.62]],"id":9612932}],"con":true,"img":false,"tv":71679.07}]}
{"op":"mcm","clk":"1150000970","pt":1439927181852,"mc":[{"id":"1.120089104","rc":[{"trd":[[1.16,24991.72]],"ltp":1.16,"tv":24991.72,"id":9612932},{"atb":[[1.16,4264.63]],"id":9612932}],"con":true,"img":false,"tv":72679.07}]}
{"op":"mcm","clk":"1150001034","pt":1439927182613,"mc":[{"id":"1.120089104","rc":[{"atb":[[1.16,4419.8]],"id":9612932}],"con":true,"img":false,"tv":72679.07}]}
{"op":"mcm","clk":"1150001041","pt":1439927182719,"mc":[{"id":"1.120089104","rc":[{"atb":[[1.16,4455.44]],"id":9612932}],"con":true,"img":false,"tv":72679.07}]}
{"op":"mcm","clk":"1150002166","pt":1439927196233,"mc":[{"id":"1.120089104","rc":[{"atb":[[6.2,96.62]],"id":9480385}],"con":true,"img":false,"tv":72679.07}]}
{"op":"mcm","clk":"1150002177","pt":1439927196340,"mc":[{"id":"1.120089104","rc":[{"atb":[[6.8,77.5]],"id":9480385}],"con":true,"img":false,"tv":72679.07}]}
{"op":"mcm","clk":"1150002448","pt":1439927199553,"mc":[{"id":"1.120089104","rc":[{"atb":[[1.16,4437.22],[1.15,14622.03]],"id":9612932},{"atb":[[6,65.78]],"id":9480385}],"con":true,"img":false,"tv":72679.07}]}
{"op":"mcm","clk":"1150003029","pt":1439927206319,"mc":[{"id":"1.120089104","rc":[{"trd":[[1.16,25096.35]],"ltp":1.16,"tv":25096.35,"id":9612932},{"atb":[[1.16,4384.9]],"id":9612932}],"con":true,"img":false,"tv":72783.69}]}
{"op":"mcm","clk":"1150003133","pt":1439927207536,"mc":[{"id":"1.120089104","rc":[{"atb":[[1.16,4594.1]],"id":9612932}],"con":true,"img":false,"tv":72783.69}]}
{"op":"mcm","clk":"1150003486","pt":1439927211736,"mc":[{"id":"1.120089104","rc":[{"trd":[[1.17,23141.23]],"ltp":1.17,"tv":23141.23,"id":9612932},{"atl":[[1.17,162.62]],"id":9612932}],"con":true,"img":false,"tv":72801.69}]}
{"op":"mcm","clk":"1150003628","pt":1439927213441,"mc":[{"id":"1.120089104","rc":[{"trd":[[1.16,25296.35]],"ltp":1.16,"tv":25296.35,"id":9612932},{"atb":[[1.16,4494.1]],"id":9612932}],"con":true,"img":false,"tv":73001.69}]}
{"op":"mcm","clk":"1150005579","pt":1439927234978,"mc":[{"id":"1.120089104","rc":[{"atb":[[1.16,4490.58]],"id":9612932},{"spn":1.16,"spf":1.1,"id":9612932}],"con":true,"img":false,"tv":73001.69}]}
{"op":"mcm","clk":"1150005609","pt":1439927235352,"mc":[{"id":"1.120089104","rc":[{"trd":[[1.17,23161.41]],"ltp":1.17,"tv":23161.41,"id":9612932},{"atl":[[1.17,152.53]],"id":9612932}],"con":true,"img":false,"tv":73021.87}]}
{"op":"mcm","clk":"1150006028","pt":1439927239923,"mc":[{"id":"1.120089104","rc":[{"trd":[[1.17,23168.45]],"ltp":1.17,"tv":23168.45,"id":9612932},{"atl":[[1.17,149.01]],"id":9612932}],"con":true,"img":false,"tv":73028.92}]}
{"op":"mcm","clk":"1150006237","pt":1439927242127,"mc":[{"id":"1.120089104","rc":[{"trd":[[1.16,25396.35]],"ltp":1.16,"tv":25396.35,"id":9612932},{"atb":[[1.16,4440.58]],"id":9612932}],"con":true,"img":false,"tv":73128.92}]}
{"op":"mcm","clk":"1150007825","pt":1439927259081,"mc":[{"id":"1.120089104","rc":[{"trd":[[1.17,23240.76]],"ltp":1.17,"tv":23240.76,"id":9612932},{"atl":[[1.17,112.86]],"id":9612932}],"con":true,"img":false,"tv":73201.22}]}
{"op":"mcm","clk":"1150008883","pt":1439927269414,"mc":[{"id":"1.120089104","rc":[{"trd":[[1.17,23291.66]],"ltp":1.17,"tv":23291.66,"id":9612932},{"atl":[[1.17,87.41]],"id":9612932}],"con":true,"img":false,"tv":73252.12}]}
{"op":"mcm","clk":"1150011735","pt":1439927297584,"mc":[{"id":"1.120089104","rc":[{"trd":[[7,331.9]],"ltp":7.0,"tv":331.9,"id":9480385},{"atb":[[7,11.26]],"id":9480385},{"atl":[[7,0]],"id":9480385},{"spn":7.0,"spf":5.54,"id":9480385}],"con":true,"img":false,"tv":73334.54}]}
{"op":"mcm","clk":"1150011820","pt":1439927298496,"mc":[{"id":"1.120089104","rc":[{"atb":[[6.8,121.83]],"id":9480385}],"con":true,"img":false,"tv":73334.54}]}
{"op":"mcm","clk":"1150013018","pt":1439927310974,"mc":[{"id":"1.120089104","rc":[{"trd":[[7,335.9]],"ltp":7.0,"tv":335.9,"id":9480385},{"atb":[[7,9.26]],"id":9480385}],"con":true,"img":false,"tv":73338.54}]}
{"op":"mcm","clk":"1150013226","pt":1439927313237,"mc":[{"id":"1.120089104","rc":[{"atb":[[6.8,104.96]],"id":9480385}],"con":true,"img":false,"tv":73338.54}]}
{"op":"mcm","clk":"1150013230","pt":1439927313328,"mc":[{"id":"1.120089104","rc":[{"atb":[[7,26.13]],"id":9480385}],"con":true,"img":false,"tv":73338.54}]}
{"op":"mcm","clk":"1150013349","pt":1439927314531,"mc":[{"id":"1.120089104","rc":[{"atl":[[1.17,294.72]],"id":9612932}],"con":true,"img":false,"tv":73338.54}]}
{"op":"mcm","clk":"1150013648","pt":1439927317510,"mc":[{"id":"1.120089104","rc":[{"trd":[[1.16,25783.89]],"ltp":1.16,"tv":25783.89,"id":9612932},{"atb":[[1.16,4246.8]],"id":9612932}],"con":true,"img":false,"tv":73726.08}]}
{"op":"mcm","clk":"1150014801","pt":1439927329708,"mc":[{"id":"1.120089104","rc":[{"atb":[[5.6,58.52]],"id":9480385}],"con":true,"img":false,"tv":73726.08}]}
{"op":"mcm","clk":"1150014813","pt":1439927329813,"mc":[{"id":"1.120089104","rc":[{"atb":[[5.9,78.46]],"id":9480385}],"con":true,"img":false,"tv":73726.08}]}
{"op":"mcm","clk":"1150015018","pt":1439927331837,"mc":[{"id":"1.120089104","rc":[{"trd":[[1.17,23295.66]],"ltp":1.17,"tv":23295.66,"id":9612932},{"atl":[[1.17,292.72]],"id":9612932}],"con":true,"img":false,"tv":73730.08}]}
{"op":"mcm","clk":"1150016144","pt":1439927342495,"mc":[{"id":"1.120089104","rc":[{"atb":[[1.2,100]],"id":9480385}],"con":true,"img":false,"tv":73730.08}]}
{"op":"mcm","clk":"1150016190","pt":1439927342882,"mc":[{"id":"1.120089104","rc":[{"trd":[[1.17,23300.7]],"ltp":1.17,"tv":23300.7,"id":9612932},{"atl":[[1.17,290.2]],"id":9612932}],"con":true,"img":false,"tv":73735.12}]}
{"op":"mcm","clk":"1150016418","pt":1439927345312,"mc":[{"id":"1.120089104","rc":[{"atl":[[1.17,1401.2]],"id":9612932}],"con":true,"img":false,"tv":73735.12}]}
{"op":"mcm","clk":"1150016715","pt":1439927348161,"mc":[{"id":"1.120089104","rc":[{"atl":[[1.17,1420.37]],"id":9612932}],"con":true,"img":false,"tv":73735.12}]}
{"op":"mcm","clk":"1150017343","pt":1439927354419,"mc":[{"id":"1.120089104","rc":[{"trd":[[7,376.09]],"ltp":7.0,"tv":376.09,"id":9480385},{"atb":[[7,6.04]],"id":9480385}],"con":true,"img":false,"tv":73775.3}]}
{"op":"mcm","clk":"1150018008","pt":1439927361047,"mc":[{"id":"1.120089104","rc":[{"atl":[[1.17,1440.37]],"id":9612932}],"con":true,"img":false,"tv":73775.3}]}
{"op":"mcm","clk":"1150028162","pt":1439927372719,"mc":[{"id":"1.120089104","rc":[{"trd":[[1.17,23410.7]],"ltp":1.17,"tv":23410.7,"id":9612932},{"atl":[[1.17,1385.37]],"id":9612932}],"con":true,"img":false,"tv":73885.3}]}
{"op":"mcm","clk":"1150028381","pt":1439927374834,"mc":[{"id":"1.120089104","rc":[{"atb":[[5.6,45.23]],"id":9480385}],"con":true,"img":false,"tv":73885.3}]}
{"op":"mcm","clk":"1150028388","pt":1439927374945,"mc":[{"id":"1.120089104","rc":[{"atb":[[5.9,91.75]],"id":9480385}],"con":true,"img":false,"tv":73885.3}]}
{"op":"mcm","clk":"1150028461","pt":1439927375749,"mc":[{"id":"1.120089104","rc":[{"trd":[[1.17,23451.42]],"ltp":1.17,"tv":23451.42,"id":9612932},{"atl":[[1.17,1365.01]],"id":9612932}],"con":true,"img":false,"tv":73926.02}]}
{"op":"mcm","clk":"1150029049","pt":1439927381048,"mc":[{"id":"1.120089104","rc":[{"trd":[[7,384.09]],"ltp":7.0,"tv":384.09,"id":9480385},{"atb":[[7,2.04]],"id":9480385}],"con":true,"img":false,"tv":73934.02}]}
{"op":"mcm","clk":"1150029093","pt":1439927381519,"mc":[{"id":"1.120089104","rc":[{"atb":[[5.7,0]],"id":9480385},{"atl":[[8.4,0]],"id":9480385}],"con":true,"img":false,"tv":73934.02}]}
{"op":"mcm","clk":"1150029100","pt":1439927381626,"mc":[{"id":"1.120089104","rc":[{"atb":[[5.8,51.13]],"id":9480385},{"atl":[[8.6,29]],"id":9480385}],"con":true,"img":false,"tv":73934.02}]}
{"op":"mcm","clk":"1150030090","pt":1439927390695,"mc":[{"id":"1.120089104","rc":[{"atl":[[1.21,241.32]],"id":9612932}],"con":true,"img":false,"tv":73934.02}]}
{"op":"mcm","clk":"1150031007","pt":1439927399901,"mc":[{"id":"1.120089104","rc":[{"atb":[[7,13.04]],"id":9480385}],"con":true,"img":false,"tv":73934.02}]}
{"op":"mcm","clk":"1150031391","pt":1439927403232,"mc":[{"id":"1.120089104","rc":[{"atb":[[1.14,18227.45]],"id":9612932},{"atl":[[1000,9]],"id":9612932},{"atb":[[6.8,120.14],[1.01,2577.93]],"id":9480385}],"con":true,"img":false,"tv":73934.02}]}
{"op":"mcm","clk":"1150031400","pt":1439927403344,"mc":[{"id":"1.120089104","rc":[{"atl":[[1000,11.25]],"id":9612932},{"atb":[[1.01,2584.03]],"id":9480385}],"con":true,"img":false,"tv":73934.02}]}
{"op":"mcm","clk":"1150031405","pt":1439927403440,"mc":[{"id":"1.120089104","rc":[{"atb":[[1.09,935.72]],"id":9612932},{"atl":[[1000,3.25]],"id":9612932},{"atb":[[1.01,2576.03],[6.6,75.36]],"id":9480385}],"con":true,"img":false,"tv":73934.02}]}
{"op":"mcm","clk":"1150031417","pt":1439927403494,"mc":[{"id":"1.120089104","rc":[{"atl":[[1000,1]],"id":9612932},{"atb":[[1.01,2569.93]],"id":9480385}],"con":true,"img":false,"tv":73934.02}]}
{"op":"mcm","clk":"1150031426","pt":1439927403601,"mc":[{"id":"1.120089104","rc":[{"trd":[[1.16,25786.43]],"ltp":1.16,"tv":25786.43,"id":9612932},{"atb":[[1.16,4245.54]],"id":9612932},{"atl":[[1.17,1365.99]],"id":9612932},{"trd":[[7.2,197.59]],"ltp":7.2,"tv":197.59,"id":9480385},{"atb":[[7,15.69]],"id":9480385},{"atl":[[7.2,77.63]],"id":9480385}],"con":true,"img":false,"tv":73943.46}]}
{"op":"mcm","clk":"1150031436","pt":1439927403709,"mc":[{"id":"1.120089104","rc":[{"atb":[[1.13,15428.94]],"id":9612932}],"con":true,"img":false,"tv":73943.46}]}
{"op":"mcm","clk":"1150031458","pt":1439927403926,"mc":[{"id":"1.120089104","rc":[{"atb":[[5.6,39.23]],"id":9480385}],"con":true,"img":false,"tv":73943.46}]}
{"op":"mcm","clk":"1150031469","pt":1439927404035,"mc":[{"id":"1.120089104","rc":[{"atb":[[6.4,151.26]],"id":9480385}],"con":true,"img":false,"tv":73943.46}]}
{"op":"mcm","clk":"1150031483","pt":1439927404144,"mc":[{"id":"1.120089104","rc":[{"atl":[[8,35.15]],"id":9480385}],"con":true,"img":false,"tv":73943.46}]}
{"op":"mcm","clk":"1150031504","pt":1439927404312,"mc":[{"id":"1.120089104","rc":[{"atb":[[1.01,2593.93]],"id":9612932}],"con":true,"img":false,"tv":73943.46}]}
{"op":"mcm","clk":"1150031520","pt":1439927404422,"mc":[{"id":"1.120089104","rc":[{"atb":[[1.01,2593.98]],"id":9612932}],"con":true,"img":false,"tv":73943.46}]}
{"op":"mcm","clk":"1150031529","pt":1439927404548,"mc":[{"id":"1.120089104","rc":[{"atb":[[1.01,2593.93]],"id":9612932}],"con":true,"img":false,"tv":73943.46}]}
{"op":"mcm","clk":"1150031540","pt":1439927404640,"mc":[{"id":"1.120089104","rc":[{"trd":[[1.17,23451.52]],"ltp":1.17,"tv":23451.52,"id":9612932},{"atl":[[1.17,1365.94]],"id":9612932}],"con":true,"img":false,"tv":73943.56}]}
{"op":"mcm","clk":"1150031562","pt":1439927404859,"mc":[{"id":"1.120089104","rc":[{"atb":[[1.01,2571.93]],"id":9480385}],"con":true,"img":false,"tv":73943.56}]}
{"op":"mcm","clk":"1150031575","pt":1439927404914,"mc":[{"id":"1.120089104","rc":[{"atb":[[1.01,2572.69]],"id":9480385}],"con":true,"img":false,"tv":73943.56}]}
{"op":"mcm","clk":"1150031586","pt":1439927405021,"mc":[{"id":"1.120089104","rc":[{"atb":[[1.01,2571.93]],"id":9480385}],"con":true,"img":false,"tv":73943.56}]}
{"op":"mcm","clk":"1150031601","pt":1439927405131,"mc":[{"id":"1.120089104","rc":[{"trd":[[7.2,199.11]],"ltp":7.2,"tv":199.11,"id":9480385},{"atl":[[7.2,76.87]],"id":9480385}],"con":true,"img":false,"tv":73945.08}]}
{"op":"mcm","clk":"1150031824","pt":1439927407220,"mc":[{"id":"1.120089104","rc":[{"atl":[[7,2]],"id":9612932},{"trd":[[7,388.09]],"ltp":7.0,"tv":388.09,"id":9480385},{"atb":[[7,13.69]],"id":9480385}],"con":true,"img":false,"tv":73949.08}]}
{"op":"mcm","clk":"1150031840","pt":1439927407330,"mc":[{"id":"1.120089104","rc":[{"atl":[[1000,2]],"id":9480385}],"con":true,"img":false,"tv":73949.08}]}
{"op":"mcm","clk":"1150031854","pt":1439927407493,"mc":[{"id":"1.120089104","rc":[{"atl":[[1000,1.25]],"id":9480385}],"con":true,"img":false,"tv":73949.08}]}
{"op":"mcm","clk":"1150031873","pt":1439927407612,"mc":[{"id":"1.120089104","rc":[{"atl":[[1000,0]],"id":9480385}],"con":true,"img":false,"tv":73949.08}]}
{"op":"mcm","clk":"1150031878","pt":1439927407710,"mc":[{"id":"1.120089104","rc":[{"trd":[[7,390.59]],"ltp":7.0,"tv":390.59,"id":9480385},{"atb":[[7,12.44]],"id":9480385}],"con":true,"img":false,"tv":73951.59}]}
{"op":"mcm","clk":"1150032086","pt":1439927409636,"mc":[{"id":"1.120089104","rc":[{"atb":[[1.08,25.5]],"id":9612932}],"con":true,"img":false,"tv":73951.59}]}
{"op":"mcm","clk":"1150032111","pt":1439927409909,"mc":[{"id":"1.120089104","rc":[{"atb":[[1.08,29.02]],"id":9612932}],"con":true,"img":false,"tv":73951.59}]}
{"op":"mcm","clk":"1150032224","pt":1439927410979,"mc":[{"id":"1.120089104","rc":[{"atb":[[1.08,21.97]],"id":9612932}],"con":true,"img":false,"tv":73951.59}]}
{"op":"mcm","clk":"1150032232","pt":1439927411069,"mc":[{"id":"1.120089104","rc":[{"atb":[[1.07,7.04]],"id":9612932}],"con":true,"img":false,"tv":73951.59}]}
{"op":"mcm","clk":"1150032348","pt":1439927412061,"mc":[{"id":"1.120089104","rc":[{"atb":[[1.07,0]],"id":9612932}],"con":true,"img":false,"tv":73951.59}]}
{"op":"mcm","clk":"1150032677","pt":1439927414822,"mc":[{"id":"1.120089104","rc":[{"atb":[[1.16,5357.54]],"id":9612932}],"con":true,"img":false,"tv":73951.59}]}
{"op":"mcm","clk":"1150032809","pt":1439927415984,"mc":[{"id":"1.120089104","rc":[{"atb":[[1.06,78.71]],"id":9612932}],"con":true,"img":false,"tv":73951.59}]}
{"op":"mcm","clk":"1150032830","pt":1439927416203,"mc":[{"id":"1.120089104","rc":[{"atb":[[1.06,137.43]],"id":9612932}],"con":true,"img":false,"tv":73951.59}]}
{"op":"mcm","clk":"1150032923","pt":1439927416999,"mc":[{"id":"1.120089104","rc":[{"atb":[[1.11,26624.87]],"id":9612932}],"con":true,"img":false,"tv":73951.59}]}
{"op":"mcm","clk":"1150032948","pt":1439927417218,"mc":[{"id":"1.120089104","rc":[{"atb":[[5.6,20.01]],"id":9480385}],"con":true,"img":false,"tv":73951.59}]}
{"op":"mcm","clk":"1150033061","pt":1439927418126,"mc":[{"id":"1.120089104","rc":[{"atb":[[1.06,20]],"id":9612932}],"con":true,"img":false,"tv":73951.59}]}
{"op":"mcm","clk":"1150033326","pt":1439927420465,"mc":[{"id":"1.120089104","rc":[{"atb":[[1.01,2595.93]],"id":9612932}],"con":true,"img":false,"tv":73951.59}]}
{"op":"mcm","clk":"1150033332","pt":1439927420555,"mc":[{"id":"1.120089104","rc":[{"atb":[[1.01,2593.95]],"id":9612932}],"con":true,"img":false,"tv":73951.59}]}
{"op":"mcm","clk":"1150033341","pt":1439927420665,"mc":[{"id":"1.120089104","rc":[{"atb":[[1.01,2593.93]],"id":9612932}],"con":true,"img":false,"tv":73951.59}]}
{"op":"mcm","clk":"1150033359","pt":1439927420745,"mc":[{"id":"1.120089104","rc":[{"trd":[[1.17,23451.56]],"ltp":1.17,"tv":23451.56,"id":9612932},{"atl":[[1.17,1365.92]],"id":9612932}],"con":true,"img":false,"tv":73951.63}]}
{"op":"mcm","clk":"1150033547","pt":1439927422655,"mc":[{"id":"1.120089104","rc":[{"atb":[[1.16,5458.35]],"id":9612932}],"con":true,"img":false,"tv":73951.63}]}
{"op":"mcm","clk":"1150033631","pt":1439927423361,"mc":[{"id":"1.120089104","rc":[{"atb":[[1.08,66.01]],"id":9612932}],"con":true,"img":false,"tv":73951.63}]}
{"op":"mcm","clk":"1150033664","pt":1439927423689,"mc":[{"id":"1.120089104","rc":[{"atb":[[1.08,110.04]],"id":9612932}],"con":true,"img":false,"tv":73951.63}]}
{"op":"mcm","clk":"1150033733","pt":1439927424295,"mc":[{"id":"1.120089104","rc":[{"atb":[[1.11,25824.17]],"id":9612932}],"con":true,"img":false,"tv":73951.63}]}
{"op":"mcm","clk":"1150033790","pt":1439927424814,"mc":[{"id":"1.120089104","rc":[{"atb":[[5.6,0]],"id":9480385}],"con":true,"img":false,"tv":73951.63}]}
{"op":"mcm","clk":"1150033928","pt":1439927426013,"mc":[{"id":"1.120089104","rc":[{"atb":[[1.08,21.97]],"id":9612932}],"con":true,"img":false,"tv":73951.63}]}
{"op":"mcm","clk":"1150034303","pt":1439927429398,"mc":[{"id":"1.120089104","rc":[{"atb":[[1.03,135.43]],"id":9612932}],"con":true,"img":false,"tv":73951.63}]}
{"op":"mcm","clk":"1150034330","pt":1439927429567,"mc":[{"id":"1.120089104","rc":[{"atb":[[1.03,252.86]],"id":9612932}],"con":true,"img":false,"tv":73951.63}]}
{"op":"mcm","clk":"1150034508","pt":1439927431372,"mc":[{"id":"1.120089104","rc":[{"atb":[[1.03,18]],"id":9612932}],"con":true,"img":false,"tv":73951.63}]}
{"op":"mcm","clk":"1150034642","pt":1439927432601,"mc":[{"id":"1.120089104","rc":[{"atb":[[1.05,70.45]],"id":9612932}],"con":true,"img":false,"tv":73951.63}]}
{"op":"mcm","clk":"1150034669","pt":1439927432823,"mc":[{"id":"1.120089104","rc":[{"atb":[[1.05,140.91]],"id":9612932}],"con":true,"img":false,"tv":73951.63}]}
{"op":"mcm","clk":"1150034860","pt":1439927434523,"mc":[{"id":"1.120089104","rc":[{"atb":[[1.05,0]],"id":9612932}],"con":true,"img":false,"tv":73951.63}]}
{"op":"mcm","clk":"1150035206","pt":1439927437142,"mc":[{"id":"1.120089104","rc":[{"trd":[[1.17,23457.56]],"ltp":1.17,"tv":23457.56,"id":9612932},{"atl":[[1.17,1362.92]],"id":9612932}],"con":true,"img":false,"tv":73957.63}]}
{"op":"mcm","clk":"1150035551","pt":1439927440197,"mc":[{"id":"1.120089104","rc":[{"atl":[[1.36,12]],"id":9612932}],"con":true,"img":false,"tv":73957.63}]}
{"op":"mcm","clk":"1150035566","pt":1439927440310,"mc":[{"id":"1.120089104","rc":[{"atb":[[1.01,2605.93]],"id":9612932},{"atb":[[4.6,12.11]],"id":9480385},{"atl":[[12.5,12]],"id":9480385}],"con":true,"img":false,"tv":73957.63}]}
{"op":"mcm","clk":"1150035903","pt":1439927442943,"mc":[{"id":"1.120089104","rc":[{"atl":[[1.17,2278.92]],"id":9612932}],"con":true,"img":false,"tv":73957.63}]}
{"op":"mcm","clk":"1150035915","pt":1439927443028,"mc":[{"id":"1.120089104","rc":[{"atb":[[6.2,40.25]],"id":9480385}],"con":true,"img":false,"tv":73957.63}]}
{"op":"mcm","clk":"1150035925","pt":1439927443118,"mc":[{"id":"1.120089104","rc":[{"trd":[[1.16,25790.43]],"ltp":1.16,"tv":25790.43,"id":9612932},{"atb":[[1.16,5456.35]],"id":9612932}],"con":true,"img":false,"tv":73961.63}]}
{"op":"mcm","clk":"1150035949","pt":1439927443329,"mc":[{"id":"1.120089104","rc":[{"trd":[[1.17,23575.56]],"ltp":1.17,"tv":23575.56,"id":9612932},{"atl":[[1.17,2219.93]],"id":9612932}],"con":true,"img":false,"tv":74079.62}]}
{"op":"mcm","clk":"1150036322","pt":1439927446578,"mc":[{"id":"1.120089104","rc":[{"atb":[[6.2,56.93]],"id":9480385}],"con":true,"img":false,"tv":74079.62}]}
{"op":"mcm","clk":"1150037748","pt":1439927459110,"mc":[{"id":"1.120089104","rc":[{"trd":[[1.16,25890.43]],"ltp":1.16,"tv":25890.43,"id":9612932},{"atb":[[1.16,5406.35]],"id":9612932}],"con":true,"img":false,"tv":74179.62}]}
{"op":"mcm","clk":"1150038349","pt":1439927464073,"mc":[{"id":"1.120089104","rc":[{"atb":[[5.5,61.23]],"id":9480385}],"con":true,"img":false,"tv":74179.62}]}
{"op":"mcm","clk":"1150038382","pt":1439927464346,"mc":[{"id":"1.120089104","rc":[{"atb":[[4.9,35.23],[5.5,96.47]],"id":9480385}],"con":true,"img":false,"tv":74179.62}]}
{"op":"mcm","clk":"1150038811","pt":1439927468234,"mc":[{"id":"1.120089104","rc":[{"atl":[[1000,2.55]],"id":9480385}],"con":true,"img":false,"tv":74179.62}]}
{"op":"mcm","clk":"1150038839","pt":1439927468492,"mc":[{"id":"1.120089104","rc":[{"atl":[[1000,0]],"id":9480385}],"con":true,"img":false,"tv":74179.62}]}
{"op":"mcm","clk":"1150038864","pt":1439927468882,"mc":[{"id":"1.120089104","rc":[{"atl":[[1000,0]],"id":9480385}],"con":true,"img":false,"tv":74179.62}]}
{"op":"mcm","clk":"1150038870","pt":1439927468920,"mc":[{"id":"1.120089104","rc":[{"trd":[[7,390.61]],"ltp":7.0,"tv":390.61,"id":9480385},{"atb":[[7,12.43]],"id":9480385}],"con":true,"img":false,"tv":74179.64}]}
{"op":"mcm","clk":"1150039020","pt":1439927470201,"mc":[{"id":"1.120089104","rc":[{"trd":[[1.17,23975.55]],"ltp":1.17,"tv":23975.55,"id":9612932},{"atl":[[1.17,2019.93]],"id":9612932}],"con":true,"img":false,"tv":74579.64}]}
{"op":"mcm","clk":"1150039080","pt":1439927470748,"mc":[{"id":"1.120089104","rc":[{"atl":[[1.17,2218.52]],"id":9612932}],"con":true,"img":false,"tv":74579.64}]}
{"op":"mcm","clk":"1150039565","pt":1439927475415,"mc":[{"id":"1.120089104","marketDefinition":{"bspMarket":true,"turnInPlayEnabled":true,"persistenceEnabled":true,"marketBaseRate":5.0,"eventId":"27514783","eventTypeId":"7","numberOfWinners":1,"bettingType":"ODDS","marketType":"WIN","marketTime":"2015-08-18T20:20:00.000Z","suspendTime":"2015-08-18T20:20:00.000Z","bspReconciled":false,"complete":true,"inPlay":false,"crossMatching":true,"runnersVoidable":false,"numberOfActiveRunners":2,"betDelay":0,"status":"OPEN","runners":[{"adjustmentFactor":79.72,"status":"ACTIVE","sortPriority":1,"id":9612932,"name":"Alinstante"},{"adjustmentFactor":20.27,"status":"ACTIVE","sortPriority":2,"id":9480385,"name":"Vallance Road"}],"regulators":["MR_NJ","MR_INT"],"venue":"Chelmsford City","countryCode":"GB","discountAllowed":true,"timezone":"Europe/London","openDate":"2015-08-18T17:20:00.000Z","version":1061915291,"name":"1m Cond Stks","eventName":"ChelmC 18th Aug"},"rc":[],"con":true,"img":false,"tv":74579.64}]}
{"op":"mcm","clk":"1150039603","pt":1439927475704,"mc":[{"id":"1.120089104","rc":[{"atb":[[7,17.78]],"id":9480385},{"atl":[[7.2,82.07]],"id":9480385}],"con":true,"img":false,"tv":74579.64}]}
{"op":"mcm","clk":"1150039612","pt":1439927475820,"mc":[{"id":"1.120089104","rc":[{"atl":[[7.2,88.07]],"id":9480385}],"con":true,"img":false,"tv":74579.64}]}
{"op":"mcm","clk":"1150040018","pt":1439927479793,"mc":[{"id":"1.120089104","rc":[{"atl":[[1000,2.55]],"id":9480385}],"con":true,"img":false,"tv":74579.64}]}
{"op":"mcm","clk":"1150040041","pt":1439927480071,"mc":[{"id":"1.120089104","rc":[{"atl":[[1000,0]],"id":9480385}],"con":true,"img":false,"tv":74579.64}]}
{"op":"mcm","clk":"1150040077","pt":1439927480395,"mc":[{"id":"1.120089104","rc":[{"atl":[[1000,0]],"id":9480385}],"con":true,"img":false,"tv":74579.64}]}
{"op":"mcm","clk":"1150040091","pt":1439927480535,"mc":[{"id":"1.120089104","rc":[{"trd":[[7,390.62]],"ltp":7.0,"tv":390.62,"id":9480385},{"atb":[[7,17.77]],"id":9480385}],"con":true,"img":false,"tv":74579.65}]}
{"op":"mcm","clk":"1150041274","pt":1439927491973,"mc":[{"id":"1.120089104","rc":[{"trd":[[1.17,23995.55]],"ltp":1.17,"tv":23995.55,"id":9612932},{"atl":[[1.17,2208.52]],"id":9612932}],"con":true,"img":false,"tv":74599.65}]}
{"op":"mcm","clk":"1150041397","pt":1439927493180,"mc":[{"id":"1.120089104","rc":[{"trd":[[1.17,24015.93]],"ltp":1.17,"tv":24015.93,"id":9612932},{"atl":[[1.17,2198.33]],"id":9612932}],"con":true,"img":false,"tv":74620.03}]}
{"op":"mcm","clk":"1150041536","pt":1439927494501,"mc":[{"id":"1.120089104","rc":[{"trd":[[1.17,24079.99]],"ltp":1.17,"tv":24079.99,"id":9612932},{"atl":[[1.17,2166.3]],"id":9612932}],"con":true,"img":false,"tv":74684.09}]}
{"op":"mcm","clk":"1150041585","pt":1439927494991,"mc":[{"id":"1.120089104","rc":[{"trd":[[1.17,24139.99]],"ltp":1.17,"tv":24139.99,"id":9612932},{"atl":[[1.17,2136.3]],"id":9612932}],"con":true,"img":false,"tv":74744.09}]}
{"op":"mcm","clk":"1150042131","pt":1439927500211,"mc":[{"id":"1.120089104","rc":[{"trd":[[1.17,24159.99]],"ltp":1.17,"tv":24159.99,"id":9612932},{"atl":[[1.17,2126.3]],"id":9612932}],"con":true,"img":false,"tv":74764.09}]}
{"op":"mcm","clk":"1150044831","pt":1439927524697,"mc":[{"id":"1.120089104","rc":[{"trd":[[1.16,25990.43]],"ltp":1.16,"tv":25990.43,"id":9612932},{"atb":[[1.16,5356.35]],"id":9612932}],"con":true,"img":false,"tv":74864.09}]}
{"op":"mcm","clk":"1150045402","pt":1439927529348,"mc":[{"id":"1.120089104","rc":[{"atb":[[1.07,2]],"id":9612932}],"con":true,"img":false,"tv":74864.09}]}
{"op":"mcm","clk":"1150045464","pt":1439927529961,"mc":[{"id":"1.120089104","rc":[{"trd":[[7,426.16]],"ltp":7.0,"tv":426.16,"id":9480385},{"atb":[[7,0]],"id":9480385},{"atl":[[7,2.32]],"id":9480385}],"con":true,"img":false,"tv":74899.63}]}
{"op":"mcm","clk":"1150045510","pt":1439927530342,"mc":[{"id":"1.120089104","rc":[{"atl":[[7.2,82.07]],"id":9480385}],"con":true,"img":false,"tv":74899.63}]}
{"op":"mcm","clk":"1150045573","pt":1439927530979,"mc":[{"id":"1.120089104","rc":[{"atb":[[6.8,131.43]],"id":9480385}],"con":true,"img":false,"tv":74899.63}]}
{"op":"mcm","clk":"1150045601","pt":1439927531174,"mc":[{"id":"1.120089104","rc":[{"atb":[[6.6,91.08]],"id":9480385}],"con":true,"img":false,"tv":74899.63}]}
{"op":"mcm","clk":"1150045616","pt":1439927531291,"mc":[{"id":"1.120089104","rc":[{"atb":[[6.6,78.5]],"id":9480385}],"con":true,"img":false,"tv":74899.63}]}
{"op":"mcm","clk":"1150045630","pt":1439927531454,"mc":[{"id":"1.120089104","rc":[{"atb":[[6.4,164.31]],"id":9480385}],"con":true,"img":false,"tv":74899.63}]}
{"op":"mcm","clk":"1150045852","pt":1439927533041,"mc":[{"id":"1.120089104","rc":[{"atb":[[5.9,13.28]],"id":9480385}],"con":true,"img":false,"tv":74899.63}]}
{"op":"mcm","clk":"1150045867","pt":1439927533174,"mc":[{"id":"1.120089104","rc":[{"atb":[[5.6,78.46]],"id":9480385}],"con":true,"img":false,"tv":74899.63}]}
{"op":"mcm","clk":"1150046529","pt":1439927539142,"mc":[{"id":"1.120089104","rc":[{"atb":[[6.8,132.83]],"id":9480385}],"con":true,"img":false,"tv":74899.63}]}
{"op":"mcm","clk":"1150046909","pt":1439927542661,"mc":[{"id":"1.120089104","rc":[{"atb":[[1.14,19431.91]],"id":9612932},{"atb":[[6.4,195.54]],"id":9480385}],"con":true,"img":false,"tv":74899.63}]}
{"op":"mcm","clk":"1150047267","pt":1439927546319,"mc":[{"id":"1.120089104","rc":[{"atb":[[1.07,0]],"id":9612932}],"con":true,"img":false,"tv":74899.63}]}
{"op":"mcm","clk":"1150047643","pt":1439927548866,"mc":[{"id":"1.120089104","rc":[{"atb":[[1.07,2]],"id":9612932}],"con":true,"img":false,"tv":74899.63}]}
{"op":"mcm","clk":"1150047977","pt":1439927551779,"mc":[{"id":"1.120089104","rc":[{"trd":[[6.8,562.38]],"ltp":6.8,"tv":562.38,"id":9480385},{"atb":[[6.8,130.83]],"id":9480385}],"con":true,"img":false,"tv":74903.63}]}
{"op":"mcm","clk":"1150048055","pt":1439927552597,"mc":[{"id":"1.120089104","rc":[{"trd":[[1.17,24487.53]],"ltp":1.17,"tv":24487.53,"id":9612932},{"atl":[[1.17,1962.53]],"id":9612932},{"spn":6.8,"spf":5.54,"id":9480385}],"con":true,"img":false,"tv":75231.17}]}
{"op":"mcm","clk":"1150048413","pt":1439927556540,"mc":[{"id":"1.120089104","rc":[{"atb":[[1.11,25292.49]],"id":9612932}],"con":true,"img":false,"tv":75231.17}]}
{"op":"mcm","clk":"1150048445","pt":1439927556910,"mc":[{"id":"1.120089104","rc":[{"atb":[[5.9,0]],"id":9480385}],"con":true,"img":false,"tv":75231.17}]}
{"op":"mcm","clk":"1150049051","pt":1439927562277,"mc":[{"id":"1.120089104","rc":[{"atb":[[5.8,8.13]],"id":9480385},{"atl":[[8.6,0]],"id":9480385}],"con":true,"img":false,"tv":75231.17}]}
{"op":"mcm","clk":"1150049062","pt":1439927562390,"mc":[{"id":"1.120089104","rc":[{"atb":[[5.7,44]],"id":9480385},{"atl":[[8.4,30]],"id":9480385}],"con":true,"img":false,"tv":75231.17}]}
{"op":"mcm","clk":"1150049966","pt":1439927570889,"mc":[{"id":"1.120089104","rc":[{"atl":[[7,0]],"id":9480385}],"con":true,"img":false,"tv":75231.17}]}
{"op":"mcm","clk":"1150049992","pt":1439927571055,"mc":[{"id":"1.120089104","rc":[{"atb":[[7,5.36]],"id":9480385},{"atl":[[7.2,87.28]],"id":9480385}],"con":true,"img":false,"tv":75231.17}]}
{"op":"mcm","clk":"1150050014","pt":1439927571273,"mc":[{"id":"1.120089104","rc":[{"atb":[[7,10.62]],"id":9480385},{"atl":[[7.2,92.39]],"id":9480385}],"con":true,"img":false,"tv":75231.17}]}
{"op":"mcm","clk":"1150050023","pt":1439927571382,"mc":[{"id":"1.120089104","rc":[{"atl":[[7.2,98.39]],"id":9480385}],"con":true,"img":false,"tv":75231.17}]}
{"op":"mcm","clk":"1150050097","pt":1439927571939,"mc":[{"id":"1.120089104","rc":[{"atb":[[6.8,146.02]],"id":9480385}],"con":true,"img":false,"tv":75231.17}]}
{"op":"mcm","clk":"1150050241","pt":1439927573274,"mc":[{"id":"1.120089104","rc":[{"atb":[[6.6,91.08]],"id":9480385}],"con":true,"img":false,"tv":75231.17}]}
{"op":"mcm","clk":"1150050294","pt":1439927573880,"mc":[{"id":"1.120089104","rc":[{"atb":[[5.6,0]],"id":9480385}],"con":true,"img":false,"tv":75231.17}]}
{"op":"mcm","clk":"1150050305","pt":1439927574017,"mc":[{"id":"1.120089104","rc":[{"atb":[[5.9,78.46]],"id":9480385}],"con":true,"img":false,"tv":75231.17}]}
{"op":"mcm","clk":"1150050586","pt":1439927576542,"mc":[{"id":"1.120089104","rc":[{"atb":[[1.16,5357.76]],"id":9612932}],"con":true,"img":false,"tv":75231.17}]}
{"op":"mcm","clk":"1150050653","pt":1439927577051,"mc":[{"id":"1.120089104","rc":[{"atb":[[1.15,15622.03]],"id":9612932}],"con":true,"img":false,"tv":75231.17}]}
{"op":"mcm","clk":"1150050682","pt":1439927577368,"mc":[{"id":"1.120089104","rc":[{"atb":[[1.15,16622.03]],"id":9612932}],"con":true,"img":false,"tv":75231.17}]}
{"op":"mcm","clk":"1150050738","pt":1439927577768,"mc":[{"id":"1.120089104","rc":[{"atb":[[1.16,5359.17]],"id":9612932}],"con":true,"img":false,"tv":75231.17}]}
{"op":"mcm","clk":"1150050741","pt":1439927577858,"mc":[{"id":"1.120089104","rc":[{"atb":[[1.14,20431.91]],"id":9612932}],"con":true,"img":false,"tv":75231.17}]}
{"op":"mcm","clk":"1150050770","pt":1439927578037,"mc":[{"id":"1.120089104","rc":[{"atb":[[1.14,21431.91]],"id":9612932}],"con":true,"img":false,"tv":75231.17}]}
{"op":"mcm","clk":"1150050813","pt":1439927578578,"mc":[{"id":"1.120089104","rc":[{"atb":[[1.13,16428.94]],"id":9612932}],"con":true,"img":false,"tv":75231.17}]}
{"op":"mcm","clk":"1150050835","pt":1439927578767,"mc":[{"id":"1.120089104","rc":[{"atb":[[1.13,17428.94]],"id":9612932}],"con":true,"img":false,"tv":75231.17}]}
{"op":"mcm","clk":"1150050896","pt":1439927579304,"mc":[{"id":"1.120089104","rc":[{"atb":[[1.12,17585.46]],"id":9612932}],"con":true,"img":false,"tv":75231.17}]}
{"op":"mcm","clk":"1150050917","pt":1439927579486,"mc":[{"id":"1.120089104","rc":[{"atb":[[1.12,18585.46]],"id":9612932}],"con":true,"img":false,"tv":75231.17}]}
{"op":"mcm","clk":"1150051092","pt":1439927580797,"mc":[{"id":"1.120089104","rc":[{"atl":[[1.18,2489.8]],"id":9612932}],"con":true,"img":false,"tv":75231.17}]}
{"op":"mcm","clk":"1150052120","pt":1439927589582,"mc":[{"id":"1.120089104","rc":[{"trd":[[1.17,24490.35]],"ltp":1.17,"tv":24490.35,"id":9612932},{"atl":[[1.17,1961.12]],"id":9612932}],"con":true,"img":false,"tv":75233.99}]}
{"op":"mcm","clk":"1150052430","pt":1439927592609,"mc":[{"id":"1.120089104","rc":[{"atl":[[1.18,1964.8]],"id":9612932}],"con":true,"img":false,"tv":75233.99}]}
{"op":"mcm","clk":"1150052437","pt":1439927592712,"mc":[{"id":"1.120089104","rc":[{"atl":[[1.2,1431.41]],"id":9612932}],"con":true,"img":false,"tv":75233.99}]}
{"op":"mcm","clk":"1150052596","pt":1439927594001,"mc":[{"id":"1.120089104","rc":[{"trd":[[1.17,24560.35]],"ltp":1.17,"tv":24560.35,"id":9612932},{"atl":[[1.17,1926.12]],"id":9612932}],"con":true,"img":false,"tv":75303.99}]}
{"op":"mcm","clk":"1150052686","pt":1439927594538,"mc":[{"id":"1.120089104","rc":[{"trd":[[1.17,24563.17]],"ltp":1.17,"tv":24563.17,"id":9612932},{"atl":[[1.17,1924.71]],"id":9612932}],"con":true,"img":false,"tv":75306.81}]}
{"op":"mcm","clk":"1150052914","pt":1439927597113,"mc":[{"id":"1.120089104","rc":[{"trd":[[1.17,24565.99]],"ltp":1.17,"tv":24565.99,"id":9612932},{"atl":[[1.17,1923.3]],"id":9612932}],"con":true,"img":false,"tv":75309.63}]}
{"op":"mcm","clk":"1150053027","pt":1439927598124,"mc":[{"id":"1.120089104","rc":[{"trd":[[1.17,24720.23]],"ltp":1.17,"tv":24720.23,"id":9612932},{"atl":[[1.17,1846.18]],"id":9612932}],"con":true,"img":false,"tv":75463.87}]}
{"op":"mcm","clk":"1150053212","pt":1439927599570,"mc":[{"id":"1.120089104","rc":[{"trd":[[1.17,24723.05]],"ltp":1.17,"tv":24723.05,"id":9612932},{"atl":[[1.17,1844.77]],"id":9612932}],"con":true,"img":false,"tv":75466.69}]}
{"op":"mcm","clk":"1150053559","pt":1439927602918,"mc":[{"id":"1.120089104","rc":[{"atb":[[6.8,144.61]],"id":9480385}],"con":true,"img":false,"tv":75466.69}]}
{"op":"mcm","clk":"1150053569","pt":1439927603024,"mc":[{"id":"1.120089104","rc":[{"atb":[[7,12.02]],"id":9480385}],"con":true,"img":false,"tv":75466.69}]}
{"op":"mcm","clk":"1150054166","pt":1439927608669,"mc":[{"id":"1.120089104","rc":[{"trd":[[1.16,26292.73]],"ltp":1.16,"tv":26292.73,"id":9612932},{"atb":[[1.16,5208.02]],"id":9612932}],"con":true,"img":false,"tv":75768.98}]}
{"op":"mcm","clk":"1150054388","pt":1439927610444,"mc":[{"id":"1.120089104","rc":[{"atl":[[1.24,1026.48]],"id":9612932}],"con":true,"img":false,"tv":75768.98}]}
{"op":"mcm","clk":"1150055735","pt":1439927622836,"mc":[{"id":"1.120089104","rc":[{"atb":[[5.7,0]],"id":9480385},{"atl":[[8.4,0]],"id":9480385},{"spn":7.0,"spf":5.54,"id":9480385}],"con":true,"img":false,"tv":75768.98}]}
{"op":"mcm","clk":"1150055760","pt":1439927623060,"mc":[{"id":"1.120089104","rc":[{"atb":[[5.8,51.13]],"id":9480385},{"atl":[[8.6,29]],"id":9480385}],"con":true,"img":false,"tv":75768.98}]}
{"op":"mcm","clk":"1150055995","pt":1439927625106,"mc":[{"id":"1.120089104","rc":[{"atb":[[1.01,2607.93]],"id":9612932}],"con":true,"img":false,"tv":75768.98}]}
{"op":"mcm","clk":"1150056004","pt":1439927625304,"mc":[{"id":"1.120089104","rc":[{"atb":[[1.01,2606.93]],"id":9612932}],"con":true,"img":false,"tv":75768.98}]}
{"op":"mcm","clk":"1150056023","pt":1439927625418,"mc":[{"id":"1.120089104","rc":[{"atb":[[1.01,2605.93]],"id":9612932}],"con":true,"img":false,"tv":75768.98}]}
{"op":"mcm","clk":"1150056029","pt":1439927625475,"mc":[{"id":"1.120089104","rc":[{"trd":[[1.17,24725.05]],"ltp":1.17,"tv":24725.05,"id":9612932},{"atl":[[1.17,1843.77]],"id":9612932}],"con":true,"img":false,"tv":75770.98}]}
{"op":"mcm","clk":"1150056396","pt":1439927628836,"mc":[{"id":"1.120089104","rc":[{"trd":[[1.17,24730.01]],"ltp":1.17,"tv":24730.01,"id":9612932},{"atl":[[1.17,1841.29]],"id":9612932}],"con":true,"img":false,"tv":75775.94}]}
{"op":"mcm","clk":"1150056753","pt":1439927631864,"mc":[{"id":"1.120089104","rc":[{"trd":[[1.17,24833.59]],"ltp":1.17,"tv":24833.59,"id":9612932},{"atl":[[1.17,1789.5]],"id":9612932}],"con":true,"img":false,"tv":75879.52}]}
{"op":"mcm","clk":"1150056863","pt":1439927632877,"mc":[{"id":"1.120089104","rc":[{"atb":[[1.16,5833.02]],"id":9612932}],"con":true,"img":false,"tv":75879.52}]}
{"op":"mcm","clk":"1150057557","pt":1439927639341,"mc":[{"id":"1.120089104","rc":[{"atl":[[1.19,1557.18]],"id":9612932}],"con":true,"img":false,"tv":75879.52}]}
{"op":"mcm","clk":"1150058383","pt":1439927647216,"mc":[{"id":"1.120089104","rc":[{"trd":[[1.17,24933.59]],"ltp":1.17,"tv":24933.59,"id":9612932},{"atl":[[1.17,1739.5]],"id":9612932}],"con":true,"img":false,"tv":76239.52}]}
{"op":"mcm","clk":"1150058874","pt":1439927651903,"mc":[{"id":"1.120089104","rc":[{"atb":[[1.16,6520.73]],"id":9612932}],"con":true,"img":false,"tv":76239.52}]}
{"op":"mcm","clk":"1150059028","pt":1439927653378,"mc":[{"id":"1.120089104","rc":[{"atb":[[1.16,7208.44]],"id":9612932}],"con":true,"img":false,"tv":76239.52}]}
{"op":"mcm","clk":"1150059267","pt":1439927655172,"mc":[{"id":"1.120089104","rc":[{"trd":[[1.17,25133.59]],"ltp":1.17,"tv":25133.59,"id":9612932},{"atl":[[1.17,1639.5]],"id":9612932}],"con":true,"img":false,"tv":76239.52}]}
{"op":"mcm","clk":"1150059406","pt":1439927656697,"mc":[{"id":"1.120089104","rc":[{"atb":[[1.16,7833.44]],"id":9612932}],"con":true,"img":false,"tv":84239.52}]}
