{"op":"mcm","clk":"1143716056","pt":1439811304600,"mc":[{"id":"1.120089104","marketDefinition":{"bspMarket":true,"turnInPlayEnabled":true,"persistenceEnabled":true,"marketBaseRate":5.0,"eventId":"27514783","eventTypeId":"7","numberOfWinners":1,"bettingType":"ODDS","marketType":"WIN","marketTime":"2015-08-18T20:20:00.000Z","suspendTime":"2015-08-18T20:20:00.000Z","bspReconciled":false,"complete":true,"inPlay":false,"crossMatching":false,"runnersVoidable":false,"numberOfActiveRunners":2,"betDelay":0,"status":"OPEN","runners":[{"adjustmentFactor":79.72,"status":"ACTIVE","sortPriority":1,"id":9612932,"name":"Alinstante"},{"adjustmentFactor":20.27,"status":"ACTIVE","sortPriority":2,"id":9480385,"name":"Vallance Road"}],"regulators":["MR_INT"],"venue":"Chelmsford City","countryCode":"GB","discountAllowed":false,"timezone":"Europe/London","openDate":"2015-08-18T17:20:00.000Z","version":1060767560,"name":"1m Cond Stks","eventName":"ChelmC 18th Aug"},"rc":[],"con":true,"img":false}]}
{"op":"mcm","clk":"1143716878","pt":1439811328317,"mc":[{"id":"1.120089104","rc":[{"atb":[[1.01,111.29]],"id":9612932},{"atb":[[1.01,111.29]],"id":9480385}],"con":true,"img":false}]}
{"op":"mcm","clk":"1143716883","pt":1439811328427,"mc":[{"id":"1.120089104","rc":[{"atb":[[1.01,132.58]],"id":9612932},{"atb":[[1.01,132.58]],"id":9480385}],"con":true,"img":false}]}
{"op":"mcm","clk":"1143716902","pt":1439811328907,"mc":[{"id":"1.120089104","rc":[{"atb":[[1.01,203.55]],"id":9612932},{"atb":[[1.01,203.55]],"id":9480385}],"con":true,"img":false}]}
{"op":"mcm","clk":"1143717212","pt":1439811336905,"mc":[{"id":"1.120089104","rc":[{"atb":[[1.01,223.55]],"id":9612932},{"atb":[[1.01,223.55]],"id":9480385}],"con":true,"img":false}]}
{"op":"mcm","clk":"1143717238","pt":1439811337645,"mc":[{"id":"1.120089104","rc":[{"atb":[[1.4,24.69]],"id":9612932},{"atb":[[1.81,12.35]],"id":9480385}],"con":true,"img":false}]}
{"op":"mcm","clk":"1143723058","pt":1439811510072,"mc":[{"id":"1.120089104","rc":[{"atb":[[1.01,473.55]],"id":9612932},{"spn":"Infinity","spf":"NaN","id":9612932},{"atb":[[1.01,473.55]],"id":9480385},{"spn":"Infinity","spf":"NaN","id":9480385}],"con":true,"img":false}]}
{"op":"mcm","clk":"1143723354","pt":1439811518200,"mc":[{"id":"1.120089104","rc":[{"atb":[[1.01,475.55]],"id":9612932},{"atb":[[1.01,475.55]],"id":9480385}],"con":true,"img":false}]}
{"op":"mcm","clk":"1143766881","pt":1439812416845,"mc":[{"id":"1.120089104","rc":[{"atl":[[1000,2]],"id":9612932},{"spn":500.7,"spf":"NaN","id":9612932},{"atl":[[1000,2]],"id":9480385},{"spn":500.9,"spf":"NaN","id":9480385}],"con":true,"img":false}]}
{"op":"mcm","clk":"1143767047","pt":1439812421108,"mc":[{"id":"1.120089104","rc":[{"atl":[[1000,0.09]],"id":9612932},{"atl":[[1000,0.09]],"id":9480385}],"con":true,"img":false}]}
{"op":"mcm","clk":"1143767048","pt":1439812421214,"mc":[{"id":"1.120089104","rc":[{"atl":[[1000,0]],"id":9612932},{"atl":[[1000,0]],"id":9480385}],"con":true,"img":false}]}
{"op":"mcm","clk":"1143767053","pt":1439812421321,"mc":[{"id":"1.120089104","rc":[{"atl":[[630,0.09]],"id":9612932},{"atl":[[630,0.09]],"id":9480385}],"con":true,"img":false}]}
{"op":"mcm","clk":"1143783246","pt":1439812843764,"mc":[{"id":"1.120089104","rc":[{"atb":[[1.08,10],[1.01,475.7]],"id":9612932},{"spn":315.7,"spf":"NaN","id":9612932},{"atb":[[1.08,10],[1.01,475.7]],"id":9480385},{"spn":315.9,"spf":"NaN","id":9480385}],"con":true,"img":false}]}
{"op":"mcm","clk":"1143859193","pt":1439814360577,"mc":[{"id":"1.120089104","rc":[{"atb":[[1.06,10]],"id":9612932},{"atb":[[1.06,10]],"id":9480385}],"con":true,"img":false}]}
{"op":"mcm","clk":"1143861969","pt":1439814429787,"mc":[{"id":"1.120089104","rc":[{"atb":[[2.22,12.07]],"id":9480385},{"spn":316.11,"spf":"NaN","id":9480385}],"con":true,"img":false}]}
{"op":"mcm","clk":"1143871533","pt":1439814686366,"mc":[{"id":"1.120089104","rc":[{"atb":[[1.01,477.12]],"id":9480385}],"con":true,"img":false,"tv":49.38}]}
{"op":"mcm","clk":"1143871542","pt":1439814686575,"mc":[{"id":"1.120089104","rc":[{"atb":[[1.01,477.11]],"id":9480385}],"con":true,"img":false,"tv":49.38}]}
{"op":"mcm","clk":"1143871553","pt":1439814686786,"mc":[{"id":"1.120089104","rc":[{"atb":[[1.01,475.7]],"id":9480385}],"con":true,"img":false,"tv":49.38}]}
{"op":"mcm","clk":"1143871560","pt":1439814686894,"mc":[{"id":"1.120089104","rc":[{"atb":[[2.24,1.41]],"id":9480385}],"con":true,"img":false,"tv":49.38}]}
{"op":"mcm","clk":"1143881666","pt":1439814864959,"mc":[{"id":"1.120089104","marketDefinition":{"bspMarket":true,"turnInPlayEnabled":true,"persistenceEnabled":true,"marketBaseRate":5.0,"eventId":"27514783","eventTypeId":"7","numberOfWinners":1,"bettingType":"ODDS","marketType":"WIN","marketTime":"2015-08-18T20:20:00.000Z","suspendTime":"2015-08-18T20:20:00.000Z","bspReconciled":false,"complete":true,"inPlay":false,"crossMatching":false,"runnersVoidable":false,"numberOfActiveRunners":2,"betDelay":0,"status":"OPEN","runners":[{"adjustmentFactor":79.72,"status":"ACTIVE","sortPriority":1,"id":9612932,"name":"Alinstante"},{"adjustmentFactor":20.27,"status":"ACTIVE","sortPriority":2,"id":9480385,"name":"Vallance Road"}],"regulators":["MR_INT"],"venue":"Chelmsford City","countryCode":"GB","discountAllowed":false,"timezone":"Europe/London","openDate":"2015-08-18T17:20:00.000Z","version":1060767560,"name":"1m Cond Stks","eventName":"ChelmC 18th Aug"},"rc":[{"atb":[[1.08,10],[1.06,10],[1.4,24.69],[1.01,475.7]],"id":9612932},{"atl":[[630,0.09]],"id":9612932},{"spn":315.7,"spf":"NaN","id":9612932},{"atb":[[2.24,1.41],[1.08,10],[2.22,12.07],[1.06,10],[1.81,12.35],[1.01,475.7]],"id":9480385},{"atl":[[630,0.09]],"id":9480385},{"spn":316.12,"spf":"NaN","id":9480385}],"con":true,"img":true,"tv":49.38}]}
{"op":"mcm","clk":"1143907024","pt":1439815367749,"mc":[{"id":"1.120089104","rc":[{"atb":[[1.01,477.7]],"id":9612932},{"spn":316.12,"spf":"NaN","id":9480385}],"con":true,"img":false,"tv":49.38}]}
{"op":"mcm","clk":"1143907196","pt":1439815371023,"mc":[{"id":"1.120089104","rc":[{"atb":[[1.01,479.69]],"id":9612932}],"con":true,"img":false,"tv":49.38}]}
{"op":"mcm","clk":"1143907392","pt":1439815375183,"mc":[{"id":"1.120089104","rc":[{"atb":[[1.01,477.7]],"id":9612932}],"con":true,"img":false,"tv":49.38}]}
{"op":"mcm","clk":"1143907399","pt":1439815375289,"mc":[{"id":"1.120089104","rc":[{"atb":[[1.02,1.99]],"id":9612932}],"con":true,"img":false,"tv":49.38}]}
{"op":"mcm","clk":"1143907595","pt":1439815378860,"mc":[{"id":"1.120089104","rc":[{"atb":[[1.01,477.7]],"id":9480385}],"con":true,"img":false,"tv":49.38}]}
{"op":"mcm","clk":"1143907741","pt":1439815381990,"mc":[{"id":"1.120089104","rc":[{"atb":[[1.01,479.69]],"id":9480385}],"con":true,"img":false,"tv":49.38}]}
{"op":"mcm","clk":"1143907982","pt":1439815386226,"mc":[{"id":"1.120089104","rc":[{"atb":[[1.01,477.7]],"id":9480385}],"con":true,"img":false,"tv":49.38}]}
{"op":"mcm","clk":"1143907984","pt":1439815386328,"mc":[{"id":"1.120089104","rc":[{"atb":[[1.02,1.99]],"id":9480385}],"con":true,"img":false,"tv":49.38}]}
{"op":"mcm","clk":"1143971969","pt":1439816578363,"mc":[{"id":"1.120089104","rc":[{"trd":[[1.4,49.38]],"ltp":1.4,"tv":49.38,"id":9612932},{"atb":[[1.4,0],[1.01,477.81]],"id":9612932},{"atl":[[1.4,0.31]],"id":9612932},{"spn":1.24,"spf":"NaN","id":9612932},{"atb":[[2.24,1.41],[2.22,12.08],[1.01,477.81]],"id":9480385}],"con":true,"img":false,"tv":49.38}]}
{"op":"mcm","clk":"1143985693","pt":1439816690797,"mc":[{"id":"1.120089104","rc":[{"atl":[[22,11]],"id":9612932}],"con":true,"img":false,"tv":49.38}]}
{"op":"mcm","clk":"1143985903","pt":1439816695885,"mc":[{"id":"1.120089104","rc":[{"atl":[[22,12.9]],"id":9612932}],"con":true,"img":false,"tv":49.38}]}
{"op":"mcm","clk":"1143986066","pt":1439816699054,"mc":[{"id":"1.120089104","rc":[{"atl":[[22,11]],"id":9612932}],"con":true,"img":false,"tv":49.38}]}
{"op":"mcm","clk":"1143986077","pt":1439816699163,"mc":[{"id":"1.120089104","rc":[{"atl":[[20,1.9]],"id":9612932}],"con":true,"img":false,"tv":49.38}]}
{"op":"mcm","clk":"1143986391","pt":1439816705764,"mc":[{"id":"1.120089104","rc":[{"atl":[[1.4,0]],"id":9612932}],"con":true,"img":false,"tv":49.38}]}
{"op":"mcm","clk":"1144030815","pt":1439817565003,"mc":[{"id":"1.120089104","marketDefinition":{"bspMarket":true,"turnInPlayEnabled":true,"persistenceEnabled":true,"marketBaseRate":5.0,"eventId":"27514783","eventTypeId":"7","numberOfWinners":1,"bettingType":"ODDS","marketType":"WIN","marketTime":"2015-08-18T20:20:00.000Z","suspendTime":"2015-08-18T20:20:00.000Z","bspReconciled":false,"complete":true,"inPlay":false,"crossMatching":false,"runnersVoidable":false,"numberOfActiveRunners":2,"betDelay":0,"status":"OPEN","runners":[{"adjustmentFactor":79.72,"status":"ACTIVE","sortPriority":1,"id":9612932,"name":"Alinstante"},{"adjustmentFactor":20.27,"status":"ACTIVE","sortPriority":2,"id":9480385,"name":"Vallance Road"}],"regulators":["MR_INT"],"venue":"Chelmsford City","countryCode":"GB","discountAllowed":false,"timezone":"Europe/London","openDate":"2015-08-18T17:20:00.000Z","version":1060767560,"name":"1m Cond Stks","eventName":"ChelmC 18th Aug"},"rc":[{"trd":[[1.4,49.38]],"ltp":1.4,"tv":49.38,"id":9612932},{"atb":[[1.08,10],[1.06,10],[1.01,477.81],[1.02,1.99]],"id":9612932},{"atl":[[630,0.09],[20,1.9],[22,11]],"id":9612932},{"spn":10.54,"spf":"NaN","id":9612932},{"atb":[[2.24,1.41],[1.08,10],[2.22,12.08],[1.06,10],[1.81,12.35],[1.01,477.81],[1.02,1.99]],"id":9480385},{"atl":[[630,0.09]],"id":9480385},{"spn":316.12,"spf":"NaN","id":9480385}],"con":true,"img":true,"tv":49.38}]}
{"op":"mcm","clk":"1144043231","pt":1439817708512,"mc":[{"id":"1.120089104","rc":[{"atl":[[20,0]],"id":9612932},{"spn":11.54,"spf":"NaN","id":9612932}],"con":true,"img":false,"tv":49.38}]}
{"op":"mcm","clk":"1144043235","pt":1439817708619,"mc":[{"id":"1.120089104","rc":[{"atl":[[1.8,1.9]],"id":9612932}],"con":true,"img":false,"tv":49.38}]}
{"op":"mcm","clk":"1144044123","pt":1439817728500,"mc":[{"id":"1.120089104","rc":[{"atb":[[2.22,49.08]],"id":9480385}],"con":true,"img":false,"tv":49.38}]}
{"op":"mcm","clk":"1144044360","pt":1439817734369,"mc":[{"id":"1.120089104","rc":[{"atb":[[2.22,50.98]],"id":9480385}],"con":true,"img":false,"tv":49.38}]}
{"op":"mcm","clk":"1144044545","pt":1439817738666,"mc":[{"id":"1.120089104","rc":[{"atb":[[2.22,49.08]],"id":9480385}],"con":true,"img":false,"tv":49.38}]}
{"op":"mcm","clk":"1144044551","pt":1439817738771,"mc":[{"id":"1.120089104","rc":[{"atb":[[2.24,3.31]],"id":9480385}],"con":true,"img":false,"tv":49.38}]}
{"op":"mcm","clk":"1144045653","pt":1439817763259,"mc":[{"id":"1.120089104","rc":[{"atb":[[1.01,479.81]],"id":9612932}],"con":true,"img":false,"tv":49.38}]}
{"op":"mcm","clk":"1144045838","pt":1439817767558,"mc":[{"id":"1.120089104","rc":[{"atb":[[1.01,481.71]],"id":9612932}],"con":true,"img":false,"tv":49.38}]}
{"op":"mcm","clk":"1144046030","pt":1439817772387,"mc":[{"id":"1.120089104","rc":[{"atb":[[1.01,479.81]],"id":9612932},{"spn":1.44,"spf":"NaN","id":9612932}],"con":true,"img":false,"tv":49.38}]}
{"op":"mcm","clk":"1144046039","pt":1439817772475,"mc":[{"id":"1.120089104","rc":[{"atb":[[1.09,1.9]],"id":9612932}],"con":true,"img":false,"tv":49.38}]}
{"op":"mcm","clk":"1144054961","pt":1439817985690,"mc":[{"id":"1.120089104","rc":[{"spn":1.44,"spf":"NaN","id":9612932},{"atb":[[2.24,1.9]],"id":9480385}],"con":true,"img":false,"tv":49.38}]}
{"op":"mcm","clk":"1144054965","pt":1439817985795,"mc":[{"id":"1.120089104","rc":[{"atb":[[2.26,1.41]],"id":9480385}],"con":true,"img":false,"tv":49.38}]}
{"op":"mcm","clk":"1144059088","pt":1439818088310,"mc":[{"id":"1.120089104","rc":[{"atb":[[1.02,0]],"id":9612932},{"spn":316.13,"spf":"NaN","id":9480385}],"con":true,"img":false,"tv":49.38}]}
{"op":"mcm","clk":"1144059091","pt":1439818088416,"mc":[{"id":"1.120089104","rc":[{"atb":[[1.1,1.99]],"id":9612932}],"con":true,"img":false,"tv":49.38}]}
{"op":"mcm","clk":"1144059259","pt":1439818092523,"mc":[{"id":"1.120089104","rc":[{"atb":[[1.02,0]],"id":9480385}],"con":true,"img":false,"tv":49.38}]}
{"op":"mcm","clk":"1144059266","pt":1439818092626,"mc":[{"id":"1.120089104","rc":[{"atb":[[2.28,1.99]],"id":9480385}],"con":true,"img":false,"tv":49.38}]}
{"op":"mcm","clk":"1144059409","pt":1439818096070,"mc":[{"id":"1.120089104","rc":[{"atb":[[1.02,6]],"id":9612932}],"con":true,"img":false,"tv":49.38}]}
{"op":"mcm","clk":"1144062435","pt":1439818172820,"mc":[{"id":"1.120089104","rc":[{"spn":1.45,"spf":"NaN","id":9612932},{"atb":[[2.24,0],[2.22,12.08]],"id":9480385},{"spn":316.14,"spf":"NaN","id":9480385}],"con":true,"img":false,"tv":49.38}]}
{"op":"mcm","clk":"1144062438","pt":1439818172923,"mc":[{"id":"1.120089104","rc":[{"atb":[[2.28,3.89],[2.26,38.41]],"id":9480385}],"con":true,"img":false,"tv":49.38}]}
{"op":"mcm","clk":"1144062581","pt":1439818176427,"mc":[{"id":"1.120089104","rc":[{"atb":[[1.11,1.98]],"id":9612932},{"atb":[[2.3,1.98]],"id":9480385}],"con":true,"img":false,"tv":49.38}]}
{"op":"mcm","clk":"1144062710","pt":1439818179300,"mc":[{"id":"1.120089104","rc":[{"atb":[[2.28,1.99],[2.26,1.41]],"id":9480385}],"con":true,"img":false,"tv":49.38}]}
{"op":"mcm","clk":"1144062714","pt":1439818179398,"mc":[{"id":"1.120089104","rc":[{"atb":[[2.28,38.99],[2.3,3.88]],"id":9480385}],"con":true,"img":false,"tv":49.38}]}
{"op":"mcm","clk":"1144062949","pt":1439818185485,"mc":[{"id":"1.120089104","rc":[{"atb":[[2.28,1.99],[2.3,1.98]],"id":9480385}],"con":true,"img":false,"tv":49.38}]}
{"op":"mcm","clk":"1144062955","pt":1439818185591,"mc":[{"id":"1.120089104","rc":[{"atb":[[2.32,1.9],[2.3,38.98]],"id":9480385}],"con":true,"img":false,"tv":49.38}]}
{"op":"mcm","clk":"1144063663","pt":1439818202785,"mc":[{"id":"1.120089104","rc":[{"atb":[[1.09,0]],"id":9612932}],"con":true,"img":false,"tv":49.38}]}
{"op":"mcm","clk":"1144063669","pt":1439818202844,"mc":[{"id":"1.120089104","rc":[{"atb":[[1.1,3.89]],"id":9612932}],"con":true,"img":false,"tv":49.38}]}
{"op":"mcm","clk":"1144065226","pt":1439818239238,"mc":[{"id":"1.120089104","rc":[{"spn":1.45,"spf":"NaN","id":9612932},{"atb":[[2.26,0]],"id":9480385},{"spn":316.16,"spf":"NaN","id":9480385}],"con":true,"img":false,"tv":49.38}]}
{"op":"mcm","clk":"1144065229","pt":1439818239350,"mc":[{"id":"1.120089104","rc":[{"atb":[[2.34,1.41]],"id":9480385}],"con":true,"img":false,"tv":49.38}]}
{"op":"mcm","clk":"1144069003","pt":1439818328477,"mc":[{"id":"1.120089104","rc":[{"atb":[[2.32,0],[2.3,1.98]],"id":9480385},{"spn":316.17,"spf":"NaN","id":9480385}],"con":true,"img":false,"tv":49.38}]}
{"op":"mcm","clk":"1144069008","pt":1439818328582,"mc":[{"id":"1.120089104","rc":[{"atb":[[2.34,3.31],[2.32,37]],"id":9480385}],"con":true,"img":false,"tv":49.38}]}
{"op":"mcm","clk":"1144069268","pt":1439818334321,"mc":[{"id":"1.120089104","rc":[{"atb":[[2.34,1.41],[2.32,0]],"id":9480385}],"con":true,"img":false,"tv":49.38}]}
{"op":"mcm","clk":"1144069272","pt":1439818334421,"mc":[{"id":"1.120089104","rc":[{"atb":[[2.34,38.41],[2.36,1.9]],"id":9480385}],"con":true,"img":false,"tv":49.38}]}
{"op":"mcm","clk":"1144077901","pt":1439818465070,"mc":[{"id":"1.120089104","marketDefinition":{"bspMarket":true,"turnInPlayEnabled":true,"persistenceEnabled":true,"marketBaseRate":5.0,"eventId":"27514783","eventTypeId":"7","numberOfWinners":1,"bettingType":"ODDS","marketType":"WIN","marketTime":"2015-08-18T20:20:00.000Z","suspendTime":"2015-08-18T20:20:00.000Z","bspReconciled":false,"complete":true,"inPlay":false,"crossMatching":false,"runnersVoidable":false,"numberOfActiveRunners":2,"betDelay":0,"status":"OPEN","runners":[{"adjustmentFactor":79.72,"status":"ACTIVE","sortPriority":1,"id":9612932,"name":"Alinstante"},{"adjustmentFactor":20.27,"status":"ACTIVE","sortPriority":2,"id":9480385,"name":"Vallance Road"}],"regulators":["MR_INT"],"venue":"Chelmsford City","countryCode":"GB","discountAllowed":false,"timezone":"Europe/London","openDate":"2015-08-18T17:20:00.000Z","version":1060767560,"name":"1m Cond Stks","eventName":"ChelmC 18th Aug"},"rc":[{"trd":[[1.4,49.38]],"ltp":1.4,"tv":49.38,"id":9612932},{"atb":[[1.1,3.89],[1.08,10],[1.11,1.98],[1.06,10],[1.01,479.81],[1.02,6]],"id":9612932},{"atl":[[630,0.09],[1.8,1.9],[22,11]],"id":9612932},{"spn":1.45,"spf":"NaN","id":9612932},{"atb":[[2.34,38.41],[1.08,10],[2.36,1.9],[2.22,12.08],[1.06,10],[1.81,12.35],[2.28,1.99],[1.01,477.81],[2.3,1.98]],"id":9480385},{"atl":[[630,0.09]],"id":9480385},{"spn":316.18,"spf":"NaN","id":9480385}],"con":true,"img":true,"tv":49.38}]}
{"op":"mcm","clk":"1144084375","pt":1439818490066,"mc":[{"id":"1.120089104","rc":[{"atb":[[2.34,37]],"id":9480385},{"spn":316.18,"spf":"NaN","id":9480385}],"con":true,"img":false,"tv":49.38}]}
{"op":"mcm","clk":"1144084380","pt":1439818490167,"mc":[{"id":"1.120089104","rc":[{"atb":[[2.38,1.41]],"id":9480385}],"con":true,"img":false,"tv":49.38}]}
{"op":"mcm","clk":"1144102146","pt":1439818905170,"mc":[{"id":"1.120089104","rc":[{"atb":[[2.34,0],[2.36,0]],"id":9480385},{"spn":316.19,"spf":"NaN","id":9480385}],"con":true,"img":false,"tv":49.38}]}
{"op":"mcm","clk":"1144102149","pt":1439818905275,"mc":[{"id":"1.120089104","rc":[{"atb":[[2.24,38.9]],"id":9480385}],"con":true,"img":false,"tv":49.38}]}
{"op":"mcm","clk":"1144106689","pt":1439819005227,"mc":[{"id":"1.120089104","rc":[{"atb":[[2.38,0]],"id":9480385},{"spn":316.15,"spf":"NaN","id":9480385}],"con":true,"img":false,"tv":49.38}]}
{"op":"mcm","clk":"1144106693","pt":1439819005333,"mc":[{"id":"1.120089104","rc":[{"atb":[[2.32,1.41]],"id":9480385}],"con":true,"img":false,"tv":49.38}]}
{"op":"mcm","clk":"1144126687","pt":1439819365034,"mc":[{"id":"1.120089104","marketDefinition":{"bspMarket":true,"turnInPlayEnabled":true,"persistenceEnabled":true,"marketBaseRate":5.0,"eventId":"27514783","eventTypeId":"7","numberOfWinners":1,"bettingType":"ODDS","marketType":"WIN","marketTime":"2015-08-18T20:20:00.000Z","suspendTime":"2015-08-18T20:20:00.000Z","bspReconciled":false,"complete":true,"inPlay":false,"crossMatching":false,"runnersVoidable":false,"numberOfActiveRunners":2,"betDelay":0,"status":"OPEN","runners":[{"adjustmentFactor":79.72,"status":"ACTIVE","sortPriority":1,"id":9612932,"name":"Alinstante"},{"adjustmentFactor":20.27,"status":"ACTIVE","sortPriority":2,"id":9480385,"name":"Vallance Road"}],"regulators":["MR_INT"],"venue":"Chelmsford City","countryCode":"GB","discountAllowed":false,"timezone":"Europe/London","openDate":"2015-08-18T17:20:00.000Z","version":1060767560,"name":"1m Cond Stks","eventName":"ChelmC 18th Aug"},"rc":[{"trd":[[1.4,49.38]],"ltp":1.4,"tv":49.38,"id":9612932},{"atb":[[1.1,3.89],[1.08,10],[1.11,1.98],[1.06,10],[1.01,479.81],[1.02,6]],"id":9612932},{"atl":[[630,0.09],[1.8,1.9],[22,11]],"id":9612932},{"spn":1.45,"spf":"NaN","id":9612932},{"atb":[[2.24,38.9],[2.32,1.41],[1.08,10],[2.22,12.08],[1.06,10],[1.81,12.35],[2.28,1.99],[1.01,477.81],[2.3,1.98]],"id":9480385},{"atl":[[630,0.09]],"id":9480385},{"spn":316.16,"spf":"NaN","id":9480385}],"con":true,"img":true,"tv":49.38}]}
{"op":"mcm","clk":"1144204318","pt":1439820654827,"mc":[{"id":"1.120089104","rc":[{"atb":[[1.06,20]],"id":9612932},{"atb":[[1.06,20]],"id":9480385},{"spn":316.16,"spf":"NaN","id":9480385}],"con":true,"img":false,"tv":49.38}]}
{"op":"mcm","clk":"1144267183","pt":1439821782610,"mc":[{"id":"1.120089104","rc":[{"atb":[[1.1,1.9]],"id":9612932}],"con":true,"img":false,"tv":49.38}]}
{"op":"mcm","clk":"1144267189","pt":1439821782664,"mc":[{"id":"1.120089104","rc":[{"atb":[[1.12,1.99]],"id":9612932}],"con":true,"img":false,"tv":49.38}]}
{"op":"mcm","clk":"1144267371","pt":1439821786820,"mc":[{"id":"1.120089104","rc":[{"atb":[[2.28,0]],"id":9480385}],"con":true,"img":false,"tv":49.38}]}
{"op":"mcm","clk":"1144267378","pt":1439821786925,"mc":[{"id":"1.120089104","rc":[{"atb":[[2.34,1.99]],"id":9480385}],"con":true,"img":false,"tv":49.38}]}
{"op":"mcm","clk":"1144268580","pt":1439821813752,"mc":[{"id":"1.120089104","rc":[{"atb":[[2.32,0]],"id":9480385}],"con":true,"img":false,"tv":49.38}]}
{"op":"mcm","clk":"1144268586","pt":1439821813855,"mc":[{"id":"1.120089104","rc":[{"atb":[[2.36,1.41]],"id":9480385}],"con":true,"img":false,"tv":49.38}]}
{"op":"mcm","clk":"1144275417","pt":1439821984920,"mc":[{"id":"1.120089104","rc":[{"spn":1.46,"spf":"NaN","id":9612932},{"atl":[[5,5]],"id":9480385},{"spn":3.68,"spf":"NaN","id":9480385}],"con":true,"img":false,"tv":49.38}]}
{"op":"mcm","clk":"1144275579","pt":1439821989451,"mc":[{"id":"1.120089104","rc":[{"atl":[[5,0]],"id":9480385}],"con":true,"img":false,"tv":49.38}]}
{"op":"mcm","clk":"1144281983","pt":1439822064961,"mc":[{"id":"1.120089104","marketDefinition":{"bspMarket":true,"turnInPlayEnabled":true,"persistenceEnabled":true,"marketBaseRate":5.0,"eventId":"27514783","eventTypeId":"7","numberOfWinners":1,"bettingType":"ODDS","marketType":"WIN","marketTime":"2015-08-18T20:20:00.000Z","suspendTime":"2015-08-18T20:20:00.000Z","bspReconciled":false,"complete":true,"inPlay":false,"crossMatching":false,"runnersVoidable":false,"numberOfActiveRunners":2,"betDelay":0,"status":"OPEN","runners":[{"adjustmentFactor":79.72,"status":"ACTIVE","sortPriority":1,"id":9612932,"name":"Alinstante"},{"adjustmentFactor":20.27,"status":"ACTIVE","sortPriority":2,"id":9480385,"name":"Vallance Road"}],"regulators":["MR_INT"],"venue":"Chelmsford City","countryCode":"GB","discountAllowed":false,"timezone":"Europe/London","openDate":"2015-08-18T17:20:00.000Z","version":1060767560,"name":"1m Cond Stks","eventName":"ChelmC 18th Aug"},"rc":[{"trd":[[1.4,49.38]],"ltp":1.4,"tv":49.38,"id":9612932},{"atb":[[1.12,1.99],[1.1,1.9],[1.08,10],[1.11,1.98],[1.06,20],[1.01,479.81],[1.02,6]],"id":9612932},{"atl":[[630,0.09],[1.8,1.9],[22,11]],"id":9612932},{"spn":1.46,"spf":"NaN","id":9612932},{"atb":[[2.24,38.9],[2.34,1.99],[1.08,10],[2.36,1.41],[2.22,12.08],[1.06,20],[1.81,12.35],[1.01,477.81],[2.3,1.98]],"id":9480385},{"atl":[[630,0.09]],"id":9480385},{"spn":316.18,"spf":"NaN","id":9480385}],"con":true,"img":true,"tv":49.38}]}
{"op":"mcm","clk":"1144290501","pt":1439822127902,"mc":[{"id":"1.120089104","rc":[{"atb":[[1.11,0]],"id":9612932},{"atb":[[2.3,0]],"id":9480385},{"spn":316.18,"spf":"NaN","id":9480385}],"con":true,"img":false,"tv":49.38}]}
{"op":"mcm","clk":"1144290507","pt":1439822127977,"mc":[{"id":"1.120089104","rc":[{"atb":[[1.13,1.98]],"id":9612932},{"atb":[[2.36,3.39]],"id":9480385}],"con":true,"img":false,"tv":49.38}]}
{"op":"mcm","clk":"1144290921","pt":1439822136338,"mc":[{"id":"1.120089104","rc":[{"atb":[[1.02,0]],"id":9612932}],"con":true,"img":false,"tv":49.38}]}
{"op":"mcm","clk":"1144290969","pt":1439822137355,"mc":[{"id":"1.120089104","rc":[{"atb":[[1.01,729.81]],"id":9612932},{"atb":[[1.01,727.81]],"id":9480385}],"con":true,"img":false,"tv":49.38}]}
{"op":"mcm","clk":"1144291000","pt":1439822137941,"mc":[{"id":"1.120089104","rc":[{"atb":[[1.02,250]],"id":9612932},{"atb":[[1.02,250]],"id":9480385}],"con":true,"img":false,"tv":49.38}]}
{"op":"mcm","clk":"1144291401","pt":1439822147100,"mc":[{"id":"1.120089104","rc":[{"atb":[[1.03,6]],"id":9612932}],"con":true,"img":false,"tv":49.38}]}
{"op":"mcm","clk":"1144300265","pt":1439822317188,"mc":[{"id":"1.120089104","rc":[{"spn":1.46,"spf":"NaN","id":9612932},{"atb":[[2.36,1.98]],"id":9480385}],"con":true,"img":false,"tv":49.38}]}
{"op":"mcm","clk":"1144300272","pt":1439822317287,"mc":[{"id":"1.120089104","rc":[{"atb":[[2.38,1.41]],"id":9480385}],"con":true,"img":false,"tv":49.38}]}
{"op":"mcm","clk":"1144323173","pt":1439822823013,"mc":[{"id":"1.120089104","rc":[{"atb":[[1.12,0]],"id":9612932},{"spn":316.19,"spf":"NaN","id":9480385}],"con":true,"img":false,"tv":49.38}]}
{"op":"mcm","clk":"1144323179","pt":1439822823119,"mc":[{"id":"1.120089104","rc":[{"atb":[[1.14,1.99]],"id":9612932}],"con":true,"img":false,"tv":49.38}]}
{"op":"mcm","clk":"1144323208","pt":1439822823811,"mc":[{"id":"1.120089104","rc":[{"atb":[[1.03,0]],"id":9612932}],"con":true,"img":false,"tv":49.38}]}
{"op":"mcm","clk":"1144323357","pt":1439822826238,"mc":[{"id":"1.120089104","rc":[{"atb":[[2.34,0]],"id":9480385}],"con":true,"img":false,"tv":49.38}]}
{"op":"mcm","clk":"1144323363","pt":1439822826340,"mc":[{"id":"1.120089104","rc":[{"atb":[[2.4,1.99]],"id":9480385}],"con":true,"img":false,"tv":49.38}]}
{"op":"mcm","clk":"1144333647","pt":1439822965021,"mc":[{"id":"1.120089104","marketDefinition":{"bspMarket":true,"turnInPlayEnabled":true,"persistenceEnabled":true,"marketBaseRate":5.0,"eventId":"27514783","eventTypeId":"7","numberOfWinners":1,"bettingType":"ODDS","marketType":"WIN","marketTime":"2015-08-18T20:20:00.000Z","suspendTime":"2015-08-18T20:20:00.000Z","bspReconciled":false,"complete":true,"inPlay":false,"crossMatching":false,"runnersVoidable":false,"numberOfActiveRunners":2,"betDelay":0,"status":"OPEN","runners":[{"adjustmentFactor":79.72,"status":"ACTIVE","sortPriority":1,"id":9612932,"name":"Alinstante"},{"adjustmentFactor":20.27,"status":"ACTIVE","sortPriority":2,"id":9480385,"name":"Vallance Road"}],"regulators":["MR_INT"],"venue":"Chelmsford City","countryCode":"GB","discountAllowed":false,"timezone":"Europe/London","openDate":"2015-08-18T17:20:00.000Z","version":1060767560,"name":"1m Cond Stks","eventName":"ChelmC 18th Aug"},"rc":[{"trd":[[1.4,49.38]],"ltp":1.4,"tv":49.38,"id":9612932},{"atb":[[1.1,1.9],[1.08,10],[1.06,20],[1.14,1.99],[1.13,1.98],[1.01,729.81],[1.02,250]],"id":9612932},{"atl":[[630,0.09],[1.8,1.9],[22,11]],"id":9612932},{"spn":1.47,"spf":"NaN","id":9612932},{"atb":[[2.24,38.9],[1.08,10],[2.36,1.98],[2.22,12.08],[1.06,20],[2.4,1.99],[1.81,12.35],[1.01,727.81],[2.38,1.41],[1.02,250]],"id":9480385},{"atl":[[630,0.09]],"id":9480385},{"spn":316.2,"spf":"NaN","id":9480385}],"con":true,"img":true,"tv":49.38}]}
{"op":"mcm","clk":"1144341901","pt":1439823027803,"mc":[{"id":"1.120089104","rc":[{"atb":[[1.1,0]],"id":9612932},{"spn":1.47,"spf":"NaN","id":9612932},{"spn":316.2,"spf":"NaN","id":9480385}],"con":true,"img":false,"tv":49.38}]}
{"op":"mcm","clk":"1144341907","pt":1439823027903,"mc":[{"id":"1.120089104","rc":[{"atb":[[1.13,3.88]],"id":9612932}],"con":true,"img":false,"tv":49.38}]}
{"op":"mcm","clk":"1144344665","pt":1439823084231,"mc":[{"id":"1.120089104","rc":[{"atb":[[2.38,0]],"id":9480385}],"con":true,"img":false,"tv":49.38}]}
{"op":"mcm","clk":"1144344673","pt":1439823084329,"mc":[{"id":"1.120089104","rc":[{"atb":[[2.42,1.41]],"id":9480385}],"con":true,"img":false,"tv":49.38}]}
{"op":"mcm","clk":"1144360308","pt":1439823359710,"mc":[{"id":"1.120089104","rc":[{"atb":[[1.13,1.9]],"id":9612932},{"atb":[[2.36,0]],"id":9480385},{"spn":316.21,"spf":"NaN","id":9480385}],"con":true,"img":false,"tv":49.38}]}
{"op":"mcm","clk":"1144360313","pt":1439823359816,"mc":[{"id":"1.120089104","rc":[{"atb":[[1.15,1.98]],"id":9612932},{"atb":[[2.42,3.39]],"id":9480385}],"con":true,"img":false,"tv":49.38}]}
{"op":"mcm","clk":"1144371291","pt":1439823588853,"mc":[{"id":"1.120089104","rc":[{"spn":1.47,"spf":"NaN","id":9612932},{"atb":[[2.42,1.98]],"id":9480385}],"con":true,"img":false,"tv":49.38}]}
{"op":"mcm","clk":"1144371297","pt":1439823588956,"mc":[{"id":"1.120089104","rc":[{"atb":[[2.44,1.41]],"id":9480385}],"con":true,"img":false,"tv":49.38}]}
{"op":"mcm","clk":"1144373969","pt":1439823641787,"mc":[{"id":"1.120089104","rc":[{"atb":[[1.13,0]],"id":9612932}],"con":true,"img":false,"tv":49.38}]}
{"op":"mcm","clk":"1144373975","pt":1439823641892,"mc":[{"id":"1.120089104","rc":[{"atb":[[1.14,3.89]],"id":9612932}],"con":true,"img":false,"tv":49.38}]}
{"op":"mcm","clk":"1144387358","pt":1439823864985,"mc":[{"id":"1.120089104","marketDefinition":{"bspMarket":true,"turnInPlayEnabled":true,"persistenceEnabled":true,"marketBaseRate":5.0,"eventId":"27514783","eventTypeId":"7","numberOfWinners":1,"bettingType":"ODDS","marketType":"WIN","marketTime":"2015-08-18T20:20:00.000Z","suspendTime":"2015-08-18T20:20:00.000Z","bspReconciled":false,"complete":true,"inPlay":false,"crossMatching":false,"runnersVoidable":false,"numberOfActiveRunners":2,"betDelay":0,"status":"OPEN","runners":[{"adjustmentFactor":79.72,"status":"ACTIVE","sortPriority":1,"id":9612932,"name":"Alinstante"},{"adjustmentFactor":20.27,"status":"ACTIVE","sortPriority":2,"id":9480385,"name":"Vallance Road"}],"regulators":["MR_INT"],"venue":"Chelmsford City","countryCode":"GB","discountAllowed":false,"timezone":"Europe/London","openDate":"2015-08-18T17:20:00.000Z","version":1060767560,"name":"1m Cond Stks","eventName":"ChelmC 18th Aug"},"rc":[{"trd":[[1.4,49.38]],"ltp":1.4,"tv":49.38,"id":9612932},{"atb":[[1.08,10],[1.06,20],[1.14,3.89],[1.01,729.81],[1.15,1.98],[1.02,250]],"id":9612932},{"atl":[[630,0.09],[1.8,1.9],[22,11]],"id":9612932},{"spn":1.47,"spf":"NaN","id":9612932},{"atb":[[2.24,38.9],[2.44,1.41],[1.08,10],[2.22,12.08],[1.06,20],[2.4,1.99],[1.81,12.35],[1.01,727.81],[2.42,1.98],[1.02,250]],"id":9480385},{"atl":[[630,0.09]],"id":9480385},{"spn":316.22,"spf":"NaN","id":9480385}],"con":true,"img":true,"tv":49.38}]}
{"op":"mcm","clk":"1144396038","pt":1439823928919,"mc":[{"id":"1.120089104","rc":[{"atb":[[1.14,1.9]],"id":9612932},{"spn":316.22,"spf":"NaN","id":9480385}],"con":true,"img":false,"tv":49.38}]}
{"op":"mcm","clk":"1144396044","pt":1439823929024,"mc":[{"id":"1.120089104","rc":[{"atb":[[1.16,1.99]],"id":9612932}],"con":true,"img":false,"tv":49.38}]}
{"op":"mcm","clk":"1144396225","pt":1439823932246,"mc":[{"id":"1.120089104","rc":[{"atb":[[2.4,0]],"id":9480385}],"con":true,"img":false,"tv":49.38}]}
{"op":"mcm","clk":"1144396231","pt":1439823932353,"mc":[{"id":"1.120089104","rc":[{"atb":[[2.46,1.99]],"id":9480385}],"con":true,"img":false,"tv":49.38}]}
{"op":"mcm","clk":"1144397554","pt":1439823962764,"mc":[{"id":"1.120089104","rc":[{"atb":[[1.14,0]],"id":9612932}],"con":true,"img":false,"tv":49.38}]}
{"op":"mcm","clk":"1144397561","pt":1439823962876,"mc":[{"id":"1.120089104","rc":[{"atb":[[1.09,1.9]],"id":9612932}],"con":true,"img":false,"tv":49.38}]}
{"op":"mcm","clk":"1144398142","pt":1439823977190,"mc":[{"id":"1.120089104","rc":[{"atb":[[1.15,0]],"id":9612932},{"atb":[[2.42,0]],"id":9480385}],"con":true,"img":false,"tv":49.38}]}
{"op":"mcm","clk":"1144398149","pt":1439823977295,"mc":[{"id":"1.120089104","rc":[{"atb":[[1.17,1.98]],"id":9612932},{"atb":[[2.48,1.98]],"id":9480385}],"con":true,"img":false,"tv":49.38}]}
{"op":"mcm","clk":"1144401980","pt":1439824053354,"mc":[{"id":"1.120089104","rc":[{"atb":[[1.09,0]],"id":9612932},{"spn":1.48,"spf":"NaN","id":9612932},{"spn":316.24,"spf":"NaN","id":9480385}],"con":true,"img":false,"tv":49.38}]}
{"op":"mcm","clk":"1144401988","pt":1439824053448,"mc":[{"id":"1.120089104","rc":[{"atb":[[1.16,3.89]],"id":9612932}],"con":true,"img":false,"tv":49.38}]}
{"op":"mcm","clk":"1144402775","pt":1439824070495,"mc":[{"id":"1.120089104","rc":[{"atb":[[2.24,37]],"id":9480385}],"con":true,"img":false,"tv":49.38}]}
{"op":"mcm","clk":"1144402784","pt":1439824070602,"mc":[{"id":"1.120089104","rc":[{"atb":[[2.48,3.88]],"id":9480385}],"con":true,"img":false,"tv":49.38}]}
{"op":"mcm","clk":"1144403872","pt":1439824093094,"mc":[{"id":"1.120089104","rc":[{"atb":[[2.44,0]],"id":9480385}],"con":true,"img":false,"tv":49.38}]}
{"op":"mcm","clk":"1144403876","pt":1439824093156,"mc":[{"id":"1.120089104","rc":[{"atb":[[2.5,1.41]],"id":9480385}],"con":true,"img":false,"tv":49.38}]}
{"op":"mcm","clk":"1144441331","pt":1439824752188,"mc":[{"id":"1.120089104","rc":[{"atb":[[1.16,1.9]],"id":9612932},{"spn":316.25,"spf":"NaN","id":9480385}],"con":true,"img":false,"tv":49.38}]}
{"op":"mcm","clk":"1144441336","pt":1439824752290,"mc":[{"id":"1.120089104","rc":[{"atb":[[1.18,1.99]],"id":9612932}],"con":true,"img":false,"tv":49.38}]}
{"op":"mcm","clk":"1144441608","pt":1439824756548,"mc":[{"id":"1.120089104","rc":[{"atb":[[2.46,0]],"id":9480385}],"con":true,"img":false,"tv":49.38}]}
{"op":"mcm","clk":"1144441615","pt":1439824756654,"mc":[{"id":"1.120089104","rc":[{"atb":[[2.52,1.99]],"id":9480385}],"con":true,"img":false,"tv":49.38}]}
{"op":"mcm","clk":"1144456275","pt":1439824865370,"mc":[{"id":"1.120089104","rc":[{"spn":1.49,"spf":"NaN","id":9612932},{"atb":[[2.5,0]],"id":9480385},{"spn":316.26,"spf":"NaN","id":9480385}],"con":true,"img":false,"tv":49.38}]}
{"op":"mcm","clk":"1144456280","pt":1439824865461,"mc":[{"id":"1.120089104","rc":[{"atb":[[2.54,1.41]],"id":9480385}],"con":true,"img":false,"tv":49.38}]}
{"op":"mcm","clk":"1144466697","pt":1439825039230,"mc":[{"id":"1.120089104","rc":[{"atb":[[1.12,240]],"id":9612932},{"atb":[[2.26,175]],"id":9480385},{"spn":316.27,"spf":"NaN","id":9480385}],"con":true,"img":false,"tv":49.38}]}
{"op":"mcm","clk":"1144466874","pt":1439825041567,"mc":[{"id":"1.120089104","rc":[{"atl":[[20,15]],"id":9612932},{"atl":[[980,15]],"id":9480385}],"con":true,"img":false,"tv":49.38}]}
{"op":"mcm","clk":"1144467546","pt":1439825050661,"mc":[{"id":"1.120089104","rc":[{"atb":[[1.13,6]],"id":9612932}],"con":true,"img":false,"tv":49.38}]}
{"op":"mcm","clk":"1144471069","pt":1439825104739,"mc":[{"id":"1.120089104","rc":[{"atb":[[1.08,2691.25]],"id":9612932},{"atb":[[1.76,30]],"id":9480385}],"con":true,"img":false,"tv":49.38}]}
{"op":"mcm","clk":"1144477150","pt":1439825215237,"mc":[{"id":"1.120089104","rc":[{"atb":[[1.17,0]],"id":9612932},{"atb":[[2.48,1.9]],"id":9480385}],"con":true,"img":false,"tv":49.38}]}
{"op":"mcm","clk":"1144477155","pt":1439825215342,"mc":[{"id":"1.120089104","rc":[{"atb":[[1.19,1.98]],"id":9612932},{"atb":[[2.54,3.39]],"id":9480385}],"con":true,"img":false,"tv":49.38}]}
{"op":"mcm","clk":"1144486121","pt":1439825378994,"mc":[{"id":"1.120089104","rc":[{"spn":1.49,"spf":"NaN","id":9612932},{"atb":[[2.54,1.98]],"id":9480385}],"con":true,"img":false,"tv":49.38}]}
{"op":"mcm","clk":"1144486129","pt":1439825379103,"mc":[{"id":"1.120089104","rc":[{"atb":[[2.56,1.41]],"id":9480385}],"con":true,"img":false,"tv":49.38}]}
{"op":"mcm","clk":"1144491303","pt":1439825462085,"mc":[{"id":"1.120089104","rc":[{"atb":[[1.13,39]],"id":9612932},{"spn":316.28,"spf":"NaN","id":9480385}],"con":true,"img":false,"tv":49.38}]}
{"op":"mcm","clk":"1144491784","pt":1439825469794,"mc":[{"id":"1.120089104","rc":[{"atl":[[22,0]],"id":9612932}],"con":true,"img":false,"tv":49.38}]}
{"op":"mcm","clk":"1144491794","pt":1439825469908,"mc":[{"id":"1.120089104","rc":[{"atl":[[19.5,11]],"id":9612932}],"con":true,"img":false,"tv":49.38}]}
{"op":"mcm","clk":"1144491849","pt":1439825471035,"mc":[{"id":"1.120089104","rc":[{"atb":[[1.09,6]],"id":9612932}],"con":true,"img":false,"tv":49.38}]}
{"op":"mcm","clk":"1144492520","pt":1439825483172,"mc":[{"id":"1.120089104","rc":[{"atb":[[2.24,0],[2.48,0]],"id":9480385}],"con":true,"img":false,"tv":49.38}]}
{"op":"mcm","clk":"1144492529","pt":1439825483282,"mc":[{"id":"1.120089104","rc":[{"atb":[[2.28,37],[2.54,3.88]],"id":9480385}],"con":true,"img":false,"tv":49.38}]}
{"op":"mcm","clk":"1144539847","pt":1439826099154,"mc":[{"id":"1.120089104","rc":[{"atb":[[1.18,0]],"id":9612932}],"con":true,"img":false,"tv":49.38}]}
{"op":"mcm","clk":"1144539855","pt":1439826099273,"mc":[{"id":"1.120089104","rc":[{"atb":[[1.2,1.99]],"id":9612932}],"con":true,"img":false,"tv":49.38}]}
{"op":"mcm","clk":"1144540008","pt":1439826102497,"mc":[{"id":"1.120089104","rc":[{"atb":[[2.52,0]],"id":9480385}],"con":true,"img":false,"tv":49.38}]}
{"op":"mcm","clk":"1144540014","pt":1439826102605,"mc":[{"id":"1.120089104","rc":[{"atb":[[2.58,1.99]],"id":9480385}],"con":true,"img":false,"tv":49.38}]}
{"op":"mcm","clk":"1144540321","pt":1439826108550,"mc":[{"id":"1.120089104","rc":[{"atb":[[1.09,0]],"id":9612932}],"con":true,"img":false,"tv":49.38}]}
{"op":"mcm","clk":"1144542343","pt":1439826146579,"mc":[{"id":"1.120089104","rc":[{"atb":[[2.56,0]],"id":9480385}],"con":true,"img":false,"tv":49.38}]}
{"op":"mcm","clk":"1144542348","pt":1439826146686,"mc":[{"id":"1.120089104","rc":[{"atb":[[2.6,1.41]],"id":9480385}],"con":true,"img":false,"tv":49.38}]}
{"op":"mcm","clk":"1144559994","pt":1439826442671,"mc":[{"id":"1.120089104","rc":[{"atb":[[1.19,0]],"id":9612932},{"spn":1.5,"spf":"NaN","id":9612932},{"atb":[[2.54,1.9]],"id":9480385},{"spn":316.3,"spf":"NaN","id":9480385}],"con":true,"img":false,"tv":49.38}]}
{"op":"mcm","clk":"1144559999","pt":1439826442778,"mc":[{"id":"1.120089104","rc":[{"atb":[[1.21,1.98]],"id":9612932},{"atb":[[2.6,3.39]],"id":9480385}],"con":true,"img":false,"tv":49.38}]}
{"op":"mcm","clk":"1144563048","pt":1439826497267,"mc":[{"id":"1.120089104","rc":[{"atb":[[2.54,0]],"id":9480385}],"con":true,"img":false,"tv":49.38}]}
{"op":"mcm","clk":"1144563052","pt":1439826497331,"mc":[{"id":"1.120089104","rc":[{"atb":[[2.6,5.29]],"id":9480385}],"con":true,"img":false,"tv":49.38}]}
{"op":"mcm","clk":"1144570126","pt":1439826565030,"mc":[{"id":"1.120089104","marketDefinition":{"bspMarket":true,"turnInPlayEnabled":true,"persistenceEnabled":true,"marketBaseRate":5.0,"eventId":"27514783","eventTypeId":"7","numberOfWinners":1,"bettingType":"ODDS","marketType":"WIN","marketTime":"2015-08-18T20:20:00.000Z","suspendTime":"2015-08-18T20:20:00.000Z","bspReconciled":false,"complete":true,"inPlay":false,"crossMatching":false,"runnersVoidable":false,"numberOfActiveRunners":2,"betDelay":0,"status":"OPEN","runners":[{"adjustmentFactor":79.72,"status":"ACTIVE","sortPriority":1,"id":9612932,"name":"Alinstante"},{"adjustmentFactor":20.27,"status":"ACTIVE","sortPriority":2,"id":9480385,"name":"Vallance Road"}],"regulators":["MR_INT"],"venue":"Chelmsford City","countryCode":"GB","discountAllowed":false,"timezone":"Europe/London","openDate":"2015-08-18T17:20:00.000Z","version":1060767560,"name":"1m Cond Stks","eventName":"ChelmC 18th Aug"},"rc":[{"trd":[[1.4,49.38]],"ltp":1.4,"tv":49.38,"id":9612932},{"atb":[[1.12,240],[1.16,1.9],[1.08,2691.25],[1.06,20],[1.2,1.99],[1.13,39],[1.01,729.81],[1.21,1.98],[1.02,250]],"id":9612932},{"atl":[[19.5,11],[630,0.09],[1.8,1.9],[20,15]],"id":9612932},{"spn":1.5,"spf":"NaN","id":9612932},{"atb":[[2.6,5.29],[2.58,1.99],[1.08,10],[2.22,12.08],[1.06,20],[1.76,30],[1.81,12.35],[2.28,37],[1.01,727.81],[2.26,175],[1.02,250]],"id":9480385},{"atl":[[980,15],[630,0.09]],"id":9480385},{"spn":316.3,"spf":"NaN","id":9480385}],"con":true,"img":true,"tv":49.38}]}
{"op":"mcm","clk":"1144577114","pt":1439826591052,"mc":[{"id":"1.120089104","rc":[{"atb":[[1.16,0]],"id":9612932},{"spn":1.5,"spf":"NaN","id":9612932}],"con":true,"img":false,"tv":49.38}]}
{"op":"mcm","clk":"1144577122","pt":1439826591159,"mc":[{"id":"1.120089104","rc":[{"atb":[[1.14,1.9]],"id":9612932}],"con":true,"img":false,"tv":49.38}]}
{"op":"mcm","clk":"1144581530","pt":1439826656110,"mc":[{"id":"1.120089104","rc":[{"atb":[[2.6,3.88]],"id":9480385}],"con":true,"img":false,"tv":49.38}]}
{"op":"mcm","clk":"1144581540","pt":1439826656226,"mc":[{"id":"1.120089104","rc":[{"atb":[[2.62,1.41]],"id":9480385}],"con":true,"img":false,"tv":49.38}]}
{"op":"mcm","clk":"1144594976","pt":1439826857941,"mc":[{"id":"1.120089104","rc":[{"atb":[[1.14,13.11]],"id":9612932},{"atl":[[19,2.55]],"id":9612932},{"spn":316.31,"spf":"NaN","id":9480385}],"con":true,"img":false,"tv":49.38}]}
{"op":"mcm","clk":"1144594982","pt":1439826858053,"mc":[{"id":"1.120089104","rc":[{"atb":[[2.3,11.07]],"id":9480385},{"atl":[[970,2.55]],"id":9480385}],"con":true,"img":false,"tv":49.38}]}
{"op":"mcm","clk":"1144595759","pt":1439826870423,"mc":[{"id":"1.120089104","rc":[{"atl":[[1.42,20]],"id":9612932}],"con":true,"img":false,"tv":49.38}]}
{"op":"mcm","clk":"1144616916","pt":1439827200917,"mc":[{"id":"1.120089104","rc":[{"atb":[[1.2,0]],"id":9612932},{"spn":1.31,"spf":"NaN","id":9612932}],"con":true,"img":false,"tv":49.38}]}
{"op":"mcm","clk":"1144616919","pt":1439827201019,"mc":[{"id":"1.120089104","rc":[{"atb":[[1.22,1.99]],"id":9612932}],"con":true,"img":false,"tv":49.38}]}
{"op":"mcm","clk":"1144617125","pt":1439827204190,"mc":[{"id":"1.120089104","rc":[{"atb":[[2.58,0]],"id":9480385}],"con":true,"img":false,"tv":49.38}]}
{"op":"mcm","clk":"1144617137","pt":1439827204243,"mc":[{"id":"1.120089104","rc":[{"atb":[[2.64,1.99]],"id":9480385}],"con":true,"img":false,"tv":49.38}]}
{"op":"mcm","clk":"1144619329","pt":1439827242465,"mc":[{"id":"1.120089104","rc":[{"atb":[[1.14,13.14],[1.01,729.7],[1.21,0]],"id":9612932},{"atl":[[19,2.56]],"id":9612932},{"atb":[[2.62,1.41],[2.6,1.9],[2.22,12.07],[1.01,727.7],[2.3,11.09]],"id":9480385},{"atl":[[970,2.56]],"id":9480385}],"con":true,"img":false,"tv":49.38}]}
{"op":"mcm","clk":"1144619332","pt":1439827242568,"mc":[{"id":"1.120089104","rc":[{"atb":[[1.22,3.97]],"id":9612932},{"atb":[[2.66,1.98]],"id":9480385}],"con":true,"img":false,"tv":49.38}]}
{"op":"mcm","clk":"1144622989","pt":1439827302658,"mc":[{"id":"1.120089104","rc":[{"atl":[[20,0]],"id":9612932},{"spn":1.32,"spf":"NaN","id":9612932},{"atl":[[980,0]],"id":9480385},{"spn":316.33,"spf":"NaN","id":9480385}],"con":true,"img":false,"tv":49.38}]}
{"op":"mcm","clk":"1144622995","pt":1439827302761,"mc":[{"id":"1.120089104","rc":[{"atl":[[1.69,15]],"id":9612932},{"atl":[[950,15]],"id":9480385}],"con":true,"img":false,"tv":49.38}]}
{"op":"mcm","clk":"1144673044","pt":1439827838673,"mc":[{"id":"1.120089104","rc":[{"atl":[[1.42,0]],"id":9612932},{"spn":1.45,"spf":"NaN","id":9612932}],"con":true,"img":false,"tv":49.38}]}
{"op":"mcm","clk":"1144673052","pt":1439827838736,"mc":[{"id":"1.120089104","rc":[{"atl":[[1.4,20]],"id":9612932}],"con":true,"img":false,"tv":49.38}]}
{"op":"mcm","clk":"1144697846","pt":1439828132356,"mc":[{"id":"1.120089104","rc":[{"spn":1.31,"spf":"NaN","id":9612932},{"atb":[[2.64,0]],"id":9480385}],"con":true,"img":false,"tv":49.38}]}
{"op":"mcm","clk":"1144697855","pt":1439828132461,"mc":[{"id":"1.120089104","rc":[{"atb":[[2.68,1.99]],"id":9480385}],"con":true,"img":false,"tv":49.38}]}
{"op":"mcm","clk":"1144698185","pt":1439828135894,"mc":[{"id":"1.120089104","rc":[{"atb":[[2.66,0]],"id":9480385}],"con":true,"img":false,"tv":49.38}]}
{"op":"mcm","clk":"1144698192","pt":1439828136002,"mc":[{"id":"1.120089104","rc":[{"atb":[[2.7,1.98]],"id":9480385}],"con":true,"img":false,"tv":49.38}]}
{"op":"mcm","clk":"1144720431","pt":1439828364973,"mc":[{"id":"1.120089104","marketDefinition":{"bspMarket":true,"turnInPlayEnabled":true,"persistenceEnabled":true,"marketBaseRate":5.0,"eventId":"27514783","eventTypeId":"7","numberOfWinners":1,"bettingType":"ODDS","marketType":"WIN","marketTime":"2015-08-18T20:20:00.000Z","suspendTime":"2015-08-18T20:20:00.000Z","bspReconciled":false,"complete":true,"inPlay":false,"crossMatching":false,"runnersVoidable":false,"numberOfActiveRunners":2,"betDelay":0,"status":"OPEN","runners":[{"adjustmentFactor":79.72,"status":"ACTIVE","sortPriority":1,"id":9612932,"name":"Alinstante"},{"adjustmentFactor":20.27,"status":"ACTIVE","sortPriority":2,"id":9480385,"name":"Vallance Road"}],"regulators":["MR_INT"],"venue":"Chelmsford City","countryCode":"GB","discountAllowed":false,"timezone":"Europe/London","openDate":"2015-08-18T17:20:00.000Z","version":1060767560,"name":"1m Cond Stks","eventName":"ChelmC 18th Aug"},"rc":[{"trd":[[1.4,49.38]],"ltp":1.4,"tv":49.38,"id":9612932},{"atb":[[1.12,240],[1.22,3.97],[1.08,2691.25],[1.06,20],[1.14,13.14],[1.13,39],[1.01,729.7],[1.02,250]],"id":9612932},{"atl":[[1.69,15],[19.5,11],[630,0.09],[1.4,20],[1.8,1.9],[19,2.56]],"id":9612932},{"spn":1.31,"spf":"NaN","id":9612932},{"atb":[[2.62,1.41],[2.6,1.9],[1.08,10],[2.22,12.07],[1.06,20],[2.7,1.98],[1.76,30],[1.81,12.35],[2.28,37],[1.01,727.7],[2.68,1.99],[2.26,175],[2.3,11.09],[1.02,250]],"id":9480385},{"atl":[[950,15],[630,0.09],[970,2.56]],"id":9480385},{"spn":316.35,"spf":"NaN","id":9480385}],"con":true,"img":true,"tv":49.38}]}
{"op":"mcm","clk":"1144797260","pt":1439829180151,"mc":[{"id":"1.120089104","rc":[{"atb":[[2.68,0]],"id":9480385},{"spn":316.35,"spf":"NaN","id":9480385}],"con":true,"img":false,"tv":49.38}]}
{"op":"mcm","clk":"1144797268","pt":1439829180257,"mc":[{"id":"1.120089104","rc":[{"atb":[[2.72,1.99]],"id":9480385}],"con":true,"img":false,"tv":49.38}]}
{"op":"mcm","clk":"1144798155","pt":1439829188653,"mc":[{"id":"1.120089104","rc":[{"atb":[[2.7,0]],"id":9480385}],"con":true,"img":false,"tv":49.38}]}
{"op":"mcm","clk":"1144798168","pt":1439829188763,"mc":[{"id":"1.120089104","rc":[{"atb":[[2.74,1.98]],"id":9480385}],"con":true,"img":false,"tv":49.38}]}
{"op":"mcm","clk":"1144808692","pt":1439829265039,"mc":[{"id":"1.120089104","marketDefinition":{"bspMarket":true,"turnInPlayEnabled":true,"persistenceEnabled":true,"marketBaseRate":5.0,"eventId":"27514783","eventTypeId":"7","numberOfWinners":1,"bettingType":"ODDS","marketType":"WIN","marketTime":"2015-08-18T20:20:00.000Z","suspendTime":"2015-08-18T20:20:00.000Z","bspReconciled":false,"complete":true,"inPlay":false,"crossMatching":false,"runnersVoidable":false,"numberOfActiveRunners":2,"betDelay":0,"status":"OPEN","runners":[{"adjustmentFactor":79.72,"status":"ACTIVE","sortPriority":1,"id":9612932,"name":"Alinstante"},{"adjustmentFactor":20.27,"status":"ACTIVE","sortPriority":2,"id":9480385,"name":"Vallance Road"}],"regulators":["MR_INT"],"venue":"Chelmsford City","countryCode":"GB","discountAllowed":false,"timezone":"Europe/London","openDate":"2015-08-18T17:20:00.000Z","version":1060767560,"name":"1m Cond Stks","eventName":"ChelmC 18th Aug"},"rc":[{"trd":[[1.4,49.38]],"ltp":1.4,"tv":49.38,"id":9612932},{"atb":[[1.12,240],[1.22,3.97],[1.08,2691.25],[1.06,20],[1.14,13.14],[1.13,39],[1.01,729.7],[1.02,250]],"id":9612932},{"atl":[[1.69,15],[19.5,11],[630,0.09],[1.4,20],[1.8,1.9],[19,2.56]],"id":9612932},{"spn":1.31,"spf":"NaN","id":9612932},{"atb":[[2.72,1.99],[2.62,1.41],[2.6,1.9],[1.08,10],[2.74,1.98],[2.22,12.07],[1.06,20],[1.76,30],[1.81,12.35],[2.28,37],[1.01,727.7],[2.26,175],[2.3,11.09],[1.02,250]],"id":9480385},{"atl":[[950,15],[630,0.09],[970,2.56]],"id":9480385},{"spn":316.37,"spf":"NaN","id":9480385}],"con":true,"img":true,"tv":49.38}]}
{"op":"mcm","clk":"1144852133","pt":1439829670990,"mc":[{"id":"1.120089104","rc":[{"atb":[[1.01,729.7]],"id":9480385},{"spn":316.37,"spf":"NaN","id":9480385}],"con":true,"img":false,"tv":49.38}]}
{"op":"mcm","clk":"1144852322","pt":1439829673114,"mc":[{"id":"1.120089104","rc":[{"atb":[[1.01,730.58]],"id":9480385}],"con":true,"img":false,"tv":49.38}]}
{"op":"mcm","clk":"1144852786","pt":1439829677375,"mc":[{"id":"1.120089104","rc":[{"atb":[[1.01,729.7]],"id":9480385}],"con":true,"img":false,"tv":49.38}]}
{"op":"mcm","clk":"1144852799","pt":1439829677490,"mc":[{"id":"1.120089104","rc":[{"atb":[[2.74,2.86]],"id":9480385}],"con":true,"img":false,"tv":49.38}]}
{"op":"mcm","clk":"1144852852","pt":1439829677980,"mc":[{"id":"1.120089104","rc":[{"atb":[[1.01,727.7]],"id":9480385}],"con":true,"img":false,"tv":49.38}]}
{"op":"mcm","clk":"1144853064","pt":1439829680085,"mc":[{"id":"1.120089104","rc":[{"atb":[[1.01,731.7]],"id":9612932}],"con":true,"img":false,"tv":49.38}]}
{"op":"mcm","clk":"1144853488","pt":1439829684580,"mc":[{"id":"1.120089104","rc":[{"atb":[[1.01,732.58]],"id":9612932}],"con":true,"img":false,"tv":49.38}]}
{"op":"mcm","clk":"1144853877","pt":1439829689020,"mc":[{"id":"1.120089104","rc":[{"atb":[[1.01,731.7]],"id":9612932}],"con":true,"img":false,"tv":49.38}]}
{"op":"mcm","clk":"1144853889","pt":1439829689117,"mc":[{"id":"1.120089104","rc":[{"atb":[[1.23,0.88]],"id":9612932}],"con":true,"img":false,"tv":49.38}]}
{"op":"mcm","clk":"1144853904","pt":1439829689330,"mc":[{"id":"1.120089104","rc":[{"atb":[[1.01,729.7]],"id":9612932}],"con":true,"img":false,"tv":49.38}]}
{"op":"mcm","clk":"1144876011","pt":1439829959162,"mc":[{"id":"1.120089104","rc":[{"atb":[[1.01,731.8]],"id":9612932},{"spn":1.31,"spf":"NaN","id":9612932},{"atb":[[1.01,729.8]],"id":9480385}],"con":true,"img":false,"tv":49.38}]}
{"op":"mcm","clk":"1144876045","pt":1439829959588,"mc":[{"id":"1.120089104","rc":[{"atb":[[1.01,731.69]],"id":9612932},{"atb":[[1.01,729.69]],"id":9480385}],"con":true,"img":false,"tv":49.38}]}
{"op":"mcm","clk":"1144876080","pt":1439829959971,"mc":[{"id":"1.120089104","rc":[{"atb":[[1.01,729.7]],"id":9612932},{"atb":[[1.01,727.7]],"id":9480385}],"con":true,"img":false,"tv":49.38}]}
{"op":"mcm","clk":"1144876093","pt":1439829960081,"mc":[{"id":"1.120089104","rc":[{"atb":[[1.14,15.13]],"id":9612932},{"atb":[[2.76,1.99]],"id":9480385}],"con":true,"img":false,"tv":49.38}]}
{"op":"mcm","clk":"1144876196","pt":1439829961381,"mc":[{"id":"1.120089104","rc":[{"atb":[[2.74,0.88]],"id":9480385}],"con":true,"img":false,"tv":49.38}]}
{"op":"mcm","clk":"1144876209","pt":1439829961498,"mc":[{"id":"1.120089104","rc":[{"atb":[[2.78,1.98]],"id":9480385}],"con":true,"img":false,"tv":49.38}]}
{"op":"mcm","clk":"1144896445","pt":1439830164977,"mc":[{"id":"1.120089104","marketDefinition":{"bspMarket":true,"turnInPlayEnabled":true,"persistenceEnabled":true,"marketBaseRate":5.0,"eventId":"27514783","eventTypeId":"7","numberOfWinners":1,"bettingType":"ODDS","marketType":"WIN","marketTime":"2015-08-18T20:20:00.000Z","suspendTime":"2015-08-18T20:20:00.000Z","bspReconciled":false,"complete":true,"inPlay":false,"crossMatching":false,"runnersVoidable":false,"numberOfActiveRunners":2,"betDelay":0,"status":"OPEN","runners":[{"adjustmentFactor":79.72,"status":"ACTIVE","sortPriority":1,"id":9612932,"name":"Alinstante"},{"adjustmentFactor":20.27,"status":"ACTIVE","sortPriority":2,"id":9480385,"name":"Vallance Road"}],"regulators":["MR_INT"],"venue":"Chelmsford City","countryCode":"GB","discountAllowed":false,"timezone":"Europe/London","openDate":"2015-08-18T17:20:00.000Z","version":1060767560,"name":"1m Cond Stks","eventName":"ChelmC 18th Aug"},"rc":[{"trd":[[1.4,49.38]],"ltp":1.4,"tv":49.38,"id":9612932},{"atb":[[1.23,0.88],[1.12,240],[1.22,3.97],[1.08,2691.25],[1.06,20],[1.14,15.13],[1.13,39],[1.01,729.7],[1.02,250]],"id":9612932},{"atl":[[1.69,15],[19.5,11],[630,0.09],[1.4,20],[1.8,1.9],[19,2.56]],"id":9612932},{"spn":1.31,"spf":"NaN","id":9612932},{"atb":[[2.62,1.41],[2.6,1.9],[1.06,20],[1.76,30],[1.81,12.35],[2.28,37],[1.01,727.7],[2.26,175],[2.3,11.09],[2.78,1.98],[1.02,250],[2.76,1.99],[2.72,1.99],[1.08,10],[2.22,12.07],[2.74,0.88]],"id":9480385},{"atl":[[950,15],[630,0.09],[970,2.56]],"id":9480385},{"spn":316.39,"spf":"NaN","id":9480385}],"con":true,"img":true,"tv":49.38}]}
{"op":"mcm","clk":"1144902095","pt":1439830166729,"mc":[{"id":"1.120089104","rc":[{"atb":[[1.22,1.98]],"id":9612932},{"spn":316.39,"spf":"NaN","id":9480385}],"con":true,"img":false,"tv":49.38}]}
{"op":"mcm","clk":"1144902103","pt":1439830166841,"mc":[{"id":"1.120089104","rc":[{"atb":[[1.24,1.99]],"id":9612932}],"con":true,"img":false,"tv":49.38}]}
{"op":"mcm","clk":"1144902392","pt":1439830170852,"mc":[{"id":"1.120089104","rc":[{"atb":[[1.22,0]],"id":9612932}],"con":true,"img":false,"tv":49.38}]}
{"op":"mcm","clk":"1144902403","pt":1439830170961,"mc":[{"id":"1.120089104","rc":[{"atb":[[1.24,3.97]],"id":9612932},{"atb":[[2.72,0]],"id":9480385}],"con":true,"img":false,"tv":49.38}]}
{"op":"mcm","clk":"1144902423","pt":1439830171067,"mc":[{"id":"1.120089104","rc":[{"atb":[[2.8,1.99]],"id":9480385}],"con":true,"img":false,"tv":49.38}]}
{"op":"mcm","clk":"1144902788","pt":1439830175965,"mc":[{"id":"1.120089104","rc":[{"atb":[[1.13,33]],"id":9612932}],"con":true,"img":false,"tv":49.38}]}
{"op":"mcm","clk":"1144903077","pt":1439830179389,"mc":[{"id":"1.120089104","rc":[{"atb":[[2.78,0]],"id":9480385}],"con":true,"img":false,"tv":49.38}]}
{"op":"mcm","clk":"1144903084","pt":1439830179497,"mc":[{"id":"1.120089104","rc":[{"atb":[[2.82,1.98]],"id":9480385}],"con":true,"img":false,"tv":49.38}]}
{"op":"mcm","clk":"1144912762","pt":1439830313605,"mc":[{"id":"1.120089104","rc":[{"atb":[[1.15,22]],"id":9612932},{"spn":1.32,"spf":"NaN","id":9612932},{"atb":[[3.75,15]],"id":9480385},{"spn":316.87,"spf":"NaN","id":9480385}],"con":true,"img":false,"tv":49.38}]}
{"op":"mcm","clk":"1144912871","pt":1439830315540,"mc":[{"id":"1.120089104","rc":[{"atb":[[2.82,0]],"id":9480385}],"con":true,"img":false,"tv":49.38}]}
{"op":"mcm","clk":"1144912881","pt":1439830315646,"mc":[{"id":"1.120089104","rc":[{"atb":[[3.8,1.98]],"id":9480385}],"con":true,"img":false,"tv":49.38}]}
{"op":"mcm","clk":"1144914445","pt":1439830336558,"mc":[{"id":"1.120089104","rc":[{"atb":[[3.85,4.05]],"id":9480385}],"con":true,"img":false,"tv":49.38}]}
{"op":"mcm","clk":"1144914683","pt":1439830340008,"mc":[{"id":"1.120089104","rc":[{"atb":[[3.8,0]],"id":9480385}],"con":true,"img":false,"tv":49.38}]}
{"op":"mcm","clk":"1144914690","pt":1439830340113,"mc":[{"id":"1.120089104","rc":[{"atb":[[3.9,1.98]],"id":9480385}],"con":true,"img":false,"tv":49.38}]}
{"op":"mcm","clk":"1144916535","pt":1439830367768,"mc":[{"id":"1.120089104","rc":[{"atb":[[3.85,0]],"id":9480385}],"con":true,"img":false,"tv":49.38}]}
{"op":"mcm","clk":"1144916544","pt":1439830367971,"mc":[{"id":"1.120089104","rc":[{"atb":[[3.95,3.95]],"id":9480385}],"con":true,"img":false,"tv":49.38}]}
{"op":"mcm","clk":"1144916896","pt":1439830373491,"mc":[{"id":"1.120089104","rc":[{"atb":[[3.9,0]],"id":9480385}],"con":true,"img":false,"tv":49.38}]}
{"op":"mcm","clk":"1144916904","pt":1439830373553,"mc":[{"id":"1.120089104","rc":[{"atb":[[4,1.98]],"id":9480385}],"con":true,"img":false,"tv":49.38}]}
{"op":"mcm","clk":"1144918625","pt":1439830399910,"mc":[{"id":"1.120089104","rc":[{"atb":[[3.95,0]],"id":9480385},{"spn":317.0,"spf":"NaN","id":9480385}],"con":true,"img":false,"tv":49.38}]}
{"op":"mcm","clk":"1144918640","pt":1439830400115,"mc":[{"id":"1.120089104","rc":[{"atb":[[4.1,3.81]],"id":9480385}],"con":true,"img":false,"tv":49.38}]}
{"op":"mcm","clk":"1144919082","pt":1439830407469,"mc":[{"id":"1.120089104","rc":[{"atb":[[4,0]],"id":9480385}],"con":true,"img":false,"tv":49.38}]}
{"op":"mcm","clk":"1144919088","pt":1439830407582,"mc":[{"id":"1.120089104","rc":[{"atb":[[4.2,1.98]],"id":9480385}],"con":true,"img":false,"tv":49.38}]}
{"op":"mcm","clk":"1144920738","pt":1439830430742,"mc":[{"id":"1.120089104","rc":[{"atl":[[19,0]],"id":9612932}],"con":true,"img":false,"tv":49.38}]}
{"op":"mcm","clk":"1144920746","pt":1439830430809,"mc":[{"id":"1.120089104","rc":[{"atl":[[1.39,9.22]],"id":9612932}],"con":true,"img":false,"tv":49.38}]}
{"op":"mcm","clk":"1144920753","pt":1439830430908,"mc":[{"id":"1.120089104","rc":[{"atb":[[2.3,0]],"id":9480385}],"con":true,"img":false,"tv":49.38}]}
{"op":"mcm","clk":"1144920759","pt":1439830431015,"mc":[{"id":"1.120089104","rc":[{"atb":[[4.2,8.06]],"id":9480385}],"con":true,"img":false,"tv":49.38}]}
{"op":"mcm","clk":"1144920768","pt":1439830431123,"mc":[{"id":"1.120089104","rc":[{"atl":[[970,0]],"id":9480385}],"con":true,"img":false,"tv":49.38}]}
{"op":"mcm","clk":"1144920783","pt":1439830431344,"mc":[{"id":"1.120089104","rc":[{"atl":[[940,2.56]],"id":9480385}],"con":true,"img":false,"tv":49.38}]}
{"op":"mcm","clk":"1144920997","pt":1439830434442,"mc":[{"id":"1.120089104","rc":[{"atb":[[4.1,0]],"id":9480385}],"con":true,"img":false,"tv":49.38}]}
{"op":"mcm","clk":"1144921011","pt":1439830434656,"mc":[{"id":"1.120089104","rc":[{"atb":[[4.3,3.63]],"id":9480385}],"con":true,"img":false,"tv":49.38}]}
{"op":"mcm","clk":"1144921205","pt":1439830437232,"mc":[{"id":"1.120089104","rc":[{"atl":[[950,0]],"id":9480385}],"con":true,"img":false,"tv":49.38}]}
{"op":"mcm","clk":"1144921210","pt":1439830437335,"mc":[{"id":"1.120089104","rc":[{"atl":[[920,15]],"id":9480385}],"con":true,"img":false,"tv":49.38}]}
{"op":"mcm","clk":"1144944444","pt":1439830761441,"mc":[{"id":"1.120089104","rc":[{"spn":1.31,"spf":"NaN","id":9612932},{"atb":[[2.74,0]],"id":9480385},{"spn":317.15,"spf":"NaN","id":9480385}],"con":true,"img":false,"tv":49.38}]}
{"op":"mcm","clk":"1144944455","pt":1439830761554,"mc":[{"id":"1.120089104","rc":[{"atb":[[4.4,0.88]],"id":9480385}],"con":true,"img":false,"tv":49.38}]}
{"op":"mcm","clk":"1144944693","pt":1439830764777,"mc":[{"id":"1.120089104","rc":[{"atb":[[1.23,0]],"id":9612932}],"con":true,"img":false,"tv":49.38}]}
{"op":"mcm","clk":"1144944700","pt":1439830764878,"mc":[{"id":"1.120089104","rc":[{"atb":[[1.25,0.88]],"id":9612932}],"con":true,"img":false,"tv":49.38}]}
{"op":"mcm","clk":"1144958681","pt":1439830919812,"mc":[{"id":"1.120089104","rc":[{"atb":[[1.24,1.98],[1.14,15.13],[1.01,729.78]],"id":9612932},{"atl":[[1.39,9.22]],"id":9612932},{"spn":1.32,"spf":"NaN","id":9612932},{"atb":[[2.62,1.41],[4.3,3.63],[1.01,727.78],[2.22,12.07],[4.2,8.06]],"id":9480385},{"atl":[[940,2.56]],"id":9480385},{"spn":317.2,"spf":"NaN","id":9480385}],"con":true,"img":false,"tv":49.38}]}
{"op":"mcm","clk":"1144958695","pt":1439830919924,"mc":[{"id":"1.120089104","rc":[{"atb":[[1.02,251.99]],"id":9612932}],"con":true,"img":false,"tv":49.38}]}
{"op":"mcm","clk":"1144959026","pt":1439830923063,"mc":[{"id":"1.120089104","rc":[{"atb":[[2.8,0]],"id":9480385}],"con":true,"img":false,"tv":49.38}]}
{"op":"mcm","clk":"1144959040","pt":1439830923180,"mc":[{"id":"1.120089104","rc":[{"atb":[[1.02,251.99]],"id":9480385}],"con":true,"img":false,"tv":49.38}]}
{"op":"mcm","clk":"1144968613","pt":1439831013327,"mc":[{"id":"1.120089104","rc":[{"atb":[[1.12,0]],"id":9612932},{"atb":[[2.26,0]],"id":9480385}],"con":true,"img":false,"tv":49.38}]}
{"op":"mcm","clk":"1144968622","pt":1439831013436,"mc":[{"id":"1.120089104","rc":[{"atb":[[1.09,240]],"id":9612932},{"atb":[[2.92,175]],"id":9480385}],"con":true,"img":false,"tv":49.38}]}
{"op":"mcm","clk":"1144968639","pt":1439831013598,"mc":[{"id":"1.120089104","rc":[{"atb":[[1.08,10]],"id":9612932},{"atb":[[1.76,0]],"id":9480385}],"con":true,"img":false,"tv":49.38}]}
{"op":"mcm","clk":"1144968665","pt":1439831013827,"mc":[{"id":"1.120089104","rc":[{"atb":[[1.06,5840]],"id":9612932},{"atb":[[2.16,30]],"id":9480385}],"con":true,"img":false,"tv":49.38}]}
{"op":"mcm","clk":"1144970841","pt":1439831033753,"mc":[{"id":"1.120089104","rc":[{"trd":[[1.24,3.96],[1.25,1.76]],"ltp":1.24,"tv":5.72,"id":9612932},{"atb":[[1.24,0],[1.25,0]],"id":9612932},{"atl":[[1.24,97.14]],"id":9612932}],"con":true,"img":false,"tv":55.1}]}
{"op":"mcm","clk":"1144971431","pt":1439831039750,"mc":[{"id":"1.120089104","rc":[{"atb":[[1.15,66.15]],"id":9612932}],"con":true,"img":false,"tv":55.1}]}
{"op":"mcm","clk":"1144971458","pt":1439831039929,"mc":[{"id":"1.120089104","rc":[{"atb":[[4.2,6.08]],"id":9480385}],"con":true,"img":false,"tv":55.1}]}
{"op":"mcm","clk":"1144971468","pt":1439831040038,"mc":[{"id":"1.120089104","rc":[{"atb":[[4.4,2.86]],"id":9480385}],"con":true,"img":false,"tv":55.1}]}
{"op":"mcm","clk":"1144973334","pt":1439831056929,"mc":[{"id":"1.120089104","rc":[{"atb":[[4.3,0]],"id":9480385}],"con":true,"img":false,"tv":55.1}]}
{"op":"mcm","clk":"1144973357","pt":1439831057089,"mc":[{"id":"1.120089104","rc":[{"atb":[[4.5,3.47]],"id":9480385}],"con":true,"img":false,"tv":55.1}]}
{"op":"mcm","clk":"1144973527","pt":1439831058711,"mc":[{"id":"1.120089104","rc":[{"atl":[[1.24,0]],"id":9612932}],"con":true,"img":false,"tv":55.1}]}
{"op":"mcm","clk":"1144982823","pt":1439831065508,"mc":[{"id":"1.120089104","rc":[{"atb":[[4.4,0.88]],"id":9480385}],"con":true,"img":false,"tv":55.1}]}
{"op":"mcm","clk":"1144982838","pt":1439831065621,"mc":[{"id":"1.120089104","rc":[{"atb":[[4.6,1.98]],"id":9480385}],"con":true,"img":false,"tv":55.1}]}
{"op":"mcm","clk":"1144985257","pt":1439831089733,"mc":[{"id":"1.120089104","rc":[{"atb":[[1.1,6]],"id":9612932},{"spn":1.27,"spf":"NaN","id":9612932},{"spn":317.3,"spf":"NaN","id":9480385}],"con":true,"img":false,"tv":55.1}]}
{"op":"mcm","clk":"1144985592","pt":1439831092946,"mc":[{"id":"1.120089104","rc":[{"atb":[[1.07,6]],"id":9612932}],"con":true,"img":false,"tv":55.1}]}
{"op":"mcm","clk":"1144985617","pt":1439831093160,"mc":[{"id":"1.120089104","rc":[{"atb":[[4.5,0]],"id":9480385}],"con":true,"img":false,"tv":55.1}]}
{"op":"mcm","clk":"1144985632","pt":1439831093325,"mc":[{"id":"1.120089104","rc":[{"atb":[[4.7,3.32]],"id":9480385}],"con":true,"img":false,"tv":55.1}]}
{"op":"mcm","clk":"1144986360","pt":1439831100040,"mc":[{"id":"1.120089104","rc":[{"atb":[[4.6,0]],"id":9480385}],"con":true,"img":false,"tv":55.1}]}
{"op":"mcm","clk":"1144986370","pt":1439831100146,"mc":[{"id":"1.120089104","rc":[{"atb":[[4.8,1.98]],"id":9480385}],"con":true,"img":false,"tv":55.1}]}
{"op":"mcm","clk":"1144992770","pt":1439831162356,"mc":[{"id":"1.120089104","rc":[{"atb":[[4.7,0]],"id":9480385},{"spn":317.4,"spf":"NaN","id":9480385}],"con":true,"img":false,"tv":55.1}]}
{"op":"mcm","clk":"1144992793","pt":1439831162567,"mc":[{"id":"1.120089104","rc":[{"atb":[[4.9,3.19]],"id":9480385}],"con":true,"img":false,"tv":55.1}]}
{"op":"mcm","clk":"1144993375","pt":1439831168404,"mc":[{"id":"1.120089104","rc":[{"atb":[[4.8,0]],"id":9480385}],"con":true,"img":false,"tv":55.1}]}
{"op":"mcm","clk":"1144993384","pt":1439831168564,"mc":[{"id":"1.120089104","rc":[{"atb":[[5,1.98]],"id":9480385}],"con":true,"img":false,"tv":55.1}]}
{"op":"mcm","clk":"1144996337","pt":1439831196093,"mc":[{"id":"1.120089104","rc":[{"atb":[[4.9,0]],"id":9480385}],"con":true,"img":false,"tv":55.1}]}
{"op":"mcm","clk":"1144996355","pt":1439831196303,"mc":[{"id":"1.120089104","rc":[{"atb":[[5.1,3.06]],"id":9480385}],"con":true,"img":false,"tv":55.1}]}
{"op":"mcm","clk":"1144996924","pt":1439831201717,"mc":[{"id":"1.120089104","rc":[{"atb":[[5,0]],"id":9480385}],"con":true,"img":false,"tv":55.1}]}
{"op":"mcm","clk":"1144996931","pt":1439831201878,"mc":[{"id":"1.120089104","rc":[{"atb":[[5.2,1.98]],"id":9480385}],"con":true,"img":false,"tv":55.1}]}
{"op":"mcm","clk":"1145036416","pt":1439831564069,"mc":[{"id":"1.120089104","rc":[{"atb":[[4.4,0]],"id":9480385},{"spn":317.6,"spf":"NaN","id":9480385}],"con":true,"img":false,"tv":55.1}]}
{"op":"mcm","clk":"1145036428","pt":1439831564128,"mc":[{"id":"1.120089104","rc":[{"atb":[[5.2,2.86]],"id":9480385}],"con":true,"img":false,"tv":55.1}]}
{"op":"mcm","clk":"1145055332","pt":1439831719370,"mc":[{"id":"1.120089104","rc":[{"atb":[[1.14,3.89]],"id":9612932}],"con":true,"img":false,"tv":55.1}]}
{"op":"mcm","clk":"1145055349","pt":1439831719487,"mc":[{"id":"1.120089104","rc":[{"atb":[[1.16,11.05]],"id":9612932}],"con":true,"img":false,"tv":55.1}]}
{"op":"mcm","clk":"1145055364","pt":1439831719598,"mc":[{"id":"1.120089104","rc":[{"atl":[[940,0]],"id":9480385}],"con":true,"img":false,"tv":55.1}]}
{"op":"mcm","clk":"1145055374","pt":1439831719686,"mc":[{"id":"1.120089104","rc":[{"atl":[[910,2.56]],"id":9480385}],"con":true,"img":false,"tv":55.1}]}
{"op":"mcm","clk":"1145055866","pt":1439831723946,"mc":[{"id":"1.120089104","rc":[{"atb":[[1.15,22]],"id":9612932}],"con":true,"img":false,"tv":55.1}]}
{"op":"mcm","clk":"1145055879","pt":1439831724053,"mc":[{"id":"1.120089104","rc":[{"atb":[[1.17,44.15]],"id":9612932}],"con":true,"img":false,"tv":55.1}]}
{"op":"mcm","clk":"1145061446","pt":1439831770859,"mc":[{"id":"1.120089104","rc":[{"atl":[[920,0]],"id":9480385}],"con":true,"img":false,"tv":55.1}]}
{"op":"mcm","clk":"1145061463","pt":1439831770939,"mc":[{"id":"1.120089104","rc":[{"atl":[[890,15]],"id":9480385}],"con":true,"img":false,"tv":55.1}]}
{"op":"mcm","clk":"1145086989","pt":1439831964995,"mc":[{"id":"1.120089104","marketDefinition":{"bspMarket":true,"turnInPlayEnabled":true,"persistenceEnabled":true,"marketBaseRate":5.0,"eventId":"27514783","eventTypeId":"7","numberOfWinners":1,"bettingType":"ODDS","marketType":"WIN","marketTime":"2015-08-18T20:20:00.000Z","suspendTime":"2015-08-18T20:20:00.000Z","bspReconciled":false,"complete":true,"inPlay":false,"crossMatching":false,"runnersVoidable":false,"numberOfActiveRunners":2,"betDelay":0,"status":"OPEN","runners":[{"adjustmentFactor":79.72,"status":"ACTIVE","sortPriority":1,"id":9612932,"name":"Alinstante"},{"adjustmentFactor":20.27,"status":"ACTIVE","sortPriority":2,"id":9480385,"name":"Vallance Road"}],"regulators":["MR_INT"],"venue":"Chelmsford City","countryCode":"GB","discountAllowed":false,"timezone":"Europe/London","openDate":"2015-08-18T17:20:00.000Z","version":1060767560,"name":"1m Cond Stks","eventName":"ChelmC 18th Aug"},"rc":[{"trd":[[1.24,3.96],[1.4,49.38],[1.25,1.76]],"ltp":1.24,"tv":55.1,"id":9612932},{"atb":[[1.17,44.15],[1.1,6],[1.16,11.05],[1.08,10],[1.06,5840],[1.14,3.89],[1.07,6],[1.13,33],[1.01,729.78],[1.15,22],[1.09,240],[1.02,251.99]],"id":9612932},{"atl":[[1.69,15],[19.5,11],[630,0.09],[1.4,20],[1.8,1.9],[1.39,9.22]],"id":9612932},{"spn":1.28,"spf":"NaN","id":9612932},{"atb":[[2.62,1.41],[2.6,1.9],[1.06,20],[3.75,15],[1.81,12.35],[2.28,37],[1.01,727.78],[1.02,251.99],[2.76,1.99],[5.2,2.86],[2.16,30],[1.08,10],[2.22,12.07],[4.2,6.08],[5.1,3.06],[2.92,175]],"id":9480385},{"atl":[[890,15],[630,0.09],[910,2.56]],"id":9480385},{"spn":317.6,"spf":"NaN","id":9480385}],"con":true,"img":true,"tv":55.1}]}
{"op":"mcm","clk":"1145105636","pt":1439832102670,"mc":[{"id":"1.120089104","rc":[{"atb":[[1.14,1.9]],"id":9612932},{"spn":1.28,"spf":"NaN","id":9612932},{"atb":[[2.76,0]],"id":9480385}],"con":true,"img":false,"tv":55.1}]}
{"op":"mcm","clk":"1145105645","pt":1439832102776,"mc":[{"id":"1.120089104","rc":[{"atb":[[1.18,1.99]],"id":9612932},{"atb":[[5.3,1.99]],"id":9480385}],"con":true,"img":false,"tv":55.1}]}
{"op":"mcm","clk":"1145105885","pt":1439832105691,"mc":[{"id":"1.120089104","rc":[{"atb":[[1.07,0]],"id":9612932}],"con":true,"img":false,"tv":55.1}]}
{"op":"mcm","clk":"1145109982","pt":1439832149935,"mc":[{"id":"1.120089104","rc":[{"atb":[[1.18,4.03]],"id":9612932}],"con":true,"img":false,"tv":55.1}]}
{"op":"mcm","clk":"1145113440","pt":1439832185422,"mc":[{"id":"1.120089104","rc":[{"atb":[[1.14,0]],"id":9612932},{"spn":1.28,"spf":"NaN","id":9612932},{"spn":317.65,"spf":"NaN","id":9480385}],"con":true,"img":false,"tv":55.1}]}
{"op":"mcm","clk":"1145113445","pt":1439832185526,"mc":[{"id":"1.120089104","rc":[{"atb":[[1.18,5.93]],"id":9612932}],"con":true,"img":false,"tv":55.1}]}
{"op":"mcm","clk":"1145126959","pt":1439832323139,"mc":[{"id":"1.120089104","rc":[{"atl":[[1.4,0]],"id":9612932}],"con":true,"img":false,"tv":55.1}]}
{"op":"mcm","clk":"1145174648","pt":1439832769887,"mc":[{"id":"1.120089104","rc":[{"atb":[[1.16,0]],"id":9612932}],"con":true,"img":false,"tv":55.1}]}
{"op":"mcm","clk":"1145174659","pt":1439832770002,"mc":[{"id":"1.120089104","rc":[{"atb":[[1.19,10.78]],"id":9612932}],"con":true,"img":false,"tv":55.1}]}
{"op":"mcm","clk":"1145174665","pt":1439832770095,"mc":[{"id":"1.120089104","rc":[{"atl":[[1.39,0]],"id":9612932}],"con":true,"img":false,"tv":55.1}]}
{"op":"mcm","clk":"1145174680","pt":1439832770169,"mc":[{"id":"1.120089104","rc":[{"atl":[[1.68,7.63]],"id":9612932}],"con":true,"img":false,"tv":55.1}]}
{"op":"mcm","clk":"1145174686","pt":1439832770263,"mc":[{"id":"1.120089104","rc":[{"atl":[[910,0]],"id":9480385}],"con":true,"img":false,"tv":55.1}]}
{"op":"mcm","clk":"1145174709","pt":1439832770485,"mc":[{"id":"1.120089104","rc":[{"atl":[[880,2.56]],"id":9480385}],"con":true,"img":false,"tv":55.1}]}
{"op":"mcm","clk":"1145175101","pt":1439832773943,"mc":[{"id":"1.120089104","rc":[{"atb":[[1.18,3.94]],"id":9612932}],"con":true,"img":false,"tv":55.1}]}
{"op":"mcm","clk":"1145175109","pt":1439832774087,"mc":[{"id":"1.120089104","rc":[{"atb":[[1.2,1.99]],"id":9612932}],"con":true,"img":false,"tv":55.1}]}
{"op":"mcm","clk":"1145180320","pt":1439832820160,"mc":[{"id":"1.120089104","rc":[{"atl":[[890,0]],"id":9480385}],"con":true,"img":false,"tv":55.1}]}
{"op":"mcm","clk":"1145180333","pt":1439832820274,"mc":[{"id":"1.120089104","rc":[{"atl":[[860,15]],"id":9480385}],"con":true,"img":false,"tv":55.1}]}
{"op":"mcm","clk":"1145188542","pt":1439832864929,"mc":[{"id":"1.120089104","marketDefinition":{"bspMarket":true,"turnInPlayEnabled":true,"persistenceEnabled":true,"marketBaseRate":5.0,"eventId":"27514783","eventTypeId":"7","numberOfWinners":1,"bettingType":"ODDS","marketType":"WIN","marketTime":"2015-08-18T20:20:00.000Z","suspendTime":"2015-08-18T20:20:00.000Z","bspReconciled":false,"complete":true,"inPlay":false,"crossMatching":false,"runnersVoidable":false,"numberOfActiveRunners":2,"betDelay":0,"status":"OPEN","runners":[{"adjustmentFactor":79.72,"status":"ACTIVE","sortPriority":1,"id":9612932,"name":"Alinstante"},{"adjustmentFactor":20.27,"status":"ACTIVE","sortPriority":2,"id":9480385,"name":"Vallance Road"}],"regulators":["MR_INT"],"venue":"Chelmsford City","countryCode":"GB","discountAllowed":false,"timezone":"Europe/London","openDate":"2015-08-18T17:20:00.000Z","version":1060767560,"name":"1m Cond Stks","eventName":"ChelmC 18th Aug"},"rc":[{"trd":[[1.24,3.96],[1.4,49.38],[1.25,1.76]],"ltp":1.24,"tv":55.1,"id":9612932},{"atb":[[1.17,44.15],[1.1,6],[1.08,10],[1.18,3.94],[1.06,5840],[1.2,1.99],[1.19,10.78],[1.13,33],[1.01,729.78],[1.15,22],[1.09,240],[1.02,251.99]],"id":9612932},{"atl":[[1.69,15],[19.5,11],[630,0.09],[1.8,1.9],[1.68,7.63]],"id":9612932},{"spn":1.44,"spf":"NaN","id":9612932},{"atb":[[2.62,1.41],[2.6,1.9],[1.06,20],[3.75,15],[1.81,12.35],[2.28,37],[1.01,727.78],[5.3,1.99],[1.02,251.99],[5.2,2.86],[2.16,30],[1.08,10],[2.22,12.07],[4.2,6.08],[5.1,3.06],[2.92,175]],"id":9480385},{"atl":[[880,2.56],[860,15],[630,0.09]],"id":9480385},{"spn":317.65,"spf":"NaN","id":9480385}],"con":true,"img":true,"tv":55.1}]}
{"op":"mcm","clk":"1145277350","pt":1439833629426,"mc":[{"id":"1.120089104","rc":[{"atl":[[1.8,0]],"id":9612932},{"spn":1.44,"spf":"NaN","id":9612932}],"con":true,"img":false,"tv":55.1}]}
{"op":"mcm","clk":"1145277361","pt":1439833629534,"mc":[{"id":"1.120089104","rc":[{"atl":[[1.67,1.9]],"id":9612932}],"con":true,"img":false,"tv":55.1}]}
{"op":"mcm","clk":"1145278252","pt":1439833637037,"mc":[{"id":"1.120089104","rc":[{"atb":[[1.18,2.04]],"id":9612932}],"con":true,"img":false,"tv":55.1}]}
{"op":"mcm","clk":"1145278259","pt":1439833637123,"mc":[{"id":"1.120089104","rc":[{"atb":[[1.2,3.89]],"id":9612932}],"con":true,"img":false,"tv":55.1}]}
{"op":"mcm","clk":"1145294237","pt":1439833764930,"mc":[{"id":"1.120089104","marketDefinition":{"bspMarket":true,"turnInPlayEnabled":true,"persistenceEnabled":true,"marketBaseRate":5.0,"eventId":"27514783","eventTypeId":"7","numberOfWinners":1,"bettingType":"ODDS","marketType":"WIN","marketTime":"2015-08-18T20:20:00.000Z","suspendTime":"2015-08-18T20:20:00.000Z","bspReconciled":false,"complete":true,"inPlay":false,"crossMatching":false,"runnersVoidable":false,"numberOfActiveRunners":2,"betDelay":0,"status":"OPEN","runners":[{"adjustmentFactor":79.72,"status":"ACTIVE","sortPriority":1,"id":9612932,"name":"Alinstante"},{"adjustmentFactor":20.27,"status":"ACTIVE","sortPriority":2,"id":9480385,"name":"Vallance Road"}],"regulators":["MR_INT"],"venue":"Chelmsford City","countryCode":"GB","discountAllowed":false,"timezone":"Europe/London","openDate":"2015-08-18T17:20:00.000Z","version":1060767560,"name":"1m Cond Stks","eventName":"ChelmC 18th Aug"},"rc":[{"trd":[[1.24,3.96],[1.4,49.38],[1.25,1.76]],"ltp":1.24,"tv":55.1,"id":9612932},{"atb":[[1.17,44.15],[1.1,6],[1.08,10],[1.18,2.04],[1.06,5840],[1.2,3.89],[1.19,10.78],[1.13,33],[1.01,729.78],[1.15,22],[1.09,240],[1.02,251.99]],"id":9612932},{"atl":[[1.69,15],[19.5,11],[630,0.09],[1.67,1.9],[1.68,7.63]],"id":9612932},{"spn":1.43,"spf":"NaN","id":9612932},{"atb":[[2.62,1.41],[2.6,1.9],[1.06,20],[3.75,15],[1.81,12.35],[2.28,37],[1.01,727.78],[5.3,1.99],[1.02,251.99],[5.2,2.86],[2.16,30],[1.08,10],[2.22,12.07],[4.2,6.08],[5.1,3.06],[2.92,175]],"id":9480385},{"atl":[[880,2.56],[860,15],[630,0.09]],"id":9480385},{"spn":317.65,"spf":"NaN","id":9480385}],"con":true,"img":true,"tv":55.1}]}
{"op":"mcm","clk":"1145305403","pt":1439833827678,"mc":[{"id":"1.120089104","rc":[{"spn":1.43,"spf":"NaN","id":9612932},{"atl":[[880,0]],"id":9480385}],"con":true,"img":false,"tv":55.1}]}
{"op":"mcm","clk":"1145305415","pt":1439833827787,"mc":[{"id":"1.120089104","rc":[{"atl":[[850,2.56]],"id":9480385}],"con":true,"img":false,"tv":55.1}]}
{"op":"mcm","clk":"1145307487","pt":1439833848806,"mc":[{"id":"1.120089104","rc":[{"atl":[[860,0]],"id":9480385}],"con":true,"img":false,"tv":55.1}]}
{"op":"mcm","clk":"1145307499","pt":1439833848914,"mc":[{"id":"1.120089104","rc":[{"atl":[[830,15]],"id":9480385}],"con":true,"img":false,"tv":55.1}]}
{"op":"mcm","clk":"1145324066","pt":1439834040310,"mc":[{"id":"1.120089104","rc":[{"atb":[[5.2,1.98]],"id":9480385}],"con":true,"img":false,"tv":55.1}]}
{"op":"mcm","clk":"1145324075","pt":1439834040420,"mc":[{"id":"1.120089104","rc":[{"atb":[[5.3,2.87]],"id":9480385}],"con":true,"img":false,"tv":55.1}]}
{"op":"mcm","clk":"1145361822","pt":1439834479605,"mc":[{"id":"1.120089104","rc":[{"atl":[[850,0]],"id":9480385}],"con":true,"img":false,"tv":55.1}]}
{"op":"mcm","clk":"1145361842","pt":1439834479815,"mc":[{"id":"1.120089104","rc":[{"atl":[[820,2.56]],"id":9480385}],"con":true,"img":false,"tv":55.1}]}
{"op":"mcm","clk":"1145366524","pt":1439834528892,"mc":[{"id":"1.120089104","rc":[{"atl":[[830,0]],"id":9480385}],"con":true,"img":false,"tv":55.1}]}
{"op":"mcm","clk":"1145366532","pt":1439834528997,"mc":[{"id":"1.120089104","rc":[{"atl":[[800,15]],"id":9480385}],"con":true,"img":false,"tv":55.1}]}
{"op":"mcm","clk":"1145409494","pt":1439834809909,"mc":[{"id":"1.120089104","rc":[{"atl":[[1.4,500]],"id":9612932},{"spn":1.3,"spf":"NaN","id":9612932}],"con":true,"img":false,"tv":55.1}]}
{"op":"mcm","clk":"1145430595","pt":1439834986531,"mc":[{"id":"1.120089104","rc":[{"atl":[[1.67,0]],"id":9612932}],"con":true,"img":false,"tv":55.1}]}
{"op":"mcm","clk":"1145430606","pt":1439834986591,"mc":[{"id":"1.120089104","rc":[{"atl":[[1.39,1.9]],"id":9612932}],"con":true,"img":false,"tv":55.1}]}
{"op":"mcm","clk":"1145446475","pt":1439835131491,"mc":[{"id":"1.120089104","rc":[{"atl":[[1.68,0]],"id":9612932},{"spn":1.29,"spf":"NaN","id":9612932}],"con":true,"img":false,"tv":55.1}]}
{"op":"mcm","clk":"1145446501","pt":1439835131711,"mc":[{"id":"1.120089104","rc":[{"atl":[[1.39,11.12]],"id":9612932}],"con":true,"img":false,"tv":55.1}]}
{"op":"mcm","clk":"1145446505","pt":1439835131805,"mc":[{"id":"1.120089104","rc":[{"atl":[[820,0]],"id":9480385}],"con":true,"img":false,"tv":55.1}]}
{"op":"mcm","clk":"1145446516","pt":1439835131914,"mc":[{"id":"1.120089104","rc":[{"atl":[[790,2.56]],"id":9480385}],"con":true,"img":false,"tv":55.1}]}
{"op":"mcm","clk":"1145450060","pt":1439835168328,"mc":[{"id":"1.120089104","rc":[{"atl":[[800,0]],"id":9480385}],"con":true,"img":false,"tv":55.1}]}
{"op":"mcm","clk":"1145450079","pt":1439835168444,"mc":[{"id":"1.120089104","rc":[{"atl":[[770,15]],"id":9480385}],"con":true,"img":false,"tv":55.1}]}
{"op":"mcm","clk":"1145457797","pt":1439835236320,"mc":[{"id":"1.120089104","rc":[{"atl":[[790,0]],"id":9480385}],"con":true,"img":false,"tv":55.1}]}
{"op":"mcm","clk":"1145457814","pt":1439835236435,"mc":[{"id":"1.120089104","rc":[{"atl":[[760,2.56]],"id":9480385}],"con":true,"img":false,"tv":55.1}]}
{"op":"mcm","clk":"1145462536","pt":1439835277723,"mc":[{"id":"1.120089104","rc":[{"atl":[[770,0]],"id":9480385}],"con":true,"img":false,"tv":55.1}]}
{"op":"mcm","clk":"1145462553","pt":1439835277843,"mc":[{"id":"1.120089104","rc":[{"atl":[[740,15]],"id":9480385}],"con":true,"img":false,"tv":55.1}]}
{"op":"mcm","clk":"1145493287","pt":1439835521978,"mc":[{"id":"1.120089104","rc":[{"atl":[[760,0]],"id":9480385}],"con":true,"img":false,"tv":55.1}]}
{"op":"mcm","clk":"1145493309","pt":1439835522194,"mc":[{"id":"1.120089104","rc":[{"atl":[[730,2.56]],"id":9480385}],"con":true,"img":false,"tv":55.1}]}
{"op":"mcm","clk":"1145496573","pt":1439835547130,"mc":[{"id":"1.120089104","rc":[{"atl":[[740,0]],"id":9480385}],"con":true,"img":false,"tv":55.1}]}
{"op":"mcm","clk":"1145496587","pt":1439835547238,"mc":[{"id":"1.120089104","rc":[{"atl":[[710,15]],"id":9480385}],"con":true,"img":false,"tv":55.1}]}
{"op":"mcm","clk":"1145805128","pt":1439837789893,"mc":[{"id":"1.120089104","rc":[{"atl":[[730,0]],"id":9480385}],"con":true,"img":false,"tv":55.1}]}
{"op":"mcm","clk":"1145805153","pt":1439837790060,"mc":[{"id":"1.120089104","rc":[{"atl":[[700,2.56]],"id":9480385}],"con":true,"img":false,"tv":55.1}]}
{"op":"mcm","clk":"1145807581","pt":1439837811791,"mc":[{"id":"1.120089104","rc":[{"atl":[[710,0]],"id":9480385}],"con":true,"img":false,"tv":55.1}]}
{"op":"mcm","clk":"1145807592","pt":1439837811898,"mc":[{"id":"1.120089104","rc":[{"atl":[[680,15]],"id":9480385}],"con":true,"img":false,"tv":55.1}]}
{"op":"mcm","clk":"1145826382","pt":1439837978253,"mc":[{"id":"1.120089104","rc":[{"atl":[[90,2]],"id":9480385},{"spn":47.65,"spf":"NaN","id":9480385}],"con":true,"img":false,"tv":55.1}]}
{"op":"mcm","clk":"1145826911","pt":1439837982733,"mc":[{"id":"1.120089104","rc":[{"atl":[[700,0]],"id":9480385}],"con":true,"img":false,"tv":55.1}]}
{"op":"mcm","clk":"1145826933","pt":1439837982908,"mc":[{"id":"1.120089104","rc":[{"atl":[[670,2.56]],"id":9480385}],"con":true,"img":false,"tv":55.1}]}
{"op":"mcm","clk":"1145831366","pt":1439838019592,"mc":[{"id":"1.120089104","rc":[{"atl":[[680,0]],"id":9480385}],"con":true,"img":false,"tv":55.1}]}
{"op":"mcm","clk":"1145831377","pt":1439838019689,"mc":[{"id":"1.120089104","rc":[{"atl":[[80,15]],"id":9480385}],"con":true,"img":false,"tv":55.1}]}
{"op":"mcm","clk":"1145837347","pt":1439838073782,"mc":[{"id":"1.120089104","rc":[{"atl":[[670,0]],"id":9480385},{"spn":42.65,"spf":"NaN","id":9480385}],"con":true,"img":false,"tv":55.1}]}
{"op":"mcm","clk":"1145837361","pt":1439838073871,"mc":[{"id":"1.120089104","rc":[{"atl":[[75,2.56]],"id":9480385}],"con":true,"img":false,"tv":55.1}]}
{"op":"mcm","clk":"1145838141","pt":1439838081190,"mc":[{"id":"1.120089104","rc":[{"atl":[[80,0]],"id":9480385}],"con":true,"img":false,"tv":55.1}]}
{"op":"mcm","clk":"1145838149","pt":1439838081282,"mc":[{"id":"1.120089104","rc":[{"atl":[[65,15]],"id":9480385}],"con":true,"img":false,"tv":55.1}]}
{"op":"mcm","clk":"1145862827","pt":1439838264801,"mc":[{"id":"1.120089104","marketDefinition":{"bspMarket":true,"turnInPlayEnabled":true,"persistenceEnabled":true,"marketBaseRate":5.0,"eventId":"27514783","eventTypeId":"7","numberOfWinners":1,"bettingType":"ODDS","marketType":"WIN","marketTime":"2015-08-18T20:20:00.000Z","suspendTime":"2015-08-18T20:20:00.000Z","bspReconciled":false,"complete":true,"inPlay":false,"crossMatching":false,"runnersVoidable":false,"numberOfActiveRunners":2,"betDelay":0,"status":"OPEN","runners":[{"adjustmentFactor":79.72,"status":"ACTIVE","sortPriority":1,"id":9612932,"name":"Alinstante"},{"adjustmentFactor":20.27,"status":"ACTIVE","sortPriority":2,"id":9480385,"name":"Vallance Road"}],"regulators":["MR_INT"],"venue":"Chelmsford City","countryCode":"GB","discountAllowed":false,"timezone":"Europe/London","openDate":"2015-08-18T17:20:00.000Z","version":1060767560,"name":"1m Cond Stks","eventName":"ChelmC 18th Aug"},"rc":[{"trd":[[1.24,3.96],[1.4,49.38],[1.25,1.76]],"ltp":1.24,"tv":55.1,"id":9612932},{"atb":[[1.17,44.15],[1.1,6],[1.08,10],[1.18,2.04],[1.06,5840],[1.2,3.89],[1.19,10.78],[1.13,33],[1.01,729.78],[1.15,22],[1.09,240],[1.02,251.99]],"id":9612932},{"atl":[[1.69,15],[19.5,11],[630,0.09],[1.4,500],[1.39,11.12]],"id":9612932},{"spn":1.29,"spf":"NaN","id":9612932},{"atb":[[2.62,1.41],[2.6,1.9],[1.06,20],[3.75,15],[1.81,12.35],[2.28,37],[1.01,727.78],[5.3,2.87],[1.02,251.99],[5.2,1.98],[2.16,30],[1.08,10],[2.22,12.07],[4.2,6.08],[5.1,3.06],[2.92,175]],"id":9480385},{"atl":[[65,15],[630,0.09],[75,2.56],[90,2]],"id":9480385},{"spn":35.15,"spf":"NaN","id":9480385}],"con":true,"img":true,"tv":55.1}]}
{"op":"mcm","clk":"1145920556","pt":1439838727964,"mc":[{"id":"1.120089104","rc":[{"atl":[[1.3,4.26]],"id":9612932},{"spn":1.25,"spf":"NaN","id":9612932},{"spn":35.15,"spf":"NaN","id":9480385}],"con":true,"img":false,"tv":55.1}]}
{"op":"mcm","clk":"1145920667","pt":1439838729113,"mc":[{"id":"1.120089104","rc":[{"atl":[[1.3,0]],"id":9612932}],"con":true,"img":false,"tv":55.1}]}
{"op":"mcm","clk":"1145940696","pt":1439838916630,"mc":[{"id":"1.120089104","rc":[{"spn":1.29,"spf":"NaN","id":9612932},{"atl":[[75,0]],"id":9480385}],"con":true,"img":false,"tv":55.1}]}
{"op":"mcm","clk":"1145940708","pt":1439838916739,"mc":[{"id":"1.120089104","rc":[{"atl":[[60,2.56]],"id":9480385}],"con":true,"img":false,"tv":55.1}]}
{"op":"mcm","clk":"1145946526","pt":1439838972154,"mc":[{"id":"1.120089104","rc":[{"atl":[[65,0]],"id":9480385}],"con":true,"img":false,"tv":55.1}]}
{"op":"mcm","clk":"1145946548","pt":1439838972282,"mc":[{"id":"1.120089104","rc":[{"atl":[[50,15]],"id":9480385}],"con":true,"img":false,"tv":55.1}]}
{"op":"mcm","clk":"1145970326","pt":1439839164874,"mc":[{"id":"1.120089104","marketDefinition":{"bspMarket":true,"turnInPlayEnabled":true,"persistenceEnabled":true,"marketBaseRate":5.0,"eventId":"27514783","eventTypeId":"7","numberOfWinners":1,"bettingType":"ODDS","marketType":"WIN","marketTime":"2015-08-18T20:20:00.000Z","suspendTime":"2015-08-18T20:20:00.000Z","bspReconciled":false,"complete":true,"inPlay":false,"crossMatching":false,"runnersVoidable":false,"numberOfActiveRunners":2,"betDelay":0,"status":"OPEN","runners":[{"adjustmentFactor":79.72,"status":"ACTIVE","sortPriority":1,"id":9612932,"name":"Alinstante"},{"adjustmentFactor":20.27,"status":"ACTIVE","sortPriority":2,"id":9480385,"name":"Vallance Road"}],"regulators":["MR_INT"],"venue":"Chelmsford City","countryCode":"GB","discountAllowed":false,"timezone":"Europe/London","openDate":"2015-08-18T17:20:00.000Z","version":1060767560,"name":"1m Cond Stks","eventName":"ChelmC 18th Aug"},"rc":[{"trd":[[1.24,3.96],[1.4,49.38],[1.25,1.76]],"ltp":1.24,"tv":55.1,"id":9612932},{"atb":[[1.17,44.15],[1.1,6],[1.08,10],[1.18,2.04],[1.06,5840],[1.2,3.89],[1.19,10.78],[1.13,33],[1.01,729.78],[1.15,22],[1.09,240],[1.02,251.99]],"id":9612932},{"atl":[[1.69,15],[19.5,11],[630,0.09],[1.4,500],[1.39,11.12]],"id":9612932},{"spn":1.29,"spf":"NaN","id":9612932},{"atb":[[2.62,1.41],[2.6,1.9],[1.06,20],[3.75,15],[1.81,12.35],[2.28,37],[1.01,727.78],[5.3,2.87],[1.02,251.99],[5.2,1.98],[2.16,30],[1.08,10],[2.22,12.07],[4.2,6.08],[5.1,3.06],[2.92,175]],"id":9480385},{"atl":[[630,0.09],[90,2],[60,2.56],[50,15]],"id":9480385},{"spn":27.65,"spf":"NaN","id":9480385}],"con":true,"img":true,"tv":55.1}]}
{"op":"mcm","clk":"1146037305","pt":1439839693887,"mc":[{"id":"1.120089104","rc":[{"atl":[[60,0]],"id":9480385},{"spn":27.65,"spf":"NaN","id":9480385}],"con":true,"img":false,"tv":55.1}]}
{"op":"mcm","clk":"1146037314","pt":1439839693998,"mc":[{"id":"1.120089104","rc":[{"atl":[[48,2.56]],"id":9480385}],"con":true,"img":false,"tv":55.1}]}
{"op":"mcm","clk":"1146039039","pt":1439839708169,"mc":[{"id":"1.120089104","rc":[{"atl":[[50,0]],"id":9480385}],"con":true,"img":false,"tv":55.1}]}
{"op":"mcm","clk":"1146039052","pt":1439839708281,"mc":[{"id":"1.120089104","rc":[{"atl":[[44,15]],"id":9480385}],"con":true,"img":false,"tv":55.1}]}
{"op":"mcm","clk":"1146081565","pt":1439840064850,"mc":[{"id":"1.120089104","marketDefinition":{"bspMarket":true,"turnInPlayEnabled":true,"persistenceEnabled":true,"marketBaseRate":5.0,"eventId":"27514783","eventTypeId":"7","numberOfWinners":1,"bettingType":"ODDS","marketType":"WIN","marketTime":"2015-08-18T20:20:00.000Z","suspendTime":"2015-08-18T20:20:00.000Z","bspReconciled":false,"complete":true,"inPlay":false,"crossMatching":false,"runnersVoidable":false,"numberOfActiveRunners":2,"betDelay":0,"status":"OPEN","runners":[{"adjustmentFactor":79.72,"status":"ACTIVE","sortPriority":1,"id":9612932,"name":"Alinstante"},{"adjustmentFactor":20.27,"status":"ACTIVE","sortPriority":2,"id":9480385,"name":"Vallance Road"}],"regulators":["MR_INT"],"venue":"Chelmsford City","countryCode":"GB","discountAllowed":false,"timezone":"Europe/London","openDate":"2015-08-18T17:20:00.000Z","version":1060767560,"name":"1m Cond Stks","eventName":"ChelmC 18th Aug"},"rc":[{"trd":[[1.24,3.96],[1.4,49.38],[1.25,1.76]],"ltp":1.24,"tv":55.1,"id":9612932},{"atb":[[1.17,44.15],[1.1,6],[1.08,10],[1.18,2.04],[1.06,5840],[1.2,3.89],[1.19,10.78],[1.13,33],[1.01,729.78],[1.15,22],[1.09,240],[1.02,251.99]],"id":9612932},{"atl":[[1.69,15],[19.5,11],[630,0.09],[1.4,500],[1.39,11.12]],"id":9612932},{"spn":1.29,"spf":"NaN","id":9612932},{"atb":[[2.62,1.41],[2.6,1.9],[1.06,20],[3.75,15],[1.81,12.35],[2.28,37],[1.01,727.78],[5.3,2.87],[1.02,251.99],[5.2,1.98],[2.16,30],[1.08,10],[2.22,12.07],[4.2,6.08],[5.1,3.06],[2.92,175]],"id":9480385},{"atl":[[44,15],[630,0.09],[90,2],[48,2.56]],"id":9480385},{"spn":24.65,"spf":"NaN","id":9480385}],"con":true,"img":true,"tv":55.1}]}
{"op":"mcm","clk":"1146145291","pt":1439840616214,"mc":[{"id":"1.120089104","rc":[{"atl":[[48,0]],"id":9480385},{"spn":24.65,"spf":"NaN","id":9480385}],"con":true,"img":false,"tv":55.1}]}
{"op":"mcm","clk":"1146145310","pt":1439840616426,"mc":[{"id":"1.120089104","rc":[{"atl":[[42,2.56]],"id":9480385}],"con":true,"img":false,"tv":55.1}]}
{"op":"mcm","clk":"1146146994","pt":1439840635417,"mc":[{"id":"1.120089104","rc":[{"atl":[[44,0]],"id":9480385}],"con":true,"img":false,"tv":55.1}]}
{"op":"mcm","clk":"1146147006","pt":1439840635519,"mc":[{"id":"1.120089104","rc":[{"atl":[[38,15]],"id":9480385}],"con":true,"img":false,"tv":55.1}]}
{"op":"mcm","clk":"1146159407","pt":1439840772966,"mc":[{"id":"1.120089104","rc":[{"atl":[[1000,2]],"id":9612932},{"spn":21.65,"spf":"NaN","id":9480385}],"con":true,"img":false,"tv":55.1}]}
{"op":"mcm","clk":"1146159679","pt":1439840775961,"mc":[{"id":"1.120089104","rc":[{"atl":[[1000,3]],"id":9612932}],"con":true,"img":false,"tv":55.1}]}
{"op":"mcm","clk":"1146160512","pt":1439840785089,"mc":[{"id":"1.120089104","rc":[{"atl":[[1000,1]],"id":9612932}],"con":true,"img":false,"tv":55.1}]}
{"op":"mcm","clk":"1146192224","pt":1439841041826,"mc":[{"id":"1.120089104","rc":[{"atl":[[1.38,500]],"id":9612932},{"spn":1.29,"spf":"NaN","id":9612932}],"con":true,"img":false,"tv":55.1}]}
{"op":"mcm","clk":"1146244566","pt":1439841645377,"mc":[{"id":"1.120089104","rc":[{"trd":[[1.24,3.96]],"ltp":1.24,"tv":3.96,"id":9612932},{"atb":[[1.17,44.19],[1.19,10.78],[1.01,729.96]],"id":9612932},{"atl":[[1.39,1.9]],"id":9612932},{"atb":[[2.62,1.41],[1.01,727.96],[5.2,1.98],[2.22,12.08],[4.2,6.08],[5.1,3.06]],"id":9480385},{"atl":[[42,2.56]],"id":9480385}],"con":true,"img":false,"tv":55.1}]}
{"op":"mcm","clk":"1146244577","pt":1439841645587,"mc":[{"id":"1.120089104","rc":[{"atl":[[1.37,9.36]],"id":9612932}],"con":true,"img":false,"tv":55.1}]}
{"op":"mcm","clk":"1146244583","pt":1439841645643,"mc":[{"id":"1.120089104","rc":[{"atl":[[42,0]],"id":9480385}],"con":true,"img":false,"tv":55.1}]}
{"op":"mcm","clk":"1146244590","pt":1439841645748,"mc":[{"id":"1.120089104","rc":[{"atl":[[36,2.56]],"id":9480385}],"con":true,"img":false,"tv":55.1}]}
{"op":"mcm","clk":"1146246978","pt":1439841680481,"mc":[{"id":"1.120089104","rc":[{"atl":[[38,0]],"id":9480385}],"con":true,"img":false,"tv":55.1}]}
{"op":"mcm","clk":"1146246986","pt":1439841680538,"mc":[{"id":"1.120089104","rc":[{"atl":[[32,15]],"id":9480385}],"con":true,"img":false,"tv":55.1}]}
{"op":"mcm","clk":"1146264824","pt":1439841864861,"mc":[{"id":"1.120089104","marketDefinition":{"bspMarket":true,"turnInPlayEnabled":true,"persistenceEnabled":true,"marketBaseRate":5.0,"eventId":"27514783","eventTypeId":"7","numberOfWinners":1,"bettingType":"ODDS","marketType":"WIN","marketTime":"2015-08-18T20:20:00.000Z","suspendTime":"2015-08-18T20:20:00.000Z","bspReconciled":false,"complete":true,"inPlay":false,"crossMatching":false,"runnersVoidable":false,"numberOfActiveRunners":2,"betDelay":0,"status":"OPEN","runners":[{"adjustmentFactor":79.72,"status":"ACTIVE","sortPriority":1,"id":9612932,"name":"Alinstante"},{"adjustmentFactor":20.27,"status":"ACTIVE","sortPriority":2,"id":9480385,"name":"Vallance Road"}],"regulators":["MR_INT"],"venue":"Chelmsford City","countryCode":"GB","discountAllowed":false,"timezone":"Europe/London","openDate":"2015-08-18T17:20:00.000Z","version":1060767560,"name":"1m Cond Stks","eventName":"ChelmC 18th Aug"},"rc":[{"trd":[[1.24,3.96],[1.4,49.38],[1.25,1.76]],"ltp":1.24,"tv":55.1,"id":9612932},{"atb":[[1.17,44.19],[1.1,6],[1.08,10],[1.18,2.04],[1.06,5840],[1.2,3.89],[1.19,10.78],[1.13,33],[1.01,729.96],[1.15,22],[1.09,240],[1.02,251.99]],"id":9612932},{"atl":[[1.69,15],[1.37,9.36],[19.5,11],[630,0.09],[1.4,500],[1000,1],[1.39,1.9],[1.38,500]],"id":9612932},{"spn":1.28,"spf":"NaN","id":9612932},{"atb":[[2.62,1.41],[2.6,1.9],[1.06,20],[3.75,15],[1.81,12.35],[2.28,37],[1.01,727.96],[5.3,2.87],[1.02,251.99],[5.2,1.98],[2.16,30],[1.08,10],[2.22,12.08],[4.2,6.08],[5.1,3.06],[2.92,175]],"id":9480385},{"atl":[[32,15],[36,2.56],[630,0.09],[90,2]],"id":9480385},{"spn":18.65,"spf":"NaN","id":9480385}],"con":true,"img":true,"tv":55.1}]}
{"op":"mcm","clk":"1146291709","pt":1439842092065,"mc":[{"id":"1.120089104","rc":[{"spn":1.28,"spf":"NaN","id":9612932},{"atl":[[36,0]],"id":9480385},{"spn":18.65,"spf":"NaN","id":9480385}],"con":true,"img":false,"tv":55.1}]}
{"op":"mcm","clk":"1146291731","pt":1439842092289,"mc":[{"id":"1.120089104","rc":[{"atl":[[30,2.56]],"id":9480385}],"con":true,"img":false,"tv":55.1}]}
{"op":"mcm","clk":"1146292165","pt":1439842097026,"mc":[{"id":"1.120089104","rc":[{"atl":[[32,0]],"id":9480385}],"con":true,"img":false,"tv":55.1}]}
{"op":"mcm","clk":"1146292174","pt":1439842097130,"mc":[{"id":"1.120089104","rc":[{"atl":[[28,15]],"id":9480385}],"con":true,"img":false,"tv":55.1}]}
{"op":"mcm","clk":"1146320171","pt":1439842385787,"mc":[{"id":"1.120089104","rc":[{"atl":[[30,0]],"id":9480385},{"spn":16.65,"spf":"NaN","id":9480385}],"con":true,"img":false,"tv":55.1}]}
{"op":"mcm","clk":"1146320182","pt":1439842385890,"mc":[{"id":"1.120089104","rc":[{"atl":[[27,2.56]],"id":9480385}],"con":true,"img":false,"tv":55.1}]}
{"op":"mcm","clk":"1146322268","pt":1439842407874,"mc":[{"id":"1.120089104","rc":[{"atl":[[28,0]],"id":9480385}],"con":true,"img":false,"tv":55.1}]}
{"op":"mcm","clk":"1146322276","pt":1439842407981,"mc":[{"id":"1.120089104","rc":[{"atl":[[25,15]],"id":9480385}],"con":true,"img":false,"tv":55.1}]}
{"op":"mcm","clk":"1146360586","pt":1439842764833,"mc":[{"id":"1.120089104","marketDefinition":{"bspMarket":true,"turnInPlayEnabled":true,"persistenceEnabled":true,"marketBaseRate":5.0,"eventId":"27514783","eventTypeId":"7","numberOfWinners":1,"bettingType":"ODDS","marketType":"WIN","marketTime":"2015-08-18T20:20:00.000Z","suspendTime":"2015-08-18T20:20:00.000Z","bspReconciled":false,"complete":true,"inPlay":false,"crossMatching":false,"runnersVoidable":false,"numberOfActiveRunners":2,"betDelay":0,"status":"OPEN","runners":[{"adjustmentFactor":79.72,"status":"ACTIVE","sortPriority":1,"id":9612932,"name":"Alinstante"},{"adjustmentFactor":20.27,"status":"ACTIVE","sortPriority":2,"id":9480385,"name":"Vallance Road"}],"regulators":["MR_INT"],"venue":"Chelmsford City","countryCode":"GB","discountAllowed":false,"timezone":"Europe/London","openDate":"2015-08-18T17:20:00.000Z","version":1060767560,"name":"1m Cond Stks","eventName":"ChelmC 18th Aug"},"rc":[{"trd":[[1.24,3.96],[1.4,49.38],[1.25,1.76]],"ltp":1.24,"tv":55.1,"id":9612932},{"atb":[[1.17,44.19],[1.1,6],[1.08,10],[1.18,2.04],[1.06,5840],[1.2,3.89],[1.19,10.78],[1.13,33],[1.01,729.96],[1.15,22],[1.09,240],[1.02,251.99]],"id":9612932},{"atl":[[1.69,15],[1.37,9.36],[19.5,11],[630,0.09],[1.4,500],[1000,1],[1.39,1.9],[1.38,500]],"id":9612932},{"spn":1.28,"spf":"NaN","id":9612932},{"atb":[[2.62,1.41],[2.6,1.9],[1.06,20],[3.75,15],[1.81,12.35],[2.28,37],[1.01,727.96],[5.3,2.87],[1.02,251.99],[5.2,1.98],[2.16,30],[1.08,10],[2.22,12.08],[4.2,6.08],[5.1,3.06],[2.92,175]],"id":9480385},{"atl":[[25,15],[27,2.56],[630,0.09],[90,2]],"id":9480385},{"spn":15.15,"spf":"NaN","id":9480385}],"con":true,"img":true,"tv":55.1}]}
{"op":"mcm","clk":"1146369734","pt":1439842800345,"mc":[{"id":"1.120089104","rc":[{"atb":[[1.02,5251.99]],"id":9612932},{"atb":[[1.02,5251.99]],"id":9480385},{"spn":15.15,"spf":"NaN","id":9480385}],"con":true,"img":false,"tv":55.1}]}
{"op":"mcm","clk":"1146370161","pt":1439842804137,"mc":[{"id":"1.120089104","rc":[{"atb":[[1.12,400],[1.1,406],[1.14,400]],"id":9612932},{"atb":[[4.4,60],[4.8,60],[4.6,60]],"id":9480385}],"con":true,"img":false,"tv":55.1}]}
{"op":"mcm","clk":"1146370198","pt":1439842804412,"mc":[{"id":"1.120089104","rc":[{"atb":[[4.9,6]],"id":9480385}],"con":true,"img":false,"tv":55.1}]}
{"op":"mcm","clk":"1146370222","pt":1439842804626,"mc":[{"id":"1.120089104","rc":[{"atb":[[4.7,6]],"id":9480385}],"con":true,"img":false,"tv":55.1}]}
{"op":"mcm","clk":"1146370246","pt":1439842804838,"mc":[{"id":"1.120089104","rc":[{"atb":[[4.5,6]],"id":9480385}],"con":true,"img":false,"tv":55.1}]}
{"op":"mcm","clk":"1146371030","pt":1439842812132,"mc":[{"id":"1.120089104","rc":[{"atl":[[24,1.42]],"id":9480385}],"con":true,"img":false,"tv":55.1}]}
{"op":"mcm","clk":"1146376131","pt":1439842860693,"mc":[{"id":"1.120089104","rc":[{"atb":[[4.2,0]],"id":9480385},{"spn":14.65,"spf":"NaN","id":9480385}],"con":true,"img":false,"tv":55.1}]}
{"op":"mcm","clk":"1146376143","pt":1439842860815,"mc":[{"id":"1.120089104","rc":[{"atb":[[5.4,4.72]],"id":9480385}],"con":true,"img":false,"tv":55.1}]}
{"op":"mcm","clk":"1146376165","pt":1439842861012,"mc":[{"id":"1.120089104","rc":[{"atl":[[27,0]],"id":9480385}],"con":true,"img":false,"tv":55.1}]}
{"op":"mcm","clk":"1146376179","pt":1439842861116,"mc":[{"id":"1.120089104","rc":[{"atl":[[24,3.98]],"id":9480385}],"con":true,"img":false,"tv":55.1}]}
{"op":"mcm","clk":"1146377598","pt":1439842874216,"mc":[{"id":"1.120089104","rc":[{"atl":[[25,0]],"id":9480385}],"con":true,"img":false,"tv":55.1}]}
{"op":"mcm","clk":"1146377611","pt":1439842874328,"mc":[{"id":"1.120089104","rc":[{"atl":[[22,15]],"id":9480385}],"con":true,"img":false,"tv":55.1}]}
{"op":"mcm","clk":"1146379785","pt":1439842894078,"mc":[{"id":"1.120089104","rc":[{"atb":[[5.3,0.88]],"id":9480385}],"con":true,"img":false,"tv":55.1}]}
{"op":"mcm","clk":"1146379797","pt":1439842894195,"mc":[{"id":"1.120089104","rc":[{"atb":[[5.5,1.99]],"id":9480385}],"con":true,"img":false,"tv":55.1}]}
{"op":"mcm","clk":"1146380725","pt":1439842902591,"mc":[{"id":"1.120089104","rc":[{"atl":[[24,2.56]],"id":9480385}],"con":true,"img":false,"tv":55.1}]}
{"op":"mcm","clk":"1146380749","pt":1439842902755,"mc":[{"id":"1.120089104","rc":[{"atl":[[21,1.42]],"id":9480385}],"con":true,"img":false,"tv":55.1}]}
{"op":"mcm","clk":"1146397323","pt":1439843077396,"mc":[{"id":"1.120089104","rc":[{"atb":[[5.4,0]],"id":9480385},{"spn":13.25,"spf":"NaN","id":9480385}],"con":true,"img":false,"tv":55.1}]}
{"op":"mcm","clk":"1146397344","pt":1439843077614,"mc":[{"id":"1.120089104","rc":[{"atb":[[5.4,4.72]],"id":9480385}],"con":true,"img":false,"tv":55.1}]}
{"op":"mcm","clk":"1146397350","pt":1439843077710,"mc":[{"id":"1.120089104","rc":[{"atl":[[24,0]],"id":9480385}],"con":true,"img":false,"tv":55.1}]}
{"op":"mcm","clk":"1146397378","pt":1439843077877,"mc":[{"id":"1.120089104","rc":[{"atl":[[21,3.98]],"id":9480385}],"con":true,"img":false,"tv":55.1}]}
{"op":"mcm","clk":"1146397915","pt":1439843083431,"mc":[{"id":"1.120089104","rc":[{"atl":[[22,0]],"id":9480385}],"con":true,"img":false,"tv":55.1}]}
{"op":"mcm","clk":"1146397927","pt":1439843083544,"mc":[{"id":"1.120089104","rc":[{"atl":[[19.5,15]],"id":9480385}],"con":true,"img":false,"tv":55.1}]}
{"op":"mcm","clk":"1146400671","pt":1439843113566,"mc":[{"id":"1.120089104","rc":[{"atl":[[21,2.56]],"id":9480385}],"con":true,"img":false,"tv":55.1}]}
{"op":"mcm","clk":"1146400683","pt":1439843113673,"mc":[{"id":"1.120089104","rc":[{"atl":[[19,1.42]],"id":9480385}],"con":true,"img":false,"tv":55.1}]}
{"op":"mcm","clk":"1146451667","pt":1439843664820,"mc":[{"id":"1.120089104","marketDefinition":{"bspMarket":true,"turnInPlayEnabled":true,"persistenceEnabled":true,"marketBaseRate":5.0,"eventId":"27514783","eventTypeId":"7","numberOfWinners":1,"bettingType":"ODDS","marketType":"WIN","marketTime":"2015-08-18T20:20:00.000Z","suspendTime":"2015-08-18T20:20:00.000Z","bspReconciled":false,"complete":true,"inPlay":false,"crossMatching":false,"runnersVoidable":false,"numberOfActiveRunners":2,"betDelay":0,"status":"OPEN","runners":[{"adjustmentFactor":79.72,"status":"ACTIVE","sortPriority":1,"id":9612932,"name":"Alinstante"},{"adjustmentFactor":20.27,"status":"ACTIVE","sortPriority":2,"id":9480385,"name":"Vallance Road"}],"regulators":["MR_INT"],"venue":"Chelmsford City","countryCode":"GB","discountAllowed":false,"timezone":"Europe/London","openDate":"2015-08-18T17:20:00.000Z","version":1060767560,"name":"1m Cond Stks","eventName":"ChelmC 18th Aug"},"rc":[{"trd":[[1.24,3.96],[1.4,49.38],[1.25,1.76]],"ltp":1.24,"tv":55.1,"id":9612932},{"atb":[[1.17,44.19],[1.18,2.04],[1.06,5840],[1.14,400],[1.01,729.96],[1.13,33],[1.15,22],[1.02,5251.99],[1.12,400],[1.1,406],[1.08,10],[1.2,3.89],[1.19,10.78],[1.09,240]],"id":9612932},{"atl":[[1.69,15],[1.37,9.36],[19.5,11],[630,0.09],[1.4,500],[1000,1],[1.39,1.9],[1.38,500]],"id":9612932},{"spn":1.28,"spf":"NaN","id":9612932},{"atb":[[2.62,1.41],[4.4,60],[2.6,1.9],[4.9,6],[5.4,4.72],[1.06,20],[3.75,15],[1.81,12.35],[2.28,37],[1.01,727.96],[4.8,60],[5.3,0.88],[1.02,5251.99],[5.2,1.98],[2.16,30],[1.08,10],[4.7,6],[2.22,12.08],[4.5,6],[5.1,3.06],[2.92,175],[5.5,1.99],[4.6,60]],"id":9480385},{"atl":[[19.5,15],[21,2.56],[630,0.09],[90,2],[19,1.42]],"id":9480385},{"spn":12.25,"spf":"NaN","id":9480385}],"con":true,"img":true,"tv":55.1}]}
{"op":"mcm","clk":"1146464930","pt":1439843756401,"mc":[{"id":"1.120089104","rc":[{"spl":[[1.01,10]],"id":9612932},{"spn":1.19,"spf":1.0,"id":9612932},{"spn":12.25,"spf":"NaN","id":9480385}],"con":true,"img":false,"tv":55.1}]}
{"op":"mcm","clk":"1146478042","pt":1439843913832,"mc":[{"id":"1.120089104","rc":[{"atl":[[1000,2.56]],"id":9480385}],"con":true,"img":false,"tv":55.1}]}
{"op":"mcm","clk":"1146478121","pt":1439843914697,"mc":[{"id":"1.120089104","rc":[{"atl":[[1000,0.5]],"id":9480385}],"con":true,"img":false,"tv":55.1}]}
{"op":"mcm","clk":"1146478142","pt":1439843914906,"mc":[{"id":"1.120089104","rc":[{"atl":[[1000,0]],"id":9480385}],"con":true,"img":false,"tv":55.1}]}
{"op":"mcm","clk":"1146478155","pt":1439843915017,"mc":[{"id":"1.120089104","rc":[{"atl":[[19,1.92]],"id":9480385}],"con":true,"img":false,"tv":55.1}]}
{"op":"mcm","clk":"1146493378","pt":1439844093623,"mc":[{"id":"1.120089104","rc":[{"atb":[[5.4,0]],"id":9480385}],"con":true,"img":false,"tv":55.1}]}
{"op":"mcm","clk":"1146493388","pt":1439844093753,"mc":[{"id":"1.120089104","rc":[{"atb":[[5.5,6.63]],"id":9480385}],"con":true,"img":false,"tv":55.1}]}
{"op":"mcm","clk":"1146493402","pt":1439844093852,"mc":[{"id":"1.120089104","rc":[{"atl":[[21,0]],"id":9480385}],"con":true,"img":false,"tv":55.1}]}
{"op":"mcm","clk":"1146493408","pt":1439844093950,"mc":[{"id":"1.120089104","rc":[{"atl":[[19,4.49]],"id":9480385}],"con":true,"img":false,"tv":55.1}]}
{"op":"mcm","clk":"1146494781","pt":1439844112026,"mc":[{"id":"1.120089104","rc":[{"atb":[[1.01,1730.45]],"id":9612932},{"atb":[[1.01,1728.45]],"id":9480385}],"con":true,"img":false,"tv":55.1}]}
{"op":"mcm","clk":"1146495635","pt":1439844123109,"mc":[{"id":"1.120089104","rc":[{"atl":[[19.5,0]],"id":9480385}],"con":true,"img":false,"tv":55.1}]}
{"op":"mcm","clk":"1146495644","pt":1439844123213,"mc":[{"id":"1.120089104","rc":[{"atl":[[18,15]],"id":9480385}],"con":true,"img":false,"tv":55.1}]}
{"op":"mcm","clk":"1146495706","pt":1439844123792,"mc":[{"id":"1.120089104","rc":[{"atl":[[1000,2.56],[19,3.98]],"id":9480385}],"con":true,"img":false,"tv":55.1}]}
{"op":"mcm","clk":"1146495761","pt":1439844124420,"mc":[{"id":"1.120089104","rc":[{"atl":[[1000,0.55]],"id":9480385}],"con":true,"img":false,"tv":55.1}]}
{"op":"mcm","clk":"1146495777","pt":1439844124629,"mc":[{"id":"1.120089104","rc":[{"atl":[[1000,0]],"id":9480385}],"con":true,"img":false,"tv":55.1}]}
{"op":"mcm","clk":"1146495786","pt":1439844124734,"mc":[{"id":"1.120089104","rc":[{"atl":[[17.5,0.55]],"id":9480385}],"con":true,"img":false,"tv":55.1}]}
{"op":"mcm","clk":"1146496787","pt":1439844137021,"mc":[{"id":"1.120089104","rc":[{"atl":[[19,2.56]],"id":9480385}],"con":true,"img":false,"tv":55.1}]}
{"op":"mcm","clk":"1146496800","pt":1439844137075,"mc":[{"id":"1.120089104","rc":[{"atl":[[17.5,1.97]],"id":9480385}],"con":true,"img":false,"tv":55.1}]}
{"op":"mcm","clk":"1146513471","pt":1439844379121,"mc":[{"id":"1.120089104","rc":[{"atl":[[1.3,200]],"id":9612932},{"spn":11.5,"spf":"NaN","id":9480385}],"con":true,"img":false,"tv":55.1}]}
{"op":"mcm","clk":"1146523158","pt":1439844513544,"mc":[{"id":"1.120089104","rc":[{"atl":[[1000,3]],"id":9612932}],"con":true,"img":false,"tv":55.1}]}
{"op":"mcm","clk":"1146523172","pt":1439844513749,"mc":[{"id":"1.120089104","rc":[{"atl":[[1000,1.25]],"id":9612932}],"con":true,"img":false,"tv":55.1}]}
{"op":"mcm","clk":"1146523185","pt":1439844513960,"mc":[{"id":"1.120089104","rc":[{"atl":[[1000,1]],"id":9612932}],"con":true,"img":false,"tv":55.1}]}
{"op":"mcm","clk":"1146523194","pt":1439844514069,"mc":[{"id":"1.120089104","rc":[{"atl":[[4,0.25]],"id":9612932}],"con":true,"img":false,"tv":55.1}]}
{"op":"mcm","clk":"1146545031","pt":1439844722894,"mc":[{"id":"1.120089104","rc":[{"spl":[[1.01,12]],"id":9612932},{"spn":1.19,"spf":1.0,"id":9612932}],"con":true,"img":false,"tv":55.1}]}
{"op":"mcm","clk":"1146562895","pt":1439845113260,"mc":[{"id":"1.120089104","rc":[{"atl":[[1.37,0]],"id":9612932}],"con":true,"img":false,"tv":55.1}]}
{"op":"mcm","clk":"1146562905","pt":1439845113464,"mc":[{"id":"1.120089104","rc":[{"atl":[[1.29,9.95]],"id":9612932}],"con":true,"img":false,"tv":55.1}]}
{"op":"mcm","clk":"1146562913","pt":1439845113571,"mc":[{"id":"1.120089104","rc":[{"atb":[[5.5,1.99]],"id":9480385}],"con":true,"img":false,"tv":55.1}]}
{"op":"mcm","clk":"1146562919","pt":1439845113677,"mc":[{"id":"1.120089104","rc":[{"atb":[[5.5,6.63]],"id":9480385}],"con":true,"img":false,"tv":55.1}]}
{"op":"mcm","clk":"1146562922","pt":1439845113784,"mc":[{"id":"1.120089104","rc":[{"atl":[[1.29,29.95]],"id":9612932},{"atl":[[19,0]],"id":9480385}],"con":true,"img":false,"tv":55.1}]}
{"op":"mcm","clk":"1146562927","pt":1439845113890,"mc":[{"id":"1.120089104","rc":[{"atl":[[17.5,4.54]],"id":9480385}],"con":true,"img":false,"tv":55.1}]}
{"op":"mcm","clk":"1146564714","pt":1439845155937,"mc":[{"id":"1.120089104","rc":[{"atl":[[18,0]],"id":9480385}],"con":true,"img":false,"tv":55.1}]}
{"op":"mcm","clk":"1146564720","pt":1439845156094,"mc":[{"id":"1.120089104","rc":[{"atl":[[16.5,15]],"id":9480385}],"con":true,"img":false,"tv":55.1}]}
{"op":"mcm","clk":"1146564767","pt":1439845157359,"mc":[{"id":"1.120089104","rc":[{"atl":[[17.5,3.98],[1000,2.56]],"id":9480385}],"con":true,"img":false,"tv":55.1}]}
{"op":"mcm","clk":"1146564800","pt":1439845157977,"mc":[{"id":"1.120089104","rc":[{"atl":[[1000,0.6]],"id":9480385}],"con":true,"img":false,"tv":55.1}]}
{"op":"mcm","clk":"1146564810","pt":1439845158189,"mc":[{"id":"1.120089104","rc":[{"atl":[[1000,0]],"id":9480385}],"con":true,"img":false,"tv":55.1}]}
{"op":"mcm","clk":"1146564815","pt":1439845158246,"mc":[{"id":"1.120089104","rc":[{"atl":[[16,0.6]],"id":9480385}],"con":true,"img":false,"tv":55.1}]}
{"op":"mcm","clk":"1146564913","pt":1439845160393,"mc":[{"id":"1.120089104","rc":[{"atl":[[17.5,2.56]],"id":9480385}],"con":true,"img":false,"tv":55.1}]}
{"op":"mcm","clk":"1146564918","pt":1439845160501,"mc":[{"id":"1.120089104","rc":[{"atl":[[16,2.02]],"id":9480385}],"con":true,"img":false,"tv":55.1}]}
{"op":"mcm","clk":"1146564955","pt":1439845161434,"mc":[{"id":"1.120089104","rc":[{"atb":[[1.01,1731.01]],"id":9480385}],"con":true,"img":false,"tv":55.1}]}
{"op":"mcm","clk":"1146564974","pt":1439845161850,"mc":[{"id":"1.120089104","rc":[{"atb":[[1.01,1730.17]],"id":9480385}],"con":true,"img":false,"tv":55.1}]}
{"op":"mcm","clk":"1146564980","pt":1439845162010,"mc":[{"id":"1.120089104","rc":[{"atb":[[1.01,1728.45]],"id":9480385}],"con":true,"img":false,"tv":55.1}]}
{"op":"mcm","clk":"1146564987","pt":1439845162166,"mc":[{"id":"1.120089104","rc":[{"atb":[[5.6,1.71]],"id":9480385}],"con":true,"img":false,"tv":55.1}]}
{"op":"mcm","clk":"1146565037","pt":1439845163428,"mc":[{"id":"1.120089104","rc":[{"atb":[[4.5,0]],"id":9480385}],"con":true,"img":false,"tv":55.1}]}
{"op":"mcm","clk":"1146567034","pt":1439845207603,"mc":[{"id":"1.120089104","rc":[{"atl":[[16.5,0]],"id":9480385},{"spn":10.8,"spf":"NaN","id":9480385}],"con":true,"img":false,"tv":55.1}]}
{"op":"mcm","clk":"1146567040","pt":1439845207708,"mc":[{"id":"1.120089104","rc":[{"atl":[[15,15]],"id":9480385}],"con":true,"img":false,"tv":55.1}]}
{"op":"mcm","clk":"1146567116","pt":1439845209483,"mc":[{"id":"1.120089104","rc":[{"atl":[[1000,2.56],[16,1.42]],"id":9480385}],"con":true,"img":false,"tv":55.1}]}
{"op":"mcm","clk":"1146567149","pt":1439845210104,"mc":[{"id":"1.120089104","rc":[{"atl":[[1000,0.66]],"id":9480385}],"con":true,"img":false,"tv":55.1}]}
{"op":"mcm","clk":"1146567158","pt":1439845210311,"mc":[{"id":"1.120089104","rc":[{"atl":[[1000,0]],"id":9480385}],"con":true,"img":false,"tv":55.1}]}
{"op":"mcm","clk":"1146567164","pt":1439845210418,"mc":[{"id":"1.120089104","rc":[{"atl":[[14.5,0.66]],"id":9480385}],"con":true,"img":false,"tv":55.1}]}
{"op":"mcm","clk":"1146567444","pt":1439845220828,"mc":[{"id":"1.120089104","rc":[{"atl":[[16,0]],"id":9480385}],"con":true,"img":false,"tv":55.1}]}
{"op":"mcm","clk":"1146567448","pt":1439845220932,"mc":[{"id":"1.120089104","rc":[{"atl":[[17,1.42]],"id":9480385}],"con":true,"img":false,"tv":55.1}]}
{"op":"mcm","clk":"1146568361","pt":1439845247670,"mc":[{"id":"1.120089104","rc":[{"trd":[[1.24,3.96]],"ltp":1.24,"tv":3.96,"id":9612932},{"atb":[[1.17,44.16],[1.01,1730.3]],"id":9612932},{"atb":[[2.62,1.41],[1.01,1728.3],[5.2,1.98],[2.22,12.08],[5.1,3.06]],"id":9480385},{"atl":[[17.5,0],[17,1.42]],"id":9480385}],"con":true,"img":false,"tv":55.1}]}
{"op":"mcm","clk":"1146568365","pt":1439845247774,"mc":[{"id":"1.120089104","rc":[{"atl":[[14.5,3.22]],"id":9480385}],"con":true,"img":false,"tv":55.1}]}
{"op":"mcm","clk":"1146568469","pt":1439845251126,"mc":[{"id":"1.120089104","rc":[{"atl":[[17,0]],"id":9480385}],"con":true,"img":false,"tv":55.1}]}
{"op":"mcm","clk":"1146568476","pt":1439845251231,"mc":[{"id":"1.120089104","rc":[{"atl":[[14,1.42]],"id":9480385}],"con":true,"img":false,"tv":55.1}]}
{"op":"mcm","clk":"1146568776","pt":1439845260512,"mc":[{"id":"1.120089104","rc":[{"atl":[[15,0]],"id":9480385}],"con":true,"img":false,"tv":55.1}]}
{"op":"mcm","clk":"1146568777","pt":1439845260615,"mc":[{"id":"1.120089104","rc":[{"atl":[[13.5,15]],"id":9480385}],"con":true,"img":false,"tv":55.1}]}
{"op":"mcm","clk":"1146568802","pt":1439845261404,"mc":[{"id":"1.120089104","rc":[{"atl":[[14.5,2.56],[1000,2.56]],"id":9480385}],"con":true,"img":false,"tv":55.1}]}
{"op":"mcm","clk":"1146568827","pt":1439845261987,"mc":[{"id":"1.120089104","rc":[{"atl":[[1000,0.73]],"id":9480385}],"con":true,"img":false,"tv":55.1}]}
{"op":"mcm","clk":"1146568833","pt":1439845262193,"mc":[{"id":"1.120089104","rc":[{"atl":[[1000,0]],"id":9480385}],"con":true,"img":false,"tv":55.1}]}
{"op":"mcm","clk":"1146568837","pt":1439845262298,"mc":[{"id":"1.120089104","rc":[{"atl":[[13,0.73]],"id":9480385}],"con":true,"img":false,"tv":55.1}]}
{"op":"mcm","clk":"1146579435","pt":1439845464703,"mc":[{"id":"1.120089104","marketDefinition":{"bspMarket":true,"turnInPlayEnabled":true,"persistenceEnabled":true,"marketBaseRate":5.0,"eventId":"27514783","eventTypeId":"7","numberOfWinners":1,"bettingType":"ODDS","marketType":"WIN","marketTime":"2015-08-18T20:20:00.000Z","suspendTime":"2015-08-18T20:20:00.000Z","bspReconciled":false,"complete":true,"inPlay":false,"crossMatching":false,"runnersVoidable":false,"numberOfActiveRunners":2,"betDelay":0,"status":"OPEN","runners":[{"adjustmentFactor":79.72,"status":"ACTIVE","sortPriority":1,"id":9612932,"name":"Alinstante"},{"adjustmentFactor":20.27,"status":"ACTIVE","sortPriority":2,"id":9480385,"name":"Vallance Road"}],"regulators":["MR_INT"],"venue":"Chelmsford City","countryCode":"GB","discountAllowed":false,"timezone":"Europe/London","openDate":"2015-08-18T17:20:00.000Z","version":1060767560,"name":"1m Cond Stks","eventName":"ChelmC 18th Aug"},"rc":[{"trd":[[1.24,3.96],[1.4,49.38],[1.25,1.76]],"ltp":1.24,"tv":55.1,"id":9612932},{"atb":[[1.17,44.16],[1.18,2.04],[1.06,5840],[1.14,400],[1.01,1730.3],[1.13,33],[1.15,22],[1.02,5251.99],[1.12,400],[1.1,406],[1.08,10],[1.2,3.89],[1.19,10.78],[1.09,240]],"id":9612932},{"atl":[[1.29,29.95],[1.3,200],[1.69,15],[19.5,11],[630,0.09],[1.4,500],[1000,1],[4,0.25],[1.39,1.9],[1.38,500]],"id":9612932},{"spl":[[1.01,12]],"id":9612932},{"spn":1.19,"spf":1.0,"id":9612932},{"atb":[[2.62,1.41],[4.4,60],[2.6,1.9],[4.9,6],[1.06,20],[3.75,15],[1.81,12.35],[2.28,37],[1.01,1728.3],[4.8,60],[5.3,0.88],[1.02,5251.99],[5.2,1.98],[2.16,30],[1.08,10],[4.7,6],[2.22,12.08],[5.1,3.06],[2.92,175],[5.6,1.71],[5.5,6.63],[4.6,60]],"id":9480385},{"atl":[[14.5,2.56],[14,1.42],[13.5,15],[13,0.73],[630,0.09],[90,2]],"id":9480385},{"spn":9.3,"spf":"NaN","id":9480385}],"con":true,"img":true,"tv":55.1}]}
{"op":"mcm","clk":"1146586715","pt":1439845512853,"mc":[{"id":"1.120089104","rc":[{"atl":[[14.5,0]],"id":9480385},{"spn":9.3,"spf":"NaN","id":9480385}],"con":true,"img":false,"tv":55.1}]}
{"op":"mcm","clk":"1146586723","pt":1439845512959,"mc":[{"id":"1.120089104","rc":[{"atl":[[13,3.3]],"id":9480385}],"con":true,"img":false,"tv":55.1}]}
{"op":"mcm","clk":"1146587032","pt":1439845520197,"mc":[{"id":"1.120089104","rc":[{"atl":[[13.5,0]],"id":9480385}],"con":true,"img":false,"tv":55.1}]}
{"op":"mcm","clk":"1146587035","pt":1439845520302,"mc":[{"id":"1.120089104","rc":[{"atl":[[12,15]],"id":9480385}],"con":true,"img":false,"tv":55.1}]}
{"op":"mcm","clk":"1146587074","pt":1439845521312,"mc":[{"id":"1.120089104","rc":[{"atl":[[13,2.56],[1000,2.56]],"id":9480385}],"con":true,"img":false,"tv":55.1}]}
{"op":"mcm","clk":"1146587100","pt":1439845521892,"mc":[{"id":"1.120089104","rc":[{"atl":[[1000,0.83]],"id":9480385}],"con":true,"img":false,"tv":55.1}]}
{"op":"mcm","clk":"1146587113","pt":1439845522104,"mc":[{"id":"1.120089104","rc":[{"atl":[[1000,0]],"id":9480385}],"con":true,"img":false,"tv":55.1}]}
{"op":"mcm","clk":"1146587118","pt":1439845522213,"mc":[{"id":"1.120089104","rc":[{"atl":[[14,0],[11.5,0.83]],"id":9480385}],"con":true,"img":false,"tv":55.1}]}
{"op":"mcm","clk":"1146588093","pt":1439845545233,"mc":[{"id":"1.120089104","rc":[{"atl":[[11,1.42]],"id":9480385},{"spn":8.3,"spf":"NaN","id":9480385}],"con":true,"img":false,"tv":55.1}]}
{"op":"mcm","clk":"1146589258","pt":1439845572227,"mc":[{"id":"1.120089104","rc":[{"atl":[[12,0]],"id":9480385}],"con":true,"img":false,"tv":55.1}]}
{"op":"mcm","clk":"1146589262","pt":1439845572331,"mc":[{"id":"1.120089104","rc":[{"atl":[[10.5,15]],"id":9480385}],"con":true,"img":false,"tv":55.1}]}
{"op":"mcm","clk":"1146589389","pt":1439845575486,"mc":[{"id":"1.120089104","rc":[{"atl":[[11,0]],"id":9480385}],"con":true,"img":false,"tv":55.1}]}
{"op":"mcm","clk":"1146589392","pt":1439845575538,"mc":[{"id":"1.120089104","rc":[{"atl":[[10,1.42]],"id":9480385}],"con":true,"img":false,"tv":55.1}]}
{"op":"mcm","clk":"1146589749","pt":1439845584337,"mc":[{"id":"1.120089104","rc":[{"atb":[[5.6,6.71]],"id":9480385}],"con":true,"img":false,"tv":55.1}]}
{"op":"mcm","clk":"1146597159","pt":1439845734109,"mc":[{"id":"1.120089104","rc":[{"atl":[[13,0]],"id":9480385},{"spn":7.8,"spf":"NaN","id":9480385}],"con":true,"img":false,"tv":55.1}]}
{"op":"mcm","clk":"1146597164","pt":1439845734210,"mc":[{"id":"1.120089104","rc":[{"atl":[[10,3.98]],"id":9480385}],"con":true,"img":false,"tv":55.1}]}
{"op":"mcm","clk":"1146652064","pt":1439846588400,"mc":[{"id":"1.120089104","rc":[{"atl":[[1.38,0]],"id":9612932}],"con":true,"img":false,"tv":55.1}]}
{"op":"mcm","clk":"1146652077","pt":1439846588516,"mc":[{"id":"1.120089104","rc":[{"atl":[[1.28,500]],"id":9612932}],"con":true,"img":false,"tv":55.1}]}
{"op":"mcm","clk":"1146661901","pt":1439846743477,"mc":[{"id":"1.120089104","rc":[{"atl":[[1.29,20]],"id":9612932}],"con":true,"img":false,"tv":55.1}]}
{"op":"mcm","clk":"1146661910","pt":1439846743685,"mc":[{"id":"1.120089104","rc":[{"atl":[[1.27,10.1]],"id":9612932}],"con":true,"img":false,"tv":55.1}]}
{"op":"mcm","clk":"1146668604","pt":1439846880011,"mc":[{"id":"1.120089104","rc":[{"atl":[[1.28,0]],"id":9612932}],"con":true,"img":false,"tv":55.1}]}
{"op":"mcm","clk":"1146668607","pt":1439846880066,"mc":[{"id":"1.120089104","rc":[{"atl":[[1.29,520]],"id":9612932}],"con":true,"img":false,"tv":55.1}]}
{"op":"mcm","clk":"1146671550","pt":1439846947004,"mc":[{"id":"1.120089104","rc":[{"atl":[[1.29,20]],"id":9612932}],"con":true,"img":false,"tv":55.1}]}
{"op":"mcm","clk":"1146671555","pt":1439846947109,"mc":[{"id":"1.120089104","rc":[{"atl":[[1.3,700]],"id":9612932}],"con":true,"img":false,"tv":55.1}]}
{"op":"mcm","clk":"1146673275","pt":1439846996310,"mc":[{"id":"1.120089104","rc":[{"atl":[[1.3,200]],"id":9612932}],"con":true,"img":false,"tv":55.1}]}
{"op":"mcm","clk":"1146673278","pt":1439846996416,"mc":[{"id":"1.120089104","rc":[{"atl":[[1.28,500]],"id":9612932}],"con":true,"img":false,"tv":55.1}]}
{"op":"mcm","clk":"1146713342","pt":1439847784172,"mc":[{"id":"1.120089104","rc":[{"atb":[[1.01,1752.3]],"id":9612932}],"con":true,"img":false,"tv":55.1}]}
{"op":"mcm","clk":"1146741368","pt":1439848201910,"mc":[{"id":"1.120089104","rc":[{"spl":[[1.01,34.01]],"id":9612932}],"con":true,"img":false,"tv":55.1}]}
{"op":"mcm","clk":"1146743624","pt":1439848252948,"mc":[{"id":"1.120089104","rc":[{"spl":[[1.01,38.95]],"id":9612932},{"spn":1.17,"spf":1.0,"id":9612932}],"con":true,"img":false,"tv":55.1}]}
{"op":"mcm","clk":"1146749255","pt":1439848497287,"mc":[{"id":"1.120089104","rc":[{"atb":[[1.18,4.04]],"id":9612932},{"spn":1.17,"spf":1.0,"id":9612932},{"atb":[[5,2]],"id":9480385}],"con":true,"img":false,"tv":55.1}]}
{"op":"mcm","clk":"1146750494","pt":1439848559586,"mc":[{"id":"1.120089104","rc":[{"atl":[[1000,2]],"id":9480385}],"con":true,"img":false,"tv":55.1}]}
{"op":"mcm","clk":"1146750498","pt":1439848559697,"mc":[{"id":"1.120089104","rc":[{"atl":[[1000,0.1]],"id":9480385}],"con":true,"img":false,"tv":55.1}]}
{"op":"mcm","clk":"1146750507","pt":1439848560002,"mc":[{"id":"1.120089104","rc":[{"atl":[[1000,0]],"id":9480385}],"con":true,"img":false,"tv":55.1}]}
{"op":"mcm","clk":"1146750511","pt":1439848560112,"mc":[{"id":"1.120089104","rc":[{"atl":[[9.8,0.1]],"id":9480385}],"con":true,"img":false,"tv":55.1}]}
{"op":"mcm","clk":"1146756341","pt":1439848801280,"mc":[{"id":"1.120089104","rc":[{"atb":[[1.2,5.66]],"id":9612932},{"spn":1.18,"spf":1.0,"id":9612932},{"spn":7.7,"spf":"NaN","id":9480385}],"con":true,"img":false,"tv":55.1}]}
{"op":"mcm","clk":"1146756345","pt":1439848801389,"mc":[{"id":"1.120089104","rc":[{"atb":[[1.01,1729.72]],"id":9480385}],"con":true,"img":false,"tv":55.1}]}
{"op":"mcm","clk":"1146756792","pt":1439848818784,"mc":[{"id":"1.120089104","rc":[{"atb":[[1.01,1728.38]],"id":9480385}],"con":true,"img":false,"tv":55.1}]}
{"op":"mcm","clk":"1146756798","pt":1439848818992,"mc":[{"id":"1.120089104","rc":[{"atb":[[1.01,1728.3]],"id":9480385}],"con":true,"img":false,"tv":55.1}]}
{"op":"mcm","clk":"1146756803","pt":1439848819097,"mc":[{"id":"1.120089104","rc":[{"atb":[[5.6,6.79]],"id":9480385}],"con":true,"img":false,"tv":55.1}]}
{"op":"mcm","clk":"1146772008","pt":1439849121185,"mc":[{"id":"1.120089104","rc":[{"atl":[[55,2]],"id":9480385}],"con":true,"img":false,"tv":55.1}]}
{"op":"mcm","clk":"1146772393","pt":1439849134280,"mc":[{"id":"1.120089104","rc":[{"atl":[[55,2.01]],"id":9480385}],"con":true,"img":false,"tv":55.1}]}
{"op":"mcm","clk":"1146772595","pt":1439849140952,"mc":[{"id":"1.120089104","rc":[{"atl":[[55,0.01]],"id":9480385}],"con":true,"img":false,"tv":55.1}]}
{"op":"mcm","clk":"1146809029","pt":1439850159318,"mc":[{"id":"1.120089104","rc":[{"atb":[[1.18,44.04]],"id":9612932},{"spn":1.18,"spf":1.0,"id":9612932}],"con":true,"img":false,"tv":55.1}]}
{"op":"mcm","clk":"1146809383","pt":1439850177106,"mc":[{"id":"1.120089104","rc":[{"atl":[[46,2]],"id":9612932},{"atl":[[46,2]],"id":9480385}],"con":true,"img":false,"tv":55.1}]}
{"op":"mcm","clk":"1146809632","pt":1439850189659,"mc":[{"id":"1.120089104","rc":[{"atb":[[1.18,30]],"id":9480385}],"con":true,"img":false,"tv":55.1}]}
{"op":"mcm","clk":"1146820865","pt":1439850571736,"mc":[{"id":"1.120089104","rc":[{"atl":[[9.6,2]],"id":9480385},{"spn":7.6,"spf":"NaN","id":9480385}],"con":true,"img":false,"tv":55.1}]}
{"op":"mcm","clk":"1146820878","pt":1439850572099,"mc":[{"id":"1.120089104","rc":[{"atl":[[9.8,0]],"id":9480385}],"con":true,"img":false,"tv":55.1}]}
{"op":"mcm","clk":"1146820884","pt":1439850572208,"mc":[{"id":"1.120089104","rc":[{"atl":[[9.4,0.1]],"id":9480385}],"con":true,"img":false,"tv":55.1}]}
{"op":"mcm","clk":"1146821423","pt":1439850588895,"mc":[{"id":"1.120089104","rc":[{"atl":[[9.6,0]],"id":9480385}],"con":true,"img":false,"tv":55.1}]}
{"op":"mcm","clk":"1146821430","pt":1439850589104,"mc":[{"id":"1.120089104","rc":[{"atl":[[9.2,2]],"id":9480385}],"con":true,"img":false,"tv":55.1}]}
{"op":"mcm","clk":"1146821450","pt":1439850589629,"mc":[{"id":"1.120089104","rc":[{"atl":[[9.4,0]],"id":9480385}],"con":true,"img":false,"tv":55.1}]}
{"op":"mcm","clk":"1146821452","pt":1439850589732,"mc":[{"id":"1.120089104","rc":[{"atl":[[9,0.1]],"id":9480385}],"con":true,"img":false,"tv":55.1}]}
{"op":"mcm","clk":"1146821836","pt":1439850601763,"mc":[{"id":"1.120089104","rc":[{"atl":[[10,2.56]],"id":9480385}],"con":true,"img":false,"tv":55.1}]}
{"op":"mcm","clk":"1146821837","pt":1439850601866,"mc":[{"id":"1.120089104","rc":[{"atl":[[9,1.52]],"id":9480385}],"con":true,"img":false,"tv":55.1}]}
{"op":"mcm","clk":"1146821866","pt":1439850602603,"mc":[{"id":"1.120089104","rc":[{"atl":[[9,1.42]],"id":9480385}],"con":true,"img":false,"tv":55.1}]}
{"op":"mcm","clk":"1146821869","pt":1439850602708,"mc":[{"id":"1.120089104","rc":[{"atl":[[8.8,0.1]],"id":9480385}],"con":true,"img":false,"tv":55.1}]}
{"op":"mcm","clk":"1146821962","pt":1439850605648,"mc":[{"id":"1.120089104","rc":[{"atl":[[9.2,0]],"id":9480385}],"con":true,"img":false,"tv":55.1}]}
{"op":"mcm","clk":"1146821973","pt":1439850605809,"mc":[{"id":"1.120089104","rc":[{"atl":[[8.6,2]],"id":9480385}],"con":true,"img":false,"tv":55.1}]}
{"op":"mcm","clk":"1146821993","pt":1439850606438,"mc":[{"id":"1.120089104","rc":[{"atl":[[8.8,0]],"id":9480385}],"con":true,"img":false,"tv":55.1}]}
{"op":"mcm","clk":"1146821996","pt":1439850606544,"mc":[{"id":"1.120089104","rc":[{"atl":[[8.4,0.1]],"id":9480385}],"con":true,"img":false,"tv":55.1}]}
{"op":"mcm","clk":"1146822528","pt":1439850622907,"mc":[{"id":"1.120089104","rc":[{"atl":[[8.6,0]],"id":9480385}],"con":true,"img":false,"tv":55.1}]}
{"op":"mcm","clk":"1146822533","pt":1439850623010,"mc":[{"id":"1.120089104","rc":[{"atl":[[8.8,2]],"id":9480385}],"con":true,"img":false,"tv":55.1}]}
{"op":"mcm","clk":"1146822541","pt":1439850623322,"mc":[{"id":"1.120089104","rc":[{"atl":[[10,0]],"id":9480385}],"con":true,"img":false,"tv":55.1}]}
{"op":"mcm","clk":"1146822547","pt":1439850623429,"mc":[{"id":"1.120089104","rc":[{"atl":[[8.8,4.9]],"id":9480385}],"con":true,"img":false,"tv":55.1}]}
{"op":"mcm","clk":"1146822784","pt":1439850632127,"mc":[{"id":"1.120089104","rc":[{"atl":[[9,0]],"id":9480385},{"spn":7.0,"spf":"NaN","id":9480385}],"con":true,"img":false,"tv":55.1}]}
{"op":"mcm","clk":"1146822788","pt":1439850632236,"mc":[{"id":"1.120089104","rc":[{"atl":[[8.6,1.42]],"id":9480385}],"con":true,"img":false,"tv":55.1}]}
{"op":"mcm","clk":"1146822983","pt":1439850639491,"mc":[{"id":"1.120089104","rc":[{"atl":[[8.8,2.9]],"id":9480385}],"con":true,"img":false,"tv":55.1}]}
{"op":"mcm","clk":"1146822989","pt":1439850639597,"mc":[{"id":"1.120089104","rc":[{"atl":[[8.2,2]],"id":9480385}],"con":true,"img":false,"tv":55.1}]}
{"op":"mcm","clk":"1146823008","pt":1439850640131,"mc":[{"id":"1.120089104","rc":[{"atl":[[8.4,0]],"id":9480385}],"con":true,"img":false,"tv":55.1}]}
{"op":"mcm","clk":"1146823009","pt":1439850640178,"mc":[{"id":"1.120089104","rc":[{"atl":[[8,0.1]],"id":9480385}],"con":true,"img":false,"tv":55.1}]}
{"op":"mcm","clk":"1146823491","pt":1439850656561,"mc":[{"id":"1.120089104","rc":[{"atl":[[8.2,0]],"id":9480385}],"con":true,"img":false,"tv":55.1}]}
{"op":"mcm","clk":"1146823494","pt":1439850656665,"mc":[{"id":"1.120089104","rc":[{"atl":[[8.4,2]],"id":9480385}],"con":true,"img":false,"tv":55.1}]}
{"op":"mcm","clk":"1146823679","pt":1439850662512,"mc":[{"id":"1.120089104","rc":[{"atl":[[8.6,0]],"id":9480385}],"con":true,"img":false,"tv":55.1}]}
{"op":"mcm","clk":"1146823684","pt":1439850662616,"mc":[{"id":"1.120089104","rc":[{"atl":[[8.2,1.42]],"id":9480385}],"con":true,"img":false,"tv":55.1}]}
{"op":"mcm","clk":"1146823994","pt":1439850673322,"mc":[{"id":"1.120089104","rc":[{"atl":[[8.4,0]],"id":9480385}],"con":true,"img":false,"tv":55.1}]}
{"op":"mcm","clk":"1146824002","pt":1439850673428,"mc":[{"id":"1.120089104","rc":[{"atl":[[7.8,2]],"id":9480385}],"con":true,"img":false,"tv":55.1}]}
{"op":"mcm","clk":"1146824013","pt":1439850673949,"mc":[{"id":"1.120089104","rc":[{"atl":[[8,0]],"id":9480385}],"con":true,"img":false,"tv":55.1}]}
{"op":"mcm","clk":"1146824016","pt":1439850674054,"mc":[{"id":"1.120089104","rc":[{"atl":[[7.6,0.1]],"id":9480385}],"con":true,"img":false,"tv":55.1}]}
{"op":"mcm","clk":"1146824245","pt":1439850680817,"mc":[{"id":"1.120089104","rc":[{"atl":[[8.8,0]],"id":9480385}],"con":true,"img":false,"tv":55.1}]}
{"op":"mcm","clk":"1146824249","pt":1439850680921,"mc":[{"id":"1.120089104","rc":[{"atl":[[8,3.19]],"id":9480385}],"con":true,"img":false,"tv":55.1}]}
{"op":"mcm","clk":"1146824558","pt":1439850692788,"mc":[{"id":"1.120089104","rc":[{"atl":[[8.2,0]],"id":9480385},{"spn":6.6,"spf":"NaN","id":9480385}],"con":true,"img":false,"tv":55.1}]}
{"op":"mcm","clk":"1146824559","pt":1439850692894,"mc":[{"id":"1.120089104","rc":[{"atl":[[7.6,1.52]],"id":9480385}],"con":true,"img":false,"tv":55.1}]}
{"op":"mcm","clk":"1146824566","pt":1439850693157,"mc":[{"id":"1.120089104","rc":[{"atl":[[7.6,1.42]],"id":9480385}],"con":true,"img":false,"tv":55.1}]}
{"op":"mcm","clk":"1146824569","pt":1439850693265,"mc":[{"id":"1.120089104","rc":[{"atl":[[7.4,0.1]],"id":9480385}],"con":true,"img":false,"tv":55.1}]}
{"op":"mcm","clk":"1146824675","pt":1439850696628,"mc":[{"id":"1.120089104","rc":[{"atl":[[1.26,25.65]],"id":9612932}],"con":true,"img":false,"tv":55.1}]}
{"op":"mcm","clk":"1146824979","pt":1439850706647,"mc":[{"id":"1.120089104","rc":[{"atl":[[7.8,0]],"id":9480385}],"con":true,"img":false,"tv":55.1}]}
{"op":"mcm","clk":"1146824983","pt":1439850706700,"mc":[{"id":"1.120089104","rc":[{"atl":[[7.2,2]],"id":9480385}],"con":true,"img":false,"tv":55.1}]}
{"op":"mcm","clk":"1146825179","pt":1439850713299,"mc":[{"id":"1.120089104","rc":[{"atl":[[1.27,0]],"id":9612932}],"con":true,"img":false,"tv":55.1}]}
{"op":"mcm","clk":"1146825185","pt":1439850713512,"mc":[{"id":"1.120089104","rc":[{"atl":[[1.25,10.26]],"id":9612932}],"con":true,"img":false,"tv":55.1}]}
{"op":"mcm","clk":"1146825188","pt":1439850713617,"mc":[{"id":"1.120089104","rc":[{"atl":[[8,0]],"id":9480385}],"con":true,"img":false,"tv":55.1}]}
{"op":"mcm","clk":"1146825192","pt":1439850713725,"mc":[{"id":"1.120089104","rc":[{"atl":[[7.4,3.55]],"id":9480385}],"con":true,"img":false,"tv":55.1}]}
{"op":"mcm","clk":"1146825455","pt":1439850723046,"mc":[{"id":"1.120089104","rc":[{"atl":[[7.6,0]],"id":9480385}],"con":true,"img":false,"tv":55.1}]}
{"op":"mcm","clk":"1146825458","pt":1439850723150,"mc":[{"id":"1.120089104","rc":[{"atl":[[7,1.42]],"id":9480385}],"con":true,"img":false,"tv":55.1}]}
{"op":"mcm","clk":"1146826032","pt":1439850746145,"mc":[{"id":"1.120089104","rc":[{"atl":[[7.2,0]],"id":9480385}],"con":true,"img":false,"tv":55.1}]}
{"op":"mcm","clk":"1146826037","pt":1439850746250,"mc":[{"id":"1.120089104","rc":[{"atl":[[6.8,2]],"id":9480385}],"con":true,"img":false,"tv":55.1}]}
{"op":"mcm","clk":"1146826227","pt":1439850753354,"mc":[{"id":"1.120089104","rc":[{"atl":[[7,0]],"id":9480385},{"spn":6.2,"spf":"NaN","id":9480385}],"con":true,"img":false,"tv":55.1}]}
{"op":"mcm","clk":"1146826229","pt":1439850753458,"mc":[{"id":"1.120089104","rc":[{"atl":[[6.6,1.42]],"id":9480385}],"con":true,"img":false,"tv":55.1}]}
{"op":"mcm","clk":"1146826454","pt":1439850763145,"mc":[{"id":"1.120089104","rc":[{"atl":[[6.8,0]],"id":9480385}],"con":true,"img":false,"tv":55.1}]}
{"op":"mcm","clk":"1146826990","pt":1439850783627,"mc":[{"id":"1.120089104","rc":[{"atl":[[6.6,0]],"id":9480385}],"con":true,"img":false,"tv":55.1}]}
{"op":"mcm","clk":"1146826994","pt":1439850783733,"mc":[{"id":"1.120089104","rc":[{"atl":[[7.2,1.42]],"id":9480385}],"con":true,"img":false,"tv":55.1}]}
{"op":"mcm","clk":"1146827212","pt":1439850790664,"mc":[{"id":"1.120089104","rc":[{"atl":[[7.4,0.1]],"id":9480385}],"con":true,"img":false,"tv":55.1}]}
{"op":"mcm","clk":"1146827215","pt":1439850790770,"mc":[{"id":"1.120089104","rc":[{"atl":[[10,2.56]],"id":9480385}],"con":true,"img":false,"tv":55.1}]}
{"op":"mcm","clk":"1146827882","pt":1439850813956,"mc":[{"id":"1.120089104","rc":[{"atl":[[7.2,0]],"id":9480385},{"spn":6.5,"spf":"NaN","id":9480385}],"con":true,"img":false,"tv":55.1}]}
{"op":"mcm","clk":"1146827885","pt":1439850814059,"mc":[{"id":"1.120089104","rc":[{"atl":[[9.8,1.42]],"id":9480385}],"con":true,"img":false,"tv":55.1}]}
{"op":"mcm","clk":"1146827895","pt":1439850814371,"mc":[{"id":"1.120089104","rc":[{"atl":[[7.4,0]],"id":9480385}],"con":true,"img":false,"tv":55.1}]}
{"op":"mcm","clk":"1146827898","pt":1439850814424,"mc":[{"id":"1.120089104","rc":[{"atl":[[9.6,0.1]],"id":9480385}],"con":true,"img":false,"tv":55.1}]}
{"op":"mcm","clk":"1146828343","pt":1439850835542,"mc":[{"id":"1.120089104","rc":[{"atl":[[9.4,2]],"id":9480385}],"con":true,"img":false,"tv":55.1}]}
{"op":"mcm","clk":"1146828354","pt":1439850836221,"mc":[{"id":"1.120089104","rc":[{"atl":[[9.6,0]],"id":9480385}],"con":true,"img":false,"tv":55.1}]}
{"op":"mcm","clk":"1146828359","pt":1439850836325,"mc":[{"id":"1.120089104","rc":[{"atl":[[9.2,0.1]],"id":9480385}],"con":true,"img":false,"tv":55.1}]}
{"op":"mcm","clk":"1146828564","pt":1439850844258,"mc":[{"id":"1.120089104","rc":[{"atl":[[9.8,0]],"id":9480385}],"con":true,"img":false,"tv":55.1}]}
{"op":"mcm","clk":"1146828567","pt":1439850844470,"mc":[{"id":"1.120089104","rc":[{"atl":[[9.2,1.52]],"id":9480385}],"con":true,"img":false,"tv":55.1}]}
{"op":"mcm","clk":"1146828579","pt":1439850845037,"mc":[{"id":"1.120089104","rc":[{"atl":[[9.2,1.42]],"id":9480385}],"con":true,"img":false,"tv":55.1}]}
{"op":"mcm","clk":"1146828581","pt":1439850845153,"mc":[{"id":"1.120089104","rc":[{"atl":[[9,0.1]],"id":9480385}],"con":true,"img":false,"tv":55.1}]}
{"op":"mcm","clk":"1146828771","pt":1439850852239,"mc":[{"id":"1.120089104","rc":[{"atl":[[9.4,0]],"id":9480385}],"con":true,"img":false,"tv":55.1}]}
{"op":"mcm","clk":"1146828775","pt":1439850852291,"mc":[{"id":"1.120089104","rc":[{"atl":[[8.8,2]],"id":9480385}],"con":true,"img":false,"tv":55.1}]}
{"op":"mcm","clk":"1146828786","pt":1439850852920,"mc":[{"id":"1.120089104","rc":[{"atl":[[9,0]],"id":9480385}],"con":true,"img":false,"tv":55.1}]}
{"op":"mcm","clk":"1146828789","pt":1439850853027,"mc":[{"id":"1.120089104","rc":[{"atl":[[8.6,0.1]],"id":9480385}],"con":true,"img":false,"tv":55.1}]}
{"op":"mcm","clk":"1146828907","pt":1439850857508,"mc":[{"id":"1.120089104","rc":[{"atl":[[10,0]],"id":9480385}],"con":true,"img":false,"tv":55.1}]}
{"op":"mcm","clk":"1146828912","pt":1439850857563,"mc":[{"id":"1.120089104","rc":[{"atl":[[9,2.83]],"id":9480385}],"con":true,"img":false,"tv":55.1}]}
{"op":"mcm","clk":"1146837317","pt":1439850874641,"mc":[{"id":"1.120089104","rc":[{"atl":[[9.2,0]],"id":9480385},{"spn":7.1,"spf":"NaN","id":9480385}],"con":true,"img":false,"tv":55.1}]}
{"op":"mcm","clk":"1146837320","pt":1439850874747,"mc":[{"id":"1.120089104","rc":[{"atl":[[8.6,1.52]],"id":9480385}],"con":true,"img":false,"tv":55.1}]}
{"op":"mcm","clk":"1146837335","pt":1439850875228,"mc":[{"id":"1.120089104","rc":[{"atl":[[8.6,1.42]],"id":9480385}],"con":true,"img":false,"tv":55.1}]}
{"op":"mcm","clk":"1146837338","pt":1439850875331,"mc":[{"id":"1.120089104","rc":[{"atl":[[8.4,0.1]],"id":9480385}],"con":true,"img":false,"tv":55.1}]}
{"op":"mcm","clk":"1146837553","pt":1439850885930,"mc":[{"id":"1.120089104","rc":[{"atl":[[8.8,0]],"id":9480385}],"con":true,"img":false,"tv":55.1}]}
{"op":"mcm","clk":"1146837556","pt":1439850886033,"mc":[{"id":"1.120089104","rc":[{"atl":[[8.2,2]],"id":9480385}],"con":true,"img":false,"tv":55.1}]}
{"op":"mcm","clk":"1146837561","pt":1439850886240,"mc":[{"id":"1.120089104","rc":[{"atl":[[8.4,0]],"id":9480385}],"con":true,"img":false,"tv":55.1}]}
{"op":"mcm","clk":"1146837565","pt":1439850886343,"mc":[{"id":"1.120089104","rc":[{"atl":[[8,0.1]],"id":9480385}],"con":true,"img":false,"tv":55.1}]}
{"op":"mcm","clk":"1146837690","pt":1439850890248,"mc":[{"id":"1.120089104","rc":[{"atl":[[9,0]],"id":9480385}],"con":true,"img":false,"tv":55.1}]}
{"op":"mcm","clk":"1146837693","pt":1439850890351,"mc":[{"id":"1.120089104","rc":[{"atl":[[8.4,3.04]],"id":9480385}],"con":true,"img":false,"tv":55.1}]}
{"op":"mcm","clk":"1146838054","pt":1439850904937,"mc":[{"id":"1.120089104","rc":[{"atl":[[8.6,0]],"id":9480385}],"con":true,"img":false,"tv":55.1}]}
{"op":"mcm","clk":"1146838057","pt":1439850905041,"mc":[{"id":"1.120089104","rc":[{"atl":[[8,1.52]],"id":9480385}],"con":true,"img":false,"tv":55.1}]}
{"op":"mcm","clk":"1146838066","pt":1439850905456,"mc":[{"id":"1.120089104","rc":[{"atl":[[8,1.42]],"id":9480385}],"con":true,"img":false,"tv":55.1}]}
{"op":"mcm","clk":"1146838070","pt":1439850905562,"mc":[{"id":"1.120089104","rc":[{"atl":[[7.8,0.1]],"id":9480385}],"con":true,"img":false,"tv":55.1}]}
{"op":"mcm","clk":"1146838448","pt":1439850919589,"mc":[{"id":"1.120089104","rc":[{"atl":[[8.2,0]],"id":9480385}],"con":true,"img":false,"tv":55.1}]}
{"op":"mcm","clk":"1146838451","pt":1439850919692,"mc":[{"id":"1.120089104","rc":[{"atl":[[7.6,2]],"id":9480385}],"con":true,"img":false,"tv":55.1}]}
{"op":"mcm","clk":"1146838465","pt":1439850920322,"mc":[{"id":"1.120089104","rc":[{"atl":[[7.8,0]],"id":9480385}],"con":true,"img":false,"tv":55.1}]}
{"op":"mcm","clk":"1146838469","pt":1439850920426,"mc":[{"id":"1.120089104","rc":[{"atl":[[7.4,0.1]],"id":9480385}],"con":true,"img":false,"tv":55.1}]}
{"op":"mcm","clk":"1146838741","pt":1439850930126,"mc":[{"id":"1.120089104","rc":[{"atl":[[8.4,0]],"id":9480385}],"con":true,"img":false,"tv":55.1}]}
{"op":"mcm","clk":"1146838745","pt":1439850930234,"mc":[{"id":"1.120089104","rc":[{"atl":[[7.8,3.27]],"id":9480385}],"con":true,"img":false,"tv":55.1}]}
{"op":"mcm","clk":"1146838877","pt":1439850935276,"mc":[{"id":"1.120089104","rc":[{"atl":[[8,0]],"id":9480385},{"spn":6.5,"spf":"NaN","id":9480385}],"con":true,"img":false,"tv":55.1}]}
{"op":"mcm","clk":"1146838881","pt":1439850935381,"mc":[{"id":"1.120089104","rc":[{"atl":[[7.4,1.52]],"id":9480385}],"con":true,"img":false,"tv":55.1}]}
{"op":"mcm","clk":"1146838891","pt":1439850935697,"mc":[{"id":"1.120089104","rc":[{"atl":[[7.4,1.42]],"id":9480385}],"con":true,"img":false,"tv":55.1}]}
{"op":"mcm","clk":"1146838894","pt":1439850935803,"mc":[{"id":"1.120089104","rc":[{"atl":[[7.2,0.1]],"id":9480385}],"con":true,"img":false,"tv":55.1}]}
{"op":"mcm","clk":"1146838915","pt":1439850936379,"mc":[{"id":"1.120089104","rc":[{"atl":[[7.6,0]],"id":9480385}],"con":true,"img":false,"tv":55.1}]}
{"op":"mcm","clk":"1146838918","pt":1439850936484,"mc":[{"id":"1.120089104","rc":[{"atl":[[7,2]],"id":9480385}],"con":true,"img":false,"tv":55.1}]}
{"op":"mcm","clk":"1146839807","pt":1439850965542,"mc":[{"id":"1.120089104","rc":[{"atl":[[7.4,0]],"id":9480385}],"con":true,"img":false,"tv":55.1}]}
{"op":"mcm","clk":"1146839810","pt":1439850965752,"mc":[{"id":"1.120089104","rc":[{"atl":[[6.8,1.42]],"id":9480385}],"con":true,"img":false,"tv":55.1}]}
{"op":"mcm","clk":"1146849461","pt":1439851482111,"mc":[{"id":"1.120089104","rc":[{"trd":[[1.2,9.99]],"ltp":1.2,"tv":9.99,"id":9612932},{"atb":[[1.2,0.66]],"id":9612932},{"spn":1.18,"spf":1.0,"id":9612932},{"spn":6.2,"spf":"NaN","id":9480385}],"con":true,"img":false,"tv":65.1}]}
{"op":"mcm","clk":"1146849796","pt":1439851512677,"mc":[{"id":"1.120089104","rc":[{"atl":[[1.24,20]],"id":9612932}],"con":true,"img":false,"tv":65.1}]}
{"op":"mcm","clk":"1146849808","pt":1439851513200,"mc":[{"id":"1.120089104","rc":[{"atl":[[1.27,6]],"id":9612932}],"con":true,"img":false,"tv":65.1}]}
{"op":"mcm","clk":"1146849870","pt":1439851516825,"mc":[{"id":"1.120089104","rc":[{"atb":[[1.11,6]],"id":9612932}],"con":true,"img":false,"tv":65.1}]}
{"op":"mcm","clk":"1146850002","pt":1439851532832,"mc":[{"id":"1.120089104","rc":[{"atl":[[1.25,0]],"id":9612932}],"con":true,"img":false,"tv":65.1}]}
{"op":"mcm","clk":"1146850004","pt":1439851532935,"mc":[{"id":"1.120089104","rc":[{"atl":[[1.23,10.43]],"id":9612932}],"con":true,"img":false,"tv":65.1}]}
{"op":"mcm","clk":"1146850007","pt":1439851533041,"mc":[{"id":"1.120089104","rc":[{"atb":[[1.19,14.03]],"id":9612932},{"atl":[[1.23,13.74]],"id":9612932}],"con":true,"img":false,"tv":65.1}]}
{"op":"mcm","clk":"1146850202","pt":1439851553443,"mc":[{"id":"1.120089104","rc":[{"trd":[[1.19,20.65],[1.2,11.33]],"ltp":1.19,"tv":31.97,"id":9612932},{"atb":[[1.2,0],[1.19,3.7]],"id":9612932},{"spn":1.18,"spf":1.0,"id":9612932}],"con":true,"img":false,"tv":87.09}]}
{"op":"mcm","clk":"1146850210","pt":1439851554118,"mc":[{"id":"1.120089104","rc":[{"atl":[[1.23,15.47]],"id":9612932}],"con":true,"img":false,"tv":87.09}]}
{"op":"mcm","clk":"1146850372","pt":1439851568735,"mc":[{"id":"1.120089104","rc":[{"trd":[[1.19,26.65]],"ltp":1.19,"tv":26.65,"id":9612932},{"atb":[[1.19,0.7]],"id":9612932}],"con":true,"img":false,"tv":93.09}]}
{"op":"mcm","clk":"1146850646","pt":1439851590645,"mc":[{"id":"1.120089104","rc":[{"atl":[[1.24,0]],"id":9612932}],"con":true,"img":false,"tv":93.09}]}
{"op":"mcm","clk":"1146850648","pt":1439851590750,"mc":[{"id":"1.120089104","rc":[{"atl":[[1.22,20]],"id":9612932}],"con":true,"img":false,"tv":93.09}]}
{"op":"mcm","clk":"1146850739","pt":1439851597592,"mc":[{"id":"1.120089104","rc":[{"atb":[[1.19,0]],"id":9612932},{"atl":[[1.23,1.73]],"id":9612932}],"con":true,"img":false,"tv":93.09}]}
{"op":"mcm","clk":"1146850743","pt":1439851597690,"mc":[{"id":"1.120089104","rc":[{"atl":[[1.23,14.62]],"id":9612932}],"con":true,"img":false,"tv":93.09}]}
{"op":"mcm","clk":"1146850834","pt":1439851607353,"mc":[{"id":"1.120089104","rc":[{"atl":[[1.22,21]],"id":9612932}],"con":true,"img":false,"tv":93.09}]}
{"op":"mcm","clk":"1146855771","pt":1439851764804,"mc":[{"id":"1.120089104","marketDefinition":{"bspMarket":true,"turnInPlayEnabled":true,"persistenceEnabled":true,"marketBaseRate":5.0,"eventId":"27514783","eventTypeId":"7","numberOfWinners":1,"bettingType":"ODDS","marketType":"WIN","marketTime":"2015-08-18T20:20:00.000Z","suspendTime":"2015-08-18T20:20:00.000Z","bspReconciled":false,"complete":true,"inPlay":false,"crossMatching":false,"runnersVoidable":false,"numberOfActiveRunners":2,"betDelay":0,"status":"OPEN","runners":[{"adjustmentFactor":79.72,"status":"ACTIVE","sortPriority":1,"id":9612932,"name":"Alinstante"},{"adjustmentFactor":20.27,"status":"ACTIVE","sortPriority":2,"id":9480385,"name":"Vallance Road"}],"regulators":["MR_INT"],"venue":"Chelmsford City","countryCode":"GB","discountAllowed":false,"timezone":"Europe/London","openDate":"2015-08-18T17:20:00.000Z","version":1060767560,"name":"1m Cond Stks","eventName":"ChelmC 18th Aug"},"rc":[{"trd":[[1.19,26.65],[1.24,3.96],[1.2,11.33],[1.4,49.38],[1.25,1.76]],"ltp":1.19,"tv":93.08,"id":9612932},{"atb":[[1.17,44.16],[1.12,400],[1.1,406],[1.08,10],[1.11,6],[1.06,5840],[1.18,44.04],[1.14,400],[1.13,33],[1.01,1752.3],[1.15,22],[1.09,240],[1.02,5251.99]],"id":9612932},{"atl":[[1.29,20],[1.3,200],[19.5,11],[630,0.09],[1.4,500],[1000,1],[1.27,6],[1.28,500],[1.39,1.9],[1.26,25.65],[1.23,14.62],[1.22,21],[1.69,15],[46,2],[4,0.25]],"id":9612932},{"spl":[[1.01,38.95]],"id":9612932},{"spn":1.18,"spf":1.0,"id":9612932},{"atb":[[2.62,1.41],[4.4,60],[2.6,1.9],[4.9,6],[1.06,20],[1.18,30],[3.75,15],[1.81,12.35],[2.28,37],[1.01,1728.3],[4.8,60],[5.3,0.88],[1.02,5251.99],[5.2,1.98],[2.16,30],[1.08,10],[4.7,6],[2.22,12.08],[5.1,3.06],[2.92,175],[5.6,6.79],[5.5,6.63],[4.6,60],[5,2]],"id":9480385},{"atl":[[6.8,1.42],[46,2],[7,2],[7.8,3.27],[55,0.01],[630,0.09],[11.5,0.83],[90,2],[7.2,0.1],[10.5,15]],"id":9480385},{"spn":6.2,"spf":"NaN","id":9480385}],"con":true,"img":true,"tv":93.09}]}
{"op":"mcm","clk":"1146863141","pt":1439851912586,"mc":[{"id":"1.120089104","rc":[{"atl":[[1000,3.1]],"id":9612932},{"spn":1.18,"spf":1.0,"id":9612932}],"con":true,"img":false,"tv":93.09}]}
{"op":"mcm","clk":"1146863150","pt":1439851912895,"mc":[{"id":"1.120089104","rc":[{"atl":[[1000,2.89]],"id":9612932}],"con":true,"img":false,"tv":93.09}]}
{"op":"mcm","clk":"1146863158","pt":1439851913312,"mc":[{"id":"1.120089104","rc":[{"atl":[[1000,1]],"id":9612932}],"con":true,"img":false,"tv":93.09}]}
{"op":"mcm","clk":"1146863161","pt":1439851913414,"mc":[{"id":"1.120089104","rc":[{"atl":[[1.27,7.89]],"id":9612932}],"con":true,"img":false,"tv":93.09}]}
{"op":"mcm","clk":"1146873094","pt":1439852403103,"mc":[{"id":"1.120089104","rc":[{"atb":[[1.18,46.01]],"id":9612932}],"con":true,"img":false,"tv":93.09}]}
{"op":"mcm","clk":"1146874824","pt":1439852489943,"mc":[{"id":"1.120089104","rc":[{"atb":[[1.19,1.42]],"id":9612932},{"spn":1.18,"spf":1.0,"id":9612932}],"con":true,"img":false,"tv":93.09}]}
{"op":"mcm","clk":"1146874832","pt":1439852490152,"mc":[{"id":"1.120089104","rc":[{"atb":[[1.01,1729.72]],"id":9480385}],"con":true,"img":false,"tv":93.09}]}
{"op":"mcm","clk":"1146874836","pt":1439852490258,"mc":[{"id":"1.120089104","rc":[{"atb":[[1.01,1729.69]],"id":9480385}],"con":true,"img":false,"tv":93.09}]}
{"op":"mcm","clk":"1146874841","pt":1439852490362,"mc":[{"id":"1.120089104","rc":[{"atb":[[1.01,1728.3]],"id":9480385}],"con":true,"img":false,"tv":93.09}]}
{"op":"mcm","clk":"1146874844","pt":1439852490466,"mc":[{"id":"1.120089104","rc":[{"atb":[[5.6,8.19]],"id":9480385}],"con":true,"img":false,"tv":93.09}]}
{"op":"mcm","clk":"1146938728","pt":1439855039721,"mc":[{"id":"1.120089104","rc":[{"atl":[[1.26,0]],"id":9612932}],"con":true,"img":false,"tv":93.09}]}
{"op":"mcm","clk":"1146938730","pt":1439855039826,"mc":[{"id":"1.120089104","rc":[{"atl":[[1.21,25.65]],"id":9612932}],"con":true,"img":false,"tv":93.09}]}
{"op":"mcm","clk":"1146939091","pt":1439855065173,"mc":[{"id":"1.120089104","rc":[{"trd":[[5.6,9.99]],"ltp":5.6,"tv":9.99,"id":9480385},{"atb":[[5.6,3.19]],"id":9480385}],"con":true,"img":false,"tv":103.09}]}
{"op":"mcm","clk":"1146942392","pt":1439855212785,"mc":[{"id":"1.120089104","rc":[{"atb":[[1.09,0]],"id":9612932}],"con":true,"img":false,"tv":103.09}]}
{"op":"mcm","clk":"1146942396","pt":1439855212889,"mc":[{"id":"1.120089104","rc":[{"atb":[[1.04,240]],"id":9612932}],"con":true,"img":false,"tv":103.09}]}
{"op":"mcm","clk":"1146942400","pt":1439855213094,"mc":[{"id":"1.120089104","rc":[{"atb":[[1.06,20]],"id":9612932}],"con":true,"img":false,"tv":103.09}]}
{"op":"mcm","clk":"1146942401","pt":1439855213197,"mc":[{"id":"1.120089104","rc":[{"atb":[[1.04,6060]],"id":9612932}],"con":true,"img":false,"tv":103.09}]}
{"op":"mcm","clk":"1146942490","pt":1439855217398,"mc":[{"id":"1.120089104","rc":[{"atb":[[1.1,400]],"id":9612932}],"con":true,"img":false,"tv":103.09}]}
{"op":"mcm","clk":"1146955415","pt":1439855443698,"mc":[{"id":"1.120089104","rc":[{"atb":[[1.04,240]],"id":9612932}],"con":true,"img":false,"tv":103.09}]}
{"op":"mcm","clk":"1146955421","pt":1439855443807,"mc":[{"id":"1.120089104","rc":[{"atb":[[1.03,5820]],"id":9612932}],"con":true,"img":false,"tv":103.09}]}
{"op":"mcm","clk":"1146961174","pt":1439855661720,"mc":[{"id":"1.120089104","rc":[{"atb":[[1.03,0]],"id":9612932}],"con":true,"img":false,"tv":103.09}]}
{"op":"mcm","clk":"1146961177","pt":1439855661821,"mc":[{"id":"1.120089104","rc":[{"atb":[[1.02,11071.99]],"id":9612932}],"con":true,"img":false,"tv":103.09}]}
{"op":"mcm","clk":"1146973893","pt":1439856264878,"mc":[{"id":"1.120089104","marketDefinition":{"bspMarket":true,"turnInPlayEnabled":true,"persistenceEnabled":true,"marketBaseRate":5.0,"eventId":"27514783","eventTypeId":"7","numberOfWinners":1,"bettingType":"ODDS","marketType":"WIN","marketTime":"2015-08-18T20:20:00.000Z","suspendTime":"2015-08-18T20:20:00.000Z","bspReconciled":false,"complete":true,"inPlay":false,"crossMatching":false,"runnersVoidable":false,"numberOfActiveRunners":2,"betDelay":0,"status":"OPEN","runners":[{"adjustmentFactor":79.72,"status":"ACTIVE","sortPriority":1,"id":9612932,"name":"Alinstante"},{"adjustmentFactor":20.27,"status":"ACTIVE","sortPriority":2,"id":9480385,"name":"Vallance Road"}],"regulators":["MR_INT"],"venue":"Chelmsford City","countryCode":"GB","discountAllowed":false,"timezone":"Europe/London","openDate":"2015-08-18T17:20:00.000Z","version":1060767560,"name":"1m Cond Stks","eventName":"ChelmC 18th Aug"},"rc":[{"trd":[[1.19,26.65],[1.24,3.96],[1.2,11.33],[1.4,49.38],[1.25,1.76]],"ltp":1.19,"tv":93.08,"id":9612932},{"atb":[[1.17,44.17],[1.04,240],[1.18,46.01],[1.06,20],[1.14,400],[1.01,1752.36],[1.13,33],[1.15,22],[1.02,11071.99],[1.12,400],[1.1,400],[1.08,10],[1.11,6],[1.19,1.42]],"id":9612932},{"atl":[[1.29,20],[1.3,200],[19.5,11],[630,0.09],[1.4,500],[1000,1],[1.27,7.89],[1.28,500],[1.39,1.9],[1.23,14.62],[1.22,21],[1.69,15],[46,2],[4,0.25],[1.21,25.65]],"id":9612932},{"spl":[[1.01,38.95]],"id":9612932},{"spn":1.18,"spf":1.0,"id":9612932},{"trd":[[5.6,9.99]],"ltp":5.6,"tv":9.99,"id":9480385},{"atb":[[2.62,1.41],[4.4,60],[2.6,1.9],[4.9,6],[1.06,20],[1.18,30],[3.75,15],[1.81,12.35],[2.28,37],[1.01,1728.36],[4.8,60],[5.3,0.88],[1.02,5251.99],[5.2,1.98],[2.16,30],[1.08,10],[4.7,6],[2.22,12.08],[5.1,3.06],[2.92,175],[5.6,3.19],[5.5,6.63],[4.6,60],[5,2]],"id":9480385},{"atl":[[6.8,1.42],[46,2],[7,2],[7.8,3.27],[55,0.01],[630,0.09],[11.5,0.83],[90,2],[7.2,0.1],[10.5,15]],"id":9480385},{"spn":6.2,"spf":"NaN","id":9480385}],"con":true,"img":true,"tv":103.09}]}
{"op":"mcm","clk":"1147047142","pt":1439859864863,"mc":[{"id":"1.120089104","marketDefinition":{"bspMarket":true,"turnInPlayEnabled":true,"persistenceEnabled":true,"marketBaseRate":5.0,"eventId":"27514783","eventTypeId":"7","numberOfWinners":1,"bettingType":"ODDS","marketType":"WIN","marketTime":"2015-08-18T20:20:00.000Z","suspendTime":"2015-08-18T20:20:00.000Z","bspReconciled":false,"complete":true,"inPlay":false,"crossMatching":false,"runnersVoidable":false,"numberOfActiveRunners":2,"betDelay":0,"status":"OPEN","runners":[{"adjustmentFactor":79.72,"status":"ACTIVE","sortPriority":1,"id":9612932,"name":"Alinstante"},{"adjustmentFactor":20.27,"status":"ACTIVE","sortPriority":2,"id":9480385,"name":"Vallance Road"}],"regulators":["MR_INT"],"venue":"Chelmsford City","countryCode":"GB","discountAllowed":false,"timezone":"Europe/London","openDate":"2015-08-18T17:20:00.000Z","version":1060767560,"name":"1m Cond Stks","eventName":"ChelmC 18th Aug"},"rc":[{"trd":[[1.19,26.65],[1.24,3.96],[1.2,11.33],[1.4,49.38],[1.25,1.76]],"ltp":1.19,"tv":93.08,"id":9612932},{"atb":[[1.17,44.16],[1.04,240],[1.18,46.01],[1.06,20],[1.14,400],[1.01,1752.3],[1.13,33],[1.15,22],[1.02,11071.99],[1.12,400],[1.1,400],[1.08,10],[1.11,6],[1.19,1.42]],"id":9612932},{"atl":[[1.29,20],[1.3,200],[19.5,11],[630,0.09],[1.4,500],[1000,1],[1.27,7.89],[1.28,500],[1.39,1.9],[1.23,14.62],[1.22,21],[1.69,15],[46,2],[4,0.25],[1.21,25.65]],"id":9612932},{"spl":[[1.01,38.95]],"id":9612932},{"spn":1.18,"spf":1.0,"id":9612932},{"trd":[[5.6,9.99]],"ltp":5.6,"tv":9.99,"id":9480385},{"atb":[[2.62,1.41],[4.4,60],[2.6,1.9],[4.9,6],[1.06,20],[1.18,30],[3.75,15],[1.81,12.35],[2.28,37],[1.01,1728.3],[4.8,60],[5.3,0.88],[1.02,5251.99],[5.2,1.98],[2.16,30],[1.08,10],[4.7,6],[2.22,12.08],[5.1,3.06],[2.92,175],[5.6,3.19],[5.5,6.63],[4.6,60],[5,2]],"id":9480385},{"atl":[[6.8,1.42],[46,2],[7,2],[7.8,3.27],[55,0.01],[630,0.09],[11.5,0.83],[90,2],[7.2,0.1],[10.5,15]],"id":9480385},{"spn":6.2,"spf":"NaN","id":9480385}],"con":true,"img":true,"tv":103.09}]}
{"op":"mcm","clk":"1147112411","pt":1439864307366,"mc":[{"id":"1.120089104","rc":[{"trd":[[1.22,28.7],[1.19,26.65],[1.21,51.3]],"ltp":1.22,"tv":106.64,"id":9612932},{"atl":[[1.23,14.62],[1.22,6.65],[1.21,0]],"id":9612932},{"trd":[[5.6,9.99]],"ltp":5.6,"tv":9.99,"id":9480385},{"atb":[[5.5,6.63]],"id":9480385},{"atl":[[7.8,3.27],[11.5,0.83]],"id":9480385}],"con":true,"img":false,"tv":183.09}]}
{"op":"mcm","clk":"1147166800","pt":1439867968231,"mc":[{"id":"1.120089104","rc":[{"trd":[[1.22,41.98]],"ltp":1.22,"tv":41.98,"id":9612932},{"atl":[[1.22,0.01]],"id":9612932},{"trd":[[5.6,16.38]],"ltp":5.6,"tv":16.38,"id":9480385},{"atb":[[5.6,0]],"id":9480385}],"con":true,"img":false,"tv":202.76}]}
{"op":"mcm","clk":"1147166804","pt":1439867969749,"mc":[{"id":"1.120089104","rc":[{"atl":[[1000,1.42]],"id":9480385}],"con":true,"img":false,"tv":202.76}]}
{"op":"mcm","clk":"1147166806","pt":1439867969853,"mc":[{"id":"1.120089104","rc":[{"atb":[[1.01,1729.72]],"id":9480385}],"con":true,"img":false,"tv":202.76}]}
{"op":"mcm","clk":"1147166809","pt":1439867970750,"mc":[{"id":"1.120089104","rc":[{"atl":[[1000,0.06]],"id":9480385}],"con":true,"img":false,"tv":202.76}]}
{"op":"mcm","clk":"1147166810","pt":1439867970961,"mc":[{"id":"1.120089104","rc":[{"atb":[[4.5,6]],"id":9480385},{"atl":[[1000,0]],"id":9480385}],"con":true,"img":false,"tv":202.76}]}
{"op":"mcm","clk":"1147166812","pt":1439867971066,"mc":[{"id":"1.120089104","rc":[{"atl":[[6.6,0.06]],"id":9480385}],"con":true,"img":false,"tv":202.76}]}
{"op":"mcm","clk":"1147166815","pt":1439867971329,"mc":[{"id":"1.120089104","rc":[{"atb":[[1.01,1728.39]],"id":9480385}],"con":true,"img":false,"tv":202.76}]}
{"op":"mcm","clk":"1147166817","pt":1439867971536,"mc":[{"id":"1.120089104","rc":[{"atb":[[1.01,1728.3]],"id":9480385}],"con":true,"img":false,"tv":202.76}]}
{"op":"mcm","clk":"1147166818","pt":1439867971640,"mc":[{"id":"1.120089104","rc":[{"atb":[[5.4,0.08]],"id":9480385}],"con":true,"img":false,"tv":202.76}]}
{"op":"mcm","clk":"1147166852","pt":1439867981117,"mc":[{"id":"1.120089104","rc":[{"atb":[[1.16,22.89]],"id":9612932},{"atl":[[1.23,36.22]],"id":9612932}],"con":true,"img":false,"tv":202.76}]}
{"op":"mcm","clk":"1147166900","pt":1439867991934,"mc":[{"id":"1.120089104","rc":[{"atl":[[7,0]],"id":9480385}],"con":true,"img":false,"tv":202.76}]}
{"op":"mcm","clk":"1147166929","pt":1439868004301,"mc":[{"id":"1.120089104","rc":[{"atl":[[6.8,0]],"id":9480385}],"con":true,"img":false,"tv":202.76}]}
{"op":"mcm","clk":"1147166930","pt":1439868004458,"mc":[{"id":"1.120089104","rc":[{"atl":[[7.6,1.42]],"id":9480385}],"con":true,"img":false,"tv":202.76}]}
{"op":"mcm","clk":"1147167011","pt":1439868030862,"mc":[{"id":"1.120089104","rc":[{"atl":[[1.23,1.73]],"id":9612932},{"spn":6.05,"spf":"NaN","id":9480385}],"con":true,"img":false,"tv":202.76}]}
{"op":"mcm","clk":"1147167012","pt":1439868030966,"mc":[{"id":"1.120089104","rc":[{"atl":[[1.26,33.66]],"id":9612932}],"con":true,"img":false,"tv":202.76}]}
{"op":"mcm","clk":"1147167013","pt":1439868031071,"mc":[{"id":"1.120089104","rc":[{"atl":[[7.8,0]],"id":9480385}],"con":true,"img":false,"tv":202.76}]}
{"op":"mcm","clk":"1147167014","pt":1439868031177,"mc":[{"id":"1.120089104","rc":[{"atl":[[10,2.56]],"id":9480385}],"con":true,"img":false,"tv":202.76}]}
{"op":"mcm","clk":"1147167021","pt":1439868034675,"mc":[{"id":"1.120089104","rc":[{"atl":[[7.6,0]],"id":9480385}],"con":true,"img":false,"tv":202.76}]}
{"op":"mcm","clk":"1147167022","pt":1439868034780,"mc":[{"id":"1.120089104","rc":[{"atl":[[9.8,1.42]],"id":9480385}],"con":true,"img":false,"tv":202.76}]}
{"op":"mcm","clk":"1147167324","pt":1439868136870,"mc":[{"id":"1.120089104","rc":[{"atl":[[6.4,2]],"id":9480385},{"spn":5.95,"spf":"NaN","id":9480385}],"con":true,"img":false,"tv":202.76}]}
{"op":"mcm","clk":"1147167348","pt":1439868146668,"mc":[{"id":"1.120089104","rc":[{"atl":[[10,0]],"id":9480385}],"con":true,"img":false,"tv":202.76}]}
{"op":"mcm","clk":"1147167350","pt":1439868146771,"mc":[{"id":"1.120089104","rc":[{"atl":[[9.6,2.66]],"id":9480385}],"con":true,"img":false,"tv":202.76}]}
{"op":"mcm","clk":"1147167372","pt":1439868155259,"mc":[{"id":"1.120089104","rc":[{"atl":[[9.8,0]],"id":9480385}],"con":true,"img":false,"tv":202.76}]}
{"op":"mcm","clk":"1147177778","pt":1439868928991,"mc":[{"id":"1.120089104","rc":[{"trd":[[1.23,3.46],[1.22,42]],"ltp":1.23,"tv":45.46,"id":9612932},{"atl":[[1.23,0],[1.22,0]],"id":9612932},{"trd":[[5.5,13.25]],"ltp":5.5,"tv":13.25,"id":9480385},{"atb":[[5.5,0]],"id":9480385}],"con":true,"img":false,"tv":219.5}]}
{"op":"mcm","clk":"1147177784","pt":1439868931207,"mc":[{"id":"1.120089104","rc":[{"atb":[[1.2,1.77]],"id":9612932}],"con":true,"img":false,"tv":219.5}]}
{"op":"mcm","clk":"1147177785","pt":1439868934254,"mc":[{"id":"1.120089104","rc":[{"atl":[[6.2,1.42]],"id":9480385}],"con":true,"img":false,"tv":219.5}]}
{"op":"mcm","clk":"1147180090","pt":1439869599831,"mc":[{"id":"1.120089104","rc":[{"atl":[[1.25,6.41]],"id":9612932},{"spn":1.18,"spf":1.0,"id":9612932},{"spn":5.85,"spf":"NaN","id":9480385}],"con":true,"img":false,"tv":225.9}]}
{"op":"mcm","clk":"1147180112","pt":1439869607135,"mc":[{"id":"1.120089104","rc":[{"trd":[[1.19,29.49],[1.2,14.89]],"ltp":1.19,"tv":44.37,"id":9612932},{"atb":[[1.2,0],[1.19,0]],"id":9612932},{"atl":[[1.19,0.01]],"id":9612932}],"con":true,"img":false,"tv":225.9}]}
{"op":"mcm","clk":"1147180117","pt":1439869608334,"mc":[{"id":"1.120089104","rc":[{"atl":[[1.23,1.73]],"id":9612932}],"con":true,"img":false,"tv":225.9}]}
{"op":"mcm","clk":"1147180119","pt":1439869610944,"mc":[{"id":"1.120089104","rc":[{"atl":[[1.25,0],[1.19,0]],"id":9612932}],"con":true,"img":false,"tv":225.9}]}
{"op":"mcm","clk":"1147180126","pt":1439869615479,"mc":[{"id":"1.120089104","rc":[{"atl":[[1.23,8.15]],"id":9612932}],"con":true,"img":false,"tv":225.9}]}
{"op":"mcm","clk":"1147180442","pt":1439869711765,"mc":[{"id":"1.120089104","rc":[{"atb":[[1.19,1.42]],"id":9612932},{"spn":1.18,"spf":1.0,"id":9612932}],"con":true,"img":false,"tv":225.9}]}
{"op":"mcm","clk":"1147188872","pt":1439869889668,"mc":[{"id":"1.120089104","rc":[{"trd":[[1.23,19.77]],"ltp":1.23,"tv":19.77,"id":9612932},{"atl":[[1.23,0]],"id":9612932},{"trd":[[5.2,3.95],[5.4,0.17],[5.3,1.76],[5.5,13.27]],"ltp":5.2,"tv":19.15,"id":9480385},{"atb":[[5.2,0],[5.4,0],[5.3,0],[5.5,0]],"id":9480385},{"spn":5.7,"spf":"NaN","id":9480385}],"con":true,"img":false,"tv":248.1}]}
{"op":"mcm","clk":"1147188877","pt":1439869890499,"mc":[{"id":"1.120089104","rc":[{"atb":[[1.2,1.77]],"id":9612932},{"atl":[[1000,1.42]],"id":9480385}],"con":true,"img":false,"tv":248.1}]}
{"op":"mcm","clk":"1147188878","pt":1439869890603,"mc":[{"id":"1.120089104","rc":[{"atb":[[1.01,1729.72]],"id":9480385}],"con":true,"img":false,"tv":248.1}]}
{"op":"mcm","clk":"1147188883","pt":1439869891331,"mc":[{"id":"1.120089104","rc":[{"atl":[[1000,0.07]],"id":9480385}],"con":true,"img":false,"tv":248.1}]}
{"op":"mcm","clk":"1147188885","pt":1439869891383,"mc":[{"id":"1.120089104","rc":[{"atb":[[1.01,1728.39]],"id":9480385}],"con":true,"img":false,"tv":248.1}]}
{"op":"mcm","clk":"1147188886","pt":1439869891487,"mc":[{"id":"1.120089104","rc":[{"atb":[[1.01,1728.3]],"id":9480385},{"atl":[[1000,0]],"id":9480385}],"con":true,"img":false,"tv":248.1}]}
{"op":"mcm","clk":"1147188887","pt":1439869891591,"mc":[{"id":"1.120089104","rc":[{"atb":[[5.2,0.09]],"id":9480385},{"atl":[[6,0.07]],"id":9480385}],"con":true,"img":false,"tv":248.1}]}
{"op":"mcm","clk":"1147188948","pt":1439869917275,"mc":[{"id":"1.120089104","rc":[{"atb":[[5,4.78]],"id":9480385}],"con":true,"img":false,"tv":248.1}]}
{"op":"mcm","clk":"1147188949","pt":1439869917379,"mc":[{"id":"1.120089104","rc":[{"atl":[[1000,2.56]],"id":9480385}],"con":true,"img":false,"tv":248.1}]}
{"op":"mcm","clk":"1147188950","pt":1439869917483,"mc":[{"id":"1.120089104","rc":[{"atl":[[1000,1.45]],"id":9480385}],"con":true,"img":false,"tv":248.1}]}
{"op":"mcm","clk":"1147188952","pt":1439869917587,"mc":[{"id":"1.120089104","rc":[{"atl":[[1000,0]],"id":9480385}],"con":true,"img":false,"tv":248.1}]}
{"op":"mcm","clk":"1147188955","pt":1439869917692,"mc":[{"id":"1.120089104","rc":[{"atl":[[9.6,4.11]],"id":9480385}],"con":true,"img":false,"tv":248.1}]}
{"op":"mcm","clk":"1147189044","pt":1439869943007,"mc":[{"id":"1.120089104","rc":[{"atl":[[6.4,0]],"id":9480385}],"con":true,"img":false,"tv":248.1}]}
{"op":"mcm","clk":"1147189045","pt":1439869943110,"mc":[{"id":"1.120089104","rc":[{"atl":[[5.9,2]],"id":9480385}],"con":true,"img":false,"tv":248.1}]}
{"op":"mcm","clk":"1147189081","pt":1439869950075,"mc":[{"id":"1.120089104","rc":[{"spn":1.18,"spf":1.0,"id":9612932},{"atb":[[5,2]],"id":9480385},{"spn":5.55,"spf":"NaN","id":9480385}],"con":true,"img":false,"tv":248.1}]}
{"op":"mcm","clk":"1147189083","pt":1439869950179,"mc":[{"id":"1.120089104","rc":[{"atb":[[5.2,2.77]],"id":9480385}],"con":true,"img":false,"tv":248.1}]}
{"op":"mcm","clk":"1147189106","pt":1439869957663,"mc":[{"id":"1.120089104","rc":[{"atl":[[6.2,0]],"id":9480385}],"con":true,"img":false,"tv":248.1}]}
{"op":"mcm","clk":"1147189188","pt":1439869982554,"mc":[{"id":"1.120089104","rc":[{"atl":[[9.6,0]],"id":9480385}],"con":true,"img":false,"tv":248.1}]}
{"op":"mcm","clk":"1147189189","pt":1439869982658,"mc":[{"id":"1.120089104","rc":[{"atl":[[10,3.94]],"id":9480385}],"con":true,"img":false,"tv":248.1}]}
{"op":"mcm","clk":"1147194452","pt":1439870664887,"mc":[{"id":"1.120089104","marketDefinition":{"bspMarket":true,"turnInPlayEnabled":true,"persistenceEnabled":true,"marketBaseRate":5.0,"eventId":"27514783","eventTypeId":"7","numberOfWinners":1,"bettingType":"ODDS","marketType":"WIN","marketTime":"2015-08-18T20:20:00.000Z","suspendTime":"2015-08-18T20:20:00.000Z","bspReconciled":false,"complete":true,"inPlay":false,"crossMatching":false,"runnersVoidable":false,"numberOfActiveRunners":2,"betDelay":0,"status":"OPEN","runners":[{"adjustmentFactor":79.72,"status":"ACTIVE","sortPriority":1,"id":9612932,"name":"Alinstante"},{"adjustmentFactor":20.27,"status":"ACTIVE","sortPriority":2,"id":9480385,"name":"Vallance Road"}],"regulators":["MR_INT"],"venue":"Chelmsford City","countryCode":"GB","discountAllowed":false,"timezone":"Europe/London","openDate":"2015-08-18T17:20:00.000Z","version":1060767560,"name":"1m Cond Stks","eventName":"ChelmC 18th Aug"},"rc":[{"trd":[[1.23,19.76],[1.22,41.99],[1.24,3.96],[1.2,14.88],[1.4,49.38],[1.19,29.48],[1.25,1.76],[1.21,51.3]],"ltp":1.23,"tv":212.51,"id":9612932},{"atb":[[1.17,44.15],[1.16,22.88],[1.04,240],[1.06,20],[1.18,46.01],[1.14,400],[1.01,1752.23],[1.13,33],[1.15,22],[1.02,11071.99],[1.12,400],[1.1,400],[1.08,10],[1.11,6],[1.2,1.77],[1.19,1.42]],"id":9612932},{"atl":[[1.29,20],[1.3,200],[1.69,15],[46,2],[19.5,11],[630,0.09],[1.4,500],[1000,1],[1.27,7.89],[1.28,500],[4,0.25],[1.39,1.9],[1.26,33.64]],"id":9612932},{"spl":[[1.01,38.95]],"id":9612932},{"spn":1.18,"spf":1.0,"id":9612932},{"trd":[[5.2,3.94],[5.4,0.17],[5.6,16.37],[5.3,1.76],[5.5,13.26]],"ltp":5.2,"tv":35.5,"id":9480385},{"atb":[[4.4,60],[2.62,1.41],[2.6,1.9],[4.9,6],[1.06,20],[1.18,30],[3.75,15],[1.81,12.35],[2.28,37],[1.01,1728.23],[4.8,60],[1.02,5251.99],[5.2,2.77],[2.16,30],[1.08,10],[4.7,6],[2.22,12.07],[4.5,6],[5.1,3.06],[2.92,175],[4.6,60],[5,2]],"id":9480385},{"atl":[[6,0.07],[46,2],[5.9,2],[6.6,0.06],[55,0.01],[630,0.09],[11.5,0.83],[90,2],[10,3.94],[7.2,0.1],[10.5,15]],"id":9480385},{"spn":5.55,"spf":"NaN","id":9480385}],"con":true,"img":true,"tv":248.06}]}
{"op":"mcm","clk":"1147200116","pt":1439870850396,"mc":[{"id":"1.120089104","rc":[{"trd":[[1.26,67.27],[1.23,19.76],[1.22,41.99],[1.24,3.96],[1.2,14.88],[1.19,29.48]],"ltp":1.26,"tv":177.34,"id":9612932},{"atb":[[1.17,44.15],[1.16,22.88],[1.18,46.01],[1.01,1752.23],[1.2,1.77],[1.19,1.42]],"id":9612932},{"atl":[[1.26,0]],"id":9612932},{"trd":[[5.2,9.49],[5.6,16.37],[5.3,1.76],[5.5,13.26]],"ltp":5.2,"tv":40.88,"id":9480385},{"atb":[[2.62,1.41],[1.01,1728.23],[5.2,0],[2.22,12.07],[5.1,3.06]],"id":9480385},{"atl":[[11.5,0.83],[10,3.94]],"id":9480385},{"spn":5.5,"spf":"NaN","id":9480385}],"con":true,"img":false,"tv":320.88}]}
{"op":"mcm","clk":"1147200117","pt":1439870850811,"mc":[{"id":"1.120089104","rc":[{"atl":[[1000,1.42]],"id":9480385}],"con":true,"img":false,"tv":320.88}]}
{"op":"mcm","clk":"1147200118","pt":1439870850914,"mc":[{"id":"1.120089104","rc":[{"atb":[[1.01,1729.65]],"id":9480385}],"con":true,"img":false,"tv":320.88}]}
{"op":"mcm","clk":"1147200119","pt":1439870851850,"mc":[{"id":"1.120089104","rc":[{"atl":[[1000,0.08]],"id":9480385}],"con":true,"img":false,"tv":320.88}]}
{"op":"mcm","clk":"1147200121","pt":1439870851954,"mc":[{"id":"1.120089104","rc":[{"atl":[[1000,0]],"id":9480385}],"con":true,"img":false,"tv":320.88}]}
{"op":"mcm","clk":"1147200122","pt":1439870852006,"mc":[{"id":"1.120089104","rc":[{"atb":[[1.01,1728.33]],"id":9480385},{"atl":[[5.8,0.08]],"id":9480385}],"con":true,"img":false,"tv":320.88}]}
{"op":"mcm","clk":"1147200124","pt":1439870852110,"mc":[{"id":"1.120089104","rc":[{"atb":[[1.01,1728.23]],"id":9480385}],"con":true,"img":false,"tv":320.88}]}
{"op":"mcm","clk":"1147200125","pt":1439870852215,"mc":[{"id":"1.120089104","rc":[{"atb":[[5,2.09]],"id":9480385}],"con":true,"img":false,"tv":320.88}]}
{"op":"mcm","clk":"1147200128","pt":1439870853466,"mc":[{"id":"1.120089104","rc":[{"atb":[[5,4.88]],"id":9480385}],"con":true,"img":false,"tv":320.88}]}
{"op":"mcm","clk":"1147200131","pt":1439870853519,"mc":[{"id":"1.120089104","rc":[{"atl":[[1000,2.56]],"id":9480385}],"con":true,"img":false,"tv":320.88}]}
{"op":"mcm","clk":"1147200132","pt":1439870853625,"mc":[{"id":"1.120089104","rc":[{"atl":[[1000,1.39]],"id":9480385}],"con":true,"img":false,"tv":320.88}]}
{"op":"mcm","clk":"1147200133","pt":1439870853727,"mc":[{"id":"1.120089104","rc":[{"atl":[[1000,0]],"id":9480385}],"con":true,"img":false,"tv":320.88}]}
{"op":"mcm","clk":"1147200136","pt":1439870853831,"mc":[{"id":"1.120089104","rc":[{"atl":[[10,5.34]],"id":9480385}],"con":true,"img":false,"tv":320.88}]}
{"op":"mcm","clk":"1147200228","pt":1439870885854,"mc":[{"id":"1.120089104","rc":[{"atb":[[5,2.09]],"id":9480385}],"con":true,"img":false,"tv":320.88}]}
{"op":"mcm","clk":"1147200229","pt":1439870885960,"mc":[{"id":"1.120089104","rc":[{"atb":[[5.2,2.68]],"id":9480385}],"con":true,"img":false,"tv":320.88}]}
{"op":"mcm","clk":"1147200339","pt":1439870920087,"mc":[{"id":"1.120089104","rc":[{"atl":[[5.9,0]],"id":9480385}],"con":true,"img":false,"tv":320.88}]}
{"op":"mcm","clk":"1147200390","pt":1439870938266,"mc":[{"id":"1.120089104","rc":[{"atl":[[6.4,1.42]],"id":9480385}],"con":true,"img":false,"tv":320.88}]}
{"op":"mcm","clk":"1147211530","pt":1439871811162,"mc":[{"id":"1.120089104","rc":[{"trd":[[1.27,15.76]],"ltp":1.27,"tv":15.76,"id":9612932},{"atl":[[1.27,0.01]],"id":9612932},{"trd":[[5.2,14.85]],"ltp":5.2,"tv":14.85,"id":9480385},{"atb":[[5.2,0]],"id":9480385},{"spn":5.45,"spf":"NaN","id":9480385}],"con":true,"img":false,"tv":342.01}]}
{"op":"mcm","clk":"1147211541","pt":1439871814715,"mc":[{"id":"1.120089104","rc":[{"atb":[[1.21,6]],"id":9612932}],"con":true,"img":false,"tv":342.01}]}
{"op":"mcm","clk":"1147211775","pt":1439871888395,"mc":[{"id":"1.120089104","rc":[{"atb":[[1.13,798.02]],"id":9612932},{"spn":1.18,"spf":1.0,"id":9612932}],"con":true,"img":false,"tv":342.01}]}
{"op":"mcm","clk":"1147222307","pt":1439872772169,"mc":[{"id":"1.120089104","rc":[{"trd":[[1.28,1000],[1.27,15.78]],"ltp":1.28,"tv":1015.78,"id":9612932},{"atl":[[1.27,0],[1.28,0]],"id":9612932},{"trd":[[5.1,6.1]],"ltp":5.1,"tv":6.1,"id":9480385},{"atb":[[5.1,0]],"id":9480385}],"con":true,"img":false,"tv":1348.13}]}
{"op":"mcm","clk":"1147223274","pt":1439873015148,"mc":[{"id":"1.120089104","rc":[{"atl":[[5.7,2]],"id":9480385},{"spn":5.4,"spf":"NaN","id":9480385}],"con":true,"img":false,"tv":1348.13}]}
{"op":"mcm","clk":"1147223277","pt":1439873015664,"mc":[{"id":"1.120089104","rc":[{"atl":[[6.4,0]],"id":9480385}],"con":true,"img":false,"tv":1348.13}]}
{"op":"mcm","clk":"1147223634","pt":1439873129564,"mc":[{"id":"1.120089104","rc":[{"atb":[[5,5.09]],"id":9480385}],"con":true,"img":false,"tv":1348.13}]}
{"op":"mcm","clk":"1147233874","pt":1439873732911,"mc":[{"id":"1.120089104","rc":[{"trd":[[1.29,39.99]],"ltp":1.29,"tv":39.99,"id":9612932},{"atl":[[1.29,0]],"id":9612932},{"trd":[[5,10.18],[5.1,6.12]],"ltp":5.0,"tv":16.3,"id":9480385},{"atb":[[5.1,0],[5,0.01]],"id":9480385},{"spn":5.35,"spf":"NaN","id":9480385}],"con":true,"img":false,"tv":1398.33}]}
{"op":"mcm","clk":"1147233879","pt":1439873733838,"mc":[{"id":"1.120089104","rc":[{"atl":[[1000,1.42]],"id":9480385}],"con":true,"img":false,"tv":1398.33}]}
{"op":"mcm","clk":"1147233880","pt":1439873733941,"mc":[{"id":"1.120089104","rc":[{"atb":[[1.01,1729.65]],"id":9480385}],"con":true,"img":false,"tv":1398.33}]}
{"op":"mcm","clk":"1147233883","pt":1439873734355,"mc":[{"id":"1.120089104","rc":[{"atl":[[1000,0.08]],"id":9480385}],"con":true,"img":false,"tv":1398.33}]}
{"op":"mcm","clk":"1147233884","pt":1439873734459,"mc":[{"id":"1.120089104","rc":[{"atl":[[1000,0]],"id":9480385}],"con":true,"img":false,"tv":1398.33}]}
{"op":"mcm","clk":"1147233886","pt":1439873734563,"mc":[{"id":"1.120089104","rc":[{"atl":[[5.6,0.08]],"id":9480385}],"con":true,"img":false,"tv":1398.33}]}
{"op":"mcm","clk":"1147233888","pt":1439873734977,"mc":[{"id":"1.120089104","rc":[{"atb":[[1.01,1728.34]],"id":9480385}],"con":true,"img":false,"tv":1398.33}]}
{"op":"mcm","clk":"1147233890","pt":1439873735031,"mc":[{"id":"1.120089104","rc":[{"atb":[[1.01,1728.23]],"id":9480385}],"con":true,"img":false,"tv":1398.33}]}
{"op":"mcm","clk":"1147233891","pt":1439873735132,"mc":[{"id":"1.120089104","rc":[{"atb":[[4.8,60.1]],"id":9480385}],"con":true,"img":false,"tv":1398.33}]}
{"op":"mcm","clk":"1147233912","pt":1439873738904,"mc":[{"id":"1.120089104","rc":[{"atb":[[5,3.13]],"id":9480385}],"con":true,"img":false,"tv":1398.33}]}
{"op":"mcm","clk":"1147233921","pt":1439873742356,"mc":[{"id":"1.120089104","rc":[{"atl":[[5.7,0]],"id":9480385}],"con":true,"img":false,"tv":1398.33}]}
{"op":"mcm","clk":"1147235300","pt":1439874038787,"mc":[{"id":"1.120089104","rc":[{"trd":[[1.29,39.97],[1.23,19.75],[1.22,41.99],[1.24,3.95],[1.2,14.88],[1.19,29.49],[1.27,15.77],[1.28,999.46],[1.26,67.27]],"ltp":1.29,"tv":1232.53,"id":9612932},{"atb":[[1.17,44.1],[1.16,22.9],[1.18,46.01],[1.01,1752.01],[1.13,797.2],[1.2,1.77],[1.19,1.41]],"id":9612932},{"trd":[[5,10.17],[5.2,14.84],[5.4,0.17],[5.1,6.11],[5.6,16.37],[5.3,1.75],[5.5,13.26]],"ltp":5.0,"tv":62.67,"id":9480385},{"atb":[[2.62,1.41],[1.01,1728.01],[4.8,60.1],[2.22,12.06],[5.1,3],[5,3.13]],"id":9480385},{"atl":[[11.5,0.83],[10,5.34]],"id":9480385}],"con":true,"img":false,"tv":1397.73}]}
{"op":"mcm","clk":"1147235948","pt":1439874142430,"mc":[{"id":"1.120089104","rc":[{"atb":[[1.15,60.73]],"id":9612932}],"con":true,"img":false,"tv":1397.73}]}
{"op":"mcm","clk":"1147247016","pt":1439874693825,"mc":[{"id":"1.120089104","rc":[{"trd":[[5.1,12.1]],"ltp":5.1,"tv":12.1,"id":9480385},{"atb":[[5.1,0.01]],"id":9480385}],"con":true,"img":false,"tv":1403.71}]}
{"op":"mcm","clk":"1147247069","pt":1439874707728,"mc":[{"id":"1.120089104","rc":[{"atl":[[5.7,2.68]],"id":9480385}],"con":true,"img":false,"tv":1403.71}]}
{"op":"mcm","clk":"1147247121","pt":1439874721116,"mc":[{"id":"1.120089104","rc":[{"atl":[[5.7,5.3]],"id":9480385}],"con":true,"img":false,"tv":1403.71}]}
{"op":"mcm","clk":"1147248786","pt":1439875040008,"mc":[{"id":"1.120089104","rc":[{"atb":[[1.15,110.73]],"id":9612932}],"con":true,"img":false,"tv":1403.71}]}
{"op":"mcm","clk":"1147258236","pt":1439875203917,"mc":[{"id":"1.120089104","rc":[{"trd":[[1.3,50]],"ltp":1.3,"tv":50.0,"id":9612932},{"atl":[[1.3,175]],"id":9612932}],"con":true,"img":false,"tv":1453.71}]}
{"op":"mcm","clk":"1147258730","pt":1439875295853,"mc":[{"id":"1.120089104","rc":[{"trd":[[1.3,150]],"ltp":1.3,"tv":150.0,"id":9612932},{"atl":[[1.3,125]],"id":9612932}],"con":true,"img":false,"tv":1553.71}]}
{"op":"mcm","clk":"1147261018","pt":1439875654474,"mc":[{"id":"1.120089104","rc":[{"trd":[[5,16.43],[5.1,12.11]],"ltp":5.0,"tv":28.54,"id":9480385},{"atb":[[5.1,0],[5,0]],"id":9480385},{"spn":5.25,"spf":"NaN","id":9480385}],"con":true,"img":false,"tv":1559.99}]}
{"op":"mcm","clk":"1147261023","pt":1439875655776,"mc":[{"id":"1.120089104","rc":[{"atb":[[1.22,7.89]],"id":9612932}],"con":true,"img":false,"tv":1559.99}]}
{"op":"mcm","clk":"1147261040","pt":1439875658121,"mc":[{"id":"1.120089104","rc":[{"atb":[[1.21,0]],"id":9612932}],"con":true,"img":false,"tv":1559.99}]}
{"op":"mcm","clk":"1147261042","pt":1439875658226,"mc":[{"id":"1.120089104","rc":[{"atb":[[1.23,6]],"id":9612932}],"con":true,"img":false,"tv":1559.99}]}
{"op":"mcm","clk":"1147261043","pt":1439875658331,"mc":[{"id":"1.120089104","rc":[{"atb":[[1.11,0]],"id":9612932}],"con":true,"img":false,"tv":1559.99}]}
{"op":"mcm","clk":"1147262179","pt":1439875854727,"mc":[{"id":"1.120089104","rc":[{"atb":[[1.19,0]],"id":9612932},{"spn":1.19,"spf":1.0,"id":9612932}],"con":true,"img":false,"tv":1559.99}]}
{"op":"mcm","clk":"1147271210","pt":1439876068818,"mc":[{"id":"1.120089104","rc":[{"atb":[[1.23,7.41]],"id":9612932}],"con":true,"img":false,"tv":1559.99}]}
{"op":"mcm","clk":"1147271977","pt":1439876184424,"mc":[{"id":"1.120089104","rc":[{"atb":[[1.13,789.2]],"id":9612932},{"spn":1.19,"spf":1.0,"id":9612932}],"con":true,"img":false,"tv":1559.99}]}
{"op":"mcm","clk":"1147272113","pt":1439876204940,"mc":[{"id":"1.120089104","rc":[{"atl":[[1.39,0]],"id":9612932}],"con":true,"img":false,"tv":1559.99}]}
{"op":"mcm","clk":"1147272114","pt":1439876205045,"mc":[{"id":"1.120089104","rc":[{"atl":[[1.29,1.9]],"id":9612932}],"con":true,"img":false,"tv":1559.99}]}
{"op":"mcm","clk":"1147272988","pt":1439876375117,"mc":[{"id":"1.120089104","rc":[{"trd":[[1.29,43.76]],"ltp":1.29,"tv":43.76,"id":9612932},{"atl":[[1.29,0.01]],"id":9612932}],"con":true,"img":false,"tv":1563.77}]}
{"op":"mcm","clk":"1147275731","pt":1439876615502,"mc":[{"id":"1.120089104","rc":[{"trd":[[4.9,11.99]],"ltp":4.9,"tv":11.99,"id":9480385},{"atb":[[4.9,0]],"id":9480385},{"spn":5.2,"spf":"NaN","id":9480385}],"con":true,"img":false,"tv":1575.77}]}
{"op":"mcm","clk":"1147275734","pt":1439876615708,"mc":[{"id":"1.120089104","rc":[{"atl":[[5.5,6]],"id":9480385}],"con":true,"img":false,"tv":1575.77}]}
{"op":"mcm","clk":"1147275781","pt":1439876619634,"mc":[{"id":"1.120089104","rc":[{"atl":[[5.7,2.62]],"id":9480385}],"con":true,"img":false,"tv":1575.77}]}
{"op":"mcm","clk":"1147275782","pt":1439876619738,"mc":[{"id":"1.120089104","rc":[{"atl":[[5.4,2.83]],"id":9480385}],"con":true,"img":false,"tv":1575.77}]}
{"op":"mcm","clk":"1147275790","pt":1439876620313,"mc":[{"id":"1.120089104","rc":[{"atl":[[5.5,0]],"id":9480385}],"con":true,"img":false,"tv":1575.77}]}
{"op":"mcm","clk":"1147275792","pt":1439876620422,"mc":[{"id":"1.120089104","rc":[{"atl":[[5.3,6]],"id":9480385}],"con":true,"img":false,"tv":1575.77}]}
{"op":"mcm","clk":"1147275964","pt":1439876634233,"mc":[{"id":"1.120089104","rc":[{"atl":[[5.7,0]],"id":9480385}],"con":true,"img":false,"tv":1575.77}]}
{"op":"mcm","clk":"1147276046","pt":1439876641521,"mc":[{"id":"1.120089104","rc":[{"atl":[[5.4,0]],"id":9480385}],"con":true,"img":false,"tv":1575.77}]}
{"op":"mcm","clk":"1147276047","pt":1439876641625,"mc":[{"id":"1.120089104","rc":[{"atl":[[5.7,2.68]],"id":9480385}],"con":true,"img":false,"tv":1575.77}]}
{"op":"mcm","clk":"1147276091","pt":1439876644723,"mc":[{"id":"1.120089104","rc":[{"atl":[[5.3,0]],"id":9480385}],"con":true,"img":false,"tv":1575.77}]}
{"op":"mcm","clk":"1147276093","pt":1439876644826,"mc":[{"id":"1.120089104","rc":[{"atl":[[5.5,6]],"id":9480385}],"con":true,"img":false,"tv":1575.77}]}
{"op":"mcm","clk":"1147276191","pt":1439876653015,"mc":[{"id":"1.120089104","rc":[{"atl":[[5.5,8.73]],"id":9480385}],"con":true,"img":false,"tv":1575.77}]}
{"op":"mcm","clk":"1147276444","pt":1439876674440,"mc":[{"id":"1.120089104","rc":[{"atl":[[5.7,0]],"id":9480385}],"con":true,"img":false,"tv":1575.77}]}
{"op":"mcm","clk":"1147276447","pt":1439876674547,"mc":[{"id":"1.120089104","rc":[{"atl":[[5.4,2.83]],"id":9480385}],"con":true,"img":false,"tv":1575.77}]}
{"op":"mcm","clk":"1147276472","pt":1439876676889,"mc":[{"id":"1.120089104","rc":[{"atl":[[5.5,2.73]],"id":9480385},{"spn":5.1,"spf":"NaN","id":9480385}],"con":true,"img":false,"tv":1575.77}]}
{"op":"mcm","clk":"1147276474","pt":1439876676992,"mc":[{"id":"1.120089104","rc":[{"atl":[[5.3,6]],"id":9480385}],"con":true,"img":false,"tv":1575.77}]}
{"op":"mcm","clk":"1147276595","pt":1439876689696,"mc":[{"id":"1.120089104","rc":[{"atl":[[5.5,0]],"id":9480385}],"con":true,"img":false,"tv":1575.77}]}
{"op":"mcm","clk":"1147276710","pt":1439876702113,"mc":[{"id":"1.120089104","rc":[{"atl":[[5.4,0]],"id":9480385}],"con":true,"img":false,"tv":1575.77}]}
{"op":"mcm","clk":"1147276713","pt":1439876702219,"mc":[{"id":"1.120089104","rc":[{"atl":[[5.7,2.68]],"id":9480385}],"con":true,"img":false,"tv":1575.77}]}
{"op":"mcm","clk":"1147276716","pt":1439876702531,"mc":[{"id":"1.120089104","rc":[{"atl":[[5.3,0]],"id":9480385}],"con":true,"img":false,"tv":1575.77}]}
{"op":"mcm","clk":"1147276718","pt":1439876702635,"mc":[{"id":"1.120089104","rc":[{"atl":[[5.5,6]],"id":9480385}],"con":true,"img":false,"tv":1575.77}]}
{"op":"mcm","clk":"1147276803","pt":1439876708912,"mc":[{"id":"1.120089104","rc":[{"atl":[[5.5,8.73]],"id":9480385}],"con":true,"img":false,"tv":1575.77}]}
{"op":"mcm","clk":"1147277006","pt":1439876729464,"mc":[{"id":"1.120089104","rc":[{"atl":[[5.7,0]],"id":9480385}],"con":true,"img":false,"tv":1575.77}]}
{"op":"mcm","clk":"1147277008","pt":1439876729568,"mc":[{"id":"1.120089104","rc":[{"atl":[[5.4,2.83]],"id":9480385}],"con":true,"img":false,"tv":1575.77}]}
{"op":"mcm","clk":"1147277013","pt":1439876730141,"mc":[{"id":"1.120089104","rc":[{"atl":[[5.5,2.73]],"id":9480385}],"con":true,"img":false,"tv":1575.77}]}
{"op":"mcm","clk":"1147277015","pt":1439876730245,"mc":[{"id":"1.120089104","rc":[{"atl":[[5.3,6]],"id":9480385}],"con":true,"img":false,"tv":1575.77}]}
{"op":"mcm","clk":"1147277168","pt":1439876745389,"mc":[{"id":"1.120089104","rc":[{"atl":[[5.5,0]],"id":9480385},{"spn":5.05,"spf":"NaN","id":9480385}],"con":true,"img":false,"tv":1575.77}]}
{"op":"mcm","clk":"1147277312","pt":1439876756754,"mc":[{"id":"1.120089104","rc":[{"atl":[[5.4,0]],"id":9480385}],"con":true,"img":false,"tv":1575.77}]}
{"op":"mcm","clk":"1147277314","pt":1439876756856,"mc":[{"id":"1.120089104","rc":[{"atl":[[5.7,2.68]],"id":9480385}],"con":true,"img":false,"tv":1575.77}]}
{"op":"mcm","clk":"1147277332","pt":1439876758158,"mc":[{"id":"1.120089104","rc":[{"atl":[[5.3,0]],"id":9480385}],"con":true,"img":false,"tv":1575.77}]}
{"op":"mcm","clk":"1147277335","pt":1439876758262,"mc":[{"id":"1.120089104","rc":[{"atl":[[5.5,6]],"id":9480385}],"con":true,"img":false,"tv":1575.77}]}
{"op":"mcm","clk":"1147277408","pt":1439876763842,"mc":[{"id":"1.120089104","rc":[{"atl":[[5.5,8.73]],"id":9480385}],"con":true,"img":false,"tv":1575.77}]}
{"op":"mcm","clk":"1147277787","pt":1439876800562,"mc":[{"id":"1.120089104","rc":[{"atl":[[5.7,0]],"id":9480385}],"con":true,"img":false,"tv":1575.77}]}
{"op":"mcm","clk":"1147277790","pt":1439876800614,"mc":[{"id":"1.120089104","rc":[{"atl":[[5.4,2.83]],"id":9480385}],"con":true,"img":false,"tv":1575.77}]}
{"op":"mcm","clk":"1147277800","pt":1439876802266,"mc":[{"id":"1.120089104","rc":[{"atl":[[5.5,2.73]],"id":9480385}],"con":true,"img":false,"tv":1575.77}]}
{"op":"mcm","clk":"1147277801","pt":1439876802369,"mc":[{"id":"1.120089104","rc":[{"atl":[[5.3,6]],"id":9480385}],"con":true,"img":false,"tv":1575.77}]}
{"op":"mcm","clk":"1147277955","pt":1439876818499,"mc":[{"id":"1.120089104","rc":[{"atl":[[5.5,0]],"id":9480385}],"con":true,"img":false,"tv":1575.77}]}
{"op":"mcm","clk":"1147277986","pt":1439876822664,"mc":[{"id":"1.120089104","rc":[{"atl":[[5.4,0]],"id":9480385}],"con":true,"img":false,"tv":1575.77}]}
{"op":"mcm","clk":"1147277988","pt":1439876822760,"mc":[{"id":"1.120089104","rc":[{"atl":[[5.7,2.68]],"id":9480385}],"con":true,"img":false,"tv":1575.77}]}
{"op":"mcm","clk":"1147278038","pt":1439876827189,"mc":[{"id":"1.120089104","rc":[{"atl":[[5.3,0]],"id":9480385}],"con":true,"img":false,"tv":1575.77}]}
{"op":"mcm","clk":"1147278040","pt":1439876827293,"mc":[{"id":"1.120089104","rc":[{"atl":[[5.5,6]],"id":9480385}],"con":true,"img":false,"tv":1575.77}]}
{"op":"mcm","clk":"1147278140","pt":1439876836984,"mc":[{"id":"1.120089104","rc":[{"atl":[[5.5,8.73]],"id":9480385}],"con":true,"img":false,"tv":1575.77}]}
{"op":"mcm","clk":"1147278290","pt":1439876849967,"mc":[{"id":"1.120089104","rc":[{"atl":[[5.7,0]],"id":9480385}],"con":true,"img":false,"tv":1575.77}]}
{"op":"mcm","clk":"1147278292","pt":1439876850072,"mc":[{"id":"1.120089104","rc":[{"atl":[[5.4,2.83]],"id":9480385}],"con":true,"img":false,"tv":1575.77}]}
{"op":"mcm","clk":"1147278353","pt":1439876853470,"mc":[{"id":"1.120089104","rc":[{"atl":[[5.5,2.73]],"id":9480385}],"con":true,"img":false,"tv":1575.77}]}
{"op":"mcm","clk":"1147278354","pt":1439876853575,"mc":[{"id":"1.120089104","rc":[{"atl":[[5.3,6]],"id":9480385}],"con":true,"img":false,"tv":1575.77}]}
{"op":"mcm","clk":"1147278726","pt":1439876873730,"mc":[{"id":"1.120089104","rc":[{"atl":[[5.5,0]],"id":9480385}],"con":true,"img":false,"tv":1575.77}]}
{"op":"mcm","clk":"1147278800","pt":1439876877601,"mc":[{"id":"1.120089104","rc":[{"atl":[[5.4,0]],"id":9480385}],"con":true,"img":false,"tv":1575.77}]}
{"op":"mcm","clk":"1147278803","pt":1439876877755,"mc":[{"id":"1.120089104","rc":[{"atl":[[5.7,2.68]],"id":9480385}],"con":true,"img":false,"tv":1575.77}]}
{"op":"mcm","clk":"1147278853","pt":1439876880134,"mc":[{"id":"1.120089104","rc":[{"atl":[[5.3,0]],"id":9480385},{"spn":5.2,"spf":"NaN","id":9480385}],"con":true,"img":false,"tv":1575.77}]}
{"op":"mcm","clk":"1147278867","pt":1439876880238,"mc":[{"id":"1.120089104","rc":[{"atl":[[5.5,6]],"id":9480385}],"con":true,"img":false,"tv":1575.77}]}
{"op":"mcm","clk":"1147279159","pt":1439876893192,"mc":[{"id":"1.120089104","rc":[{"atl":[[5.5,8.73]],"id":9480385}],"con":true,"img":false,"tv":1575.77}]}
{"op":"mcm","clk":"1147279451","pt":1439876910619,"mc":[{"id":"1.120089104","rc":[{"atl":[[5.7,0]],"id":9480385}],"con":true,"img":false,"tv":1575.77}]}
{"op":"mcm","clk":"1147279453","pt":1439876910721,"mc":[{"id":"1.120089104","rc":[{"atl":[[5.4,2.83]],"id":9480385}],"con":true,"img":false,"tv":1575.77}]}
{"op":"mcm","clk":"1147279463","pt":1439876911452,"mc":[{"id":"1.120089104","rc":[{"atl":[[5.5,6]],"id":9480385}],"con":true,"img":false,"tv":1575.77}]}
{"op":"mcm","clk":"1147279471","pt":1439876912338,"mc":[{"id":"1.120089104","rc":[{"atl":[[5.5,0]],"id":9480385}],"con":true,"img":false,"tv":1575.77}]}
{"op":"mcm","clk":"1147279473","pt":1439876912442,"mc":[{"id":"1.120089104","rc":[{"atl":[[5.3,6]],"id":9480385}],"con":true,"img":false,"tv":1575.77}]}
{"op":"mcm","clk":"1147279917","pt":1439876938000,"mc":[{"id":"1.120089104","rc":[{"atl":[[5.4,0]],"id":9480385}],"con":true,"img":false,"tv":1575.77}]}
{"op":"mcm","clk":"1147279919","pt":1439876938105,"mc":[{"id":"1.120089104","rc":[{"atl":[[5.7,2.68]],"id":9480385}],"con":true,"img":false,"tv":1575.77}]}
{"op":"mcm","clk":"1147279949","pt":1439876940141,"mc":[{"id":"1.120089104","rc":[{"atl":[[5.3,0]],"id":9480385}],"con":true,"img":false,"tv":1575.77}]}
{"op":"mcm","clk":"1147279952","pt":1439876940245,"mc":[{"id":"1.120089104","rc":[{"atl":[[5.5,6]],"id":9480385}],"con":true,"img":false,"tv":1575.77}]}
{"op":"mcm","clk":"1147280091","pt":1439876948574,"mc":[{"id":"1.120089104","rc":[{"atl":[[5.5,8.73]],"id":9480385}],"con":true,"img":false,"tv":1575.77}]}
{"op":"mcm","clk":"1147288352","pt":1439876976538,"mc":[{"id":"1.120089104","rc":[{"atl":[[5.7,0]],"id":9480385}],"con":true,"img":false,"tv":1575.77}]}
{"op":"mcm","clk":"1147288354","pt":1439876976590,"mc":[{"id":"1.120089104","rc":[{"atl":[[5.4,2.83]],"id":9480385}],"con":true,"img":false,"tv":1575.77}]}
{"op":"mcm","clk":"1147288358","pt":1439876976903,"mc":[{"id":"1.120089104","rc":[{"atl":[[5.5,2.73]],"id":9480385}],"con":true,"img":false,"tv":1575.77}]}
{"op":"mcm","clk":"1147288361","pt":1439876977007,"mc":[{"id":"1.120089104","rc":[{"atl":[[5.3,6]],"id":9480385}],"con":true,"img":false,"tv":1575.77}]}
{"op":"mcm","clk":"1147288423","pt":1439876984979,"mc":[{"id":"1.120089104","rc":[{"atl":[[5.5,0]],"id":9480385}],"con":true,"img":false,"tv":1575.77}]}
{"op":"mcm","clk":"1147288636","pt":1439877003167,"mc":[{"id":"1.120089104","rc":[{"atl":[[5.3,8.83]],"id":9480385},{"spn":5.05,"spf":"NaN","id":9480385}],"con":true,"img":false,"tv":1575.77}]}
{"op":"mcm","clk":"1147288649","pt":1439877004315,"mc":[{"id":"1.120089104","rc":[{"atl":[[5.4,0]],"id":9480385}],"con":true,"img":false,"tv":1575.77}]}
{"op":"mcm","clk":"1147288651","pt":1439877004368,"mc":[{"id":"1.120089104","rc":[{"atl":[[5.7,2.68]],"id":9480385}],"con":true,"img":false,"tv":1575.77}]}
{"op":"mcm","clk":"1147292569","pt":1439877336051,"mc":[{"id":"1.120089104","rc":[{"trd":[[1.3,191.18],[1.29,43.77]],"ltp":1.3,"tv":234.95,"id":9612932},{"atl":[[1.29,0],[1.3,104.41]],"id":9612932}],"con":true,"img":false,"tv":1616.97}]}
{"op":"mcm","clk":"1147294784","pt":1439877500945,"mc":[{"id":"1.120089104","rc":[{"atb":[[1.02,16071.99]],"id":9612932},{"atb":[[1.02,10251.99]],"id":9480385}],"con":true,"img":false,"tv":1616.97}]}
{"op":"mcm","clk":"1147295714","pt":1439877576467,"mc":[{"id":"1.120089104","rc":[{"trd":[[4.8,120.21]],"ltp":4.8,"tv":120.21,"id":9480385},{"atb":[[4.8,0]],"id":9480385},{"spn":5.0,"spf":"NaN","id":9480385}],"con":true,"img":false,"tv":1737.18}]}
{"op":"mcm","clk":"1147295754","pt":1439877578882,"mc":[{"id":"1.120089104","rc":[{"atl":[[1000,1.41]],"id":9480385}],"con":true,"img":false,"tv":1737.18}]}
{"op":"mcm","clk":"1147295756","pt":1439877578987,"mc":[{"id":"1.120089104","rc":[{"atb":[[1.01,1729.43]],"id":9480385}],"con":true,"img":false,"tv":1737.18}]}
{"op":"mcm","clk":"1147295764","pt":1439877579563,"mc":[{"id":"1.120089104","rc":[{"atl":[[1000,0.09]],"id":9480385}],"con":true,"img":false,"tv":1737.18}]}
{"op":"mcm","clk":"1147295765","pt":1439877579669,"mc":[{"id":"1.120089104","rc":[{"atl":[[1000,0]],"id":9480385}],"con":true,"img":false,"tv":1737.18}]}
{"op":"mcm","clk":"1147295766","pt":1439877579774,"mc":[{"id":"1.120089104","rc":[{"atl":[[5.2,0.09]],"id":9480385}],"con":true,"img":false,"tv":1737.18}]}
{"op":"mcm","clk":"1147295768","pt":1439877579881,"mc":[{"id":"1.120089104","rc":[{"atb":[[1.01,1728.13]],"id":9480385}],"con":true,"img":false,"tv":1737.18}]}
{"op":"mcm","clk":"1147295771","pt":1439877580090,"mc":[{"id":"1.120089104","rc":[{"atb":[[1.01,1728.01]],"id":9480385}],"con":true,"img":false,"tv":1737.18}]}
{"op":"mcm","clk":"1147295773","pt":1439877580196,"mc":[{"id":"1.120089104","rc":[{"atb":[[4.6,60.11]],"id":9480385}],"con":true,"img":false,"tv":1737.18}]}
{"op":"mcm","clk":"1147295795","pt":1439877581915,"mc":[{"id":"1.120089104","rc":[{"atl":[[5.3,2.83]],"id":9480385}],"con":true,"img":false,"tv":1737.18}]}
{"op":"mcm","clk":"1147295798","pt":1439877581971,"mc":[{"id":"1.120089104","rc":[{"atl":[[5.2,6.09]],"id":9480385}],"con":true,"img":false,"tv":1737.18}]}
{"op":"mcm","clk":"1147295852","pt":1439877586056,"mc":[{"id":"1.120089104","rc":[{"atl":[[5.3,0]],"id":9480385}],"con":true,"img":false,"tv":1737.18}]}
{"op":"mcm","clk":"1147295890","pt":1439877588684,"mc":[{"id":"1.120089104","rc":[{"atb":[[1.12,420]],"id":9612932}],"con":true,"img":false,"tv":1737.18}]}
{"op":"mcm","clk":"1147295919","pt":1439877591524,"mc":[{"id":"1.120089104","rc":[{"atl":[[5.7,0]],"id":9480385}],"con":true,"img":false,"tv":1737.18}]}
{"op":"mcm","clk":"1147295922","pt":1439877591628,"mc":[{"id":"1.120089104","rc":[{"atl":[[5.9,2.59]],"id":9480385}],"con":true,"img":false,"tv":1737.18}]}
{"op":"mcm","clk":"1147295989","pt":1439877597215,"mc":[{"id":"1.120089104","rc":[{"atl":[[1000,3]],"id":9612932},{"atl":[[1000,2]],"id":9480385}],"con":true,"img":false,"tv":1737.18}]}
{"op":"mcm","clk":"1147295991","pt":1439877597319,"mc":[{"id":"1.120089104","rc":[{"atl":[[1000,1.01]],"id":9612932},{"atl":[[1000,0.01]],"id":9480385}],"con":true,"img":false,"tv":1737.18}]}
{"op":"mcm","clk":"1147295993","pt":1439877597424,"mc":[{"id":"1.120089104","rc":[{"atl":[[1000,1]],"id":9612932},{"atl":[[1000,0]],"id":9480385}],"con":true,"img":false,"tv":1737.22}]}
{"op":"mcm","clk":"1147295995","pt":1439877597527,"mc":[{"id":"1.120089104","rc":[{"trd":[[1.23,19.77]],"ltp":1.23,"tv":19.77,"id":9612932},{"atb":[[1.23,7.4]],"id":9612932},{"trd":[[4.7,0.02]],"ltp":4.7,"tv":0.02,"id":9480385},{"atb":[[4.7,5.99]],"id":9480385}],"con":true,"img":false,"tv":1737.22}]}
{"op":"mcm","clk":"1147296095","pt":1439877604373,"mc":[{"id":"1.120089104","rc":[{"atl":[[5.2,8.97]],"id":9480385}],"con":true,"img":false,"tv":1737.22}]}
{"op":"mcm","clk":"1147302112","pt":1439877864875,"mc":[{"id":"1.120089104","marketDefinition":{"bspMarket":true,"turnInPlayEnabled":true,"persistenceEnabled":true,"marketBaseRate":5.0,"eventId":"27514783","eventTypeId":"7","numberOfWinners":1,"bettingType":"ODDS","marketType":"WIN","marketTime":"2015-08-18T20:20:00.000Z","suspendTime":"2015-08-18T20:20:00.000Z","bspReconciled":false,"complete":true,"inPlay":false,"crossMatching":false,"runnersVoidable":false,"numberOfActiveRunners":2,"betDelay":0,"status":"OPEN","runners":[{"adjustmentFactor":79.72,"status":"ACTIVE","sortPriority":1,"id":9612932,"name":"Alinstante"},{"adjustmentFactor":20.27,"status":"ACTIVE","sortPriority":2,"id":9480385,"name":"Vallance Road"}],"regulators":["MR_INT"],"venue":"Chelmsford City","countryCode":"GB","discountAllowed":false,"timezone":"Europe/London","openDate":"2015-08-18T17:20:00.000Z","version":1060767560,"name":"1m Cond Stks","eventName":"ChelmC 18th Aug"},"rc":[{"trd":[[1.23,19.77],[1.3,191.18],[1.29,43.77],[1.22,41.99],[1.24,3.95],[1.2,14.88],[1.4,49.38],[1.19,29.49],[1.28,999.46],[1.27,15.77],[1.25,1.76],[1.26,67.27],[1.21,51.3]],"ltp":1.23,"tv":1529.97,"id":9612932},{"atb":[[1.17,44.1],[1.16,22.9],[1.04,240],[1.06,20],[1.18,46.01],[1.14,400],[1.01,1752.01],[1.13,789.2],[1.15,110.73],[1.02,16071.99],[1.23,7.4],[1.12,420],[1.1,400],[1.22,7.89],[1.08,10],[1.2,1.77]],"id":9612932},{"atl":[[1.3,104.41],[1.69,15],[46,2],[19.5,11],[630,0.09],[1.4,500],[1000,1],[4,0.25]],"id":9612932},{"spl":[[1.01,38.95]],"id":9612932},{"spn":1.19,"spf":1.0,"id":9612932},{"trd":[[4.7,0.02],[4.9,11.99],[5.2,14.84],[5.4,0.17],[5.1,12.11],[4.8,120.21],[5.6,16.37],[5.3,1.75],[5.5,13.26],[5,16.43]],"ltp":4.7,"tv":207.14,"id":9480385},{"atb":[[4.4,60],[2.62,1.41],[2.6,1.9],[1.06,20],[1.18,30],[3.75,15],[1.81,12.35],[2.28,37],[1.01,1728.01],[1.02,10251.99],[2.16,30],[1.08,10],[2.22,12.06],[4.7,5.99],[4.5,6],[2.92,175],[4.6,60.11]],"id":9480385},{"atl":[[5.9,2.59],[630,0.09],[10,5.34],[5.8,0.08],[5.2,8.97],[6,0.07],[46,2],[6.6,0.06],[55,0.01],[90,2],[11.5,0.83],[10.5,15],[7.2,0.1],[5.6,0.08]],"id":9480385},{"spn":4.95,"spf":"NaN","id":9480385}],"con":true,"img":true,"tv":1737.22}]}
{"op":"mcm","clk":"1147312984","pt":1439878297012,"mc":[{"id":"1.120089104","rc":[{"trd":[[1.3,209.87]],"ltp":1.3,"tv":209.87,"id":9612932},{"atl":[[1.3,95.06]],"id":9612932},{"spn":4.95,"spf":"NaN","id":9480385}],"con":true,"img":false,"tv":1755.92}]}
{"op":"mcm","clk":"1147315385","pt":1439878475138,"mc":[{"id":"1.120089104","rc":[{"atl":[[1.28,2.63]],"id":9612932}],"con":true,"img":false,"tv":1755.92}]}
{"op":"mcm","clk":"1147315399","pt":1439878475766,"mc":[{"id":"1.120089104","rc":[{"atl":[[1.28,0]],"id":9612932}],"con":true,"img":false,"tv":1755.92}]}
{"op":"mcm","clk":"1147315931","pt":1439878522207,"mc":[{"id":"1.120089104","rc":[{"atl":[[1.29,97]],"id":9612932}],"con":true,"img":false,"tv":1755.92}]}
{"op":"mcm","clk":"1147316116","pt":1439878537380,"mc":[{"id":"1.120089104","rc":[{"trd":[[4.7,11.99]],"ltp":4.7,"tv":11.99,"id":9480385},{"atb":[[4.7,0]],"id":9480385},{"spn":4.9,"spf":"NaN","id":9480385}],"con":true,"img":false,"tv":1767.9}]}
{"op":"mcm","clk":"1147316224","pt":1439878546175,"mc":[{"id":"1.120089104","rc":[{"atb":[[1.22,0],[1.24,7.76]],"id":9612932}],"con":true,"img":false,"tv":1767.9}]}
{"op":"mcm","clk":"1147316254","pt":1439878547893,"mc":[{"id":"1.120089104","rc":[{"atb":[[1.23,1.41]],"id":9612932}],"con":true,"img":false,"tv":1767.9}]}
{"op":"mcm","clk":"1147316256","pt":1439878547996,"mc":[{"id":"1.120089104","rc":[{"atb":[[1.25,5.99]],"id":9612932}],"con":true,"img":false,"tv":1767.9}]}
{"op":"mcm","clk":"1147318254","pt":1439878704228,"mc":[{"id":"1.120089104","rc":[{"atb":[[1.13,25]],"id":9612932},{"spn":1.2,"spf":1.0,"id":9612932}],"con":true,"img":false,"tv":1767.9}]}
{"op":"mcm","clk":"1147318256","pt":1439878704433,"mc":[{"id":"1.120089104","rc":[{"atb":[[1.17,628.49]],"id":9612932}],"con":true,"img":false,"tv":1767.9}]}
{"op":"mcm","clk":"1147318986","pt":1439878757206,"mc":[{"id":"1.120089104","rc":[{"atb":[[1.23,0]],"id":9612932}],"con":true,"img":false,"tv":1767.9}]}
